Workbook

Sheet LogicCommon
A2: オペレーション実装仕様書 | B2: ModuleID : | C2: MG | D2: LogicID : | E2: MGBDL0640 | F2: Pj.ID : | G2: MC
B3: SubModuleID : | C3: MGBD | D3: LogicClass : | E3: MGBDL_CostItmCopyReg | F3: SuperClassPj.ID :
D4: LogicName : | E4: 原価品目系情報確認＆コピー | F4: SuperLogicID : | G4: MG.MGUDL5010
A5: 概要 :
A6: 詳細 :

Sheet CostItmCopy_Chk01
A1: * | B1: * | D1: L | E1: 1
A2: * | D2: オペレーション実装仕様書 Operation Specification Implementation Sheet | E2: ModuleID : | F2: =IF(LogicCommon!C2="","",LogicCommon!C2) -> MG | G2: LogicID : | H2: =IF(LogicCommon!E2="","",LogicCommon!E2) -> MGBDL0640 | I2: Ope.ID : | J2: CostItmCopy_Chk01 | K2: Pj.ID : | L2: =IF(LogicCommon!G2="","",LogicCommon!G2) -> MC | M2: Ope.Body : | N2: MA.MAUDL5010.Checker
A3: * | D3: =IF(LogicCommon!A3="","",LogicCommon!A3) | E3: SubModuleID : | F3: =IF(LogicCommon!C3="","",LogicCommon!C3) -> MGBD | G3: LogicClass : | H3: =IF(LogicCommon!E3="","",LogicCommon!E3) -> MGBDL_CostItmCopyReg | I3: Ope.Method : | J3: @ | K3: SuperClassPj.ID : | L3: =IF(LogicCommon!G3="","",LogicCommon!G3) | O3: Gene.Type : | P3: ALL
A4: * | E4: Version : | F4: 000000 | G4: LogicName : | H4: =IF(LogicCommon!E4="","",LogicCommon!E4) -> 原価品目系情報確認＆コピー | I4: Ope.Name : | J4: コピー前チェック | K4: SuperLogicID : | L4: =IF(LogicCommon!G4="","",LogicCommon!G4) -> MG.MGUDL5010 | M4: ImplOpe.ID:
A5: * | E5: ACType :
A6: * | D6: 概要 : | E6: コピーする前のチェックを行う | AD6: ID | AF6: ID | AH6: ID
A7: # | I7: U | K7: K | L7: K | M7: K | N7: K | O7: K | P7: K | Q7: K | R7: K | S7: K | T7: K | U7: K | V7: K | W7: K | X7: K | Y7: K | Z7: K | AA7: K | AB7: K | AC7: o | AE7: o | AG7: o
A8: # | D8: ブロック名 Block Name | E8: 型 Type | G8: super/share | H8: 対象ブロック名 Target Block Name | K8: REQ_UPD_CNT_CHK | L8: REQUIRED | M8: CHK_NUM | N8: SMALL_LARGE | O8: CHK_DT | P8: BEFORE_AFTER | Q8: CHK_PTN | R8: DUPLICATE | S8: TOO_MANY_INPUTS | T8: AT_LEAST_ONE | U8: ONLY_ONE_INPUT | V8: LIST_LOGIC | W8: LIST_OUT | X8: LIST_OUT_BASE | Y8: LIST_IN | Z8: LIST_IN_BASE | AA8: CONST | AB8: NULL_VAL | AC8: TargetName | AE8: TargetName | AG8: TargetName | AK8: ブロック備考 Block Remarks
A9: # | D9: 項目名 Field Name | E9: 型 Type | F9: 桁 Digits | G9: フルネーム Full Name | H9: 日本語名 Japanese Name | I9: 上り項目 Request Message Field | J9: 下り項目 Response Message Field | AI9: 条件および編集方法 Conditions and Editing Methods | AK9: 項目備考 Field Remarks
A10: # | AC10: 上り項目 Request Message Field | AD10: 下り項目 Response Message Field | AE10: 上り項目 Request Message Field | AF10: 下り項目 Response Message Field | AG10: 上り項目 Request Message Field | AH10: 下り項目 Response Message Field
A11: 10 | B11: * | D11: Dtl | E11: GL | G11: $super$ | H11: DBC:MA.MAM_ITM
A12: 10 | D12: calc_ctg_cd | E12: #MA.CALC_CTG_CD | G12: Calculation category cd. | H12: 計算カテゴリーＣＤ | I12: E | L12: E
A13: 10 | D13: term | E13: #MA.YM | G13: Term | H13: 期 | I13: E | L13: E
A14: 10 | D14: itm_cd | E14: #MA.ITM_CD | G14: Item cd. | H14: 品目ＣＤ | I14: E | L14: E
A15: 10 | D15: itm_sub1 | E15: #MA.ITM_SUB1 | G15: Branch No. 1 | H15: 枝番１ | I15: E | AB15: E
A16: 10 | D16: itm_sub2 | E16: #MA.ITM_SUB2 | G16: Branch No. 2 | H16: 枝番２ | I16: E | AB16: E
A17: 10 | D17: itm_sub3 | E17: #MA.ITM_SUB3 | G17: Branch No. 3 | H17: 枝番３ | I17: E | V17: MA.MAUAL0010.ItmSub3 | W17: stk_mng_typ;asset_mng_typ;base_unit_cd | X17: stk_mng_typ;asset_mng_typ;unit_cd | Y17: MAC_ITM_IS_SRCH_TYP.NOT_ASSET3;itm_cd;itm_sub1;itm_sub2;true;true | Z17: itm_is_srch_typ;itm_cd;itm_sub1;itm_sub2;release_flg_on;release_flg_off | AB17: E
A18: 10 | D18: itm_nm | E18: #MA.ITM_NM | G18: Item name | H18: 品名
A19: 10 | D19: base_itm_nm | E19: #MA.ITM_NM | G19: Standard Item name | H19: 標準品名
A20: 10 | D20: itm_typ | E20: #MA.ITM_TYP | G20: Item type | H20: 品目区分 | AA20: MAC_ITM_TYP
A21: 10 | D21: itm_typ_nm | E21: #MA.ITM_TYP_NM | G21: Item type name | H21: 品目区分名
A22: 10 | D22: itm_typ_d_cd | E22: #MA.ITM_TYP_D_CD | G22: Item type details cd. | H22: 品目区分詳細ＣＤ
A23: 10 | D23: itm_typ_d_nm | E23: #MA.ITM_TYP_D_NM | G23: Item type details name | H23: 品目区分詳細名
A24: 10 | D24: itm_jnl_cd | E24: #MA.ITM_JNL_CD | G24: Item journal cd. | H24: 品目仕訳ＣＤ
A25: 10 | D25: itm_jnl_nm | E25: #MA.ITM_JNL_NM | G25: Item journal name | H25: 品目仕訳名
A26: 10 | D26: stk_mng_typ | E26: #MA.STK_MNG_TYP | G26: Inventory management type | H26: 在庫管理区分 | J26: E
A27: 10 | D27: asset_mng_typ | E27: #MA.ASSET_MNG_TYP | G27: Asset management type | H27: 資産管理区分 | J27: E
A28: 10 | D28: base_unit_cd | E28: #MA.UNIT_CD | G28: Base unit cd. | H28: 基準単位ＣＤ | J28: E
A29: 10 | D29: dest_itm_cd | E29: #MA.ITM_CD | G29: (Copy-to) Item cd. | H29: （コピー先）品目ＣＤ | I29: E
A30: 10 | D30: dest_itm_sub1 | E30: #MA.ITM_SUB1 | G30: (Copy-to) Branch No. 1 | H30: （コピー先）枝番１ | I30: E | AB30: E
A31: 10 | D31: dest_itm_sub2 | E31: #MA.ITM_SUB2 | G31: (Copy-to) Branch No. 2 | H31: （コピー先）枝番２ | I31: E | AB31: E
A32: 10 | D32: dest_itm_sub3 | E32: #MA.ITM_SUB3 | G32: (Copy-to) Branch No. 3 | H32: （コピー先）枝番３ | I32: E | V32: MA.MAUAL0010.ItmSub3 | W32: dest_stk_mng_typ;dest_asset_mng_typ;dest_base_unit_cd | X32: stk_mng_typ;asset_mng_typ;unit_cd | Y32: MAC_ITM_IS_SRCH_TYP.NOT_ASSET3;dest_itm_cd;dest_itm_sub1;dest_itm_sub2;true;true | Z32: itm_is_srch_typ;itm_cd;itm_sub1;itm_sub2;release_flg_on;release_flg_off | AB32: E
A33: 10 | D33: dest_itm_nm | E33: #MA.ITM_NM | G33: (Copy-to) Item name | H33: （コピー先）品名
A34: 10 | D34: dest_stk_mng_typ | E34: #MA.STK_MNG_TYP | G34: (Copy-to) Inventory management type | H34: （コピー先）在庫管理区分 | J34: E
A35: 10 | D35: dest_asset_mng_typ | E35: #MA.ASSET_MNG_TYP | G35: (Copy-to) Asset management type | H35: （コピー先）資産管理区分 | J35: E
A36: 10 | D36: dest_base_unit_cd | E36: #MA.UNIT_CD | G36: (Copy-to) Base unit cd. | H36: （コピー先）基準単位ＣＤ | J36: E
A37: 10 | D37: mam_itm_ | E37: #MA.INT | G37: Item | H37: 品目
A38: 10 | D38: mgt_itm | E38: #MA.INT | G38: Cost item info. | H38: 原価品目情報
A39: 10 | D39: mgt_itm_dtl | E39: #MA.INT | G39: Cost item details | H39: 原価品目詳細
A40: 10 | D40: mgt_itm_oper | E40: #MA.INT | G40: Cost item operation | H40: 原価品目工程
...

Sheet CostItmCopy_Chk02
A1: * | B1: * | D1: L | E1: 1
A2: * | D2: オペレーション実装仕様書 Operation Specification Implementation Sheet | E2: ModuleID : | F2: =IF(LogicCommon!C2="","",LogicCommon!C2) -> MG | G2: LogicID : | H2: =IF(LogicCommon!E2="","",LogicCommon!E2) -> MGBDL0640 | I2: Ope.ID : | J2: CostItmCopy_Chk02 | K2: Pj.ID : | L2: =IF(LogicCommon!G2="","",LogicCommon!G2) -> MC | M2: Ope.Body : | N2: MA.MAUDL5010.Checker
A3: * | D3: =IF(LogicCommon!A3="","",LogicCommon!A3) | E3: SubModuleID : | F3: =IF(LogicCommon!C3="","",LogicCommon!C3) -> MGBD | G3: LogicClass : | H3: =IF(LogicCommon!E3="","",LogicCommon!E3) -> MGBDL_CostItmCopyReg | I3: Ope.Method : | J3: @ | K3: SuperClassPj.ID : | L3: =IF(LogicCommon!G3="","",LogicCommon!G3) | O3: Gene.Type : | P3: ALL
A4: * | E4: Version : | F4: 000000 | G4: LogicName : | H4: =IF(LogicCommon!E4="","",LogicCommon!E4) -> 原価品目系情報確認＆コピー | I4: Ope.Name : | J4: 削除前チェック | K4: SuperLogicID : | L4: =IF(LogicCommon!G4="","",LogicCommon!G4) -> MG.MGUDL5010 | M4: ImplOpe.ID:
A5: * | E5: ACType :
A6: * | D6: 概要 : | E6: 削除する前のチェックを行う | M6: ID | O6: ID | Q6: ID
A7: # | I7: U | K7: K | L7: o | N7: o | P7: o
A8: # | D8: ブロック名 Block Name | E8: 型 Type | G8: super/share | H8: 対象ブロック名 Target Block Name | L8: TargetName | N8: TargetName | P8: TargetName | T8: ブロック備考 Block Remarks
A9: # | D9: 項目名 Field Name | E9: 型 Type | F9: 桁 Digits | G9: フルネーム Full Name | H9: 日本語名 Japanese Name | I9: 上り項目 Request Message Field | J9: 下り項目 Response Message Field | R9: 条件および編集方法 Conditions and Editing Methods | T9: 項目備考 Field Remarks
A10: # | L10: 上り項目 Request Message Field | M10: 下り項目 Response Message Field | N10: 上り項目 Request Message Field | O10: 下り項目 Response Message Field | P10: 上り項目 Request Message Field | Q10: 下り項目 Response Message Field
A11: 10 | B11: * | D11: Dtl | E11: L | G11: $share$ | H11: MG.MGBDL0640.CostItmCopy_Chk01.Dtl
A12: 10 | D12: calc_ctg_cd | E12: #MA.CALC_CTG_CD | G12: Calculation category cd. | H12: 計算カテゴリーＣＤ | I12: E | J12: E
A13: 10 | D13: term | E13: #MA.YM | G13: Term | H13: 期 | I13: E | J13: E
A14: 10 | D14: itm_cd | E14: #MA.ITM_CD | G14: Item cd. | H14: 品目ＣＤ | I14: E | J14: E
A15: 10 | D15: itm_sub1 | E15: #MA.ITM_SUB1 | G15: Branch No. 1 | H15: 枝番１ | I15: E | J15: E
A16: 10 | D16: itm_sub2 | E16: #MA.ITM_SUB2 | G16: Branch No. 2 | H16: 枝番２ | I16: E | J16: E
A17: 10 | D17: itm_sub3 | E17: #MA.ITM_SUB3 | G17: Branch No. 3 | H17: 枝番３ | I17: E | J17: E
A18: 10 | D18: itm_nm | E18: #MA.ITM_NM | G18: Item name | H18: 品名
A19: 10 | D19: base_itm_nm | E19: #MA.ITM_NM | G19: Standard Item name | H19: 標準品名
A20: 10 | D20: itm_typ | E20: #MA.ITM_TYP | G20: Item type | H20: 品目区分
A21: 10 | D21: itm_typ_nm | E21: #MA.ITM_TYP_NM | G21: Item type name | H21: 品目区分名
A22: 10 | D22: itm_typ_d_cd | E22: #MA.ITM_TYP_D_CD | G22: Item type details cd. | H22: 品目区分詳細ＣＤ
A23: 10 | D23: itm_typ_d_nm | E23: #MA.ITM_TYP_D_NM | G23: Item type details name | H23: 品目区分詳細名
A24: 10 | D24: itm_jnl_cd | E24: #MA.ITM_JNL_CD | G24: Item journal cd. | H24: 品目仕訳ＣＤ
A25: 10 | D25: itm_jnl_nm | E25: #MA.ITM_JNL_NM | G25: Item journal name | H25: 品目仕訳名
A26: 10 | D26: stk_mng_typ | E26: #MA.STK_MNG_TYP | G26: Inventory management type | H26: 在庫管理区分
A27: 10 | D27: asset_mng_typ | E27: #MA.ASSET_MNG_TYP | G27: Asset management type | H27: 資産管理区分
A28: 10 | D28: base_unit_cd | E28: #MA.UNIT_CD | G28: Base unit cd. | H28: 基準単位ＣＤ
A29: 10 | D29: dest_itm_cd | E29: #MA.ITM_CD | G29: (Copy-to) Item cd. | H29: （コピー先）品目ＣＤ
... A48: 10 | D48: copy_mam_itm_ | E48: #MA.FLG | G48: Item | H48: 品目
A49: 10 | D49: copy_mgt_itm | E49: #MA.FLG | G49: Cost item info. | H49: 原価品目情報 | I49: E | J49: E
A50: 10 | D50: copy_mgt_itm_dtl | E50: #MA.FLG | G50: Cost item details | H50: 原価品目詳細 | I50: E | J50: E
A51: 10 | D51: copy_mgt_itm_oper | E51: #MA.FLG | G51: Cost item operation | H51: 原価品目工程 | I51: E | J51: E
A52: 10 | D52: copy_mgt_bom | E52: #MA.FLG | G52: Cost BOM | H52: 原価ＢＯＭ | I52: E | J52: E
A53: 10 | D53: copy_mgt_itm_wk | E53: #MA.FLG | G53: Cost item man-hour | H53: 原価品目工数 | I53: E | J53: E
A54: 10 | D54: copy_mgt_itm_purc | E54: #MA.FLG | G54: Cost purchase unit price | H54: 原価購買単価 | I54: E | J54: E
A55: 10 | D55: copy_mgt_itm_proc | E55: #MA.FLG | G55: Cost subcontracting unit price | H55: 原価加工単価 | I55: E | J55: E
A56: 10 | D56: copy_mgt_itm_prov | E56: #MA.FLG | G56: Cost supply unit price | H56: 原価支給単価 | I56: E | J56: E
A57: 10 | D57: copy_mgt_itm_sls | E57: #MA.FLG | G57: Cost item sales unit price | H57: 原価品目販売単価 | I57: E | J57: E
A58: 10 | D58: copy_mgt_itm_fix | E58: #MA.FLG | G58: Cost item limit unit price | H58: 原価品目指値 | I58: E | J58: E
...

Sheet CostItmCopy_Ins01
A1: * | B1: * | D1: L | E1: 1
A2: * | D2: オペレーション実装仕様書 Operation Specification Implementation Sheet | E2: ModuleID : | F2: =IF(LogicCommon!C2="","",LogicCommon!C2) -> MG | G2: LogicID : | H2: =IF(LogicCommon!E2="","",LogicCommon!E2) -> MGBDL0640 | I2: Ope.ID : | J2: CostItmCopy_Ins01 | K2: Pj.ID : | L2: =IF(LogicCommon!G2="","",LogicCommon!G2) -> MC | M2: Ope.Body : | N2: "mcframe.serverMAUD.MAUDL5010.MAUDL_Operation"
A3: * | D3: =IF(LogicCommon!A3="","",LogicCommon!A3) | E3: SubModuleID : | F3: =IF(LogicCommon!C3="","",LogicCommon!C3) -> MGBD | G3: LogicClass : | H3: =IF(LogicCommon!E3="","",LogicCommon!E3) -> MGBDL_CostItmCopyReg | I3: Ope.Method : | J3: @ | K3: SuperClassPj.ID : | L3: =IF(LogicCommon!G3="","",LogicCommon!G3) | O3: Gene.Type : | P3: ALL
A4: * | E4: Version : | F4: 000000 | G4: LogicName : | H4: =IF(LogicCommon!E4="","",LogicCommon!E4) -> 原価品目系情報確認＆コピー | I4: Ope.Name : | J4: コピー | K4: SuperLogicID : | L4: =IF(LogicCommon!G4="","",LogicCommon!G4) -> MG.MGUDL5010 | M4: ImplOpe.ID:
A5: * | E5: ACType :
A6: * | D6: 概要 : | E6: コピー処理をする | M6: ID | O6: ID | Q6: ID | S6: ID | U6: ID | W6: ID | Y6: ID | AA6: ID | AC6: ID | AE6: ID
A7: # | I7: U | K7: K | L7: o | M7: PI.i1 | N7: o | O7: PI.i2 | P7: o | Q7: PI.i3 | R7: o | S7: PI.i4 | T7: o | U7: PI.i5 | V7: o | W7: PI.i6 | X7: o | Y7: PI.i7 | Z7: o | AA7: PI.i8 | AB7: o | AC7: PI.i9 | AD7: o | AE7: PI.i10
A8: # | D8: ブロック名 Block Name | E8: 型 Type | G8: super/share | H8: 対象ブロック名 Target Block Name | L8: TargetName | M8: DBC.MG.MGT_ITM | N8: TargetName | O8: DBC.MG.MGT_ITM_DTL | P8: TargetName | Q8: DBC.MG.MGT_ITM_OPER | R8: TargetName | S8: DBC.MG.MGT_BOM | T8: TargetName | U8: DBC.MG.MGT_ITM_WK | V8: TargetName | W8: DBC.MG.MGT_ITM_PURC | X8: TargetName | Y8: DBC.MG.MGT_ITM_PROC | Z8: TargetName | AA8: DBC.MG.MGT_ITM_PROV | AB8: TargetName | AC8: DBC.MG.MGT_ITM_SLS | AD8: TargetName | AE8: DBC.MG.MGT_ITM_FIX | AH8: ブロック備考 Block Remarks
A9: # | D9: 項目名 Field Name | E9: 型 Type | F9: 桁 Digits | G9: フルネーム Full Name | H9: 日本語名 Japanese Name | I9: 上り項目 Request Message Field | J9: 下り項目 Response Message Field | AF9: 条件および編集方法 Conditions and Editing Methods | AH9: 項目備考 Field Remarks
A10: # | L10: 上り項目 Request Message Field | M10: 下り項目 Response Message Field | N10: 上り項目 Request Message Field | O10: 下り項目 Response Message Field | P10: 上り項目 Request Message Field | Q10: 下り項目 Response Message Field | R10: 上り項目 Request Message Field | S10: 下り項目 Response Message Field | T10: 上り項目 Request Message Field | U10: 下り項目 Response Message Field | V10: 上り項目 Request Message Field | W10: 下り項目 Response Message Field | X10: 上り項目 Request Message Field | Y10: 下り項目 Response Message Field | Z10: 上り項目 Request Message Field | AA10: 下り項目 Response Message Field | AB10: 上り項目 Request Message Field | AC10: 下り項目 Response Message Field | AD10: 上り項目 Request Message Field | AE10: 下り項目 Response Message Field
A11: 10 | B11: * | D11: Dtl | E11: L | G11: $share$ | H11: MG.MGBDL0640.CostItmCopy_Chk01.Dtl
A12: 10 | D12: calc_ctg_cd | E12: #MA.CALC_CTG_CD | G12: Calculation category cd. | H12: 計算カテゴリーＣＤ | I12: E
A13: 10 | D13: term | E13: #MA.YM | G13: Term | H13: 期 | I13: E
A14: 10 | D14: itm_cd | E14: #MA.ITM_CD | G14: Item cd. | H14: 品目ＣＤ | I14: E
A15: 10 | D15: itm_sub1 | E15: #MA.ITM_SUB1 | G15: Branch No. 1 | H15: 枝番１ | I15: E
A16: 10 | D16: itm_sub2 | E16: #MA.ITM_SUB2 | G16: Branch No. 2 | H16: 枝番２ | I16: E
A17: 10 | D17: itm_sub3 | E17: #MA.ITM_SUB3 | G17: Branch No. 3 | H17: 枝番３ | I17: E
A18: 10 | D18: itm_nm | E18: #MA.ITM_NM | G18: Item name | H18: 品名
A19: 10 | D19: base_itm_nm | E19: #MA.ITM_NM | G19: Standard Item name | H19: 標準品名
A20: 10 | D20: itm_typ | E20: #MA.ITM_TYP | G20: Item type | H20: 品目区分
A21: 10 | D21: itm_typ_nm | E21: #MA.ITM_TYP_NM | G21: Item type name | H21: 品目区分名
A22: 10 | D22: itm_typ_d_cd | E22: #MA.ITM_TYP_D_CD | G22: Item type details cd. | H22: 品目区分詳細ＣＤ
A23: 10 | D23: itm_typ_d_nm | E23: #MA.ITM_TYP_D_NM | G23: Item type details name | H23: 品目区分詳細名
A24: 10 | D24: itm_jnl_cd | E24: #MA.ITM_JNL_CD | G24: Item journal cd. | H24: 品目仕訳ＣＤ
A25: 10 | D25: itm_jnl_nm | E25: #MA.ITM_JNL_NM | G25: Item journal name | H25: 品目仕訳名
A26: 10 | D26: stk_mng_typ | E26: #MA.STK_MNG_TYP | G26: Inventory management type | H26: 在庫管理区分
A27: 10 | D27: asset_mng_typ | E27: #MA.ASSET_MNG_TYP | G27: Asset management type | H27: 資産管理区分
A28: 10 | D28: base_unit_cd | E28: #MA.UNIT_CD | G28: Base unit cd. | H28: 基準単位ＣＤ | J28: E
A29: 10 | D29: dest_itm_cd | E29: #MA.ITM_CD | G29: (Copy-to) Item cd. | H29: （コピー先）品目ＣＤ | I29: E
A30: 10 | D30: dest_itm_sub1 | E30: #MA.ITM_SUB1 | G30: (Copy-to) Branch No. 1 | H30: （コピー先）枝番１ | I30: E
A31: 10 | D31: dest_itm_sub2 | E31: #MA.ITM_SUB2 | G31: (Copy-to) Branch No. 2 | H31: （コピー先）枝番２ | I31: E
A32: 10 | D32: dest_itm_sub3 | E32: #MA.ITM_SUB3 | G32: (Copy-to) Branch No. 3 | H32: （コピー先）枝番３ | I32: E
A33: 10 | D33: dest_itm_nm | E33: #MA.ITM_NM | G33: (Copy-to) Item name | H33: （コピー先）品名
A34: 10 | D34: dest_stk_mng_typ | E34: #MA.STK_MNG_TYP | G34: (Copy-to) Inventory management type | H34: （コピー先）在庫管理区分
A35: 10 | D35: dest_asset_mng_typ | E35: #MA.ASSET_MNG_TYP | G35: (Copy-to) Asset management type | H35: （コピー先）資産管理区分
A36: 10 | D36: dest_base_unit_cd | E36: #MA.UNIT_CD | G36: (Copy-to) Base unit cd. | H36: （コピー先）基準単位ＣＤ | J36: E
A37: 10 | D37: mam_itm_ | E37: #MA.INT | G37: Item | H37: 品目
A38: 10 | D38: mgt_itm | E38: #MA.INT | G38: Cost item info. | H38: 原価品目情報
A39: 10 | D39: mgt_itm_dtl | E39: #MA.INT | G39: Cost item details | H39: 原価品目詳細
A40: 10 | D40: mgt_itm_oper | E40: #MA.INT | G40: Cost item operation | H40: 原価品目工程
...

Sheet CostItmCopy_Del01
A1: * | B1: * | D1: L | E1: 1
A2: * | D2: オペレーション実装仕様書 Operation Specification Implementation Sheet | E2: ModuleID : | F2: =IF(LogicCommon!C2="","",LogicCommon!C2) -> MG | G2: LogicID : | H2: =IF(LogicCommon!E2="","",LogicCommon!E2) -> MGBDL0640 | I2: Ope.ID : | J2: CostItmCopy_Del01 | K2: Pj.ID : | L2: =IF(LogicCommon!G2="","",LogicCommon!G2) -> MC | M2: Ope.Body : | N2: "mcframe.serverMAUD.MAUDL5010.MAUDL_Operation"
A3: * | D3: =IF(LogicCommon!A3="","",LogicCommon!A3) | E3: SubModuleID : | F3: =IF(LogicCommon!C3="","",LogicCommon!C3) -> MGBD | G3: LogicClass : | H3: =IF(LogicCommon!E3="","",LogicCommon!E3) -> MGBDL_CostItmCopyReg | I3: Ope.Method : | J3: @ | K3: SuperClassPj.ID : | L3: =IF(LogicCommon!G3="","",LogicCommon!G3) | O3: Gene.Type : | P3: ALL
A4: * | E4: Version : | F4: 000000 | G4: LogicName : | H4: =IF(LogicCommon!E4="","",LogicCommon!E4) -> 原価品目系情報確認＆コピー | I4: Ope.Name : | J4: 削除 | K4: SuperLogicID : | L4: =IF(LogicCommon!G4="","",LogicCommon!G4) -> MG.MGUDL5010 | M4: ImplOpe.ID:
A5: * | E5: ACType :
A6: * | D6: 概要 : | E6: 削除処理をする | M6: ID | O6: ID | Q6: ID | S6: ID | U6: ID | W6: ID | Y6: ID | AA6: ID | AC6: ID | AE6: ID
A7: # | I7: U | K7: K | L7: o | M7: PI.i1 | N7: o | O7: PI.i2 | P7: o | Q7: PI.i3 | R7: o | S7: PI.i4 | T7: o | U7: PI.i5 | V7: o | W7: PI.i6 | X7: o | Y7: PI.i7 | Z7: o | AA7: PI.i8 | AB7: o | AC7: PI.i9 | AD7: o | AE7: PI.i10
A8: # | D8: ブロック名 Block Name | E8: 型 Type | G8: super/share | H8: 対象ブロック名 Target Block Name | L8: TargetName | M8: DBC.MG.MGT_ITM | N8: TargetName | O8: DBC.MG.MGT_ITM_DTL | P8: TargetName | Q8: DBC.MG.MGT_ITM_OPER | R8: TargetName | S8: DBC.MG.MGT_BOM | T8: TargetName | U8: DBC.MG.MGT_ITM_WK | V8: TargetName | W8: DBC.MG.MGT_ITM_PURC | X8: TargetName | Y8: DBC.MG.MGT_ITM_PROC | Z8: TargetName | AA8: DBC.MG.MGT_ITM_PROV | AB8: TargetName | AC8: DBC.MG.MGT_ITM_SLS | AD8: TargetName | AE8: DBC.MG.MGT_ITM_FIX | AH8: ブロック備考 Block Remarks
A9: # | D9: 項目名 Field Name | E9: 型 Type | F9: 桁 Digits | G9: フルネーム Full Name | H9: 日本語名 Japanese Name | I9: 上り項目 Request Message Field | J9: 下り項目 Response Message Field | AF9: 条件および編集方法 Conditions and Editing Methods | AH9: 項目備考 Field Remarks
A10: # | R10: 上り項目 Request Message Field | S10: 下り項目 Response Message Field | T10: 上り項目 Request Message Field | U10: 下り項目 Response Message Field | V10: 上り項目 Request Message Field | W10: 下り項目 Response Message Field | X10: 上り項目 Request Message Field | Y10: 下り項目 Response Message Field | Z10: 上り項目 Request Message Field | AA10: 下り項目 Response Message Field | AB10: 上り項目 Request Message Field | AC10: 下り項目 Response Message Field | AD10: 上り項目 Request Message Field | AE10: 下り項目 Response Message Field
A11: 10 | B11: * | D11: Dtl | E11: L | G11: $share$ | H11: MG.MGBDL0640.CostItmCopy_Chk02.Dtl
A12: 10 | D12: calc_ctg_cd | E12: #MA.CALC_CTG_CD | G12: Calculation category cd. | H12: 計算カテゴリーＣＤ | I12: E
A13: 10 | D13: term | E13: #MA.YM | G13: Term | H13: 期 | I13: E
A14: 10 | D14: itm_cd | E14: #MA.ITM_CD | G14: Item cd. | H14: 品目ＣＤ | I14: E
A15: 10 | D15: itm_sub1 | E15: #MA.ITM_SUB1 | G15: Branch No. 1 | H15: 枝番１ | I15: E
A16: 10 | D16: itm_sub2 | E16: #MA.ITM_SUB2 | G16: Branch No. 2 | H16: 枝番２ | I16: E
A17: 10 | D17: itm_sub3 | E17: #MA.ITM_SUB3 | G17: Branch No. 3 | H17: 枝番３ | I17: E
A18: 10 | D18: itm_nm | E18: #MA.ITM_NM | G18: Item name | H18: 品名
A19: 10 | D19: base_itm_nm | E19: #MA.ITM_NM | G19: Standard Item name | H19: 標準品名
A20: 10 | D20: itm_typ | E20: #MA.ITM_TYP | G20: Item type | H20: 品目区分
A21: 10 | D21: itm_typ_nm | E21: #MA.ITM_TYP_NM | G21: Item type name | H21: 品目区分名
A22: 10 | D22: itm_typ_d_cd | E22: #MA.ITM_TYP_D_CD | G22: Item type details cd. | H22: 品目区分詳細ＣＤ
A23: 10 | D23: itm_typ_d_nm | E23: #MA.ITM_TYP_D_NM | G23: Item type details name | H23: 品目区分詳細名
A24: 10 | D24: itm_jnl_cd | E24: #MA.ITM_JNL_CD | G24: Item journal cd. | H24: 品目仕訳ＣＤ
A25: 10 | D25: itm_jnl_nm | E25: #MA.ITM_JNL_NM | G25: Item journal name | H25: 品目仕訳名
A26: 10 | D26: stk_mng_typ | E26: #MA.STK_MNG_TYP | G26: Inventory management type | H26: 在庫管理区分
A27: 10 | D27: asset_mng_typ | E27: #MA.ASSET_MNG_TYP | G27: Asset management type | H27: 資産管理区分
A28: 10 | D28: base_unit_cd | E28: #MA.UNIT_CD | G28: Base unit cd. | H28: 基準単位ＣＤ | J28: E
A29: 10 | D29: dest_itm_cd | E29: #MA.ITM_CD | G29: (Copy-to) Item cd. | H29: （コピー先）品目ＣＤ
A30: 10 | D30: dest_itm_sub1 | E30: #MA.ITM_SUB1 | G30: (Copy-to) Branch No. 1 | H30: （コピー先）枝番１
A31: 10 | D31: dest_itm_sub2 | E31: #MA.ITM_SUB2 | G31: (Copy-to) Branch No. 2 | H31: （コピー先）枝番２
A32: 10 | D32: dest_itm_sub3 | E32: #MA.ITM_SUB3 | G32: (Copy-to) Branch No. 3 | H32: （コピー先）枝番３
A33: 10 | D33: dest_itm_nm | E33: #MA.ITM_NM | G33: (Copy-to) Item name | H33: （コピー先）品名
A34: 10 | D34: dest_stk_mng_typ | E34: #MA.STK_MNG_TYP | G34: (Copy-to) Inventory management type | H34: （コピー先）在庫管理区分
A35: 10 | D35: dest_asset_mng_typ | E35: #MA.ASSET_MNG_TYP | G35: (Copy-to) Asset management type | H35: （コピー先）資産管理区分
A36: 10 | D36: dest_base_unit_cd | E36: #MA.UNIT_CD | G36: (Copy-to) Base unit cd. | H36: （コピー先）基準単位ＣＤ | J36: E
A37: 10 | D37: mam_itm_ | E37: #MA.INT | G37: Item | H37: 品目
A38: 10 | D38: mgt_itm | E38: #MA.INT | G38: Cost item info. | H38: 原価品目情報
A39: 10 | D39: mgt_itm_dtl | E39: #MA.INT | G39: Cost item details | H39: 原価品目詳細
A40: 10 | D40: mgt_itm_oper | E40: #MA.INT | G40: Cost item operation | H40: 原価品目工程
...

Sheet Ins01
A1: * | B1: * | D1: L | E1: 1
A2: * | D2: オペレーション実装仕様書 Operation Specification Implementation Sheet | E2: ModuleID : | F2: =IF(LogicCommon!C2="","",LogicCommon!C2) -> MG | G2: LogicID : | H2: =IF(LogicCommon!E2="","",LogicCommon!E2) -> MGBDL0640 | I2: Ope.ID : | J2: Ins01 | K2: Pj.ID : | L2: =IF(LogicCommon!G2="","",LogicCommon!G2) -> MC | M2: Ope.Body : | N2: "mcframe.serverMAUD.MAUDL5010.MAUDL_Operation"
A3: * | D3: =IF(LogicCommon!A3="","",LogicCommon!A3) | E3: SubModuleID : | F3: =IF(LogicCommon!C3="","",LogicCommon!C3) -> MGBD | G3: LogicClass : | H3: =IF(LogicCommon!E3="","",LogicCommon!E3) -> MGBDL_CostItmCopyReg | I3: Ope.Method : | J3: @ | K3: SuperClassPj.ID : | L3: =IF(LogicCommon!G3="","",LogicCommon!G3) | O3: Gene.Type : | P3: ALL
A4: * | E4: Version : | F4: 000000 | G4: LogicName : | H4: =IF(LogicCommon!E4="","",LogicCommon!E4) -> 原価品目系情報確認＆コピー | I4: Ope.Name : | J4: コピー | K4: SuperLogicID : | L4: =IF(LogicCommon!G4="","",LogicCommon!G4) -> MG.MGUDL5010 | M4: ImplOpe.ID:
A5: * | E5: ACType :
A6: * | D6: 概要 : | E6: コピー処理をする(画面用) | M6: ID | O6: ID | Q6: ID | S6: ID | U6: ID | W6: ID | Y6: ID | AA6: ID | AC6: ID | AE6: ID | AG6: ID
A7: # | I7: U | K7: K | L7: o | N7: o | P7: o | R7: o | T7: o | V7: o | X7: o | Z7: o | AB7: o | AD7: o | AF7: o
A8: # | D8: ブロック名 Block Name | E8: 型 Type | G8: super/share | H8: 対象ブロック名 Target Block Name | L8: TargetName | N8: TargetName | P8: TargetName | R8: TargetName | T8: TargetName | V8: TargetName | X8: TargetName | Z8: TargetName | AB8: TargetName | AD8: TargetName | AF8: TargetName | AJ8: ブロック備考 Block Remarks
A9: # | D9: 項目名 Field Name | E9: 型 Type | F9: 桁 Digits | G9: フルネーム Full Name | H9: 日本語名 Japanese Name | I9: 上り項目 Request Message Field | J9: 下り項目 Response Message Field | AH9: 条件および編集方法 Conditions and Editing Methods | AJ9: 項目備考 Field Remarks
A10: # | L10: 上り項目 Request Message Field | M10: 下り項目 Response Message Field | N10: 上り項目 Request Message Field | O10: 下り項目 Response Message Field | P10: 上り項目 Request Message Field | Q10: 下り項目 Response Message Field | R10: 上り項目 Request Message Field | S10: 下り項目 Response Message Field | T10: 上り項目 Request Message Field | U10: 下り項目 Response Message Field | V10: 上り項目 Request Message Field | W10: 下り項目 Response Message Field | X10: 上り項目 Request Message Field | Y10: 下り項目 Response Message Field | Z10: 上り項目 Request Message Field | AA10: 下り項目 Response Message Field | AB10: 上り項目 Request Message Field | AC10: 下り項目 Response Message Field | AD10: 上り項目 Request Message Field | AE10: 下り項目 Response Message Field | AF10: 上り項目 Request Message Field | AG10: 下り項目 Response Message Field
A11: 10 | B11: * | D11: Dtl | E11: L | G11: $share$ | H11: MG.MGBDL0640.CostItmCopy_Ins01.Dtl
A12: 10 | D12: calc_ctg_cd | E12: #MA.CALC_CTG_CD | G12: Calculation category cd. | H12: 計算カテゴリーＣＤ | I12: E
A13: 10 | D13: term | E13: #MA.YM | G13: Term | H13: 期 | I13: E
A14: 10 | D14: itm_cd | E14: #MA.ITM_CD | G14: Item cd. | H14: 品目ＣＤ | I14: E
A15: 10 | D15: itm_sub1 | E15: #MA.ITM_SUB1 | G15: Branch No. 1 | H15: 枝番１ | I15: E
A16: 10 | D16: itm_sub2 | E16: #MA.ITM_SUB2 | G16: Branch No. 2 | H16: 枝番２ | I16: E
A17: 10 | D17: itm_sub3 | E17: #MA.ITM_SUB3 | G17: Branch No. 3 | H17: 枝番３ | I17: E
A18: 10 | D18: itm_nm | E18: #MA.ITM_NM | G18: Item name | H18: 品名
A19: 10 | D19: base_itm_nm | E19: #MA.ITM_NM | G19: Standard Item name | H19: 標準品名
A20: 10 | D20: itm_typ | E20: #MA.ITM_TYP | G20: Item type | H20: 品目区分
A21: 10 | D21: itm_typ_nm | E21: #MA.ITM_TYP_NM | G21: Item type name | H21: 品目区分名
A22: 10 | D22: itm_typ_d_cd | E22: #MA.ITM_TYP_D_CD | G22: Item type details cd. | H22: 品目区分詳細ＣＤ
A23: 10 | D23: itm_typ_d_nm | E23: #MA.ITM_TYP_D_NM | G23: Item type details name | H23: 品目区分詳細名
A24: 10 | D24: itm_jnl_cd | E24: #MA.ITM_JNL_CD | G24: Item journal cd. | H24: 品目仕訳ＣＤ
A25: 10 | D25: itm_jnl_nm | E25: #MA.ITM_JNL_NM | G25: Item journal name | H25: 品目仕訳名
A26: 10 | D26: stk_mng_typ | E26: #MA.STK_MNG_TYP | G26: Inventory management type | H26: 在庫管理区分
A27: 10 | D27: asset_mng_typ | E27: #MA.ASSET_MNG_TYP | G27: Asset management type | H27: 資産管理区分
A28: 10 | D28: base_unit_cd | E28: #MA.UNIT_CD | G28: Base unit cd. | H28: 基準単位ＣＤ
A29: 10 | D29: dest_itm_cd | E29: #MA.ITM_CD | G29: (Copy-to) Item cd. | H29: （コピー先）品目ＣＤ | I29: E
A30: 10 | D30: dest_itm_sub1 | E30: #MA.ITM_SUB1 | G30: (Copy-to) Branch No. 1 | H30: （コピー先）枝番１ | I30: E
A31: 10 | D31: dest_itm_sub2 | E31: #MA.ITM_SUB2 | G31: (Copy-to) Branch No. 2 | H31: （コピー先）枝番２ | I31: E
A32: 10 | D32: dest_itm_sub3 | E32: #MA.ITM_SUB3 | G32: (Copy-to) Branch No. 3 | H32: （コピー先）枝番３ | I32: E
A33: 10 | D33: dest_itm_nm | E33: #MA.ITM_NM | G33: (Copy-to) Item name | H33: （コピー先）品名
A34: 10 | D34: dest_stk_mng_typ | E34: #MA.STK_MNG_TYP | G34: (Copy-to) Inventory management type | H34: （コピー先）在庫管理区分
A35: 10 | D35: dest_asset_mng_typ | E35: #MA.ASSET_MNG_TYP | G35: (Copy-to) Asset management type | H35: （コピー先）資産管理区分
A36: 10 | D36: dest_base_unit_cd | E36: #MA.UNIT_CD | G36: (Copy-to) Base unit cd. | H36: （コピー先）基準単位ＣＤ
A37: 10 | D37: mam_itm_ | E37: #MA.INT | G37: Item | H37: 品目
A38: 10 | D38: mgt_itm | E38: #MA.INT | G38: Cost item info. | H38: 原価品目情報
A39: 10 | D39: mgt_itm_dtl | E39: #MA.INT | G39: Cost item details | H39: 原価品目詳細
A40: 10 | D40: mgt_itm_oper | E40: #MA.INT | G40: Cost item operation | H40: 原価品目工程
...

Sheet Del01
A1: * | B1: * | D1: L | E1: 1
A2: * | D2: オペレーション実装仕様書 Operation Specification Implementation Sheet | E2: ModuleID : | F2: =IF(LogicCommon!C2="","",LogicCommon!C2) -> MG | G2: LogicID : | H2: =IF(LogicCommon!E2="","",LogicCommon!E2) -> MGBDL0640 | I2: Ope.ID : | J2: Del01 | K2: Pj.ID : | L2: =IF(LogicCommon!G2="","",LogicCommon!G2) -> MC | M2: Ope.Body : | N2: "mcframe.serverMAUD.MAUDL5010.MAUDL_Operation"
A3: * | D3: =IF(LogicCommon!A3="","",LogicCommon!A3) | E3: SubModuleID : | F3: =IF(LogicCommon!C3="","",LogicCommon!C3) -> MGBD | G3: LogicClass : | H3: =IF(LogicCommon!E3="","",LogicCommon!E3) -> MGBDL_CostItmCopyReg | I3: Ope.Method : | J3: @ | K3: SuperClassPj.ID : | L3: =IF(LogicCommon!G3="","",LogicCommon!G3) | O3: Gene.Type : | P3: ALL
A4: * | E4: Version : | F4: 000000 | G4: LogicName : | H4: =IF(LogicCommon!E4="","",LogicCommon!E4) -> 原価品目系情報確認＆コピー | I4: Ope.Name : | J4: 削除 | K4: SuperLogicID : | L4: =IF(LogicCommon!G4="","",LogicCommon!G4) -> MG.MGUDL5010 | M4: ImplOpe.ID:
A5: * | E5: ACType :
A6: * | D6: 概要 : | E6: 削除処理をする(画面用) | M6: ID | O6: ID | Q6: ID | S6: ID | U6: ID | W6: ID | Y6: ID | AA6: ID
A7: # | I7: U | K7: K | L7: o | N7: o | P7: o | R7: o | T7: o | V7: o | X7: o | Z7: o
A8: # | D8: ブロック名 Block Name | E8: 型 Type | G8: super/share | H8: 対象ブロック名 Target Block Name | L8: TargetName | N8: TargetName | P8: TargetName | R8: TargetName | T8: TargetName | V8: TargetName | X8: TargetName | Z8: TargetName | AD8: ブロック備考 Block Remarks
A9: # | D9: 項目名 Field Name | E9: 型 Type | F9: 桁 Digits | G9: フルネーム Full Name | H9: 日本語名 Japanese Name | I9: 上り項目 Request Message Field | J9: 下り項目 Response Message Field | AB9: 条件および編集方法 Conditions and Editing Methods | AD9: 項目備考 Field Remarks
A10: # | L10: 上り項目 Request Message Field | M10: 下り項目 Response Message Field | N10: 上り項目 Request Message Field | O10: 下り項目 Response Message Field | P10: 上り項目 Request Message Field | Q10: 下り項目 Response Message Field | R10: 上り項目 Request Message Field | S10: 下り項目 Response Message Field | T10: 上り項目 Request Message Field | U10: 下り項目 Response Message Field | V10: 上り項目 Request Message Field | W10: 下り項目 Response Message Field | X10: 上り項目 Request Message Field | Y10: 下り項目 Response Message Field | Z10: 上り項目 Request Message Field | AA10: 下り項目 Response Message Field
A11: 10 | B11: * | D11: Dtl | E11: L | G11: $share$ | H11: MG.MGBDL0640.CostItmCopy_Del01.Dtl
A12: 10 | D12: calc_ctg_cd | E12: #MA.CALC_CTG_CD | G12: Calculation category cd. | H12: 計算カテゴリーＣＤ | I12: E
A13: 10 | D13: term | E13: #MA.YM | G13: Term | H13: 期 | I13: E
A14: 10 | D14: itm_cd | E14: #MA.ITM_CD | G14: Item cd. | H14: 品目ＣＤ | I14: E
A15: 10 | D15: itm_sub1 | E15: #MA.ITM_SUB1 | G15: Branch No. 1 | H15: 枝番１ | I15: E
A16: 10 | D16: itm_sub2 | E16: #MA.ITM_SUB2 | G16: Branch No. 2 | H16: 枝番２ | I16: E
A17: 10 | D17: itm_sub3 | E17: #MA.ITM_SUB3 | G17: Branch No. 3 | H17: 枝番３ | I17: E
A18: 10 | D18: itm_nm | E18: #MA.ITM_NM | G18: Item name | H18: 品名
A19: 10 | D19: base_itm_nm | E19: #MA.ITM_NM | G19: Standard Item name | H19: 標準品名
A20: 10 | D20: itm_typ | E20: #MA.ITM_TYP | G20: Item type | H20: 品目区分
A21: 10 | D21: itm_typ_nm | E21: #MA.ITM_TYP_NM | G21: Item type name | H21: 品目区分名
A22: 10 | D22: itm_typ_d_cd | E22: #MA.ITM_TYP_D_CD | G22: Item type details cd. | H22: 品目区分詳細ＣＤ
A23: 10 | D23: itm_typ_d_nm | E23: #MA.ITM_TYP_D_NM | G23: Item type details name | H23: 品目区分詳細名
A24: 10 | D24: itm_jnl_cd | E24: #MA.ITM_JNL_CD | G24: Item journal cd. | H24: 品目仕訳ＣＤ
A25: 10 | D25: itm_jnl_nm | E25: #MA.ITM_JNL_NM | G25: Item journal name | H25: 品目仕訳名
A26: 10 | D26: stk_mng_typ | E26: #MA.STK_MNG_TYP | G26: Inventory management type | H26: 在庫管理区分
A27: 10 | D27: asset_mng_typ | E27: #MA.ASSET_MNG_TYP | G27: Asset management type | H27: 資産管理区分
A28: 10 | D28: base_unit_cd | E28: #MA.UNIT_CD | G28: Base unit cd. | H28: 基準単位ＣＤ
A29: 10 | D29: dest_itm_cd | E29: #MA.ITM_CD | G29: (Copy-to) Item cd. | H29: （コピー先）品目ＣＤ
... A58: 10 | D58: copy_mgt_itm_fix | E58: #MA.FLG | G58: Cost item limit unit price | H58: 原価品目指値
A59: 10 | D59: rtn_sts_typ | E59: #MA.RTN_STS_TYP | G59: Process result status type | H59: 処理結果状況区分 | J59: E
A60: 10 | D60: err_flg | E60: #MA.FLG | G60: Error | H60: エラー
D61: 詳細 :

Sheet Srch01
A1: * | B1: * | D1: L | E1: 1
A2: * | D2: オペレーション実装仕様書 Operation Specification Implementation Sheet | E2: ModuleID : | F2: =IF(LogicCommon!C2="","",LogicCommon!C2) -> MG | G2: LogicID : | H2: =IF(LogicCommon!E2="","",LogicCommon!E2) -> MGBDL0640 | I2: Ope.ID : | J2: Srch01 | K2: Pj.ID : | L2: =IF(LogicCommon!G2="","",LogicCommon!G2) -> MC | M2: Ope.Body : | N2: "mcframe.serverMAUD.MAUDL5010.MAUDL_Searcher"
A3: * | D3: =IF(LogicCommon!A3="","",LogicCommon!A3) | E3: SubModuleID : | F3: =IF(LogicCommon!C3="","",LogicCommon!C3) -> MGBD | G3: LogicClass : | H3: =IF(LogicCommon!E3="","",LogicCommon!E3) -> MGBDL_CostItmCopyReg | I3: Ope.Method : | J3: @ | K3: SuperClassPj.ID : | L3: =IF(LogicCommon!G3="","",LogicCommon!G3) | O3: Gene.Type : | P3: ALL
A4: * | E4: Version : | F4: 000000 | G4: LogicName : | H4: =IF(LogicCommon!E4="","",LogicCommon!E4) -> 原価品目系情報確認＆コピー | I4: Ope.Name : | J4: 検索 | K4: SuperLogicID : | L4: =IF(LogicCommon!G4="","",LogicCommon!G4) -> MG.MGUDL5010 | M4: ImplOpe.ID:
A5: * | E5: ACType :
A6: * | D6: 概要 : | E6: 検索処理をする | M6: ID | O6: ID | Q6: ID | S6: ID | U6: ID | W6: ID | Y6: ID | AA6: ID | AC6: ID | AE6: ID
A7: # | I7: U | K7: K | L7: o | M7: PI.i1 | N7: o | O7: PI.i2 | P7: o | Q7: PI.i3 | R7: o | S7: PI.i4 | T7: o | U7: PI.i5 | V7: o | W7: PI.i6 | X7: o | Y7: PI.i7 | Z7: o | AA7: PI.i8 | AB7: o | AC7: PI.i9 | AD7: o | AE7: PI.i10
A8: # | D8: ブロック名 Block Name | E8: 型 Type | G8: super/share | H8: 対象ブロック名 Target Block Name | L8: TargetName | M8: DBC.MG.MGT_ITM | N8: TargetName | O8: DBC.MG.MGT_ITM_DTL | P8: TargetName | Q8: DBC.MG.MGT_ITM_OPER | R8: TargetName | S8: DBC.MG.MGT_BOM | T8: TargetName | U8: DBC.MG.MGT_ITM_WK | V8: TargetName | W8: DBC.MG.MGT_ITM_PURC | X8: TargetName | Y8: DBC.MG.MGT_ITM_PROC | Z8: TargetName | AA8: DBC.MG.MGT_ITM_PROV | AB8: TargetName | AC8: DBC.MG.MGT_ITM_SLS | AD8: TargetName | AE8: DBC.MG.MGT_ITM_FIX | AH8: ブロック備考 Block Remarks
A9: # | D9: 項目名 Field Name | E9: 型 Type | F9: 桁 Digits | G9: フルネーム Full Name | H9: 日本語名 Japanese Name | I9: 上り項目 Request Message Field | J9: 下り項目 Response Message Field | AF9: 条件および編集方法 Conditions and Editing Methods | AH9: 項目備考 Field Remarks
A10: # | L10: 上り項目 Request Message Field | M10: 下り項目 Response Message Field | N10: 上り項目 Request Message Field | O10: 下り項目 Response Message Field | P10: 上り項目 Request Message Field | Q10: 下り項目 Response Message Field | R10: 上り項目 Request Message Field | S10: 下り項目 Response Message Field | T10: 上り項目 Request Message Field | U10: 下り項目 Response Message Field | V10: 上り項目 Request Message Field | W10: 下り項目 Response Message Field | X10: 上り項目 Request Message Field | Y10: 下り項目 Response Message Field | Z10: 上り項目 Request Message Field | AA10: 下り項目 Response Message Field | AB10: 上り項目 Request Message Field | AC10: 下り項目 Response Message Field | AD10: 上り項目 Request Message Field | AE10: 下り項目 Response Message Field
A11: 10 | B11: * | D11: Cnd | E11: R
A12: 10 | D12: calc_ctg_cd | E12: #MA.CALC_CTG_CD | G12: Calculation category cd. | H12: 計算カテゴリＣＤ | I12: E
A13: 10 | D13: term | E13: #MA.YM | G13: Term | H13: 期 | I13: E
A14: 10 | D14: itm_cd | E14: #MA.ITM_CD | G14: Item cd. | H14: 品目ＣＤ | I14: E
A15: 10 | D15: itm_sub1 | E15: #MA.ITM_SUB1 | G15: Branch No. 1 | H15: 枝番１ | I15: E
A16: 10 | D16: itm_sub2 | E16: #MA.ITM_SUB2 | G16: Branch No. 2 | H16: 枝番２ | I16: E
A17: 10 | D17: itm_sub3 | E17: #MA.ITM_SUB3 | G17: Branch No. 3 | H17: 枝番３ | I17: E
A18: 10 | D18: itm_nm | E18: #MA.ITM_NM | G18: Item name | H18: 品名 | I18: E
A19: 10 | D19: del_flg_on | E19: #MA.FLG | G19: Logical delete. On | H19: 論理削除.オン | I19: E
A20: 10 | D20: del_flg_off | E20: #MA.FLG | G20: Logical delete. Off | H20: 論理削除.オフ | I20: E
A21: 10 | D21: release_flg_on | E21: #MA.FLG | G21: Release. On | H21: リリース.オン | I21: E
A22: 10 | D22: release_flg_off | E22: #MA.FLG | G22: Release. Off | H22: リリース.オフ | I22: E
A23: 10 | D23: itm_typ | E23: #MA.ITM_TYP | G23: Item type | H23: 品目区分 | I23: E
... A47: 10 | D47: itm_jnl_nm | E47: #MA.ITM_JNL_NM | G47: Item journal name | H47: 品目仕訳名 | I47: E
A49: 20 | B49: * | D49: Dtl | E49: L | G49: $share$ | H49: MG.MGBDL0640.CostItmCopy_Chk01.Dtl
A50: 20 | D50: calc_ctg_cd | E50: #MA.CALC_CTG_CD | G50: Calculation category cd. | H50: 計算カテゴリーＣＤ | J50: E
A51: 20 | D51: term | E51: #MA.YM | G51: Term | H51: 期 | J51: E
A52: 20 | D52: itm_cd | E52: #MA.ITM_CD | G52: Item cd. | H52: 品目ＣＤ | J52: E
A53: 20 | D53: itm_sub1 | E53: #MA.ITM_SUB1 | G53: Branch No. 1 | H53: 枝番１ | J53: E
A54: 20 | D54: itm_sub2 | E54: #MA.ITM_SUB2 | G54: Branch No. 2 | H54: 枝番２ | J54: E
A55: 20 | D55: itm_sub3 | E55: #MA.ITM_SUB3 | G55: Branch No. 3 | H55: 枝番３ | J55: E
A56: 20 | D56: itm_nm | E56: #MA.ITM_NM | G56: Item name | H56: 品名 | J56: E
A57: 20 | D57: base_itm_nm | E57: #MA.ITM_NM | G57: Standard Item name | H57: 標準品名 | J57: E
A58: 20 | D58: itm_typ | E58: #MA.ITM_TYP | G58: Item type | H58: 品目区分 | J58: E
A59: 20 | D59: itm_typ_nm | E59: #MA.ITM_TYP_NM | G59: Item type name | H59: 品目区分名 | J59: E
A60: 20 | D60: itm_typ_d_cd | E60: #MA.ITM_TYP_D_CD | G60: Item type details cd. | H60: 品目区分詳細ＣＤ | J60: E
A61: 20 | D61: itm_typ_d_nm | E61: #MA.ITM_TYP_D_NM | G61: Item type details name | H61: 品目区分詳細名 | J61: E
... A63: 20 | D63: itm_jnl_nm | E63: #MA.ITM_JNL_NM | G63: Item journal name | H63: 品目仕訳名 | J63: E
A64: 20 | D64: stk_mng_typ | E64: #MA.STK_MNG_TYP | G64: Inventory management type | H64: 在庫管理区分
A65: 20 | D65: asset_mng_typ | E65: #MA.ASSET_MNG_TYP | G65: Asset management type | H65: 資産管理区分
...

Sheet Srch02
A1: * | B1: * | D1: L | E1: 1
A2: * | D2: オペレーション実装仕様書 Operation Specification Implementation Sheet | E2: ModuleID : | F2: =IF(LogicCommon!C2="","",LogicCommon!C2) -> MG | G2: LogicID : | H2: =IF(LogicCommon!E2="","",LogicCommon!E2) -> MGBDL0640 | I2: Ope.ID : | J2: Srch02 | K2: Pj.ID : | L2: =IF(LogicCommon!G2="","",LogicCommon!G2) -> MC | M2: Ope.Body : | N2: "mcframe.serverMAUD.MAUDL5010.MAUDL_Searcher"
A3: * | D3: =IF(LogicCommon!A3="","",LogicCommon!A3) | E3: SubModuleID : | F3: =IF(LogicCommon!C3="","",LogicCommon!C3) -> MGBD | G3: LogicClass : | H3: =IF(LogicCommon!E3="","",LogicCommon!E3) -> MGBDL_CostItmCopyReg | I3: Ope.Method : | J3: @ | K3: SuperClassPj.ID : | L3: =IF(LogicCommon!G3="","",LogicCommon!G3) | O3: Gene.Type : | P3: ALL
A4: * | E4: Version : | F4: 000000 | G4: LogicName : | H4: =IF(LogicCommon!E4="","",LogicCommon!E4) -> 原価品目系情報確認＆コピー | I4: Ope.Name : | J4: 参照品目検索 | K4: SuperLogicID : | L4: =IF(LogicCommon!G4="","",LogicCommon!G4) -> MG.MGUDL5010 | M4: ImplOpe.ID:
A5: * | E5: ACType :
A6: * | D6: 概要 : | E6: 参照品目検索処理をする | M6: ID | O6: ID | Q6: ID | S6: ID | U6: ID | W6: ID | Y6: ID | AA6: ID | AC6: ID | AE6: ID
A7: # | I7: U | K7: K | L7: o | M7: PI.i1 | N7: o | O7: PI.i2 | P7: o | Q7: PI.i3 | R7: o | S7: PI.i4 | T7: o | U7: PI.i5 | V7: o | W7: PI.i6 | X7: o | Y7: PI.i7 | Z7: o | AA7: PI.i8 | AB7: o | AC7: PI.i9 | AD7: o | AE7: PI.i10
A8: # | D8: ブロック名 Block Name | E8: 型 Type | G8: super/share | H8: 対象ブロック名 Target Block Name | L8: TargetName | M8: DBC.MG.MGT_ITM | N8: TargetName | O8: DBC.MG.MGT_ITM_DTL | P8: TargetName | Q8: DBC.MG.MGT_ITM_OPER | R8: TargetName | S8: DBC.MG.MGT_BOM | T8: TargetName | U8: DBC.MG.MGT_ITM_WK | V8: TargetName | W8: DBC.MG.MGT_ITM_PURC | X8: TargetName | Y8: DBC.MG.MGT_ITM_PROC | Z8: TargetName | AA8: DBC.MG.MGT_ITM_PROV | AB8: TargetName | AC8: DBC.MG.MGT_ITM_SLS | AD8: TargetName | AE8: DBC.MG.MGT_ITM_FIX | AH8: ブロック備考 Block Remarks
A9: # | D9: 項目名 Field Name | E9: 型 Type | F9: 桁 Digits | G9: フルネーム Full Name | H9: 日本語名 Japanese Name | I9: 上り項目 Request Message Field | J9: 下り項目 Response Message Field | AF9: 条件および編集方法 Conditions and Editing Methods | AH9: 項目備考 Field Remarks
A10: # | L10: 上り項目 Request Message Field | M10: 下り項目 Response Message Field | N10: 上り項目 Request Message Field | O10: 下り項目 Response Message Field | P10: 上り項目 Request Message Field | Q10: 下り項目 Response Message Field | R10: 上り項目 Request Message Field | S10: 下り項目 Response Message Field | T10: 上り項目 Request Message Field | U10: 下り項目 Response Message Field | V10: 上り項目 Request Message Field | W10: 下り項目 Response Message Field | X10: 上り項目 Request Message Field | Y10: 下り項目 Response Message Field | Z10: 上り項目 Request Message Field | AA10: 下り項目 Response Message Field | AB10: 上り項目 Request Message Field | AC10: 下り項目 Response Message Field | AD10: 上り項目 Request Message Field | AE10: 下り項目 Response Message Field
A11: 10 | B11: * | D11: Cnd | E11: R | G11: $share$ | H11: MG.MGBDL0640.Srch01.Cnd
A12: 10 | D12: calc_ctg_cd | E12: #MA.CALC_CTG_CD | G12: Calculation category cd. | H12: 計算カテゴリＣＤ | I12: E
A13: 10 | D13: term | E13: #MA.YM | G13: Term | H13: 期 | I13: E
A14: 10 | D14: itm_cd | E14: #MA.ITM_CD | G14: Item cd. | H14: 品目ＣＤ | I14: E
A15: 10 | D15: itm_sub1 | E15: #MA.ITM_SUB1 | G15: Branch No. 1 | H15: 枝番１ | I15: E
A16: 10 | D16: itm_sub2 | E16: #MA.ITM_SUB2 | G16: Branch No. 2 | H16: 枝番２ | I16: E
A17: 10 | D17: itm_sub3 | E17: #MA.ITM_SUB3 | G17: Branch No. 3 | H17: 枝番３ | I17: E
A18: 10 | D18: itm_nm | E18: #MA.ITM_NM | G18: Item name | H18: 品名 | I18: E
A19: 10 | D19: del_flg_on | E19: #MA.FLG | G19: Logical delete. On | H19: 論理削除.オン | I19: E
A20: 10 | D20: del_flg_off | E20: #MA.FLG | G20: Logical delete. Off | H20: 論理削除.オフ | I20: E
A21: 10 | D21: release_flg_on | E21: #MA.FLG | G21: Release. On | H21: リリース.オン | I21: E
A22: 10 | D22: release_flg_off | E22: #MA.FLG | G22: Release. Off | H22: リリース.オフ | I22: E
A23: 10 | D23: itm_typ | E23: #MA.ITM_TYP | G23: Item type | H23: 品目区分 | I23: E
... A47: 10 | D47: itm_jnl_nm | E47: #MA.ITM_JNL_NM | G47: Item journal name | H47: 品目仕訳名 | I47: E
A49: 20 | B49: * | D49: Dtl | E49: L | G49: $share$ | H49: MG.MGBDL0640.CostItmCopy_Chk01.Dtl
A50: 20 | D50: calc_ctg_cd | E50: #MA.CALC_CTG_CD | G50: Calculation category cd. | H50: 計算カテゴリーＣＤ | J50: E
A51: 20 | D51: term | E51: #MA.YM | G51: Term | H51: 期 | J51: E
A52: 20 | D52: itm_cd | E52: #MA.ITM_CD | G52: Item cd. | H52: 品目ＣＤ | J52: E
A53: 20 | D53: itm_sub1 | E53: #MA.ITM_SUB1 | G53: Branch No. 1 | H53: 枝番１ | J53: E
A54: 20 | D54: itm_sub2 | E54: #MA.ITM_SUB2 | G54: Branch No. 2 | H54: 枝番２ | J54: E
A55: 20 | D55: itm_sub3 | E55: #MA.ITM_SUB3 | G55: Branch No. 3 | H55: 枝番３ | J55: E
A56: 20 | D56: itm_nm | E56: #MA.ITM_NM | G56: Item name | H56: 品名 | J56: E
A57: 20 | D57: base_itm_nm | E57: #MA.ITM_NM | G57: Standard Item name | H57: 標準品名 | J57: E
A58: 20 | D58: itm_typ | E58: #MA.ITM_TYP | G58: Item type | H58: 品目区分 | J58: E
A59: 20 | D59: itm_typ_nm | E59: #MA.ITM_TYP_NM | G59: Item type name | H59: 品目区分名 | J59: E
A60: 20 | D60: itm_typ_d_cd | E60: #MA.ITM_TYP_D_CD | G60: Item type details cd. | H60: 品目区分詳細ＣＤ | J60: E
A61: 20 | D61: itm_typ_d_nm | E61: #MA.ITM_TYP_D_NM | G61: Item type details name | H61: 品目区分詳細名 | J61: E
... A63: 20 | D63: itm_jnl_nm | E63: #MA.ITM_JNL_NM | G63: Item journal name | H63: 品目仕訳名 | J63: E
A64: 20 | D64: stk_mng_typ | E64: #MA.STK_MNG_TYP | G64: Inventory management type | H64: 在庫管理区分
A65: 20 | D65: asset_mng_typ | E65: #MA.ASSET_MNG_TYP | G65: Asset management type | H65: 資産管理区分
...

Sheet 来歴
A1: 変更来歴
A3: Rev. | H3: 修正番号 | O3: 変更内容 | AQ3: 変更箇所
A4: 1 | O4: 初版
A5: 1.1 | O5: 英語の名称を追記 | AQ5: 全般
