Workbook

Sheet LogicCommon
A2: オペレーション実装仕様書 | B2: ModuleID : | C2: MG | D2: LogicID : | E2: MGBDL0030 | F2: Pj.ID : | G2: MC
B3: SubModuleID : | C3: MGBD | D3: LogicClass : | E3: MGBDL_ArgSrch | F3: SuperClassPj.ID :
D4: LogicName : | E4: 原価計算結果確認 | F4: SuperLogicID : | G4: MG.MGUDL5010
A5: 概要 :
A6: 詳細 :

Sheet Chk01
A1: * | B1: * | D1: L | E1: 1
A2: * | D2: オペレーション実装仕様書 Operation Specification Implementation Sheet | E2: ModuleID : | F2: =IF(LogicCommon!C2="","",LogicCommon!C2) -> MG | G2: LogicID : | H2: =IF(LogicCommon!E2="","",LogicCommon!E2) -> MGBDL0030 | I2: Ope.ID : | J2: Chk01 | K2: Pj.ID : | L2: =IF(LogicCommon!G2="","",LogicCommon!G2) -> MC | M2: Ope.Body : | N2: MA.MAUDL5010.Checker
A3: * | E3: SubModuleID : | F3: =IF(LogicCommon!C3="","",LogicCommon!C3) -> MGBD | G3: LogicClass : | H3: =IF(LogicCommon!E3="","",LogicCommon!E3) -> MGBDL_ArgSrch | I3: Ope.Method : | J3: @ | K3: SuperClassPj.ID : | L3: =IF(LogicCommon!G3="","",LogicCommon!G3) | O3: Gene.Type : | P3: ALL
A4: * | E4: Version : | F4: 000000 | G4: LogicName : | H4: =IF(LogicCommon!E4="","",LogicCommon!E4) -> 原価計算結果確認 | I4: Ope.Name : | J4: 訂正前チェック | K4: SuperLogicID : | L4: =IF(LogicCommon!G4="","",LogicCommon!G4) -> MG.MGUDL5010 | M4: ImplOpe.ID:
A5: * | E5: ACType :
A6: * | D6: 概要 : | E6: 訂正する前のチェックを行う | AD6: ID
A7: # | I7: U | K7: K | L7: K | M7: K | N7: K | O7: K | P7: K | Q7: K | R7: K | S7: K | T7: K | U7: K | V7: K | W7: K | X7: K | Y7: K | Z7: K | AA7: K | AB7: K | AC7: o
A8: # | D8: ブロック名 Block Name | E8: 型 Type | G8: super/share | H8: 対象ブロック名 Target Block Name | K8: REQ_UPD_CNT_CHK | L8: REQUIRED | M8: CHK_NUM | N8: SMALL_LARGE | O8: CHK_DT | P8: BEFORE_AFTER | Q8: CHK_PTN | R8: DUPLICATE | S8: TOO_MANY_INPUTS | T8: AT_LEAST_ONE | U8: ONLY_ONE_INPUT | V8: LIST_LOGIC | W8: LIST_OUT | X8: LIST_OUT_BASE | Y8: LIST_IN | Z8: LIST_IN_BASE | AA8: CONST | AB8: NULL_VAL | AC8: TargetName | AG8: ブロック備考 Block Remarks
A9: # | D9: 項目名 Field Name | E9: 型 Type | F9: 桁 Digits | G9: フルネーム Full Name | H9: 日本語名 Japanese Name | I9: 上り項目 Request Message Field | J9: 下り項目 Response Message Field | AE9: 条件および編集方法 Conditions and Editing Methods | AG9: 項目備考 Field Remarks
A10: # | AC10: 上り項目 Request Message Field | AD10: 下り項目 Response Message Field
A11: 10 | B11: * | D11: Dtl | E11: GL | G11: $super$ | H11: DBC:MG.MGT_ARG
A12: 10 | D12: calc_grp_cd | E12: #MA.CALC_GRP_CD | G12: Calculation group cd. | H12: 計算グループＣＤ | I12: E | L12: E | V12: MA.MAUAL0010.CalcGrp
A13: 10 | D13: calc_no | E13: #MA.CALC_NO | G13: Calculation No. | H13: 原価計算ＮＯ | I13: E | L13: E
A14: 10 | D14: st_ym | E14: #MA.YM | G14: First month of the term | H14: 対象期間先頭年月
A15: 10 | D15: end_ym | E15: #MA.YM | G15: Last month of the term | H15: 対象期間末尾年月
A16: 10 | D16: xrate_cd | E16: #MA.XRATE_CD | G16: Exchange rate cd. | H16: 為替レートＣＤ
A17: 10 | D17: xrate_nm | E17: #MA.XRATE_NM | G17: Exchange rate name | H17: 為替レート名
A18: 10 | D18: calc_usr_cd | E18: #MA.USR_CD | G18: Calculation user cd. | H18: 計算者ＣＤ
A19: 10 | D19: calc_usr_nm | E19: #MA.USR_NM | G19: Calculation user name | H19: 計算者名
A20: 10 | D20: calc_st | E20: #MA.YMDHMS | G20: Calculation start time | H20: 計算開始時刻
A21: 10 | D21: calc_fin | E21: #MA.YMDHMS | G21: Calculation end time | H21: 計算終了時刻
A22: 10 | D22: alc_err_flg | E22: #MA.FLG | G22: Unallocated | H22: 未配賦
A23: 10 | D23: trd_amt_flg | E23: #MA.FLG | G23: Transfer difference | H23: 振替差額
A24: 10 | D24: adj_amt_flg | E24: #MA.FLG | G24: GR/GI difference | H24: 受払差額
A25: 10 | D25: non_del_flg | E25: #MA.FLG | G25: Undeletable | H25: 削除不可
... A49: 10 | D49: upd_srv_req_no | E49: #MA.SRV_REQ_NO | G49: Update request No. | H49: 更新リクエストＮＯ
A50: 10 | D50: upd_cntr | E50: #MA.INT | G50: Update counter | H50: 更新カウンタ | I50: E
A51: 10 | D51: err_flg | E51: #MA.FLG | G51: Error | H51: エラー
A52: 10 | D52: rtn_sts_typ | E52: #MA.RTN_STS_TYP | G52: Process result status type | H52: 処理結果状況区分 | J52: E
D53: 詳細 :

Sheet Upd01
A1: * | B1: * | D1: L | E1: 1
A2: * | D2: オペレーション実装仕様書 Operation Specification Implementation Sheet | E2: ModuleID : | F2: =IF(LogicCommon!C2="","",LogicCommon!C2) -> MG | G2: LogicID : | H2: =IF(LogicCommon!E2="","",LogicCommon!E2) -> MGBDL0030 | I2: Ope.ID : | J2: Upd01 | K2: Pj.ID : | L2: =IF(LogicCommon!G2="","",LogicCommon!G2) -> MC | M2: Ope.Body : | N2: "mcframe.serverMAUD.MAUDL5010.MAUDL_Operation"
A3: * | E3: SubModuleID : | F3: =IF(LogicCommon!C3="","",LogicCommon!C3) -> MGBD | G3: LogicClass : | H3: =IF(LogicCommon!E3="","",LogicCommon!E3) -> MGBDL_ArgSrch | I3: Ope.Method : | J3: @ | K3: SuperClassPj.ID : | L3: =IF(LogicCommon!G3="","",LogicCommon!G3) | O3: Gene.Type : | P3: ALL
A4: * | E4: Version : | F4: 000000 | G4: LogicName : | H4: =IF(LogicCommon!E4="","",LogicCommon!E4) -> 原価計算結果確認 | I4: Ope.Name : | J4: 訂正 | K4: SuperLogicID : | L4: =IF(LogicCommon!G4="","",LogicCommon!G4) -> MG.MGUDL5010 | M4: ImplOpe.ID:
A5: * | E5: ACType :
A6: * | D6: 概要 : | E6: 訂正処理をする | M6: ID
A7: # | I7: U | K7: K | L7: o
A8: # | D8: ブロック名 Block Name | E8: 型 Type | G8: super/share | H8: 対象ブロック名 Target Block Name | L8: TargetName | P8: ブロック備考 Block Remarks
A9: # | D9: 項目名 Field Name | E9: 型 Type | F9: 桁 Digits | G9: フルネーム Full Name | H9: 日本語名 Japanese Name | I9: 上り項目 Request Message Field | J9: 下り項目 Response Message Field | N9: 条件および編集方法 Conditions and Editing Methods | P9: 項目備考 Field Remarks
A10: # | L10: 上り項目 Request Message Field | M10: 下り項目 Response Message Field
A11: 10 | B11: * | D11: Dtl | E11: GL | G11: $share$ | H11: MG.MGBDL0030.Chk01.Dtl
A12: 10 | D12: calc_grp_cd | E12: #MA.CALC_GRP_CD | G12: Calculation group cd. | H12: 計算グループＣＤ | I12: E
A13: 10 | D13: calc_no | E13: #MA.CALC_NO | G13: Calculation No. | H13: 原価計算ＮＯ | I13: E
A14: 10 | D14: st_ym | E14: #MA.YM | G14: First month of the term | H14: 対象期間先頭年月
A15: 10 | D15: end_ym | E15: #MA.YM | G15: Last month of the term | H15: 対象期間末尾年月
A16: 10 | D16: xrate_cd | E16: #MA.XRATE_CD | G16: Exchange rate cd. | H16: 為替レートＣＤ
A17: 10 | D17: xrate_nm | E17: #MA.XRATE_NM | G17: Exchange rate name | H17: 為替レート名
A18: 10 | D18: calc_usr_cd | E18: #MA.USR_CD | G18: Calculation user cd. | H18: 計算者ＣＤ
A19: 10 | D19: calc_usr_nm | E19: #MA.USR_NM | G19: Calculation user name | H19: 計算者名
A20: 10 | D20: calc_st | E20: #MA.YMDHMS | G20: Calculation start time | H20: 計算開始時刻
A21: 10 | D21: calc_fin | E21: #MA.YMDHMS | G21: Calculation end time | H21: 計算終了時刻
A22: 10 | D22: alc_err_flg | E22: #MA.FLG | G22: Unallocated | H22: 未配賦
A23: 10 | D23: trd_amt_flg | E23: #MA.FLG | G23: Transfer difference | H23: 振替差額
A24: 10 | D24: adj_amt_flg | E24: #MA.FLG | G24: GR/GI difference | H24: 受払差額
A25: 10 | D25: non_del_flg | E25: #MA.FLG | G25: Undeletable | H25: 削除不可 | I25: E
A26: 10 | D26: minus_stk_flg | E26: #MA.FLG | G26: Negative inventory | H26: マイナス在庫
A27: 10 | D27: other_chk_flg | E27: #MA.FLG | G27: Optional check | H27: 任意チェック
A28: 10 | D28: itm_limit_flg | E28: #MA.FLG | G28: Specify item | H28: 品目指定
A29: 10 | D29: data_check_flg | E29: #MA.FLG | G29: Check data | H29: データ確認
A30: 10 | D30: rate_fix_flg | E30: #MA.FLG | G30: Firm allocation rate | H30: 配賦率確定
A31: 10 | D31: calc_err_flg | E31: #MA.FLG | G31: Error | H31: エラー
A32: 10 | D32: fix_flg | E32: #MA.FLG | G32: Firm | H32: 確定
A33: 10 | D33: ins_srv_req_no | E33: #MA.SRV_REQ_NO | G33: Entry request No. | H33: 登録リクエストＮＯ
A34: 10 | D34: rmrks | E34: #MG.CALC_ARG_RMRKS | G34: Remarks | H34: 備考 | I34: E
A35: 10 | D35: sub_char1 | E35: #MG.CALC_ARG_SUB_CHAR1 | G35: Spare 1 | H35: 予備１ | I35: E
A36: 10 | D36: sub_char2 | E36: #MG.CALC_ARG_SUB_CHAR2 | G36: Spare 2 | H36: 予備２ | I36: E
A37: 10 | D37: sub_char3 | E37: #MG.CALC_ARG_SUB_CHAR3 | G37: Spare 3 | H37: 予備３ | I37: E
A38: 10 | D38: ins_usr_id | E38: #MA.FCM_USR_ID | G38: Entry user ID | H38: 登録ユーザＩＤ
A39: 10 | D39: ins_usr_nm | E39: #MA.FCM_USR_NM | G39: Entry user name | H39: 登録ユーザ名
A40: 10 | D40: ins_func_id | E40: #MA.FUNC_ID | G40: Entry function ID | H40: 登録機能ＩＤ
...

Sheet Del01
A1: * | B1: * | D1: L | E1: 1
A2: * | D2: オペレーション実装仕様書 Operation Specification Implementation Sheet | E2: ModuleID : | F2: =IF(LogicCommon!C2="","",LogicCommon!C2) -> MG | G2: LogicID : | H2: =IF(LogicCommon!E2="","",LogicCommon!E2) -> MGBDL0030 | I2: Ope.ID : | J2: Del01 | K2: Pj.ID : | L2: =IF(LogicCommon!G2="","",LogicCommon!G2) -> MC | M2: Ope.Body : | N2: "mcframe.serverMAUD.MAUDL5010.MAUDL_Operation"
A3: * | E3: SubModuleID : | F3: =IF(LogicCommon!C3="","",LogicCommon!C3) -> MGBD | G3: LogicClass : | H3: =IF(LogicCommon!E3="","",LogicCommon!E3) -> MGBDL_ArgSrch | I3: Ope.Method : | J3: @ | K3: SuperClassPj.ID : | L3: =IF(LogicCommon!G3="","",LogicCommon!G3) | O3: Gene.Type : | P3: ALL
A4: * | E4: Version : | F4: 000000 | G4: LogicName : | H4: =IF(LogicCommon!E4="","",LogicCommon!E4) -> 原価計算結果確認 | I4: Ope.Name : | J4: 削除 | K4: SuperLogicID : | L4: =IF(LogicCommon!G4="","",LogicCommon!G4) -> MG.MGUDL5010 | M4: ImplOpe.ID:
A5: * | E5: ACType :
A6: * | D6: 概要 : | E6: 削除処理をする | M6: ID
A7: # | I7: U | K7: K | L7: o
A8: # | D8: ブロック名 Block Name | E8: 型 Type | G8: super/share | H8: 対象ブロック名 Target Block Name | L8: TargetName | P8: ブロック備考 Block Remarks
A9: # | D9: 項目名 Field Name | E9: 型 Type | F9: 桁 Digits | G9: フルネーム Full Name | H9: 日本語名 Japanese Name | I9: 上り項目 Request Message Field | J9: 下り項目 Response Message Field | N9: 条件および編集方法 Conditions and Editing Methods | P9: 項目備考 Field Remarks
A10: # | L10: 上り項目 Request Message Field | M10: 下り項目 Response Message Field
A11: 10 | B11: * | D11: Dtl | E11: L | G11: $share$ | H11: MG.MGBDL5010.CalcRsltDel_Del01.CalcRsltDel_Dtl
A12: 10 | D12: calc_grp_cd | E12: #MA.CALC_GRP_CD | G12: Calculation group cd. | H12: 計算グループＣＤ | I12: E
A13: 10 | D13: calc_no | E13: #MA.CALC_NO | G13: Calculation No. | H13: 原価計算ＮＯ | I13: E
A14: 10 | D14: upd_cntr | E14: #MA.INT | G14: Update counter | H14: 更新カウンタ | I14: E
A15: 10 | D15: err_flg | E15: #MA.FLG | G15: Error | H15: エラー
A16: 10 | D16: rtn_sts_typ | E16: #MA.RTN_STS_TYP | G16: Process result status type | H16: 処理結果状況区分
L17: 上り項目 Request Message Field | M17: 下り項目 Response Message Field
A18: 20 | B18: * | D18: Hdr | E18: R
A19: 20 | D19: ope | E19: C | I19: E
D20: 詳細 :

Sheet Srch01
A1: * | B1: * | D1: L | E1: 1
A2: * | D2: オペレーション実装仕様書 Operation Specification Implementation Sheet | E2: ModuleID : | F2: =IF(LogicCommon!C2="","",LogicCommon!C2) -> MG | G2: LogicID : | H2: =IF(LogicCommon!E2="","",LogicCommon!E2) -> MGBDL0030 | I2: Ope.ID : | J2: Srch01 | K2: Pj.ID : | L2: =IF(LogicCommon!G2="","",LogicCommon!G2) -> MC | M2: Ope.Body : | N2: "mcframe.serverMAUD.MAUDL5010.MAUDL_Searcher"
A3: * | E3: SubModuleID : | F3: =IF(LogicCommon!C3="","",LogicCommon!C3) -> MGBD | G3: LogicClass : | H3: =IF(LogicCommon!E3="","",LogicCommon!E3) -> MGBDL_ArgSrch | I3: Ope.Method : | J3: @ | K3: SuperClassPj.ID : | L3: =IF(LogicCommon!G3="","",LogicCommon!G3) | O3: Gene.Type : | P3: ALL
A4: * | E4: Version : | F4: 000000 | G4: LogicName : | H4: =IF(LogicCommon!E4="","",LogicCommon!E4) -> 原価計算結果確認 | I4: Ope.Name : | J4: 検索 | K4: SuperLogicID : | L4: =IF(LogicCommon!G4="","",LogicCommon!G4) -> MG.MGUDL5010 | M4: ImplOpe.ID:
A5: * | E5: ACType :
A6: * | D6: 概要 : | E6: 検索処理をする | M6: ID
A7: # | I7: U | K7: K | L7: o
A8: # | D8: ブロック名 Block Name | E8: 型 Type | G8: super/share | H8: 対象ブロック名 Target Block Name | L8: TargetName | P8: ブロック備考 Block Remarks
A9: # | D9: 項目名 Field Name | E9: 型 Type | F9: 桁 Digits | G9: フルネーム Full Name | H9: 日本語名 Japanese Name | I9: 上り項目 Request Message Field | J9: 下り項目 Response Message Field | N9: 条件および編集方法 Conditions and Editing Methods | P9: 項目備考 Field Remarks
A10: # | L10: 上り項目 Request Message Field | M10: 下り項目 Response Message Field
A11: 10 | B11: * | D11: Srch01_Cnd | E11: R | G11: $super$ | H11: DBC:MG.MGT_ARG
A12: 10 | D12: term | E12: #MA.YM | G12: Term | H12: 期 | I12: E
A13: 10 | D13: calc_grp_cd | E13: #MA.CALC_GRP_CD | G13: Calculation group cd. | H13: 計算グループＣＤ | I13: E
A14: 10 | D14: calc_no | E14: #MA.CALC_NO | G14: Calculation No. | H14: 原価計算ＮＯ | I14: E
A15: 10 | D15: calc_usr_cd | E15: #MA.USR_CD | G15: Calculation user cd. | H15: 計算者ＣＤ | I15: E
A16: 10 | D16: calc_usr_nm | E16: #MA.USR_NM | G16: Calculation user name | H16: 計算者名 | I16: E
A17: 10 | D17: st_ym | E17: #MA.YM | G17: First month of the term | H17: 対象期間先頭年月 | I17: E
A18: 10 | D18: end_ym | E18: #MA.YM | G18: Last month of the term | H18: 対象期間末尾年月 | I18: E
A19: 10 | D19: rmrks | E19: #MG.CALC_ARG_RMRKS | G19: Remarks | H19: 備考 | I19: E
A20: 10 | D20: sub_char1 | E20: #MG.CALC_ARG_SUB_CHAR1 | G20: Spare 1 | H20: 予備１ | I20: E
A21: 10 | D21: sub_char2 | E21: #MG.CALC_ARG_SUB_CHAR2 | G21: Spare 2 | H21: 予備２ | I21: E
A22: 10 | D22: sub_char3 | E22: #MG.CALC_ARG_SUB_CHAR3 | G22: Spare 3 | H22: 予備３ | I22: E
A23: 10 | D23: fix_true_flg | E23: #MA.FLG | G23: Firm | H23: 確定 | I23: R
... A28: 10 | D28: calc_err_false_flg | E28: #MA.FLG | G28: Successful completion | H28: 正常終了 | I28: R
L29: 上り項目 Request Message Field | M29: 下り項目 Response Message Field
A30: 20 | B30: * | D30: Dtl | E30: GL | G30: $share$ | H30: MG.MGBDL0030.Chk01.Dtl
A31: 20 | D31: calc_grp_cd | E31: #MA.CALC_GRP_CD | G31: Calculation group cd. | H31: 計算グループＣＤ | J31: E
A32: 20 | D32: calc_no | E32: #MA.CALC_NO | G32: Calculation No. | H32: 原価計算ＮＯ | J32: E
A33: 20 | D33: st_ym | E33: #MA.YM | G33: First month of the term | H33: 対象期間先頭年月 | J33: E
A34: 20 | D34: end_ym | E34: #MA.YM | G34: Last month of the term | H34: 対象期間末尾年月 | J34: E
A35: 20 | D35: xrate_cd | E35: #MA.XRATE_CD | G35: Exchange rate cd. | H35: 為替レートＣＤ | J35: E
A36: 20 | D36: xrate_nm | E36: #MA.XRATE_NM | G36: Exchange rate name | H36: 為替レート名 | J36: E
A37: 20 | D37: calc_usr_cd | E37: #MA.USR_CD | G37: Calculation user cd. | H37: 計算者ＣＤ | J37: E
A38: 20 | D38: calc_usr_nm | E38: #MA.USR_NM | G38: Calculation user name | H38: 計算者名 | J38: E
A39: 20 | D39: calc_st | E39: #MA.YMDHMS | G39: Calculation start time | H39: 計算開始時刻 | J39: E
A40: 20 | D40: calc_fin | E40: #MA.YMDHMS | G40: Calculation end time | H40: 計算終了時刻 | J40: E
A41: 20 | D41: alc_err_flg | E41: #MA.FLG | G41: Unallocated | H41: 未配賦 | J41: E
A42: 20 | D42: trd_amt_flg | E42: #MA.FLG | G42: Transfer difference | H42: 振替差額 | J42: E
... A69: 20 | D69: upd_cntr | E69: #MA.INT | G69: Update counter | H69: 更新カウンタ | J69: E
D70: 詳細 :

Sheet Srch02
A1: * | B1: * | D1: L | E1: 1
A2: * | D2: オペレーション実装仕様書 Operation Specification Implementation Sheet | E2: ModuleID : | F2: =IF(LogicCommon!C2="","",LogicCommon!C2) -> MG | G2: LogicID : | H2: =IF(LogicCommon!E2="","",LogicCommon!E2) -> MGBDL0030 | I2: Ope.ID : | J2: Srch02 | K2: Pj.ID : | L2: =IF(LogicCommon!G2="","",LogicCommon!G2) -> MC | M2: Ope.Body : | N2: "mcframe.serverMAUD.MAUDL5010.MAUDL_Searcher"
A3: * | E3: SubModuleID : | F3: =IF(LogicCommon!C3="","",LogicCommon!C3) -> MGBD | G3: LogicClass : | H3: =IF(LogicCommon!E3="","",LogicCommon!E3) -> MGBDL_ArgSrch | I3: Ope.Method : | J3: @ | K3: SuperClassPj.ID : | L3: =IF(LogicCommon!G3="","",LogicCommon!G3) | O3: Gene.Type : | P3: ALL
A4: * | E4: Version : | F4: 000000 | G4: LogicName : | H4: =IF(LogicCommon!E4="","",LogicCommon!E4) -> 原価計算結果確認 | I4: Ope.Name : | J4: メニュー検索 | K4: SuperLogicID : | L4: =IF(LogicCommon!G4="","",LogicCommon!G4) -> MG.MGUDL5010 | M4: ImplOpe.ID:
A5: * | E5: ACType :
A6: * | D6: 概要 : | E6: 原価メニューの検索処理をする | M6: ID
A7: # | I7: U | K7: K | L7: o
A8: # | D8: ブロック名 Block Name | E8: 型 Type | G8: super/share | H8: 対象ブロック名 Target Block Name | L8: TargetName | P8: ブロック備考 Block Remarks
A9: # | D9: 項目名 Field Name | E9: 型 Type | F9: 桁 Digits | G9: フルネーム Full Name | H9: 日本語名 Japanese Name | I9: 上り項目 Request Message Field | J9: 下り項目 Response Message Field | N9: 条件および編集方法 Conditions and Editing Methods | P9: 項目備考 Field Remarks
A10: # | L10: 上り項目 Request Message Field | M10: 下り項目 Response Message Field
A11: 10 | B11: * | D11: Srch02_Cnd | E11: R | G11: $share$ | H11: DBC:MA.MAM_MENU_CONFIG
A12: 10 | D12: menu_cd | E12: #MA.MENU_CD | G12: Menu cd. | H12: メニューＣＤ | I12: E
L13: 上り項目 Request Message Field | M13: 下り項目 Response Message Field
A14: 20 | B14: * | D14: Srch02_Dtl | E14: GL | G14: $super$ | H14: DBC:MA.MAM_MENU_CONFIG
A15: 20 | D15: menu_no | E15: #MA.MENU_NO | G15: Menu placement number | H15: メニュー配置番号 | J15: E
A16: 20 | D16: module_id | E16: #MA.MODULE_ID | G16: Module ID | H16: モジュールＩＤ | J16: E
A17: 20 | D17: scrn_id | E17: #MA.SCREEN_ID | G17: Screen ID | H17: 画面ＩＤ | J17: E
D18: 詳細 :

Sheet 来歴
A1: 変更来歴
A3: Rev. | H3: 修正番号 | O3: 変更内容 | AQ3: 変更箇所
A4: 1 | O4: 初版
A5: 1.1 | H5: MG7032#013 | O5: Hdrブロックを追加 | AQ5: Del01
A6: 1.2 | O6: 英語の名称を追記 | AQ6: 全般
