Workbook

Sheet LogicCommon
A2: オペレーション実装仕様書 | B2: ModuleID : | C2: MS | D2: LogicID : | E2: MSBFL5210 | F2: Pj.ID : | G2: MC
B3: SubModuleID : | C3: MSBF | D3: LogicClass : | E3: MSBFL_LotService | F3: SuperClassPj.ID :
D4: LogicName : | E4: ロット情報サービス | F4: SuperLogicID : | G4: MS.MSUDL5010
A5: 概要 :
A6: 詳細 :

Sheet Lot_Chk01
A1: * | B1: * | D1: L | E1: 1
A2: * | D2: オペレーション実装仕様書 Operation Specification Implementation Sheet | E2: ModuleID : | F2: =IF(LogicCommon!C2="","",LogicCommon!C2) -> MS | G2: LogicID : | H2: =IF(LogicCommon!E2="","",LogicCommon!E2) -> MSBFL5210 | I2: Ope.ID : | J2: Lot_Chk01 | K2: Pj.ID : | L2: =IF(LogicCommon!G2="","",LogicCommon!G2) -> MC | M2: Ope.Body : | N2: "mcframe.serverMAUD.MAUDL5010.MAUDL_Operation"
A3: * | D3: =IF(LogicCommon!A3="","",LogicCommon!A3) | E3: SubModuleID : | F3: =IF(LogicCommon!C3="","",LogicCommon!C3) -> MSBF | G3: LogicClass : | H3: =IF(LogicCommon!E3="","",LogicCommon!E3) -> MSBFL_LotService | I3: Ope.Method : | J3: @ | K3: SuperClassPj.ID : | L3: =IF(LogicCommon!G3="","",LogicCommon!G3) | O3: Gene.Type : | P3: ALL
A4: * | E4: Version : | F4: 000000 | G4: LogicName : | H4: =IF(LogicCommon!E4="","",LogicCommon!E4) -> ロット情報サービス | I4: Ope.Name : | J4: ロット削除チェック | K4: SuperLogicID : | L4: =IF(LogicCommon!G4="","",LogicCommon!G4) -> MS.MSUDL5010 | M4: ImplOpe.ID:
A5: * | E5: ACType :
A6: * | D6: 概要 : | E6: ロットの削除前にチェックを行う。 | M6: ID | O6: ID | Q6: ID
A7: # | I7: U | K7: K | L7: o | N7: o | P7: o
A8: # | D8: ブロック名 Block Name | E8: 型 Type | G8: super/share | H8: 対象ブロック名 Target Block Name | L8: TargetName | N8: TargetName | P8: TargetName | T8: ブロック備考 Block Remarks
A9: # | D9: 項目名 Field Name | E9: 型 Type | F9: 桁 Digits | G9: フルネーム Full Name | H9: 日本語名 Japanese Name | I9: 上り項目 Request Message Field | J9: 下り項目 Response Message Field | R9: 条件および編集方法 Conditions and Editing Methods | T9: 項目備考 Field Remarks
A10: # | L10: 上り項目 Request Message Field | M10: 下り項目 Response Message Field | N10: 上り項目 Request Message Field | O10: 下り項目 Response Message Field | P10: 上り項目 Request Message Field | Q10: 下り項目 Response Message Field
A11: 10 | B11: * | D11: Lot_Chk01_Cnd | E11: L
A12: 10 | D12: peg_no | E12: #MA.INT | G12: Pegging No. | H12: 紐付ＮＯ | I12: E | J12: E
A13: 10 | D13: exception_flg | E13: #MA.FLG | G13: Exception | H13: 例外 | I13: E
A14: 10 | D14: lot_p | E14: R | F14: DBC:MS.MST_LOT
A15: 10 | D15: lot_p.itm_cd# | E15: RI | G15: Item cd. | H15: 品目ＣＤ | I15: E
A16: 10 | D16: lot_p.itm_sub1# | E16: RI | G16: Branch No. 1 | H16: 枝番１ | I16: E
A17: 10 | D17: lot_p.itm_sub2# | E17: RI | G17: Branch No. 2 | H17: 枝番２ | I17: E
A18: 10 | D18: lot_p.itm_sub3# | E18: RI | G18: Branch No. 3 | H18: 枝番３ | I18: E
A19: 10 | D19: lot_p.lot_no# | E19: RI | G19: Lot No. | H19: ロットＮＯ | I19: E
A20: 10 | D20: lot_p.sublot_no# | E20: RI | G20: Sublot No. | H20: サブロットＮＯ | I20: E
A21: 10 | D21: err_flg | E21: #MA.FLG | G21: Error flg. | H21: エラーＦＬＧ | J21: E

Sheet Lot_Chk02
A1: * | B1: * | D1: L | E1: 1
A2: * | D2: オペレーション実装仕様書 Operation Specification Implementation Sheet | E2: ModuleID : | F2: =IF(LogicCommon!C2="","",LogicCommon!C2) -> MS | G2: LogicID : | H2: =IF(LogicCommon!E2="","",LogicCommon!E2) -> MSBFL5210 | I2: Ope.ID : | J2: Lot_Chk02 | K2: Pj.ID : | L2: =IF(LogicCommon!G2="","",LogicCommon!G2) -> MC | M2: Ope.Body : | N2: "mcframe.serverMAUD.MAUDL5010.MAUDL_Operation"
A3: * | D3: =IF(LogicCommon!A3="","",LogicCommon!A3) | E3: SubModuleID : | F3: =IF(LogicCommon!C3="","",LogicCommon!C3) -> MSBF | G3: LogicClass : | H3: =IF(LogicCommon!E3="","",LogicCommon!E3) -> MSBFL_LotService | I3: Ope.Method : | J3: @ | K3: SuperClassPj.ID : | L3: =IF(LogicCommon!G3="","",LogicCommon!G3) | O3: Gene.Type : | P3: ALL
A4: * | E4: Version : | F4: 000000 | G4: LogicName : | H4: =IF(LogicCommon!E4="","",LogicCommon!E4) -> ロット情報サービス | I4: Ope.Name : | J4: ロット重複チェック | K4: SuperLogicID : | L4: =IF(LogicCommon!G4="","",LogicCommon!G4) -> MS.MSUDL5010 | M4: ImplOpe.ID:
A5: * | E5: ACType :
A6: * | D6: 概要 : | E6: ロットの重複チェックを行う。 | M6: ID | O6: ID | Q6: ID
A7: # | I7: U | K7: K | L7: o | N7: o | P7: o
A8: # | D8: ブロック名 Block Name | E8: 型 Type | G8: super/share | H8: 対象ブロック名 Target Block Name | L8: TargetName | N8: TargetName | P8: TargetName | T8: ブロック備考 Block Remarks
A9: # | D9: 項目名 Field Name | E9: 型 Type | F9: 桁 Digits | G9: フルネーム Full Name | H9: 日本語名 Japanese Name | I9: 上り項目 Request Message Field | J9: 下り項目 Response Message Field | R9: 条件および編集方法 Conditions and Editing Methods | T9: 項目備考 Field Remarks
A10: # | L10: 上り項目 Request Message Field | M10: 下り項目 Response Message Field | N10: 上り項目 Request Message Field | O10: 下り項目 Response Message Field | P10: 上り項目 Request Message Field | Q10: 下り項目 Response Message Field
A11: 10 | B11: * | D11: Lot_Chk02_Cnd | E11: L
A12: 10 | D12: peg_no | E12: #MA.INT | G12: Pegging No. | H12: 紐付ＮＯ | I12: E | J12: E
A13: 10 | D13: itm_cd | E13: #MA.ITM_CD | G13: Item cd. | H13: 品目ＣＤ | I13: E
A14: 10 | D14: itm_sub1 | E14: #MA.ITM_SUB1 | G14: Branch No. 1 | H14: 枝番１ | I14: E
A15: 10 | D15: itm_sub2 | E15: #MA.ITM_SUB2 | G15: Branch No. 2 | H15: 枝番２ | I15: E
A16: 10 | D16: itm_sub3 | E16: #MA.ITM_SUB3 | G16: Branch No. 3 | H16: 枝番３ | I16: E
A17: 10 | D17: lot_no | E17: #MA.LOT_NO | G17: Lot No. | H17: ロットＮＯ | I17: E
A18: 10 | D18: sublot_no | E18: #MA.SUBLOT_NO | G18: Sublot No. | H18: サブロットＮＯ | I18: E
A19: 10 | D19: lot_mng_typ | E19: #MA.LOT_MNG_TYP | G19: Lot management type | H19: ロット管理区分
A20: 10 | D20: sublot_mng_typ | E20: #MA.SUBLOT_MNG_TYP | G20: Sublot management type | H20: サブロット管理区分
A21: 10 | D21: lot_not_change_flg | E21: #MA.FLG | I21: E
A22: 10 | D22: err_flg | E22: #MA.FLG | G22: Error flg. | H22: エラーＦＬＧ | J22: E

Sheet Lot_Chk03
A1: * | B1: * | D1: L | E1: 1
A2: * | D2: オペレーション実装仕様書 Operation Specification Implementation Sheet | E2: ModuleID : | F2: =IF(LogicCommon!C2="","",LogicCommon!C2) -> MS | G2: LogicID : | H2: =IF(LogicCommon!E2="","",LogicCommon!E2) -> MSBFL5210 | I2: Ope.ID : | J2: Lot_Chk03 | K2: Pj.ID : | L2: =IF(LogicCommon!G2="","",LogicCommon!G2) -> MC | M2: Ope.Body : | N2: "mcframe.serverMAUD.MAUDL5010.MAUDL_Operation"
A3: * | D3: =IF(LogicCommon!A3="","",LogicCommon!A3) | E3: SubModuleID : | F3: =IF(LogicCommon!C3="","",LogicCommon!C3) -> MSBF | G3: LogicClass : | H3: =IF(LogicCommon!E3="","",LogicCommon!E3) -> MSBFL_LotService | I3: Ope.Method : | J3: @ | K3: SuperClassPj.ID : | L3: =IF(LogicCommon!G3="","",LogicCommon!G3) | O3: Gene.Type : | P3: ALL
A4: * | E4: Version : | F4: 000000 | G4: LogicName : | H4: =IF(LogicCommon!E4="","",LogicCommon!E4) -> ロット情報サービス | I4: Ope.Name : | J4: ロット存在チェック | K4: SuperLogicID : | L4: =IF(LogicCommon!G4="","",LogicCommon!G4) -> MS.MSUDL5010 | M4: ImplOpe.ID:
A5: * | E5: ACType :
A6: * | D6: 概要 : | E6: ロットの存在チェックを行う。 | M6: ID | O6: ID | Q6: ID
A7: # | I7: U | K7: K | L7: o | N7: o | P7: o
A8: # | D8: ブロック名 Block Name | E8: 型 Type | G8: super/share | H8: 対象ブロック名 Target Block Name | L8: TargetName | N8: TargetName | P8: TargetName | T8: ブロック備考 Block Remarks
A9: # | D9: 項目名 Field Name | E9: 型 Type | F9: 桁 Digits | G9: フルネーム Full Name | H9: 日本語名 Japanese Name | I9: 上り項目 Request Message Field | J9: 下り項目 Response Message Field | R9: 条件および編集方法 Conditions and Editing Methods | T9: 項目備考 Field Remarks
A10: # | L10: 上り項目 Request Message Field | M10: 下り項目 Response Message Field | N10: 上り項目 Request Message Field | O10: 下り項目 Response Message Field | P10: 上り項目 Request Message Field | Q10: 下り項目 Response Message Field
A11: 10 | B11: * | D11: Lot_Chk03_Cnd | E11: L
A12: 10 | D12: peg_no | E12: #MA.INT | G12: Pegging No. | H12: 紐付ＮＯ | I12: E | J12: E
A13: 10 | D13: lot_p | E13: R | F13: DBC:MS.MST_LOT
A14: 10 | D14: lot_p.itm_cd# | E14: RI | G14: Item cd. | H14: 品目ＣＤ | I14: E
A15: 10 | D15: lot_p.itm_sub1# | E15: RI | G15: Branch No. 1 | H15: 枝番１ | I15: E
A16: 10 | D16: lot_p.itm_sub2# | E16: RI | G16: Branch No. 2 | H16: 枝番２ | I16: E
A17: 10 | D17: lot_p.itm_sub3# | E17: RI | G17: Branch No. 3 | H17: 枝番３ | I17: E
A18: 10 | D18: lot_p.lot_no# | E18: RI | G18: Lot No. | H18: ロットＮＯ | I18: E
A19: 10 | D19: lot_p.sublot_no# | E19: RI | G19: Sublot No. | H19: サブロットＮＯ | I19: E
A20: 10 | D20: lot_p.ver_no# | E20: RI | G20: Version No. | H20: 版ＮＯ | I20: E | J20: E
A21: 10 | D21: lot_p.first_gr_dt# | E21: RI | G21: Oldest GR date | H21: 最古入庫日 | J21: E
A22: 10 | D22: lot_p.vld_dt# | E22: RI | G22: Expiration date | H22: 有効期限 | J22: E
A23: 10 | D23: lot_p.lot_seq# | E23: RI | G23: Lot sequence | H23: ロットシーケンス | J23: E
A24: 10 | D24: lot_p.stk_insp_typ# | E24: RI | G24: Inventory inspection type | H24: 在庫検査区分 | J24: E
A25: 10 | D25: lot_p.quality_typ# | E25: RI | G25: Conforming type | H25: 良品区分 | J25: E
A26: 10 | D26: lot_p.mfg_aprv_sts_typ# | E26: RI | G26: Mfg. approval status type | H26: 製造承認状況区分 | J26: E
A27: 10 | D27: lot_p.insp_aprv_sts_typ# | E27: RI | G27: Inspection approval status type | H27: 検査承認状況区分 | J27: E
A28: 10 | D28: lot_p.plnt_aprv_sts_typ# | E28: RI | G28: Factory release approval status type | H28: 工場出荷承認状況区分 | J28: E
A29: 10 | D29: lot_p.mrkt_judg_sts_typ# | E29: RI | G29: Market release decision status type | H29: 市場出荷判定状況区分 | J29: E
A30: 10 | D30: lot_p.act_cont_fctr# | E30: RI | G30: Actual active ingredient coefficient | H30: 実際有効成分係数 | J30: E
A31: 10 | D31: err_flg | E31: #MA.FLG | G31: Error | H31: エラー | J31: E

Sheet Lot_Srch01
A1: * | B1: * | D1: L | E1: 1
A2: * | D2: オペレーション実装仕様書 Operation Specification Implementation Sheet | E2: ModuleID : | F2: =IF(LogicCommon!C2="","",LogicCommon!C2) -> MS | G2: LogicID : | H2: =IF(LogicCommon!E2="","",LogicCommon!E2) -> MSBFL5210 | I2: Ope.ID : | J2: Lot_Srch01 | K2: Pj.ID : | L2: =IF(LogicCommon!G2="","",LogicCommon!G2) -> MC | M2: Ope.Body : | N2: "mcframe.serverMAUD.MAUDL5010.MAUDL_Operation"
A3: * | D3: =IF(LogicCommon!A3="","",LogicCommon!A3) | E3: SubModuleID : | F3: =IF(LogicCommon!C3="","",LogicCommon!C3) -> MSBF | G3: LogicClass : | H3: =IF(LogicCommon!E3="","",LogicCommon!E3) -> MSBFL_LotService | I3: Ope.Method : | J3: @ | K3: SuperClassPj.ID : | L3: =IF(LogicCommon!G3="","",LogicCommon!G3) | O3: Gene.Type : | P3: ALL
A4: * | E4: Version : | F4: 000000 | G4: LogicName : | H4: =IF(LogicCommon!E4="","",LogicCommon!E4) -> ロット情報サービス | I4: Ope.Name : | J4: 期限取得 | K4: SuperLogicID : | L4: =IF(LogicCommon!G4="","",LogicCommon!G4) -> MS.MSUDL5010 | M4: ImplOpe.ID:
A5: * | E5: ACType :
A6: * | D6: 概要 : | E6: 有効期限・使用期限を取得する。 | M6: ID | O6: ID | Q6: ID
A7: # | I7: U | K7: K | L7: o | N7: o | P7: o
A8: # | D8: ブロック名 Block Name | E8: 型 Type | G8: super/share | H8: 対象ブロック名 Target Block Name | L8: TargetName | N8: TargetName | P8: TargetName | T8: ブロック備考 Block Remarks
A9: # | D9: 項目名 Field Name | E9: 型 Type | F9: 桁 Digits | G9: フルネーム Full Name | H9: 日本語名 Japanese Name | I9: 上り項目 Request Message Field | J9: 下り項目 Response Message Field | R9: 条件および編集方法 Conditions and Editing Methods | T9: 項目備考 Field Remarks
A10: # | L10: 上り項目 Request Message Field | M10: 下り項目 Response Message Field | N10: 上り項目 Request Message Field | O10: 下り項目 Response Message Field | P10: 上り項目 Request Message Field | Q10: 下り項目 Response Message Field
A11: 10 | B11: * | D11: Lot_Srch01_Cnd | E11: L
A12: 10 | D12: peg_no | E12: #MA.INT | G12: Pegging No. | H12: 紐付ＮＯ | I12: E
A13: 10 | D13: lmt_dt_frm | E13: #MA.DT | G13: Base date | H13: 起算日 | I13: E
A14: 10 | D14: insp_typ | E14: #MS.INSP_TYP | G14: Inspection classification type | H14: 検査種類区分 | I14: E
A15: 10 | D15: src_no1 | E15: #MA.SRC_NO | G15: Source No. 1 | H15: 作成元ＮＯ１ | I15: E
A16: 10 | D16: src_no2 | E16: #MA.SRC_NO | G16: Source No. 2 | H16: 作成元ＮＯ２ | I16: E
A17: 10 | D17: src_no3 | E17: #MA.SRC_NO | G17: Source No. 3 | H17: 作成元ＮＯ３ | I17: E
A18: 10 | D18: src_no4 | E18: #MA.SRC_NO | G18: Source No. 4 | H18: 作成元ＮＯ４ | I18: E
A19: 10 | D19: lmt_dt_frm_typ | E19: #MA.LMT_DT_FRM_TYP | G19: Expiration base date type | H19: 期限起算日区分 | I19: E
A20: 10 | D20: vld_pd | E20: #MA.VLD_PD | G20: Valid period | H20: 有効期間 | I20: E
A21: 10 | D21: lmt_pd | E21: #MA.LMT_PD | G21: Period until expiration | H21: 使用期間 | I21: E
A22: 10 | D22: calc_pd_typ | E22: #MA.CALC_PD_TYP | G22: Period calculation type | H22: 期間計算区分 | I22: E
A23: 10 | D23: lmt_dt | E23: #MA.DT | G23: Current usage expiration date | H23: 現使用期限 | I23: E
A24: 10 | D24: base_dt | E24: #MA.DT | G24: Base date | H24: 基準日 | I24: E
A26: 20 | B26: * | D26: Lot_Srch01_Rslt | E26: L
A27: 20 | D27: peg_no | E27: #MA.INT | G27: Pegging No. | H27: 紐付ＮＯ | J27: E
A28: 20 | D28: lmt_dt_frm | E28: #MA.DT | G28: Base date | H28: 起算日 | J28: E
A29: 20 | D29: vld_dt | E29: #MA.DT | G29: Expiration date | H29: 有効期限 | J29: E
A30: 20 | D30: lmt_dt | E30: #MA.DT | G30: Usage expiration date | H30: 使用期限 | J30: E

Sheet Lot_Srch02
A1: * | B1: * | D1: L | E1: 1
A2: * | D2: オペレーション実装仕様書 Operation Specification Implementation Sheet | E2: ModuleID : | F2: =IF(LogicCommon!C2="","",LogicCommon!C2) -> MS | G2: LogicID : | H2: =IF(LogicCommon!E2="","",LogicCommon!E2) -> MSBFL5210 | I2: Ope.ID : | J2: Lot_Srch02 | K2: Pj.ID : | L2: =IF(LogicCommon!G2="","",LogicCommon!G2) -> MC | M2: Ope.Body : | N2: "mcframe.serverMAUD.MAUDL5010.MAUDL_Operation"
A3: * | D3: =IF(LogicCommon!A3="","",LogicCommon!A3) | E3: SubModuleID : | F3: =IF(LogicCommon!C3="","",LogicCommon!C3) -> MSBF | G3: LogicClass : | H3: =IF(LogicCommon!E3="","",LogicCommon!E3) -> MSBFL_LotService | I3: Ope.Method : | J3: @ | K3: SuperClassPj.ID : | L3: =IF(LogicCommon!G3="","",LogicCommon!G3) | O3: Gene.Type : | P3: ALL
A4: * | E4: Version : | F4: 000000 | G4: LogicName : | H4: =IF(LogicCommon!E4="","",LogicCommon!E4) -> ロット情報サービス | I4: Ope.Name : | J4: 期限取得（検査指図単位） | K4: SuperLogicID : | L4: =IF(LogicCommon!G4="","",LogicCommon!G4) -> MS.MSUDL5010 | M4: ImplOpe.ID:
A5: * | E5: ACType :
A6: * | D6: 概要 : | E6: 検査指図単位で、有効期限・使用期限を取得する。 | M6: ID | O6: ID | Q6: ID
A7: # | I7: U | K7: K | L7: o | N7: o | P7: o
A8: # | D8: ブロック名 Block Name | E8: 型 Type | G8: super/share | H8: 対象ブロック名 Target Block Name | L8: TargetName | N8: TargetName | P8: TargetName | T8: ブロック備考 Block Remarks
A9: # | D9: 項目名 Field Name | E9: 型 Type | F9: 桁 Digits | G9: フルネーム Full Name | H9: 日本語名 Japanese Name | I9: 上り項目 Request Message Field | J9: 下り項目 Response Message Field | R9: 条件および編集方法 Conditions and Editing Methods | T9: 項目備考 Field Remarks
A10: # | L10: 上り項目 Request Message Field | M10: 下り項目 Response Message Field | N10: 上り項目 Request Message Field | O10: 下り項目 Response Message Field | P10: 上り項目 Request Message Field | Q10: 下り項目 Response Message Field
A11: 10 | B11: * | D11: Lot_Srch02_Cnd | E11: L
A12: 10 | D12: peg_no | E12: #MA.INT | G12: Pegging No. | H12: 紐付ＮＯ | I12: E
A13: 10 | D13: insp_no | E13: #MA.INSP_NO | G13: Inspection No. | H13: 検査ＮＯ | I13: E
A14: 10 | D14: lmt_dt_frm | E14: #MA.DT | G14: Base date | H14: 起算日 | I14: E
A15: 10 | D15: insp_typ | E15: #MS.INSP_TYP | G15: Inspection classification type | H15: 検査種類区分
A16: 10 | D16: src_no1 | E16: #MA.SRC_NO | G16: Source No. 1 | H16: 作成元ＮＯ１
A17: 10 | D17: src_no2 | E17: #MA.SRC_NO | G17: Source No. 2 | H17: 作成元ＮＯ２
A18: 10 | D18: src_no3 | E18: #MA.SRC_NO | G18: Source No. 3 | H18: 作成元ＮＯ３
A19: 10 | D19: src_no4 | E19: #MA.SRC_NO | G19: Source No. 4 | H19: 作成元ＮＯ４
A20: 10 | D20: itm_cd | E20: #MA.ITM_CD | G20: Item cd. | H20: 品目ＣＤ
A21: 10 | D21: itm_sub1 | E21: #MA.ITM_SUB1 | G21: Branch No. 1 | H21: 枝番１
A22: 10 | D22: itm_sub2 | E22: #MA.ITM_SUB2 | G22: Branch No. 2 | H22: 枝番２
A23: 10 | D23: itm_sub3 | E23: #MA.ITM_SUB3 | G23: Branch No. 3 | H23: 枝番３
A24: 10 | D24: sppl_cd | E24: #MA.BP_CD | G24: Supplier cd. | H24: 発注先ＣＤ
A25: 10 | D25: maker_cd | E25: #MA.BP_CD | G25: Maker cd. | H25: メーカＣＤ
A26: 10 | D26: mfg_loc_cd | E26: #MA.LOC_CD | G26: Mfg. location cd. | H26: 製造場所ＣＤ
... A34: 10 | D34: lmt_dt | E34: #MA.DT | G34: Usage expiration date | H34: 使用期限
A36: 20 | B36: * | D36: Lot_Srch02_Rslt | E36: L
A37: 20 | D37: peg_no | E37: #MA.INT | G37: Pegging No. | H37: 紐付ＮＯ | J37: E
A38: 20 | D38: lmt_dt_frm_typ | E38: #MA.LMT_DT_FRM_TYP | G38: Expiration base date type | H38: 期限起算日区分 | J38: E
A39: 20 | D39: lmt_dt_frm | E39: #MA.DT | G39: Base date | H39: 起算日 | J39: E
A40: 20 | D40: vld_dt | E40: #MA.DT | G40: Expiration date | H40: 有効期限 | J40: E
A41: 20 | D41: lmt_dt | E41: #MA.DT | G41: Usage expiration date | H41: 使用期限 | J41: E

Sheet Lot_Upd01
A1: * | B1: * | D1: L | E1: 1
A2: * | D2: オペレーション実装仕様書 Operation Specification Implementation Sheet | E2: ModuleID : | F2: =IF(LogicCommon!C2="","",LogicCommon!C2) -> MS | G2: LogicID : | H2: =IF(LogicCommon!E2="","",LogicCommon!E2) -> MSBFL5210 | I2: Ope.ID : | J2: Lot_Upd01 | K2: Pj.ID : | L2: =IF(LogicCommon!G2="","",LogicCommon!G2) -> MC | M2: Ope.Body : | N2: "mcframe.serverMAUD.MAUDL5010.MAUDL_Operation"
A3: * | D3: =IF(LogicCommon!A3="","",LogicCommon!A3) | E3: SubModuleID : | F3: =IF(LogicCommon!C3="","",LogicCommon!C3) -> MSBF | G3: LogicClass : | H3: =IF(LogicCommon!E3="","",LogicCommon!E3) -> MSBFL_LotService | I3: Ope.Method : | J3: @ | K3: SuperClassPj.ID : | L3: =IF(LogicCommon!G3="","",LogicCommon!G3) | O3: Gene.Type : | P3: ALL
A4: * | E4: Version : | F4: 000000 | G4: LogicName : | H4: =IF(LogicCommon!E4="","",LogicCommon!E4) -> ロット情報サービス | I4: Ope.Name : | J4: ロット追加・更新 | K4: SuperLogicID : | L4: =IF(LogicCommon!G4="","",LogicCommon!G4) -> MS.MSUDL5010 | M4: ImplOpe.ID:
A5: * | E5: ACType :
A6: * | D6: 概要 : | E6: ロットの追加・更新を行う。 | M6: ID | O6: ID | Q6: ID
A7: # | I7: U | K7: K | L7: o | N7: o | P7: o
A8: # | D8: ブロック名 Block Name | E8: 型 Type | G8: super/share | H8: 対象ブロック名 Target Block Name | L8: TargetName | N8: TargetName | P8: TargetName | T8: ブロック備考 Block Remarks
A9: # | D9: 項目名 Field Name | E9: 型 Type | F9: 桁 Digits | G9: フルネーム Full Name | H9: 日本語名 Japanese Name | I9: 上り項目 Request Message Field | J9: 下り項目 Response Message Field | R9: 条件および編集方法 Conditions and Editing Methods | T9: 項目備考 Field Remarks
A10: # | L10: 上り項目 Request Message Field | M10: 下り項目 Response Message Field | N10: 上り項目 Request Message Field | O10: 下り項目 Response Message Field | P10: 上り項目 Request Message Field | Q10: 下り項目 Response Message Field
A11: 10 | B11: * | D11: Lot_Upd01_Cnd | E11: L
A12: 10 | D12: base_dt | E12: #MA.DT | G12: GR date | H12: 入庫日 | I12: E
A13: 10 | D13: loc_cd | E13: #MA.LOC_CD | G13: Location cd. | H13: 場所ＣＤ | I13: E
A14: 10 | D14: mfg_loc_cd | E14: #MA.LOC_CD | G14: Mfg. location cd. | H14: 製造場所ＣＤ | I14: E
A15: 10 | D15: sppl_cd | E15: #MA.BP_CD | G15: Supplier cd. | H15: 発注先ＣＤ | I15: E
A16: 10 | D16: maker_cd | E16: #MA.BP_CD | G16: Maker cd. | H16: メーカＣＤ | I16: E
A17: 10 | D17: arr_act_no | E17: #MA.ARR_ACT_NO | G17: Receipt result No. | H17: 入荷実績ＮＯ | I17: E
A18: 10 | D18: arr_pr_no | E18: #MA.ARR_PR_NO | G18: Receipt progress No. | H18: 入荷進捗ＮＯ | I18: E
A19: 10 | D19: lot_p | E19: R | F19: DBC:MS.MST_LOT
A20: 10 | D20: lot_p.itm_cd# | E20: RI | G20: Item cd. | H20: 品目ＣＤ | I20: E
A21: 10 | D21: lot_p.itm_sub1# | E21: RI | G21: Branch No. 1 | H21: 枝番１ | I21: E
A22: 10 | D22: lot_p.itm_sub2# | E22: RI | G22: Branch No. 2 | H22: 枝番２ | I22: E
A23: 10 | D23: lot_p.itm_sub3# | E23: RI | G23: Branch No. 3 | H23: 枝番３ | I23: E
A24: 10 | D24: lot_p.lot_no# | E24: RI | G24: Lot No. | H24: ロットＮＯ | I24: E
A25: 10 | D25: lot_p.sublot_no# | E25: RI | G25: Sublot No. | H25: サブロットＮＯ | I25: E
A26: 10 | D26: lot_p.schd_flg# | E26: RI | G26: Schedule flg. | H26: 予定ＦＬＧ | I26: E
A27: 10 | D27: lot_p.lot_sub_char1# | E27: RI | G27: Lot spare (String) 1 | H27: ロット予備（文字列）１ | I27: E
A28: 10 | D28: lot_p.lot_sub_char2# | E28: RI | G28: Lot spare (String) 2 | H28: ロット予備（文字列）２ | I28: E
A29: 10 | D29: lot_p.lot_sub_char3# | E29: RI | G29: Lot spare (String) 3 | H29: ロット予備（文字列）３ | I29: E
A30: 10 | D30: lot_p.lot_sub_char4# | E30: RI | G30: Lot spare (String) 4 | H30: ロット予備（文字列）４ | I30: E
A31: 10 | D31: lot_p.lot_sub_char5# | E31: RI | G31: Lot spare (String) 5 | H31: ロット予備（文字列）５ | I31: E
... A46: 10 | D46: lot_p.lot_sub_flg5# | E46: RI | G46: Lot spare (flg.) 5 | H46: ロット予備（ＦＬＧ）５ | I46: E
A47: 10 | D47: peg_no | E47: #MA.INT | G47: Pegging No. | H47: 紐付けＮＯ
A48: 10 | D48: insp_typ | E48: #MS.INSP_TYP | G48: Inspection classification type | H48: 検査種類区分
A49: 10 | D49: sublot_no_org | E49: #MA.SUBLOT_NO | G49: Sublot No. (Caller) | H49: サブロットＮＯ(呼出元)

Sheet Lot_Upd02
A1: * | B1: * | D1: L | E1: 1
A2: * | D2: オペレーション実装仕様書 Operation Specification Implementation Sheet | E2: ModuleID : | F2: =IF(LogicCommon!C2="","",LogicCommon!C2) -> MS | G2: LogicID : | H2: =IF(LogicCommon!E2="","",LogicCommon!E2) -> MSBFL5210 | I2: Ope.ID : | J2: Lot_Upd02 | K2: Pj.ID : | L2: =IF(LogicCommon!G2="","",LogicCommon!G2) -> MC | M2: Ope.Body : | N2: "mcframe.serverMAUD.MAUDL5010.MAUDL_Operation"
A3: * | D3: =IF(LogicCommon!A3="","",LogicCommon!A3) | E3: SubModuleID : | F3: =IF(LogicCommon!C3="","",LogicCommon!C3) -> MSBF | G3: LogicClass : | H3: =IF(LogicCommon!E3="","",LogicCommon!E3) -> MSBFL_LotService | I3: Ope.Method : | J3: @ | K3: SuperClassPj.ID : | L3: =IF(LogicCommon!G3="","",LogicCommon!G3) | O3: Gene.Type : | P3: ALL
A4: * | E4: Version : | F4: 000000 | G4: LogicName : | H4: =IF(LogicCommon!E4="","",LogicCommon!E4) -> ロット情報サービス | I4: Ope.Name : | J4: 備考・予備項目更新 | K4: SuperLogicID : | L4: =IF(LogicCommon!G4="","",LogicCommon!G4) -> MS.MSUDL5010 | M4: ImplOpe.ID:
A5: * | E5: ACType :
A6: * | D6: 概要 : | E6: ロットの備考・予備項目を更新する。 | M6: ID | O6: ID | Q6: ID
A7: # | I7: U | K7: K | L7: o | N7: o | P7: o
A8: # | D8: ブロック名 Block Name | E8: 型 Type | G8: super/share | H8: 対象ブロック名 Target Block Name | L8: TargetName | N8: TargetName | P8: TargetName | T8: ブロック備考 Block Remarks
A9: # | D9: 項目名 Field Name | E9: 型 Type | F9: 桁 Digits | G9: フルネーム Full Name | H9: 日本語名 Japanese Name | I9: 上り項目 Request Message Field | J9: 下り項目 Response Message Field | R9: 条件および編集方法 Conditions and Editing Methods | T9: 項目備考 Field Remarks
A10: # | L10: 上り項目 Request Message Field | M10: 下り項目 Response Message Field | N10: 上り項目 Request Message Field | O10: 下り項目 Response Message Field | P10: 上り項目 Request Message Field | Q10: 下り項目 Response Message Field
A11: 10 | B11: * | D11: Lot_Upd02_Cnd | E11: L
A12: 10 | D12: lot_p | E12: R | F12: DBC:MS.MST_LOT
A13: 10 | D13: lot_p.itm_cd# | E13: RI | G13: Item cd. | H13: 品目ＣＤ | I13: E
A14: 10 | D14: lot_p.itm_sub1# | E14: RI | G14: Branch No. 1 | H14: 枝番１ | I14: E
A15: 10 | D15: lot_p.itm_sub2# | E15: RI | G15: Branch No. 2 | H15: 枝番２ | I15: E
A16: 10 | D16: lot_p.itm_sub3# | E16: RI | G16: Branch No. 3 | H16: 枝番３ | I16: E
A17: 10 | D17: lot_p.lot_no# | E17: RI | G17: Lot No. | H17: ロットＮＯ | I17: E
A18: 10 | D18: lot_p.sublot_no# | E18: RI | G18: Sublot No. | H18: サブロットＮＯ | I18: E
A19: 10 | D19: lot_p.lot_rmrks# | E19: RI | G19: Lot remarks | H19: ロット備考 | I19: E

Sheet Lot_Upd03
A1: * | B1: * | D1: L | E1: 1
A2: * | D2: オペレーション実装仕様書 Operation Specification Implementation Sheet | E2: ModuleID : | F2: =IF(LogicCommon!C2="","",LogicCommon!C2) -> MS | G2: LogicID : | H2: =IF(LogicCommon!E2="","",LogicCommon!E2) -> MSBFL5210 | I2: Ope.ID : | J2: Lot_Upd03 | K2: Pj.ID : | L2: =IF(LogicCommon!G2="","",LogicCommon!G2) -> MC | M2: Ope.Body : | N2: "mcframe.serverMAUD.MAUDL5010.MAUDL_Operation"
A3: * | D3: =IF(LogicCommon!A3="","",LogicCommon!A3) | E3: SubModuleID : | F3: =IF(LogicCommon!C3="","",LogicCommon!C3) -> MSBF | G3: LogicClass : | H3: =IF(LogicCommon!E3="","",LogicCommon!E3) -> MSBFL_LotService | I3: Ope.Method : | J3: @ | K3: SuperClassPj.ID : | L3: =IF(LogicCommon!G3="","",LogicCommon!G3) | O3: Gene.Type : | P3: ALL
A4: * | E4: Version : | F4: 000000 | G4: LogicName : | H4: =IF(LogicCommon!E4="","",LogicCommon!E4) -> ロット情報サービス | I4: Ope.Name : | J4: 製造承認状況更新 | K4: SuperLogicID : | L4: =IF(LogicCommon!G4="","",LogicCommon!G4) -> MS.MSUDL5010 | M4: ImplOpe.ID:
A5: * | E5: ACType :
A6: * | D6: 概要 : | E6: ロットの製造承認状況を更新する。 | M6: ID | O6: ID | Q6: ID
A7: # | I7: U | K7: K | L7: o | N7: o | P7: o
A8: # | D8: ブロック名 Block Name | E8: 型 Type | G8: super/share | H8: 対象ブロック名 Target Block Name | L8: TargetName | N8: TargetName | P8: TargetName | T8: ブロック備考 Block Remarks
A9: # | D9: 項目名 Field Name | E9: 型 Type | F9: 桁 Digits | G9: フルネーム Full Name | H9: 日本語名 Japanese Name | I9: 上り項目 Request Message Field | J9: 下り項目 Response Message Field | R9: 条件および編集方法 Conditions and Editing Methods | T9: 項目備考 Field Remarks
A10: # | L10: 上り項目 Request Message Field | M10: 下り項目 Response Message Field | N10: 上り項目 Request Message Field | O10: 下り項目 Response Message Field | P10: 上り項目 Request Message Field | Q10: 下り項目 Response Message Field
A11: 10 | B11: * | D11: Lot_Upd03_Cnd | E11: L
A12: 10 | D12: itm_mfg_inst_no | E12: #MA.ITM_MFG_INST_NO | G12: Item mfg. order No. | H12: 品目製造指図ＮＯ | I12: E
A13: 10 | D13: mfg_aprv_sts_typ | E13: #MS.MFG_APRV_STS_TYP | G13: Mfg. approval status type | H13: 製造承認状況区分

Sheet Lot_Upd04
A1: * | B1: * | D1: L | E1: 1
A2: * | D2: オペレーション実装仕様書 Operation Specification Implementation Sheet | E2: ModuleID : | F2: =IF(LogicCommon!C2="","",LogicCommon!C2) -> MS | G2: LogicID : | H2: =IF(LogicCommon!E2="","",LogicCommon!E2) -> MSBFL5210 | I2: Ope.ID : | J2: Lot_Upd04 | K2: Pj.ID : | L2: =IF(LogicCommon!G2="","",LogicCommon!G2) -> MC | M2: Ope.Body : | N2: "mcframe.serverMAUD.MAUDL5010.MAUDL_Operation"
A3: * | D3: =IF(LogicCommon!A3="","",LogicCommon!A3) | E3: SubModuleID : | F3: =IF(LogicCommon!C3="","",LogicCommon!C3) -> MSBF | G3: LogicClass : | H3: =IF(LogicCommon!E3="","",LogicCommon!E3) -> MSBFL_LotService | I3: Ope.Method : | J3: @ | K3: SuperClassPj.ID : | L3: =IF(LogicCommon!G3="","",LogicCommon!G3) | O3: Gene.Type : | P3: ALL
A4: * | E4: Version : | F4: 000000 | G4: LogicName : | H4: =IF(LogicCommon!E4="","",LogicCommon!E4) -> ロット情報サービス | I4: Ope.Name : | J4: 期限・有効成分更新 | K4: SuperLogicID : | L4: =IF(LogicCommon!G4="","",LogicCommon!G4) -> MS.MSUDL5010 | M4: ImplOpe.ID:
A5: * | E5: ACType :
A6: * | D6: 概要 : | E6: ロットの有効期限・使用期限・実際有効成分係数を更新する。 | M6: ID | O6: ID | Q6: ID
A7: # | I7: U | K7: K | L7: o | N7: o | P7: o
A8: # | D8: ブロック名 Block Name | E8: 型 Type | G8: super/share | H8: 対象ブロック名 Target Block Name | L8: TargetName | N8: TargetName | P8: TargetName | T8: ブロック備考 Block Remarks
A9: # | D9: 項目名 Field Name | E9: 型 Type | F9: 桁 Digits | G9: フルネーム Full Name | H9: 日本語名 Japanese Name | I9: 上り項目 Request Message Field | J9: 下り項目 Response Message Field | R9: 条件および編集方法 Conditions and Editing Methods | T9: 項目備考 Field Remarks
A10: # | L10: 上り項目 Request Message Field | M10: 下り項目 Response Message Field | N10: 上り項目 Request Message Field | O10: 下り項目 Response Message Field | P10: 上り項目 Request Message Field | Q10: 下り項目 Response Message Field
A11: 10 | B11: * | D11: Lot_Upd04_Cnd | E11: L
A12: 10 | D12: insp_typ | E12: #MS.INSP_TYP | G12: Inspection classification type | H12: 検査種類区分 | I12: E
A13: 10 | D13: vld_dt_flg | E13: #MA.FLG | G13: Expiration date update flg. | H13: 有効期限更新ＦＬＧ | I13: E
A14: 10 | D14: lot_p | E14: R | F14: DBC:MS.MST_LOT
A15: 10 | D15: lot_p.itm_cd# | E15: RI | G15: Item cd. | H15: 品目ＣＤ | I15: E
A16: 10 | D16: lot_p.itm_sub1# | E16: RI | G16: Branch No. 1 | H16: 枝番１ | I16: E
A17: 10 | D17: lot_p.itm_sub2# | E17: RI | G17: Branch No. 2 | H17: 枝番２ | I17: E
A18: 10 | D18: lot_p.itm_sub3# | E18: RI | G18: Branch No. 3 | H18: 枝番３ | I18: E
A19: 10 | D19: lot_p.lot_no# | E19: RI | G19: Lot No. | H19: ロットＮＯ | I19: E
A20: 10 | D20: lot_p.sublot_no# | E20: RI | G20: Sublot No. | H20: サブロットＮＯ | I20: E
A21: 10 | D21: lot_p.vld_dt# | E21: RI | G21: Expiration date | H21: 有効期限 | I21: E
A22: 10 | D22: lot_p.lmt_dt# | E22: RI | G22: Usage expiration date | H22: 使用期限 | I22: E
A23: 10 | D23: lot_p.lmt_dt_frm_typ# | E23: RI | G23: Expiration base date type | H23: 期限起算日区分 | I23: E
A24: 10 | D24: lot_p.lmt_dt_frm# | E24: RI | G24: Base date | H24: 起算日 | I24: E
A25: 10 | D25: lot_p.act_cont_fctr# | E25: RI | G25: Actual active ingredient coefficient | H25: 実際有効成分係数 | I25: E
A26: 10 | D26: lot_p.base_gr_dt# | E26: RI | G26: Base GR date and time | H26: 基準入庫日時 | I26: E

Sheet Lot_Upd05
A1: * | B1: * | D1: L | E1: 1
A2: * | D2: オペレーション実装仕様書 Operation Specification Implementation Sheet | E2: ModuleID : | F2: =IF(LogicCommon!C2="","",LogicCommon!C2) -> MS | G2: LogicID : | H2: =IF(LogicCommon!E2="","",LogicCommon!E2) -> MSBFL5210 | I2: Ope.ID : | J2: Lot_Upd05 | K2: Pj.ID : | L2: =IF(LogicCommon!G2="","",LogicCommon!G2) -> MC | M2: Ope.Body : | N2: "mcframe.serverMAUD.MAUDL5010.MAUDL_Operation"
A3: * | D3: =IF(LogicCommon!A3="","",LogicCommon!A3) | E3: SubModuleID : | F3: =IF(LogicCommon!C3="","",LogicCommon!C3) -> MSBF | G3: LogicClass : | H3: =IF(LogicCommon!E3="","",LogicCommon!E3) -> MSBFL_LotService | I3: Ope.Method : | J3: @ | K3: SuperClassPj.ID : | L3: =IF(LogicCommon!G3="","",LogicCommon!G3) | O3: Gene.Type : | P3: ALL
A4: * | E4: Version : | F4: 000000 | G4: LogicName : | H4: =IF(LogicCommon!E4="","",LogicCommon!E4) -> ロット情報サービス | I4: Ope.Name : | J4: 区分更新 | K4: SuperLogicID : | L4: =IF(LogicCommon!G4="","",LogicCommon!G4) -> MS.MSUDL5010 | M4: ImplOpe.ID:
A5: * | E5: ACType :
A6: * | D6: 概要 : | E6: ロットの在庫検査区分・良品区分・工場出荷承認区分を更新する。 | M6: ID | O6: ID | Q6: ID
A7: # | I7: U | K7: K | L7: o | N7: o | P7: o
A8: # | D8: ブロック名 Block Name | E8: 型 Type | G8: super/share | H8: 対象ブロック名 Target Block Name | L8: TargetName | N8: TargetName | P8: TargetName | T8: ブロック備考 Block Remarks
A9: # | D9: 項目名 Field Name | E9: 型 Type | F9: 桁 Digits | G9: フルネーム Full Name | H9: 日本語名 Japanese Name | I9: 上り項目 Request Message Field | J9: 下り項目 Response Message Field | R9: 条件および編集方法 Conditions and Editing Methods | T9: 項目備考 Field Remarks
A10: # | L10: 上り項目 Request Message Field | M10: 下り項目 Response Message Field | N10: 上り項目 Request Message Field | O10: 下り項目 Response Message Field | P10: 上り項目 Request Message Field | Q10: 下り項目 Response Message Field
A11: 10 | B11: * | D11: Lot_Upd05_Cnd | E11: L
A12: 10 | D12: insp_no | E12: #MA.INSP_NO | G12: Inspection No. | H12: 検査ＮＯ | I12: E
A13: 10 | D13: insp_typ | E13: #MS.INSP_TYP | G13: Inspection classification type | H13: 検査種類区分 | I13: E
A14: 10 | D14: lmt_up_flg | E14: #MA.FLG | G14: Re-inspection for expiration flg. | H14: 期限再検査ＦＬＧ | I14: E
A15: 10 | D15: lot_p | E15: R | F15: DBC:MS.MST_LOT
A16: 10 | D16: lot_p.itm_cd# | E16: RI | G16: Item cd. | H16: 品目ＣＤ | I16: E
A17: 10 | D17: lot_p.itm_sub1# | E17: RI | G17: Branch No. 1 | H17: 枝番１ | I17: E
A18: 10 | D18: lot_p.itm_sub2# | E18: RI | G18: Branch No. 2 | H18: 枝番２ | I18: E
A19: 10 | D19: lot_p.itm_sub3# | E19: RI | G19: Branch No. 3 | H19: 枝番３ | I19: E
A20: 10 | D20: lot_p.lot_no# | E20: RI | G20: Lot No. | H20: ロットＮＯ | I20: E
A21: 10 | D21: lot_p.sublot_no# | E21: RI | G21: Sublot No. | H21: サブロットＮＯ | I21: E
A22: 10 | D22: lot_p.stk_insp_typ# | E22: RI | G22: Inventory inspection type | H22: 在庫検査区分 | I22: E
A23: 10 | D23: lot_p.quality_typ# | E23: RI | G23: Conforming type | H23: 良品区分 | I23: E
A24: 10 | D24: lot_p.plnt_aprv_sts_typ# | E24: RI | G24: Factory release approval type | H24: 工場出荷承認区分 | I24: E
A25: 10 | D25: lot_p.insp_aprv_sts_typ# | E25: RI | G25: Inspection approval status type | H25: 検査承認状況区分 | I25: E
A26: 10 | D26: lot_p.mrkt_judg_sts_typ# | E26: RI | G26: Market release decision status type | H26: 市場出荷判定状況区分 | I26: E
A27: 10 | D27: lot_insp_schd_flg | E27: #MA.FLG | G27: Lot inspection schedule flg. | H27: ロット検査予定ＦＬＧ | I27: E
... A33: 10 | D33: mrkt_judg_flg | E33: #MA.FLG | G33: Market release decision flg. | H33: 市場出荷判定ＦＬＧ | I33: E
A34: 10 | D34: in_prmt_insp_flg | E34: #MA.FLG | G34: Allow inspecting use flg. | H34: 検査中使用許可ＦＬＧ
A35: 10 | D35: insp_bind_typ | E35: #MA.INSP_BIND_TYP | G35: Inspection implementation unit type | H35: 検査実施単位区分

Sheet Lot_Upd06
A1: * | B1: * | D1: L | E1: 1
A2: * | D2: オペレーション実装仕様書 Operation Specification Implementation Sheet | E2: ModuleID : | F2: =IF(LogicCommon!C2="","",LogicCommon!C2) -> MS | G2: LogicID : | H2: =IF(LogicCommon!E2="","",LogicCommon!E2) -> MSBFL5210 | I2: Ope.ID : | J2: Lot_Upd06 | K2: Pj.ID : | L2: =IF(LogicCommon!G2="","",LogicCommon!G2) -> MC | M2: Ope.Body : | N2: "mcframe.serverMAUD.MAUDL5010.MAUDL_Operation"
A3: * | D3: =IF(LogicCommon!A3="","",LogicCommon!A3) | E3: SubModuleID : | F3: =IF(LogicCommon!C3="","",LogicCommon!C3) -> MSBF | G3: LogicClass : | H3: =IF(LogicCommon!E3="","",LogicCommon!E3) -> MSBFL_LotService | I3: Ope.Method : | J3: @ | K3: SuperClassPj.ID : | L3: =IF(LogicCommon!G3="","",LogicCommon!G3) | O3: Gene.Type : | P3: ALL
A4: * | E4: Version : | F4: 000000 | G4: LogicName : | H4: =IF(LogicCommon!E4="","",LogicCommon!E4) -> ロット情報サービス | I4: Ope.Name : | J4: 期限更新（子品目引継） | K4: SuperLogicID : | L4: =IF(LogicCommon!G4="","",LogicCommon!G4) -> MS.MSUDL5010 | M4: ImplOpe.ID:
A5: * | E5: ACType :
A6: * | D6: 概要 : | E6: ロットの有効期限・使用期限を更新する（子品目期限引継ぎ・子品目起算日引継ぎ）。 | M6: ID | O6: ID | Q6: ID
A7: # | I7: U | K7: K | L7: o | N7: o | P7: o
A8: # | D8: ブロック名 Block Name | E8: 型 Type | G8: super/share | H8: 対象ブロック名 Target Block Name | L8: TargetName | N8: TargetName | P8: TargetName | T8: ブロック備考 Block Remarks
A9: # | D9: 項目名 Field Name | E9: 型 Type | F9: 桁 Digits | G9: フルネーム Full Name | H9: 日本語名 Japanese Name | I9: 上り項目 Request Message Field | J9: 下り項目 Response Message Field | R9: 条件および編集方法 Conditions and Editing Methods | T9: 項目備考 Field Remarks
A10: # | L10: 上り項目 Request Message Field | M10: 下り項目 Response Message Field | N10: 上り項目 Request Message Field | O10: 下り項目 Response Message Field | P10: 上り項目 Request Message Field | Q10: 下り項目 Response Message Field
A11: 10 | B11: * | D11: Lot_Upd06_DtlChd | E11: L
A12: 10 | D12: peg_no | E12: #MA.INT | G12: Pegging No. | H12: 紐付ＮＯ | I12: E
A13: 10 | D13: main_itm_cd | E13: #MA.ITM_CD | G13: Copy-from item cd. | H13: 引継対象品目ＣＤ | I13: E
A14: 10 | D14: main_itm_sub1 | E14: #MA.ITM_SUB1 | G14: Copy-from branch No. 1 | H14: 引継対象枝番１ | I14: E
A15: 10 | D15: main_itm_sub2 | E15: #MA.ITM_SUB2 | G15: Copy-from branch No. 2 | H15: 引継対象枝番２ | I15: E
A16: 10 | D16: main_itm_sub3 | E16: #MA.ITM_SUB3 | G16: Copy-from branch No. 3 | H16: 引継対象枝番３ | I16: E
A17: 10 | D17: main_lot_no | E17: #MA.LOT_NO | G17: Copy-from lot No. | H17: 引継対象ロットＮＯ | I17: E
A18: 10 | D18: main_sublot_no | E18: #MA.SUBLOT_NO | G18: Copy-from sublot No. | H18: 引継対象サブロットＮＯ | I18: E
A19: 10 | D19: sublot_mng_typ | E19: #MA.SUBLOT_MNG_TYP | G19: Sublot management type | H19: サブロット管理区分 | I19: E
A20: 10 | D20: vld_dt | E20: #MA.DT | G20: Expiration date | H20: 有効期限 | I20: E
A21: 10 | D21: lmt_dt | E21: #MA.DT | G21: Usage expiration date | H21: 使用期限 | I21: E
A22: 10 | D22: lmt_dt_frm | E22: #MA.DT | G22: Base date | H22: 起算日 | I22: E
A24: 20 | B24: * | D24: Lot_Upd06_DtlPar | E24: L
A25: 20 | D25: chd_peg_no | E25: #MA.INT | G25: Copy-from child item pegging No. | H25: 引継対象子品目紐付けＮＯ | I25: E
A26: 20 | D26: site_cd | E26: #MA.SITE_CD | G26: Storage location factory/distribution warehouse cd. | H26: 格納場所工場・物流倉庫ＣＤ | I26: E
A27: 20 | D27: mfg_loc_cd | E27: #MA.LOC_CD | G27: Mfg. location cd. | H27: 製造場所ＣＤ | I27: E
A28: 20 | D28: gr_dt | E28: #MA.DT | G28: GR date | H28: 入庫日 | I28: E
A29: 20 | D29: lot_p | E29: R | F29: DBC:MS.MST_LOT
A30: 20 | D30: lot_p.itm_cd# | E30: RI | G30: Item cd. | H30: 品目ＣＤ | I30: E
A31: 20 | D31: lot_p.itm_sub1# | E31: RI | G31: Branch No. 1 | H31: 枝番１ | I31: E
A32: 20 | D32: lot_p.itm_sub2# | E32: RI | G32: Branch No. 2 | H32: 枝番２ | I32: E
A33: 20 | D33: lot_p.itm_sub3# | E33: RI | G33: Branch No. 3 | H33: 枝番３ | I33: E
A34: 20 | D34: lot_p.lot_no# | E34: RI | G34: Lot No. | H34: ロットＮＯ | I34: E
A35: 20 | D35: lot_p.sublot_no# | E35: RI | G35: Sublot No. | H35: サブロットＮＯ | I35: E
A36: 20 | D36: lot_p.vld_dt# | E36: RI | G36: Expiration date | H36: 有効期限
A37: 20 | D37: lot_p.lmt_dt# | E37: RI | G37: Usage expiration date | H37: 使用期限
A38: 20 | D38: lot_p.unreg_lmt_flg# | E38: RI | G38: Without expiration flg. | H38: 期限未設定ＦＬＧ
A39: 20 | D39: lot_p.lmt_dt_frm# | E39: RI | G39: Base date | H39: 起算日
A40: 20 | D40: lot_p.lmt_dt_frm_typ# | E40: RI | G40: Expiration base date type | H40: 期限起算日区分
A41: 20 | D41: master_dt | E41: #MA.DT | G41: Master application date | H41: マスタ適用日
...

Sheet Lot_Upd07
A1: * | B1: * | D1: L | E1: 1
A2: * | D2: オペレーション実装仕様書 Operation Specification Implementation Sheet | E2: ModuleID : | F2: =IF(LogicCommon!C2="","",LogicCommon!C2) -> MS | G2: LogicID : | H2: =IF(LogicCommon!E2="","",LogicCommon!E2) -> MSBFL5210 | I2: Ope.ID : | J2: Lot_Upd07 | K2: Pj.ID : | L2: =IF(LogicCommon!G2="","",LogicCommon!G2) -> MC | M2: Ope.Body : | N2: "mcframe.serverMAUD.MAUDL5010.MAUDL_Operation"
A3: * | D3: =IF(LogicCommon!A3="","",LogicCommon!A3) | E3: SubModuleID : | F3: =IF(LogicCommon!C3="","",LogicCommon!C3) -> MSBF | G3: LogicClass : | H3: =IF(LogicCommon!E3="","",LogicCommon!E3) -> MSBFL_LotService | I3: Ope.Method : | J3: @ | K3: SuperClassPj.ID : | L3: =IF(LogicCommon!G3="","",LogicCommon!G3) | O3: Gene.Type : | P3: ALL
A4: * | E4: Version : | F4: 000000 | G4: LogicName : | H4: =IF(LogicCommon!E4="","",LogicCommon!E4) -> ロット情報サービス | I4: Ope.Name : | J4: 期限更新（工程実績起算） | K4: SuperLogicID : | L4: =IF(LogicCommon!G4="","",LogicCommon!G4) -> MS.MSUDL5010 | M4: ImplOpe.ID:
A5: * | E5: ACType :
A6: * | D6: 概要 : | E6: ロットの有効期限・使用期限を更新する（工程着手実績日・終了実績日起算）。 | M6: ID | O6: ID | Q6: ID
A7: # | I7: U | K7: K | L7: o | N7: o | P7: o
A8: # | D8: ブロック名 Block Name | E8: 型 Type | G8: super/share | H8: 対象ブロック名 Target Block Name | L8: TargetName | N8: TargetName | P8: TargetName | T8: ブロック備考 Block Remarks
A9: # | D9: 項目名 Field Name | E9: 型 Type | F9: 桁 Digits | G9: フルネーム Full Name | H9: 日本語名 Japanese Name | I9: 上り項目 Request Message Field | J9: 下り項目 Response Message Field | R9: 条件および編集方法 Conditions and Editing Methods | T9: 項目備考 Field Remarks
A10: # | L10: 上り項目 Request Message Field | M10: 下り項目 Response Message Field | N10: 上り項目 Request Message Field | O10: 下り項目 Response Message Field | P10: 上り項目 Request Message Field | Q10: 下り項目 Response Message Field
A11: 10 | B11: * | D11: Lot_Upd07_Cnd | E11: L
A12: 10 | D12: data_crud_typ | E12: #MA.DATA_CRUD_TYP | G12: Data update type | H12: データ更新区分 | I12: E
A13: 10 | D13: mfg_act_no | E13: #MA.MFG_ACT_NO | G13: Mfg. result No. | H13: 製造実績ＮＯ | I13: E
A14: 10 | D14: oper_inst_no | E14: #MA.OPER_INST_NO | G14: Operation order No. | H14: 工程指図ＮＯ | I14: E

Sheet Lot_Upd08
A1: * | B1: * | D1: L | E1: 1
A2: * | D2: オペレーション実装仕様書 Operation Specification Implementation Sheet | E2: ModuleID : | F2: =IF(LogicCommon!C2="","",LogicCommon!C2) -> MS | G2: LogicID : | H2: =IF(LogicCommon!E2="","",LogicCommon!E2) -> MSBFL5210 | I2: Ope.ID : | J2: Lot_Upd08 | K2: Pj.ID : | L2: =IF(LogicCommon!G2="","",LogicCommon!G2) -> MC | M2: Ope.Body : | N2: "mcframe.serverMAUD.MAUDL5010.MAUDL_Operation"
A3: * | D3: =IF(LogicCommon!A3="","",LogicCommon!A3) | E3: SubModuleID : | F3: =IF(LogicCommon!C3="","",LogicCommon!C3) -> MSBF | G3: LogicClass : | H3: =IF(LogicCommon!E3="","",LogicCommon!E3) -> MSBFL_LotService | I3: Ope.Method : | J3: @ | K3: SuperClassPj.ID : | L3: =IF(LogicCommon!G3="","",LogicCommon!G3) | O3: Gene.Type : | P3: ALL
A4: * | E4: Version : | F4: 000000 | G4: LogicName : | H4: =IF(LogicCommon!E4="","",LogicCommon!E4) -> ロット情報サービス | I4: Ope.Name : | J4: ロット更新（出来高・入荷） | K4: SuperLogicID : | L4: =IF(LogicCommon!G4="","",LogicCommon!G4) -> MS.MSUDL5010 | M4: ImplOpe.ID:
A5: * | E5: ACType :
A6: * | D6: 概要 : | E6: 出来高、入荷実績後にロットを更新する。 | M6: ID | O6: ID | Q6: ID
A7: # | I7: U | K7: K | L7: o | N7: o | P7: o
A8: # | D8: ブロック名 Block Name | E8: 型 Type | G8: super/share | H8: 対象ブロック名 Target Block Name | L8: TargetName | N8: TargetName | P8: TargetName | T8: ブロック備考 Block Remarks
A9: # | D9: 項目名 Field Name | E9: 型 Type | F9: 桁 Digits | G9: フルネーム Full Name | H9: 日本語名 Japanese Name | I9: 上り項目 Request Message Field | J9: 下り項目 Response Message Field | R9: 条件および編集方法 Conditions and Editing Methods | T9: 項目備考 Field Remarks
A10: # | L10: 上り項目 Request Message Field | M10: 下り項目 Response Message Field | N10: 上り項目 Request Message Field | O10: 下り項目 Response Message Field | P10: 上り項目 Request Message Field | Q10: 下り項目 Response Message Field
A11: 10 | B11: * | D11: Lot_Upd08_Cnd | E11: L
A12: 10 | D12: data_crud_typ | E12: #MA.DATA_CRUD_TYP | G12: Data update type | H12: データ更新区分 | I12: E
A13: 10 | D13: lot_p | E13: R | F13: DBC:MS.MST_LOT
A14: 10 | D14: lot_p.itm_cd# | E14: RI | G14: Item cd. | H14: 品目ＣＤ | I14: E
A15: 10 | D15: lot_p.itm_sub1# | E15: RI | G15: Branch No. 1 | H15: 枝番１ | I15: E
A16: 10 | D16: lot_p.itm_sub2# | E16: RI | G16: Branch No. 2 | H16: 枝番２ | I16: E
A17: 10 | D17: lot_p.itm_sub3# | E17: RI | G17: Branch No. 3 | H17: 枝番３ | I17: E
A18: 10 | D18: lot_p.lot_no# | E18: RI | G18: Lot No. | H18: ロットＮＯ | I18: E
A19: 10 | D19: lot_p.sublot_no# | E19: RI | G19: Sublot No. | H19: サブロットＮＯ | I19: E
A20: 10 | D20: lot_p.ver_no# | E20: RI | G20: Version No. | H20: 版ＮＯ | I20: E
A21: 10 | D21: lot_p.bp_lot_no# | E21: RI | G21: Vendor lot No. | H21: 業者ロットＮＯ | I21: E
A22: 10 | D22: mfg_loc_cd | E22: #MA.LOC_CD | G22: Mfg. location cd. | H22: 製造場所ＣＤ | I22: E
A23: 10 | D23: sppl_cd | E23: #MA.BP_CD | G23: BP cd. | H23: 取引先ＣＤ | I23: E
A24: 10 | D24: maker_cd | E24: #MA.BP_CD | G24: Maker cd. | H24: メーカＣＤ | I24: E
A25: 10 | D25: from_site_cd | E25: #MA.SITE_CD | G25: Shipping point factory/distribution warehouse cd. | H25: 出荷元工場・物流倉庫ＣＤ | I25: E
... A33: 10 | D33: site_cd | E33: #MA.SITE_CD | G33: Factory/Distribution warehouse cd. | H33: 工場・物流倉庫ＣＤ | I33: E
A34: 10 | D34: stk_sublot_no | E34: #MA.SUBLOT_NO | G34: Inventory sublot No. | H34: 在庫サブロットＮＯ
A35: 10 | D35: peg_no | E35: #MA.INT | G35: Pegging No. | H35: 紐付けＮＯ

Sheet Lot_Del01
A1: * | B1: * | D1: L | E1: 1
A2: * | D2: オペレーション実装仕様書 Operation Specification Implementation Sheet | E2: ModuleID : | F2: =IF(LogicCommon!C2="","",LogicCommon!C2) -> MS | G2: LogicID : | H2: =IF(LogicCommon!E2="","",LogicCommon!E2) -> MSBFL5210 | I2: Ope.ID : | J2: Lot_Del01 | K2: Pj.ID : | L2: =IF(LogicCommon!G2="","",LogicCommon!G2) -> MC | M2: Ope.Body : | N2: "mcframe.serverMAUD.MAUDL5010.MAUDL_Operation"
A3: * | D3: =IF(LogicCommon!A3="","",LogicCommon!A3) | E3: SubModuleID : | F3: =IF(LogicCommon!C3="","",LogicCommon!C3) -> MSBF | G3: LogicClass : | H3: =IF(LogicCommon!E3="","",LogicCommon!E3) -> MSBFL_LotService | I3: Ope.Method : | J3: @ | K3: SuperClassPj.ID : | L3: =IF(LogicCommon!G3="","",LogicCommon!G3) | O3: Gene.Type : | P3: ALL
A4: * | E4: Version : | F4: 000000 | G4: LogicName : | H4: =IF(LogicCommon!E4="","",LogicCommon!E4) -> ロット情報サービス | I4: Ope.Name : | J4: ロット削除 | K4: SuperLogicID : | L4: =IF(LogicCommon!G4="","",LogicCommon!G4) -> MS.MSUDL5010 | M4: ImplOpe.ID:
A5: * | E5: ACType :
A6: * | D6: 概要 : | E6: ロットを削除する。 | M6: ID | O6: ID | Q6: ID
A7: # | I7: U | K7: K | L7: o | N7: o | P7: o
A8: # | D8: ブロック名 Block Name | E8: 型 Type | G8: super/share | H8: 対象ブロック名 Target Block Name | L8: TargetName | N8: TargetName | P8: TargetName | T8: ブロック備考 Block Remarks
A9: # | D9: 項目名 Field Name | E9: 型 Type | F9: 桁 Digits | G9: フルネーム Full Name | H9: 日本語名 Japanese Name | I9: 上り項目 Request Message Field | J9: 下り項目 Response Message Field | R9: 条件および編集方法 Conditions and Editing Methods | T9: 項目備考 Field Remarks
A10: # | L10: 上り項目 Request Message Field | M10: 下り項目 Response Message Field | N10: 上り項目 Request Message Field | O10: 下り項目 Response Message Field | P10: 上り項目 Request Message Field | Q10: 下り項目 Response Message Field
A11: 10 | B11: * | D11: Lot_Del01_Cnd | E11: L
A12: 10 | D12: lot_p | E12: R | F12: DBC:MS.MST_LOT
A13: 10 | D13: lot_p.itm_cd# | E13: RI | G13: Item cd. | H13: 品目ＣＤ | I13: E
A14: 10 | D14: lot_p.itm_sub1# | E14: RI | G14: Branch No. 1 | H14: 枝番１ | I14: E
A15: 10 | D15: lot_p.itm_sub2# | E15: RI | G15: Branch No. 2 | H15: 枝番２ | I15: E
A16: 10 | D16: lot_p.itm_sub3# | E16: RI | G16: Branch No. 3 | H16: 枝番３ | I16: E
A17: 10 | D17: lot_p.lot_no# | E17: RI | G17: Lot No. | H17: ロットＮＯ | I17: E
A18: 10 | D18: lot_p.sublot_no# | E18: RI | G18: Sublot No. | H18: サブロットＮＯ | I18: E
A19: 10 | D19: lot_p.no_del_flg# | E19: RI | G19: Undeletable flg. | H19: 削除不可ＦＬＧ
A20: 10 | D20: stk_sublot_no | E20: #MA.SUBLOT_NO | G20: Inventory sublot No. | H20: 在庫サブロットＮＯ
A21: 10 | D21: peg_no | E21: #MA.INT | G21: Pegging No. | H21: 紐付けＮＯ
A22: 10 | D22: err_flg | E22: #MA.FLG | G22: Error flg. | H22: エラーＦＬＧ

Sheet 来歴
A1: 変更来歴
A3: Rev. | H3: 修正番号 | O3: 変更内容 | AQ3: 変更箇所
A4: 1 | O4: 初版
A5: 1.1 | O5: 英語の名称を追記 | AQ5: 全般
