Workbook

Sheet LogicCommon
A2: オペレーション実装仕様書 | B2: ModuleID : | C2: MS | D2: LogicID : | E2: MSBDL4010 | F2: Pj.ID : | G2: MC
B3: SubModuleID : | C3: MSBD | D3: LogicClass : | E3: MSBDL_PoCrctRsnReg | F3: SuperClassPj.ID :
D4: LogicName : | E4: 発注訂正理由登録 | F4: SuperLogicID : | G4: MS.MSUDL5010
A5: 概要 :
A6: 詳細 :

Sheet PoCrctRsn_UpdChk01
A1: * | B1: * | D1: L | E1: 1
A2: * | D2: オペレーション実装仕様書 Operation Specification Implementation Sheet | E2: ModuleID : | F2: =IF(LogicCommon!C2="","",LogicCommon!C2) -> MS | G2: LogicID : | H2: =IF(LogicCommon!E2="","",LogicCommon!E2) -> MSBDL4010 | I2: Ope.ID : | J2: PoCrctRsn_UpdChk01 | K2: Pj.ID : | L2: =IF(LogicCommon!G2="","",LogicCommon!G2) -> MC | M2: Ope.Body : | N2: MA.MAUDL5010.Checker
A3: * | D3: =IF(LogicCommon!A3="","",LogicCommon!A3) | E3: SubModuleID : | F3: =IF(LogicCommon!C3="","",LogicCommon!C3) -> MSBD | G3: LogicClass : | H3: =IF(LogicCommon!E3="","",LogicCommon!E3) -> MSBDL_PoCrctRsnReg | I3: Ope.Method : | J3: @ | K3: SuperClassPj.ID : | L3: =IF(LogicCommon!G3="","",LogicCommon!G3) | O3: Gene.Type : | P3: ALL
A4: * | E4: Version : | F4: 000000 | G4: LogicName : | H4: =IF(LogicCommon!E4="","",LogicCommon!E4) -> 発注訂正理由登録 | I4: Ope.Name : | J4: 更新前チェック | K4: SuperLogicID : | L4: =IF(LogicCommon!G4="","",LogicCommon!G4) -> MS.MSUDL5010 | M4: ImplOpe.ID:
A5: * | E5: ACType :
A6: * | D6: 概要 : | E6: 発注訂正理由の登録前のチェックを行います。 | Q6: ID | S6: ID | U6: ID
A7: # | I7: U | K7: K | L7: K | M7: K | N7: K | O7: K | P7: o | R7: o | T7: o
A8: # | D8: ブロック名 Block Name | E8: 型 Type | G8: super/share | H8: 対象ブロック名 Target Block Name | K8: REQUIRED | L8: LIST_LOGIC | M8: LIST_OUT | N8: LIST_OUT_BASE | O8: CONST | P8: TargetName | R8: TargetName | T8: TargetName | X8: ブロック備考 Block Remarks
A9: # | D9: 項目名 Field Name | E9: 型 Type | F9: 桁 Digits | G9: フルネーム Full Name | H9: 日本語名 Japanese Name | I9: 上り項目 Request Message Field | J9: 下り項目 Response Message Field | V9: 条件および編集方法 Conditions and Editing Methods | X9: 項目備考 Field Remarks
A10: # | P10: 上り項目 Request Message Field | Q10: 下り項目 Response Message Field | R10: 上り項目 Request Message Field | S10: 下り項目 Response Message Field | T10: 上り項目 Request Message Field | U10: 下り項目 Response Message Field
A11: 10 | B11: * | D11: PoCrctRsn_UpdChk01_Dtl | E11: L | G11: $super$ | H11: DBC:MS.MST_PO_CRCT_RSN
A12: 10 | D12: po_crct_rsn_cd | E12: #MS.PO_CRCT_RSN_CD | G12: PO correction reason | H12: 発注訂正理由 | I12: E | K12: E
A13: 10 | D13: po_crct_rsn_nm | E13: #MS.PO_CRCT_RSN_NM | G13: PO correction reason name | H13: 発注訂正理由名 | I13: E | K13: E
A14: 10 | D14: po_crct_rsn_rmrks | E14: #MS.PO_CRCT_RSN_RMRKS | G14: PO correction reason remarks | H14: 発注訂正理由備考 | I14: E
A15: 10 | D15: upri_mod_typ | E15: #MS.UPRI_MOD_TYP | G15: Unit price correction reason type | H15: 単価訂正理由区分 | I15: E | K15: E | O15: MSC_UPRI_MOD_TYP
A16: 10 | D16: memo1 | E16: #MA.MST_MEMO1 | G16: Memo 1 | H16: メモ１ | I16: E
A17: 10 | D17: memo2 | E17: #MA.MST_MEMO2 | G17: Memo 2 | H17: メモ２ | I17: E
A18: 10 | D18: memo3 | E18: #MA.MST_MEMO3 | G18: Memo 3 | H18: メモ３ | I18: E
A19: 10 | D19: del_flg | E19: #MA.FLG | G19: Logical delete | H19: 論理削除 | I19: E
A20: 10 | D20: upd_cntr | E20: #MA.UPD_CNT | G20: Update counter | H20: 更新カウンタ | I20: E

Sheet PoCrctRsn_Upd01
A1: * | B1: * | D1: L | E1: 1
A2: * | D2: オペレーション実装仕様書 Operation Specification Implementation Sheet | E2: ModuleID : | F2: =IF(LogicCommon!C2="","",LogicCommon!C2) -> MS | G2: LogicID : | H2: =IF(LogicCommon!E2="","",LogicCommon!E2) -> MSBDL4010 | I2: Ope.ID : | J2: PoCrctRsn_Upd01 | K2: Pj.ID : | L2: =IF(LogicCommon!G2="","",LogicCommon!G2) -> MC | M2: Ope.Body : | N2: "mcframe.serverMAUD.MAUDL5030.MAUDL_RLUpdater"
A3: * | D3: =IF(LogicCommon!A3="","",LogicCommon!A3) | E3: SubModuleID : | F3: =IF(LogicCommon!C3="","",LogicCommon!C3) -> MSBD | G3: LogicClass : | H3: =IF(LogicCommon!E3="","",LogicCommon!E3) -> MSBDL_PoCrctRsnReg | I3: Ope.Method : | J3: @ | K3: SuperClassPj.ID : | L3: =IF(LogicCommon!G3="","",LogicCommon!G3) | O3: Gene.Type : | P3: ALL
A4: * | E4: Version : | F4: 000000 | G4: LogicName : | H4: =IF(LogicCommon!E4="","",LogicCommon!E4) -> 発注訂正理由登録 | I4: Ope.Name : | J4: 更新 | K4: SuperLogicID : | L4: =IF(LogicCommon!G4="","",LogicCommon!G4) -> MS.MSUDL5010 | M4: ImplOpe.ID:
A5: * | E5: ACType :
A6: * | D6: 概要 : | E6: 発注訂正理由の登録を行います。 | M6: ID | O6: ID | Q6: ID
A7: # | I7: U | K7: K | L7: o | M7: UPDATE.updMaster | N7: o | O7: MAIN.chkMaster | P7: o
A8: # | D8: ブロック名 Block Name | E8: 型 Type | G8: super/share | H8: 対象ブロック名 Target Block Name | L8: TargetName | M8: DBC.MS.MST_PO_CRCT_RSN | N8: TargetName | O8: DBC.MS.MST_PO_CRCT_RSN | P8: TargetName | T8: ブロック備考 Block Remarks
A9: # | D9: 項目名 Field Name | E9: 型 Type | F9: 桁 Digits | G9: フルネーム Full Name | H9: 日本語名 Japanese Name | I9: 上り項目 Request Message Field | J9: 下り項目 Response Message Field | R9: 条件および編集方法 Conditions and Editing Methods | T9: 項目備考 Field Remarks
A10: # | L10: 上り項目 Request Message Field | M10: 下り項目 Response Message Field | N10: 上り項目 Request Message Field | O10: 下り項目 Response Message Field | P10: 上り項目 Request Message Field | Q10: 下り項目 Response Message Field
A11: 10 | B11: * | D11: PoCrctRsn_Upd01_Dtl | E11: L | G11: $share$ | H11: MS.MSBDL4010.PoCrctRsn_UpdChk01.PoCrctRsn_UpdChk01_Dtl | L11: L | N11: L
A12: 10 | D12: po_crct_rsn_cd | E12: #MS.PO_CRCT_RSN_CD | G12: PO correction reason | H12: 発注訂正理由 | I12: E | L12: E | N12: E
A13: 10 | D13: po_crct_rsn_nm | E13: #MS.PO_CRCT_RSN_NM | G13: PO correction reason name | H13: 発注訂正理由名 | I13: E | L13: E | N13: E
A14: 10 | D14: po_crct_rsn_rmrks | E14: #MS.PO_CRCT_RSN_RMRKS | G14: PO correction reason remarks | H14: 発注訂正理由備考 | I14: E | L14: E | N14: E
A15: 10 | D15: upri_mod_typ | E15: #MS.UPRI_MOD_TYP | G15: Unit price correction reason type | H15: 単価訂正理由区分 | I15: E | L15: E | N15: E
A16: 10 | D16: memo1 | E16: #MA.MST_MEMO1 | G16: Memo 1 | H16: メモ１ | I16: E | L16: E
A17: 10 | D17: memo2 | E17: #MA.MST_MEMO2 | G17: Memo 2 | H17: メモ２ | I17: E | L17: E
A18: 10 | D18: memo3 | E18: #MA.MST_MEMO3 | G18: Memo 3 | H18: メモ３ | I18: E | L18: E
A19: 10 | D19: del_flg | E19: #MA.FLG | G19: Logical delete | H19: 論理削除 | I19: E | L19: E
A20: 10 | D20: upd_cntr | E20: #MA.UPD_CNT | G20: Update counter | H20: 更新カウンタ | I20: E | L20: E

Sheet PoCrctRsn_DelChk01
A1: * | B1: * | D1: L | E1: 1
A2: * | D2: オペレーション実装仕様書 Operation Specification Implementation Sheet | E2: ModuleID : | F2: =IF(LogicCommon!C2="","",LogicCommon!C2) -> MS | G2: LogicID : | H2: =IF(LogicCommon!E2="","",LogicCommon!E2) -> MSBDL4010 | I2: Ope.ID : | J2: PoCrctRsn_DelChk01 | K2: Pj.ID : | L2: =IF(LogicCommon!G2="","",LogicCommon!G2) -> MC | M2: Ope.Body : | N2: MA.MAUDL5010.Checker
A3: * | D3: =IF(LogicCommon!A3="","",LogicCommon!A3) | E3: SubModuleID : | F3: =IF(LogicCommon!C3="","",LogicCommon!C3) -> MSBD | G3: LogicClass : | H3: =IF(LogicCommon!E3="","",LogicCommon!E3) -> MSBDL_PoCrctRsnReg | I3: Ope.Method : | J3: @ | K3: SuperClassPj.ID : | L3: =IF(LogicCommon!G3="","",LogicCommon!G3) | O3: Gene.Type : | P3: ALL
A4: * | E4: Version : | F4: 000000 | G4: LogicName : | H4: =IF(LogicCommon!E4="","",LogicCommon!E4) -> 発注訂正理由登録 | I4: Ope.Name : | J4: 削除前チェック | K4: SuperLogicID : | L4: =IF(LogicCommon!G4="","",LogicCommon!G4) -> MS.MSUDL5010 | M4: ImplOpe.ID:
A5: * | E5: ACType :
A6: * | D6: 概要 : | E6: 発注訂正理由の削除前のチェックを行います。 | M6: ID | O6: ID | Q6: ID
A7: # | I7: U | K7: K | L7: o | N7: o | P7: o
A8: # | D8: ブロック名 Block Name | E8: 型 Type | G8: super/share | H8: 対象ブロック名 Target Block Name | K8: REQUIRED | L8: TargetName | N8: TargetName | P8: TargetName | T8: ブロック備考 Block Remarks
A9: # | D9: 項目名 Field Name | E9: 型 Type | F9: 桁 Digits | G9: フルネーム Full Name | H9: 日本語名 Japanese Name | I9: 上り項目 Request Message Field | J9: 下り項目 Response Message Field | R9: 条件および編集方法 Conditions and Editing Methods | T9: 項目備考 Field Remarks
A10: # | L10: 上り項目 Request Message Field | M10: 下り項目 Response Message Field | N10: 上り項目 Request Message Field | O10: 下り項目 Response Message Field | P10: 上り項目 Request Message Field | Q10: 下り項目 Response Message Field
A11: 10 | B11: * | D11: PoCrctRsn_DelChk01_Dtl | E11: L
A12: 10 | D12: po_crct_rsn_cd | E12: #MS.PO_CRCT_RSN_CD | G12: PO correction reason | H12: 発注訂正理由 | I12: E | K12: E
A13: 10 | D13: upd_cntr | E13: #MA.UPD_CNT | G13: Update counter | H13: 更新カウンタ | I13: E

Sheet PoCrctRsn_Del01
A1: * | B1: * | D1: L | E1: 1
A2: * | D2: オペレーション実装仕様書 Operation Specification Implementation Sheet | E2: ModuleID : | F2: =IF(LogicCommon!C2="","",LogicCommon!C2) -> MS | G2: LogicID : | H2: =IF(LogicCommon!E2="","",LogicCommon!E2) -> MSBDL4010 | I2: Ope.ID : | J2: PoCrctRsn_Del01 | K2: Pj.ID : | L2: =IF(LogicCommon!G2="","",LogicCommon!G2) -> MC | M2: Ope.Body : | N2: "mcframe.serverMAUD.MAUDL5030.MAUDL_RLDeleter"
A3: * | D3: =IF(LogicCommon!A3="","",LogicCommon!A3) | E3: SubModuleID : | F3: =IF(LogicCommon!C3="","",LogicCommon!C3) -> MSBD | G3: LogicClass : | H3: =IF(LogicCommon!E3="","",LogicCommon!E3) -> MSBDL_PoCrctRsnReg | I3: Ope.Method : | J3: @ | K3: SuperClassPj.ID : | L3: =IF(LogicCommon!G3="","",LogicCommon!G3) | O3: Gene.Type : | P3: ALL
A4: * | E4: Version : | F4: 000000 | G4: LogicName : | H4: =IF(LogicCommon!E4="","",LogicCommon!E4) -> 発注訂正理由登録 | I4: Ope.Name : | J4: 削除 | K4: SuperLogicID : | L4: =IF(LogicCommon!G4="","",LogicCommon!G4) -> MS.MSUDL5010 | M4: ImplOpe.ID:
A5: * | E5: ACType :
A6: * | D6: 概要 : | M6: ID | O6: ID | Q6: ID
A7: # | I7: U | K7: K | L7: o | M7: UPDATE.updMaster1 | N7: o | P7: o
A8: # | D8: ブロック名 Block Name | E8: 型 Type | G8: super/share | H8: 対象ブロック名 Target Block Name | L8: TargetName | M8: DBC.MS.MST_PO_CRCT_RSN | N8: TargetName | P8: TargetName | T8: ブロック備考 Block Remarks
A9: # | D9: 項目名 Field Name | E9: 型 Type | F9: 桁 Digits | G9: フルネーム Full Name | H9: 日本語名 Japanese Name | I9: 上り項目 Request Message Field | J9: 下り項目 Response Message Field | R9: 条件および編集方法 Conditions and Editing Methods | T9: 項目備考 Field Remarks
A10: # | L10: 上り項目 Request Message Field | M10: 下り項目 Response Message Field | N10: 上り項目 Request Message Field | O10: 下り項目 Response Message Field | P10: 上り項目 Request Message Field | Q10: 下り項目 Response Message Field
A11: 10 | B11: * | D11: PoCrctRsn_Del01_Dtl | E11: L | G11: $share$ | H11: MS.MSBDL4010.PoCrctRsn_DelChk01.PoCrctRsn_DelChk01_Dtl | L11: L
A12: 10 | D12: po_crct_rsn_cd | E12: #MS.PO_CRCT_RSN_CD | G12: PO correction reason | H12: 発注訂正理由 | I12: E | L12: E
A13: 10 | D13: upd_cntr | E13: #MA.UPD_CNT | G13: Update counter | H13: 更新カウンタ | I13: E | L13: E

Sheet Srch01
A1: * | B1: * | D1: L | E1: 1
A2: * | D2: オペレーション実装仕様書 Operation Specification Implementation Sheet | E2: ModuleID : | F2: =IF(LogicCommon!C2="","",LogicCommon!C2) -> MS | G2: LogicID : | H2: =IF(LogicCommon!E2="","",LogicCommon!E2) -> MSBDL4010 | I2: Ope.ID : | J2: Srch01 | K2: Pj.ID : | L2: =IF(LogicCommon!G2="","",LogicCommon!G2) -> MC | M2: Ope.Body : | N2: "mcframe.serverMAUD.MAUDL5030.MAUDL_RLSearcher"
A3: * | D3: =IF(LogicCommon!A3="","",LogicCommon!A3) | E3: SubModuleID : | F3: =IF(LogicCommon!C3="","",LogicCommon!C3) -> MSBD | G3: LogicClass : | H3: =IF(LogicCommon!E3="","",LogicCommon!E3) -> MSBDL_PoCrctRsnReg | I3: Ope.Method : | J3: @ | K3: SuperClassPj.ID : | L3: =IF(LogicCommon!G3="","",LogicCommon!G3) | O3: Gene.Type : | P3: ALL
A4: * | E4: Version : | F4: 000000 | G4: LogicName : | H4: =IF(LogicCommon!E4="","",LogicCommon!E4) -> 発注訂正理由登録 | I4: Ope.Name : | J4: 検索 | K4: SuperLogicID : | L4: =IF(LogicCommon!G4="","",LogicCommon!G4) -> MS.MSUDL5010 | M4: ImplOpe.ID:
A5: * | E5: ACType :
A6: * | D6: 概要 : | E6: 発注訂正理由の検索を行います。 | M6: ID | O6: ID | Q6: ID
A7: # | I7: U | K7: K | L7: o | M7: SELECT.c0 | N7: o | P7: o
A8: # | D8: ブロック名 Block Name | E8: 型 Type | G8: super/share | H8: 対象ブロック名 Target Block Name | K8: CONST | L8: TargetName | M8: DBC.MS.MST_PO_CRCT_RSN | N8: TargetName | P8: TargetName | T8: ブロック備考 Block Remarks
A9: # | D9: 項目名 Field Name | E9: 型 Type | F9: 桁 Digits | G9: フルネーム Full Name | H9: 日本語名 Japanese Name | I9: 上り項目 Request Message Field | J9: 下り項目 Response Message Field | R9: 条件および編集方法 Conditions and Editing Methods | T9: 項目備考 Field Remarks
A10: # | L10: 上り項目 Request Message Field | M10: 下り項目 Response Message Field | N10: 上り項目 Request Message Field | O10: 下り項目 Response Message Field | P10: 上り項目 Request Message Field | Q10: 下り項目 Response Message Field
A11: 10 | B11: * | D11: Srch01_Cnd | E11: R | L11: R
A12: 10 | D12: po_crct_rsn_cd | E12: #MS.PO_CRCT_RSN_CD | G12: PO correction reason | H12: 発注訂正理由 | I12: E
A13: 10 | D13: po_crct_rsn_nm | E13: #MS.PO_CRCT_RSN_NM | G13: PO correction reason name | H13: 発注訂正理由名 | I13: E
A14: 10 | D14: off_del_flg | E14: #MA.FLG | G14: Logical delete flg. (Off) | H14: 論理削除ＦＬＧ（オフ） | I14: E
A15: 10 | D15: on_del_flg | E15: #MA.FLG | G15: Logical delete flg. (On) | H15: 論理削除ＦＬＧ（オン） | I15: E
A16: 10 | D16: memo1 | E16: #MA.MST_MEMO1 | G16: Memo 1 | H16: メモ１ | I16: E
A17: 10 | D17: memo2 | E17: #MA.MST_MEMO2 | G17: Memo 2 | H17: メモ２ | I17: E
A18: 10 | D18: memo3 | E18: #MA.MST_MEMO3 | G18: Memo 3 | H18: メモ３ | I18: E
A20: 20 | B20: * | D20: Srch01_Rslt | E20: L | M20: L
A21: 20 | D21: po_crct_rsn_cd | E21: #MS.PO_CRCT_RSN_CD | G21: PO correction reason | H21: 発注訂正理由 | J21: E | M21: E
A22: 20 | D22: po_crct_rsn_nm | E22: #MS.PO_CRCT_RSN_NM | G22: PO correction reason name | H22: 発注訂正理由名 | J22: E | M22: E
A23: 20 | D23: del_flg | E23: #MA.FLG | G23: Logical delete | H23: 論理削除 | J23: E | M23: E
A24: 20 | D24: po_crct_rsn_rmrks | E24: #MS.PO_CRCT_RSN_RMRKS | G24: PO correction reason remarks | H24: 発注訂正理由備考 | J24: E | M24: E
A25: 20 | D25: upri_mod_typ | E25: #MS.UPRI_MOD_TYP | G25: Unit price correction reason type | H25: 単価訂正理由区分 | J25: E | K25: MSC_UPRI_MOD_TYP | M25: E
A26: 20 | D26: upri_mod_typ_nm | E26: #MS.UPRI_MOD_TYP_NM | G26: Reason type name for unit price correction | H26: 単価訂正理由区分名 | J26: E
A27: 20 | D27: memo1 | E27: #MA.MST_MEMO1 | G27: Memo 1 | H27: メモ１ | J27: E | M27: E
A28: 20 | D28: memo2 | E28: #MA.MST_MEMO2 | G28: Memo 2 | H28: メモ２ | J28: E | M28: E
A29: 20 | D29: memo3 | E29: #MA.MST_MEMO3 | G29: Memo 3 | H29: メモ３ | J29: E | M29: E
A30: 20 | D30: ins_usr_id | E30: #MA.FCM_USR_ID | G30: Entry user ID | H30: 登録ユーザＩＤ | J30: E | M30: E
A31: 20 | D31: ins_usr_nm | E31: #MA.FCM_USR_NM | G31: Entry user name | H31: 登録ユーザ名 | J31: E | M31: E
A32: 20 | D32: ins_ts | E32: #MA.SYS_TS | G32: Entry date and time | H32: 登録日時 | J32: E | M32: E
A33: 20 | D33: ins_func_id | E33: #MA.FUNC_ID | G33: Entry function ID | H33: 登録機能ＩＤ | J33: E | M33: E
A34: 20 | D34: ins_func_nm | E34: #MA.FUNC_NM | G34: Entry function name | H34: 登録機能名 | J34: E
A35: 20 | D35: upd_cntr | E35: #MA.UPD_CNT | G35: Update counter | H35: 更新カウンタ | J35: E | M35: E
A36: 20 | D36: upd_usr_id | E36: #MA.FCM_USR_ID | G36: Update user ID | H36: 更新ユーザＩＤ | J36: E | M36: E
A37: 20 | D37: upd_usr_nm | E37: #MA.FCM_USR_NM | G37: Update user name | H37: 更新ユーザ名 | J37: E | M37: E
A38: 20 | D38: upd_ts | E38: #MA.SYS_TS | G38: Update date and time | H38: 更新日時 | J38: E | M38: E
A39: 20 | D39: upd_func_id | E39: #MA.FUNC_ID | G39: Update function ID | H39: 更新機能ＩＤ | J39: E | M39: E
A40: 20 | D40: upd_func_nm | E40: #MA.FUNC_NM | G40: Update function name | H40: 更新機能名 | J40: E
A41: 20 | D41: upd_srv_req_no | E41: #MA.SRV_REQ_NO | G41: Update request No. | H41: 更新リクエストＮＯ | J41: E | M41: E
...

Sheet Upd01
A1: * | B1: * | D1: L | E1: 1
A2: * | D2: オペレーション実装仕様書 Operation Specification Implementation Sheet | E2: ModuleID : | F2: =IF(LogicCommon!C2="","",LogicCommon!C2) -> MS | G2: LogicID : | H2: =IF(LogicCommon!E2="","",LogicCommon!E2) -> MSBDL4010 | I2: Ope.ID : | J2: Upd01 | K2: Pj.ID : | L2: =IF(LogicCommon!G2="","",LogicCommon!G2) -> MC | M2: Ope.Body : | N2: "mcframe.serverMAUD.MAUDL5030.MAUDL_RLUpdater"
A3: * | D3: =IF(LogicCommon!A3="","",LogicCommon!A3) | E3: SubModuleID : | F3: =IF(LogicCommon!C3="","",LogicCommon!C3) -> MSBD | G3: LogicClass : | H3: =IF(LogicCommon!E3="","",LogicCommon!E3) -> MSBDL_PoCrctRsnReg | I3: Ope.Method : | J3: @ | K3: SuperClassPj.ID : | L3: =IF(LogicCommon!G3="","",LogicCommon!G3) | O3: Gene.Type : | P3: ALL
A4: * | E4: Version : | F4: 000000 | G4: LogicName : | H4: =IF(LogicCommon!E4="","",LogicCommon!E4) -> 発注訂正理由登録 | I4: Ope.Name : | J4: 更新 | K4: SuperLogicID : | L4: =IF(LogicCommon!G4="","",LogicCommon!G4) -> MS.MSUDL5010 | M4: ImplOpe.ID:
A5: * | E5: ACType :
A6: * | D6: 概要 : | E6: 発注訂正理由の登録を行います。 | M6: ID | O6: ID | Q6: ID
A7: # | I7: U | K7: K | L7: o | M7: CALL_OPE01.chk01 | N7: o | O7: CALL_OPE01.upd01 | P7: o
A8: # | D8: ブロック名 Block Name | E8: 型 Type | G8: super/share | H8: 対象ブロック名 Target Block Name | L8: TargetName | M8: OPE.MS.MSBDL4010.PoCrctRsn_UpdChk01 | N8: TargetName | O8: OPE.MS.MSBDL4010.PoCrctRsn_Upd01 | P8: TargetName | T8: ブロック備考 Block Remarks
A9: # | D9: 項目名 Field Name | E9: 型 Type | F9: 桁 Digits | G9: フルネーム Full Name | H9: 日本語名 Japanese Name | I9: 上り項目 Request Message Field | J9: 下り項目 Response Message Field | R9: 条件および編集方法 Conditions and Editing Methods | T9: 項目備考 Field Remarks
A10: # | L10: 上り項目 Request Message Field | M10: 下り項目 Response Message Field | N10: 上り項目 Request Message Field | O10: 下り項目 Response Message Field | P10: 上り項目 Request Message Field | Q10: 下り項目 Response Message Field
A11: 10 | B11: * | D11: Upd01_Dtl | E11: L | G11: $share$ | H11: MS.MSBDL4010.PoCrctRsn_UpdChk01.PoCrctRsn_UpdChk01_Dtl | L11: PoCrctRsn_UpdChk01_Dtl | N11: PoCrctRsn_Upd01_Dtl
A12: 10 | D12: po_crct_rsn_cd | E12: #MS.PO_CRCT_RSN_CD | G12: PO correction reason | H12: 発注訂正理由 | I12: E | L12: E | N12: E
A13: 10 | D13: po_crct_rsn_nm | E13: #MS.PO_CRCT_RSN_NM | G13: PO correction reason name | H13: 発注訂正理由名 | I13: E | L13: E | N13: E
A14: 10 | D14: po_crct_rsn_rmrks | E14: #MS.PO_CRCT_RSN_RMRKS | G14: PO correction reason remarks | H14: 発注訂正理由備考 | I14: E | L14: E | N14: E
A15: 10 | D15: upri_mod_typ | E15: #MS.UPRI_MOD_TYP | G15: Unit price correction reason type | H15: 単価訂正理由区分 | I15: E | L15: E | N15: E
A16: 10 | D16: memo1 | E16: #MA.MST_MEMO1 | G16: Memo 1 | H16: メモ１ | I16: E | L16: E | N16: E
A17: 10 | D17: memo2 | E17: #MA.MST_MEMO2 | G17: Memo 2 | H17: メモ２ | I17: E | L17: E | N17: E
A18: 10 | D18: memo3 | E18: #MA.MST_MEMO3 | G18: Memo 3 | H18: メモ３ | I18: E | L18: E | N18: E
A19: 10 | D19: del_flg | E19: #MA.FLG | G19: Logical delete | H19: 論理削除 | I19: E | L19: E | N19: E
A20: 10 | D20: upd_cntr | E20: #MA.UPD_CNT | G20: Update counter | H20: 更新カウンタ | I20: E | L20: E | N20: E

Sheet Del01
A1: * | B1: * | D1: L | E1: 1
A2: * | D2: オペレーション実装仕様書 Operation Specification Implementation Sheet | E2: ModuleID : | F2: =IF(LogicCommon!C2="","",LogicCommon!C2) -> MS | G2: LogicID : | H2: =IF(LogicCommon!E2="","",LogicCommon!E2) -> MSBDL4010 | I2: Ope.ID : | J2: Del01 | K2: Pj.ID : | L2: =IF(LogicCommon!G2="","",LogicCommon!G2) -> MC | M2: Ope.Body : | N2: "mcframe.serverMAUD.MAUDL5030.MAUDL_RLDeleter"
A3: * | D3: =IF(LogicCommon!A3="","",LogicCommon!A3) | E3: SubModuleID : | F3: =IF(LogicCommon!C3="","",LogicCommon!C3) -> MSBD | G3: LogicClass : | H3: =IF(LogicCommon!E3="","",LogicCommon!E3) -> MSBDL_PoCrctRsnReg | I3: Ope.Method : | J3: @ | K3: SuperClassPj.ID : | L3: =IF(LogicCommon!G3="","",LogicCommon!G3) | O3: Gene.Type : | P3: ALL
A4: * | E4: Version : | F4: 000000 | G4: LogicName : | H4: =IF(LogicCommon!E4="","",LogicCommon!E4) -> 発注訂正理由登録 | I4: Ope.Name : | J4: 削除 | K4: SuperLogicID : | L4: =IF(LogicCommon!G4="","",LogicCommon!G4) -> MS.MSUDL5010 | M4: ImplOpe.ID:
A5: * | E5: ACType :
A6: * | D6: 概要 : | M6: ID | O6: ID | Q6: ID
A7: # | I7: U | K7: K | L7: o | M7: CALL_OPE01.chk01 | N7: o | O7: CALL_OPE01.del01 | P7: o
A8: # | D8: ブロック名 Block Name | E8: 型 Type | G8: super/share | H8: 対象ブロック名 Target Block Name | L8: TargetName | M8: OPE.MS.MSBDL4010.PoCrctRsn_DelChk01 | N8: TargetName | O8: OPE.MS.MSBDL4010.PoCrctRsn_Del01 | P8: TargetName | T8: ブロック備考 Block Remarks
A9: # | D9: 項目名 Field Name | E9: 型 Type | F9: 桁 Digits | G9: フルネーム Full Name | H9: 日本語名 Japanese Name | I9: 上り項目 Request Message Field | J9: 下り項目 Response Message Field | R9: 条件および編集方法 Conditions and Editing Methods | T9: 項目備考 Field Remarks
A10: # | L10: 上り項目 Request Message Field | M10: 下り項目 Response Message Field | N10: 上り項目 Request Message Field | O10: 下り項目 Response Message Field | P10: 上り項目 Request Message Field | Q10: 下り項目 Response Message Field
A11: 10 | B11: * | D11: Del01_Dtl | E11: L | G11: $share$ | H11: MS.MSBDL4010.PoCrctRsn_DelChk01.PoCrctRsn_DelChk01_Dtl | L11: PoCrctRsn_DelChk01_Dtl | N11: PoCrctRsn_Del01_Dtl
A12: 10 | D12: po_crct_rsn_cd | E12: #MS.PO_CRCT_RSN_CD | G12: PO correction reason | H12: 発注訂正理由 | I12: E | L12: E | N12: E
A13: 10 | D13: upd_cntr | E13: #MA.UPD_CNT | G13: Update counter | H13: 更新カウンタ | I13: E | L13: E | N13: E

Sheet 来歴
A1: 変更来歴
A3: Rev. | H3: 修正番号 | O3: 変更内容 | AQ3: 変更箇所
A4: 1 | O4: 初版
A5: 1.1 | O5: 英語の名称を追記 | AQ5: 全般
