Workbook

Sheet LogicCommon
A2: オペレーション実装仕様書 | B2: ModuleID : | C2: MS | D2: LogicID : | E2: MSBDL5240 | F2: Pj.ID : | G2: MC
B3: SubModuleID : | C3: MSBD | D3: LogicClass : | E3: MSBDL_PurcDscntRegService | F3: SuperClassPj.ID :
D4: LogicName : | E4: 仕入値引登録サービス | F4: SuperLogicID : | G4: MS.MSUDL5010
A5: 概要 : | B5: 仕入値引情報のの登録、更新、削除に関する処理を行う。
A6: 詳細 :

Sheet PurcDscnt_Ins01
A1: * | B1: * | D1: L | E1: 1
A2: * | D2: オペレーション実装仕様書 Operation Specification Implementation Sheet | E2: ModuleID : | F2: =IF(LogicCommon!C2="","",LogicCommon!C2) -> MS | G2: LogicID : | H2: =IF(LogicCommon!E2="","",LogicCommon!E2) -> MSBDL5240 | I2: Ope.ID : | J2: PurcDscnt_Ins01 | K2: Pj.ID : | L2: =IF(LogicCommon!G2="","",LogicCommon!G2) -> MC | M2: Ope.Body : | N2: "mcframe.serverMAUD.MAUDL5010.MAUDL_Operation"
A3: * | D3: =IF(LogicCommon!A3="","",LogicCommon!A3) | E3: SubModuleID : | F3: =IF(LogicCommon!C3="","",LogicCommon!C3) -> MSBD | G3: LogicClass : | H3: =IF(LogicCommon!E3="","",LogicCommon!E3) -> MSBDL_PurcDscntRegService | I3: Ope.Method : | J3: PurcDscnt_Ins01 | K3: SuperClassPj.ID : | L3: =IF(LogicCommon!G3="","",LogicCommon!G3) | O3: Gene.Type : | P3: ALL
A4: * | E4: Version : | F4: 000000 | G4: LogicName : | H4: =IF(LogicCommon!E4="","",LogicCommon!E4) -> 仕入値引登録サービス | I4: Ope.Name : | J4: 登録 | K4: SuperLogicID : | L4: =IF(LogicCommon!G4="","",LogicCommon!G4) -> MS.MSUDL5010 | M4: ImplOpe.ID:
A5: * | E5: ACType :
A6: * | D6: 概要 : | E6: 仕入値引登録処理を実行します。 | M6: ID | O6: ID | Q6: ID
A7: # | I7: U | K7: K | L7: o | N7: o | P7: o
A8: # | D8: ブロック名 Block Name | E8: 型 Type | G8: super/share | H8: 対象ブロック名 Target Block Name | L8: TargetName | N8: TargetName | P8: TargetName | T8: ブロック備考 Block Remarks
A9: # | D9: 項目名 Field Name | E9: 型 Type | F9: 桁 Digits | G9: フルネーム Full Name | H9: 日本語名 Japanese Name | I9: 上り項目 Request Message Field | J9: 下り項目 Response Message Field | R9: 条件および編集方法 Conditions and Editing Methods | T9: 項目備考 Field Remarks
A10: # | L10: 上り項目 Request Message Field | M10: 下り項目 Response Message Field | N10: 上り項目 Request Message Field | O10: 下り項目 Response Message Field | P10: 上り項目 Request Message Field | Q10: 下り項目 Response Message Field
A11: 10 | B11: * | D11: PurcDscnt_Ins01_Hdr | E11: L
A12: 10 | D12: peg_no | E12: #MA.INT | G12: Pegging No. | H12: 紐付けＮＯ | I12: E | J12: -
A13: 10 | D13: err_flg | E13: #MA.FLG | G13: Error | H13: エラー | I13: E | J13: -
A14: 10 | D14: data_crud_typ | E14: #MA.DATA_CRUD_TYP | G14: Data update type | H14: データ更新区分 | I14: E | J14: -
A15: 10 | D15: trd_cd | E15: #MA.TRD_CD | G15: Transaction cd. | H15: 取引ＣＤ | I15: E | J15: -
A16: 10 | D16: trd_ptn_typ | E16: #MA.TRD_PTN_TYP | G16: Transaction pattern type | H16: 取引パタン区分 | I16: E | J16: -
A17: 10 | D17: purc_act_no | E17: #MA.PURC_ACT_NO | G17: Purchase result No. | H17: 仕入実績ＮＯ | I17: E | J17: E
A18: 10 | D18: purc_act_seq | E18: #MA.SLIP_SEQ | G18: Purchase result sequence number | H18: 仕入実績連番 | I18: E | J18: -
A19: 10 | D19: purc_act_rev | E19: #MA.SLIP_REV | G19: Purchase result rev. number | H19: 仕入実績改訂番号 | I19: E | J19: E
A20: 10 | D20: slip_sts_typ | E20: #MA.SLIP_STS_TYP | G20: Slip status type | H20: 伝票状況区分 | I20: E | J20: -
A21: 10 | D21: purc_dpt_cd | E21: #MA.DPT_CD | G21: Purchasing dept. cd. | H21: 購買部門ＣＤ | I21: E | J21: -
A22: 10 | D22: wg_cd | E22: #MA.WG_CD | G22: WG cd. | H22: ワーキンググループＣＤ | I22: E | J22: -
A23: 10 | D23: purc_usr_cd | E23: #MA.USR_CD | G23: Purchasing PIC cd. | H23: 購買担当者ＣＤ | I23: E | J23: -
... A64: 10 | D64: upd_cntr | E64: #MA.INT | G64: Update counter | H64: 更新カウンタ | I64: E | J64: -
A65: 10 | D65: amt_calc_flg | E65: #MA.FLG | I65: E | J65: -
L66: 上り項目 Request Message Field | M66: 下り項目 Response Message Field | N66: 上り項目 Request Message Field | O66: 下り項目 Response Message Field | P66: 上り項目 Request Message Field | Q66: 下り項目 Response Message Field
A67: 20 | B67: * | D67: PurcDscnt_Ins01_Dtl | E67: L
A68: 20 | D68: peg_no | E68: #MA.INT | G68: Pegging No. | H68: 紐付けＮＯ | I68: E | J68: -
A69: 20 | D69: hdr_peg_no | E69: #MA.INT | G69: Header pegging No. | H69: ヘッダ紐付ＮＯ | I69: E | J69: -
A70: 20 | D70: data_crud_typ | E70: #MA.DATA_CRUD_TYP | G70: Data update type | H70: データ更新区分 | I70: E | J70: -
A71: 20 | D71: err_flg | E71: #MA.FLG | G71: Error | H71: エラー | I71: E | J71: -
A72: 20 | D72: purc_act_d_no | E72: #MA.PURC_ACT_D_NO | G72: Purchase result details No. | H72: 仕入実績明細ＮＯ | I72: E | J72: E
A73: 20 | D73: purc_act_d_seq | E73: #MA.SLIP_SEQ | G73: Purchase result details sequence number | H73: 仕入実績明細連番 | I73: E | J73: -
A74: 20 | D74: purc_act_no | E74: #MA.PURC_ACT_NO | G74: Purchase result No. | H74: 仕入実績ＮＯ | I74: E | J74: -
A75: 20 | D75: purc_act_seq | E75: #MA.SLIP_SEQ | G75: Purchase result sequence number | H75: 仕入実績連番 | I75: E | J75: -
A76: 20 | D76: purc_act_io_no | E76: #MA.PURC_ACT_IO_NO | G76: Purchase result GR/GI No. | H76: 仕入実績受払ＮＯ | I76: E | J76: -
A77: 20 | D77: purc_act_io_seq | E77: #MA.SLIP_SEQ | G77: Purchase result GR/GI sequence number | H77: 仕入実績受払連番 | I77: E | J77: -
A78: 20 | D78: dscnt_rsn_cd | E78: #MA.BIZ_RSN_CD | G78: Discount reason cd. | H78: 値引理由ＣＤ | I78: E | J78: -
A79: 20 | D79: purc_typ | E79: #MA.PURC_TYP | G79: Purchase type | H79: 購買区分 | I79: E | J79: -
... A167: 20 | D167: disp_seq | E167: #MA.DISP_SEQ | G167: Display order | H167: 表示順 | I167: E | J167: -
...

Sheet PurcDscnt_Upd01
A1: * | B1: * | D1: L | E1: 1
A2: * | D2: オペレーション実装仕様書 Operation Specification Implementation Sheet | E2: ModuleID : | F2: =IF(LogicCommon!C2="","",LogicCommon!C2) -> MS | G2: LogicID : | H2: =IF(LogicCommon!E2="","",LogicCommon!E2) -> MSBDL5240 | I2: Ope.ID : | J2: PurcDscnt_Upd01 | K2: Pj.ID : | L2: =IF(LogicCommon!G2="","",LogicCommon!G2) -> MC | M2: Ope.Body : | N2: "mcframe.serverMAUD.MAUDL5010.MAUDL_Operation"
A3: * | D3: =IF(LogicCommon!A3="","",LogicCommon!A3) | E3: SubModuleID : | F3: =IF(LogicCommon!C3="","",LogicCommon!C3) -> MSBD | G3: LogicClass : | H3: =IF(LogicCommon!E3="","",LogicCommon!E3) -> MSBDL_PurcDscntRegService | I3: Ope.Method : | J3: PurcDscnt_Upd01 | K3: SuperClassPj.ID : | L3: =IF(LogicCommon!G3="","",LogicCommon!G3) | O3: Gene.Type : | P3: ALL
A4: * | E4: Version : | F4: 000000 | G4: LogicName : | H4: =IF(LogicCommon!E4="","",LogicCommon!E4) -> 仕入値引登録サービス | I4: Ope.Name : | J4: 更新 | K4: SuperLogicID : | L4: =IF(LogicCommon!G4="","",LogicCommon!G4) -> MS.MSUDL5010 | M4: ImplOpe.ID:
A5: * | E5: ACType :
A6: * | D6: 概要 : | E6: 仕入値引更新処理を実行します。 | M6: ID | O6: ID | Q6: ID
A7: # | I7: U | K7: K | L7: o | N7: o | P7: o
A8: # | D8: ブロック名 Block Name | E8: 型 Type | G8: super/share | H8: 対象ブロック名 Target Block Name | L8: TargetName | N8: TargetName | P8: TargetName | T8: ブロック備考 Block Remarks
A9: # | D9: 項目名 Field Name | E9: 型 Type | F9: 桁 Digits | G9: フルネーム Full Name | H9: 日本語名 Japanese Name | I9: 上り項目 Request Message Field | J9: 下り項目 Response Message Field | R9: 条件および編集方法 Conditions and Editing Methods | T9: 項目備考 Field Remarks
A10: # | L10: 上り項目 Request Message Field | M10: 下り項目 Response Message Field | N10: 上り項目 Request Message Field | O10: 下り項目 Response Message Field | P10: 上り項目 Request Message Field | Q10: 下り項目 Response Message Field
A11: 10 | B11: * | D11: PurcDscnt_Upd01_Hdr | E11: L | G11: $share$ | H11: MS.MSBDL5240.PurcDscnt_Ins01.PurcDscnt_Ins01_Hdr
A12: 10 | D12: peg_no | E12: #MA.INT | G12: Pegging No. | H12: 紐付けＮＯ | I12: E | J12: -
A13: 10 | D13: err_flg | E13: #MA.FLG | G13: Error | H13: エラー | I13: E | J13: -
A14: 10 | D14: data_crud_typ | E14: #MA.DATA_CRUD_TYP | G14: Data update type | H14: データ更新区分 | I14: E | J14: -
A15: 10 | D15: trd_cd | E15: #MA.TRD_CD | G15: Transaction cd. | H15: 取引ＣＤ | I15: E | J15: -
A16: 10 | D16: trd_ptn_typ | E16: #MA.TRD_PTN_TYP | G16: Transaction pattern type | H16: 取引パタン区分 | I16: E | J16: -
A17: 10 | D17: purc_act_no | E17: #MA.PURC_ACT_NO | G17: Purchase result No. | H17: 仕入実績ＮＯ | I17: E | J17: E
A18: 10 | D18: purc_act_seq | E18: #MA.SLIP_SEQ | G18: Purchase result sequence number | H18: 仕入実績連番 | I18: E | J18: -
A19: 10 | D19: purc_act_rev | E19: #MA.SLIP_REV | G19: Purchase result rev. number | H19: 仕入実績改訂番号 | I19: E | J19: E
A20: 10 | D20: slip_sts_typ | E20: #MA.SLIP_STS_TYP | G20: Slip status type | H20: 伝票状況区分 | I20: E | J20: -
A21: 10 | D21: purc_dpt_cd | E21: #MA.DPT_CD | G21: Purchasing dept. cd. | H21: 購買部門ＣＤ | I21: E | J21: -
A22: 10 | D22: wg_cd | E22: #MA.WG_CD | G22: WG cd. | H22: ワーキンググループＣＤ | I22: E | J22: -
A23: 10 | D23: purc_usr_cd | E23: #MA.USR_CD | G23: Purchasing PIC cd. | H23: 購買担当者ＣＤ | I23: E | J23: -
... A64: 10 | D64: upd_cntr | E64: #MA.INT | G64: Update counter | H64: 更新カウンタ | I64: E | J64: -
L65: 上り項目 Request Message Field | M65: 下り項目 Response Message Field | N65: 上り項目 Request Message Field | O65: 下り項目 Response Message Field | P65: 上り項目 Request Message Field | Q65: 下り項目 Response Message Field
A66: 20 | B66: * | D66: PurcDscnt_Upd01_Dtl | E66: L | G66: $share$ | H66: MS.MSBDL5240.PurcDscnt_Ins01.PurcDscnt_Ins01_Dtl
A67: 20 | D67: peg_no | E67: #MA.INT | G67: Pegging No. | H67: 紐付けＮＯ | I67: E | J67: -
A68: 20 | D68: hdr_peg_no | E68: #MA.INT | G68: Header pegging No. | H68: ヘッダ紐付ＮＯ | I68: E | J68: -
A69: 20 | D69: data_crud_typ | E69: #MA.DATA_CRUD_TYP | G69: Data update type | H69: データ更新区分 | I69: E | J69: -
A70: 20 | D70: err_flg | E70: #MA.FLG | G70: Error | H70: エラー | I70: E | J70: -
A71: 20 | D71: purc_act_d_no | E71: #MA.PURC_ACT_D_NO | G71: Purchase result details No. | H71: 仕入実績明細ＮＯ | I71: E | J71: E
A72: 20 | D72: purc_act_d_seq | E72: #MA.SLIP_SEQ | G72: Purchase result details sequence number | H72: 仕入実績明細連番 | I72: E | J72: -
A73: 20 | D73: purc_act_no | E73: #MA.PURC_ACT_NO | G73: Purchase result No. | H73: 仕入実績ＮＯ | I73: E | J73: -
A74: 20 | D74: purc_act_seq | E74: #MA.SLIP_SEQ | G74: Purchase result sequence number | H74: 仕入実績連番 | I74: E | J74: -
A75: 20 | D75: purc_act_io_no | E75: #MA.PURC_ACT_IO_NO | G75: Purchase result GR/GI No. | H75: 仕入実績受払ＮＯ | I75: E | J75: -
A76: 20 | D76: purc_act_io_seq | E76: #MA.SLIP_SEQ | G76: Purchase result GR/GI sequence number | H76: 仕入実績受払連番 | I76: E | J76: -
A77: 20 | D77: dscnt_rsn_cd | E77: #MA.BIZ_RSN_CD | G77: Discount reason cd. | H77: 値引理由ＣＤ | I77: E | J77: -
A78: 20 | D78: purc_typ | E78: #MA.PURC_TYP | G78: Purchase type | H78: 購買区分 | I78: E | J78: -
... A165: 20 | D165: disp_seq | E165: #MA.DISP_SEQ | G165: Display order | H165: 表示順 | I165: E | J165: -
D166: 詳細 :

Sheet PurcDscnt_Del01
A1: * | B1: * | D1: L | E1: 1
A2: * | D2: オペレーション実装仕様書 Operation Specification Implementation Sheet | E2: ModuleID : | F2: =IF(LogicCommon!C2="","",LogicCommon!C2) -> MS | G2: LogicID : | H2: =IF(LogicCommon!E2="","",LogicCommon!E2) -> MSBDL5240 | I2: Ope.ID : | J2: PurcDscnt_Del01 | K2: Pj.ID : | L2: =IF(LogicCommon!G2="","",LogicCommon!G2) -> MC | M2: Ope.Body : | N2: "mcframe.serverMAUD.MAUDL5010.MAUDL_Operation"
A3: * | D3: =IF(LogicCommon!A3="","",LogicCommon!A3) | E3: SubModuleID : | F3: =IF(LogicCommon!C3="","",LogicCommon!C3) -> MSBD | G3: LogicClass : | H3: =IF(LogicCommon!E3="","",LogicCommon!E3) -> MSBDL_PurcDscntRegService | I3: Ope.Method : | J3: PurcDscnt_Del01 | K3: SuperClassPj.ID : | L3: =IF(LogicCommon!G3="","",LogicCommon!G3) | O3: Gene.Type : | P3: ALL
A4: * | E4: Version : | F4: 000000 | G4: LogicName : | H4: =IF(LogicCommon!E4="","",LogicCommon!E4) -> 仕入値引登録サービス | I4: Ope.Name : | J4: 削除 | K4: SuperLogicID : | L4: =IF(LogicCommon!G4="","",LogicCommon!G4) -> MS.MSUDL5010 | M4: ImplOpe.ID:
A5: * | E5: ACType :
A6: * | D6: 概要 : | E6: 仕入値引削除処理を実行します。 | M6: ID | O6: ID | Q6: ID
A7: # | I7: U | K7: K | L7: o | N7: o | P7: o
A8: # | D8: ブロック名 Block Name | E8: 型 Type | G8: super/share | H8: 対象ブロック名 Target Block Name | L8: TargetName | N8: TargetName | P8: TargetName | T8: ブロック備考 Block Remarks
A9: # | D9: 項目名 Field Name | E9: 型 Type | F9: 桁 Digits | G9: フルネーム Full Name | H9: 日本語名 Japanese Name | I9: 上り項目 Request Message Field | J9: 下り項目 Response Message Field | R9: 条件および編集方法 Conditions and Editing Methods | T9: 項目備考 Field Remarks
A10: # | L10: 上り項目 Request Message Field | M10: 下り項目 Response Message Field | N10: 上り項目 Request Message Field | O10: 下り項目 Response Message Field | P10: 上り項目 Request Message Field | Q10: 下り項目 Response Message Field
A11: 10 | B11: * | D11: PurcDscnt_Del01_Hdr | E11: L | G11: $share$ | H11: MS.MSBDL5240.PurcDscnt_Ins01.PurcDscnt_Ins01_Hdr
A12: 10 | D12: peg_no | E12: #MA.INT | G12: Pegging No. | H12: 紐付けＮＯ | I12: E | J12: -
A13: 10 | D13: err_flg | E13: #MA.FLG | G13: Error | H13: エラー | I13: E | J13: -
A14: 10 | D14: data_crud_typ | E14: #MA.DATA_CRUD_TYP | G14: Data update type | H14: データ更新区分 | I14: E | J14: -
A15: 10 | D15: purc_act_no | E15: #MA.PURC_ACT_NO | G15: Purchase result No. | H15: 仕入実績ＮＯ | I15: E | J15: -
A16: 10 | D16: purc_act_seq | E16: #MA.SLIP_SEQ | G16: Purchase result sequence number | H16: 仕入実績連番 | I16: E | J16: -
A17: 10 | D17: purc_act_rev | E17: #MA.SLIP_REV | G17: Purchase result rev. number | H17: 仕入実績改訂番号 | I17: E | J17: -
A18: 10 | D18: can_ac_dt | E18: #MA.DT | G18: Cancellation recording date | H18: 取消計上日 | I18: E | J18: -
L19: 上り項目 Request Message Field | M19: 下り項目 Response Message Field | N19: 上り項目 Request Message Field | O19: 下り項目 Response Message Field | P19: 上り項目 Request Message Field | Q19: 下り項目 Response Message Field
A20: 20 | B20: * | D20: PurcDscnt_Del01_Dtl | E20: L | G20: $share$ | H20: MS.MSBDL5240.PurcDscnt_Ins01.PurcDscnt_Ins01_Dtl
A21: 20 | D21: peg_no | E21: #MA.INT | G21: Pegging No. | H21: 紐付けＮＯ | I21: E | J21: -
A22: 20 | D22: hdr_peg_no | E22: #MA.INT | G22: Header pegging No. | H22: ヘッダ紐付ＮＯ | I22: E | J22: -
A23: 20 | D23: data_crud_typ | E23: #MA.DATA_CRUD_TYP | G23: Data update type | H23: データ更新区分 | I23: E | J23: -
A24: 20 | D24: err_flg | E24: #MA.FLG | G24: Error | H24: エラー | I24: E | J24: -
A25: 20 | D25: purc_act_d_no | E25: #MA.PURC_ACT_D_NO | G25: Purchase result details No. | H25: 仕入実績明細ＮＯ | I25: E | J25: -
A26: 20 | D26: purc_act_d_seq | E26: #MA.SLIP_SEQ | G26: Purchase result details sequence number | H26: 仕入実績明細連番 | I26: E | J26: -
A27: 20 | D27: purc_act_no | E27: #MA.PURC_ACT_NO | G27: Purchase result No. | H27: 仕入実績ＮＯ | I27: E | J27: -
A28: 20 | D28: purc_act_seq | E28: #MA.SLIP_SEQ | G28: Purchase result sequence number | H28: 仕入実績連番 | I28: E | J28: -
A29: 20 | D29: purc_act_io_no | E29: #MA.PURC_ACT_IO_NO | G29: Purchase result GR/GI No. | H29: 仕入実績受払ＮＯ | I29: E | J29: -
A30: 20 | D30: purc_act_io_seq | E30: #MA.SLIP_SEQ | G30: Purchase result GR/GI sequence number | H30: 仕入実績受払連番 | I30: E | J30: -
D31: 詳細 :

Sheet PurcDscnt_Chk01
A1: * | B1: * | D1: L | E1: 1
A2: * | D2: オペレーション実装仕様書 Operation Specification Implementation Sheet | E2: ModuleID : | F2: =IF(LogicCommon!C2="","",LogicCommon!C2) -> MS | G2: LogicID : | H2: =IF(LogicCommon!E2="","",LogicCommon!E2) -> MSBDL5240 | I2: Ope.ID : | J2: PurcDscnt_Chk01 | K2: Pj.ID : | L2: =IF(LogicCommon!G2="","",LogicCommon!G2) -> MC | M2: Ope.Body : | N2: MA.MAUDL5010.Checker
A3: * | D3: =IF(LogicCommon!A3="","",LogicCommon!A3) | E3: SubModuleID : | F3: =IF(LogicCommon!C3="","",LogicCommon!C3) -> MSBD | G3: LogicClass : | H3: =IF(LogicCommon!E3="","",LogicCommon!E3) -> MSBDL_PurcDscntRegService | I3: Ope.Method : | J3: PurcDscnt_Chk01 | K3: SuperClassPj.ID : | L3: =IF(LogicCommon!G3="","",LogicCommon!G3) | O3: Gene.Type : | P3: ALL
A4: * | E4: Version : | F4: 000000 | G4: LogicName : | H4: =IF(LogicCommon!E4="","",LogicCommon!E4) -> 仕入値引登録サービス | I4: Ope.Name : | J4: 更新前チェック | K4: SuperLogicID : | L4: =IF(LogicCommon!G4="","",LogicCommon!G4) -> MS.MSUDL5010 | M4: ImplOpe.ID:
A5: * | E5: ACType :
A6: * | D6: 概要 : | E6: 仕入値引登録の更新前チェックを行います。 | AD6: ID | AF6: ID | AH6: ID
A7: # | I7: U | K7: K | L7: K | M7: K | N7: K | O7: K | P7: K | Q7: K | R7: K | S7: K | T7: K | U7: K | V7: K | W7: K | X7: K | Y7: K | Z7: K | AA7: K | AB7: K | AC7: o | AE7: o | AG7: o
A8: # | D8: ブロック名 Block Name | E8: 型 Type | G8: super/share | H8: 対象ブロック名 Target Block Name | K8: REQ_UPD_CNT_CHK | L8: REQUIRED | M8: CHK_NUM | N8: SMALL_LARGE | O8: CHK_DT | P8: BEFORE_AFTER | Q8: CHK_PTN | R8: DUPLICATE | S8: TOO_MANY_INPUTS | T8: AT_LEAST_ONE | U8: ONLY_ONE_INPUT | V8: LIST_LOGIC | W8: LIST_OUT | X8: LIST_OUT_BASE | Y8: LIST_IN | Z8: LIST_IN_BASE | AA8: CONST | AB8: NULL_VAL | AC8: TargetName | AE8: TargetName | AG8: TargetName | AK8: ブロック備考 Block Remarks
A9: # | D9: 項目名 Field Name | E9: 型 Type | F9: 桁 Digits | G9: フルネーム Full Name | H9: 日本語名 Japanese Name | I9: 上り項目 Request Message Field | J9: 下り項目 Response Message Field | AI9: 条件および編集方法 Conditions and Editing Methods | AK9: 項目備考 Field Remarks
A10: # | AC10: 上り項目 Request Message Field | AD10: 下り項目 Response Message Field | AE10: 上り項目 Request Message Field | AF10: 下り項目 Response Message Field | AG10: 上り項目 Request Message Field | AH10: 下り項目 Response Message Field
A11: 10 | B11: * | D11: PurcDscnt_Chk01_Hdr | E11: L | G11: $share$ | H11: MS.MSBDL5240.PurcDscnt_Ins01.PurcDscnt_Ins01_Hdr
A12: 10 | D12: peg_no | E12: #MA.INT | G12: Pegging No. | H12: 紐付けＮＯ | I12: E | J12: E
A13: 10 | D13: err_flg | E13: #MA.FLG | G13: Error | H13: エラー | I13: E | J13: E
A14: 10 | D14: trd_cd | E14: #MA.TRD_CD | G14: Transaction cd. | H14: 取引ＣＤ | I14: E | J14: E
A15: 10 | D15: trd_ptn_typ | E15: #MA.TRD_PTN_TYP | G15: Transaction pattern type | H15: 取引パタン区分 | I15: E | J15: E
A16: 10 | D16: purc_act_no | E16: #MA.PURC_ACT_NO | G16: Purchase result No. | H16: 仕入実績ＮＯ | I16: E | J16: E
A17: 10 | D17: purc_act_seq | E17: #MA.SLIP_SEQ | G17: Purchase result sequence number | H17: 仕入実績連番 | I17: E | J17: E
A18: 10 | D18: purc_act_rev | E18: #MA.SLIP_REV | G18: Purchase result rev. number | H18: 仕入実績改訂番号 | I18: E | J18: E
A19: 10 | D19: slip_sts_typ | E19: #MA.SLIP_STS_TYP | G19: Slip status type | H19: 伝票状況区分 | I19: E | J19: E
A20: 10 | D20: purc_dpt_cd | E20: #MA.DPT_CD | G20: Purchasing dept. cd. | H20: 購買部門ＣＤ | I20: E | J20: E
A21: 10 | D21: wg_cd | E21: #MA.WG_CD | G21: WG cd. | H21: ワーキンググループＣＤ | I21: E | J21: E
A22: 10 | D22: purc_usr_cd | E22: #MA.USR_CD | G22: Purchasing PIC cd. | H22: 購買担当者ＣＤ | I22: E | J22: E
A23: 10 | D23: sppl_cd | E23: #MA.BP_CD | G23: Supplier cd. | H23: 発注先ＣＤ | I23: E | J23: E
... A63: 10 | D63: upd_cntr | E63: #MA.INT | G63: Update counter | H63: 更新カウンタ | I63: E | J63: E
AC64: 上り項目 Request Message Field | AD64: 下り項目 Response Message Field | AE64: 上り項目 Request Message Field | AF64: 下り項目 Response Message Field | AG64: 上り項目 Request Message Field | AH64: 下り項目 Response Message Field
A65: 20 | B65: * | D65: PurcDscnt_Chk01_Dtl | E65: L | G65: $share$ | H65: MS.MSBDL5240.PurcDscnt_Ins01.PurcDscnt_Ins01_Dtl
A66: 20 | D66: peg_no | E66: #MA.INT | G66: Pegging No. | H66: 紐付けＮＯ | I66: E | J66: E
A67: 20 | D67: hdr_peg_no | E67: #MA.INT | G67: Header pegging No. | H67: ヘッダ紐付ＮＯ | I67: E | J67: E
A68: 20 | D68: data_crud_typ | E68: #MA.DATA_CRUD_TYP | G68: Data update type | H68: データ更新区分 | I68: E | J68: E
A69: 20 | D69: err_flg | E69: #MA.FLG | G69: Error | H69: エラー | I69: E | J69: E
A70: 20 | D70: purc_act_d_no | E70: #MA.PURC_ACT_D_NO | G70: Purchase result details No. | H70: 仕入実績明細ＮＯ | I70: E | J70: E
A71: 20 | D71: purc_act_d_seq | E71: #MA.SLIP_SEQ | G71: Purchase result details sequence number | H71: 仕入実績明細連番 | I71: E | J71: E
A72: 20 | D72: purc_act_no | E72: #MA.PURC_ACT_NO | G72: Purchase result No. | H72: 仕入実績ＮＯ | I72: E | J72: E
A73: 20 | D73: purc_act_seq | E73: #MA.SLIP_SEQ | G73: Purchase result sequence number | H73: 仕入実績連番 | I73: E | J73: E
A74: 20 | D74: purc_act_io_no | E74: #MA.PURC_ACT_IO_NO | G74: Purchase result GR/GI No. | H74: 仕入実績受払ＮＯ | I74: E | J74: E
A75: 20 | D75: purc_act_io_seq | E75: #MA.SLIP_SEQ | G75: Purchase result GR/GI sequence number | H75: 仕入実績受払連番 | I75: E | J75: E
A76: 20 | D76: dscnt_rsn_cd | E76: #MA.BIZ_RSN_CD | G76: Discount reason cd. | H76: 値引理由ＣＤ | I76: E | J76: E
A77: 20 | D77: purc_typ | E77: #MA.PURC_TYP | G77: Purchase type | H77: 購買区分 | I77: E | J77: E
... A164: 20 | D164: disp_seq | E164: #MA.DISP_SEQ | G164: Display order | H164: 表示順 | I164: E | J164: E
D165: 詳細 :

Sheet PurcDscnt_BulkImp_Chk01
A1: * | B1: * | D1: L | E1: 1
A2: * | D2: オペレーション実装仕様書 Operation Specification Implementation Sheet | E2: ModuleID : | F2: =IF(LogicCommon!C2="","",LogicCommon!C2) -> MS | G2: LogicID : | H2: =IF(LogicCommon!E2="","",LogicCommon!E2) -> MSBDL5240 | I2: Ope.ID : | J2: PurcDscnt_BulkImp_Chk01 | K2: Pj.ID : | L2: =IF(LogicCommon!G2="","",LogicCommon!G2) -> MC | M2: Ope.Body : | N2: MA.MAUDL5010.Checker
A3: * | D3: =IF(LogicCommon!A3="","",LogicCommon!A3) | E3: SubModuleID : | F3: =IF(LogicCommon!C3="","",LogicCommon!C3) -> MSBD | G3: LogicClass : | H3: =IF(LogicCommon!E3="","",LogicCommon!E3) -> MSBDL_PurcDscntRegService | I3: Ope.Method : | J3: PurcDscnt_BulkImp_Chk01 | K3: SuperClassPj.ID : | L3: =IF(LogicCommon!G3="","",LogicCommon!G3) | O3: Gene.Type : | P3: ALL
A4: * | E4: Version : | F4: 000000 | G4: LogicName : | H4: =IF(LogicCommon!E4="","",LogicCommon!E4) -> 仕入値引登録サービス | I4: Ope.Name : | J4: 登録前チェック（まとめ登録ツール用） | K4: SuperLogicID : | L4: =IF(LogicCommon!G4="","",LogicCommon!G4) -> MS.MSUDL5010 | M4: ImplOpe.ID:
A5: * | E5: ACType :
A6: * | D6: 概要 : | E6: まとめ登録ツールが取り込んだファイルの情報をもとに、仕入値引情報の登録前のチェックを行います。 | AD6: ID | AF6: ID | AH6: ID
A7: # | I7: U | K7: K | L7: K | M7: K | N7: K | O7: K | P7: K | Q7: K | R7: K | S7: K | T7: K | U7: K | V7: K | W7: K | X7: K | Y7: K | Z7: K | AA7: K | AB7: K | AC7: o | AE7: o | AG7: o
A8: # | D8: ブロック名 Block Name | E8: 型 Type | G8: super/share | H8: 対象ブロック名 Target Block Name | K8: REQ_UPD_CNT_CHK | L8: REQUIRED | M8: CHK_NUM | N8: SMALL_LARGE | O8: CHK_DT | P8: BEFORE_AFTER | Q8: CHK_PTN | R8: DUPLICATE | S8: TOO_MANY_INPUTS | T8: AT_LEAST_ONE | U8: ONLY_ONE_INPUT | V8: LIST_LOGIC | W8: LIST_OUT | X8: LIST_OUT_BASE | Y8: LIST_IN | Z8: LIST_IN_BASE | AA8: CONST | AB8: NULL_VAL | AC8: TargetName | AE8: TargetName | AG8: TargetName | AK8: ブロック備考 Block Remarks
A9: # | D9: 項目名 Field Name | E9: 型 Type | F9: 桁 Digits | G9: フルネーム Full Name | H9: 日本語名 Japanese Name | I9: 上り項目 Request Message Field | J9: 下り項目 Response Message Field | AI9: 条件および編集方法 Conditions and Editing Methods | AK9: 項目備考 Field Remarks
A10: # | AC10: 上り項目 Request Message Field | AD10: 下り項目 Response Message Field | AE10: 上り項目 Request Message Field | AF10: 下り項目 Response Message Field | AG10: 上り項目 Request Message Field | AH10: 下り項目 Response Message Field
A11: 10 | B11: * | D11: PurcDscnt_BulkImp_Chk01_Dtl | E11: L
A12: 10 | D12: peg_no | E12: #MA.INT | G12: Pegging No. | H12: 紐付けＮＯ | J12: E
A13: 10 | D13: trd_cd | E13: #MA.TRD_CD | G13: Transaction cd. | H13: 取引ＣＤ | I13: E | J13: E | L13: E | V13: MA.MAUAL0010.Trd | W13: trd_ptn_typ | X13: trd_ptn_typ
A14: 10 | D14: trd_ptn_typ | E14: #MA.TRD_PTN_TYP | G14: Transaction pattern type | H14: 取引パタン区分 | J14: E
A15: 10 | D15: purc_usr_cd | E15: #MA.USR_CD | G15: Purchasing PIC cd. | H15: 購買担当者ＣＤ | I15: E | J15: E | V15: MA.MAUAL0010.Usr | Y15: ac_dt | Z15: dt
A16: 10 | D16: purc_dpt_cd | E16: #MA.DPT_CD | G16: Purchasing dept. cd. | H16: 購買部門ＣＤ | I16: E | J16: E | V16: MA.MAUAL0010.Dpt | W16: wg_cd | X16: wg_cd | Y16: ac_dt;purc_usr_cd;MAC_DPT_IS_SRCH_TYP.PURC | Z16: dt;usr_cd;dpt_is_srch_typ
A17: 10 | D17: wg_cd | E17: #MA.WG_CD | G17: WG cd. | H17: ワーキンググループＣＤ | J17: E
A18: 10 | D18: sppl_cd | E18: #MA.BP_CD | G18: Supplier cd. | H18: 発注先ＣＤ | I18: E | J18: E | L18: E | V18: MA.MAUAL0010.Bp | W18: sppl_iv_flg;asppl_cd;purc_amt_rnd_typ;purc_tax_rnd_typ;purc_tax_calc_typ;prnt_lcl_cd | X18: sppl_iv_flg;asppl_cd;purc_amt_rnd_typ;purc_tax_rnd_typ;purc_tax_calc_typ;prnt_lcl_cd | Y18: MAC_BP_IS_SRCH_TYP.SPPL;purc_dt | Z18: bp_is_srch_typ;dt
A19: 10 | D19: sppl_iv_flg | E19: #MA.FLG | G19: For I/V transaction | H19: Ｉ／Ｖ取引対象 | J19: E
A20: 10 | D20: asppl_cd | E20: #MA.BP_CD | G20: AP supplier cd. | H20: 買掛先ＣＤ | J20: E | V20: MA.MAUAL0010.Bp | W20: bsppl_cd | Y20: MAC_BP_IS_SRCH_TYP.ASPPL | Z20: dpt_is_srch_typ
A21: 10 | D21: bsppl_cd | E21: #MA.BP_CD | G21: Scheduled payee cd. | H21: 支払予定管理先ＣＤ | J21: E | V21: MA.MAUAL0010.Bp | W21: psppl_cd;pay_spot_flg;cred_cd | X21: psppl_cd;pay_spot_flg;ap_cred_cd | Y21: MAC_BP_IS_SRCH_TYP.BSPPL | Z21: dpt_is_srch_typ
A22: 10 | D22: psppl_cd | E22: #MA.BP_CD | G22: Payee cd. | H22: 支払先ＣＤ | J22: E | V22: MA.MAUAL0010.Bp | Y22: MAC_BP_IS_SRCH_TYP.PSPPL | Z22: dpt_is_srch_typ
A23: 10 | D23: cred_cd | E23: #MA.BP_CD | G23: Credit managed BP cd. | H23: 与信管理先ＣＤ | J23: E | V23: MA.MAUAL0010.Bp | Y23: MAC_BP_IS_SRCH_TYP.CRED | Z23: dpt_is_srch_typ
A24: 10 | D24: pay_spot_flg | E24: #MA.FLG | G24: Payment per transaction | H24: 都度支払 | J24: E
A25: 10 | D25: purc_amt_rnd_typ | E25: #MA.RND_TYP | G25: Rounding type (Purchase amount) | H25: 仕入金額端数処理区分 | J25: E
A26: 10 | D26: purc_tax_rnd_typ | E26: #MA.RND_TYP | G26: Purchase tax rounding type | H26: 仕入税端数処理区分 | J26: E
A27: 10 | D27: purc_tax_calc_typ | E27: #MA.TAX_CALC_TYP | G27: Purchase tax calculation type | H27: 仕入税計算区分 | J27: E
A28: 10 | D28: trd_cur_cd | E28: #MA.CUR_CD | G28: Transaction currency cd. | H28: 取引通貨ＣＤ | I28: E | J28: E | L28: E | V28: MA.MAUAL0010.Cur | W28: upri_dec_place;amt_dec_place | X28: upri_dec_place;amt_dec_place
A29: 10 | D29: upri_dec_place | E29: #MA.DEC_PLACE | G29: Unit price number of decimal places | H29: 単価小数部有効桁数 | J29: E
A30: 10 | D30: amt_dec_place | E30: #MA.DEC_PLACE | G30: Amount number of decimal places | H30: 金額小数部有効桁数 | J30: E
A31: 10 | D31: ptax_cur_cd | E31: #MA.CUR_CD | G31: Taxpaying currency cd. | H31: 納税通貨ＣＤ | J31: E | V31: MA.MAUAL0010.Cur | W31: ptax_cur_amt_dec_place;ptax_cur_upri_dec_place | X31: amt_dec_place;upri_dec_place
A32: 10 | D32: ptax_cur_amt_dec_place | E32: #MA.DEC_PLACE | G32: Tax amount number of decimal places | H32: 納税金額小数部有効桁数 | J32: E
A33: 10 | D33: ptax_cur_upri_dec_place | E33: #MA.DEC_PLACE | G33: Tax unit price number of decimal places | H33: 納税単価小数部有効桁数 | J33: E
A34: 10 | D34: base_cur_cd | E34: #MA.CUR_CD | G34: Base currency cd. | H34: 基準通貨ＣＤ | J34: E | V34: MA.MAUAL0010.Cur | W34: base_cur_amt_dec_place;base_cur_upri_dec_place | X34: amt_dec_place;upri_dec_place
A35: 10 | D35: base_cur_amt_dec_place | E35: #MA.DEC_PLACE | G35: Base amount number of decimal places | H35: 基準金額小数部有効桁数 | J35: E
A36: 10 | D36: base_cur_upri_dec_place | E36: #MA.DEC_PLACE | G36: Base unit price number of decimal places | H36: 基準単価小数部有効桁数 | J36: E
A37: 10 | D37: trd_rmrks | E37: #MA.TRD_RMRKS | G37: Transaction remarks | H37: 取引備考 | I37: E | J37: E
A38: 10 | D38: intr_rmrks | E38: #MS.PO_INTR_RMRKS | G38: Internal remarks | H38: 内部備考 | I38: E | J38: E
A39: 10 | D39: tterm_cd1 | E39: #MA.TTERM_CD | G39: Transaction terms cd. 1 | H39: 取引条件ＣＤ１ | I39: E | J39: E | V39: MA.MAUAL0010.Tterm1
A40: 10 | D40: tterm_rmrks1 | E40: #MS.TTERM_RMRKS1 | G40: Transaction terms remarks 1 | H40: 取引条件備考１ | I40: E | J40: E
...

Sheet PurcDscnt_BulkImp_Ins01
A1: * | B1: * | D1: L | E1: 1
A2: * | D2: オペレーション実装仕様書 Operation Specification Implementation Sheet | E2: ModuleID : | F2: =IF(LogicCommon!C2="","",LogicCommon!C2) -> MS | G2: LogicID : | H2: =IF(LogicCommon!E2="","",LogicCommon!E2) -> MSBDL5240 | I2: Ope.ID : | J2: PurcDscnt_BulkImp_Ins01 | K2: Pj.ID : | L2: =IF(LogicCommon!G2="","",LogicCommon!G2) -> MC | M2: Ope.Body : | N2: "mcframe.serverMAUD.MAUDL5010.MAUDL_Operation"
A3: * | D3: =IF(LogicCommon!A3="","",LogicCommon!A3) | E3: SubModuleID : | F3: =IF(LogicCommon!C3="","",LogicCommon!C3) -> MSBD | G3: LogicClass : | H3: =IF(LogicCommon!E3="","",LogicCommon!E3) -> MSBDL_PurcDscntRegService | I3: Ope.Method : | J3: PurcDscnt_BulkImp_Ins01 | K3: SuperClassPj.ID : | L3: =IF(LogicCommon!G3="","",LogicCommon!G3) | O3: Gene.Type : | P3: ALL
A4: * | E4: Version : | F4: 000000 | G4: LogicName : | H4: =IF(LogicCommon!E4="","",LogicCommon!E4) -> 仕入値引登録サービス | I4: Ope.Name : | J4: 登録（まとめ登録ツール用） | K4: SuperLogicID : | L4: =IF(LogicCommon!G4="","",LogicCommon!G4) -> MS.MSUDL5010 | M4: ImplOpe.ID:
A5: * | E5: ACType :
A6: * | D6: 概要 : | E6: まとめ登録ツールが取り込んだファイルの情報をもとに、仕入値引情報の登録を行います。 | M6: ID | O6: ID | Q6: ID
A7: # | I7: U | K7: K | L7: o | N7: o | P7: o
A8: # | D8: ブロック名 Block Name | E8: 型 Type | G8: super/share | H8: 対象ブロック名 Target Block Name | L8: TargetName | N8: TargetName | P8: TargetName | T8: ブロック備考 Block Remarks
A9: # | D9: 項目名 Field Name | E9: 型 Type | F9: 桁 Digits | G9: フルネーム Full Name | H9: 日本語名 Japanese Name | I9: 上り項目 Request Message Field | J9: 下り項目 Response Message Field | R9: 条件および編集方法 Conditions and Editing Methods | T9: 項目備考 Field Remarks
A10: # | L10: 上り項目 Request Message Field | M10: 下り項目 Response Message Field | N10: 上り項目 Request Message Field | O10: 下り項目 Response Message Field | P10: 上り項目 Request Message Field | Q10: 下り項目 Response Message Field
A11: 10 | B11: * | D11: PurcDscnt_BulkImp_Ins01_Dtl | E11: L | G11: $share$ | H11: MS.MSBDL5240.PurcDscnt_BulkImp_Chk01.PurcDscnt_BulkImp_Chk01_Dtl
A12: 10 | D12: peg_no | E12: #MA.INT | G12: Pegging No. | H12: 紐付けＮＯ | I12: E
A13: 10 | D13: trd_cd | E13: #MA.TRD_CD | G13: Transaction cd. | H13: 取引ＣＤ | I13: E
A14: 10 | D14: trd_ptn_typ | E14: #MA.TRD_PTN_TYP | G14: Transaction pattern type | H14: 取引パタン区分 | I14: E
A15: 10 | D15: purc_usr_cd | E15: #MA.USR_CD | G15: Purchasing PIC cd. | H15: 購買担当者ＣＤ | I15: E
A16: 10 | D16: purc_dpt_cd | E16: #MA.DPT_CD | G16: Purchasing dept. cd. | H16: 購買部門ＣＤ | I16: E
A17: 10 | D17: wg_cd | E17: #MA.WG_CD | G17: WG cd. | H17: ワーキンググループＣＤ | I17: E
A18: 10 | D18: sppl_cd | E18: #MA.BP_CD | G18: Supplier cd. | H18: 発注先ＣＤ | I18: E
A19: 10 | D19: sppl_iv_flg | E19: #MA.FLG | G19: For I/V transaction | H19: Ｉ／Ｖ取引対象 | I19: E
A20: 10 | D20: asppl_cd | E20: #MA.BP_CD | G20: AP supplier cd. | H20: 買掛先ＣＤ | I20: E
A21: 10 | D21: bsppl_cd | E21: #MA.BP_CD | G21: Scheduled payee cd. | H21: 支払予定管理先ＣＤ | I21: E
A22: 10 | D22: psppl_cd | E22: #MA.BP_CD | G22: Payee cd. | H22: 支払先ＣＤ | I22: E
A23: 10 | D23: cred_cd | E23: #MA.BP_CD | G23: Credit managed BP cd. | H23: 与信管理先ＣＤ | I23: E
... A155: 10 | D155: disp_seq | E155: #MA.DISP_SEQ | G155: Display order | H155: 表示順 | I155: E
D156: 詳細 :

Sheet PurcDscnt_BulkImp_Chk02
A1: * | B1: * | D1: L | E1: 1
A2: * | D2: オペレーション実装仕様書 Operation Specification Implementation Sheet | E2: ModuleID : | F2: =IF(LogicCommon!C2="","",LogicCommon!C2) -> MS | G2: LogicID : | H2: =IF(LogicCommon!E2="","",LogicCommon!E2) -> MSBDL5240 | I2: Ope.ID : | J2: PurcDscnt_BulkImp_Chk02 | K2: Pj.ID : | L2: =IF(LogicCommon!G2="","",LogicCommon!G2) -> MC | M2: Ope.Body : | N2: MA.MAUDL5010.Checker
A3: * | D3: =IF(LogicCommon!A3="","",LogicCommon!A3) | E3: SubModuleID : | F3: =IF(LogicCommon!C3="","",LogicCommon!C3) -> MSBD | G3: LogicClass : | H3: =IF(LogicCommon!E3="","",LogicCommon!E3) -> MSBDL_PurcDscntRegService | I3: Ope.Method : | J3: PurcDscnt_BulkImp_Chk02 | K3: SuperClassPj.ID : | L3: =IF(LogicCommon!G3="","",LogicCommon!G3) | O3: Gene.Type : | P3: ALL
A4: * | E4: Version : | F4: 000000 | G4: LogicName : | H4: =IF(LogicCommon!E4="","",LogicCommon!E4) -> 仕入値引登録サービス | I4: Ope.Name : | J4: 取消前チェック（まとめ登録ツール用） | K4: SuperLogicID : | L4: =IF(LogicCommon!G4="","",LogicCommon!G4) -> MS.MSUDL5010 | M4: ImplOpe.ID:
A5: * | E5: ACType :
A6: * | D6: 概要 : | E6: まとめ登録ツールが取り込んだファイルの情報をもとに、仕入値引情報の取消前のチェックを行います。 | AD6: ID | AF6: ID | AH6: ID
A7: # | I7: U | K7: K | L7: K | M7: K | N7: K | O7: K | P7: K | Q7: K | R7: K | S7: K | T7: K | U7: K | V7: K | W7: K | X7: K | Y7: K | Z7: K | AA7: K | AB7: K | AC7: o | AE7: o | AG7: o
A8: # | D8: ブロック名 Block Name | E8: 型 Type | G8: super/share | H8: 対象ブロック名 Target Block Name | K8: REQ_UPD_CNT_CHK | L8: REQUIRED | M8: CHK_NUM | N8: SMALL_LARGE | O8: CHK_DT | P8: BEFORE_AFTER | Q8: CHK_PTN | R8: DUPLICATE | S8: TOO_MANY_INPUTS | T8: AT_LEAST_ONE | U8: ONLY_ONE_INPUT | V8: LIST_LOGIC | W8: LIST_OUT | X8: LIST_OUT_BASE | Y8: LIST_IN | Z8: LIST_IN_BASE | AA8: CONST | AB8: NULL_VAL | AC8: TargetName | AE8: TargetName | AG8: TargetName | AK8: ブロック備考 Block Remarks
A9: # | D9: 項目名 Field Name | E9: 型 Type | F9: 桁 Digits | G9: フルネーム Full Name | H9: 日本語名 Japanese Name | I9: 上り項目 Request Message Field | J9: 下り項目 Response Message Field | AI9: 条件および編集方法 Conditions and Editing Methods | AK9: 項目備考 Field Remarks
A10: # | AC10: 上り項目 Request Message Field | AD10: 下り項目 Response Message Field | AE10: 上り項目 Request Message Field | AF10: 下り項目 Response Message Field | AG10: 上り項目 Request Message Field | AH10: 下り項目 Response Message Field
A11: 10 | B11: * | D11: PurcDscnt_BulkImp_Chk02_Dtl | E11: L
A12: 10 | D12: peg_no | E12: #MA.INT | G12: Pegging No. | H12: 紐付けＮＯ | J12: E
A13: 10 | D13: trd_cd | E13: #MA.TRD_CD | G13: Transaction cd. | H13: 取引ＣＤ | J13: E | V13: MA.MAUAL0010.Trd | W13: trd_ptn_typ | X13: trd_ptn_typ
A14: 10 | D14: trd_ptn_typ | E14: #MA.TRD_PTN_TYP | G14: Transaction pattern type | H14: 取引パタン区分 | J14: E
A15: 10 | D15: purc_act_no | E15: #MA.PURC_ACT_NO | G15: Purchase result No. | H15: 仕入実績ＮＯ | I15: E | J15: E | L15: E | R15: E
A16: 10 | D16: purc_act_seq | E16: #MA.SLIP_SEQ | G16: Purchase result sequence number | H16: 仕入実績連番 | J16: E
A17: 10 | D17: purc_act_rev | E17: #MA.SLIP_REV | G17: Purchase result rev. number | H17: 仕入実績改訂番号 | J17: E
A18: 10 | D18: can_ac_dt | E18: #MA.DT | G18: Cancellation recording date | H18: 取消計上日 | J18: E | O18: bfToday
A19: 10 | D19: upd_cntr | E19: #MA.INT | G19: Update counter | H19: 更新カウンタ
A20: 10 | D20: dtl_peg_no | E20: #MA.INT | G20: Details pegging No. | H20: 明細紐付けＮＯ | J20: E
A21: 10 | D21: data_crud_typ | E21: #MA.DATA_CRUD_TYP | G21: Data update type | H21: データ更新区分 | J21: E
A22: 10 | D22: err_flg | E22: #MA.FLG | G22: Error | H22: エラー | J22: E
A23: 10 | D23: purc_act_d_no | E23: #MA.PURC_ACT_D_NO | G23: Purchase result details No. | H23: 仕入実績明細ＮＯ | J23: E
A24: 10 | D24: purc_act_d_seq | E24: #MA.SLIP_SEQ | G24: Purchase result details sequence number | H24: 仕入実績明細連番 | J24: E
A25: 10 | D25: purc_act_io_no | E25: #MA.PURC_ACT_IO_NO | G25: Purchase result GR/GI No. | H25: 仕入実績受払ＮＯ | J25: E
A26: 10 | D26: purc_act_io_seq | E26: #MA.SLIP_SEQ | G26: Purchase result GR/GI sequence number | H26: 仕入実績受払連番 | J26: E
A27: 10 | D27: purc_dpt_cd | E27: #MA.DPT_CD | G27: Purchasing dept. cd. | H27: 購買部門ＣＤ
D28: 詳細 :

Sheet PurcDscnt_BulkImp_Del01
A1: * | B1: * | D1: L | E1: 1
A2: * | D2: オペレーション実装仕様書 Operation Specification Implementation Sheet | E2: ModuleID : | F2: =IF(LogicCommon!C2="","",LogicCommon!C2) -> MS | G2: LogicID : | H2: =IF(LogicCommon!E2="","",LogicCommon!E2) -> MSBDL5240 | I2: Ope.ID : | J2: PurcDscnt_BulkImp_Del01 | K2: Pj.ID : | L2: =IF(LogicCommon!G2="","",LogicCommon!G2) -> MC | M2: Ope.Body : | N2: "mcframe.serverMAUD.MAUDL5010.MAUDL_Operation"
A3: * | D3: =IF(LogicCommon!A3="","",LogicCommon!A3) | E3: SubModuleID : | F3: =IF(LogicCommon!C3="","",LogicCommon!C3) -> MSBD | G3: LogicClass : | H3: =IF(LogicCommon!E3="","",LogicCommon!E3) -> MSBDL_PurcDscntRegService | I3: Ope.Method : | J3: PurcDscnt_BulkImp_Del01 | K3: SuperClassPj.ID : | L3: =IF(LogicCommon!G3="","",LogicCommon!G3) | O3: Gene.Type : | P3: ALL
A4: * | E4: Version : | F4: 000000 | G4: LogicName : | H4: =IF(LogicCommon!E4="","",LogicCommon!E4) -> 仕入値引登録サービス | I4: Ope.Name : | J4: 取消（まとめ登録ツール用） | K4: SuperLogicID : | L4: =IF(LogicCommon!G4="","",LogicCommon!G4) -> MS.MSUDL5010 | M4: ImplOpe.ID:
A5: * | E5: ACType :
A6: * | D6: 概要 : | E6: まとめ登録ツールが取り込んだファイルの情報をもとに、仕入値引情報の削除を行います。 | M6: ID | O6: ID | Q6: ID
A7: # | I7: U | K7: K | L7: o | N7: o | P7: o
A8: # | D8: ブロック名 Block Name | E8: 型 Type | G8: super/share | H8: 対象ブロック名 Target Block Name | L8: TargetName | N8: TargetName | P8: TargetName | T8: ブロック備考 Block Remarks
A9: # | D9: 項目名 Field Name | E9: 型 Type | F9: 桁 Digits | G9: フルネーム Full Name | H9: 日本語名 Japanese Name | I9: 上り項目 Request Message Field | J9: 下り項目 Response Message Field | R9: 条件および編集方法 Conditions and Editing Methods | T9: 項目備考 Field Remarks
A10: # | L10: 上り項目 Request Message Field | M10: 下り項目 Response Message Field | N10: 上り項目 Request Message Field | O10: 下り項目 Response Message Field | P10: 上り項目 Request Message Field | Q10: 下り項目 Response Message Field
A11: 10 | B11: * | D11: PurcDscnt_BulkImp_Del01_Dtl | E11: L | G11: $share$ | H11: MS.MSBDL5240.PurcDscnt_BulkImp_Chk02.PurcDscnt_BulkImp_Chk02_Dtl
A12: 10 | D12: peg_no | E12: #MA.INT | G12: Pegging No. | H12: 紐付けＮＯ | I12: E
A13: 10 | D13: trd_cd | E13: #MA.TRD_CD | G13: Transaction cd. | H13: 取引ＣＤ | I13: E
A14: 10 | D14: trd_ptn_typ | E14: #MA.TRD_PTN_TYP | G14: Transaction pattern type | H14: 取引パタン区分 | I14: E
A15: 10 | D15: purc_act_no | E15: #MA.PURC_ACT_NO | G15: Purchase result No. | H15: 仕入実績ＮＯ | I15: E
A16: 10 | D16: purc_act_seq | E16: #MA.SLIP_SEQ | G16: Purchase result sequence number | H16: 仕入実績連番 | I16: E
A17: 10 | D17: purc_act_rev | E17: #MA.SLIP_REV | G17: Purchase result rev. number | H17: 仕入実績改訂番号 | I17: E
A18: 10 | D18: can_ac_dt | E18: #MA.DT | G18: Cancellation recording date | H18: 取消計上日 | I18: E
A19: 10 | D19: dtl_peg_no | E19: #MA.INT | G19: Details pegging No. | H19: 明細紐付けＮＯ | I19: E
A20: 10 | D20: data_crud_typ | E20: #MA.DATA_CRUD_TYP | G20: Data update type | H20: データ更新区分 | I20: E
A21: 10 | D21: err_flg | E21: #MA.FLG | G21: Error | H21: エラー | I21: E
A22: 10 | D22: purc_act_d_no | E22: #MA.PURC_ACT_D_NO | G22: Purchase result details No. | H22: 仕入実績明細ＮＯ | I22: E
A23: 10 | D23: purc_act_d_seq | E23: #MA.SLIP_SEQ | G23: Purchase result details sequence number | H23: 仕入実績明細連番 | I23: E
... A25: 10 | D25: purc_act_io_seq | E25: #MA.SLIP_SEQ | G25: Purchase result GR/GI sequence number | H25: 仕入実績受払連番 | I25: E
D26: 詳細 :

Sheet 来歴
A1: 変更来歴
A3: Rev. | H3: 修正番号 | O3: 変更内容 | AQ3: 変更箇所
A4: 1 | O4: 初版
A5: 1.1 | H5: MS7032#001 | O5: PurcDscnt_Ins01_Hdrブロックにamt_calc_flgを追加 | AQ5: PurcDscnt_Ins01
A6: 1.2 | O6: 英語の名称を追記 | AQ6: 全般
