Workbook

Sheet LogicCommon
A2: ロジック共通定義 | B2: ModuleID : | C2: MA | D2: LogicID : | E2: MABCL0430 | F2: Pj.ID : | G2: MC
B3: SubModuleID : | C3: MABC | D3: LogicClass : | E3: MABCL_BpGrpReg | F3: SuperClassPj.ID :
D4: LogicName : | E4: 取引先分類マスタ登録 | F4: SuperLogicID : | G4: MA.MAUDL5010
A5: 概要 :
A6: 詳細 :

Sheet BpGrp_UpdChk01
A1: * | B1: * | D1: L | E1: 1
A2: * | D2: オペレーション実装仕様書 Operation Specification Implementation Sheet | E2: ModuleID : | F2: =IF(LogicCommon!C2="","",LogicCommon!C2) -> MA | G2: LogicID : | H2: =IF(LogicCommon!E2="","",LogicCommon!E2) -> MABCL0430 | I2: Ope.ID : | J2: BpGrp_UpdChk01 | K2: Pj.ID : | L2: =IF(LogicCommon!G2="","",LogicCommon!G2) -> MC | M2: Ope.Body : | N2: =L4 & ".Checker" -> MA.MAUDL5010.Checker
A3: * | D3: =IF(LogicCommon!A3="","",LogicCommon!A3) | E3: SubModuleID : | F3: =IF(LogicCommon!C3="","",LogicCommon!C3) -> MABC | G3: LogicClass : | H3: =IF(LogicCommon!E3="","",LogicCommon!E3) -> MABCL_BpGrpReg | I3: Ope.Method : | J3: @ | K3: SuperClassPj.ID : | L3: =IF(LogicCommon!G3="","",LogicCommon!G3) | M3: ReportID : | O3: Gene.Type : | P3: ALL
A4: * | E4: Version : | F4: 000000 | G4: LogicName : | H4: =IF(LogicCommon!E4="","",LogicCommon!E4) -> 取引先分類マスタ登録 | I4: Ope.Name : | J4: 登録前チェック | K4: SuperLogicID : | L4: =IF(LogicCommon!G4="","",LogicCommon!G4) -> MA.MAUDL5010
A5: * | E5: ACType :
A6: * | D6: 概要 : | E6: 取引先分類マスタを登録する前のチェックを行う | P6: ID
A7: # | I7: U | K7: K | L7: K | M7: K | N7: K | O7: o
A8: # | D8: ブロック名 Block Name | E8: 型 Type | G8: super/share | H8: 対象ブロック名 Target Block Name | K8: NULL_VAL | L8: REQUIRED | M8: SCALE | N8: CONST | O8: TargetName | S8: ブロック備考 Block Remarks
A9: # | D9: 項目名 Field Name | E9: 型 Type | F9: 桁 Digits | G9: フルネーム Full Name | H9: 日本語名 Japanese Name | I9: 上り項目 Request Message Field | J9: 下り項目 Response Message Field | Q9: 条件および編集方法 Conditions and Editing Methods | S9: 項目備考 Field Remarks
A10: # | O10: 上り項目 Request Message Field | P10: 下り項目 Response Message Field
A11: 10 | B11: * | D11: BpGrp_UpdChk01_Dtl | E11: L | G11: $super$ | H11: DBC:MA.MAM_BP_GRP
A12: 10 | D12: bp_grp_typ | E12: #MA.BP_GRP_TYP | G12: BP classification type | H12: 取引先分類区分 | I12: E | L12: E | N12: MAC_BP_GRP_TYP
A13: 10 | D13: bp_grp_cd | E13: #MA.BP_GRP_CD | G13: BP classification cd. | H13: 取引先分類ＣＤ | I13: E | L13: E
A14: 10 | D14: bp_grp_nm | E14: #MA.BP_GRP_NM | G14: BP classification name | H14: 取引先分類名 | I14: E | L14: E
A15: 10 | D15: num_id | E15: #MA.NUM_ID | G15: Numbering ID | H15: 発番ＩＤ | I15: E
A16: 10 | D16: memo1 | E16: #MA.MST_MEMO1 | G16: Memo 1 | H16: メモ１ | I16: E
A17: 10 | D17: memo2 | E17: #MA.MST_MEMO2 | G17: Memo 2 | H17: メモ２ | I17: E
A18: 10 | D18: memo3 | E18: #MA.MST_MEMO3 | G18: Memo 3 | H18: メモ３ | I18: E
A19: 10 | D19: del_flg | E19: #MA.FLG | G19: Logical delete | H19: 論理削除 | I19: E
A20: 10 | D20: upd_cntr | E20: #MA.UPD_CNT | G20: Update counter | H20: 更新カウンタ | I20: E
D21: 詳細 :

Sheet BpGrp_Upd01
A1: * | B1: * | D1: L | E1: 1
A2: * | D2: オペレーション実装仕様書 Operation Specification Implementation Sheet | E2: ModuleID : | F2: =IF(LogicCommon!C2="","",LogicCommon!C2) -> MA | G2: LogicID : | H2: =IF(LogicCommon!E2="","",LogicCommon!E2) -> MABCL0430 | I2: Ope.ID : | J2: BpGrp_Upd01 | K2: Pj.ID : | L2: =IF(LogicCommon!G2="","",LogicCommon!G2) -> MC | M2: Ope.Body : | N2: "mcframe.serverMAUD.MAUDL6020.MAUDL_LCLRLUpdater"
A3: * | D3: =IF(LogicCommon!A3="","",LogicCommon!A3) | E3: SubModuleID : | F3: =IF(LogicCommon!C3="","",LogicCommon!C3) -> MABC | G3: LogicClass : | H3: =IF(LogicCommon!E3="","",LogicCommon!E3) -> MABCL_BpGrpReg | I3: Ope.Method : | J3: @ | K3: SuperClassPj.ID : | L3: =IF(LogicCommon!G3="","",LogicCommon!G3) | M3: ReportID : | O3: Gene.Type : | P3: ALL
A4: * | E4: Version : | F4: 000000 | G4: LogicName : | H4: =IF(LogicCommon!E4="","",LogicCommon!E4) -> 取引先分類マスタ登録 | I4: Ope.Name : | J4: 登録処理 | K4: SuperLogicID : | L4: =IF(LogicCommon!G4="","",LogicCommon!G4) -> MA.MAUDL5010
A5: * | E5: ACType :
A6: * | D6: 概要 : | E6: 取引先分類マスタを登録する | L6: ID | N6: ID | P6: ID | R6: ID
A7: # | I7: U | K7: o | L7: UPDATE.updMaster | M7: o | N7: MAIN.chkMaster | O7: o | Q7: o
A8: # | D8: ブロック名 Block Name | E8: 型 Type | G8: super/share | H8: 対象ブロック名 Target Block Name | K8: TargetName | L8: DBC.MA.MAM_BP_GRP | M8: TargetName | N8: DBC.MA.MAM_BP_GRP | O8: TargetName | Q8: TargetName | U8: ブロック備考 Block Remarks
A9: # | D9: 項目名 Field Name | E9: 型 Type | F9: 桁 Digits | G9: フルネーム Full Name | H9: 日本語名 Japanese Name | I9: 上り項目 Request Message Field | J9: 下り項目 Response Message Field | S9: 条件および編集方法 Conditions and Editing Methods | U9: 項目備考 Field Remarks
A10: # | K10: 上り項目 Request Message Field | L10: 下り項目 Response Message Field | M10: 上り項目 Request Message Field | N10: 下り項目 Response Message Field | O10: 上り項目 Request Message Field | P10: 下り項目 Response Message Field | Q10: 上り項目 Request Message Field | R10: 下り項目 Response Message Field
A11: 10 | B11: * | D11: BpGrp_Upd01_Dtl | E11: L | G11: $share$ | H11: MA.MABCL0430.BpGrp_UpdChk01.BpGrp_UpdChk01_Dtl | K11: L | M11: L
A12: 10 | D12: bp_grp_typ | E12: #MA.BP_GRP_TYP | G12: BP classification type | H12: 取引先分類区分 | I12: E | K12: E | M12: E
A13: 10 | D13: bp_grp_cd | E13: #MA.BP_GRP_CD | G13: BP classification cd. | H13: 取引先分類ＣＤ | I13: E | K13: E | M13: E
A14: 10 | D14: bp_grp_nm | E14: #MA.BP_GRP_NM | G14: BP classification name | H14: 取引先分類名 | I14: E | K14: E | M14: E
A15: 10 | D15: num_id | E15: #MA.NUM_ID | G15: Numbering ID | H15: 発番ＩＤ | I15: E | K15: E
A16: 10 | D16: memo1 | E16: #MA.MST_MEMO1 | G16: Memo 1 | H16: メモ１ | I16: E | K16: E
A17: 10 | D17: memo2 | E17: #MA.MST_MEMO2 | G17: Memo 2 | H17: メモ２ | I17: E | K17: E
A18: 10 | D18: memo3 | E18: #MA.MST_MEMO3 | G18: Memo 3 | H18: メモ３ | I18: E | K18: E
A19: 10 | D19: del_flg | E19: #MA.FLG | G19: Logical delete | H19: 論理削除 | I19: E | K19: E
A20: 10 | D20: upd_cntr | E20: #MA.UPD_CNT | G20: Update counter | H20: 更新カウンタ | I20: E | K20: E
D21: 詳細 :

Sheet BpGrpLcl_UpdChk01
A1: * | B1: * | D1: L | E1: 1
A2: * | D2: オペレーション実装仕様書 Operation Specification Implementation Sheet | E2: ModuleID : | F2: =IF(LogicCommon!C2="","",LogicCommon!C2) -> MA | G2: LogicID : | H2: =IF(LogicCommon!E2="","",LogicCommon!E2) -> MABCL0430 | I2: Ope.ID : | J2: BpGrpLcl_UpdChk01 | K2: Pj.ID : | L2: =IF(LogicCommon!G2="","",LogicCommon!G2) -> MC | M2: Ope.Body : | N2: =L4 & ".Checker" -> MA.MAUDL5010.Checker
A3: * | D3: =IF(LogicCommon!A3="","",LogicCommon!A3) | E3: SubModuleID : | F3: =IF(LogicCommon!C3="","",LogicCommon!C3) -> MABC | G3: LogicClass : | H3: =IF(LogicCommon!E3="","",LogicCommon!E3) -> MABCL_BpGrpReg | I3: Ope.Method : | J3: @ | K3: SuperClassPj.ID : | L3: =IF(LogicCommon!G3="","",LogicCommon!G3) | M3: ReportID : | O3: Gene.Type : | P3: ALL
A4: * | E4: Version : | F4: 000000 | G4: LogicName : | H4: =IF(LogicCommon!E4="","",LogicCommon!E4) -> 取引先分類マスタ登録 | I4: Ope.Name : | J4: 登録前チェック(ロケール別情報) | K4: SuperLogicID : | L4: =IF(LogicCommon!G4="","",LogicCommon!G4) -> MA.MAUDL5010
A5: * | E5: ACType :
A6: * | D6: 概要 : | E6: 取引先分類マスタ(ロケール別情報)を登録する前のチェックを行う | M6: ID
A7: # | I7: U | K7: K | L7: o | M7: EXISTS.chk01
A8: # | D8: ブロック名 Block Name | E8: 型 Type | G8: super/share | H8: 対象ブロック名 Target Block Name | K8: REQUIRED | L8: TargetName | M8: DBC.MA.MAM_BP_GRP | P8: ブロック備考 Block Remarks
A9: # | D9: 項目名 Field Name | E9: 型 Type | F9: 桁 Digits | G9: フルネーム Full Name | H9: 日本語名 Japanese Name | I9: 上り項目 Request Message Field | J9: 下り項目 Response Message Field | N9: 条件および編集方法 Conditions and Editing Methods | P9: 項目備考 Field Remarks
A10: # | L10: 上り項目 Request Message Field | M10: 下り項目 Response Message Field
A11: 10 | B11: * | D11: BpGrpLcl_UpdChk01_Dtl | E11: L | G11: $super$ | H11: DBC:MA.MAM_BP_GRP_LCL | L11: L
A12: 10 | D12: bp_grp_typ | E12: #MA.BP_GRP_TYP | G12: BP classification type | H12: 取引先分類区分 | I12: E | K12: E | L12: E
A13: 10 | D13: bp_grp_cd | E13: #MA.BP_GRP_CD | G13: BP classification cd. | H13: 取引先分類ＣＤ | I13: E | K13: E | L13: E
A14: 10 | D14: lcl_cd | E14: #MA.LCL_CD | G14: Locale cd. | H14: ロケールＣＤ | I14: E | K14: E
A15: 10 | D15: bp_grp_nm | E15: #MA.BP_GRP_NM | G15: BP classification name | H15: 取引先分類名 | I15: E | K15: E
A16: 10 | D16: memo1 | E16: #MA.MST_MEMO1 | G16: Memo 1 | H16: メモ１ | I16: E
A17: 10 | D17: memo2 | E17: #MA.MST_MEMO2 | G17: Memo 2 | H17: メモ２ | I17: E
A18: 10 | D18: memo3 | E18: #MA.MST_MEMO3 | G18: Memo 3 | H18: メモ３ | I18: E
A19: 10 | D19: upd_cntr | E19: #MA.UPD_CNT | G19: Update counter | H19: 更新カウンタ | I19: E
D20: 詳細 :

Sheet BpGrpLcl_Upd01
A1: * | B1: * | D1: L | E1: 1
A2: * | D2: オペレーション実装仕様書 Operation Specification Implementation Sheet | E2: ModuleID : | F2: =IF(LogicCommon!C2="","",LogicCommon!C2) -> MA | G2: LogicID : | H2: =IF(LogicCommon!E2="","",LogicCommon!E2) -> MABCL0430 | I2: Ope.ID : | J2: BpGrpLcl_Upd01 | K2: Pj.ID : | L2: =IF(LogicCommon!G2="","",LogicCommon!G2) -> MC | M2: Ope.Body : | N2: "mcframe.serverMAUD.MAUDL6020.MAUDL_LCLRLUpdater"
A3: * | D3: =IF(LogicCommon!A3="","",LogicCommon!A3) | E3: SubModuleID : | F3: =IF(LogicCommon!C3="","",LogicCommon!C3) -> MABC | G3: LogicClass : | H3: =IF(LogicCommon!E3="","",LogicCommon!E3) -> MABCL_BpGrpReg | I3: Ope.Method : | J3: @ | K3: SuperClassPj.ID : | L3: =IF(LogicCommon!G3="","",LogicCommon!G3) | M3: ReportID : | O3: Gene.Type : | P3: ALL
A4: * | E4: Version : | F4: 000000 | G4: LogicName : | H4: =IF(LogicCommon!E4="","",LogicCommon!E4) -> 取引先分類マスタ登録 | I4: Ope.Name : | J4: 登録処理(ロケール別情報) | K4: SuperLogicID : | L4: =IF(LogicCommon!G4="","",LogicCommon!G4) -> MA.MAUDL5010
A5: * | E5: ACType :
A6: * | D6: 概要 : | E6: 取引先分類マスタ(ロケール別情報)を登録する | L6: ID | N6: ID | P6: ID | R6: ID
A7: # | I7: U | K7: o | L7: UPDATE.updMaster | M7: o | N7: MAIN.chkMaster | O7: o | Q7: o
A8: # | D8: ブロック名 Block Name | E8: 型 Type | G8: super/share | H8: 対象ブロック名 Target Block Name | K8: TargetName | L8: DBC.MA.MAM_BP_GRP_LCL | M8: TargetName | N8: DBC.MA.MAM_BP_GRP_LCL | O8: TargetName | Q8: TargetName | U8: ブロック備考 Block Remarks
A9: # | D9: 項目名 Field Name | E9: 型 Type | F9: 桁 Digits | G9: フルネーム Full Name | H9: 日本語名 Japanese Name | I9: 上り項目 Request Message Field | J9: 下り項目 Response Message Field | S9: 条件および編集方法 Conditions and Editing Methods | U9: 項目備考 Field Remarks
A10: # | K10: 上り項目 Request Message Field | L10: 下り項目 Response Message Field | M10: 上り項目 Request Message Field | N10: 下り項目 Response Message Field | O10: 上り項目 Request Message Field | P10: 下り項目 Response Message Field | Q10: 上り項目 Request Message Field | R10: 下り項目 Response Message Field
A11: 10 | B11: * | D11: BpGrpLcl_Upd01_Dtl | E11: L | G11: $share$ | H11: MA.MABCL0430.BpGrpLcl_UpdChk01.BpGrpLcl_UpdChk01_Dtl | K11: L | M11: L
A12: 10 | D12: bp_grp_typ | E12: #MA.BP_GRP_TYP | G12: BP classification type | H12: 取引先分類区分 | I12: E | K12: E | M12: E
A13: 10 | D13: bp_grp_cd | E13: #MA.BP_GRP_CD | G13: BP classification cd. | H13: 取引先分類ＣＤ | I13: E | K13: E | M13: E
A14: 10 | D14: lcl_cd | E14: #MA.LCL_CD | G14: Locale cd. | H14: ロケールＣＤ | I14: E | K14: E | M14: E
A15: 10 | D15: bp_grp_nm | E15: #MA.BP_GRP_NM | G15: BP classification name | H15: 取引先分類名 | I15: E | K15: E | M15: E
A16: 10 | D16: memo1 | E16: #MA.MST_MEMO1 | G16: Memo 1 | H16: メモ１ | I16: E | K16: E
A17: 10 | D17: memo2 | E17: #MA.MST_MEMO2 | G17: Memo 2 | H17: メモ２ | I17: E | K17: E
A18: 10 | D18: memo3 | E18: #MA.MST_MEMO3 | G18: Memo 3 | H18: メモ３ | I18: E | K18: E
A19: 10 | D19: upd_cntr | E19: #MA.UPD_CNT | G19: Update counter | H19: 更新カウンタ | I19: E | K19: E
D20: 詳細 :

Sheet BpGrp_DelChk01
A1: * | B1: * | D1: L | E1: 1
A2: * | D2: オペレーション実装仕様書 Operation Specification Implementation Sheet | E2: ModuleID : | F2: =IF(LogicCommon!C2="","",LogicCommon!C2) -> MA | G2: LogicID : | H2: =IF(LogicCommon!E2="","",LogicCommon!E2) -> MABCL0430 | I2: Ope.ID : | J2: BpGrp_DelChk01 | K2: Pj.ID : | L2: =IF(LogicCommon!G2="","",LogicCommon!G2) -> MC | M2: Ope.Body : | N2: =L4 & ".Checker" -> MA.MAUDL5010.Checker
A3: * | D3: =IF(LogicCommon!A3="","",LogicCommon!A3) | E3: SubModuleID : | F3: =IF(LogicCommon!C3="","",LogicCommon!C3) -> MABC | G3: LogicClass : | H3: =IF(LogicCommon!E3="","",LogicCommon!E3) -> MABCL_BpGrpReg | I3: Ope.Method : | J3: @ | K3: SuperClassPj.ID : | L3: =IF(LogicCommon!G3="","",LogicCommon!G3) | M3: ReportID : | O3: Gene.Type : | P3: ALL
A4: * | E4: Version : | F4: 000000 | G4: LogicName : | H4: =IF(LogicCommon!E4="","",LogicCommon!E4) -> 取引先分類マスタ登録 | I4: Ope.Name : | J4: 削除チェック | K4: SuperLogicID : | L4: =IF(LogicCommon!G4="","",LogicCommon!G4) -> MA.MAUDL5010
A5: * | E5: ACType :
A6: * | D6: 概要 : | E6: 取引先分類マスタ、取引先分類マスタ(ロケール別情報)を削除する前のチェックを行う | P6: ID
A7: # | I7: U | K7: K | L7: K | M7: K | N7: K | O7: o
A8: # | D8: ブロック名 Block Name | E8: 型 Type | G8: super/share | H8: 対象ブロック名 Target Block Name | K8: NULL_VAL | L8: REQUIRED | M8: SCALE | N8: CONST | O8: TargetName | S8: ブロック備考 Block Remarks
A9: # | D9: 項目名 Field Name | E9: 型 Type | F9: 桁 Digits | G9: フルネーム Full Name | H9: 日本語名 Japanese Name | I9: 上り項目 Request Message Field | J9: 下り項目 Response Message Field | Q9: 条件および編集方法 Conditions and Editing Methods | S9: 項目備考 Field Remarks
A10: # | O10: 上り項目 Request Message Field | P10: 下り項目 Response Message Field
A11: 10 | B11: * | D11: BpGrp_DelChk01_Dtl | E11: L
A12: 10 | D12: bp_grp_typ | E12: #MA.BP_GRP_TYP | G12: BP classification type | H12: 取引先分類区分 | I12: E | L12: E
A13: 10 | D13: bp_grp_cd | E13: #MA.BP_GRP_CD | G13: BP classification cd. | H13: 取引先分類ＣＤ | I13: E | L13: E
A14: 10 | D14: upd_cntr | E14: #MA.UPD_CNT | G14: Update counter | H14: 更新カウンタ | I14: E
D15: 詳細 :

Sheet BpGrp_Del01
A1: * | B1: * | D1: L | E1: 1
A2: * | D2: オペレーション実装仕様書 Operation Specification Implementation Sheet | E2: ModuleID : | F2: =IF(LogicCommon!C2="","",LogicCommon!C2) -> MA | G2: LogicID : | H2: =IF(LogicCommon!E2="","",LogicCommon!E2) -> MABCL0430 | I2: Ope.ID : | J2: BpGrp_Del01 | K2: Pj.ID : | L2: =IF(LogicCommon!G2="","",LogicCommon!G2) -> MC | M2: Ope.Body : | N2: "mcframe.serverMAUD.MAUDL6020.MAUDL_LCLRLDeleter"
A3: * | D3: =IF(LogicCommon!A3="","",LogicCommon!A3) | E3: SubModuleID : | F3: =IF(LogicCommon!C3="","",LogicCommon!C3) -> MABC | G3: LogicClass : | H3: =IF(LogicCommon!E3="","",LogicCommon!E3) -> MABCL_BpGrpReg | I3: Ope.Method : | J3: @ | K3: SuperClassPj.ID : | L3: =IF(LogicCommon!G3="","",LogicCommon!G3) | M3: ReportID : | O3: Gene.Type : | P3: ALL
A4: * | E4: Version : | F4: 000000 | G4: LogicName : | H4: =IF(LogicCommon!E4="","",LogicCommon!E4) -> 取引先分類マスタ登録 | I4: Ope.Name : | J4: 削除処理 | K4: SuperLogicID : | L4: =IF(LogicCommon!G4="","",LogicCommon!G4) -> MA.MAUDL5010
A5: * | E5: ACType :
A6: * | D6: 概要 : | E6: 取引先分類マスタ、取引先分類マスタ(ロケール別情報)を削除する | L6: ID | N6: ID
A7: # | I7: U | K7: o | L7: UPDATE.updMaster1 | M7: o | N7: UPDATE.updMaster2
A8: # | D8: ブロック名 Block Name | E8: 型 Type | G8: super/share | H8: 対象ブロック名 Target Block Name | K8: TargetName | L8: DBC.MA.MAM_BP_GRP | M8: TargetName | N8: DBC.MA.MAM_BP_GRP_LCL | Q8: ブロック備考 Block Remarks
A9: # | D9: 項目名 Field Name | E9: 型 Type | F9: 桁 Digits | G9: フルネーム Full Name | H9: 日本語名 Japanese Name | I9: 上り項目 Request Message Field | J9: 下り項目 Response Message Field | O9: 条件および編集方法 Conditions and Editing Methods | Q9: 項目備考 Field Remarks
A10: # | K10: 上り項目 Request Message Field | L10: 下り項目 Response Message Field | M10: 上り項目 Request Message Field | N10: 下り項目 Response Message Field
A11: 10 | B11: * | D11: BpGrp_Del01_Dtl | E11: L | G11: $share$ | H11: MA.MABCL0430.BpGrp_DelChk01.BpGrp_DelChk01_Dtl | K11: L | M11: L
A12: 10 | D12: bp_grp_typ | E12: #MA.BP_GRP_TYP | G12: BP classification type | H12: 取引先分類区分 | I12: E | K12: E | M12: E
A13: 10 | D13: bp_grp_cd | E13: #MA.BP_GRP_CD | G13: BP classification cd. | H13: 取引先分類ＣＤ | I13: E | K13: E | M13: E
A14: 10 | D14: upd_cntr | E14: #MA.UPD_CNT | G14: Update counter | H14: 更新カウンタ | I14: E | K14: E
D15: 詳細 :

Sheet Srch01
A1: * | B1: * | D1: L | E1: 1
A2: * | D2: オペレーション実装仕様書 Operation Specification Implementation Sheet | E2: ModuleID : | F2: =IF(LogicCommon!C2="","",LogicCommon!C2) -> MA | G2: LogicID : | H2: =IF(LogicCommon!E2="","",LogicCommon!E2) -> MABCL0430 | I2: Ope.ID : | J2: Srch01 | K2: Pj.ID : | L2: =IF(LogicCommon!G2="","",LogicCommon!G2) -> MC | M2: Ope.Body : | N2: "mcframe.serverMAUD.MAUDL6020.MAUDL_LCLRLSearcher"
A3: * | D3: =IF(LogicCommon!A3="","",LogicCommon!A3) | E3: SubModuleID : | F3: =IF(LogicCommon!C3="","",LogicCommon!C3) -> MABC | G3: LogicClass : | H3: =IF(LogicCommon!E3="","",LogicCommon!E3) -> MABCL_BpGrpReg | I3: Ope.Method : | J3: @ | K3: SuperClassPj.ID : | L3: =IF(LogicCommon!G3="","",LogicCommon!G3) | M3: ReportID : | O3: Gene.Type : | P3: ALL
A4: * | E4: Version : | F4: 000000 | G4: LogicName : | H4: =IF(LogicCommon!E4="","",LogicCommon!E4) -> 取引先分類マスタ登録 | I4: Ope.Name : | J4: 検索 | K4: SuperLogicID : | L4: =IF(LogicCommon!G4="","",LogicCommon!G4) -> MA.MAUDL5010
A5: * | E5: ACType :
A6: * | D6: 概要 : | E6: 検索処理を行う | M6: ID | O6: ID
A7: # | I7: U | K7: K | L7: o | M7: SELECT.c0 | N7: o | O7: SELECT_LCL.c1
A8: # | D8: ブロック名 Block Name | E8: 型 Type | G8: super/share | H8: 対象ブロック名 Target Block Name | K8: CONST | L8: TargetName | M8: DBC.MA.MAM_BP_GRP | N8: TargetName | O8: DBC.MA.MAM_BP_GRP_LCL | R8: ブロック備考 Block Remarks
A9: # | D9: 項目名 Field Name | E9: 型 Type | F9: 桁 Digits | G9: フルネーム Full Name | H9: 日本語名 Japanese Name | I9: 上り項目 Request Message Field | J9: 下り項目 Response Message Field | P9: 条件および編集方法 Conditions and Editing Methods | R9: 項目備考 Field Remarks
A10: # | L10: 上り項目 Request Message Field | M10: 下り項目 Response Message Field | N10: 上り項目 Request Message Field | O10: 下り項目 Response Message Field
A11: 10 | B11: * | D11: Srch01_Cnd | E11: R
A12: 10 | D12: bp_grp_typ | E12: #MA.BP_GRP_TYP | G12: BP classification type | H12: 取引先分類区分 | I12: E
A13: 10 | D13: bp_grp_cd | E13: #MA.BP_GRP_CD | G13: BP classification cd. | H13: 取引先分類ＣＤ | I13: E
A14: 10 | D14: bp_grp_nm_lcl | E14: #MA.BP_GRP_NM | G14: BP classification name | H14: 取引先分類名 | I14: E
A15: 10 | D15: off_del_flg | E15: #MA.FLG | G15: Logical delete. Off | H15: 論理削除.オフ | I15: E
A16: 10 | D16: on_del_flg | E16: #MA.FLG | G16: Logical delete. On | H16: 論理削除.オン | I16: E
A17: 10 | D17: memo1 | E17: #MA.MST_MEMO1 | G17: Memo 1 | H17: メモ１ | I17: E
A18: 10 | D18: memo2 | E18: #MA.MST_MEMO2 | G18: Memo 2 | H18: メモ２ | I18: E
A19: 10 | D19: memo3 | E19: #MA.MST_MEMO3 | G19: Memo 3 | H19: メモ３ | I19: E
A21: 20 | B21: * | D21: Srch01_Rslt1 | E21: L | M21: L
A22: 20 | D22: del_flg | E22: #MA.FLG | G22: Logical delete | H22: 論理削除 | J22: E | M22: E
A23: 20 | D23: bp_grp_typ | E23: #MA.BP_GRP_TYP | G23: BP classification type | H23: 取引先分類区分 | J23: E | K23: MAC_BP_GRP_TYP | M23: E
A24: 20 | D24: bp_grp_typ_nm | E24: #MA.BP_GRP_TYP_NM | G24: BP classification type name | H24: 取引先分類区分名 | J24: E
A25: 20 | D25: bp_grp_cd | E25: #MA.BP_GRP_CD | G25: BP classification cd. | H25: 取引先分類ＣＤ | J25: E | M25: E
A26: 20 | D26: bp_grp_nm_lcl | E26: #MA.BP_GRP_NM | G26: BP classification name | H26: 取引先分類名 | J26: E | M26: bp_grp_nm
A27: 20 | D27: bp_grp_nm | E27: #MA.BP_GRP_NM | G27: Standard BP classification name | H27: 標準取引先分類名 | J27: E | M27: base_bp_grp_nm
A28: 20 | D28: num_id | E28: #MA.NUM_ID | G28: Numbering ID | H28: 発番ＩＤ | J28: E | M28: E
A29: 20 | D29: memo1 | E29: #MA.MST_MEMO1 | G29: Memo 1 | H29: メモ１ | J29: E | M29: E
A30: 20 | D30: memo2 | E30: #MA.MST_MEMO2 | G30: Memo 2 | H30: メモ２ | J30: E | M30: E
A31: 20 | D31: memo3 | E31: #MA.MST_MEMO3 | G31: Memo 3 | H31: メモ３ | J31: E | M31: E
A32: 20 | D32: ins_usr_id | E32: #MA.FCM_USR_ID | G32: Entry user ID | H32: 登録ユーザＩＤ | J32: E | M32: E
A33: 20 | D33: ins_usr_nm | E33: #MA.FCM_USR_NM | G33: Entry user name | H33: 登録ユーザ名 | J33: E | M33: E
A34: 20 | D34: ins_ts | E34: #MA.SYS_TS | G34: Entry date and time | H34: 登録日時 | J34: E | M34: E
A35: 20 | D35: ins_func_id | E35: #MA.FUNC_ID | G35: Entry function ID | H35: 登録機能ＩＤ | J35: E | M35: E
A36: 20 | D36: ins_func_nm | E36: #MA.FUNC_NM | G36: Entry function name | H36: 登録機能名 | J36: E
A37: 20 | D37: upd_cntr | E37: #MA.UPD_CNT | G37: Update counter | H37: 更新カウンタ | J37: E | M37: E
A38: 20 | D38: upd_usr_id | E38: #MA.FCM_USR_ID | G38: Update user ID | H38: 更新ユーザＩＤ | J38: E | M38: E
A39: 20 | D39: upd_usr_nm | E39: #MA.FCM_USR_NM | G39: Update user name | H39: 更新ユーザ名 | J39: E | M39: E
A40: 20 | D40: upd_ts | E40: #MA.SYS_TS | G40: Update date and time | H40: 更新日時 | J40: E | M40: E
A41: 20 | D41: upd_func_id | E41: #MA.FUNC_ID | G41: Update function ID | H41: 更新機能ＩＤ | J41: E | M41: E
...

Sheet Upd01
A1: * | B1: * | D1: L | E1: 1
A2: * | D2: オペレーション実装仕様書 Operation Specification Implementation Sheet | E2: ModuleID : | F2: =IF(LogicCommon!C2="","",LogicCommon!C2) -> MA | G2: LogicID : | H2: =IF(LogicCommon!E2="","",LogicCommon!E2) -> MABCL0430 | I2: Ope.ID : | J2: Upd01 | K2: Pj.ID : | L2: =IF(LogicCommon!G2="","",LogicCommon!G2) -> MC | M2: Ope.Body : | N2: "mcframe.serverMAUD.MAUDL6020.MAUDL_LCLRLUpdater"
A3: * | D3: =IF(LogicCommon!A3="","",LogicCommon!A3) | E3: SubModuleID : | F3: =IF(LogicCommon!C3="","",LogicCommon!C3) -> MABC | G3: LogicClass : | H3: =IF(LogicCommon!E3="","",LogicCommon!E3) -> MABCL_BpGrpReg | I3: Ope.Method : | J3: @ | K3: SuperClassPj.ID : | L3: =IF(LogicCommon!G3="","",LogicCommon!G3) | M3: ReportID : | O3: Gene.Type : | P3: ALL
A4: * | E4: Version : | F4: 000000 | G4: LogicName : | H4: =IF(LogicCommon!E4="","",LogicCommon!E4) -> 取引先分類マスタ登録 | I4: Ope.Name : | J4: 登録 | K4: SuperLogicID : | L4: =IF(LogicCommon!G4="","",LogicCommon!G4) -> MA.MAUDL5010
A5: * | E5: ACType :
A6: * | D6: 概要 : | E6: 登録処理を行う | L6: ID | N6: ID | P6: ID | R6: ID
A7: # | I7: U | K7: o | L7: CALL_OPE01.chk01 | M7: o | N7: CALL_OPE01.upd01 | O7: o | P7: CALL_OPE02.chk02 | Q7: o | R7: CALL_OPE02.upd02
A8: # | D8: ブロック名 Block Name | E8: 型 Type | G8: super/share | H8: 対象ブロック名 Target Block Name | K8: TargetName | L8: OPE.MA.MABCL0430.BpGrp_UpdChk01 | M8: TargetName | N8: OPE.MA.MABCL0430.BpGrp_Upd01 | O8: TargetName | P8: OPE.MA.MABCL0430.BpGrpLcl_UpdChk01 | Q8: TargetName | R8: OPE.MA.MABCL0430.BpGrpLcl_Upd01 | U8: ブロック備考 Block Remarks
A9: # | D9: 項目名 Field Name | E9: 型 Type | F9: 桁 Digits | G9: フルネーム Full Name | H9: 日本語名 Japanese Name | I9: 上り項目 Request Message Field | J9: 下り項目 Response Message Field | S9: 条件および編集方法 Conditions and Editing Methods | U9: 項目備考 Field Remarks
A10: # | K10: 上り項目 Request Message Field | L10: 下り項目 Response Message Field | M10: 上り項目 Request Message Field | N10: 下り項目 Response Message Field | O10: 上り項目 Request Message Field | P10: 下り項目 Response Message Field | Q10: 上り項目 Request Message Field | R10: 下り項目 Response Message Field
A11: 10 | B11: * | D11: Upd01_Dtl1 | E11: L | G11: $share$ | H11: MA.MABCL0430.BpGrp_Upd01.BpGrp_Upd01_Dtl | K11: BpGrp_UpdChk01_Dtl | M11: BpGrp_Upd01_Dtl
A12: 10 | D12: bp_grp_typ | E12: #MA.BP_GRP_TYP | G12: BP classification type | H12: 取引先分類区分 | I12: E | K12: E | M12: E
A13: 10 | D13: bp_grp_cd | E13: #MA.BP_GRP_CD | G13: BP classification cd. | H13: 取引先分類ＣＤ | I13: E | K13: E | M13: E
A14: 10 | D14: bp_grp_nm | E14: #MA.BP_GRP_NM | G14: BP classification name | H14: 取引先分類名 | I14: E | K14: E | M14: E
A15: 10 | D15: num_id | E15: #MA.NUM_ID | G15: Numbering ID | H15: 発番ＩＤ | I15: E | K15: E | M15: E
A16: 10 | D16: memo1 | E16: #MA.MST_MEMO1 | G16: Memo 1 | H16: メモ１ | I16: E | K16: E | M16: E
A17: 10 | D17: memo2 | E17: #MA.MST_MEMO2 | G17: Memo 2 | H17: メモ２ | I17: E | K17: E | M17: E
A18: 10 | D18: memo3 | E18: #MA.MST_MEMO3 | G18: Memo 3 | H18: メモ３ | I18: E | K18: E | M18: E
A19: 10 | D19: del_flg | E19: #MA.FLG | G19: Logical delete | H19: 論理削除 | I19: E | K19: E | M19: E
A20: 10 | D20: upd_cntr | E20: #MA.UPD_CNT | G20: Update counter | H20: 更新カウンタ | I20: E | K20: E | M20: E
A22: 20 | B22: * | D22: Upd01_Dtl2 | E22: L | G22: $share$ | H22: MA.MABCL0430.BpGrpLcl_Upd01.BpGrpLcl_Upd01_Dtl | O22: BpGrpLcl_UpdChk01_Dtl | Q22: BpGrpLcl_Upd01_Dtl
A23: 20 | D23: bp_grp_typ | E23: #MA.BP_GRP_TYP | G23: BP classification type | H23: 取引先分類区分 | I23: E | O23: E | Q23: E
A24: 20 | D24: lcl_cd | E24: #MA.LCL_CD | G24: Locale cd. | H24: ロケールＣＤ | I24: E | O24: E | Q24: E
A25: 20 | D25: bp_grp_cd | E25: #MA.BP_GRP_CD | G25: BP classification cd. | H25: 取引先分類ＣＤ | I25: E | O25: E | Q25: E
A26: 20 | D26: bp_grp_nm | E26: #MA.BP_GRP_NM | G26: BP classification name | H26: 取引先分類名 | I26: E | O26: E | Q26: E
A27: 20 | D27: memo1 | E27: #MA.MST_MEMO1 | G27: Memo 1 | H27: メモ１ | I27: E | O27: E | Q27: E
A28: 20 | D28: memo2 | E28: #MA.MST_MEMO2 | G28: Memo 2 | H28: メモ２ | I28: E | O28: E | Q28: E
A29: 20 | D29: memo3 | E29: #MA.MST_MEMO3 | G29: Memo 3 | H29: メモ３ | I29: E | O29: E | Q29: E
A30: 20 | D30: upd_cntr | E30: #MA.UPD_CNT | G30: Update counter | H30: 更新カウンタ | I30: E | O30: E | Q30: E
D31: 詳細 :

Sheet Del01
A1: * | B1: * | D1: L | E1: 1
A2: * | D2: オペレーション実装仕様書 Operation Specification Implementation Sheet | E2: ModuleID : | F2: =IF(LogicCommon!C2="","",LogicCommon!C2) -> MA | G2: LogicID : | H2: =IF(LogicCommon!E2="","",LogicCommon!E2) -> MABCL0430 | I2: Ope.ID : | J2: Del01 | K2: Pj.ID : | L2: =IF(LogicCommon!G2="","",LogicCommon!G2) -> MC | M2: Ope.Body : | N2: "mcframe.serverMAUD.MAUDL6020.MAUDL_LCLRLDeleter"
A3: * | D3: =IF(LogicCommon!A3="","",LogicCommon!A3) | E3: SubModuleID : | F3: =IF(LogicCommon!C3="","",LogicCommon!C3) -> MABC | G3: LogicClass : | H3: =IF(LogicCommon!E3="","",LogicCommon!E3) -> MABCL_BpGrpReg | I3: Ope.Method : | J3: @ | K3: SuperClassPj.ID : | L3: =IF(LogicCommon!G3="","",LogicCommon!G3) | M3: ReportID : | O3: Gene.Type : | P3: ALL
A4: * | E4: Version : | F4: 000000 | G4: LogicName : | H4: =IF(LogicCommon!E4="","",LogicCommon!E4) -> 取引先分類マスタ登録 | I4: Ope.Name : | J4: 削除 | K4: SuperLogicID : | L4: =IF(LogicCommon!G4="","",LogicCommon!G4) -> MA.MAUDL5010
A5: * | E5: ACType :
A6: * | D6: 概要 : | E6: 削除処理を行う | L6: ID | N6: ID
A7: # | I7: U | K7: o | L7: CALL_OPE01.chk01 | M7: o | N7: CALL_OPE01.del01
A8: # | D8: ブロック名 Block Name | E8: 型 Type | G8: super/share | H8: 対象ブロック名 Target Block Name | K8: TargetName | L8: OPE.MA.MABCL0430.BpGrp_DelChk01 | M8: TargetName | N8: OPE.MA.MABCL0430.BpGrp_Del01 | Q8: ブロック備考 Block Remarks
A9: # | D9: 項目名 Field Name | E9: 型 Type | F9: 桁 Digits | G9: フルネーム Full Name | H9: 日本語名 Japanese Name | I9: 上り項目 Request Message Field | J9: 下り項目 Response Message Field | O9: 条件および編集方法 Conditions and Editing Methods | Q9: 項目備考 Field Remarks
A10: # | K10: 上り項目 Request Message Field | L10: 下り項目 Response Message Field | M10: 上り項目 Request Message Field | N10: 下り項目 Response Message Field
A11: 10 | B11: * | D11: Del01_Dtl1 | E11: L | G11: $share$ | H11: MA.MABCL0430.BpGrp_Del01.BpGrp_Del01_Dtl | K11: BpGrp_DelChk01_Dtl | M11: BpGrp_Del01_Dtl
A12: 10 | D12: bp_grp_typ | E12: #MA.BP_GRP_TYP | G12: BP classification type | H12: 取引先分類区分 | I12: E | K12: E | M12: E
A13: 10 | D13: bp_grp_cd | E13: #MA.BP_GRP_CD | G13: BP classification cd. | H13: 取引先分類ＣＤ | I13: E | K13: E | M13: E
A14: 10 | D14: upd_cntr | E14: #MA.UPD_CNT | G14: Update counter | H14: 更新カウンタ | I14: E | K14: E | M14: E
D15: 詳細 :

Sheet 来歴
A1: 変更来歴
A3: Rev. | H3: 修正番号 | O3: 変更内容 | AQ3: 変更箇所
A4: 1 | O4: 初版
A5: 1.1 | O5: 英語の名称を追記 | AQ5: 全般
