Workbook

Sheet LogicCommon
A2: ロジック共通定義 | B2: ModuleID : | C2: MA | D2: LogicID : | E2: MABCL0940 | F2: Pj.ID : | G2: MC
B3: SubModuleID : | C3: MABC | D3: LogicClass : | E3: MABCL_BizRsnReg | F3: SuperClassPj.ID :
D4: LogicName : | E4: 業務理由マスタ登録 | F4: SuperLogicID : | G4: MA.MAUDL5010
A5: 概要 :
A6: 詳細 :

Sheet BizRsn_UpdChk01
A1: * | B1: * | D1: L | E1: 1
A2: * | D2: オペレーション実装仕様書 Operation Specification Implementation Sheet | E2: ModuleID : | F2: =IF(LogicCommon!C2="","",LogicCommon!C2) -> MA | G2: LogicID : | H2: =IF(LogicCommon!E2="","",LogicCommon!E2) -> MABCL0940 | I2: Ope.ID : | J2: BizRsn_UpdChk01 | K2: Pj.ID : | L2: =IF(LogicCommon!G2="","",LogicCommon!G2) -> MC | M2: Ope.Body : | N2: =L4 & ".Checker" -> MA.MAUDL5010.Checker
A3: * | D3: =IF(LogicCommon!A3="","",LogicCommon!A3) | E3: SubModuleID : | F3: =IF(LogicCommon!C3="","",LogicCommon!C3) -> MABC | G3: LogicClass : | H3: =IF(LogicCommon!E3="","",LogicCommon!E3) -> MABCL_BizRsnReg | I3: Ope.Method : | J3: @ | K3: SuperClassPj.ID : | L3: =IF(LogicCommon!G3="","",LogicCommon!G3) | M3: ReportID : | O3: Gene.Type : | P3: ALL
A4: * | E4: Version : | F4: 000000 | G4: LogicName : | H4: =IF(LogicCommon!E4="","",LogicCommon!E4) -> 業務理由マスタ登録 | I4: Ope.Name : | J4: 登録前チェック | K4: SuperLogicID : | L4: =IF(LogicCommon!G4="","",LogicCommon!G4) -> MA.MAUDL5010
A5: * | E5: ACType :
A6: * | D6: 概要 : | E6: 業務理由マスタを登録する前のチェックを行う | Q6: ID
A7: # | I7: U | K7: K | L7: K | M7: K | N7: K | O7: K | P7: o
A8: # | D8: ブロック名 Block Name | E8: 型 Type | G8: super/share | H8: 対象ブロック名 Target Block Name | K8: REQUIRED | L8: CONST | M8: LIST_LOGIC | N8: SMALL_LARGE | O8: TOO_MANY_INPUTS | P8: TargetName | T8: ブロック備考 Block Remarks
A9: # | D9: 項目名 Field Name | E9: 型 Type | F9: 桁 Digits | G9: フルネーム Full Name | H9: 日本語名 Japanese Name | I9: 上り項目 Request Message Field | J9: 下り項目 Response Message Field | R9: 条件および編集方法 Conditions and Editing Methods | T9: 項目備考 Field Remarks
A10: # | P10: 上り項目 Request Message Field | Q10: 下り項目 Response Message Field
A11: 10 | B11: * | D11: BizRsn_UpdChk01_Dtl | E11: L | G11: $super$ | H11: DBC:MA.MAM_BIZ_RSN
A12: 10 | D12: biz_rsn_cd | E12: #MA.BIZ_RSN_CD | G12: Business reason cd. | H12: 業務理由ＣＤ | I12: E | K12: E
A13: 10 | D13: biz_rsn_nm | E13: #MA.BIZ_RSN_NM | G13: Business reason name | H13: 業務理由名 | I13: E | K13: E
A14: 10 | D14: ac_rsn_cd | E14: #MA.AC_RSN_CD | G14: Accounting reason cd. | H14: 会計理由ＣＤ | I14: E | M14: MA.MAUAL0010.AcRsn
A15: 10 | D15: purc_flg | E15: #MA.FLG | G15: Purchase | H15: 仕入 | I15: E
A16: 10 | D16: purc_sort_seq | E16: #MA.INT | G16: Purchase sort order | H16: 仕入ソート順 | I16: E | N16: 0:
A17: 10 | D17: purc_rtn_flg | E17: #MA.FLG | G17: Purchase return | H17: 仕入返品 | I17: E
A18: 10 | D18: purc_rtn_sort_seq | E18: #MA.INT | G18: Purchase return sort order | H18: 仕入返品ソート順 | I18: E | N18: 0:
A19: 10 | D19: xpns_purc_flg | E19: #MA.FLG | G19: Expense purchase | H19: 経費購買 | I19: E
A20: 10 | D20: slo_xpns_purc_flg | E20: #MA.FLG | G20: Expense purchase (pegged to sales order) | H20: 受注紐付経費購買 | I20: E
A21: 10 | D21: purc_dscnt_flg | E21: #MA.FLG | G21: Purchase adjustment | H21: 仕入調整 | I21: E
A22: 10 | D22: purc_dscnt_loc_mng_typ | E22: #MA.LOC_MNG_TYP | G22: Purchase adjustment controlling site type | H22: 仕入調整管轄区分 | I22: E | L22: MAC_LOC_MNG_TYP
A23: 10 | D23: purc_dscnt_sort_seq | E23: #MA.INT | G23: Purchase adjustment sort order | H23: 仕入調整ソート順 | I23: E | N23: 0:
A24: 10 | D24: sls_flg | E24: #MA.FLG | G24: Sales result | H24: 売上 | I24: E
A25: 10 | D25: sls_sort_seq | E25: #MA.INT | G25: Sales sort order | H25: 売上ソート順 | I25: E | N25: 0:
A26: 10 | D26: sls_rtn_flg | E26: #MA.FLG | G26: Sales return | H26: 売上返品 | I26: E
A27: 10 | D27: sls_rtn_sort_seq | E27: #MA.INT | G27: Sales return sort order | H27: 売上返品ソート順 | I27: E | N27: 0:
A28: 10 | D28: sls_acxfr_flg | E28: #MA.FLG | G28: Sales other accounting | H28: 販売他勘定 | I28: E
A29: 10 | D29: sls_dscnt_flg | E29: #MA.FLG | G29: Sales adjustment | H29: 売上調整 | I29: E
A30: 10 | D30: sls_dscnt_sort_seq | E30: #MA.INT | G30: Sales adjustment sort order | H30: 売上調整ソート順 | I30: E | N30: 0:
A31: 10 | D31: acxfr_gr_flg | E31: #MA.FLG | G31: Other accounting GR | H31: 他勘定入庫 | I31: E | O31: E
A32: 10 | D32: acxfr_gr_sort_seq | E32: #MA.INT | G32: Other accounting GR sort order | H32: 他勘定入庫ソート順 | I32: E | N32: 0:
A33: 10 | D33: acxfr_gi_flg | E33: #MA.FLG | G33: Other accounting GI | H33: 他勘定出庫 | I33: E | O33: E
A34: 10 | D34: acxfr_gi_sort_seq | E34: #MA.INT | G34: Other accounting GI sort order | H34: 他勘定出庫ソート順 | I34: E | N34: 0:
A35: 10 | D35: inpt_acxfr_sort_seq | E35: #MA.INT | G35: Input other accounting sort order | H35: 投入他勘定ソート順 | I35: E | N35: 0:
A36: 10 | D36: disp_flg | E36: #MA.FLG | G36: Disposal | H36: 廃棄 | I36: E
A37: 10 | D37: disp_sort_seq | E37: #MA.INT | G37: Disposal sort order | H37: 廃棄ソート順 | I37: E | N37: 0:
A38: 10 | D38: stk_xfr_flg | E38: #MA.FLG | G38: Inventory transfer | H38: 在庫振替 | I38: E
A39: 10 | D39: stk_xfr_sort_seq | E39: #MA.INT | G39: Inventory transfer sort order | H39: 在庫振替ソート順 | I39: E | N39: 0:
A40: 10 | D40: xfr_flg | E40: #MA.FLG | G40: Transport | H40: 移送 | I40: E
...

Sheet BizRsn_Upd01
A1: * | B1: * | D1: L | E1: 1
A2: * | D2: オペレーション実装仕様書 Operation Specification Implementation Sheet | E2: ModuleID : | F2: =IF(LogicCommon!C2="","",LogicCommon!C2) -> MA | G2: LogicID : | H2: =IF(LogicCommon!E2="","",LogicCommon!E2) -> MABCL0940 | I2: Ope.ID : | J2: BizRsn_Upd01 | K2: Pj.ID : | L2: =IF(LogicCommon!G2="","",LogicCommon!G2) -> MC | M2: Ope.Body : | N2: "mcframe.serverMAUD.MAUDL6020.MAUDL_LCLRLUpdater"
A3: * | D3: =IF(LogicCommon!A3="","",LogicCommon!A3) | E3: SubModuleID : | F3: =IF(LogicCommon!C3="","",LogicCommon!C3) -> MABC | G3: LogicClass : | H3: =IF(LogicCommon!E3="","",LogicCommon!E3) -> MABCL_BizRsnReg | I3: Ope.Method : | J3: @ | K3: SuperClassPj.ID : | L3: =IF(LogicCommon!G3="","",LogicCommon!G3) | M3: ReportID : | O3: Gene.Type : | P3: ALL
A4: * | E4: Version : | F4: 000000 | G4: LogicName : | H4: =IF(LogicCommon!E4="","",LogicCommon!E4) -> 業務理由マスタ登録 | I4: Ope.Name : | J4: 登録処理 | K4: SuperLogicID : | L4: =IF(LogicCommon!G4="","",LogicCommon!G4) -> MA.MAUDL5010
A5: * | E5: ACType :
A6: * | D6: 概要 : | E6: 業務理由マスタを登録する | L6: ID | N6: ID | P6: ID | R6: ID
A7: # | I7: U | K7: o | L7: UPDATE.updMaster | M7: o | N7: MAIN.chkMaster | O7: o | Q7: o
A8: # | D8: ブロック名 Block Name | E8: 型 Type | G8: super/share | H8: 対象ブロック名 Target Block Name | K8: TargetName | L8: DBC.MA.MAM_BIZ_RSN | M8: TargetName | N8: DBC.MA.MAM_BIZ_RSN | O8: TargetName | Q8: TargetName | U8: ブロック備考 Block Remarks
A9: # | D9: 項目名 Field Name | E9: 型 Type | F9: 桁 Digits | G9: フルネーム Full Name | H9: 日本語名 Japanese Name | I9: 上り項目 Request Message Field | J9: 下り項目 Response Message Field | S9: 条件および編集方法 Conditions and Editing Methods | U9: 項目備考 Field Remarks
A10: # | K10: 上り項目 Request Message Field | L10: 下り項目 Response Message Field | M10: 上り項目 Request Message Field | N10: 下り項目 Response Message Field | O10: 上り項目 Request Message Field | P10: 下り項目 Response Message Field | Q10: 上り項目 Request Message Field | R10: 下り項目 Response Message Field
A11: 10 | B11: * | D11: BizRsn_Upd01_Dtl | E11: L | G11: $share$ | H11: MA.MABCL0940.BizRsn_UpdChk01.BizRsn_UpdChk01_Dtl | K11: L | M11: L
A12: 10 | D12: biz_rsn_cd | E12: #MA.BIZ_RSN_CD | G12: Business reason cd. | H12: 業務理由ＣＤ | I12: E | K12: E | M12: E
A13: 10 | D13: biz_rsn_nm | E13: #MA.BIZ_RSN_NM | G13: Business reason name | H13: 業務理由名 | I13: E | K13: E
A14: 10 | D14: ac_rsn_cd | E14: #MA.AC_RSN_CD | G14: Accounting reason cd. | H14: 会計理由ＣＤ | I14: E | K14: E
A15: 10 | D15: purc_flg | E15: #MA.FLG | G15: Purchase | H15: 仕入 | I15: E | K15: E
A16: 10 | D16: purc_sort_seq | E16: #MA.INT | G16: Purchase sort order | H16: 仕入ソート順 | I16: E | K16: E
A17: 10 | D17: purc_rtn_flg | E17: #MA.FLG | G17: Purchase return | H17: 仕入返品 | I17: E | K17: E
A18: 10 | D18: purc_rtn_sort_seq | E18: #MA.INT | G18: Purchase return sort order | H18: 仕入返品ソート順 | I18: E | K18: E
A19: 10 | D19: xpns_purc_flg | E19: #MA.FLG | G19: Expense purchase | H19: 経費購買 | I19: E | K19: E
A20: 10 | D20: slo_xpns_purc_flg | E20: #MA.FLG | G20: Expense purchase (pegged to sales order) | H20: 受注紐付経費購買 | I20: E | K20: E
A21: 10 | D21: purc_dscnt_flg | E21: #MA.FLG | G21: Purchase adjustment | H21: 仕入調整 | I21: E | K21: E
A22: 10 | D22: purc_dscnt_loc_mng_typ | E22: #MA.LOC_MNG_TYP | G22: Purchase adjustment controlling site type | H22: 仕入調整管轄区分 | I22: E | K22: E
A23: 10 | D23: purc_dscnt_sort_seq | E23: #MA.INT | G23: Purchase adjustment sort order | H23: 仕入調整ソート順 | I23: E | K23: E
A24: 10 | D24: sls_flg | E24: #MA.FLG | G24: Sales result | H24: 売上 | I24: E | K24: E
... A57: 10 | D57: upd_cntr | E57: #MA.UPD_CNT | G57: Update counter | H57: 更新カウンタ | I57: E | K57: E
D58: 詳細 :

Sheet BizRsnLcl_UpdChk01
A1: * | B1: * | D1: L | E1: 1
A2: * | D2: オペレーション実装仕様書 Operation Specification Implementation Sheet | E2: ModuleID : | F2: =IF(LogicCommon!C2="","",LogicCommon!C2) -> MA | G2: LogicID : | H2: =IF(LogicCommon!E2="","",LogicCommon!E2) -> MABCL0940 | I2: Ope.ID : | J2: BizRsnLcl_UpdChk01 | K2: Pj.ID : | L2: =IF(LogicCommon!G2="","",LogicCommon!G2) -> MC | M2: Ope.Body : | N2: =L4 & ".Checker" -> MA.MAUDL5010.Checker
A3: * | D3: =IF(LogicCommon!A3="","",LogicCommon!A3) | E3: SubModuleID : | F3: =IF(LogicCommon!C3="","",LogicCommon!C3) -> MABC | G3: LogicClass : | H3: =IF(LogicCommon!E3="","",LogicCommon!E3) -> MABCL_BizRsnReg | I3: Ope.Method : | J3: @ | K3: SuperClassPj.ID : | L3: =IF(LogicCommon!G3="","",LogicCommon!G3) | M3: ReportID : | O3: Gene.Type : | P3: ALL
A4: * | E4: Version : | F4: 000000 | G4: LogicName : | H4: =IF(LogicCommon!E4="","",LogicCommon!E4) -> 業務理由マスタ登録 | I4: Ope.Name : | J4: 登録前チェック(ロケール別情報) | K4: SuperLogicID : | L4: =IF(LogicCommon!G4="","",LogicCommon!G4) -> MA.MAUDL5010
A5: * | E5: ACType :
A6: * | D6: 概要 : | E6: 業務理由マスタ(ロケール別情報)を登録する前のチェックを行う | M6: ID
A7: # | I7: U | K7: K | L7: o | M7: EXISTS.chk01
A8: # | D8: ブロック名 Block Name | E8: 型 Type | G8: super/share | H8: 対象ブロック名 Target Block Name | K8: REQUIRED | L8: TargetName | M8: DBC.MA.MAM_BIZ_RSN | P8: ブロック備考 Block Remarks
A9: # | D9: 項目名 Field Name | E9: 型 Type | F9: 桁 Digits | G9: フルネーム Full Name | H9: 日本語名 Japanese Name | I9: 上り項目 Request Message Field | J9: 下り項目 Response Message Field | N9: 条件および編集方法 Conditions and Editing Methods | P9: 項目備考 Field Remarks
A10: # | L10: 上り項目 Request Message Field | M10: 下り項目 Response Message Field
A11: 10 | B11: * | D11: BizRsnLcl_UpdChk01_Dtl | E11: L | G11: $super$ | H11: DBC:MA.MAM_BIZ_RSN_LCL | L11: L
A12: 10 | D12: biz_rsn_cd | E12: #MA.BIZ_RSN_CD | G12: Business reason cd. | H12: 業務理由ＣＤ | I12: E | K12: E | L12: E
A13: 10 | D13: lcl_cd | E13: #MA.LCL_CD | G13: Locale cd. | H13: ロケールＣＤ | I13: E | K13: E
A14: 10 | D14: biz_rsn_nm | E14: #MA.BIZ_RSN_NM | G14: Business reason name | H14: 業務理由名 | I14: E | K14: E
A15: 10 | D15: memo1 | E15: #MA.MST_MEMO1 | G15: Memo 1 | H15: メモ１ | I15: E
A16: 10 | D16: memo2 | E16: #MA.MST_MEMO2 | G16: Memo 2 | H16: メモ２ | I16: E
A17: 10 | D17: memo3 | E17: #MA.MST_MEMO3 | G17: Memo 3 | H17: メモ３ | I17: E
A18: 10 | D18: upd_cntr | E18: #MA.UPD_CNT | G18: Update counter | H18: 更新カウンタ | I18: E
D19: 詳細 :

Sheet BizRsnLcl_Upd01
A1: * | B1: * | D1: L | E1: 1
A2: * | D2: オペレーション実装仕様書 Operation Specification Implementation Sheet | E2: ModuleID : | F2: =IF(LogicCommon!C2="","",LogicCommon!C2) -> MA | G2: LogicID : | H2: =IF(LogicCommon!E2="","",LogicCommon!E2) -> MABCL0940 | I2: Ope.ID : | J2: BizRsnLcl_Upd01 | K2: Pj.ID : | L2: =IF(LogicCommon!G2="","",LogicCommon!G2) -> MC | M2: Ope.Body : | N2: "mcframe.serverMAUD.MAUDL6020.MAUDL_LCLRLUpdater"
A3: * | D3: =IF(LogicCommon!A3="","",LogicCommon!A3) | E3: SubModuleID : | F3: =IF(LogicCommon!C3="","",LogicCommon!C3) -> MABC | G3: LogicClass : | H3: =IF(LogicCommon!E3="","",LogicCommon!E3) -> MABCL_BizRsnReg | I3: Ope.Method : | J3: @ | K3: SuperClassPj.ID : | L3: =IF(LogicCommon!G3="","",LogicCommon!G3) | M3: ReportID : | O3: Gene.Type : | P3: ALL
A4: * | E4: Version : | F4: 000000 | G4: LogicName : | H4: =IF(LogicCommon!E4="","",LogicCommon!E4) -> 業務理由マスタ登録 | I4: Ope.Name : | J4: 登録処理(ロケール別情報) | K4: SuperLogicID : | L4: =IF(LogicCommon!G4="","",LogicCommon!G4) -> MA.MAUDL5010
A5: * | E5: ACType :
A6: * | D6: 概要 : | E6: 業務理由マスタ(ロケール別情報)を登録する | L6: ID | N6: ID | P6: ID | R6: ID
A7: # | I7: U | K7: o | L7: UPDATE.updMaster | M7: o | N7: MAIN.chkMaster | O7: o | Q7: o
A8: # | D8: ブロック名 Block Name | E8: 型 Type | G8: super/share | H8: 対象ブロック名 Target Block Name | K8: TargetName | L8: DBC.MA.MAM_BIZ_RSN_LCL | M8: TargetName | N8: DBC.MA.MAM_BIZ_RSN_LCL | O8: TargetName | Q8: TargetName | U8: ブロック備考 Block Remarks
A9: # | D9: 項目名 Field Name | E9: 型 Type | F9: 桁 Digits | G9: フルネーム Full Name | H9: 日本語名 Japanese Name | I9: 上り項目 Request Message Field | J9: 下り項目 Response Message Field | S9: 条件および編集方法 Conditions and Editing Methods | U9: 項目備考 Field Remarks
A10: # | K10: 上り項目 Request Message Field | L10: 下り項目 Response Message Field | M10: 上り項目 Request Message Field | N10: 下り項目 Response Message Field | O10: 上り項目 Request Message Field | P10: 下り項目 Response Message Field | Q10: 上り項目 Request Message Field | R10: 下り項目 Response Message Field
A11: 10 | B11: * | D11: BizRsnLcl_Upd01_Dtl | E11: L | G11: $share$ | H11: MA.MABCL0940.BizRsnLcl_UpdChk01.BizRsnLcl_UpdChk01_Dtl | K11: L | M11: L
A12: 10 | D12: biz_rsn_cd | E12: #MA.BIZ_RSN_CD | G12: Business reason cd. | H12: 業務理由ＣＤ | I12: E | K12: E | M12: E
A13: 10 | D13: lcl_cd | E13: #MA.LCL_CD | G13: Locale cd. | H13: ロケールＣＤ | I13: E | K13: E | M13: E
A14: 10 | D14: biz_rsn_nm | E14: #MA.BIZ_RSN_NM | G14: Business reason name | H14: 業務理由名 | I14: E | K14: E
A15: 10 | D15: memo1 | E15: #MA.MST_MEMO1 | G15: Memo 1 | H15: メモ１ | I15: E | K15: E
A16: 10 | D16: memo2 | E16: #MA.MST_MEMO2 | G16: Memo 2 | H16: メモ２ | I16: E | K16: E
A17: 10 | D17: memo3 | E17: #MA.MST_MEMO3 | G17: Memo 3 | H17: メモ３ | I17: E | K17: E
A18: 10 | D18: upd_cntr | E18: #MA.UPD_CNT | G18: Update counter | H18: 更新カウンタ | I18: E | K18: E
D19: 詳細 :

Sheet BizRsn_DelChk01
A1: * | B1: * | D1: L | E1: 1
A2: * | D2: オペレーション実装仕様書 Operation Specification Implementation Sheet | E2: ModuleID : | F2: =IF(LogicCommon!C2="","",LogicCommon!C2) -> MA | G2: LogicID : | H2: =IF(LogicCommon!E2="","",LogicCommon!E2) -> MABCL0940 | I2: Ope.ID : | J2: BizRsn_DelChk01 | K2: Pj.ID : | L2: =IF(LogicCommon!G2="","",LogicCommon!G2) -> MC | M2: Ope.Body : | N2: =L4 & ".Checker" -> MA.MAUDL5010.Checker
A3: * | D3: =IF(LogicCommon!A3="","",LogicCommon!A3) | E3: SubModuleID : | F3: =IF(LogicCommon!C3="","",LogicCommon!C3) -> MABC | G3: LogicClass : | H3: =IF(LogicCommon!E3="","",LogicCommon!E3) -> MABCL_BizRsnReg | I3: Ope.Method : | J3: @ | K3: SuperClassPj.ID : | L3: =IF(LogicCommon!G3="","",LogicCommon!G3) | M3: ReportID : | O3: Gene.Type : | P3: ALL
A4: * | E4: Version : | F4: 000000 | G4: LogicName : | H4: =IF(LogicCommon!E4="","",LogicCommon!E4) -> 業務理由マスタ登録 | I4: Ope.Name : | J4: 削除チェック | K4: SuperLogicID : | L4: =IF(LogicCommon!G4="","",LogicCommon!G4) -> MA.MAUDL5010
A5: * | E5: ACType :
A6: * | D6: 概要 : | E6: 業務理由マスタ、業務理由マスタ(ロケール別情報)を削除する前のチェックを行う | M6: ID
A7: # | I7: U | K7: K | L7: o
A8: # | D8: ブロック名 Block Name | E8: 型 Type | G8: super/share | H8: 対象ブロック名 Target Block Name | K8: REQUIRED | L8: TargetName | P8: ブロック備考 Block Remarks
A9: # | D9: 項目名 Field Name | E9: 型 Type | F9: 桁 Digits | G9: フルネーム Full Name | H9: 日本語名 Japanese Name | I9: 上り項目 Request Message Field | J9: 下り項目 Response Message Field | N9: 条件および編集方法 Conditions and Editing Methods | P9: 項目備考 Field Remarks
A10: # | L10: 上り項目 Request Message Field | M10: 下り項目 Response Message Field
A11: 10 | B11: * | D11: BizRsn_DelChk01_Dtl | E11: L
A12: 10 | D12: biz_rsn_cd | E12: #MA.BIZ_RSN_CD | G12: Business reason cd. | H12: 業務理由ＣＤ | I12: E | K12: E
A13: 10 | D13: upd_cntr | E13: #MA.UPD_CNT | G13: Update counter | H13: 更新カウンタ | I13: E
D14: 詳細 :

Sheet BizRsn_Del01
A1: * | B1: * | D1: L | E1: 1
A2: * | D2: オペレーション実装仕様書 Operation Specification Implementation Sheet | E2: ModuleID : | F2: =IF(LogicCommon!C2="","",LogicCommon!C2) -> MA | G2: LogicID : | H2: =IF(LogicCommon!E2="","",LogicCommon!E2) -> MABCL0940 | I2: Ope.ID : | J2: BizRsn_Del01 | K2: Pj.ID : | L2: =IF(LogicCommon!G2="","",LogicCommon!G2) -> MC | M2: Ope.Body : | N2: "mcframe.serverMAUD.MAUDL6020.MAUDL_LCLRLDeleter"
A3: * | D3: =IF(LogicCommon!A3="","",LogicCommon!A3) | E3: SubModuleID : | F3: =IF(LogicCommon!C3="","",LogicCommon!C3) -> MABC | G3: LogicClass : | H3: =IF(LogicCommon!E3="","",LogicCommon!E3) -> MABCL_BizRsnReg | I3: Ope.Method : | J3: @ | K3: SuperClassPj.ID : | L3: =IF(LogicCommon!G3="","",LogicCommon!G3) | M3: ReportID : | O3: Gene.Type : | P3: ALL
A4: * | E4: Version : | F4: 000000 | G4: LogicName : | H4: =IF(LogicCommon!E4="","",LogicCommon!E4) -> 業務理由マスタ登録 | I4: Ope.Name : | J4: 削除処理 | K4: SuperLogicID : | L4: =IF(LogicCommon!G4="","",LogicCommon!G4) -> MA.MAUDL5010
A5: * | E5: ACType :
A6: * | D6: 概要 : | E6: 業務理由マスタ、業務理由マスタ(ロケール別情報)を削除する | L6: ID | N6: ID
A7: # | I7: U | K7: o | L7: UPDATE.updMaster1 | M7: o | N7: UPDATE.updMaster2
A8: # | D8: ブロック名 Block Name | E8: 型 Type | G8: super/share | H8: 対象ブロック名 Target Block Name | K8: TargetName | L8: DBC.MA.MAM_BIZ_RSN | M8: TargetName | N8: DBC.MA.MAM_BIZ_RSN_LCL | Q8: ブロック備考 Block Remarks
A9: # | D9: 項目名 Field Name | E9: 型 Type | F9: 桁 Digits | G9: フルネーム Full Name | H9: 日本語名 Japanese Name | I9: 上り項目 Request Message Field | J9: 下り項目 Response Message Field | O9: 条件および編集方法 Conditions and Editing Methods | Q9: 項目備考 Field Remarks
A10: # | K10: 上り項目 Request Message Field | L10: 下り項目 Response Message Field | M10: 上り項目 Request Message Field | N10: 下り項目 Response Message Field
A11: 10 | B11: * | D11: BizRsn_Del01_Dtl | E11: L | G11: $share$ | H11: MA.MABCL0940.BizRsn_DelChk01.BizRsn_DelChk01_Dtl | K11: L | M11: L
A12: 10 | D12: biz_rsn_cd | E12: #MA.BIZ_RSN_CD | G12: Business reason cd. | H12: 業務理由ＣＤ | I12: E | K12: E | M12: E
A13: 10 | D13: upd_cntr | E13: #MA.UPD_CNT | G13: Update counter | H13: 更新カウンタ | I13: E | K13: E
D14: 詳細 :

Sheet Srch01
A1: * | B1: * | D1: L | E1: 1
A2: * | D2: オペレーション実装仕様書 Operation Specification Implementation Sheet | E2: ModuleID : | F2: =IF(LogicCommon!C2="","",LogicCommon!C2) -> MA | G2: LogicID : | H2: =IF(LogicCommon!E2="","",LogicCommon!E2) -> MABCL0940 | I2: Ope.ID : | J2: Srch01 | K2: Pj.ID : | L2: =IF(LogicCommon!G2="","",LogicCommon!G2) -> MC | M2: Ope.Body : | N2: "mcframe.serverMAUD.MAUDL6020.MAUDL_LCLRLSearcher"
A3: * | D3: =IF(LogicCommon!A3="","",LogicCommon!A3) | E3: SubModuleID : | F3: =IF(LogicCommon!C3="","",LogicCommon!C3) -> MABC | G3: LogicClass : | H3: =IF(LogicCommon!E3="","",LogicCommon!E3) -> MABCL_BizRsnReg | I3: Ope.Method : | J3: @ | K3: SuperClassPj.ID : | L3: =IF(LogicCommon!G3="","",LogicCommon!G3) | M3: ReportID : | O3: Gene.Type : | P3: ALL
A4: * | E4: Version : | F4: 000000 | G4: LogicName : | H4: =IF(LogicCommon!E4="","",LogicCommon!E4) -> 業務理由マスタ登録 | I4: Ope.Name : | J4: 検索 | K4: SuperLogicID : | L4: =IF(LogicCommon!G4="","",LogicCommon!G4) -> MA.MAUDL5010
A5: * | E5: ACType :
A6: * | D6: 概要 : | E6: 検索処理を行う | M6: ID | O6: ID
A7: # | I7: U | K7: K | L7: o | M7: SELECT.c0 | N7: o | O7: SELECT_LCL.c1
A8: # | D8: ブロック名 Block Name | E8: 型 Type | G8: super/share | H8: 対象ブロック名 Target Block Name | K8: CONST | L8: TargetName | M8: DBC.MA.MAM_BIZ_RSN | N8: TargetName | O8: DBC.MA.MAM_BIZ_RSN_LCL | R8: ブロック備考 Block Remarks
A9: # | D9: 項目名 Field Name | E9: 型 Type | F9: 桁 Digits | G9: フルネーム Full Name | H9: 日本語名 Japanese Name | I9: 上り項目 Request Message Field | J9: 下り項目 Response Message Field | P9: 条件および編集方法 Conditions and Editing Methods | R9: 項目備考 Field Remarks
A10: # | L10: 上り項目 Request Message Field | M10: 下り項目 Response Message Field | N10: 上り項目 Request Message Field | O10: 下り項目 Response Message Field
A11: 10 | B11: * | D11: Srch01_Cnd | E11: R | L11: R
A12: 10 | D12: biz_rsn_cd | E12: #MA.BIZ_RSN_CD | G12: Business reason cd. | H12: 業務理由ＣＤ | I12: E
A13: 10 | D13: biz_rsn_nm_lcl | E13: #MA.BIZ_RSN_NM | G13: Business reason name | H13: 業務理由名 | I13: E
A14: 10 | D14: ac_rsn_cd | E14: #MA.AC_RSN_CD | G14: Accounting reason cd. | H14: 会計理由ＣＤ | I14: E
A15: 10 | D15: ac_rsn_nm | E15: #MA.AC_RSN_NM | G15: Accounting reason name | H15: 会計理由名 | I15: E
A16: 10 | D16: off_del_flg | E16: #MA.FLG | G16: Logical delete. Off | H16: 論理削除.オフ | I16: E
A17: 10 | D17: on_del_flg | E17: #MA.FLG | G17: Logical delete. On | H17: 論理削除.オン | I17: E
A18: 10 | D18: memo1 | E18: #MA.MST_MEMO1 | G18: Memo 1 | H18: メモ１ | I18: E
A19: 10 | D19: memo2 | E19: #MA.MST_MEMO2 | G19: Memo 2 | H19: メモ２ | I19: E
A20: 10 | D20: memo3 | E20: #MA.MST_MEMO3 | G20: Memo 3 | H20: メモ３ | I20: E
A22: 20 | B22: * | D22: Srch01_Rslt1 | E22: L | M22: L
A23: 20 | D23: del_flg | E23: #MA.FLG | G23: Logical delete | H23: 論理削除 | J23: E | M23: E
A24: 20 | D24: biz_rsn_cd | E24: #MA.BIZ_RSN_CD | G24: Business reason cd. | H24: 業務理由ＣＤ | J24: E | M24: E
A25: 20 | D25: biz_rsn_nm_lcl | E25: #MA.BIZ_RSN_NM | G25: Business reason name | H25: 業務理由名 | J25: E | M25: biz_rsn_nm
A26: 20 | D26: biz_rsn_nm | E26: #MA.BIZ_RSN_NM | G26: Standard business reason name | H26: 標準業務理由名 | J26: E | M26: base_biz_rsn_nm
A27: 20 | D27: ac_rsn_cd | E27: #MA.AC_RSN_CD | G27: Accounting reason cd. | H27: 会計理由ＣＤ | J27: E | M27: E
A28: 20 | D28: ac_rsn_nm | E28: #MA.AC_RSN_NM | G28: Accounting reason name | H28: 会計理由名 | J28: E | M28: E
A29: 20 | D29: purc_flg | E29: #MA.FLG | G29: Purchase | H29: 仕入 | J29: E | M29: E
A30: 20 | D30: purc_sort_seq | E30: #MA.INT | G30: Purchase sort order | H30: 仕入ソート順 | J30: E | M30: E
A31: 20 | D31: purc_rtn_flg | E31: #MA.FLG | G31: Purchase return | H31: 仕入返品 | J31: E | M31: E
A32: 20 | D32: purc_rtn_sort_seq | E32: #MA.INT | G32: Purchase return sort order | H32: 仕入返品ソート順 | J32: E | M32: E
A33: 20 | D33: xpns_purc_flg | E33: #MA.FLG | G33: Expense purchase | H33: 経費購買 | J33: E | M33: E
A34: 20 | D34: slo_xpns_purc_flg | E34: #MA.FLG | G34: Expense purchase (pegged to sales order) | H34: 受注紐付経費購買 | J34: E | M34: E
A35: 20 | D35: purc_dscnt_flg | E35: #MA.FLG | G35: Purchase adjustment | H35: 仕入調整 | J35: E | M35: E
A36: 20 | D36: purc_dscnt_loc_mng_typ | E36: #MA.LOC_MNG_TYP | G36: Purchase adjustment controlling site type | H36: 仕入調整管轄区分 | J36: E | K36: MAC_LOC_MNG_TYP | M36: E
A37: 20 | D37: purc_dscnt_loc_mng_typ_nm | E37: #MA.LOC_MNG_TYP_NM | G37: Purchase adjustment controlling site type name | H37: 仕入調整管轄区分名 | J37: E
A38: 20 | D38: purc_dscnt_sort_seq | E38: #MA.INT | G38: Purchase adjustment sort order | H38: 仕入調整ソート順 | J38: E | M38: E
A39: 20 | D39: sls_flg | E39: #MA.FLG | G39: Sales result | H39: 売上 | J39: E | M39: E
A40: 20 | D40: sls_sort_seq | E40: #MA.INT | G40: Sales sort order | H40: 売上ソート順 | J40: E | M40: E
A41: 20 | D41: sls_rtn_flg | E41: #MA.FLG | G41: Sales return | H41: 売上返品 | J41: E | M41: E
...

Sheet Upd01
A1: * | B1: * | D1: L | E1: 1
A2: * | D2: オペレーション実装仕様書 Operation Specification Implementation Sheet | E2: ModuleID : | F2: =IF(LogicCommon!C2="","",LogicCommon!C2) -> MA | G2: LogicID : | H2: =IF(LogicCommon!E2="","",LogicCommon!E2) -> MABCL0940 | I2: Ope.ID : | J2: Upd01 | K2: Pj.ID : | L2: =IF(LogicCommon!G2="","",LogicCommon!G2) -> MC | M2: Ope.Body : | N2: "mcframe.serverMAUD.MAUDL6020.MAUDL_LCLRLUpdater"
A3: * | D3: =IF(LogicCommon!A3="","",LogicCommon!A3) | E3: SubModuleID : | F3: =IF(LogicCommon!C3="","",LogicCommon!C3) -> MABC | G3: LogicClass : | H3: =IF(LogicCommon!E3="","",LogicCommon!E3) -> MABCL_BizRsnReg | I3: Ope.Method : | J3: @ | K3: SuperClassPj.ID : | L3: =IF(LogicCommon!G3="","",LogicCommon!G3) | M3: ReportID : | O3: Gene.Type : | P3: ALL
A4: * | E4: Version : | F4: 000000 | G4: LogicName : | H4: =IF(LogicCommon!E4="","",LogicCommon!E4) -> 業務理由マスタ登録 | I4: Ope.Name : | J4: 登録 | K4: SuperLogicID : | L4: =IF(LogicCommon!G4="","",LogicCommon!G4) -> MA.MAUDL5010
A5: * | E5: ACType :
A6: * | D6: 概要 : | E6: 登録処理を行う | L6: ID | N6: ID | P6: ID | R6: ID
A7: # | I7: U | K7: o | L7: CALL_OPE01.chk01 | M7: o | N7: CALL_OPE01.upd01 | O7: o | P7: CALL_OPE02.chk02 | Q7: o | R7: CALL_OPE02.upd02
A8: # | D8: ブロック名 Block Name | E8: 型 Type | G8: super/share | H8: 対象ブロック名 Target Block Name | K8: TargetName | L8: OPE.MA.MABCL0940.BizRsn_UpdChk01 | M8: TargetName | N8: OPE.MA.MABCL0940.BizRsn_Upd01 | O8: TargetName | P8: OPE.MA.MABCL0940.BizRsnLcl_UpdChk01 | Q8: TargetName | R8: OPE.MA.MABCL0940.BizRsnLcl_Upd01 | U8: ブロック備考 Block Remarks
A9: # | D9: 項目名 Field Name | E9: 型 Type | F9: 桁 Digits | G9: フルネーム Full Name | H9: 日本語名 Japanese Name | I9: 上り項目 Request Message Field | J9: 下り項目 Response Message Field | S9: 条件および編集方法 Conditions and Editing Methods | U9: 項目備考 Field Remarks
A10: # | K10: 上り項目 Request Message Field | L10: 下り項目 Response Message Field | M10: 上り項目 Request Message Field | N10: 下り項目 Response Message Field | O10: 上り項目 Request Message Field | P10: 下り項目 Response Message Field | Q10: 上り項目 Request Message Field | R10: 下り項目 Response Message Field
A11: 10 | B11: * | D11: Upd01_Dtl1 | E11: L | G11: $share$ | H11: MA.MABCL0940.BizRsn_Upd01.BizRsn_Upd01_Dtl | K11: BizRsn_UpdChk01_Dtl | M11: BizRsn_Upd01_Dtl
A12: 10 | D12: biz_rsn_cd | E12: #MA.BIZ_RSN_CD | G12: Business reason cd. | H12: 業務理由ＣＤ | I12: E | K12: E | M12: E
A13: 10 | D13: biz_rsn_nm | E13: #MA.BIZ_RSN_NM | G13: Business reason name | H13: 業務理由名 | I13: E | K13: E | M13: E
A14: 10 | D14: ac_rsn_cd | E14: #MA.AC_RSN_CD | G14: Accounting reason cd. | H14: 会計理由ＣＤ | I14: E | K14: E | M14: E
A15: 10 | D15: purc_flg | E15: #MA.FLG | G15: Purchase | H15: 仕入 | I15: E | K15: E | M15: E
A16: 10 | D16: purc_sort_seq | E16: #MA.INT | G16: Purchase sort order | H16: 仕入ソート順 | I16: E | K16: E | M16: E
A17: 10 | D17: purc_rtn_flg | E17: #MA.FLG | G17: Purchase return | H17: 仕入返品 | I17: E | K17: E | M17: E
A18: 10 | D18: purc_rtn_sort_seq | E18: #MA.INT | G18: Purchase return sort order | H18: 仕入返品ソート順 | I18: E | K18: E | M18: E
A19: 10 | D19: xpns_purc_flg | E19: #MA.FLG | G19: Expense purchase | H19: 経費購買 | I19: E | K19: E | M19: E
A20: 10 | D20: slo_xpns_purc_flg | E20: #MA.FLG | G20: Expense purchase (pegged to sales order) | H20: 受注紐付経費購買 | I20: E | K20: E | M20: E
A21: 10 | D21: purc_dscnt_flg | E21: #MA.FLG | G21: Purchase adjustment | H21: 仕入調整 | I21: E | K21: E | M21: E
A22: 10 | D22: purc_dscnt_loc_mng_typ | E22: #MA.LOC_MNG_TYP | G22: Purchase adjustment controlling site type | H22: 仕入調整管轄区分 | I22: E | K22: E | M22: E
A23: 10 | D23: purc_dscnt_sort_seq | E23: #MA.INT | G23: Purchase adjustment sort order | H23: 仕入調整ソート順 | I23: E | K23: E | M23: E
... A57: 10 | D57: upd_cntr | E57: #MA.UPD_CNT | G57: Update counter | H57: 更新カウンタ | I57: E | K57: E | M57: E
A59: 20 | B59: * | D59: Upd01_Dtl2 | E59: L | G59: $share$ | H59: MA.MABCL0940.BizRsnLcl_Upd01.BizRsnLcl_Upd01_Dtl | O59: BizRsnLcl_UpdChk01_Dtl | Q59: BizRsnLcl_Upd01_Dtl
A60: 20 | D60: biz_rsn_cd | E60: #MA.BIZ_RSN_CD | G60: Business reason cd. | H60: 業務理由ＣＤ | I60: E | O60: E | Q60: E
A61: 20 | D61: lcl_cd | E61: #MA.LCL_CD | G61: Locale cd. | H61: ロケールＣＤ | I61: E | O61: E | Q61: E
A62: 20 | D62: biz_rsn_nm | E62: #MA.BIZ_RSN_NM | G62: Business reason name | H62: 業務理由名 | I62: E | O62: E | Q62: E
A63: 20 | D63: memo1 | E63: #MA.MST_MEMO1 | G63: Memo 1 | H63: メモ１ | I63: E | O63: E | Q63: E
A64: 20 | D64: memo2 | E64: #MA.MST_MEMO2 | G64: Memo 2 | H64: メモ２ | I64: E | O64: E | Q64: E
A65: 20 | D65: memo3 | E65: #MA.MST_MEMO3 | G65: Memo 3 | H65: メモ３ | I65: E | O65: E | Q65: E
A66: 20 | D66: upd_cntr | E66: #MA.UPD_CNT | G66: Update counter | H66: 更新カウンタ | I66: E | O66: E | Q66: E
D67: 詳細 :

Sheet Del01
A1: * | B1: * | D1: L | E1: 1
A2: * | D2: オペレーション実装仕様書 Operation Specification Implementation Sheet | E2: ModuleID : | F2: =IF(LogicCommon!C2="","",LogicCommon!C2) -> MA | G2: LogicID : | H2: =IF(LogicCommon!E2="","",LogicCommon!E2) -> MABCL0940 | I2: Ope.ID : | J2: Del01 | K2: Pj.ID : | L2: =IF(LogicCommon!G2="","",LogicCommon!G2) -> MC | M2: Ope.Body : | N2: "mcframe.serverMAUD.MAUDL6020.MAUDL_LCLRLDeleter"
A3: * | D3: =IF(LogicCommon!A3="","",LogicCommon!A3) | E3: SubModuleID : | F3: =IF(LogicCommon!C3="","",LogicCommon!C3) -> MABC | G3: LogicClass : | H3: =IF(LogicCommon!E3="","",LogicCommon!E3) -> MABCL_BizRsnReg | I3: Ope.Method : | J3: @ | K3: SuperClassPj.ID : | L3: =IF(LogicCommon!G3="","",LogicCommon!G3) | M3: ReportID : | O3: Gene.Type : | P3: ALL
A4: * | E4: Version : | F4: 000000 | G4: LogicName : | H4: =IF(LogicCommon!E4="","",LogicCommon!E4) -> 業務理由マスタ登録 | I4: Ope.Name : | J4: 削除 | K4: SuperLogicID : | L4: =IF(LogicCommon!G4="","",LogicCommon!G4) -> MA.MAUDL5010
A5: * | E5: ACType :
A6: * | D6: 概要 : | E6: 削除処理を行う | L6: ID | N6: ID
A7: # | I7: U | K7: o | L7: CALL_OPE01.chk01 | M7: o | N7: CALL_OPE01.del01
A8: # | D8: ブロック名 Block Name | E8: 型 Type | G8: super/share | H8: 対象ブロック名 Target Block Name | K8: TargetName | L8: OPE.MA.MABCL0940.BizRsn_DelChk01 | M8: TargetName | N8: OPE.MA.MABCL0940.BizRsn_Del01 | Q8: ブロック備考 Block Remarks
A9: # | D9: 項目名 Field Name | E9: 型 Type | F9: 桁 Digits | G9: フルネーム Full Name | H9: 日本語名 Japanese Name | I9: 上り項目 Request Message Field | J9: 下り項目 Response Message Field | O9: 条件および編集方法 Conditions and Editing Methods | Q9: 項目備考 Field Remarks
A10: # | K10: 上り項目 Request Message Field | L10: 下り項目 Response Message Field | M10: 上り項目 Request Message Field | N10: 下り項目 Response Message Field
A11: 10 | B11: * | D11: Del01_Dtl1 | E11: L | G11: $share$ | H11: MA.MABCL0940.BizRsn_Del01.BizRsn_Del01_Dtl | K11: BizRsn_DelChk01_Dtl | M11: BizRsn_Del01_Dtl
A12: 10 | D12: biz_rsn_cd | E12: #MA.BIZ_RSN_CD | G12: Business reason cd. | H12: 業務理由ＣＤ | I12: E | K12: E | M12: E
A13: 10 | D13: upd_cntr | E13: #MA.UPD_CNT | G13: Update counter | H13: 更新カウンタ | I13: E | K13: E | M13: E
D14: 詳細 :

Sheet 来歴
A1: 変更来歴
A3: Rev. | H3: 修正番号 | O3: 変更内容 | AQ3: 変更箇所
A4: 1 | O4: 初版
A5: 1.1 | O5: 英語の名称を追記 | AQ5: 全般
