Workbook

Sheet LogicCommon
A2: ロジック共通定義 | B2: ModuleID : | C2: MA | D2: LogicID : | E2: MABCL0290 | F2: Pj.ID : | G2: MC
B3: SubModuleID : | C3: MABC | D3: LogicClass : | E3: MABCL_DptLclReg | F3: SuperClassPj.ID :
D4: LogicName : | E4: 部門名称登録 | F4: SuperLogicID : | G4: MA.MAUDL5010
A5: 概要 :
A6: 詳細 :

Sheet DptLcl_UpdChk01
A1: * | B1: * | D1: L | E1: 1
A2: * | D2: オペレーション実装仕様書 Operation Specification Implementation Sheet | E2: ModuleID : | F2: =IF(LogicCommon!C2="","",LogicCommon!C2) -> MA | G2: LogicID : | H2: =IF(LogicCommon!E2="","",LogicCommon!E2) -> MABCL0290 | I2: Ope.ID : | J2: DptLcl_UpdChk01 | K2: Pj.ID : | L2: =IF(LogicCommon!G2="","",LogicCommon!G2) -> MC | M2: Ope.Body : | N2: =L4 & ".Checker" -> MA.MAUDL5010.Checker
A3: * | D3: =IF(LogicCommon!A3="","",LogicCommon!A3) | E3: SubModuleID : | F3: =IF(LogicCommon!C3="","",LogicCommon!C3) -> MABC | G3: LogicClass : | H3: =IF(LogicCommon!E3="","",LogicCommon!E3) -> MABCL_DptLclReg | I3: Ope.Method : | J3: @ | K3: SuperClassPj.ID : | L3: =IF(LogicCommon!G3="","",LogicCommon!G3) | M3: ReportID : | O3: Gene.Type : | P3: ALL
A4: * | E4: Version : | F4: 000000 | G4: LogicName : | H4: =IF(LogicCommon!E4="","",LogicCommon!E4) -> 部門名称登録 | I4: Ope.Name : | J4: 登録前チェック | K4: SuperLogicID : | L4: =IF(LogicCommon!G4="","",LogicCommon!G4) -> MA.MAUDL5010
A5: * | E5: ACType :
A6: * | D6: 概要 : | E6: 部門マスタ(ロケール別情報)を登録する前のチェックを行う | R6: ID
A7: # | I7: U | K7: K | L7: K | M7: K | N7: K | O7: K | P7: K | Q7: o
A8: # | D8: ブロック名 Block Name | E8: 型 Type | G8: super/share | H8: 対象ブロック名 Target Block Name | K8: REQUIRED | L8: LIST_LOGIC | M8: LIST_IN | N8: LIST_IN_BASE | O8: CHK_PTN | P8: BEFORE_AFTER | Q8: TargetName | U8: ブロック備考 Block Remarks
A9: # | D9: 項目名 Field Name | E9: 型 Type | F9: 桁 Digits | G9: フルネーム Full Name | H9: 日本語名 Japanese Name | I9: 上り項目 Request Message Field | J9: 下り項目 Response Message Field | S9: 条件および編集方法 Conditions and Editing Methods | U9: 項目備考 Field Remarks
A10: # | Q10: 上り項目 Request Message Field | R10: 下り項目 Response Message Field
A11: 10 | B11: * | D11: DptLcl_UpdChk01_Dtl | E11: L | G11: $super$ | H11: DBC:MA.MAM_DPT_LCL
A12: 10 | D12: dpt_cd | E12: #MA.DPT_CD | G12: Dept. cd. | H12: 部門ＣＤ | I12: E | K12: E | L12: MA.MAUAL0010.DptForEndDtChk | M12: st_dt;end_dt | N12: st_dt;end_dt
A13: 10 | D13: lcl_cd | E13: #MA.LCL_CD | G13: Locale cd. | H13: ロケールＣＤ | I13: E | K13: E
A14: 10 | D14: st_dt_key | E14: #MA.DT | G14: Application start date_[Before change] | H14: 適用開始日_[変更前] | I14: E
A15: 10 | D15: st_dt | E15: #MA.DT | G15: Application start date | H15: 適用開始日 | I15: E | K15: E | P15: E1:BF
A16: 10 | D16: end_dt | E16: #MA.DT | G16: Application end date | H16: 適用終了日 | I16: E | K16: E | P16: E1:AF
A17: 10 | D17: dpt_nm | E17: #MA.DPT_NM | G17: Dept. name | H17: 部門名 | I17: E | K17: E
A18: 10 | D18: zip_cd | E18: #MA.ZIP_CD | G18: Zip code | H18: 郵便番号 | I18: E | O18: ZIP
A19: 10 | D19: addr1 | E19: #MA.ADDR1 | G19: Address 1 | H19: 住所１ | I19: E
A20: 10 | D20: addr2 | E20: #MA.ADDR2 | G20: Address 2 | H20: 住所２ | I20: E
A21: 10 | D21: addr3 | E21: #MA.ADDR3 | G21: Address 3 | H21: 住所３ | I21: E
A22: 10 | D22: addr4 | E22: #MA.ADDR4 | G22: Address 4 | H22: 住所４ | I22: E
A23: 10 | D23: tel | E23: #MA.TEL | G23: TEL | H23: ＴＥＬ | I23: E | O23: TEL
A24: 10 | D24: fax | E24: #MA.TEL | G24: FAX | H24: ＦＡＸ | I24: E | O24: TEL
A25: 10 | D25: memo1 | E25: #MA.MST_MEMO1 | G25: Memo 1 | H25: メモ１ | I25: E
A26: 10 | D26: memo2 | E26: #MA.MST_MEMO2 | G26: Memo 2 | H26: メモ２ | I26: E
A27: 10 | D27: memo3 | E27: #MA.MST_MEMO3 | G27: Memo 3 | H27: メモ３ | I27: E
A28: 10 | D28: upd_cntr | E28: #MA.UPD_CNT | G28: Update counter | H28: 更新カウンタ | I28: E
D29: 詳細 :

Sheet DptLcl_Upd01
A1: * | B1: * | D1: L | E1: 1
A2: * | D2: オペレーション実装仕様書 Operation Specification Implementation Sheet | E2: ModuleID : | F2: =IF(LogicCommon!C2="","",LogicCommon!C2) -> MA | G2: LogicID : | H2: =IF(LogicCommon!E2="","",LogicCommon!E2) -> MABCL0290 | I2: Ope.ID : | J2: DptLcl_Upd01 | K2: Pj.ID : | L2: =IF(LogicCommon!G2="","",LogicCommon!G2) -> MC | M2: Ope.Body : | N2: "mcframe.serverMAUD.MAUDL6010.MAUDL_RLUpdater"
A3: * | D3: =IF(LogicCommon!A3="","",LogicCommon!A3) | E3: SubModuleID : | F3: =IF(LogicCommon!C3="","",LogicCommon!C3) -> MABC | G3: LogicClass : | H3: =IF(LogicCommon!E3="","",LogicCommon!E3) -> MABCL_DptLclReg | I3: Ope.Method : | J3: @ | K3: SuperClassPj.ID : | L3: =IF(LogicCommon!G3="","",LogicCommon!G3) | M3: ReportID : | O3: Gene.Type : | P3: ALL
A4: * | E4: Version : | F4: 000000 | G4: LogicName : | H4: =IF(LogicCommon!E4="","",LogicCommon!E4) -> 部門名称登録 | I4: Ope.Name : | J4: 登録処理 | K4: SuperLogicID : | L4: =IF(LogicCommon!G4="","",LogicCommon!G4) -> MA.MAUDL5010
A5: * | E5: ACType :
A6: * | D6: 概要 : | E6: 部門マスタ(ロケール別情報)を登録する | L6: ID | N6: ID | P6: ID | R6: ID
A7: # | I7: U | K7: o | L7: UPDATE.updMaster | M7: o | N7: MAIN.chkMaster | O7: o | Q7: o
A8: # | D8: ブロック名 Block Name | E8: 型 Type | G8: super/share | H8: 対象ブロック名 Target Block Name | K8: TargetName | L8: DBC.MA.MAM_DPT_LCL | M8: TargetName | N8: DBC.MA.MAM_DPT_LCL | O8: TargetName | Q8: TargetName | U8: ブロック備考 Block Remarks
A9: # | D9: 項目名 Field Name | E9: 型 Type | F9: 桁 Digits | G9: フルネーム Full Name | H9: 日本語名 Japanese Name | I9: 上り項目 Request Message Field | J9: 下り項目 Response Message Field | S9: 条件および編集方法 Conditions and Editing Methods | U9: 項目備考 Field Remarks
A10: # | K10: 上り項目 Request Message Field | L10: 下り項目 Response Message Field | M10: 上り項目 Request Message Field | N10: 下り項目 Response Message Field | O10: 上り項目 Request Message Field | P10: 下り項目 Response Message Field | Q10: 上り項目 Request Message Field | R10: 下り項目 Response Message Field
A11: 10 | B11: * | D11: DptLcl_Upd01_Dtl | E11: L | G11: $share$ | H11: MA.MABCL0290.DptLcl_UpdChk01.DptLcl_UpdChk01_Dtl | K11: L | M11: L
A12: 10 | D12: dpt_cd | E12: #MA.DPT_CD | G12: Dept. cd. | H12: 部門ＣＤ | I12: E | K12: E | M12: E
A13: 10 | D13: lcl_cd | E13: #MA.LCL_CD | G13: Locale cd. | H13: ロケールＣＤ | I13: E | K13: E | M13: E
A14: 10 | D14: st_dt_key | E14: #MA.DT | G14: Application start date_[Before change] | H14: 適用開始日_[変更前] | I14: E
A15: 10 | D15: st_dt | E15: #MA.DT | G15: Application start date | H15: 適用開始日 | I15: E | K15: E | M15: E
A16: 10 | D16: end_dt | E16: #MA.DT | G16: Application end date | H16: 適用終了日 | I16: E | K16: E
A17: 10 | D17: dpt_nm | E17: #MA.DPT_NM | G17: Dept. name | H17: 部門名 | I17: E | K17: E
A18: 10 | D18: zip_cd | E18: #MA.ZIP_CD | G18: Zip code | H18: 郵便番号 | I18: E | K18: E
A19: 10 | D19: addr1 | E19: #MA.ADDR1 | G19: Address 1 | H19: 住所１ | I19: E | K19: E
A20: 10 | D20: addr2 | E20: #MA.ADDR2 | G20: Address 2 | H20: 住所２ | I20: E | K20: E
A21: 10 | D21: addr3 | E21: #MA.ADDR3 | G21: Address 3 | H21: 住所３ | I21: E | K21: E
A22: 10 | D22: addr4 | E22: #MA.ADDR4 | G22: Address 4 | H22: 住所４ | I22: E | K22: E
A23: 10 | D23: tel | E23: #MA.TEL | G23: TEL | H23: ＴＥＬ | I23: E | K23: E
A24: 10 | D24: fax | E24: #MA.TEL | G24: FAX | H24: ＦＡＸ | I24: E | K24: E
A25: 10 | D25: memo1 | E25: #MA.MST_MEMO1 | G25: Memo 1 | H25: メモ１ | I25: E | K25: E
A26: 10 | D26: memo2 | E26: #MA.MST_MEMO2 | G26: Memo 2 | H26: メモ２ | I26: E | K26: E
A27: 10 | D27: memo3 | E27: #MA.MST_MEMO3 | G27: Memo 3 | H27: メモ３ | I27: E | K27: E
A28: 10 | D28: upd_cntr | E28: #MA.UPD_CNT | G28: Update counter | H28: 更新カウンタ | I28: E | K28: E
D29: 詳細 :

Sheet DptLcl_DelChk01
A1: * | B1: * | D1: L | E1: 1
A2: * | D2: オペレーション実装仕様書 Operation Specification Implementation Sheet | E2: ModuleID : | F2: =IF(LogicCommon!C2="","",LogicCommon!C2) -> MA | G2: LogicID : | H2: =IF(LogicCommon!E2="","",LogicCommon!E2) -> MABCL0290 | I2: Ope.ID : | J2: DptLcl_DelChk01 | K2: Pj.ID : | L2: =IF(LogicCommon!G2="","",LogicCommon!G2) -> MC | M2: Ope.Body : | N2: =L4 & ".Checker" -> MA.MAUDL5010.Checker
A3: * | D3: =IF(LogicCommon!A3="","",LogicCommon!A3) | E3: SubModuleID : | F3: =IF(LogicCommon!C3="","",LogicCommon!C3) -> MABC | G3: LogicClass : | H3: =IF(LogicCommon!E3="","",LogicCommon!E3) -> MABCL_DptLclReg | I3: Ope.Method : | J3: @ | K3: SuperClassPj.ID : | L3: =IF(LogicCommon!G3="","",LogicCommon!G3) | M3: ReportID : | O3: Gene.Type : | P3: ALL
A4: * | E4: Version : | F4: 000000 | G4: LogicName : | H4: =IF(LogicCommon!E4="","",LogicCommon!E4) -> 部門名称登録 | I4: Ope.Name : | J4: 削除前チェック | K4: SuperLogicID : | L4: =IF(LogicCommon!G4="","",LogicCommon!G4) -> MA.MAUDL5010
A5: * | E5: ACType :
A6: * | D6: 概要 : | E6: 部門マスタ(ロケール別情報)を削除する前のチェックを行う | M6: ID
A7: # | I7: U | K7: K | L7: o
A8: # | D8: ブロック名 Block Name | E8: 型 Type | G8: super/share | H8: 対象ブロック名 Target Block Name | K8: REQUIRED | L8: TargetName | P8: ブロック備考 Block Remarks
A9: # | D9: 項目名 Field Name | E9: 型 Type | F9: 桁 Digits | G9: フルネーム Full Name | H9: 日本語名 Japanese Name | I9: 上り項目 Request Message Field | J9: 下り項目 Response Message Field | N9: 条件および編集方法 Conditions and Editing Methods | P9: 項目備考 Field Remarks
A10: # | L10: 上り項目 Request Message Field | M10: 下り項目 Response Message Field
A11: 10 | B11: * | D11: DptLcl_DelChk01_Dtl | E11: L
A12: 10 | D12: dpt_cd | E12: #MA.DPT_CD | G12: Dept. cd. | H12: 部門ＣＤ | I12: E | K12: E
A13: 10 | D13: lcl_cd | E13: #MA.LCL_CD | G13: Locale cd. | H13: ロケールＣＤ | I13: E | K13: E
A14: 10 | D14: st_dt | E14: #MA.DT | G14: Application start date | H14: 適用開始日 | I14: E | K14: E
A15: 10 | D15: upd_cntr | E15: #MA.UPD_CNT | G15: Update counter | H15: 更新カウンタ | I15: E
D16: 詳細 :

Sheet DptLcl_Del01
A1: * | B1: * | D1: L | E1: 1
A2: * | D2: オペレーション実装仕様書 Operation Specification Implementation Sheet | E2: ModuleID : | F2: =IF(LogicCommon!C2="","",LogicCommon!C2) -> MA | G2: LogicID : | H2: =IF(LogicCommon!E2="","",LogicCommon!E2) -> MABCL0290 | I2: Ope.ID : | J2: DptLcl_Del01 | K2: Pj.ID : | L2: =IF(LogicCommon!G2="","",LogicCommon!G2) -> MC | M2: Ope.Body : | N2: "mcframe.serverMAUD.MAUDL6010.MAUDL_RLDeleter"
A3: * | D3: =IF(LogicCommon!A3="","",LogicCommon!A3) | E3: SubModuleID : | F3: =IF(LogicCommon!C3="","",LogicCommon!C3) -> MABC | G3: LogicClass : | H3: =IF(LogicCommon!E3="","",LogicCommon!E3) -> MABCL_DptLclReg | I3: Ope.Method : | J3: @ | K3: SuperClassPj.ID : | L3: =IF(LogicCommon!G3="","",LogicCommon!G3) | M3: ReportID : | O3: Gene.Type : | P3: ALL
A4: * | E4: Version : | F4: 000000 | G4: LogicName : | H4: =IF(LogicCommon!E4="","",LogicCommon!E4) -> 部門名称登録 | I4: Ope.Name : | J4: 削除処理 | K4: SuperLogicID : | L4: =IF(LogicCommon!G4="","",LogicCommon!G4) -> MA.MAUDL5010
A5: * | E5: ACType :
A6: * | D6: 概要 : | E6: 部門マスタ(ロケール別情報)を削除する | L6: ID | N6: ID
A7: # | I7: U | K7: o | L7: UPDATE.updMaster1 | M7: o
A8: # | D8: ブロック名 Block Name | E8: 型 Type | G8: super/share | H8: 対象ブロック名 Target Block Name | K8: TargetName | L8: DBC.MA.MAM_DPT_LCL | M8: TargetName | Q8: ブロック備考 Block Remarks
A9: # | D9: 項目名 Field Name | E9: 型 Type | F9: 桁 Digits | G9: フルネーム Full Name | H9: 日本語名 Japanese Name | I9: 上り項目 Request Message Field | J9: 下り項目 Response Message Field | O9: 条件および編集方法 Conditions and Editing Methods | Q9: 項目備考 Field Remarks
A10: # | K10: 上り項目 Request Message Field | L10: 下り項目 Response Message Field | M10: 上り項目 Request Message Field | N10: 下り項目 Response Message Field
A11: 10 | B11: * | D11: DptLcl_Del01_Dtl | E11: L | G11: $share$ | H11: MA.MABCL0290.DptLcl_DelChk01.DptLcl_DelChk01_Dtl | K11: L
A12: 10 | D12: dpt_cd | E12: #MA.DPT_CD | G12: Dept. cd. | H12: 部門ＣＤ | I12: E | K12: E
A13: 10 | D13: lcl_cd | E13: #MA.LCL_CD | G13: Locale cd. | H13: ロケールＣＤ | I13: E | K13: E
A14: 10 | D14: st_dt | E14: #MA.DT | G14: Application start date | H14: 適用開始日 | I14: E | K14: E
A15: 10 | D15: upd_cntr | E15: #MA.UPD_CNT | G15: Update counter | H15: 更新カウンタ | I15: E | K15: E
D16: 詳細 :

Sheet Srch01
A1: * | B1: * | D1: L | E1: 1
A2: * | D2: オペレーション実装仕様書 Operation Specification Implementation Sheet | E2: ModuleID : | F2: =IF(LogicCommon!C2="","",LogicCommon!C2) -> MA | G2: LogicID : | H2: =IF(LogicCommon!E2="","",LogicCommon!E2) -> MABCL0290 | I2: Ope.ID : | J2: Srch01 | K2: Pj.ID : | L2: =IF(LogicCommon!G2="","",LogicCommon!G2) -> MC | M2: Ope.Body : | N2: "mcframe.serverMAUD.MAUDL6010.MAUDL_RLSearcher"
A3: * | D3: =IF(LogicCommon!A3="","",LogicCommon!A3) | E3: SubModuleID : | F3: =IF(LogicCommon!C3="","",LogicCommon!C3) -> MABC | G3: LogicClass : | H3: =IF(LogicCommon!E3="","",LogicCommon!E3) -> MABCL_DptLclReg | I3: Ope.Method : | J3: @ | K3: SuperClassPj.ID : | L3: =IF(LogicCommon!G3="","",LogicCommon!G3) | M3: ReportID : | O3: Gene.Type : | P3: ALL
A4: * | E4: Version : | F4: 000000 | G4: LogicName : | H4: =IF(LogicCommon!E4="","",LogicCommon!E4) -> 部門名称登録 | I4: Ope.Name : | J4: 検索 | K4: SuperLogicID : | L4: =IF(LogicCommon!G4="","",LogicCommon!G4) -> MA.MAUDL5010
A5: * | E5: ACType :
A6: * | D6: 概要 : | E6: 検索処理を行う | L6: ID | N6: ID
A7: # | I7: U | K7: o | L7: SELECT.c0 | M7: o
A8: # | D8: ブロック名 Block Name | E8: 型 Type | G8: super/share | H8: 対象ブロック名 Target Block Name | K8: TargetName | L8: DBC.MA.MAM_DPT_LCL | M8: TargetName | Q8: ブロック備考 Block Remarks
A9: # | D9: 項目名 Field Name | E9: 型 Type | F9: 桁 Digits | G9: フルネーム Full Name | H9: 日本語名 Japanese Name | I9: 上り項目 Request Message Field | J9: 下り項目 Response Message Field | O9: 条件および編集方法 Conditions and Editing Methods | Q9: 項目備考 Field Remarks
A10: # | K10: 上り項目 Request Message Field | L10: 下り項目 Response Message Field | M10: 上り項目 Request Message Field | N10: 下り項目 Response Message Field
A11: 10 | B11: * | D11: Srch01_Cnd | E11: R
A12: 10 | D12: st_dt_fr | E12: #MA.DT | G12: Application start date FROM | H12: 適用開始日ＦＲＯＭ | I12: E
A13: 10 | D13: st_dt_to | E13: #MA.DT | G13: Application start date TO | H13: 適用開始日ＴＯ | I13: E
A14: 10 | D14: end_dt_fr | E14: #MA.DT | G14: Application end date FROM | H14: 適用終了日ＦＲＯＭ | I14: E
A15: 10 | D15: end_dt_to | E15: #MA.DT | G15: Application end date TO | H15: 適用終了日ＴＯ | I15: E
A16: 10 | D16: dpt_cd | E16: #MA.DPT_CD | G16: Dept. cd. | H16: 部門ＣＤ | I16: E
A17: 10 | D17: dpt_nm_std | E17: #MA.DPT_NM | G17: Standard dept. name | H17: 標準部門名 | I17: E
A18: 10 | D18: dpt_nm | E18: #MA.DPT_NM | G18: Dept. name | H18: 部門名 | I18: E
A19: 10 | D19: lcl_cd | E19: #MA.LCL_CD | G19: Locale cd. | H19: ロケールＣＤ | I19: E
A20: 10 | D20: reg_flg | E20: #MA.FLG | G20: Entered | H20: 登録済 | I20: E
A21: 10 | D21: yet_flg | E21: #MA.FLG | G21: Non-entry | H21: 未登録 | I21: E
A22: 10 | D22: memo1 | E22: #MA.MST_MEMO1 | G22: Memo 1 | H22: メモ１ | I22: E
A23: 10 | D23: memo2 | E23: #MA.MST_MEMO2 | G23: Memo 2 | H23: メモ２ | I23: E
A24: 10 | D24: memo3 | E24: #MA.MST_MEMO3 | G24: Memo 3 | H24: メモ３ | I24: E
A26: 20 | B26: * | D26: Srch01_Rslt | E26: L | L26: L
A27: 20 | D27: yet_flg | E27: #MA.FLG | G27: Non-entry | H27: 未登録 | J27: E | L27: E
A28: 20 | D28: dpt_cd | E28: #MA.DPT_CD | G28: Dept. cd. | H28: 部門ＣＤ | J28: E | L28: E
A29: 20 | D29: dpt_nm_std | E29: #MA.DPT_NM | G29: Standard dept. name | H29: 標準部門名 | J29: E | L29: E
A30: 20 | D30: lcl_cd | E30: #MA.LCL_CD | G30: Locale cd. | H30: ロケールＣＤ | J30: E | L30: E
A31: 20 | D31: lcl_nm | E31: #MA.LCL_NM | G31: Locale name | H31: ロケール名 | J31: E
A32: 20 | D32: st_dt | E32: #MA.DT | G32: Application start date | H32: 適用開始日 | J32: E | L32: E
A33: 20 | D33: end_dt | E33: #MA.DT | G33: Application end date | H33: 適用終了日 | J33: E | L33: E
A34: 20 | D34: dpt_nm | E34: #MA.DPT_NM | G34: Dept. name | H34: 部門名 | J34: E | L34: E
A35: 20 | D35: zip_cd | E35: #MA.ZIP_CD | G35: Zip code | H35: 郵便番号 | J35: E | L35: E
A36: 20 | D36: addr1 | E36: #MA.ADDR1 | G36: Address 1 | H36: 住所１ | J36: E | L36: E
A37: 20 | D37: addr2 | E37: #MA.ADDR2 | G37: Address 2 | H37: 住所２ | J37: E | L37: E
A38: 20 | D38: addr3 | E38: #MA.ADDR3 | G38: Address 3 | H38: 住所３ | J38: E | L38: E
A39: 20 | D39: addr4 | E39: #MA.ADDR4 | G39: Address 4 | H39: 住所４ | J39: E | L39: E
A40: 20 | D40: tel | E40: #MA.TEL | G40: TEL | H40: ＴＥＬ | J40: E | L40: E
A41: 20 | D41: fax | E41: #MA.TEL | G41: FAX | H41: ＦＡＸ | J41: E | L41: E
...

Sheet Upd01
A1: * | B1: * | D1: L | E1: 1
A2: * | D2: オペレーション実装仕様書 Operation Specification Implementation Sheet | E2: ModuleID : | F2: =IF(LogicCommon!C2="","",LogicCommon!C2) -> MA | G2: LogicID : | H2: =IF(LogicCommon!E2="","",LogicCommon!E2) -> MABCL0290 | I2: Ope.ID : | J2: Upd01 | K2: Pj.ID : | L2: =IF(LogicCommon!G2="","",LogicCommon!G2) -> MC | M2: Ope.Body : | N2: "mcframe.serverMAUD.MAUDL6010.MAUDL_RLUpdater"
A3: * | D3: =IF(LogicCommon!A3="","",LogicCommon!A3) | E3: SubModuleID : | F3: =IF(LogicCommon!C3="","",LogicCommon!C3) -> MABC | G3: LogicClass : | H3: =IF(LogicCommon!E3="","",LogicCommon!E3) -> MABCL_DptLclReg | I3: Ope.Method : | J3: @ | K3: SuperClassPj.ID : | L3: =IF(LogicCommon!G3="","",LogicCommon!G3) | M3: ReportID : | O3: Gene.Type : | P3: ALL
A4: * | E4: Version : | F4: 000000 | G4: LogicName : | H4: =IF(LogicCommon!E4="","",LogicCommon!E4) -> 部門名称登録 | I4: Ope.Name : | J4: 登録 | K4: SuperLogicID : | L4: =IF(LogicCommon!G4="","",LogicCommon!G4) -> MA.MAUDL5010
A5: * | E5: ACType :
A6: * | D6: 概要 : | E6: 登録処理を行う | L6: ID | N6: ID | P6: ID | R6: ID
A7: # | I7: U | K7: o | L7: CALL_OPE01.chk01 | M7: o | N7: CALL_OPE01.upd01 | O7: o | Q7: o
A8: # | D8: ブロック名 Block Name | E8: 型 Type | G8: super/share | H8: 対象ブロック名 Target Block Name | K8: TargetName | L8: OPE.MA.MABCL0290.DptLcl_UpdChk01 | M8: TargetName | N8: OPE.MA.MABCL0290.DptLcl_Upd01 | O8: TargetName | Q8: TargetName | U8: ブロック備考 Block Remarks
A9: # | D9: 項目名 Field Name | E9: 型 Type | F9: 桁 Digits | G9: フルネーム Full Name | H9: 日本語名 Japanese Name | I9: 上り項目 Request Message Field | J9: 下り項目 Response Message Field | S9: 条件および編集方法 Conditions and Editing Methods | U9: 項目備考 Field Remarks
A10: # | K10: 上り項目 Request Message Field | L10: 下り項目 Response Message Field | M10: 上り項目 Request Message Field | N10: 下り項目 Response Message Field | O10: 上り項目 Request Message Field | P10: 下り項目 Response Message Field | Q10: 上り項目 Request Message Field | R10: 下り項目 Response Message Field
A11: 10 | B11: * | D11: Upd01_Dtl1 | E11: L | G11: $share$ | H11: MA.MABCL0290.DptLcl_Upd01.DptLcl_Upd01_Dtl | K11: DptLcl_UpdChk01_Dtl | M11: DptLcl_Upd01_Dtl
A12: 10 | D12: dpt_cd | E12: #MA.DPT_CD | G12: Dept. cd. | H12: 部門ＣＤ | I12: E | K12: E | M12: E
A13: 10 | D13: lcl_cd | E13: #MA.LCL_CD | G13: Locale cd. | H13: ロケールＣＤ | I13: E | K13: E | M13: E
A14: 10 | D14: st_dt_key | E14: #MA.DT | G14: Application start date_[Before change] | H14: 適用開始日_[変更前] | I14: E | K14: E | M14: E
A15: 10 | D15: st_dt | E15: #MA.DT | G15: Application start date | H15: 適用開始日 | I15: E | K15: E | M15: E
A16: 10 | D16: end_dt | E16: #MA.DT | G16: Application end date | H16: 適用終了日 | I16: E | K16: E | M16: E
A17: 10 | D17: dpt_nm | E17: #MA.DPT_NM | G17: Dept. name | H17: 部門名 | I17: E | K17: E | M17: E
A18: 10 | D18: zip_cd | E18: #MA.ZIP_CD | G18: Zip code | H18: 郵便番号 | I18: E | K18: E | M18: E
A19: 10 | D19: addr1 | E19: #MA.ADDR1 | G19: Address 1 | H19: 住所１ | I19: E | K19: E | M19: E
A20: 10 | D20: addr2 | E20: #MA.ADDR2 | G20: Address 2 | H20: 住所２ | I20: E | K20: E | M20: E
A21: 10 | D21: addr3 | E21: #MA.ADDR3 | G21: Address 3 | H21: 住所３ | I21: E | K21: E | M21: E
A22: 10 | D22: addr4 | E22: #MA.ADDR4 | G22: Address 4 | H22: 住所４ | I22: E | K22: E | M22: E
A23: 10 | D23: tel | E23: #MA.TEL | G23: TEL | H23: ＴＥＬ | I23: E | K23: E | M23: E
... A28: 10 | D28: upd_cntr | E28: #MA.UPD_CNT | G28: Update counter | H28: 更新カウンタ | I28: E | K28: E | M28: E
D29: 詳細 :

Sheet Del01
A1: * | B1: * | D1: L | E1: 1
A2: * | D2: オペレーション実装仕様書 Operation Specification Implementation Sheet | E2: ModuleID : | F2: =IF(LogicCommon!C2="","",LogicCommon!C2) -> MA | G2: LogicID : | H2: =IF(LogicCommon!E2="","",LogicCommon!E2) -> MABCL0290 | I2: Ope.ID : | J2: Del01 | K2: Pj.ID : | L2: =IF(LogicCommon!G2="","",LogicCommon!G2) -> MC | M2: Ope.Body : | N2: "mcframe.serverMAUD.MAUDL6010.MAUDL_RLDeleter"
A3: * | D3: =IF(LogicCommon!A3="","",LogicCommon!A3) | E3: SubModuleID : | F3: =IF(LogicCommon!C3="","",LogicCommon!C3) -> MABC | G3: LogicClass : | H3: =IF(LogicCommon!E3="","",LogicCommon!E3) -> MABCL_DptLclReg | I3: Ope.Method : | J3: @ | K3: SuperClassPj.ID : | L3: =IF(LogicCommon!G3="","",LogicCommon!G3) | M3: ReportID : | O3: Gene.Type : | P3: ALL
A4: * | E4: Version : | F4: 000000 | G4: LogicName : | H4: =IF(LogicCommon!E4="","",LogicCommon!E4) -> 部門名称登録 | I4: Ope.Name : | J4: 削除 | K4: SuperLogicID : | L4: =IF(LogicCommon!G4="","",LogicCommon!G4) -> MA.MAUDL5010
A5: * | E5: ACType :
A6: * | D6: 概要 : | E6: 削除処理を行う | L6: ID | N6: ID
A7: # | I7: U | K7: o | L7: CALL_OPE01.chk01 | M7: o | N7: CALL_OPE01.del01
A8: # | D8: ブロック名 Block Name | E8: 型 Type | G8: super/share | H8: 対象ブロック名 Target Block Name | K8: TargetName | L8: OPE.MA.MABCL0290.DptLcl_DelChk01 | M8: TargetName | N8: OPE.MA.MABCL0290.DptLcl_Del01 | Q8: ブロック備考 Block Remarks
A9: # | D9: 項目名 Field Name | E9: 型 Type | F9: 桁 Digits | G9: フルネーム Full Name | H9: 日本語名 Japanese Name | I9: 上り項目 Request Message Field | J9: 下り項目 Response Message Field | O9: 条件および編集方法 Conditions and Editing Methods | Q9: 項目備考 Field Remarks
A10: # | K10: 上り項目 Request Message Field | L10: 下り項目 Response Message Field | M10: 上り項目 Request Message Field | N10: 下り項目 Response Message Field
A11: 10 | B11: * | D11: Del01_Dtl1 | E11: L | G11: $share$ | H11: MA.MABCL0290.DptLcl_Del01.DptLcl_Del01_Dtl | K11: DptLcl_DelChk01_Dtl | M11: DptLcl_Del01_Dtl
A12: 10 | D12: dpt_cd | E12: #MA.DPT_CD | G12: Dept. cd. | H12: 部門ＣＤ | I12: E | K12: E | M12: E
A13: 10 | D13: lcl_cd | E13: #MA.LCL_CD | G13: Locale cd. | H13: ロケールＣＤ | I13: E | K13: E | M13: E
A14: 10 | D14: st_dt | E14: #MA.DT | G14: Application start date | H14: 適用開始日 | I14: E | K14: E | M14: E
A15: 10 | D15: upd_cntr | E15: #MA.UPD_CNT | G15: Update counter | H15: 更新カウンタ | I15: E | K15: E | M15: E
D16: 詳細 :

Sheet 来歴
A1: 変更来歴
A3: Rev. | H3: 修正番号 | O3: 変更内容 | AQ3: 変更箇所
A4: 1 | O4: 初版
A5: 1.1 | O5: 英語の名称を追記 | AQ5: 全般
