Workbook

Sheet LogicCommon
A2: ロジック共通定義 | B2: ModuleID : | C2: MA | D2: LogicID : | E2: MABCL1220 | F2: Pj.ID : | G2: MC
B3: SubModuleID : | C3: MABC | D3: LogicClass : | E3: MABCL_JnlKeyMapReg | F3: SuperClassPj.ID :
D4: LogicName : | E4: 仕訳キー対応マスタ登録 | F4: SuperLogicID : | G4: MA.MAUDL5010
A5: 概要 :
A6: 詳細 :

Sheet JnlKeyMap_UpdChk01
A1: * | B1: * | D1: L | E1: 1
A2: * | D2: オペレーション実装仕様書 Operation Specification Implementation Sheet | E2: ModuleID : | F2: =IF(LogicCommon!C2="","",LogicCommon!C2) -> MA | G2: LogicID : | H2: =IF(LogicCommon!E2="","",LogicCommon!E2) -> MABCL1220 | I2: Ope.ID : | J2: JnlKeyMap_UpdChk01 | K2: Pj.ID : | L2: =IF(LogicCommon!G2="","",LogicCommon!G2) -> MC | M2: Ope.Body : | N2: =L4 & ".Checker" -> MA.MAUDL5010.Checker
A3: * | D3: =IF(LogicCommon!A3="","",LogicCommon!A3) | E3: SubModuleID : | F3: =IF(LogicCommon!C3="","",LogicCommon!C3) -> MABC | G3: LogicClass : | H3: =IF(LogicCommon!E3="","",LogicCommon!E3) -> MABCL_JnlKeyMapReg | I3: Ope.Method : | J3: @ | K3: SuperClassPj.ID : | L3: =IF(LogicCommon!G3="","",LogicCommon!G3) | M3: ReportID : | O3: Gene.Type : | P3: ALL
A4: * | E4: Version : | F4: 000000 | G4: LogicName : | H4: =IF(LogicCommon!E4="","",LogicCommon!E4) -> 仕訳キー対応マスタ登録 | I4: Ope.Name : | J4: 登録前チェック | K4: SuperLogicID : | L4: =IF(LogicCommon!G4="","",LogicCommon!G4) -> MA.MAUDL5010
A5: * | E5: ACType :
A6: * | D6: 概要 : | E6: 仕訳キー対応マスタを登録する前のチェックを行う | Q6: ID
A7: # | I7: U | K7: K | L7: K | M7: K | P7: o
A8: # | D8: ブロック名 Block Name | E8: 型 Type | G8: super/share | H8: 対象ブロック名 Target Block Name | K8: REQUIRED | L8: CONST | M8: LIST_LOGIC | P8: TargetName | T8: ブロック備考 Block Remarks
A9: # | D9: 項目名 Field Name | E9: 型 Type | F9: 桁 Digits | G9: フルネーム Full Name | H9: 日本語名 Japanese Name | I9: 上り項目 Request Message Field | J9: 下り項目 Response Message Field | R9: 条件および編集方法 Conditions and Editing Methods | T9: 項目備考 Field Remarks
A10: # | P10: 上り項目 Request Message Field | Q10: 下り項目 Response Message Field
A11: 10 | B11: * | D11: JnlKeyMap_UpdChk01_Dtl | E11: L | G11: $super$ | H11: DBC:MA.MAM_JNL_KEY_MAP
A12: 10 | D12: ac_slip_typ | E12: #MA.AC_SLIP_TYP | G12: Accounting slip type | H12: 会計伝票区分 | I12: E | K12: E | L12: MAC_AC_SLIP_TYP
A13: 10 | D13: cost_flg | E13: #MA.FLG | G13: Cost | H13: 原価 | I13: E
A14: 10 | D14: jnl_key_col_typ | E14: #MA.JNL_KEY_COL_TYP | G14: Journal key column type | H14: 仕訳キー項目区分 | I14: E | K14: E | L14: MAC_JNL_KEY_COL_TYP
A15: 10 | D15: jnl_key_set_col_typ | E15: #MA.JNL_KEY_SET_COL_TYP | G15: Journal key setting column type | H15: 仕訳キー設定項目区分 | I15: E | K15: E | L15: MAC_JNL_KEY_SET_COL_TYP
A16: 10 | D16: bp_jnl_key_set_col_typ | E16: #MA.JNL_KEY_SET_COL_TYP | G16: BP journal key setting column type | H16: 取引先仕訳キー設定項目区分 | I16: E | L16: MAC_JNL_KEY_SET_COL_TYP
A17: 10 | D17: default_cd | E17: #MA.JNL_KEY | G17: Default cd. | H17: デフォルトＣＤ | I17: E
A18: 10 | D18: memo1 | E18: #MA.MST_MEMO1 | G18: Memo 1 | H18: メモ１ | I18: E
A19: 10 | D19: memo2 | E19: #MA.MST_MEMO2 | G19: Memo 2 | H19: メモ２ | I19: E
A20: 10 | D20: memo3 | E20: #MA.MST_MEMO3 | G20: Memo 3 | H20: メモ３ | I20: E
A21: 10 | D21: del_flg | E21: #MA.FLG | G21: Logical delete | H21: 論理削除 | I21: E
A22: 10 | D22: upd_cntr | E22: #MA.UPD_CNT | G22: Update counter | H22: 更新カウンタ | I22: E
D23: 詳細 :

Sheet JnlKeyMap_Upd01
A1: * | B1: * | D1: L | E1: 1
A2: * | D2: オペレーション実装仕様書 Operation Specification Implementation Sheet | E2: ModuleID : | F2: =IF(LogicCommon!C2="","",LogicCommon!C2) -> MA | G2: LogicID : | H2: =IF(LogicCommon!E2="","",LogicCommon!E2) -> MABCL1220 | I2: Ope.ID : | J2: JnlKeyMap_Upd01 | K2: Pj.ID : | L2: =IF(LogicCommon!G2="","",LogicCommon!G2) -> MC | M2: Ope.Body : | N2: "mcframe.serverMAUD.MAUDL6010.MAUDL_RLUpdater"
A3: * | D3: =IF(LogicCommon!A3="","",LogicCommon!A3) | E3: SubModuleID : | F3: =IF(LogicCommon!C3="","",LogicCommon!C3) -> MABC | G3: LogicClass : | H3: =IF(LogicCommon!E3="","",LogicCommon!E3) -> MABCL_JnlKeyMapReg | I3: Ope.Method : | J3: @ | K3: SuperClassPj.ID : | L3: =IF(LogicCommon!G3="","",LogicCommon!G3) | M3: ReportID : | O3: Gene.Type : | P3: ALL
A4: * | E4: Version : | F4: 000000 | G4: LogicName : | H4: =IF(LogicCommon!E4="","",LogicCommon!E4) -> 仕訳キー対応マスタ登録 | I4: Ope.Name : | J4: 登録処理 | K4: SuperLogicID : | L4: =IF(LogicCommon!G4="","",LogicCommon!G4) -> MA.MAUDL5010
A5: * | E5: ACType :
A6: * | D6: 概要 : | E6: 仕訳キー対応マスタを登録する | L6: ID | N6: ID | P6: ID | R6: ID
A7: # | I7: U | K7: o | L7: UPDATE.updMaster | M7: o | N7: MAIN.chkMaster | O7: o | Q7: o
A8: # | D8: ブロック名 Block Name | E8: 型 Type | G8: super/share | H8: 対象ブロック名 Target Block Name | K8: TargetName | L8: DBC.MA.MAM_JNL_KEY_MAP | M8: TargetName | N8: DBC.MA.MAM_JNL_KEY_MAP | O8: TargetName | Q8: TargetName | U8: ブロック備考 Block Remarks
A9: # | D9: 項目名 Field Name | E9: 型 Type | F9: 桁 Digits | G9: フルネーム Full Name | H9: 日本語名 Japanese Name | I9: 上り項目 Request Message Field | J9: 下り項目 Response Message Field | S9: 条件および編集方法 Conditions and Editing Methods | U9: 項目備考 Field Remarks
A10: # | K10: 上り項目 Request Message Field | L10: 下り項目 Response Message Field | M10: 上り項目 Request Message Field | N10: 下り項目 Response Message Field | O10: 上り項目 Request Message Field | P10: 下り項目 Response Message Field | Q10: 上り項目 Request Message Field | R10: 下り項目 Response Message Field
A11: 10 | B11: * | D11: JnlKeyMap_Upd01_Dtl | E11: L | G11: $share$ | H11: MA.MABCL1220.JnlKeyMap_UpdChk01.JnlKeyMap_UpdChk01_Dtl | K11: L | M11: L
A12: 10 | D12: ac_slip_typ | E12: #MA.AC_SLIP_TYP | G12: Accounting slip type | H12: 会計伝票区分 | I12: E | K12: E | M12: E
A13: 10 | D13: cost_flg | E13: #MA.FLG | G13: Cost | H13: 原価 | I13: E | K13: E | M13: E
A14: 10 | D14: jnl_key_col_typ | E14: #MA.JNL_KEY_COL_TYP | G14: Journal key column type | H14: 仕訳キー項目区分 | I14: E | K14: E | M14: E
A15: 10 | D15: jnl_key_set_col_typ | E15: #MA.JNL_KEY_SET_COL_TYP | G15: Journal key setting column type | H15: 仕訳キー設定項目区分 | I15: E | K15: E
A16: 10 | D16: bp_jnl_key_set_col_typ | E16: #MA.JNL_KEY_SET_COL_TYP | G16: BP journal key setting column type | H16: 取引先仕訳キー設定項目区分 | I16: E | K16: E
A17: 10 | D17: default_cd | E17: #MA.JNL_KEY | G17: Default cd. | H17: デフォルトＣＤ | I17: E | K17: E
A18: 10 | D18: memo1 | E18: #MA.MST_MEMO1 | G18: Memo 1 | H18: メモ１ | I18: E | K18: E
A19: 10 | D19: memo2 | E19: #MA.MST_MEMO2 | G19: Memo 2 | H19: メモ２ | I19: E | K19: E
A20: 10 | D20: memo3 | E20: #MA.MST_MEMO3 | G20: Memo 3 | H20: メモ３ | I20: E | K20: E
A21: 10 | D21: del_flg | E21: #MA.FLG | G21: Logical delete | H21: 論理削除 | I21: E | K21: E
A22: 10 | D22: upd_cntr | E22: #MA.UPD_CNT | G22: Update counter | H22: 更新カウンタ | I22: E | K22: E
D23: 詳細 :

Sheet JnlKeyMap_DelChk01
A1: * | B1: * | D1: L | E1: 1
A2: * | D2: オペレーション実装仕様書 Operation Specification Implementation Sheet | E2: ModuleID : | F2: =IF(LogicCommon!C2="","",LogicCommon!C2) -> MA | G2: LogicID : | H2: =IF(LogicCommon!E2="","",LogicCommon!E2) -> MABCL1220 | I2: Ope.ID : | J2: JnlKeyMap_DelChk01 | K2: Pj.ID : | L2: =IF(LogicCommon!G2="","",LogicCommon!G2) -> MC | M2: Ope.Body : | N2: =L4 & ".Checker" -> MA.MAUDL5010.Checker
A3: * | D3: =IF(LogicCommon!A3="","",LogicCommon!A3) | E3: SubModuleID : | F3: =IF(LogicCommon!C3="","",LogicCommon!C3) -> MABC | G3: LogicClass : | H3: =IF(LogicCommon!E3="","",LogicCommon!E3) -> MABCL_JnlKeyMapReg | I3: Ope.Method : | J3: @ | K3: SuperClassPj.ID : | L3: =IF(LogicCommon!G3="","",LogicCommon!G3) | M3: ReportID : | O3: Gene.Type : | P3: ALL
A4: * | E4: Version : | F4: 000000 | G4: LogicName : | H4: =IF(LogicCommon!E4="","",LogicCommon!E4) -> 仕訳キー対応マスタ登録 | I4: Ope.Name : | J4: 削除前チェック | K4: SuperLogicID : | L4: =IF(LogicCommon!G4="","",LogicCommon!G4) -> MA.MAUDL5010
A5: * | E5: ACType :
A6: * | D6: 概要 : | E6: 仕訳キー対応マスタを削除する前のチェックを行う | Q6: ID
A7: # | I7: U | K7: K | P7: o
A8: # | D8: ブロック名 Block Name | E8: 型 Type | G8: super/share | H8: 対象ブロック名 Target Block Name | K8: REQUIRED | P8: TargetName | T8: ブロック備考 Block Remarks
A9: # | D9: 項目名 Field Name | E9: 型 Type | F9: 桁 Digits | G9: フルネーム Full Name | H9: 日本語名 Japanese Name | I9: 上り項目 Request Message Field | J9: 下り項目 Response Message Field | R9: 条件および編集方法 Conditions and Editing Methods | T9: 項目備考 Field Remarks
A10: # | P10: 上り項目 Request Message Field | Q10: 下り項目 Response Message Field
A11: 10 | B11: * | D11: JnlKeyMap_DelChk01_Dtl | E11: L
A12: 10 | D12: ac_slip_typ | E12: #MA.AC_SLIP_TYP | G12: Accounting slip type | H12: 会計伝票区分 | I12: E | K12: E
A13: 10 | D13: cost_flg | E13: #MA.FLG | G13: Cost | H13: 原価 | I13: E
A14: 10 | D14: jnl_key_col_typ | E14: #MA.JNL_KEY_COL_TYP | G14: Journal key column type | H14: 仕訳キー項目区分 | I14: E | K14: E
A15: 10 | D15: upd_cntr | E15: #MA.UPD_CNT | G15: Update counter | H15: 更新カウンタ | I15: E
D16: 詳細 :

Sheet JnlKeyMap_Del01
A1: * | B1: * | D1: L | E1: 1
A2: * | D2: オペレーション実装仕様書 Operation Specification Implementation Sheet | E2: ModuleID : | F2: =IF(LogicCommon!C2="","",LogicCommon!C2) -> MA | G2: LogicID : | H2: =IF(LogicCommon!E2="","",LogicCommon!E2) -> MABCL1220 | I2: Ope.ID : | J2: JnlKeyMap_Del01 | K2: Pj.ID : | L2: =IF(LogicCommon!G2="","",LogicCommon!G2) -> MC | M2: Ope.Body : | N2: "mcframe.serverMAUD.MAUDL6010.MAUDL_RLDeleter"
A3: * | D3: =IF(LogicCommon!A3="","",LogicCommon!A3) | E3: SubModuleID : | F3: =IF(LogicCommon!C3="","",LogicCommon!C3) -> MABC | G3: LogicClass : | H3: =IF(LogicCommon!E3="","",LogicCommon!E3) -> MABCL_JnlKeyMapReg | I3: Ope.Method : | J3: @ | K3: SuperClassPj.ID : | L3: =IF(LogicCommon!G3="","",LogicCommon!G3) | M3: ReportID : | O3: Gene.Type : | P3: ALL
A4: * | E4: Version : | F4: 000000 | G4: LogicName : | H4: =IF(LogicCommon!E4="","",LogicCommon!E4) -> 仕訳キー対応マスタ登録 | I4: Ope.Name : | J4: 削除処理 | K4: SuperLogicID : | L4: =IF(LogicCommon!G4="","",LogicCommon!G4) -> MA.MAUDL5010
A5: * | E5: ACType :
A6: * | D6: 概要 : | E6: 仕訳キー対応マスタを削除する | L6: ID | N6: ID
A7: # | I7: U | K7: o | L7: UPDATE.updMaster1 | M7: o
A8: # | D8: ブロック名 Block Name | E8: 型 Type | G8: super/share | H8: 対象ブロック名 Target Block Name | K8: TargetName | L8: DBC.MA.MAM_JNL_KEY_MAP | M8: TargetName | Q8: ブロック備考 Block Remarks
A9: # | D9: 項目名 Field Name | E9: 型 Type | F9: 桁 Digits | G9: フルネーム Full Name | H9: 日本語名 Japanese Name | I9: 上り項目 Request Message Field | J9: 下り項目 Response Message Field | O9: 条件および編集方法 Conditions and Editing Methods | Q9: 項目備考 Field Remarks
A10: # | K10: 上り項目 Request Message Field | L10: 下り項目 Response Message Field | M10: 上り項目 Request Message Field | N10: 下り項目 Response Message Field
A11: 10 | B11: * | D11: JnlKeyMap_Del01_Dtl | E11: L | G11: $share$ | H11: MA.MABCL1220.JnlKeyMap_DelChk01.JnlKeyMap_DelChk01_Dtl | K11: L
A12: 10 | D12: ac_slip_typ | E12: #MA.AC_SLIP_TYP | G12: Accounting slip type | H12: 会計伝票区分 | I12: E | K12: E
A13: 10 | D13: cost_flg | E13: #MA.FLG | G13: Cost | H13: 原価 | I13: E | K13: E
A14: 10 | D14: jnl_key_col_typ | E14: #MA.JNL_KEY_COL_TYP | G14: Journal key column type | H14: 仕訳キー項目区分 | I14: E | K14: E
A15: 10 | D15: upd_cntr | E15: #MA.UPD_CNT | G15: Update counter | H15: 更新カウンタ | I15: E | K15: E
D16: 詳細 :

Sheet Srch01
A1: * | B1: * | D1: L | E1: 1
A2: * | D2: オペレーション実装仕様書 Operation Specification Implementation Sheet | E2: ModuleID : | F2: =IF(LogicCommon!C2="","",LogicCommon!C2) -> MA | G2: LogicID : | H2: =IF(LogicCommon!E2="","",LogicCommon!E2) -> MABCL1220 | I2: Ope.ID : | J2: Srch01 | K2: Pj.ID : | L2: =IF(LogicCommon!G2="","",LogicCommon!G2) -> MC | M2: Ope.Body : | N2: "mcframe.serverMAUD.MAUDL6010.MAUDL_RLSearcher"
A3: * | D3: =IF(LogicCommon!A3="","",LogicCommon!A3) | E3: SubModuleID : | F3: =IF(LogicCommon!C3="","",LogicCommon!C3) -> MABC | G3: LogicClass : | H3: =IF(LogicCommon!E3="","",LogicCommon!E3) -> MABCL_JnlKeyMapReg | I3: Ope.Method : | J3: @ | K3: SuperClassPj.ID : | L3: =IF(LogicCommon!G3="","",LogicCommon!G3) | M3: ReportID : | O3: Gene.Type : | P3: ALL
A4: * | E4: Version : | F4: 000000 | G4: LogicName : | H4: =IF(LogicCommon!E4="","",LogicCommon!E4) -> 仕訳キー対応マスタ登録 | I4: Ope.Name : | J4: 検索 | K4: SuperLogicID : | L4: =IF(LogicCommon!G4="","",LogicCommon!G4) -> MA.MAUDL5010
A5: * | E5: ACType :
A6: * | D6: 概要 : | E6: 検索処理を行う | L6: ID | M6: ID | N6: ID | O6: ID
A7: # | I7: U | K7: K | L7: o | M7: SELECT.c0 | N7: o
A8: # | D8: ブロック名 Block Name | E8: 型 Type | G8: super/share | H8: 対象ブロック名 Target Block Name | K8: CONST | L8: TargetName | M8: DBC.MAM_JNL_KEY_MAP | N8: TargetName | R8: ブロック備考 Block Remarks
A9: # | D9: 項目名 Field Name | E9: 型 Type | F9: 桁 Digits | G9: フルネーム Full Name | H9: 日本語名 Japanese Name | I9: 上り項目 Request Message Field | J9: 下り項目 Response Message Field | P9: 条件および編集方法 Conditions and Editing Methods | R9: 項目備考 Field Remarks
A10: # | L10: 上り項目 Request Message Field | M10: 下り項目 Response Message Field | N10: 上り項目 Request Message Field | O10: 下り項目 Response Message Field
A11: 10 | B11: * | D11: Srch01_Cnd | E11: R | L11: R
A12: 10 | D12: ac_slip_typ | E12: #MA.AC_SLIP_TYP | G12: Accounting slip type | H12: 会計伝票区分 | I12: E
A13: 10 | D13: off_cost_flg | E13: #MA.FLG | G13: Cost. Off | H13: 原価.オフ | I13: E
A14: 10 | D14: on_cost_flg | E14: #MA.FLG | G14: Cost. On | H14: 原価.オン | I14: E
A15: 10 | D15: jnl_key_col_typ | E15: #MA.JNL_KEY_COL_TYP | G15: Journal key column type | H15: 仕訳キー項目区分 | I15: E
A16: 10 | D16: off_del_flg | E16: #MA.FLG | G16: Logical delete. Off | H16: 論理削除.オフ | I16: E
A17: 10 | D17: on_del_flg | E17: #MA.FLG | G17: Logical delete. On | H17: 論理削除.オン | I17: E
A18: 10 | D18: memo1 | E18: #MA.MST_MEMO1 | G18: Memo 1 | H18: メモ１ | I18: E
A19: 10 | D19: memo2 | E19: #MA.MST_MEMO2 | G19: Memo 2 | H19: メモ２ | I19: E
A20: 10 | D20: memo3 | E20: #MA.MST_MEMO3 | G20: Memo 3 | H20: メモ３ | I20: E
A22: 20 | B22: * | D22: Srch01_Rslt1 | E22: L | M22: L
A23: 20 | D23: del_flg | E23: #MA.FLG | G23: Logical delete | H23: 論理削除 | J23: E | M23: E
A24: 20 | D24: ac_slip_typ | E24: #MA.AC_SLIP_TYP | G24: Accounting slip type | H24: 会計伝票区分 | J24: E | K24: MAC_AC_SLIP_TYP | M24: E
A25: 20 | D25: ac_slip_typ_nm | E25: #MA.AC_SLIP_TYP_NM | G25: Accounting slip type name | H25: 会計伝票区分名 | J25: E
A26: 20 | D26: cost_flg | E26: #MA.FLG | G26: Cost | H26: 原価 | J26: E | M26: E
A27: 20 | D27: jnl_key_col_typ | E27: #MA.JNL_KEY_COL_TYP | G27: Journal key column type | H27: 仕訳キー項目区分 | J27: E | K27: MAC_JNL_KEY_COL_TYP | M27: E
A28: 20 | D28: jnl_key_col_typ_nm | E28: #MA.JNL_KEY_COL_TYP_NM | G28: Journal key column type name | H28: 仕訳キー項目区分名 | J28: E
A29: 20 | D29: jnl_key_set_col_typ | E29: #MA.JNL_KEY_SET_COL_TYP | G29: Journal key setting column type | H29: 仕訳キー設定項目区分 | J29: E | K29: MAC_JNL_KEY_SET_COL_TYP | M29: E
A30: 20 | D30: jnl_key_set_col_typ_nm | E30: #MA.JNL_KEY_SET_COL_TYP_NM | G30: Journal key setting column type name | H30: 仕訳キー設定項目区分名 | J30: E
A31: 20 | D31: bp_jnl_key_set_col_typ | E31: #MA.JNL_KEY_SET_COL_TYP | G31: BP journal key setting column type | H31: 取引先仕訳キー設定項目区分 | J31: E | K31: MAC_JNL_KEY_SET_COL_TYP | M31: E
A32: 20 | D32: bp_jnl_key_set_col_typ_nm | E32: #MA.JNL_KEY_SET_COL_TYP_NM | G32: BP journal key setting column name | H32: 取引先仕訳キー設定項目区分名 | J32: E
A33: 20 | D33: default_cd | E33: #MA.JNL_KEY | G33: Default cd. | H33: デフォルトＣＤ | J33: E | M33: E
A34: 20 | D34: memo1 | E34: #MA.MST_MEMO1 | G34: Memo 1 | H34: メモ１ | J34: E | M34: E
A35: 20 | D35: memo2 | E35: #MA.MST_MEMO2 | G35: Memo 2 | H35: メモ２ | J35: E | M35: E
A36: 20 | D36: memo3 | E36: #MA.MST_MEMO3 | G36: Memo 3 | H36: メモ３ | J36: E | M36: E
A37: 20 | D37: ins_usr_id | E37: #MA.FCM_USR_ID | G37: Entry user ID | H37: 登録ユーザＩＤ | J37: E | M37: E
A38: 20 | D38: ins_usr_nm | E38: #MA.FCM_USR_NM | G38: Entry user name | H38: 登録ユーザ名 | J38: E | M38: E
A39: 20 | D39: ins_ts | E39: #MA.SYS_TS | G39: Entry date and time | H39: 登録日時 | J39: E | M39: E
A40: 20 | D40: ins_func_id | E40: #MA.FUNC_ID | G40: Entry function ID | H40: 登録機能ＩＤ | J40: E | M40: E
A41: 20 | D41: ins_func_nm | E41: #MA.FUNC_NM | G41: Entry function name | H41: 登録機能名 | J41: E
...

Sheet Upd01
A1: * | B1: * | D1: L | E1: 1
A2: * | D2: オペレーション実装仕様書 Operation Specification Implementation Sheet | E2: ModuleID : | F2: =IF(LogicCommon!C2="","",LogicCommon!C2) -> MA | G2: LogicID : | H2: =IF(LogicCommon!E2="","",LogicCommon!E2) -> MABCL1220 | I2: Ope.ID : | J2: Upd01 | K2: Pj.ID : | L2: =IF(LogicCommon!G2="","",LogicCommon!G2) -> MC | M2: Ope.Body : | N2: "mcframe.serverMAUD.MAUDL6010.MAUDL_RLUpdater"
A3: * | D3: =IF(LogicCommon!A3="","",LogicCommon!A3) | E3: SubModuleID : | F3: =IF(LogicCommon!C3="","",LogicCommon!C3) -> MABC | G3: LogicClass : | H3: =IF(LogicCommon!E3="","",LogicCommon!E3) -> MABCL_JnlKeyMapReg | I3: Ope.Method : | J3: @ | K3: SuperClassPj.ID : | L3: =IF(LogicCommon!G3="","",LogicCommon!G3) | M3: ReportID : | O3: Gene.Type : | P3: ALL
A4: * | E4: Version : | F4: 000000 | G4: LogicName : | H4: =IF(LogicCommon!E4="","",LogicCommon!E4) -> 仕訳キー対応マスタ登録 | I4: Ope.Name : | J4: 登録 | K4: SuperLogicID : | L4: =IF(LogicCommon!G4="","",LogicCommon!G4) -> MA.MAUDL5010
A5: * | E5: ACType :
A6: * | D6: 概要 : | E6: 登録処理を行う | L6: ID | N6: ID | P6: ID | R6: ID
A7: # | I7: U | K7: o | L7: CALL_OPE01.chk01 | M7: o | N7: CALL_OPE01.upd01 | O7: o | Q7: o
A8: # | D8: ブロック名 Block Name | E8: 型 Type | G8: super/share | H8: 対象ブロック名 Target Block Name | K8: TargetName | L8: OPE.MA.MABCL1220.JnlKeyMap_UpdChk01 | M8: TargetName | N8: OPE.MA.MABCL1220.JnlKeyMap_Upd01 | O8: TargetName | Q8: TargetName | U8: ブロック備考 Block Remarks
A9: # | D9: 項目名 Field Name | E9: 型 Type | F9: 桁 Digits | G9: フルネーム Full Name | H9: 日本語名 Japanese Name | I9: 上り項目 Request Message Field | J9: 下り項目 Response Message Field | S9: 条件および編集方法 Conditions and Editing Methods | U9: 項目備考 Field Remarks
A10: # | K10: 上り項目 Request Message Field | L10: 下り項目 Response Message Field | M10: 上り項目 Request Message Field | N10: 下り項目 Response Message Field | O10: 上り項目 Request Message Field | P10: 下り項目 Response Message Field | Q10: 上り項目 Request Message Field | R10: 下り項目 Response Message Field
A11: 10 | B11: * | D11: Upd01_Dtl1 | E11: L | G11: $share$ | H11: MA.MABCL1220.JnlKeyMap_Upd01.JnlKeyMap_Upd01_Dtl | K11: JnlKeyMap_UpdChk01_Dtl | M11: JnlKeyMap_Upd01_Dtl
A12: 10 | D12: ac_slip_typ | E12: #MA.AC_SLIP_TYP | G12: Accounting slip type | H12: 会計伝票区分 | I12: E | K12: E | M12: E
A13: 10 | D13: cost_flg | E13: #MA.FLG | G13: Cost | H13: 原価 | I13: E | K13: E | M13: E
A14: 10 | D14: jnl_key_col_typ | E14: #MA.JNL_KEY_COL_TYP | G14: Journal key column type | H14: 仕訳キー項目区分 | I14: E | K14: E | M14: E
A15: 10 | D15: jnl_key_set_col_typ | E15: #MA.JNL_KEY_SET_COL_TYP | G15: Journal key setting column type | H15: 仕訳キー設定項目区分 | I15: E | K15: E | M15: E
A16: 10 | D16: bp_jnl_key_set_col_typ | E16: #MA.JNL_KEY_SET_COL_TYP | G16: BP journal key setting column type | H16: 取引先仕訳キー設定項目区分 | I16: E | K16: E | M16: E
A17: 10 | D17: default_cd | E17: #MA.JNL_KEY | G17: Default cd. | H17: デフォルトＣＤ | I17: E | K17: E | M17: E
A18: 10 | D18: memo1 | E18: #MA.MST_MEMO1 | G18: Memo 1 | H18: メモ１ | I18: E | K18: E | M18: E
A19: 10 | D19: memo2 | E19: #MA.MST_MEMO2 | G19: Memo 2 | H19: メモ２ | I19: E | K19: E | M19: E
A20: 10 | D20: memo3 | E20: #MA.MST_MEMO3 | G20: Memo 3 | H20: メモ３ | I20: E | K20: E | M20: E
A21: 10 | D21: del_flg | E21: #MA.FLG | G21: Logical delete | H21: 論理削除 | I21: E | K21: E | M21: E
A22: 10 | D22: upd_cntr | E22: #MA.UPD_CNT | G22: Update counter | H22: 更新カウンタ | I22: E | K22: E | M22: E
D23: 詳細 :

Sheet Del01
A1: * | B1: * | D1: L | E1: 1
A2: * | D2: オペレーション実装仕様書 Operation Specification Implementation Sheet | E2: ModuleID : | F2: =IF(LogicCommon!C2="","",LogicCommon!C2) -> MA | G2: LogicID : | H2: =IF(LogicCommon!E2="","",LogicCommon!E2) -> MABCL1220 | I2: Ope.ID : | J2: Del01 | K2: Pj.ID : | L2: =IF(LogicCommon!G2="","",LogicCommon!G2) -> MC | M2: Ope.Body : | N2: "mcframe.serverMAUD.MAUDL6010.MAUDL_RLDeleter"
A3: * | D3: =IF(LogicCommon!A3="","",LogicCommon!A3) | E3: SubModuleID : | F3: =IF(LogicCommon!C3="","",LogicCommon!C3) -> MABC | G3: LogicClass : | H3: =IF(LogicCommon!E3="","",LogicCommon!E3) -> MABCL_JnlKeyMapReg | I3: Ope.Method : | J3: @ | K3: SuperClassPj.ID : | L3: =IF(LogicCommon!G3="","",LogicCommon!G3) | M3: ReportID : | O3: Gene.Type : | P3: ALL
A4: * | E4: Version : | F4: 000000 | G4: LogicName : | H4: =IF(LogicCommon!E4="","",LogicCommon!E4) -> 仕訳キー対応マスタ登録 | I4: Ope.Name : | J4: 削除 | K4: SuperLogicID : | L4: =IF(LogicCommon!G4="","",LogicCommon!G4) -> MA.MAUDL5010
A5: * | E5: ACType :
A6: * | D6: 概要 : | E6: 削除処理を行う | L6: ID | N6: ID
A7: # | I7: U | K7: o | L7: CALL_OPE01.chk01 | M7: o | N7: CALL_OPE01.del01
A8: # | D8: ブロック名 Block Name | E8: 型 Type | G8: super/share | H8: 対象ブロック名 Target Block Name | K8: TargetName | L8: OPE.MA.MABCL1220.JnlKeyMap_DelChk01 | M8: TargetName | N8: OPE.MA.MABCL1220.JnlKeyMap_Del01 | Q8: ブロック備考 Block Remarks
A9: # | D9: 項目名 Field Name | E9: 型 Type | F9: 桁 Digits | G9: フルネーム Full Name | H9: 日本語名 Japanese Name | I9: 上り項目 Request Message Field | J9: 下り項目 Response Message Field | O9: 条件および編集方法 Conditions and Editing Methods | Q9: 項目備考 Field Remarks
A10: # | K10: 上り項目 Request Message Field | L10: 下り項目 Response Message Field | M10: 上り項目 Request Message Field | N10: 下り項目 Response Message Field
A11: 10 | B11: * | D11: Del01_Dtl1 | E11: L | G11: $share$ | H11: MA.MABCL1220.JnlKeyMap_Del01.JnlKeyMap_Del01_Dtl | K11: JnlKeyMap_DelChk01_Dtl | M11: JnlKeyMap_Del01_Dtl
A12: 10 | D12: ac_slip_typ | E12: #MA.AC_SLIP_TYP | G12: Accounting slip type | H12: 会計伝票区分 | I12: E | K12: E | M12: E
A13: 10 | D13: cost_flg | E13: #MA.FLG | G13: Cost | H13: 原価 | I13: E | K13: E | M13: E
A14: 10 | D14: jnl_key_col_typ | E14: #MA.JNL_KEY_COL_TYP | G14: Journal key column type | H14: 仕訳キー項目区分 | I14: E | K14: E | M14: E
A15: 10 | D15: upd_cntr | E15: #MA.UPD_CNT | G15: Update counter | H15: 更新カウンタ | I15: E | K15: E | M15: E
D16: 詳細 :

Sheet 来歴
A1: 変更来歴
A3: Rev. | H3: 修正番号 | O3: 変更内容 | AQ3: 変更箇所
A4: 1 | O4: 初版
A5: 1.1 | O5: 英語の名称を追記 | AQ5: 全般
