Workbook

Sheet LogicCommon
A2: ロジック共通定義 | B2: ModuleID : | C2: MA | D2: LogicID : | E2: MABCL0540 | F2: Pj.ID : | G2: MC
B3: SubModuleID : | C3: MABC | D3: LogicClass : | E3: MABCL_CstReg | F3: SuperClassPj.ID :
D4: LogicName : | E4: 得意先登録 | F4: SuperLogicID : | G4: MA.MAUDL5010
A5: 概要 :
A6: 詳細 :

Sheet BpCst_UpdChk01
A1: * | B1: * | D1: L | E1: 1
A2: * | D2: オペレーション実装仕様書 Operation Specification Implementation Sheet | E2: ModuleID : | F2: =IF(LogicCommon!C2="","",LogicCommon!C2) -> MA | G2: LogicID : | H2: =IF(LogicCommon!E2="","",LogicCommon!E2) -> MABCL0540 | I2: Ope.ID : | J2: BpCst_UpdChk01 | K2: Pj.ID : | L2: =IF(LogicCommon!G2="","",LogicCommon!G2) -> MC | M2: Ope.Body : | N2: =L4 & ".Checker" -> MA.MAUDL5010.Checker
A3: * | E3: SubModuleID : | F3: =IF(LogicCommon!C3="","",LogicCommon!C3) -> MABC | G3: LogicClass : | H3: =IF(LogicCommon!E3="","",LogicCommon!E3) -> MABCL_CstReg | I3: Ope.Method : | J3: @ | K3: SuperClassPj.ID : | L3: =IF(LogicCommon!G3="","",LogicCommon!G3) | M3: ReportID : | O3: Gene.Type : | P3: ALL
A4: * | E4: Version : | F4: 000000 | G4: LogicName : | H4: =IF(LogicCommon!E4="","",LogicCommon!E4) -> 得意先登録 | I4: Ope.Name : | J4: チェック | K4: SuperLogicID : | L4: =IF(LogicCommon!G4="","",LogicCommon!G4) -> MA.MAUDL5010
A5: * | E5: ACType :
A6: * | D6: 概要 : | E6: 取引先マスタの登録前のチェックを行います。 | T6: ID
A7: # | I7: U | K7: K | L7: K | M7: K | N7: K | O7: K | P7: K | Q7: K | R7: K | S7: o
A8: # | D8: ブロック名 Block Name | E8: 型 Type | G8: super/share | H8: 対象ブロック名 Target Block Name | K8: REQUIRED | L8: CONST | M8: LIST_LOGIC | N8: LIST_OUT | O8: LIST_OUT_BASE | P8: LIST_IN | Q8: LIST_IN_BASE | R8: SMALL_LARGE | S8: TargetName | W8: ブロック備考 Block Remarks
A9: # | D9: 項目名 Field Name | E9: 型 Type | F9: 桁 Digits | G9: フルネーム Full Name | H9: 日本語名 Japanese Name | I9: 上り項目 Request Message Field | J9: 下り項目 Response Message Field | U9: 条件および編集方法 Conditions and Editing Methods | W9: 項目備考 Field Remarks
A10: # | S10: 上り項目 Request Message Field | T10: 下り項目 Response Message Field
A11: 10 | B11: * | D11: BpCst_UpdChk01_Dtl | E11: L
A12: 10 | D12: bp_cd | E12: #MA.BP_CD | G12: BP cd. | H12: 取引先ＣＤ | I12: E | K12: E | M12: MA.MAUAL0010.Bp | N12: bcst_flg | O12: bcst_flg | P12: MAC_BP_IS_SRCH_TYP.CST | Q12: bp_is_srch_typ
A13: 10 | D13: acst_cd | E13: #MA.BP_CD | G13: AR customer cd. | H13: 売掛先ＣＤ | I13: E | M13: MA.MAUAL0010.Bp | P13: MAC_BP_IS_SRCH_TYP.ACST | Q13: bp_is_srch_typ
A14: 10 | D14: ar_dpt_typ | E14: #MA.AR_DPT_TYP | G14: AR dept. type | H14: 債権部門区分 | I14: E | L14: MAC_AR_DPT_TYP
A15: 10 | D15: ar_dpt_cd | E15: #MA.DPT_CD | G15: AR dept. cd. | H15: 債権部門ＣＤ | I15: E
A16: 10 | D16: check_ar_dpt_cd | E16: #MA.DPT_CD | G16: AR dept. cd. | H16: 債権部門ＣＤ | I16: E | M16: MA.MAUAL0010.Dpt | P16: MAC_DPT_IS_SRCH_TYP.AR;true | Q16: dpt_is_srch_typ;mode_today_flg
A17: 10 | D17: cst_cntct_dpt | E17: #MA.CNTCT_DPT | G17: Customer dept. | H17: 得意先部署 | I17: E
A18: 10 | D18: cst_cntct_psn | E18: #MA.CNTCT_PSN | G18: Customer PIC | H18: 得意先担当者 | I18: E
A19: 10 | D19: cst_cntct_psn_title | E19: #MA.BP_PSN_TITLE | G19: Form of address for Customer PIC | H19: 得意先担当者敬称 | I19: E
A20: 10 | D20: cst_sundry_flg | E20: #MA.FLG | G20: Miscellaneous customer | H20: 得意先諸口 | I20: E
A21: 10 | D21: sls_upri_req_typ | E21: #MA.SLS_UPRI_REQ_TYP | G21: Sales unit price acquisition type | H21: 販売単価取得区分 | I21: E | L21: MAC_SLS_UPRI_REQ_TYP
A22: 10 | D22: sls_upri_cng_flg | E22: #MA.FLG | G22: Allow sales unit price change | H22: 販売単価変更許可 | I22: E
A23: 10 | D23: sls_upri_rnd_typ | E23: #MA.RND_TYP | G23: Sales unit price rounding type | H23: 販売単価端数処理区分 | I23: E | L23: MAC_RND_TYP
A24: 10 | D24: sls_amt_rnd_typ | E24: #MA.RND_TYP | G24: Rounding type (Sales amount) | H24: 売上金額端数処理区分 | I24: E | K24: E | L24: MAC_RND_TYP
A25: 10 | D25: sls_tax_calc_typ | E25: #MA.TAX_CALC_TYP | G25: Sales tax calculation type | H25: 売上税計算区分 | I25: E | L25: MAC_TAX_CALC_TYP
A26: 10 | D26: sls_tax_rnd_typ | E26: #MA.RND_TYP | G26: Sales tax rounding type | H26: 売上税額端数処理区分 | I26: E | K26: E | L26: MAC_RND_TYP
A27: 10 | D27: sls_basis_typ | E27: #MA.SLS_BASIS_TYP | G27: Revenue recording type | H27: 売上計上区分 | I27: E | L27: MAC_SLS_BASIS_TYP
A28: 10 | D28: ship_schd_split_typ | E28: #MA.SHIP_SCHD_SPLIT_TYP | G28: Shipping schedule split type | H28: 出荷予定分割区分 | I28: E | L28: MAC_SHIP_SCHD_SPLIT_TYP
A29: 10 | D29: bill_basis_typ | E29: #MA.BILL_BASIS_TYP | G29: Billing initial base type | H29: 請求起算区分 | I29: E | L29: MAC_BILL_BASIS_TYP
A30: 10 | D30: bill_crryovr_times | E30: #MA.CRRYOVR_TIMES | G30: Billing carry-over count | H30: 請求繰越回数 | I30: E | R30: 0:99
A31: 10 | D31: lot_back_stop_typ | E31: #MA.LOT_BACK_STOP_TYP | G31: Lot reverse prohibit type | H31: ロット逆転禁止区分 | I31: E | L31: MAC_LOT_BACK_STOP_TYP
A32: 10 | D32: slip_each_lot_typ | E32: #MA.SLIP_EACH_LOT_TYP | G32: Lot details split type | H32: ロット明細分割区分 | I32: E | L32: MAC_SLIP_EACH_LOT_TYP
A33: 10 | D33: cst_ship_form_cd | E33: #MA.SLIP_FORM_CD | G33: Customer delivery note cd. | H33: 得意先納品書ＣＤ | I33: E | M33: MA.MAUAL0010.SlipForm
A34: 10 | D34: stk_lst_issue_flg | E34: #MA.FLG | G34: Issue identification tag | H34: 現品票発行 | I34: E
A35: 10 | D35: stk_lst_form_cd | E35: #MA.SLIP_FORM_CD | G35: Identification tag cd. | H35: 現品票ＣＤ | I35: E | M35: MA.MAUAL0010.SlipForm
A36: 10 | D36: sls_tax_cd | E36: #MA.TAX_CD | G36: Sales tax cd. | H36: 売上税ＣＤ | I36: E | M36: MA.MAUAL0010.SlsTax
A37: 10 | D37: sls_tax_cd_prio_flg | E37: #MA.FLG | G37: Sales tax priority | H37: 売上税優先 | I37: E
A38: 10 | D38: wrk_ar_flg | E38: #MA.FLG | G38: AR management by sales project | H38: 案件別債権管理 | I38: E
A39: 10 | D39: cst_iv_flg | E39: #MA.FLG | G39: Customer invoice transaction | H39: 得意先インボイス取引 | I39: E
A40: 10 | D40: ship_lt | E40: #MA.LT | G40: Shipping LT (For demand) | H40: 出荷ＬＴ（需要情報用） | I40: E | R40: 0:
...

Sheet BpCst_Upd01
A1: * | B1: * | D1: L | E1: 1
A2: * | D2: オペレーション実装仕様書 Operation Specification Implementation Sheet | E2: ModuleID : | F2: =IF(LogicCommon!C2="","",LogicCommon!C2) -> MA | G2: LogicID : | H2: =IF(LogicCommon!E2="","",LogicCommon!E2) -> MABCL0540 | I2: Ope.ID : | J2: BpCst_Upd01 | K2: Pj.ID : | L2: =IF(LogicCommon!G2="","",LogicCommon!G2) -> MC | M2: Ope.Body : | N2: "mcframe.serverMAUD.MAUDL6010.MAUDL_RLUpdater"
A3: * | E3: SubModuleID : | F3: =IF(LogicCommon!C3="","",LogicCommon!C3) -> MABC | G3: LogicClass : | H3: =IF(LogicCommon!E3="","",LogicCommon!E3) -> MABCL_CstReg | I3: Ope.Method : | J3: @ | K3: SuperClassPj.ID : | L3: =IF(LogicCommon!G3="","",LogicCommon!G3) | M3: ReportID : | O3: Gene.Type : | P3: ALL
A4: * | E4: Version : | F4: 000000 | G4: LogicName : | H4: =IF(LogicCommon!E4="","",LogicCommon!E4) -> 得意先登録 | I4: Ope.Name : | J4: 登録 | K4: SuperLogicID : | L4: =IF(LogicCommon!G4="","",LogicCommon!G4) -> MA.MAUDL5010
A5: * | E5: ACType :
A6: * | D6: 概要 : | E6: 取引先マスタの登録を行います。 | L6: ID | N6: ID | P6: ID | R6: ID
A7: # | I7: U | K7: o | L7: UPDATE.updMaster | M7: o | N7: MAIN.chkMaster | O7: o | Q7: o
A8: # | D8: ブロック名 Block Name | E8: 型 Type | G8: super/share | H8: 対象ブロック名 Target Block Name | K8: TargetName | L8: DBC.MA.MAM_BP | M8: TargetName | N8: DBC.MA.MAM_BP | O8: TargetName | Q8: TargetName | U8: ブロック備考 Block Remarks
A9: # | D9: 項目名 Field Name | E9: 型 Type | F9: 桁 Digits | G9: フルネーム Full Name | H9: 日本語名 Japanese Name | I9: 上り項目 Request Message Field | J9: 下り項目 Response Message Field | S9: 条件および編集方法 Conditions and Editing Methods | U9: 項目備考 Field Remarks
A10: # | K10: 上り項目 Request Message Field | L10: 下り項目 Response Message Field | M10: 上り項目 Request Message Field | N10: 下り項目 Response Message Field | O10: 上り項目 Request Message Field | P10: 下り項目 Response Message Field | Q10: 上り項目 Request Message Field | R10: 下り項目 Response Message Field
A11: 10 | B11: * | D11: BpCst_Upd01_Dtl | E11: L | G11: $share$ | H11: MA.MABCL0540.BpCst_UpdChk01.BpCst_UpdChk01_Dtl | K11: L | M11: L
A12: 10 | D12: bp_cd | E12: #MA.BP_CD | G12: BP cd. | H12: 取引先ＣＤ | I12: E | K12: E | M12: E
A13: 10 | D13: acst_cd | E13: #MA.BP_CD | G13: AR customer cd. | H13: 売掛先ＣＤ | I13: E | K13: E
A14: 10 | D14: ar_dpt_typ | E14: #MA.AR_DPT_TYP | G14: AR dept. type | H14: 債権部門区分 | I14: E | K14: E
A15: 10 | D15: ar_dpt_cd | E15: #MA.DPT_CD | G15: AR dept. cd. | H15: 債権部門ＣＤ | I15: E | K15: E
A16: 10 | D16: cst_cntct_dpt | E16: #MA.CNTCT_DPT | G16: Customer dept. | H16: 得意先部署 | I16: E | K16: E
A17: 10 | D17: cst_cntct_psn | E17: #MA.CNTCT_PSN | G17: Customer PIC | H17: 得意先担当者 | I17: E | K17: E
A18: 10 | D18: cst_cntct_psn_title | E18: #MA.BP_PSN_TITLE | G18: Form of address for Customer PIC | H18: 得意先担当者敬称 | I18: E | K18: E
A19: 10 | D19: cst_sundry_flg | E19: #MA.FLG | G19: Miscellaneous customer | H19: 得意先諸口 | I19: E | K19: E
A20: 10 | D20: sls_upri_req_typ | E20: #MA.SLS_UPRI_REQ_TYP | G20: Sales unit price acquisition type | H20: 販売単価取得区分 | I20: E | K20: E
A21: 10 | D21: sls_upri_cng_flg | E21: #MA.FLG | G21: Allow sales unit price change | H21: 販売単価変更許可 | I21: E | K21: E
A22: 10 | D22: sls_upri_rnd_typ | E22: #MA.RND_TYP | G22: Sales unit price rounding type | H22: 販売単価端数処理区分 | I22: E | K22: E
A23: 10 | D23: sls_amt_rnd_typ | E23: #MA.RND_TYP | G23: Rounding type (Sales amount) | H23: 売上金額端数処理区分 | I23: E | K23: E
A24: 10 | D24: sls_tax_calc_typ | E24: #MA.TAX_CALC_TYP | G24: Sales tax calculation type | H24: 売上税計算区分 | I24: E | K24: E
... A51: 10 | D51: not_sublot_mix_flg | E51: #MA.FLG | G51: Prohibit mixed sublots flg. | H51: サブロット混在不可ＦＬＧ | I51: E | K51: E
D52: 詳細 :

Sheet Srch01
A1: * | B1: * | D1: L | E1: 1
A2: * | D2: オペレーション実装仕様書 Operation Specification Implementation Sheet | E2: ModuleID : | F2: =IF(LogicCommon!C2="","",LogicCommon!C2) -> MA | G2: LogicID : | H2: =IF(LogicCommon!E2="","",LogicCommon!E2) -> MABCL0540 | I2: Ope.ID : | J2: Srch01 | K2: Pj.ID : | L2: =IF(LogicCommon!G2="","",LogicCommon!G2) -> MC | M2: Ope.Body : | N2: "mcframe.serverMAUD.MAUDL6010.MAUDL_RLSearcher"
A3: * | D3: =IF(LogicCommon!A3="","",LogicCommon!A3) | E3: SubModuleID : | F3: =IF(LogicCommon!C3="","",LogicCommon!C3) -> MABC | G3: LogicClass : | H3: =IF(LogicCommon!E3="","",LogicCommon!E3) -> MABCL_CstReg | I3: Ope.Method : | J3: @ | K3: SuperClassPj.ID : | L3: =IF(LogicCommon!G3="","",LogicCommon!G3) | M3: ReportID : | O3: Gene.Type : | P3: ALL
A4: * | E4: Version : | F4: 000000 | G4: LogicName : | H4: =IF(LogicCommon!E4="","",LogicCommon!E4) -> 得意先登録 | I4: Ope.Name : | J4: 検索 | K4: SuperLogicID : | L4: =IF(LogicCommon!G4="","",LogicCommon!G4) -> MA.MAUDL5010
A5: * | E5: ACType :
A6: * | D6: 概要 : | E6: 得意先関連マスタの検索を行います。 | M6: ID | O6: ID | Q6: ID | S6: ID | U6: ID | W6: ID | Y6: ID | AA6: ID
A7: # | I7: U | K7: K | L7: o | M7: SELECT.c0 | N7: o | O7: SELECT_SUB1.c1 | P7: o | Q7: SELECT_SUB2.c2 | R7: o | S7: SELECT_SUB3.c3 | T7: o | U7: SELECT_SUB4.c4 | V7: o | W7: SELECT_SUB5.c5 | X7: o | Y7: SELECT_SUB6.c6 | Z7: o | AA7: SELECT_SUB7.c7
A8: # | D8: ブロック名 Block Name | E8: 型 Type | G8: super/share | H8: 対象ブロック名 Target Block Name | K8: CONST | L8: TargetName | M8: DBC.MA.MAM_BP | N8: TargetName | O8: DBC.MA.MAM_CST_USR | P8: TargetName | Q8: DBC.MA.MAM_CST_SLS_UPRI_RANK | R8: TargetName | S8: DBC.MA.MAM_CST_DLV | T8: TargetName | U8: DBC.MA.MAM_SHIP_VALID_CTL | V8: TargetName | W8: DBC.MA.MAM_SLO_ALLOC_GD | X8: TargetName | Y8: DBC.MA.MAM_EDI_IF_CTL | Z8: TargetName | AA8: DBC.MA.MAM_BP_ITM | AD8: ブロック備考 Block Remarks
A9: # | D9: 項目名 Field Name | E9: 型 Type | F9: 桁 Digits | G9: フルネーム Full Name | H9: 日本語名 Japanese Name | I9: 上り項目 Request Message Field | J9: 下り項目 Response Message Field | AB9: 条件および編集方法 Conditions and Editing Methods | AD9: 項目備考 Field Remarks
A10: # | L10: 上り項目 Request Message Field | M10: 下り項目 Response Message Field | N10: 上り項目 Request Message Field | O10: 下り項目 Response Message Field | P10: 上り項目 Request Message Field | Q10: 下り項目 Response Message Field | R10: 上り項目 Request Message Field | S10: 下り項目 Response Message Field | T10: 上り項目 Request Message Field | U10: 下り項目 Response Message Field | V10: 上り項目 Request Message Field | W10: 下り項目 Response Message Field | X10: 上り項目 Request Message Field | Y10: 下り項目 Response Message Field | Z10: 上り項目 Request Message Field | AA10: 下り項目 Response Message Field
A11: 10 | B11: * | D11: Srch01_Cnd | E11: R
A12: 10 | D12: st_dt_fr | E12: #MA.DT | G12: Application start date FROM | H12: 適用開始日ＦＲＯＭ | I12: E
A13: 10 | D13: st_dt_to | E13: #MA.DT | G13: Application start date TO | H13: 適用開始日ＴＯ | I13: E
A14: 10 | D14: end_dt_fr | E14: #MA.DT | G14: Application end date FROM | H14: 適用終了日ＦＲＯＭ | I14: E
A15: 10 | D15: end_dt_to | E15: #MA.DT | G15: Application end date TO | H15: 適用終了日ＴＯ | I15: E
A16: 10 | D16: bp_cd | E16: #MA.BP_CD | G16: BP cd. | H16: 取引先ＣＤ | I16: E
A17: 10 | D17: bp_nm | E17: #MA.BP_NM | G17: BP name | H17: 取引先名 | I17: E
A18: 10 | D18: off_del_flg | E18: #MA.FLG | G18: Logical delete. Off | H18: 論理削除.オフ | I18: E
A19: 10 | D19: on_del_flg | E19: #MA.FLG | G19: Logical delete. On | H19: 論理削除.オン | I19: E
A21: 20 | B21: * | D21: Srch01_Rslt1 | E21: L | M21: L
A22: 20 | D22: bp_cd | E22: #MA.BP_CD | G22: BP cd. | H22: 取引先ＣＤ | J22: E | M22: E
A23: 20 | D23: acst_flg | E23: #MA.FLG | G23: AR customer | H23: 売掛先 | J23: E | M23: E
A24: 20 | D24: acst_cd | E24: #MA.BP_CD | G24: AR customer cd. | H24: 売掛先ＣＤ | J24: E | M24: E
A25: 20 | D25: acst_nm | E25: #MA.BP_NM | G25: AR customer name | H25: 売掛先名 | J25: E | M25: E
A26: 20 | D26: ar_dpt_typ | E26: #MA.AR_DPT_TYP | G26: AR dept. type | H26: 債権部門区分 | J26: E | K26: MAC_AR_DPT_TYP | M26: E
A27: 20 | D27: ar_dpt_typ_nm | E27: =E26&"_NM" -> #MA.AR_DPT_TYP_NM | G27: AR dept. type name | H27: 債権部門区分名 | J27: E
A28: 20 | D28: ar_dpt_cd | E28: #MA.DPT_CD | G28: AR dept. cd. | H28: 債権部門ＣＤ | J28: E | M28: E
A29: 20 | D29: ar_dpt_nm | E29: #MA.DPT_NM | G29: AR dept. name | H29: 債権部門名 | J29: E | M29: E
A30: 20 | D30: cst_cntct_dpt | E30: #MA.CNTCT_DPT | G30: Customer dept. | H30: 得意先部署 | J30: E | M30: E
A31: 20 | D31: cst_cntct_psn | E31: #MA.CNTCT_PSN | G31: Customer PIC | H31: 得意先担当者 | J31: E | M31: E
A32: 20 | D32: cst_cntct_psn_title | E32: #MA.BP_PSN_TITLE | G32: Form of address for Customer PIC | H32: 得意先担当者敬称 | J32: E | M32: E
A33: 20 | D33: cst_sundry_flg | E33: #MA.FLG | G33: Miscellaneous customer | H33: 得意先諸口 | J33: E | M33: E
A34: 20 | D34: sls_upri_req_typ | E34: #MA.SLS_UPRI_REQ_TYP | G34: Sales unit price acquisition type | H34: 販売単価取得区分 | J34: E | K34: MAC_SLS_UPRI_REQ_TYP | M34: E
A35: 20 | D35: =D34&"_nm" -> sls_upri_req_typ_nm | E35: =E34&"_NM" -> #MA.SLS_UPRI_REQ_TYP_NM | G35: Sales unit price acquisition type name | H35: 販売単価取得区分名 | J35: E
A36: 20 | D36: sls_upri_cng_flg | E36: #MA.FLG | G36: Allow sales unit price change | H36: 販売単価変更許可 | J36: E | M36: E
A37: 20 | D37: sls_upri_rnd_typ | E37: #MA.RND_TYP | G37: Sales unit price rounding type | H37: 販売単価端数処理区分 | J37: E | K37: MAC_RND_TYP | M37: E
A38: 20 | D38: =D37&"_nm" -> sls_upri_rnd_typ_nm | E38: =E37&"_NM" -> #MA.RND_TYP_NM | G38: Sales unit rounding type name | H38: 販売単価端数処理区分名 | J38: E
A39: 20 | D39: sls_amt_rnd_typ | E39: #MA.RND_TYP | G39: Rounding type (Sales amount) | H39: 売上金額端数処理区分 | J39: E | K39: MAC_RND_TYP | M39: E
A40: 20 | D40: =D39&"_nm" -> sls_amt_rnd_typ_nm | E40: =E39&"_NM" -> #MA.RND_TYP_NM | G40: Rounding type name (Sales amount) | H40: 売上金額端数処理区分名 | J40: E
A41: 20 | D41: sls_tax_calc_typ | E41: #MA.TAX_CALC_TYP | G41: Sales tax calculation type | H41: 売上税計算区分 | J41: E | K41: MAC_TAX_CALC_TYP | M41: E
...

Sheet Upd01
A1: * | B1: * | D1: L | E1: 1
A2: * | D2: オペレーション実装仕様書 Operation Specification Implementation Sheet | E2: ModuleID : | F2: =IF(LogicCommon!C2="","",LogicCommon!C2) -> MA | G2: LogicID : | H2: =IF(LogicCommon!E2="","",LogicCommon!E2) -> MABCL0540 | I2: Ope.ID : | J2: Upd01 | K2: Pj.ID : | L2: =IF(LogicCommon!G2="","",LogicCommon!G2) -> MC | M2: Ope.Body : | N2: "mcframe.serverMAUD.MAUDL6010.MAUDL_RLUpdater"
A3: * | D3: =IF(LogicCommon!A3="","",LogicCommon!A3) | E3: SubModuleID : | F3: =IF(LogicCommon!C3="","",LogicCommon!C3) -> MABC | G3: LogicClass : | H3: =IF(LogicCommon!E3="","",LogicCommon!E3) -> MABCL_CstReg | I3: Ope.Method : | J3: @ | K3: SuperClassPj.ID : | L3: =IF(LogicCommon!G3="","",LogicCommon!G3) | M3: ReportID : | O3: Gene.Type : | P3: ALL
A4: * | E4: Version : | F4: 000000 | G4: LogicName : | H4: =IF(LogicCommon!E4="","",LogicCommon!E4) -> 得意先登録 | I4: Ope.Name : | J4: 登録 | K4: SuperLogicID : | L4: =IF(LogicCommon!G4="","",LogicCommon!G4) -> MA.MAUDL5010
A5: * | E5: ACType :
A6: * | D6: 概要 : | E6: 得意先関連マスタの登録を行います。 | L6: ID | N6: ID | P6: ID | R6: ID | T6: ID | V6: ID | X6: ID | Z6: ID | AB6: ID | AD6: ID | AF6: ID | AH6: ID | AJ6: ID | AL6: ID | AN6: ID | AP6: ID
A7: # | I7: U | K7: o | L7: CALL_OPE01.chk01 | M7: o | N7: CALL_OPE01.upd01 | O7: o | P7: CALL_OPE02.chk02 | Q7: o | R7: CALL_OPE02.upd02 | S7: o | T7: CALL_OPE03.chk03 | U7: o | V7: CALL_OPE03.upd03 | W7: o | X7: CALL_OPE04.chk04 | Y7: o | Z7: CALL_OPE04.upd04 | AA7: o | AB7: CALL_OPE05.chk05 | AC7: o | AD7: CALL_OPE05.upd05 | AE7: o | AF7: CALL_OPE06.chk06 | AG7: o | AH7: CALL_OPE06.upd06 | AI7: o | AJ7: CALL_OPE07.chk07 | AK7: o | AL7: CALL_OPE07.upd07 | AM7: o | AN7: CALL_OPE08.chk08 | AO7: o | AP7: CALL_OPE08.upd08
A8: # | D8: ブロック名 Block Name | E8: 型 Type | G8: super/share | H8: 対象ブロック名 Target Block Name | K8: TargetName | L8: OPE.MA.MABCL0540.BpCst_UpdChk01 | M8: TargetName | N8: OPE.MA.MABCL0540.BpCst_Upd01 | O8: TargetName | P8: OPE.MA.MABSL0650.CstUsr_UpdChk01 | Q8: TargetName | R8: OPE.MA.MABSL0650.CstUsr_Upd01 | S8: TargetName | T8: OPE.MA.MABSL0230.CstSlsUpriRank_UpdChk01 | U8: TargetName | V8: OPE.MA.MABSL0230.CstSlsUpriRank_Upd01 | W8: TargetName | X8: OPE.MA.MABSL0660.CstDlv_UpdChk01 | Y8: TargetName | Z8: OPE.MA.MABSL0660.CstDlv_Upd01 | AA8: TargetName | AB8: OPE.MA.MABSL0480.ShipValidCtl_UpdChk01 | AC8: TargetName | AD8: OPE.MA.MABSL0480.ShipValidCtl_Upd01 | AE8: TargetName | AF8: OPE.MA.MABSL0520.SloAllocGd_UpdChk01 | AG8: TargetName | AH8: OPE.MA.MABSL0520.SloAllocGd_Upd01 | AI8: TargetName | AJ8: OPE.MA.MABSL1230.EdiIfCtl_UpdChk01 | AK8: TargetName | AL8: OPE.MA.MABSL1230.EdiIfCtl_Upd01 | AM8: TargetName | AN8: OPE.MA.MABSL0640.BpItm_UpdChk01 | AO8: TargetName | AP8: OPE.MA.MABSL0640.BpItm_Upd01 | AS8: ブロック備考 Block Remarks
A9: # | D9: 項目名 Field Name | E9: 型 Type | F9: 桁 Digits | G9: フルネーム Full Name | H9: 日本語名 Japanese Name | I9: 上り項目 Request Message Field | J9: 下り項目 Response Message Field | AQ9: 条件および編集方法 Conditions and Editing Methods | AS9: 項目備考 Field Remarks
A10: # | K10: 上り項目 Request Message Field | L10: 下り項目 Response Message Field | M10: 上り項目 Request Message Field | N10: 下り項目 Response Message Field | O10: 上り項目 Request Message Field | P10: 下り項目 Response Message Field | Q10: 上り項目 Request Message Field | R10: 下り項目 Response Message Field | S10: 上り項目 Request Message Field | T10: 下り項目 Response Message Field | U10: 上り項目 Request Message Field | V10: 下り項目 Response Message Field | W10: 上り項目 Request Message Field | X10: 下り項目 Response Message Field | Y10: 上り項目 Request Message Field | Z10: 下り項目 Response Message Field | AA10: 上り項目 Request Message Field | AB10: 下り項目 Response Message Field | AC10: 上り項目 Request Message Field | AD10: 下り項目 Response Message Field | AE10: 上り項目 Request Message Field | AF10: 下り項目 Response Message Field | AG10: 上り項目 Request Message Field | AH10: 下り項目 Response Message Field | AI10: 上り項目 Request Message Field | AJ10: 下り項目 Response Message Field | AK10: 上り項目 Request Message Field | AL10: 下り項目 Response Message Field | AM10: 上り項目 Request Message Field | AN10: 下り項目 Response Message Field | AO10: 上り項目 Request Message Field | AP10: 下り項目 Response Message Field
A11: 10 | B11: * | D11: Upd01_Dtl1 | E11: L | G11: $share$ | H11: MA.MABCL0540.BpCst_Upd01.BpCst_Upd01_Dtl | K11: BpCst_UpdChk01_Dtl | M11: BpCst_Upd01_Dtl
A12: 10 | D12: bp_cd | E12: #MA.BP_CD | G12: BP cd. | H12: 取引先ＣＤ | I12: E | K12: E | M12: E
A13: 10 | D13: acst_cd | E13: #MA.BP_CD | G13: AR customer cd. | H13: 売掛先ＣＤ | I13: E | K13: E | M13: E
A14: 10 | D14: ar_dpt_typ | E14: #MA.AR_DPT_TYP | G14: AR dept. type | H14: 債権部門区分 | I14: E | K14: E | M14: E
A15: 10 | D15: ar_dpt_cd | E15: #MA.DPT_CD | G15: AR dept. cd. | H15: 債権部門ＣＤ | I15: E | K15: E | M15: E
A16: 10 | D16: check_ar_dpt_cd | E16: #MA.DPT_CD | G16: AR dept. cd. | H16: 債権部門ＣＤ | I16: E | K16: E
A17: 10 | D17: cst_cntct_dpt | E17: #MA.CNTCT_DPT | G17: Customer dept. | H17: 得意先部署 | I17: E | K17: E | M17: E
A18: 10 | D18: cst_cntct_psn | E18: #MA.CNTCT_PSN | G18: Customer PIC | H18: 得意先担当者 | I18: E | K18: E | M18: E
A19: 10 | D19: cst_cntct_psn_title | E19: #MA.BP_PSN_TITLE | G19: Form of address for Customer PIC | H19: 得意先担当者敬称 | I19: E | K19: E | M19: E
A20: 10 | D20: cst_sundry_flg | E20: #MA.FLG | G20: Miscellaneous customer | H20: 得意先諸口 | I20: E | K20: E | M20: E
A21: 10 | D21: sls_upri_req_typ | E21: #MA.SLS_UPRI_REQ_TYP | G21: Sales unit price acquisition type | H21: 販売単価取得区分 | I21: E | K21: E | M21: E
A22: 10 | D22: sls_upri_cng_flg | E22: #MA.FLG | G22: Allow sales unit price change | H22: 販売単価変更許可 | I22: E | K22: E | M22: E
A23: 10 | D23: sls_upri_rnd_typ | E23: #MA.RND_TYP | G23: Sales unit price rounding type | H23: 販売単価端数処理区分 | I23: E | K23: E | M23: E
A24: 10 | D24: sls_amt_rnd_typ | E24: #MA.RND_TYP | G24: Rounding type (Sales amount) | H24: 売上金額端数処理区分 | I24: E | K24: E | M24: E
A25: 10 | D25: sls_tax_calc_typ | E25: #MA.TAX_CALC_TYP | G25: Sales tax calculation type | H25: 売上税計算区分 | I25: E | K25: E | M25: E
A26: 10 | D26: sls_tax_rnd_typ | E26: #MA.RND_TYP | G26: Sales tax rounding type | H26: 売上税額端数処理区分 | I26: E | K26: E | M26: E
A27: 10 | D27: sls_basis_typ | E27: #MA.SLS_BASIS_TYP | G27: Revenue recording type | H27: 売上計上区分 | I27: E | K27: E | M27: E
A28: 10 | D28: ship_schd_split_typ | E28: #MA.SHIP_SCHD_SPLIT_TYP | G28: Shipping schedule split type | H28: 出荷予定分割区分 | I28: E | K28: E | M28: E
... A46: 10 | D46: sls_anly_cd3 | E46: #MA.SLS_ANLY_CD | G46: Sales analysis cd. 3 | H46: 販売分析ＣＤ３ | I46: E | K46: E | M46: E
A47: 10 | D47: bcst_flg | E47: #MA.FLG | G47: Billing customer | H47: 請求先 | I47: E | K47: E
A48: 10 | D48: bcst_cd | E48: #MA.BP_CD | G48: Billing customer cd. | H48: 請求先ＣＤ | I48: E | K48: E | M48: E
A49: 10 | D49: cst_prnt_typ | E49: #MA.PRNT_TYP | G49: Report issue type (Customer) | H49: 帳票発行区分（得意先） | I49: E | K49: E | M49: E
A50: 10 | D50: upd_cntr | E50: #MA.UPD_CNT | G50: Update counter | H50: 更新カウンタ | I50: E | K50: E | M50: E
A51: 10 | D51: not_lg_mix_flg | E51: #MA.FLG | G51: Prohibit mixed distribution group flg. | H51: 物流グループ混在不可ＦＬＧ | I51: E | K51: E | M51: E
A52: 10 | D52: not_lot_mix_flg | E52: #MA.FLG | G52: Prohibit mixed lots flg. | H52: ロット混在不可ＦＬＧ | I52: E | K52: E | M52: E
A53: 10 | D53: not_sublot_mix_flg | E53: #MA.FLG | G53: Prohibit mixed sublots flg. | H53: サブロット混在不可ＦＬＧ | I53: E | K53: E | M53: E
A55: 20 | B55: * | D55: Upd01_Dtl2 | E55: L | G55: $share$ | H55: MA.MABSL0650.CstUsr_Upd01.CstUsr_Upd01_Dtl | O55: CstUsr_UpdChk01_Dtl | Q55: CstUsr_Upd01_Dtl
A56: 20 | D56: cst_cd | E56: #MA.BP_CD | G56: Customer cd. | H56: 得意先ＣＤ | I56: E | O56: E | Q56: E
A57: 20 | D57: st_dt_key | E57: #MA.DT | G57: Application start date_[Before change] | H57: 適用開始日_[変更前] | I57: E | O57: E | Q57: E
A58: 20 | D58: st_dt | E58: #MA.DT | G58: Application start date | H58: 適用開始日 | I58: E | O58: E | Q58: E
...

Sheet 来歴
A1: 変更来歴
A3: Rev. | H3: 修正番号 | O3: 変更内容 | AQ3: 変更箇所
A4: 1 | O4: 初版
A5: 1.1 | H5: MA7031#100 | O5: BpCst_UpdChk01_Dtlブロックに以下の項目を追加 ・not_lg_mix_flg、not_lot_mix_flg、not_sublot_mix_flg | AQ5: BpCst_UpdChk01
A6: " | H6: " | O6: BpCst_Upd01_Dtlブロックに以下の項目を追加 ・not_lg_mix_flg、not_lot_mix_flg、not_sublot_mix_flg | AQ6: BpCst_Upd01
A7: " | H7: " | O7: Srch01_Rslt1ブロックに以下の項目を追加 ・not_lg_mix_flg、not_lot_mix_flg、not_sublot_mix_flg | AQ7: Srch01
A8: " | H8: " | O8: Upd01_Dtl1ブロックに以下の項目を追加 ・not_lg_mix_flg、not_lot_mix_flg、not_sublot_mix_flg | AQ8: Upd01
A9: 1.2 | O9: 英語の名称を追記 | AQ9: 全般
