Workbook

Sheet LogicCommon
A2: ロジック共通定義 | B2: ModuleID : | C2: MA | D2: LogicID : | E2: MABCL0570 | F2: Pj.ID : | G2: MC
B3: SubModuleID : | C3: MABC | D3: LogicClass : | E3: MABCL_SpplReg | F3: SuperClassPj.ID :
D4: LogicName : | E4: 発注先登録 | F4: SuperLogicID : | G4: MA.MAUDL5010
A5: 概要 :
A6: 詳細 :

Sheet Bp_UpdChk01
A1: * | B1: * | D1: L | E1: 1
A2: * | D2: オペレーション実装仕様書 Operation Specification Implementation Sheet | E2: ModuleID : | F2: =IF(LogicCommon!C2="","",LogicCommon!C2) -> MA | G2: LogicID : | H2: =IF(LogicCommon!E2="","",LogicCommon!E2) -> MABCL0570 | I2: Ope.ID : | J2: Bp_UpdChk01 | K2: Pj.ID : | L2: =IF(LogicCommon!G2="","",LogicCommon!G2) -> MC | M2: Ope.Body : | N2: =L4 & ".Checker" -> MA.MAUDL5010.Checker
A3: * | D3: =IF(LogicCommon!A3="","",LogicCommon!A3) | E3: SubModuleID : | F3: =IF(LogicCommon!C3="","",LogicCommon!C3) -> MABC | G3: LogicClass : | H3: =IF(LogicCommon!E3="","",LogicCommon!E3) -> MABCL_SpplReg | I3: Ope.Method : | J3: @ | K3: SuperClassPj.ID : | L3: =IF(LogicCommon!G3="","",LogicCommon!G3) | M3: ReportID : | O3: Gene.Type : | P3: ALL
A4: * | E4: Version : | F4: 000000 | G4: LogicName : | H4: =IF(LogicCommon!E4="","",LogicCommon!E4) -> 発注先登録 | I4: Ope.Name : | J4: 登録前チェック | K4: SuperLogicID : | L4: =IF(LogicCommon!G4="","",LogicCommon!G4) -> MA.MAUDL5010
A5: * | E5: ACType :
A6: * | D6: 概要 : | E6: 取引先マスタを登録する前のチェックを行う | T6: ID
A7: # | I7: U | K7: K | L7: K | M7: K | N7: K | O7: K | P7: K | Q7: K | R7: K | S7: o
A8: # | D8: ブロック名 Block Name | E8: 型 Type | G8: super/share | H8: 対象ブロック名 Target Block Name | K8: REQUIRED | L8: CONST | M8: LIST_LOGIC | N8: LIST_OUT | O8: LIST_OUT_BASE | P8: LIST_IN | Q8: LIST_IN_BASE | R8: SMALL_LARGE | S8: TargetName | W8: ブロック備考 Block Remarks
A9: # | D9: 項目名 Field Name | E9: 型 Type | F9: 桁 Digits | G9: フルネーム Full Name | H9: 日本語名 Japanese Name | I9: 上り項目 Request Message Field | J9: 下り項目 Response Message Field | U9: 条件および編集方法 Conditions and Editing Methods | W9: 項目備考 Field Remarks
A10: # | S10: 上り項目 Request Message Field | T10: 下り項目 Response Message Field
A11: 10 | B11: * | D11: Bp_UpdChk01_Dtl | E11: L
A12: 10 | D12: bp_cd | E12: #MA.BP_CD | G12: BP cd. | H12: 取引先ＣＤ | I12: E | K12: E | M12: MA.MAUAL0010.Bp | N12: cntry_cd | O12: cntry_cd | P12: MAC_BP_IS_SRCH_TYP.SPPL | Q12: bp_is_srch_typ
A13: 10 | D13: asppl_cd | E13: #MA.BP_CD | G13: AP supplier cd. | H13: 買掛先ＣＤ | I13: E | K13: E | M13: MA.MAUAL0010.Bp | P13: MAC_BP_IS_SRCH_TYP.ASPPL | Q13: bp_is_srch_typ
A14: 10 | D14: cntry_cd | E14: #MA.CNTRY_CD | G14: Country cd. | H14: 国ＣＤ | I14: -
A15: 10 | D15: sppl_cntct_dpt | E15: #MA.CNTCT_DPT | G15: Supplier dept. | H15: 発注先部署 | I15: E
A16: 10 | D16: sppl_cntct_psn | E16: #MA.CNTCT_PSN | G16: Supplier PIC | H16: 発注先担当者 | I16: E
A17: 10 | D17: sppl_cntct_psn_title | E17: #MA.BP_PSN_TITLE | G17: Supplier PIC form of address | H17: 発注先担当者敬称 | I17: E
A18: 10 | D18: subcon_flg | E18: #MA.FLG | G18: For subcontract | H18: 下請対象 | I18: E
A19: 10 | D19: onr_prsppl_flg | E19: #MA.FLG | G19: Chargeable supplier | H19: 有償支給先 | I19: E
A20: 10 | D20: repurc_obli_flg | E20: #MA.FLG | G20: Repurchase obligation | H20: 買戻義務 | I20: E
A21: 10 | D21: vmi_purc_dpt_cd | E21: #MA.DPT_CD | G21: VMI purchasing dept. cd. | H21: ＶＭＩ購買部門ＣＤ | I21: E
A22: 10 | D22: check_vmi_purc_dpt_cd | E22: #MA.DPT_CD | G22: VMI purchasing dept. cd. | H22: ＶＭＩ購買部門ＣＤ | I22: E | M22: MA.MAUAL0010.Dpt | P22: MAC_DPT_IS_SRCH_TYP.PURC;true | Q22: dpt_is_srch_typ;mode_today_flg
A23: 10 | D23: purc_upri_req_typ | E23: #MA.PURC_UPRI_REQ_TYP | G23: Purchase unit price acquisition type | H23: 購買単価取得区分 | I23: E | L23: MAC_PURC_UPRI_REQ_TYP
A24: 10 | D24: purc_upri_cng_flg | E24: #MA.FLG | G24: Allow purchasing unit price change | H24: 購買単価変更許可 | I24: E
A25: 10 | D25: prms_recv_flg | E25: #MA.FLG | G25: Check order promising | H25: 納期回答確認 | I25: E
A26: 10 | D26: purc_amt_rnd_typ | E26: #MA.RND_TYP | G26: Rounding type (Purchase amount) | H26: 仕入金額端数処理区分 | I26: E | K26: E | L26: MAC_RND_TYP
A27: 10 | D27: purc_tax_calc_typ | E27: #MA.TAX_CALC_TYP | G27: Purchase tax calculation type | H27: 仕入税計算区分 | I27: E | K27: E | L27: MAC_TAX_CALC_TYP
A28: 10 | D28: purc_tax_rnd_typ | E28: #MA.RND_TYP | G28: Rounding type (Purchase tax) | H28: 仕入税額端数処理区分 | I28: E | K28: E | L28: MAC_RND_TYP
A29: 10 | D29: purc_tax_cd | E29: #MA.TAX_CD | G29: Purchase tax cd. | H29: 仕入税ＣＤ | I29: E | M29: MA.MAUAL0010.PurcTax
A30: 10 | D30: purc_tax_cd_prio_flg | E30: #MA.FLG | G30: Purchase tax priority | H30: 仕入税優先 | I30: E
A31: 10 | D31: sppl_cal_cd | E31: #MA.CAL_CD | G31: Supplier calendar cd. | H31: 発注先カレンダＣＤ | I31: E | M31: MA.MAUAL0010.CalBase
A32: 10 | D32: po_print_cd | E32: #MA.PO_PRINT_CD | G32: Display PO sheet cd. | H32: 注文書表示ＣＤ | I32: E | M32: MA.MAUAL0010.PoPrint
A33: 10 | D33: sppl_ship_form_cd | E33: #MA.SLIP_FORM_CD | G33: Supplier delivery note cd. | H33: 発注先納品書ＣＤ | I33: E | M33: MA.MAUAL0010.SlipForm
A34: 10 | D34: po_dlv_slip_flg | E34: #MA.FLG | G34: Delivery note at PO | H34: 発注時納品書 | I34: E
A35: 10 | D35: dlv_inst_dlv_slip_flg | E35: #MA.FLG | G35: Delivery note at delivery order | H35: 納入指示時納品書 | I35: E
A36: 10 | D36: prms_rcpt_dlv_slip_flg | E36: #MA.FLG | G36: Delivery note at order promising result receipt | H36: 納期回答受領時納品書 | I36: E
A37: 10 | D37: prov_rcv_typ | E37: #MA.PROV_RCV_TYP | G37: In-transit supply management type | H37: 支給積送管理区分 | I37: E | K37: E | L37: MAC_PROV_RCV_TYP
A38: 10 | D38: purc_slip_each_lot_typ | E38: #MA.SLIP_EACH_LOT_TYP | G38: Purchase lot details split type | H38: 仕入ロット明細分割区分 | I38: E | K38: E | L38: MAC_SLIP_EACH_LOT_TYP
A39: 10 | D39: sppl_tterm_cd1 | E39: #MA.TTERM_CD | G39: Supplier transaction terms cd. 1 | H39: 発注先取引条件ＣＤ１ | I39: E | M39: MA.MAUAL0010.Tterm1
A40: 10 | D40: sppl_tterm_cd2 | E40: #MA.TTERM_CD | G40: Supplier transaction terms cd. 2 | H40: 発注先取引条件ＣＤ２ | I40: E | M40: MA.MAUAL0010.Tterm2
...

Sheet Bp_Upd01
A1: * | B1: * | D1: L | E1: 1
A2: * | D2: オペレーション実装仕様書 Operation Specification Implementation Sheet | E2: ModuleID : | F2: =IF(LogicCommon!C2="","",LogicCommon!C2) -> MA | G2: LogicID : | H2: =IF(LogicCommon!E2="","",LogicCommon!E2) -> MABCL0570 | I2: Ope.ID : | J2: Bp_Upd01 | K2: Pj.ID : | L2: =IF(LogicCommon!G2="","",LogicCommon!G2) -> MC | M2: Ope.Body : | N2: "mcframe.serverMAUD.MAUDL6010.MAUDL_RLUpdater"
A3: * | D3: =IF(LogicCommon!A3="","",LogicCommon!A3) | E3: SubModuleID : | F3: =IF(LogicCommon!C3="","",LogicCommon!C3) -> MABC | G3: LogicClass : | H3: =IF(LogicCommon!E3="","",LogicCommon!E3) -> MABCL_SpplReg | I3: Ope.Method : | J3: @ | K3: SuperClassPj.ID : | L3: =IF(LogicCommon!G3="","",LogicCommon!G3) | M3: ReportID : | O3: Gene.Type : | P3: ALL
A4: * | E4: Version : | F4: 000000 | G4: LogicName : | H4: =IF(LogicCommon!E4="","",LogicCommon!E4) -> 発注先登録 | I4: Ope.Name : | J4: 登録処理 | K4: SuperLogicID : | L4: =IF(LogicCommon!G4="","",LogicCommon!G4) -> MA.MAUDL5010
A5: * | E5: ACType :
A6: * | D6: 概要 : | E6: 取引先マスタを登録する | L6: ID | N6: ID | P6: ID | R6: ID
A7: # | I7: U | K7: o | L7: UPDATE.updMaster | M7: o | N7: MAIN.chkMaster | O7: o | Q7: o
A8: # | D8: ブロック名 Block Name | E8: 型 Type | G8: super/share | H8: 対象ブロック名 Target Block Name | K8: TargetName | L8: DBC.MA.MAM_BP | M8: TargetName | N8: DBC.MA.MAM_BP | O8: TargetName | Q8: TargetName | U8: ブロック備考 Block Remarks
A9: # | D9: 項目名 Field Name | E9: 型 Type | F9: 桁 Digits | G9: フルネーム Full Name | H9: 日本語名 Japanese Name | I9: 上り項目 Request Message Field | J9: 下り項目 Response Message Field | S9: 条件および編集方法 Conditions and Editing Methods | U9: 項目備考 Field Remarks
A10: # | K10: 上り項目 Request Message Field | L10: 下り項目 Response Message Field | M10: 上り項目 Request Message Field | N10: 下り項目 Response Message Field | O10: 上り項目 Request Message Field | P10: 下り項目 Response Message Field | Q10: 上り項目 Request Message Field | R10: 下り項目 Response Message Field
A11: 10 | B11: * | D11: Bp_Upd01_Dtl | E11: L | G11: $share$ | H11: MA.MABCL0570.Bp_UpdChk01.Bp_UpdChk01_Dtl | K11: L | M11: L
A12: 10 | D12: bp_cd | E12: #MA.BP_CD | G12: BP cd. | H12: 取引先ＣＤ | I12: E | K12: E | M12: E
A13: 10 | D13: asppl_cd | E13: #MA.BP_CD | G13: AP supplier cd. | H13: 買掛先ＣＤ | I13: E | K13: E
A14: 10 | D14: vmi_purc_dpt_cd | E14: #MA.DPT_CD | G14: VMI purchasing dept. cd. | H14: ＶＭＩ購買部門ＣＤ | I14: E | K14: E
A15: 10 | D15: sppl_cntct_dpt | E15: #MA.CNTCT_DPT | G15: Supplier dept. | H15: 発注先部署 | I15: E | K15: E
A16: 10 | D16: sppl_cntct_psn | E16: #MA.CNTCT_PSN | G16: Supplier PIC | H16: 発注先担当者 | I16: E | K16: E
A17: 10 | D17: sppl_cntct_psn_title | E17: #MA.BP_PSN_TITLE | G17: Supplier PIC form of address | H17: 発注先担当者敬称 | I17: E | K17: E
A18: 10 | D18: subcon_flg | E18: #MA.FLG | G18: For subcontract | H18: 下請対象 | I18: E | K18: E
A19: 10 | D19: purc_upri_req_typ | E19: #MA.PURC_UPRI_REQ_TYP | G19: Purchase unit price acquisition type | H19: 購買単価取得区分 | I19: E | K19: E
A20: 10 | D20: purc_upri_cng_flg | E20: #MA.FLG | G20: Allow purchasing unit price change | H20: 購買単価変更許可 | I20: E | K20: E
A21: 10 | D21: purc_amt_rnd_typ | E21: #MA.RND_TYP | G21: Rounding type (Purchase amount) | H21: 仕入金額端数処理区分 | I21: E | K21: E
A22: 10 | D22: purc_tax_calc_typ | E22: #MA.TAX_CALC_TYP | G22: Purchase tax calculation type | H22: 仕入税計算区分 | I22: E | K22: E
A23: 10 | D23: purc_tax_rnd_typ | E23: #MA.RND_TYP | G23: Rounding type (Purchase tax) | H23: 仕入税額端数処理区分 | I23: E | K23: E
A24: 10 | D24: pay_crryovr_times | E24: #MA.CRRYOVR_TIMES | G24: Payment carry-over count | H24: 支払繰越回数 | I24: E | K24: E
... A57: 10 | D57: upd_cntr | E57: #MA.UPD_CNT | G57: Update counter | H57: 更新カウンタ | I57: E | K57: E
D58: 詳細 :

Sheet Srch01
A1: * | B1: * | D1: L | E1: 1
A2: * | D2: オペレーション実装仕様書 Operation Specification Implementation Sheet | E2: ModuleID : | F2: =IF(LogicCommon!C2="","",LogicCommon!C2) -> MA | G2: LogicID : | H2: =IF(LogicCommon!E2="","",LogicCommon!E2) -> MABCL0570 | I2: Ope.ID : | J2: Srch01 | K2: Pj.ID : | L2: =IF(LogicCommon!G2="","",LogicCommon!G2) -> MC | M2: Ope.Body : | N2: "mcframe.serverMAUD.MAUDL6010.MAUDL_RLSearcher"
A3: * | D3: =IF(LogicCommon!A3="","",LogicCommon!A3) | E3: SubModuleID : | F3: =IF(LogicCommon!C3="","",LogicCommon!C3) -> MABC | G3: LogicClass : | H3: =IF(LogicCommon!E3="","",LogicCommon!E3) -> MABCL_SpplReg | I3: Ope.Method : | J3: @ | K3: SuperClassPj.ID : | L3: =IF(LogicCommon!G3="","",LogicCommon!G3) | M3: ReportID : | O3: Gene.Type : | P3: ALL
A4: * | E4: Version : | F4: 000000 | G4: LogicName : | H4: =IF(LogicCommon!E4="","",LogicCommon!E4) -> 発注先登録 | I4: Ope.Name : | J4: 検索 | K4: SuperLogicID : | L4: =IF(LogicCommon!G4="","",LogicCommon!G4) -> MA.MAUDL5010
A5: * | E5: ACType :
A6: * | D6: 概要 : | E6: 検索処理を行う | M6: ID | O6: ID | Q6: ID | S6: ID | U6: ID | W6: ID | Y6: ID
A7: # | I7: U | K7: K | L7: o | M7: SELECT.c0 | N7: o | O7: SELECT_SUB1.c1 | P7: o | Q7: SELECT_SUB2.c2 | R7: o | S7: SELECT_SUB3.c3 | T7: o | U7: SELECT_SUB4.c4 | V7: o | W7: SELECT_SUB5.c5 | X7: o | Y7: SELECT_SUB6.c6
A8: # | D8: ブロック名 Block Name | E8: 型 Type | G8: super/share | H8: 対象ブロック名 Target Block Name | K8: CONST | L8: TargetName | M8: DBC.MA.MAM_BP | N8: TargetName | O8: DBC.MA.MAM_ITM_DTL_ | P8: TargetName | Q8: DBC.MA.MAM_ITM_INSP | R8: TargetName | S8: DBC.MA.MAM_PURC_DDLV_LT | T8: TargetName | U8: DBC.MA.MAM_EDI_IF_CTL | V8: TargetName | W8: DBC.MA.MAM_BP_ITM | X8: TargetName | Y8: DBC.MA.MAM_SPPL_USR | AB8: ブロック備考 Block Remarks
A9: # | D9: 項目名 Field Name | E9: 型 Type | F9: 桁 Digits | G9: フルネーム Full Name | H9: 日本語名 Japanese Name | I9: 上り項目 Request Message Field | J9: 下り項目 Response Message Field | Z9: 条件および編集方法 Conditions and Editing Methods | AB9: 項目備考 Field Remarks
A10: # | L10: 上り項目 Request Message Field | M10: 下り項目 Response Message Field | N10: 上り項目 Request Message Field | O10: 下り項目 Response Message Field | P10: 上り項目 Request Message Field | Q10: 下り項目 Response Message Field | R10: 上り項目 Request Message Field | S10: 下り項目 Response Message Field | T10: 上り項目 Request Message Field | U10: 下り項目 Response Message Field | V10: 上り項目 Request Message Field | W10: 下り項目 Response Message Field | X10: 上り項目 Request Message Field | Y10: 下り項目 Response Message Field
A11: 10 | B11: * | D11: Srch01_Cnd | E11: R
A12: 10 | D12: st_dt_fr | E12: #MA.DT | G12: Application start date FROM | H12: 適用開始日ＦＲＯＭ | I12: E
A13: 10 | D13: st_dt_to | E13: #MA.DT | G13: Application start date TO | H13: 適用開始日ＴＯ | I13: E
A14: 10 | D14: end_dt_fr | E14: #MA.DT | G14: Application end date FROM | H14: 適用終了日ＦＲＯＭ | I14: E
A15: 10 | D15: end_dt_to | E15: #MA.DT | G15: Application end date TO | H15: 適用終了日ＴＯ | I15: E
A16: 10 | D16: bp_cd | E16: #MA.BP_CD | G16: BP cd. | H16: 取引先ＣＤ | I16: E
A17: 10 | D17: bp_nm | E17: #MA.BP_NM | G17: BP name | H17: 取引先名 | I17: E
A18: 10 | D18: off_del_flg | E18: #MA.FLG | G18: Logical delete. Off | H18: 論理削除.オフ | I18: E
A19: 10 | D19: on_del_flg | E19: #MA.FLG | G19: Logical delete. On | H19: 論理削除.オン | I19: E
A21: 20 | B21: * | D21: Srch01_Rslt1 | E21: L | M21: L
A22: 20 | D22: bp_cd | E22: #MA.BP_CD | G22: BP cd. | H22: 取引先ＣＤ | J22: E | M22: E
A23: 20 | D23: asppl_flg | E23: #MA.FLG | G23: AP supplier | H23: 買掛先 | J23: E | M23: E
A24: 20 | D24: cntry_cd | E24: #MA.CNTRY_CD | G24: Country cd. | H24: 国ＣＤ | J24: E | M24: E
A25: 20 | D25: asppl_cd | E25: #MA.BP_CD | G25: AP supplier cd. | H25: 買掛先ＣＤ | J25: E | M25: E
A26: 20 | D26: asppl_nm | E26: #MA.BP_NM | G26: AP supplier name | H26: 買掛先名 | J26: E | M26: E
A27: 20 | D27: vmi_purc_dpt_cd | E27: #MA.DPT_CD | G27: VMI purchasing dept. cd. | H27: ＶＭＩ購買部門ＣＤ | J27: E | M27: E
A28: 20 | D28: vmi_purc_dpt_nm | E28: #MA.DPT_NM | G28: VMI purchasing dept. name | H28: ＶＭＩ購買部門名 | J28: E | M28: E
A29: 20 | D29: sppl_cntct_dpt | E29: #MA.CNTCT_DPT | G29: Supplier dept. | H29: 発注先部署 | J29: E | M29: E
A30: 20 | D30: sppl_cntct_psn | E30: #MA.CNTCT_PSN | G30: Supplier PIC | H30: 発注先担当者 | J30: E | M30: E
A31: 20 | D31: sppl_cntct_psn_title | E31: #MA.BP_PSN_TITLE | G31: Supplier PIC form of address | H31: 発注先担当者敬称 | J31: E | M31: E
A32: 20 | D32: subcon_flg | E32: #MA.FLG | G32: For subcontract | H32: 下請対象 | J32: E | M32: E
A33: 20 | D33: purc_upri_req_typ | E33: #MA.PURC_UPRI_REQ_TYP | G33: Purchase unit price acquisition type | H33: 購買単価取得区分 | J33: E | K33: MAC_PURC_UPRI_REQ_TYP | M33: E
A34: 20 | D34: =D33&"_nm" -> purc_upri_req_typ_nm | E34: =E33&"_NM" -> #MA.PURC_UPRI_REQ_TYP_NM | G34: Purchase unit price acquisition type name | H34: 購買単価取得区分名 | J34: E
A35: 20 | D35: purc_upri_cng_flg | E35: #MA.FLG | G35: Allow purchasing unit price change | H35: 購買単価変更許可 | J35: E | M35: E
A36: 20 | D36: purc_amt_rnd_typ | E36: #MA.RND_TYP | G36: Rounding type (Purchase amount) | H36: 仕入金額端数処理区分 | J36: E | K36: MAC_RND_TYP | M36: E
A37: 20 | D37: =D36&"_nm" -> purc_amt_rnd_typ_nm | E37: =E36&"_NM" -> #MA.RND_TYP_NM | G37: Rounding type name (Purchase amount) | H37: 仕入金額端数処理区分名 | J37: E
A38: 20 | D38: purc_tax_calc_typ | E38: #MA.TAX_CALC_TYP | G38: Purchase tax calculation type | H38: 仕入税計算区分 | J38: E | K38: MAC_TAX_CALC_TYP | M38: E
A39: 20 | D39: =D38&"_nm" -> purc_tax_calc_typ_nm | E39: =E38&"_NM" -> #MA.TAX_CALC_TYP_NM | G39: Purchase tax calculation type name | H39: 仕入税計算区分名 | J39: E
A40: 20 | D40: purc_tax_rnd_typ | E40: #MA.RND_TYP | G40: Rounding type (Purchase tax) | H40: 仕入税額端数処理区分 | J40: E | K40: MAC_RND_TYP | M40: E
A41: 20 | D41: =D40&"_nm" -> purc_tax_rnd_typ_nm | E41: =E40&"_NM" -> #MA.RND_TYP_NM | G41: Purchase tax amount rounding type | H41: 仕入税額端数処理区分名 | J41: E
...

Sheet Upd01
A1: * | B1: * | D1: L | E1: 1
A2: * | D2: オペレーション実装仕様書 Operation Specification Implementation Sheet | E2: ModuleID : | F2: =IF(LogicCommon!C2="","",LogicCommon!C2) -> MA | G2: LogicID : | H2: =IF(LogicCommon!E2="","",LogicCommon!E2) -> MABCL0570 | I2: Ope.ID : | J2: Upd01 | K2: Pj.ID : | L2: =IF(LogicCommon!G2="","",LogicCommon!G2) -> MC | M2: Ope.Body : | N2: "mcframe.serverMAUD.MAUDL6010.MAUDL_RLUpdater"
A3: * | D3: =IF(LogicCommon!A3="","",LogicCommon!A3) | E3: SubModuleID : | F3: =IF(LogicCommon!C3="","",LogicCommon!C3) -> MABC | G3: LogicClass : | H3: =IF(LogicCommon!E3="","",LogicCommon!E3) -> MABCL_SpplReg | I3: Ope.Method : | J3: @ | K3: SuperClassPj.ID : | L3: =IF(LogicCommon!G3="","",LogicCommon!G3) | M3: ReportID : | O3: Gene.Type : | P3: ALL
A4: * | E4: Version : | F4: 000000 | G4: LogicName : | H4: =IF(LogicCommon!E4="","",LogicCommon!E4) -> 発注先登録 | I4: Ope.Name : | J4: 登録 | K4: SuperLogicID : | L4: =IF(LogicCommon!G4="","",LogicCommon!G4) -> MA.MAUDL5010
A5: * | E5: ACType :
A6: * | D6: 概要 : | E6: 登録処理を行う | L6: ID | N6: ID | P6: ID | R6: ID | T6: ID | V6: ID | X6: ID | Z6: ID | AB6: ID | AD6: ID | AF6: ID | AH6: ID | AJ6: ID | AL6: ID
A7: # | I7: U | K7: o | L7: CALL_OPE01.chk01 | M7: o | N7: CALL_OPE01.upd01 | O7: o | P7: CALL_OPE02.chk02 | Q7: o | R7: CALL_OPE02.upd02 | S7: o | T7: CALL_OPE03.chk03 | U7: o | V7: CALL_OPE03.upd03 | W7: o | X7: CALL_OPE04.chk04 | Y7: o | Z7: CALL_OPE04.upd04 | AA7: o | AB7: CALL_OPE05.chk05 | AC7: o | AD7: CALL_OPE05.upd05 | AE7: o | AF7: CALL_OPE06.chk06 | AG7: o | AH7: CALL_OPE06.upd06 | AI7: o | AJ7: CALL_OPE07.chk07 | AK7: o | AL7: CALL_OPE07.upd07
A8: # | D8: ブロック名 Block Name | E8: 型 Type | G8: super/share | H8: 対象ブロック名 Target Block Name | K8: TargetName | L8: OPE.MA.MABCL0570.Bp_UpdChk01 | M8: TargetName | N8: OPE.MA.MABCL0570.Bp_Upd01 | O8: TargetName | P8: OPE.MA.MABSL0010.ItmDtl_UpdChk01 | Q8: TargetName | R8: OPE.MA.MABSL0010.ItmDtl_Upd01 | S8: TargetName | T8: OPE.MA.MABSL0190.ItmInsp_UpdChk01 | U8: TargetName | V8: OPE.MA.MABSL0190.ItmInsp_Upd01 | W8: TargetName | X8: OPE.MA.MABSL0530.PurcDdlvLt_UpdChk01 | Y8: TargetName | Z8: OPE.MA.MABSL0530.PurcDdlvLt_Upd01 | AA8: TargetName | AB8: OPE.MA.MABSL1230.EdiIfCtl_UpdChk01 | AC8: TargetName | AD8: OPE.MA.MABSL1230.EdiIfCtl_Upd01 | AE8: TargetName | AF8: OPE.MA.MABSL0640.BpItm_UpdChk01 | AG8: TargetName | AH8: OPE.MA.MABSL0640.BpItm_Upd01 | AI8: TargetName | AJ8: OPE.MA.MABSL0670.SpplUsr_UpdChk01 | AK8: TargetName | AL8: OPE.MA.MABSL0670.SpplUsr_Upd01 | AO8: ブロック備考 Block Remarks
A9: # | D9: 項目名 Field Name | E9: 型 Type | F9: 桁 Digits | G9: フルネーム Full Name | H9: 日本語名 Japanese Name | I9: 上り項目 Request Message Field | J9: 下り項目 Response Message Field | AM9: 条件および編集方法 Conditions and Editing Methods | AO9: 項目備考 Field Remarks
A10: # | K10: 上り項目 Request Message Field | L10: 下り項目 Response Message Field | M10: 上り項目 Request Message Field | N10: 下り項目 Response Message Field | O10: 上り項目 Request Message Field | P10: 下り項目 Response Message Field | Q10: 上り項目 Request Message Field | R10: 下り項目 Response Message Field | S10: 上り項目 Request Message Field | T10: 下り項目 Response Message Field | U10: 上り項目 Request Message Field | V10: 下り項目 Response Message Field | W10: 上り項目 Request Message Field | X10: 下り項目 Response Message Field | Y10: 上り項目 Request Message Field | Z10: 下り項目 Response Message Field | AA10: 上り項目 Request Message Field | AB10: 下り項目 Response Message Field | AC10: 上り項目 Request Message Field | AD10: 下り項目 Response Message Field | AE10: 上り項目 Request Message Field | AF10: 下り項目 Response Message Field | AG10: 上り項目 Request Message Field | AH10: 下り項目 Response Message Field | AI10: 上り項目 Request Message Field | AJ10: 下り項目 Response Message Field | AK10: 上り項目 Request Message Field | AL10: 下り項目 Response Message Field
A11: 10 | B11: * | D11: Upd01_Dtl1 | E11: L | G11: $share$ | H11: MA.MABCL0570.Bp_Upd01.Bp_Upd01_Dtl | K11: Bp_UpdChk01_Dtl | M11: Bp_Upd01_Dtl
A12: 10 | D12: bp_cd | E12: #MA.BP_CD | G12: BP cd. | H12: 取引先ＣＤ | I12: E | K12: E | M12: E
A13: 10 | D13: asppl_cd | E13: #MA.BP_CD | G13: AP supplier cd. | H13: 買掛先ＣＤ | I13: E | K13: E | M13: E
A14: 10 | D14: vmi_purc_dpt_cd | E14: #MA.DPT_CD | G14: VMI purchasing dept. cd. | H14: ＶＭＩ購買部門ＣＤ | I14: E | K14: E | M14: E
A15: 10 | D15: check_vmi_purc_dpt_cd | E15: #MA.DPT_CD | G15: VMI purchasing dept. cd. | H15: ＶＭＩ購買部門ＣＤ | I15: E | K15: E
A16: 10 | D16: sppl_cntct_dpt | E16: #MA.CNTCT_DPT | G16: Supplier dept. | H16: 発注先部署 | I16: E | K16: E | M16: E
A17: 10 | D17: sppl_cntct_psn | E17: #MA.CNTCT_PSN | G17: Supplier PIC | H17: 発注先担当者 | I17: E | K17: E | M17: E
A18: 10 | D18: sppl_cntct_psn_title | E18: #MA.BP_PSN_TITLE | G18: Supplier PIC form of address | H18: 発注先担当者敬称 | I18: E | K18: E | M18: E
A19: 10 | D19: subcon_flg | E19: #MA.FLG | G19: For subcontract | H19: 下請対象 | I19: E | K19: E | M19: E
A20: 10 | D20: purc_upri_req_typ | E20: #MA.PURC_UPRI_REQ_TYP | G20: Purchase unit price acquisition type | H20: 購買単価取得区分 | I20: E | K20: E | M20: E
A21: 10 | D21: purc_upri_cng_flg | E21: #MA.FLG | G21: Allow purchasing unit price change | H21: 購買単価変更許可 | I21: E | K21: E | M21: E
A22: 10 | D22: purc_amt_rnd_typ | E22: #MA.RND_TYP | G22: Rounding type (Purchase amount) | H22: 仕入金額端数処理区分 | I22: E | K22: E | M22: E
A23: 10 | D23: purc_tax_calc_typ | E23: #MA.TAX_CALC_TYP | G23: Purchase tax calculation type | H23: 仕入税計算区分 | I23: E | K23: E | M23: E
A24: 10 | D24: purc_tax_rnd_typ | E24: #MA.RND_TYP | G24: Rounding type (Purchase tax) | H24: 仕入税額端数処理区分 | I24: E | K24: E | M24: E
A25: 10 | D25: pay_crryovr_times | E25: #MA.CRRYOVR_TIMES | G25: Payment carry-over count | H25: 支払繰越回数 | I25: E | K25: E | M25: E
A26: 10 | D26: sppl_cal_cd | E26: #MA.CAL_CD | G26: Supplier calendar cd. | H26: 発注先カレンダＣＤ | I26: E | K26: E | M26: E
A27: 10 | D27: po_print_cd | E27: #MA.PO_PRINT_CD | G27: Display PO sheet cd. | H27: 注文書表示ＣＤ | I27: E | K27: E | M27: E
... A54: 10 | D54: prov_tax_rnd_typ | E54: #MA.RND_TYP | G54: Supply tax rounding type | H54: 支給税額端数処理区分 | I54: E | K54: E | M54: E
A55: 10 | D55: bsppl_flg | E55: #MA.FLG | G55: Scheduled payee | H55: 支払予定管理先 | I55: E | K55: E
A56: 10 | D56: bsppl_cd | E56: #MA.BP_CD | G56: Scheduled payee cd. | H56: 支払予定管理先ＣＤ | I56: E | K56: E | M56: E
A57: 10 | D57: ap_dpt_cd | E57: #MA.DPT_CD | G57: AP dept. cd. | H57: 債務部門ＣＤ | I57: E | K57: E | M57: E
A58: 10 | D58: check_ap_dpt_cd | E58: #MA.DPT_CD | G58: AP dept. cd. | H58: 債務部門ＣＤ | I58: E | K58: E
A59: 10 | D59: sppl_prnt_typ | E59: #MA.PRNT_TYP | G59: Report issue type (Supplier) | H59: 帳票発行区分（発注先） | I59: E | K59: E | M59: E
A60: 10 | D60: upd_cntr | E60: #MA.UPD_CNT | G60: Update counter | H60: 更新カウンタ | I60: E | K60: E | M60: E
A62: 20 | B62: * | D62: Upd01_Dtl2 | E62: L | G62: $share$ | H62: MA.MABSL0010.ItmDtl_Upd01.ItmDtl_Upd01_Dtl | O62: ItmDtl_UpdChk01_Dtl | Q62: ItmDtl_Upd01_Dtl
A63: 20 | D63: sppl_cd | E63: #MA.BP_CD | G63: Supplier cd. | H63: 発注先ＣＤ | I63: E | O63: E | Q63: E
A64: 20 | D64: wg_cd | E64: #MA.WG_CD | G64: WG cd. | H64: ワーキンググループＣＤ | I64: E | O64: E | Q64: E
A65: 20 | D65: itm_cd | E65: #MA.ITM_CD | G65: Item cd. | H65: 品目ＣＤ | I65: E | O65: E | Q65: E
A66: 20 | D66: itm_sub1 | E66: #MA.ITM_SUB1 | G66: Branch No. 1 | H66: 枝番１ | I66: E | O66: E | Q66: E
A67: 20 | D67: itm_sub2 | E67: #MA.ITM_SUB2 | G67: Branch No. 2 | H67: 枝番２ | I67: E | O67: E | Q67: E
...

Sheet 来歴
A1: 変更来歴
A3: Rev. | H3: 修正番号 | O3: 変更内容 | AQ3: 変更箇所
A4: 1 | O4: 初版
A5: 1.1 | O5: 英語の名称を追記 | AQ5: 全般
