Workbook

Sheet LogicCommon
A2: ロジック共通定義 | B2: ModuleID : | C2: MA | D2: LogicID : | E2: MABCL0035 | F2: Pj.ID : | G2: MC
B3: SubModuleID : | C3: MABC | D3: LogicClass : | E3: MABCL_MultiReg | F3: SuperClassPj.ID :
D4: LogicName : | E4: マルチマスタ登録 | F4: SuperLogicID : | G4: MA.MAUDL5010
A5: 概要 :
A6: 詳細 :
B7: 対象マスタ
C8: 仕訳パタンマスタ
C9: 自動仕訳キーマスタ
C10: 検査パタンマスタ
C11: 勤務種類マスタ
C12: 出荷条件マスタ
C13: 出荷作業マスタ
C14: 資源マスタ
C15: ＨＳ分類マスタ
C16: 配賦パタンマスタ
C17: 原価品群グループマスタ
C18: 計算実行パタンマスタ

Sheet JnlPtnBase_UpdChk01
A1: * | B1: * | D1: L | E1: 1
A2: * | D2: オペレーション実装仕様書 Operation Specification Implementation Sheet | E2: ModuleID : | F2: =IF(LogicCommon!C2="","",LogicCommon!C2) -> MA | G2: LogicID : | H2: =IF(LogicCommon!E2="","",LogicCommon!E2) -> MABCL0035 | I2: Ope.ID : | J2: JnlPtnBase_UpdChk01 | K2: Pj.ID : | L2: =IF(LogicCommon!G2="","",LogicCommon!G2) -> MC | M2: Ope.Body : | N2: =L4 & ".Checker" -> MA.MAUDL5010.Checker
A3: * | D3: =IF(LogicCommon!A3="","",LogicCommon!A3) | E3: SubModuleID : | F3: =IF(LogicCommon!C3="","",LogicCommon!C3) -> MABC | G3: LogicClass : | H3: =IF(LogicCommon!E3="","",LogicCommon!E3) -> MABCL_MultiReg | I3: Ope.Method : | J3: @ | K3: SuperClassPj.ID : | L3: =IF(LogicCommon!G3="","",LogicCommon!G3) | M3: ReportID : | O3: Gene.Type : | P3: ALL
A4: * | E4: Version : | F4: 000000 | G4: LogicName : | H4: =IF(LogicCommon!E4="","",LogicCommon!E4) -> マルチマスタ登録 | I4: Ope.Name : | J4: チェック | K4: SuperLogicID : | L4: =IF(LogicCommon!G4="","",LogicCommon!G4) -> MA.MAUDL5010
A5: * | E5: ACType :
A6: * | D6: 概要 : | E6: 仕訳パタンマスタの登録前のチェックを行います。 | M6: ID
A7: # | I7: U | K7: K | L7: o
A8: # | D8: ブロック名 Block Name | E8: 型 Type | G8: super/share | H8: 対象ブロック名 Target Block Name | K8: REQUIRED | L8: TargetName | P8: ブロック備考 Block Remarks
A9: # | D9: 項目名 Field Name | E9: 型 Type | F9: 桁 Digits | G9: フルネーム Full Name | H9: 日本語名 Japanese Name | I9: 上り項目 Request Message Field | J9: 下り項目 Response Message Field | N9: 条件および編集方法 Conditions and Editing Methods | P9: 項目備考 Field Remarks
A10: # | L10: 上り項目 Request Message Field | M10: 下り項目 Response Message Field
A11: 10 | B11: * | D11: JnlPtnBase_UpdChk01_Dtl | E11: L | G11: $super$ | H11: DBC:MA.MAM_JNL_PTN_BASE
A12: 10 | D12: jnl_ptn_cd | E12: #MA.JNL_PTN_CD | G12: Journal pattern cd. | H12: 仕訳パタンＣＤ | I12: E | K12: E
A13: 10 | D13: jnl_ptn_nm | E13: #MA.JNL_PTN_NM | G13: Standard journal pattern name | H13: 標準仕訳パタン名 | I13: E | K13: E
A14: 10 | D14: memo1 | E14: #MA.MST_MEMO1 | G14: Memo 1 | H14: メモ１ | I14: E
A15: 10 | D15: memo2 | E15: #MA.MST_MEMO2 | G15: Memo 2 | H15: メモ２ | I15: E
A16: 10 | D16: memo3 | E16: #MA.MST_MEMO3 | G16: Memo 3 | H16: メモ３ | I16: E
A17: 10 | D17: del_flg | E17: #MA.FLG | G17: Logical delete | H17: 論理削除 | I17: E
A18: 10 | D18: upd_cntr | E18: #MA.UPD_CNT | G18: Update counter | H18: 更新カウンタ | I18: E
D19: 詳細 :

Sheet JnlPtnBase_Upd01
A1: * | B1: * | D1: L | E1: 1
A2: * | D2: オペレーション実装仕様書 Operation Specification Implementation Sheet | E2: ModuleID : | F2: =IF(LogicCommon!C2="","",LogicCommon!C2) -> MA | G2: LogicID : | H2: =IF(LogicCommon!E2="","",LogicCommon!E2) -> MABCL0035 | I2: Ope.ID : | J2: JnlPtnBase_Upd01 | K2: Pj.ID : | L2: =IF(LogicCommon!G2="","",LogicCommon!G2) -> MC | M2: Ope.Body : | N2: "mcframe.serverMAUD.MAUDL6020.MAUDL_LCLRLUpdater"
A3: * | D3: =IF(LogicCommon!A3="","",LogicCommon!A3) | E3: SubModuleID : | F3: =IF(LogicCommon!C3="","",LogicCommon!C3) -> MABC | G3: LogicClass : | H3: =IF(LogicCommon!E3="","",LogicCommon!E3) -> MABCL_MultiReg | I3: Ope.Method : | J3: @ | K3: SuperClassPj.ID : | L3: =IF(LogicCommon!G3="","",LogicCommon!G3) | M3: ReportID : | O3: Gene.Type : | P3: ALL
A4: * | E4: Version : | F4: 000000 | G4: LogicName : | H4: =IF(LogicCommon!E4="","",LogicCommon!E4) -> マルチマスタ登録 | I4: Ope.Name : | J4: 登録 | K4: SuperLogicID : | L4: =IF(LogicCommon!G4="","",LogicCommon!G4) -> MA.MAUDL5010
A5: * | E5: ACType :
A6: * | D6: 概要 : | E6: 仕訳パタンマスタの登録を行います。 | L6: ID | N6: ID | P6: ID | R6: ID
A7: # | I7: U | K7: o | L7: UPDATE.updMaster | M7: o | N7: MAIN.chkMaster | O7: o | Q7: o
A8: # | D8: ブロック名 Block Name | E8: 型 Type | G8: super/share | H8: 対象ブロック名 Target Block Name | K8: TargetName | L8: DBC.MA.MAM_JNL_PTN_BASE | M8: TargetName | N8: DBC.MA.MAM_JNL_PTN_BASE | O8: TargetName | Q8: TargetName | U8: ブロック備考 Block Remarks
A9: # | D9: 項目名 Field Name | E9: 型 Type | F9: 桁 Digits | G9: フルネーム Full Name | H9: 日本語名 Japanese Name | I9: 上り項目 Request Message Field | J9: 下り項目 Response Message Field | S9: 条件および編集方法 Conditions and Editing Methods | U9: 項目備考 Field Remarks
A10: # | K10: 上り項目 Request Message Field | L10: 下り項目 Response Message Field | M10: 上り項目 Request Message Field | N10: 下り項目 Response Message Field | O10: 上り項目 Request Message Field | P10: 下り項目 Response Message Field | Q10: 上り項目 Request Message Field | R10: 下り項目 Response Message Field
A11: 10 | B11: * | D11: JnlPtnBase_Upd01_Dtl | E11: L | G11: $share$ | H11: MA.MABCL0035.JnlPtnBase_UpdChk01.JnlPtnBase_UpdChk01_Dtl | K11: L | M11: L
A12: 10 | D12: jnl_ptn_cd | E12: #MA.JNL_PTN_CD | G12: Journal pattern cd. | H12: 仕訳パタンＣＤ | I12: E | K12: E | M12: E
A13: 10 | D13: jnl_ptn_nm | E13: #MA.JNL_PTN_NM | G13: Standard journal pattern name | H13: 標準仕訳パタン名 | I13: E | K13: E | M13: E
A14: 10 | D14: memo1 | E14: #MA.MST_MEMO1 | G14: Memo 1 | H14: メモ１ | I14: E | K14: E | M14: E
A15: 10 | D15: memo2 | E15: #MA.MST_MEMO2 | G15: Memo 2 | H15: メモ２ | I15: E | K15: E | M15: E
A16: 10 | D16: memo3 | E16: #MA.MST_MEMO3 | G16: Memo 3 | H16: メモ３ | I16: E | K16: E | M16: E
A17: 10 | D17: del_flg | E17: #MA.FLG | G17: Logical delete | H17: 論理削除 | I17: E | K17: E | M17: E
A18: 10 | D18: upd_cntr | E18: #MA.UPD_CNT | G18: Update counter | H18: 更新カウンタ | I18: E | K18: E | M18: E
D19: 詳細 :

Sheet JnlPtnBaseLcl_UpdChk01
A1: * | B1: * | D1: L | E1: 1
A2: * | D2: オペレーション実装仕様書 Operation Specification Implementation Sheet | E2: ModuleID : | F2: =IF(LogicCommon!C2="","",LogicCommon!C2) -> MA | G2: LogicID : | H2: =IF(LogicCommon!E2="","",LogicCommon!E2) -> MABCL0035 | I2: Ope.ID : | J2: JnlPtnBaseLcl_UpdChk01 | K2: Pj.ID : | L2: =IF(LogicCommon!G2="","",LogicCommon!G2) -> MC | M2: Ope.Body : | N2: =L4 & ".Checker" -> MA.MAUDL5010.Checker
A3: * | D3: =IF(LogicCommon!A3="","",LogicCommon!A3) | E3: SubModuleID : | F3: =IF(LogicCommon!C3="","",LogicCommon!C3) -> MABC | G3: LogicClass : | H3: =IF(LogicCommon!E3="","",LogicCommon!E3) -> MABCL_MultiReg | I3: Ope.Method : | J3: @ | K3: SuperClassPj.ID : | L3: =IF(LogicCommon!G3="","",LogicCommon!G3) | M3: ReportID : | O3: Gene.Type : | P3: ALL
A4: * | E4: Version : | F4: 000000 | G4: LogicName : | H4: =IF(LogicCommon!E4="","",LogicCommon!E4) -> マルチマスタ登録 | I4: Ope.Name : | J4: チェック | K4: SuperLogicID : | L4: =IF(LogicCommon!G4="","",LogicCommon!G4) -> MA.MAUDL5010
A5: * | E5: ACType :
A6: * | D6: 概要 : | E6: 仕訳パタンマスタの登録前のチェックを行います。（ロケール用） | M6: ID
A7: # | I7: U | K7: K | L7: o | M7: EXISTS.chk01
A8: # | D8: ブロック名 Block Name | E8: 型 Type | G8: super/share | H8: 対象ブロック名 Target Block Name | K8: REQUIRED | L8: TargetName | M8: DBC.MA.MAM_JNL_PTN_BASE | P8: ブロック備考 Block Remarks
A9: # | D9: 項目名 Field Name | E9: 型 Type | F9: 桁 Digits | G9: フルネーム Full Name | H9: 日本語名 Japanese Name | I9: 上り項目 Request Message Field | J9: 下り項目 Response Message Field | N9: 条件および編集方法 Conditions and Editing Methods | P9: 項目備考 Field Remarks
A10: # | L10: 上り項目 Request Message Field | M10: 下り項目 Response Message Field
A11: 10 | B11: * | D11: JnlPtnBaseLcl_UpdChk01_Dtl | E11: L | G11: $super$ | H11: DBC:MA.MAM_JNL_PTN_BASE_LCL | L11: L
A12: 10 | D12: jnl_ptn_cd | E12: #MA.JNL_PTN_CD | G12: Auto-journal pattern cd. | H12: 自動仕訳パタンＣＤ | I12: E | K12: E | L12: E
A13: 10 | D13: lcl_cd | E13: #MA.LCL_CD | G13: Locale cd. | H13: ロケールＣＤ | I13: E | K13: E
A14: 10 | D14: jnl_ptn_nm | E14: #MA.JNL_PTN_NM | G14: Auto-journal pattern name | H14: 自動仕訳パタン名 | I14: E | K14: E
A15: 10 | D15: memo1 | E15: #MA.MST_MEMO1 | G15: Memo 1 | H15: メモ１ | I15: E
A16: 10 | D16: memo2 | E16: #MA.MST_MEMO2 | G16: Memo 2 | H16: メモ２ | I16: E
A17: 10 | D17: memo3 | E17: #MA.MST_MEMO3 | G17: Memo 3 | H17: メモ３ | I17: E
A18: 10 | D18: upd_cntr | E18: #MA.UPD_CNT | G18: Update counter | H18: 更新カウンタ | I18: E
D19: 詳細 :

Sheet JnlPtnBaseLcl_Upd01
A1: * | B1: * | D1: L | E1: 1
A2: * | D2: オペレーション実装仕様書 Operation Specification Implementation Sheet | E2: ModuleID : | F2: =IF(LogicCommon!C2="","",LogicCommon!C2) -> MA | G2: LogicID : | H2: =IF(LogicCommon!E2="","",LogicCommon!E2) -> MABCL0035 | I2: Ope.ID : | J2: JnlPtnBaseLcl_Upd01 | K2: Pj.ID : | L2: =IF(LogicCommon!G2="","",LogicCommon!G2) -> MC | M2: Ope.Body : | N2: "mcframe.serverMAUD.MAUDL6020.MAUDL_LCLRLUpdater"
A3: * | D3: =IF(LogicCommon!A3="","",LogicCommon!A3) | E3: SubModuleID : | F3: =IF(LogicCommon!C3="","",LogicCommon!C3) -> MABC | G3: LogicClass : | H3: =IF(LogicCommon!E3="","",LogicCommon!E3) -> MABCL_MultiReg | I3: Ope.Method : | J3: @ | K3: SuperClassPj.ID : | L3: =IF(LogicCommon!G3="","",LogicCommon!G3) | M3: ReportID : | O3: Gene.Type : | P3: ALL
A4: * | E4: Version : | F4: 000000 | G4: LogicName : | H4: =IF(LogicCommon!E4="","",LogicCommon!E4) -> マルチマスタ登録 | I4: Ope.Name : | J4: 登録 | K4: SuperLogicID : | L4: =IF(LogicCommon!G4="","",LogicCommon!G4) -> MA.MAUDL5010
A5: * | E5: ACType :
A6: * | D6: 概要 : | E6: 仕訳パタンマスタの登録を行います。（ロケール用） | L6: ID | N6: ID | P6: ID | R6: ID
A7: # | I7: U | K7: o | L7: UPDATE.updMaster | M7: o | N7: MAIN.chkMaster | O7: o | Q7: o
A8: # | D8: ブロック名 Block Name | E8: 型 Type | G8: super/share | H8: 対象ブロック名 Target Block Name | K8: TargetName | L8: DBC.MA.MAM_JNL_PTN_BASE_LCL | M8: TargetName | N8: DBC.MA.MAM_JNL_PTN_BASE_LCL | O8: TargetName | Q8: TargetName | U8: ブロック備考 Block Remarks
A9: # | D9: 項目名 Field Name | E9: 型 Type | F9: 桁 Digits | G9: フルネーム Full Name | H9: 日本語名 Japanese Name | I9: 上り項目 Request Message Field | J9: 下り項目 Response Message Field | S9: 条件および編集方法 Conditions and Editing Methods | U9: 項目備考 Field Remarks
A10: # | K10: 上り項目 Request Message Field | L10: 下り項目 Response Message Field | M10: 上り項目 Request Message Field | N10: 下り項目 Response Message Field | O10: 上り項目 Request Message Field | P10: 下り項目 Response Message Field | Q10: 上り項目 Request Message Field | R10: 下り項目 Response Message Field
A11: 10 | B11: * | D11: JnlPtnBaseLcl_Upd01_Dtl | E11: L | G11: $share$ | H11: MA.MABCL0035.JnlPtnBaseLcl_UpdChk01.JnlPtnBaseLcl_UpdChk01_Dtl | K11: L | M11: L
A12: 10 | D12: jnl_ptn_cd | E12: #MA.JNL_PTN_CD | G12: Auto-journal pattern cd. | H12: 自動仕訳パタンＣＤ | I12: E | K12: E | M12: E
A13: 10 | D13: lcl_cd | E13: #MA.LCL_CD | G13: Locale cd. | H13: ロケールＣＤ | I13: E | K13: E | M13: E
A14: 10 | D14: jnl_ptn_nm | E14: #MA.JNL_PTN_NM | G14: Auto-journal pattern name | H14: 自動仕訳パタン名 | I14: E | K14: E | M14: E
A15: 10 | D15: memo1 | E15: #MA.MST_MEMO1 | G15: Memo 1 | H15: メモ１ | I15: E | K15: E | M15: E
A16: 10 | D16: memo2 | E16: #MA.MST_MEMO2 | G16: Memo 2 | H16: メモ２ | I16: E | K16: E | M16: E
A17: 10 | D17: memo3 | E17: #MA.MST_MEMO3 | G17: Memo 3 | H17: メモ３ | I17: E | K17: E | M17: E
A18: 10 | D18: upd_cntr | E18: #MA.UPD_CNT | G18: Update counter | H18: 更新カウンタ | I18: E | K18: E | M18: E
D19: 詳細 :

Sheet JnlPtnBase_DelChk01
A1: * | B1: * | D1: L | E1: 1
A2: * | D2: オペレーション実装仕様書 Operation Specification Implementation Sheet | E2: ModuleID : | F2: =IF(LogicCommon!C2="","",LogicCommon!C2) -> MA | G2: LogicID : | H2: =IF(LogicCommon!E2="","",LogicCommon!E2) -> MABCL0035 | I2: Ope.ID : | J2: JnlPtnBase_DelChk01 | K2: Pj.ID : | L2: =IF(LogicCommon!G2="","",LogicCommon!G2) -> MC | M2: Ope.Body : | N2: =L4 & ".Checker" -> MA.MAUDL5010.Checker
A3: * | D3: =IF(LogicCommon!A3="","",LogicCommon!A3) | E3: SubModuleID : | F3: =IF(LogicCommon!C3="","",LogicCommon!C3) -> MABC | G3: LogicClass : | H3: =IF(LogicCommon!E3="","",LogicCommon!E3) -> MABCL_MultiReg | I3: Ope.Method : | J3: @ | K3: SuperClassPj.ID : | L3: =IF(LogicCommon!G3="","",LogicCommon!G3) | M3: ReportID : | O3: Gene.Type : | P3: ALL
A4: * | E4: Version : | F4: 000000 | G4: LogicName : | H4: =IF(LogicCommon!E4="","",LogicCommon!E4) -> マルチマスタ登録 | I4: Ope.Name : | J4: チェック | K4: SuperLogicID : | L4: =IF(LogicCommon!G4="","",LogicCommon!G4) -> MA.MAUDL5010
A5: * | E5: ACType :
A6: * | D6: 概要 : | E6: 仕訳パタンマスタの削除前のチェックを行います。 | M6: ID
A7: # | I7: U | K7: K | L7: o
A8: # | D8: ブロック名 Block Name | E8: 型 Type | G8: super/share | H8: 対象ブロック名 Target Block Name | K8: REQUIRED | L8: TargetName | P8: ブロック備考 Block Remarks
A9: # | D9: 項目名 Field Name | E9: 型 Type | F9: 桁 Digits | G9: フルネーム Full Name | H9: 日本語名 Japanese Name | I9: 上り項目 Request Message Field | J9: 下り項目 Response Message Field | N9: 条件および編集方法 Conditions and Editing Methods | P9: 項目備考 Field Remarks
A10: # | L10: 上り項目 Request Message Field | M10: 下り項目 Response Message Field
A11: 10 | B11: * | D11: JnlPtnBase_DelChk01_Dtl | E11: L
A12: 10 | D12: jnl_ptn_cd | E12: #MA.JNL_PTN_CD | G12: Auto-journal pattern basic cd. | H12: 自動仕訳パタン基本ＣＤ | I12: E | K12: E
A13: 10 | D13: upd_cntr | E13: #MA.UPD_CNT | G13: Update counter | H13: 更新カウンタ | I13: E
D14: 詳細 :

Sheet JnlPtnBase_Del01
A1: * | B1: * | D1: L | E1: 1
A2: * | D2: オペレーション実装仕様書 Operation Specification Implementation Sheet | E2: ModuleID : | F2: =IF(LogicCommon!C2="","",LogicCommon!C2) -> MA | G2: LogicID : | H2: =IF(LogicCommon!E2="","",LogicCommon!E2) -> MABCL0035 | I2: Ope.ID : | J2: JnlPtnBase_Del01 | K2: Pj.ID : | L2: =IF(LogicCommon!G2="","",LogicCommon!G2) -> MC | M2: Ope.Body : | N2: "mcframe.serverMAUD.MAUDL6020.MAUDL_LCLRLDeleter"
A3: * | D3: =IF(LogicCommon!A3="","",LogicCommon!A3) | E3: SubModuleID : | F3: =IF(LogicCommon!C3="","",LogicCommon!C3) -> MABC | G3: LogicClass : | H3: =IF(LogicCommon!E3="","",LogicCommon!E3) -> MABCL_MultiReg | I3: Ope.Method : | J3: @ | K3: SuperClassPj.ID : | L3: =IF(LogicCommon!G3="","",LogicCommon!G3) | M3: ReportID : | O3: Gene.Type : | P3: ALL
A4: * | E4: Version : | F4: 000000 | G4: LogicName : | H4: =IF(LogicCommon!E4="","",LogicCommon!E4) -> マルチマスタ登録 | I4: Ope.Name : | J4: 削除 | K4: SuperLogicID : | L4: =IF(LogicCommon!G4="","",LogicCommon!G4) -> MA.MAUDL5010
A5: * | E5: ACType :
A6: * | D6: 概要 : | E6: 仕訳パタンマスタの削除を行います。 | L6: ID | N6: ID | P6: ID | R6: ID
A7: # | I7: U | K7: o | L7: UPDATE.updMaster1 | M7: o | N7: UPDATE.updMaster2 | O7: o | Q7: o
A8: # | D8: ブロック名 Block Name | E8: 型 Type | G8: super/share | H8: 対象ブロック名 Target Block Name | K8: TargetName | L8: DBC.MA.MAM_JNL_PTN_BASE | M8: TargetName | N8: DBC.MA.MAM_JNL_PTN_BASE_LCL | O8: TargetName | Q8: TargetName | U8: ブロック備考 Block Remarks
A9: # | D9: 項目名 Field Name | E9: 型 Type | F9: 桁 Digits | G9: フルネーム Full Name | H9: 日本語名 Japanese Name | I9: 上り項目 Request Message Field | J9: 下り項目 Response Message Field | S9: 条件および編集方法 Conditions and Editing Methods | U9: 項目備考 Field Remarks
A10: # | K10: 上り項目 Request Message Field | L10: 下り項目 Response Message Field | M10: 上り項目 Request Message Field | N10: 下り項目 Response Message Field | O10: 上り項目 Request Message Field | P10: 下り項目 Response Message Field | Q10: 上り項目 Request Message Field | R10: 下り項目 Response Message Field
A11: 10 | B11: * | D11: JnlPtnBase_Del01_Dtl | E11: L | G11: $share$ | H11: MA.MABCL0035.JnlPtnBase_DelChk01.JnlPtnBase_DelChk01_Dtl | K11: L | M11: L
A12: 10 | D12: jnl_ptn_cd | E12: #MA.JNL_PTN_CD | G12: Auto-journal pattern basic cd. | H12: 自動仕訳パタン基本ＣＤ | I12: E | K12: E | M12: E
A13: 10 | D13: upd_cntr | E13: #MA.UPD_CNT | G13: Update counter | H13: 更新カウンタ | I13: E | K13: E
D14: 詳細 :

Sheet AutoJnlKey_UpdChk01
A1: * | B1: * | D1: L | E1: 1
A2: * | D2: オペレーション実装仕様書 Operation Specification Implementation Sheet | E2: ModuleID : | F2: =IF(LogicCommon!C2="","",LogicCommon!C2) -> MA | G2: LogicID : | H2: =IF(LogicCommon!E2="","",LogicCommon!E2) -> MABCL0035 | I2: Ope.ID : | J2: AutoJnlKey_UpdChk01 | K2: Pj.ID : | L2: =IF(LogicCommon!G2="","",LogicCommon!G2) -> MC | M2: Ope.Body : | N2: =L4 & ".Checker" -> MA.MAUDL5010.Checker
A3: * | D3: =IF(LogicCommon!A3="","",LogicCommon!A3) | E3: SubModuleID : | F3: =IF(LogicCommon!C3="","",LogicCommon!C3) -> MABC | G3: LogicClass : | H3: =IF(LogicCommon!E3="","",LogicCommon!E3) -> MABCL_MultiReg | I3: Ope.Method : | J3: @ | K3: SuperClassPj.ID : | L3: =IF(LogicCommon!G3="","",LogicCommon!G3) | M3: ReportID : | O3: Gene.Type : | P3: ALL
A4: * | E4: Version : | F4: 000000 | G4: LogicName : | H4: =IF(LogicCommon!E4="","",LogicCommon!E4) -> マルチマスタ登録 | I4: Ope.Name : | J4: チェック | K4: SuperLogicID : | L4: =IF(LogicCommon!G4="","",LogicCommon!G4) -> MA.MAUDL5010
A5: * | E5: ACType :
A6: * | D6: 概要 : | E6: 自動仕訳キーマスタの登録前のチェックを行います。 | M6: ID
A7: # | I7: U | K7: K | L7: o
A8: # | D8: ブロック名 Block Name | E8: 型 Type | G8: super/share | H8: 対象ブロック名 Target Block Name | K8: REQUIRED | L8: TargetName | P8: ブロック備考 Block Remarks
A9: # | D9: 項目名 Field Name | E9: 型 Type | F9: 桁 Digits | G9: フルネーム Full Name | H9: 日本語名 Japanese Name | I9: 上り項目 Request Message Field | J9: 下り項目 Response Message Field | N9: 条件および編集方法 Conditions and Editing Methods | P9: 項目備考 Field Remarks
A10: # | L10: 上り項目 Request Message Field | M10: 下り項目 Response Message Field
A11: 10 | B11: * | D11: AutoJnlKey_UpdChk01_Dtl | E11: L | G11: $super$ | H11: DBC:MA.MAM_AUTO_JNL_KEY
A12: 10 | D12: auto_jnl_key_cd | E12: #MA.AUTO_JNL_KEY_CD | G12: Auto-journal key cd. | H12: 自動仕訳キーＣＤ | I12: E | K12: E
A13: 10 | D13: auto_jnl_key_nm | E13: #MA.AUTO_JNL_KEY_NM | G13: Standard auto-journal key name | H13: 標準自動仕訳キー名 | I13: E | K13: E
A14: 10 | D14: memo1 | E14: #MA.MST_MEMO1 | G14: Memo 1 | H14: メモ１ | I14: E
A15: 10 | D15: memo2 | E15: #MA.MST_MEMO2 | G15: Memo 2 | H15: メモ２ | I15: E
A16: 10 | D16: memo3 | E16: #MA.MST_MEMO3 | G16: Memo 3 | H16: メモ３ | I16: E
A17: 10 | D17: del_flg | E17: #MA.FLG | G17: Logical delete | H17: 論理削除 | I17: E
A18: 10 | D18: upd_cntr | E18: #MA.UPD_CNT | G18: Update counter | H18: 更新カウンタ | I18: E
D19: 詳細 :

Sheet AutoJnlKey_Upd01
A1: * | B1: * | D1: L | E1: 1
A2: * | D2: オペレーション実装仕様書 Operation Specification Implementation Sheet | E2: ModuleID : | F2: =IF(LogicCommon!C2="","",LogicCommon!C2) -> MA | G2: LogicID : | H2: =IF(LogicCommon!E2="","",LogicCommon!E2) -> MABCL0035 | I2: Ope.ID : | J2: AutoJnlKey_Upd01 | K2: Pj.ID : | L2: =IF(LogicCommon!G2="","",LogicCommon!G2) -> MC | M2: Ope.Body : | N2: "mcframe.serverMAUD.MAUDL6020.MAUDL_LCLRLUpdater"
A3: * | D3: =IF(LogicCommon!A3="","",LogicCommon!A3) | E3: SubModuleID : | F3: =IF(LogicCommon!C3="","",LogicCommon!C3) -> MABC | G3: LogicClass : | H3: =IF(LogicCommon!E3="","",LogicCommon!E3) -> MABCL_MultiReg | I3: Ope.Method : | J3: @ | K3: SuperClassPj.ID : | L3: =IF(LogicCommon!G3="","",LogicCommon!G3) | M3: ReportID : | O3: Gene.Type : | P3: ALL
A4: * | E4: Version : | F4: 000000 | G4: LogicName : | H4: =IF(LogicCommon!E4="","",LogicCommon!E4) -> マルチマスタ登録 | I4: Ope.Name : | J4: 登録 | K4: SuperLogicID : | L4: =IF(LogicCommon!G4="","",LogicCommon!G4) -> MA.MAUDL5010
A5: * | E5: ACType :
A6: * | D6: 概要 : | E6: 自動仕訳キーマスタの登録を行います。 | L6: ID | N6: ID | P6: ID | R6: ID
A7: # | I7: U | K7: o | L7: UPDATE.updMaster | M7: o | N7: MAIN.chkMaster | O7: o | Q7: o
A8: # | D8: ブロック名 Block Name | E8: 型 Type | G8: super/share | H8: 対象ブロック名 Target Block Name | K8: TargetName | L8: DBC.MA.MAM_AUTO_JNL_KEY | M8: TargetName | N8: DBC.MA.MAM_AUTO_JNL_KEY | O8: TargetName | Q8: TargetName | U8: ブロック備考 Block Remarks
A9: # | D9: 項目名 Field Name | E9: 型 Type | F9: 桁 Digits | G9: フルネーム Full Name | H9: 日本語名 Japanese Name | I9: 上り項目 Request Message Field | J9: 下り項目 Response Message Field | S9: 条件および編集方法 Conditions and Editing Methods | U9: 項目備考 Field Remarks
A10: # | K10: 上り項目 Request Message Field | L10: 下り項目 Response Message Field | M10: 上り項目 Request Message Field | N10: 下り項目 Response Message Field | O10: 上り項目 Request Message Field | P10: 下り項目 Response Message Field | Q10: 上り項目 Request Message Field | R10: 下り項目 Response Message Field
A11: 10 | B11: * | D11: AutoJnlKey_Upd01_Dtl | E11: L | G11: $share$ | H11: MA.MABCL0035.AutoJnlKey_UpdChk01.AutoJnlKey_UpdChk01_Dtl | K11: L | M11: L
A12: 10 | D12: auto_jnl_key_cd | E12: #MA.AUTO_JNL_KEY_CD | G12: Auto-journal key cd. | H12: 自動仕訳キーＣＤ | I12: E | K12: E | M12: E
A13: 10 | D13: auto_jnl_key_nm | E13: #MA.AUTO_JNL_KEY_NM | G13: Standard auto-journal key name | H13: 標準自動仕訳キー名 | I13: E | K13: E | M13: E
A14: 10 | D14: memo1 | E14: #MA.MST_MEMO1 | G14: Memo 1 | H14: メモ１ | I14: E | K14: E | M14: E
A15: 10 | D15: memo2 | E15: #MA.MST_MEMO2 | G15: Memo 2 | H15: メモ２ | I15: E | K15: E | M15: E
A16: 10 | D16: memo3 | E16: #MA.MST_MEMO3 | G16: Memo 3 | H16: メモ３ | I16: E | K16: E | M16: E
A17: 10 | D17: del_flg | E17: #MA.FLG | G17: Logical delete | H17: 論理削除 | I17: E | K17: E | M17: E
A18: 10 | D18: upd_cntr | E18: #MA.UPD_CNT | G18: Update counter | H18: 更新カウンタ | I18: E | K18: E | M18: E
D19: 詳細 :

Sheet AutoJnlKeyLcl_UpdChk01
A1: * | B1: * | D1: L | E1: 1
A2: * | D2: オペレーション実装仕様書 Operation Specification Implementation Sheet | E2: ModuleID : | F2: =IF(LogicCommon!C2="","",LogicCommon!C2) -> MA | G2: LogicID : | H2: =IF(LogicCommon!E2="","",LogicCommon!E2) -> MABCL0035 | I2: Ope.ID : | J2: AutoJnlKeyLcl_UpdChk01 | K2: Pj.ID : | L2: =IF(LogicCommon!G2="","",LogicCommon!G2) -> MC | M2: Ope.Body : | N2: =L4 & ".Checker" -> MA.MAUDL5010.Checker
A3: * | D3: =IF(LogicCommon!A3="","",LogicCommon!A3) | E3: SubModuleID : | F3: =IF(LogicCommon!C3="","",LogicCommon!C3) -> MABC | G3: LogicClass : | H3: =IF(LogicCommon!E3="","",LogicCommon!E3) -> MABCL_MultiReg | I3: Ope.Method : | J3: @ | K3: SuperClassPj.ID : | L3: =IF(LogicCommon!G3="","",LogicCommon!G3) | M3: ReportID : | O3: Gene.Type : | P3: ALL
A4: * | E4: Version : | F4: 000000 | G4: LogicName : | H4: =IF(LogicCommon!E4="","",LogicCommon!E4) -> マルチマスタ登録 | I4: Ope.Name : | J4: チェック | K4: SuperLogicID : | L4: =IF(LogicCommon!G4="","",LogicCommon!G4) -> MA.MAUDL5010
A5: * | E5: ACType :
A6: * | D6: 概要 : | E6: 自動仕訳キーマスタの登録前のチェックを行います。（ロケール用） | M6: ID
A7: # | I7: U | K7: K | L7: o | M7: EXISTS.chk01
A8: # | D8: ブロック名 Block Name | E8: 型 Type | G8: super/share | H8: 対象ブロック名 Target Block Name | K8: REQUIRED | L8: TargetName | M8: DBC.MA.MAM_AUTO_JNL_KEY | P8: ブロック備考 Block Remarks
A9: # | D9: 項目名 Field Name | E9: 型 Type | F9: 桁 Digits | G9: フルネーム Full Name | H9: 日本語名 Japanese Name | I9: 上り項目 Request Message Field | J9: 下り項目 Response Message Field | N9: 条件および編集方法 Conditions and Editing Methods | P9: 項目備考 Field Remarks
A10: # | L10: 上り項目 Request Message Field | M10: 下り項目 Response Message Field
A11: 10 | B11: * | D11: AutoJnlKeyLcl_UpdChk01_Dtl | E11: L | G11: $super$ | H11: DBC:MA.MAM_AUTO_JNL_KEY_LCL | L11: L
A12: 10 | D12: auto_jnl_key_cd | E12: #MA.AUTO_JNL_KEY_CD | G12: Auto-journal key cd. | H12: 自動仕訳キーＣＤ | I12: E | K12: E | L12: E
A13: 10 | D13: lcl_cd | E13: #MA.LCL_CD | G13: Locale cd. | H13: ロケールＣＤ | I13: E | K13: E
A14: 10 | D14: auto_jnl_key_nm | E14: #MA.AUTO_JNL_KEY_NM | G14: Auto-journal key name | H14: 自動仕訳キー名 | I14: E | K14: E
A15: 10 | D15: memo1 | E15: #MA.MST_MEMO1 | G15: Memo 1 | H15: メモ１ | I15: E
A16: 10 | D16: memo2 | E16: #MA.MST_MEMO2 | G16: Memo 2 | H16: メモ２ | I16: E
A17: 10 | D17: memo3 | E17: #MA.MST_MEMO3 | G17: Memo 3 | H17: メモ３ | I17: E
A18: 10 | D18: upd_cntr | E18: #MA.UPD_CNT | G18: Update counter | H18: 更新カウンタ | I18: E
D19: 詳細 :

Sheet AutoJnlKeyLcl_Upd01
A1: * | B1: * | D1: L | E1: 1
A2: * | D2: オペレーション実装仕様書 Operation Specification Implementation Sheet | E2: ModuleID : | F2: =IF(LogicCommon!C2="","",LogicCommon!C2) -> MA | G2: LogicID : | H2: =IF(LogicCommon!E2="","",LogicCommon!E2) -> MABCL0035 | I2: Ope.ID : | J2: AutoJnlKeyLcl_Upd01 | K2: Pj.ID : | L2: =IF(LogicCommon!G2="","",LogicCommon!G2) -> MC | M2: Ope.Body : | N2: "mcframe.serverMAUD.MAUDL6020.MAUDL_LCLRLUpdater"
A3: * | D3: =IF(LogicCommon!A3="","",LogicCommon!A3) | E3: SubModuleID : | F3: =IF(LogicCommon!C3="","",LogicCommon!C3) -> MABC | G3: LogicClass : | H3: =IF(LogicCommon!E3="","",LogicCommon!E3) -> MABCL_MultiReg | I3: Ope.Method : | J3: @ | K3: SuperClassPj.ID : | L3: =IF(LogicCommon!G3="","",LogicCommon!G3) | M3: ReportID : | O3: Gene.Type : | P3: ALL
A4: * | E4: Version : | F4: 000000 | G4: LogicName : | H4: =IF(LogicCommon!E4="","",LogicCommon!E4) -> マルチマスタ登録 | I4: Ope.Name : | J4: 登録 | K4: SuperLogicID : | L4: =IF(LogicCommon!G4="","",LogicCommon!G4) -> MA.MAUDL5010
A5: * | E5: ACType :
A6: * | D6: 概要 : | E6: 自動仕訳キーマスタの登録を行います。（ロケール用） | L6: ID | N6: ID | P6: ID | R6: ID
A7: # | I7: U | K7: o | L7: UPDATE.updMaster | M7: o | N7: MAIN.chkMaster | O7: o | Q7: o
A8: # | D8: ブロック名 Block Name | E8: 型 Type | G8: super/share | H8: 対象ブロック名 Target Block Name | K8: TargetName | L8: DBC.MA.MAM_AUTO_JNL_KEY_LCL | M8: TargetName | N8: DBC.MA.MAM_AUTO_JNL_KEY_LCL | O8: TargetName | Q8: TargetName | U8: ブロック備考 Block Remarks
A9: # | D9: 項目名 Field Name | E9: 型 Type | F9: 桁 Digits | G9: フルネーム Full Name | H9: 日本語名 Japanese Name | I9: 上り項目 Request Message Field | J9: 下り項目 Response Message Field | S9: 条件および編集方法 Conditions and Editing Methods | U9: 項目備考 Field Remarks
A10: # | K10: 上り項目 Request Message Field | L10: 下り項目 Response Message Field | M10: 上り項目 Request Message Field | N10: 下り項目 Response Message Field | O10: 上り項目 Request Message Field | P10: 下り項目 Response Message Field | Q10: 上り項目 Request Message Field | R10: 下り項目 Response Message Field
A11: 10 | B11: * | D11: AutoJnlKeyLcl_Upd01_Dtl | E11: L | G11: $share$ | H11: MA.MABCL0035.AutoJnlKeyLcl_UpdChk01.AutoJnlKeyLcl_UpdChk01_Dtl | K11: L | M11: L
A12: 10 | D12: auto_jnl_key_cd | E12: #MA.AUTO_JNL_KEY_CD | G12: Auto-journal key cd. | H12: 自動仕訳キーＣＤ | I12: E | K12: E | M12: E
A13: 10 | D13: lcl_cd | E13: #MA.LCL_CD | G13: Locale cd. | H13: ロケールＣＤ | I13: E | K13: E | M13: E
A14: 10 | D14: auto_jnl_key_nm | E14: #MA.AUTO_JNL_KEY_NM | G14: Auto-journal key name | H14: 自動仕訳キー名 | I14: E | K14: E | M14: E
A15: 10 | D15: memo1 | E15: #MA.MST_MEMO1 | G15: Memo 1 | H15: メモ１ | I15: E | K15: E | M15: E
A16: 10 | D16: memo2 | E16: #MA.MST_MEMO2 | G16: Memo 2 | H16: メモ２ | I16: E | K16: E | M16: E
A17: 10 | D17: memo3 | E17: #MA.MST_MEMO3 | G17: Memo 3 | H17: メモ３ | I17: E | K17: E | M17: E
A18: 10 | D18: upd_cntr | E18: #MA.UPD_CNT | G18: Update counter | H18: 更新カウンタ | I18: E | K18: E | M18: E
D19: 詳細 :

Sheet AutoJnlKey_DelChk01
A1: * | B1: * | D1: L | E1: 1
A2: * | D2: オペレーション実装仕様書 Operation Specification Implementation Sheet | E2: ModuleID : | F2: =IF(LogicCommon!C2="","",LogicCommon!C2) -> MA | G2: LogicID : | H2: =IF(LogicCommon!E2="","",LogicCommon!E2) -> MABCL0035 | I2: Ope.ID : | J2: AutoJnlKey_DelChk01 | K2: Pj.ID : | L2: =IF(LogicCommon!G2="","",LogicCommon!G2) -> MC | M2: Ope.Body : | N2: =L4 & ".Checker" -> MA.MAUDL5010.Checker
A3: * | D3: =IF(LogicCommon!A3="","",LogicCommon!A3) | E3: SubModuleID : | F3: =IF(LogicCommon!C3="","",LogicCommon!C3) -> MABC | G3: LogicClass : | H3: =IF(LogicCommon!E3="","",LogicCommon!E3) -> MABCL_MultiReg | I3: Ope.Method : | J3: @ | K3: SuperClassPj.ID : | L3: =IF(LogicCommon!G3="","",LogicCommon!G3) | M3: ReportID : | O3: Gene.Type : | P3: ALL
A4: * | E4: Version : | F4: 000000 | G4: LogicName : | H4: =IF(LogicCommon!E4="","",LogicCommon!E4) -> マルチマスタ登録 | I4: Ope.Name : | J4: チェック | K4: SuperLogicID : | L4: =IF(LogicCommon!G4="","",LogicCommon!G4) -> MA.MAUDL5010
A5: * | E5: ACType :
A6: * | D6: 概要 : | E6: 自動仕訳キーマスタの削除前のチェックを行います。 | M6: ID
A7: # | I7: U | K7: K | L7: o
A8: # | D8: ブロック名 Block Name | E8: 型 Type | G8: super/share | H8: 対象ブロック名 Target Block Name | K8: REQUIRED | L8: TargetName | P8: ブロック備考 Block Remarks
A9: # | D9: 項目名 Field Name | E9: 型 Type | F9: 桁 Digits | G9: フルネーム Full Name | H9: 日本語名 Japanese Name | I9: 上り項目 Request Message Field | J9: 下り項目 Response Message Field | N9: 条件および編集方法 Conditions and Editing Methods | P9: 項目備考 Field Remarks
A10: # | L10: 上り項目 Request Message Field | M10: 下り項目 Response Message Field
A11: 10 | B11: * | D11: AutoJnlKey_DelChk01_Dtl | E11: L
A12: 10 | D12: auto_jnl_key_cd | E12: #MA.AUTO_JNL_KEY_CD | G12: Auto-journal key cd. | H12: 自動仕訳キーＣＤ | I12: E | K12: E
A13: 10 | D13: upd_cntr | E13: #MA.UPD_CNT | G13: Update counter | H13: 更新カウンタ | I13: E
D14: 詳細 :

Sheet AutoJnlKey_Del01
A1: * | B1: * | D1: L | E1: 1
A2: * | D2: オペレーション実装仕様書 Operation Specification Implementation Sheet | E2: ModuleID : | F2: =IF(LogicCommon!C2="","",LogicCommon!C2) -> MA | G2: LogicID : | H2: =IF(LogicCommon!E2="","",LogicCommon!E2) -> MABCL0035 | I2: Ope.ID : | J2: AutoJnlKey_Del01 | K2: Pj.ID : | L2: =IF(LogicCommon!G2="","",LogicCommon!G2) -> MC | M2: Ope.Body : | N2: "mcframe.serverMAUD.MAUDL6020.MAUDL_LCLRLDeleter"
A3: * | D3: =IF(LogicCommon!A3="","",LogicCommon!A3) | E3: SubModuleID : | F3: =IF(LogicCommon!C3="","",LogicCommon!C3) -> MABC | G3: LogicClass : | H3: =IF(LogicCommon!E3="","",LogicCommon!E3) -> MABCL_MultiReg | I3: Ope.Method : | J3: @ | K3: SuperClassPj.ID : | L3: =IF(LogicCommon!G3="","",LogicCommon!G3) | M3: ReportID : | O3: Gene.Type : | P3: ALL
A4: * | E4: Version : | F4: 000000 | G4: LogicName : | H4: =IF(LogicCommon!E4="","",LogicCommon!E4) -> マルチマスタ登録 | I4: Ope.Name : | J4: 削除 | K4: SuperLogicID : | L4: =IF(LogicCommon!G4="","",LogicCommon!G4) -> MA.MAUDL5010
A5: * | E5: ACType :
A6: * | D6: 概要 : | E6: 自動仕訳キーマスタの削除を行います。 | L6: ID | N6: ID | P6: ID | R6: ID
A7: # | I7: U | K7: o | L7: UPDATE.updMaster1 | M7: o | N7: UPDATE.updMaster2 | O7: o | Q7: o
A8: # | D8: ブロック名 Block Name | E8: 型 Type | G8: super/share | H8: 対象ブロック名 Target Block Name | K8: TargetName | L8: DBC.MA.MAM_AUTO_JNL_KEY | M8: TargetName | N8: DBC.MA.MAM_AUTO_JNL_KEY_LCL | O8: TargetName | Q8: TargetName | U8: ブロック備考 Block Remarks
A9: # | D9: 項目名 Field Name | E9: 型 Type | F9: 桁 Digits | G9: フルネーム Full Name | H9: 日本語名 Japanese Name | I9: 上り項目 Request Message Field | J9: 下り項目 Response Message Field | S9: 条件および編集方法 Conditions and Editing Methods | U9: 項目備考 Field Remarks
A10: # | K10: 上り項目 Request Message Field | L10: 下り項目 Response Message Field | M10: 上り項目 Request Message Field | N10: 下り項目 Response Message Field | O10: 上り項目 Request Message Field | P10: 下り項目 Response Message Field | Q10: 上り項目 Request Message Field | R10: 下り項目 Response Message Field
A11: 10 | B11: * | D11: AutoJnlKey_Del01_Dtl | E11: L | G11: $share$ | H11: MA.MABCL0035.AutoJnlKey_DelChk01.AutoJnlKey_DelChk01_Dtl | K11: L | M11: L
A12: 10 | D12: auto_jnl_key_cd | E12: #MA.AUTO_JNL_KEY_CD | G12: Auto-journal key cd. | H12: 自動仕訳キーＣＤ | I12: E | K12: E | M12: E
A13: 10 | D13: upd_cntr | E13: #MA.UPD_CNT | G13: Update counter | H13: 更新カウンタ | I13: E | K13: E
D14: 詳細 :

Sheet InspPtn_UpdChk01
A1: * | B1: * | D1: L | E1: 1
A2: * | D2: オペレーション実装仕様書 Operation Specification Implementation Sheet | E2: ModuleID : | F2: =IF(LogicCommon!C2="","",LogicCommon!C2) -> MA | G2: LogicID : | H2: =IF(LogicCommon!E2="","",LogicCommon!E2) -> MABCL0035 | I2: Ope.ID : | J2: InspPtn_UpdChk01 | K2: Pj.ID : | L2: =IF(LogicCommon!G2="","",LogicCommon!G2) -> MC | M2: Ope.Body : | N2: =L4 & ".Checker" -> MA.MAUDL5010.Checker
A3: * | D3: =IF(LogicCommon!A3="","",LogicCommon!A3) | E3: SubModuleID : | F3: =IF(LogicCommon!C3="","",LogicCommon!C3) -> MABC | G3: LogicClass : | H3: =IF(LogicCommon!E3="","",LogicCommon!E3) -> MABCL_MultiReg | I3: Ope.Method : | J3: @ | K3: SuperClassPj.ID : | L3: =IF(LogicCommon!G3="","",LogicCommon!G3) | M3: ReportID : | O3: Gene.Type : | P3: ALL
A4: * | E4: Version : | F4: 000000 | G4: LogicName : | H4: =IF(LogicCommon!E4="","",LogicCommon!E4) -> マルチマスタ登録 | I4: Ope.Name : | J4: チェック | K4: SuperLogicID : | L4: =IF(LogicCommon!G4="","",LogicCommon!G4) -> MA.MAUDL5010
A5: * | E5: ACType :
A6: * | D6: 概要 : | E6: 検査パタンマスタの登録前のチェックを行います。 | M6: ID
A7: # | I7: U | K7: K | L7: o
A8: # | D8: ブロック名 Block Name | E8: 型 Type | G8: super/share | H8: 対象ブロック名 Target Block Name | K8: REQUIRED | L8: TargetName | P8: ブロック備考 Block Remarks
A9: # | D9: 項目名 Field Name | E9: 型 Type | F9: 桁 Digits | G9: フルネーム Full Name | H9: 日本語名 Japanese Name | I9: 上り項目 Request Message Field | J9: 下り項目 Response Message Field | N9: 条件および編集方法 Conditions and Editing Methods | P9: 項目備考 Field Remarks
A10: # | L10: 上り項目 Request Message Field | M10: 下り項目 Response Message Field
A11: 10 | B11: * | D11: InspPtn_UpdChk01_Dtl | E11: L | G11: $super$ | H11: DBC:MA.MAM_INSP_PTN
A12: 10 | D12: insp_ptn_cd | E12: #MA.INSP_PTN_CD | G12: Inspection pattern cd. | H12: 検査パタンＣＤ | I12: E | K12: E
A13: 10 | D13: insp_ptn_nm | E13: #MA.INSP_PTN_NM | G13: Standard inspection pattern name | H13: 標準検査パタン名 | I13: E | K13: E
A14: 10 | D14: memo1 | E14: #MA.MST_MEMO1 | G14: Memo 1 | H14: メモ１ | I14: E
A15: 10 | D15: memo2 | E15: #MA.MST_MEMO2 | G15: Memo 2 | H15: メモ２ | I15: E
A16: 10 | D16: memo3 | E16: #MA.MST_MEMO3 | G16: Memo 3 | H16: メモ３ | I16: E
A17: 10 | D17: del_flg | E17: #MA.FLG | G17: Logical delete | H17: 論理削除 | I17: E
A18: 10 | D18: upd_cntr | E18: #MA.UPD_CNT | G18: Update counter | H18: 更新カウンタ | I18: E
D19: 詳細 :

Sheet InspPtn_Upd01
A1: * | B1: * | D1: L | E1: 1
A2: * | D2: オペレーション実装仕様書 Operation Specification Implementation Sheet | E2: ModuleID : | F2: =IF(LogicCommon!C2="","",LogicCommon!C2) -> MA | G2: LogicID : | H2: =IF(LogicCommon!E2="","",LogicCommon!E2) -> MABCL0035 | I2: Ope.ID : | J2: InspPtn_Upd01 | K2: Pj.ID : | L2: =IF(LogicCommon!G2="","",LogicCommon!G2) -> MC | M2: Ope.Body : | N2: "mcframe.serverMAUD.MAUDL6020.MAUDL_LCLRLUpdater"
A3: * | D3: =IF(LogicCommon!A3="","",LogicCommon!A3) | E3: SubModuleID : | F3: =IF(LogicCommon!C3="","",LogicCommon!C3) -> MABC | G3: LogicClass : | H3: =IF(LogicCommon!E3="","",LogicCommon!E3) -> MABCL_MultiReg | I3: Ope.Method : | J3: @ | K3: SuperClassPj.ID : | L3: =IF(LogicCommon!G3="","",LogicCommon!G3) | M3: ReportID : | O3: Gene.Type : | P3: ALL
A4: * | E4: Version : | F4: 000000 | G4: LogicName : | H4: =IF(LogicCommon!E4="","",LogicCommon!E4) -> マルチマスタ登録 | I4: Ope.Name : | J4: 登録 | K4: SuperLogicID : | L4: =IF(LogicCommon!G4="","",LogicCommon!G4) -> MA.MAUDL5010
A5: * | E5: ACType :
A6: * | D6: 概要 : | E6: 検査パタンマスタの登録を行います。 | L6: ID | N6: ID | P6: ID | R6: ID
A7: # | I7: U | K7: o | L7: UPDATE.updMaster | M7: o | N7: MAIN.chkMaster | O7: o | Q7: o
A8: # | D8: ブロック名 Block Name | E8: 型 Type | G8: super/share | H8: 対象ブロック名 Target Block Name | K8: TargetName | L8: DBC.MA.MAM_INSP_PTN | M8: TargetName | N8: DBC.MA.MAM_INSP_PTN | O8: TargetName | Q8: TargetName | U8: ブロック備考 Block Remarks
A9: # | D9: 項目名 Field Name | E9: 型 Type | F9: 桁 Digits | G9: フルネーム Full Name | H9: 日本語名 Japanese Name | I9: 上り項目 Request Message Field | J9: 下り項目 Response Message Field | S9: 条件および編集方法 Conditions and Editing Methods | U9: 項目備考 Field Remarks
A10: # | K10: 上り項目 Request Message Field | L10: 下り項目 Response Message Field | M10: 上り項目 Request Message Field | N10: 下り項目 Response Message Field | O10: 上り項目 Request Message Field | P10: 下り項目 Response Message Field | Q10: 上り項目 Request Message Field | R10: 下り項目 Response Message Field
A11: 10 | B11: * | D11: InspPtn_Upd01_Dtl | E11: L | G11: $share$ | H11: MA.MABCL0035.InspPtn_UpdChk01.InspPtn_UpdChk01_Dtl | K11: L | M11: L
A12: 10 | D12: insp_ptn_cd | E12: #MA.INSP_PTN_CD | G12: Inspection pattern cd. | H12: 検査パタンＣＤ | I12: E | K12: E | M12: E
A13: 10 | D13: insp_ptn_nm | E13: #MA.INSP_PTN_NM | G13: Standard inspection pattern name | H13: 標準検査パタン名 | I13: E | K13: E | M13: E
A14: 10 | D14: memo1 | E14: #MA.MST_MEMO1 | G14: Memo 1 | H14: メモ１ | I14: E | K14: E | M14: E
A15: 10 | D15: memo2 | E15: #MA.MST_MEMO2 | G15: Memo 2 | H15: メモ２ | I15: E | K15: E | M15: E
A16: 10 | D16: memo3 | E16: #MA.MST_MEMO3 | G16: Memo 3 | H16: メモ３ | I16: E | K16: E | M16: E
A17: 10 | D17: del_flg | E17: #MA.FLG | G17: Logical delete | H17: 論理削除 | I17: E | K17: E | M17: E
A18: 10 | D18: upd_cntr | E18: #MA.UPD_CNT | G18: Update counter | H18: 更新カウンタ | I18: E | K18: E | M18: E
D19: 詳細 :

Sheet InspPtnLcl_UpdChk01
A1: * | B1: * | D1: L | E1: 1
A2: * | D2: オペレーション実装仕様書 Operation Specification Implementation Sheet | E2: ModuleID : | F2: =IF(LogicCommon!C2="","",LogicCommon!C2) -> MA | G2: LogicID : | H2: =IF(LogicCommon!E2="","",LogicCommon!E2) -> MABCL0035 | I2: Ope.ID : | J2: InspPtnLcl_UpdChk01 | K2: Pj.ID : | L2: =IF(LogicCommon!G2="","",LogicCommon!G2) -> MC | M2: Ope.Body : | N2: =L4 & ".Checker" -> MA.MAUDL5010.Checker
A3: * | D3: =IF(LogicCommon!A3="","",LogicCommon!A3) | E3: SubModuleID : | F3: =IF(LogicCommon!C3="","",LogicCommon!C3) -> MABC | G3: LogicClass : | H3: =IF(LogicCommon!E3="","",LogicCommon!E3) -> MABCL_MultiReg | I3: Ope.Method : | J3: @ | K3: SuperClassPj.ID : | L3: =IF(LogicCommon!G3="","",LogicCommon!G3) | M3: ReportID : | O3: Gene.Type : | P3: ALL
A4: * | E4: Version : | F4: 000000 | G4: LogicName : | H4: =IF(LogicCommon!E4="","",LogicCommon!E4) -> マルチマスタ登録 | I4: Ope.Name : | J4: チェック | K4: SuperLogicID : | L4: =IF(LogicCommon!G4="","",LogicCommon!G4) -> MA.MAUDL5010
A5: * | E5: ACType :
A6: * | D6: 概要 : | E6: 検査パタンマスタの登録前のチェックを行います。（ロケール用） | M6: ID
A7: # | I7: U | K7: K | L7: o | M7: EXISTS.chk01
A8: # | D8: ブロック名 Block Name | E8: 型 Type | G8: super/share | H8: 対象ブロック名 Target Block Name | K8: REQUIRED | L8: TargetName | M8: DBC.MA.MAM_INSP_PTN | P8: ブロック備考 Block Remarks
A9: # | D9: 項目名 Field Name | E9: 型 Type | F9: 桁 Digits | G9: フルネーム Full Name | H9: 日本語名 Japanese Name | I9: 上り項目 Request Message Field | J9: 下り項目 Response Message Field | N9: 条件および編集方法 Conditions and Editing Methods | P9: 項目備考 Field Remarks
A10: # | L10: 上り項目 Request Message Field | M10: 下り項目 Response Message Field
A11: 10 | B11: * | D11: InspPtnLcl_UpdChk01_Dtl | E11: L | G11: $super$ | H11: DBC:MA.MAM_INSP_PTN_LCL | L11: L
A12: 10 | D12: insp_ptn_cd | E12: #MA.INSP_PTN_CD | G12: Inspection pattern cd. | H12: 検査パタンＣＤ | I12: E | K12: E | L12: E
A13: 10 | D13: lcl_cd | E13: #MA.LCL_CD | G13: Locale cd. | H13: ロケールＣＤ | I13: E | K13: E
A14: 10 | D14: insp_ptn_nm | E14: #MA.INSP_PTN_NM | G14: Inspection pattern name | H14: 検査パタン名 | I14: E | K14: E
A15: 10 | D15: memo1 | E15: #MA.MST_MEMO1 | G15: Memo 1 | H15: メモ１ | I15: E
A16: 10 | D16: memo2 | E16: #MA.MST_MEMO2 | G16: Memo 2 | H16: メモ２ | I16: E
A17: 10 | D17: memo3 | E17: #MA.MST_MEMO3 | G17: Memo 3 | H17: メモ３ | I17: E
A18: 10 | D18: upd_cntr | E18: #MA.UPD_CNT | G18: Update counter | H18: 更新カウンタ | I18: E
D19: 詳細 :

Sheet InspPtnLcl_Upd01
A1: * | B1: * | D1: L | E1: 1
A2: * | D2: オペレーション実装仕様書 Operation Specification Implementation Sheet | E2: ModuleID : | F2: =IF(LogicCommon!C2="","",LogicCommon!C2) -> MA | G2: LogicID : | H2: =IF(LogicCommon!E2="","",LogicCommon!E2) -> MABCL0035 | I2: Ope.ID : | J2: InspPtnLcl_Upd01 | K2: Pj.ID : | L2: =IF(LogicCommon!G2="","",LogicCommon!G2) -> MC | M2: Ope.Body : | N2: "mcframe.serverMAUD.MAUDL6020.MAUDL_LCLRLUpdater"
A3: * | D3: =IF(LogicCommon!A3="","",LogicCommon!A3) | E3: SubModuleID : | F3: =IF(LogicCommon!C3="","",LogicCommon!C3) -> MABC | G3: LogicClass : | H3: =IF(LogicCommon!E3="","",LogicCommon!E3) -> MABCL_MultiReg | I3: Ope.Method : | J3: @ | K3: SuperClassPj.ID : | L3: =IF(LogicCommon!G3="","",LogicCommon!G3) | M3: ReportID : | O3: Gene.Type : | P3: ALL
A4: * | E4: Version : | F4: 000000 | G4: LogicName : | H4: =IF(LogicCommon!E4="","",LogicCommon!E4) -> マルチマスタ登録 | I4: Ope.Name : | J4: 登録 | K4: SuperLogicID : | L4: =IF(LogicCommon!G4="","",LogicCommon!G4) -> MA.MAUDL5010
A5: * | E5: ACType :
A6: * | D6: 概要 : | E6: 検査パタンマスタの登録を行います。（ロケール用） | L6: ID | N6: ID | P6: ID | R6: ID
A7: # | I7: U | K7: o | L7: UPDATE.updMaster | M7: o | N7: MAIN.chkMaster | O7: o | Q7: o
A8: # | D8: ブロック名 Block Name | E8: 型 Type | G8: super/share | H8: 対象ブロック名 Target Block Name | K8: TargetName | L8: DBC.MA.MAM_INSP_PTN_LCL | M8: TargetName | N8: DBC.MA.MAM_INSP_PTN_LCL | O8: TargetName | Q8: TargetName | U8: ブロック備考 Block Remarks
A9: # | D9: 項目名 Field Name | E9: 型 Type | F9: 桁 Digits | G9: フルネーム Full Name | H9: 日本語名 Japanese Name | I9: 上り項目 Request Message Field | J9: 下り項目 Response Message Field | S9: 条件および編集方法 Conditions and Editing Methods | U9: 項目備考 Field Remarks
A10: # | K10: 上り項目 Request Message Field | L10: 下り項目 Response Message Field | M10: 上り項目 Request Message Field | N10: 下り項目 Response Message Field | O10: 上り項目 Request Message Field | P10: 下り項目 Response Message Field | Q10: 上り項目 Request Message Field | R10: 下り項目 Response Message Field
A11: 10 | B11: * | D11: InspPtnLcl_Upd01_Dtl | E11: L | G11: $share$ | H11: MA.MABCL0035.InspPtnLcl_UpdChk01.InspPtnLcl_UpdChk01_Dtl | K11: L | M11: L
A12: 10 | D12: insp_ptn_cd | E12: #MA.INSP_PTN_CD | G12: Inspection pattern cd. | H12: 検査パタンＣＤ | I12: E | K12: E | M12: E
A13: 10 | D13: lcl_cd | E13: #MA.LCL_CD | G13: Locale cd. | H13: ロケールＣＤ | I13: E | K13: E | M13: E
A14: 10 | D14: insp_ptn_nm | E14: #MA.INSP_PTN_NM | G14: Inspection pattern name | H14: 検査パタン名 | I14: E | K14: E | M14: E
A15: 10 | D15: memo1 | E15: #MA.MST_MEMO1 | G15: Memo 1 | H15: メモ１ | I15: E | K15: E | M15: E
A16: 10 | D16: memo2 | E16: #MA.MST_MEMO2 | G16: Memo 2 | H16: メモ２ | I16: E | K16: E | M16: E
A17: 10 | D17: memo3 | E17: #MA.MST_MEMO3 | G17: Memo 3 | H17: メモ３ | I17: E | K17: E | M17: E
A18: 10 | D18: upd_cntr | E18: #MA.UPD_CNT | G18: Update counter | H18: 更新カウンタ | I18: E | K18: E | M18: E
D19: 詳細 :

Sheet InspPtn_DelChk01
A1: * | B1: * | D1: L | E1: 1
A2: * | D2: オペレーション実装仕様書 Operation Specification Implementation Sheet | E2: ModuleID : | F2: =IF(LogicCommon!C2="","",LogicCommon!C2) -> MA | G2: LogicID : | H2: =IF(LogicCommon!E2="","",LogicCommon!E2) -> MABCL0035 | I2: Ope.ID : | J2: InspPtn_DelChk01 | K2: Pj.ID : | L2: =IF(LogicCommon!G2="","",LogicCommon!G2) -> MC | M2: Ope.Body : | N2: =L4 & ".Checker" -> MA.MAUDL5010.Checker
A3: * | D3: =IF(LogicCommon!A3="","",LogicCommon!A3) | E3: SubModuleID : | F3: =IF(LogicCommon!C3="","",LogicCommon!C3) -> MABC | G3: LogicClass : | H3: =IF(LogicCommon!E3="","",LogicCommon!E3) -> MABCL_MultiReg | I3: Ope.Method : | J3: @ | K3: SuperClassPj.ID : | L3: =IF(LogicCommon!G3="","",LogicCommon!G3) | M3: ReportID : | O3: Gene.Type : | P3: ALL
A4: * | E4: Version : | F4: 000000 | G4: LogicName : | H4: =IF(LogicCommon!E4="","",LogicCommon!E4) -> マルチマスタ登録 | I4: Ope.Name : | J4: チェック | K4: SuperLogicID : | L4: =IF(LogicCommon!G4="","",LogicCommon!G4) -> MA.MAUDL5010
A5: * | E5: ACType :
A6: * | D6: 概要 : | E6: 検査パタンマスタの削除前のチェックを行います。 | M6: ID
A7: # | I7: U | K7: K | L7: o
A8: # | D8: ブロック名 Block Name | E8: 型 Type | G8: super/share | H8: 対象ブロック名 Target Block Name | K8: REQUIRED | L8: TargetName | P8: ブロック備考 Block Remarks
A9: # | D9: 項目名 Field Name | E9: 型 Type | F9: 桁 Digits | G9: フルネーム Full Name | H9: 日本語名 Japanese Name | I9: 上り項目 Request Message Field | J9: 下り項目 Response Message Field | N9: 条件および編集方法 Conditions and Editing Methods | P9: 項目備考 Field Remarks
A10: # | L10: 上り項目 Request Message Field | M10: 下り項目 Response Message Field
A11: 10 | B11: * | D11: InspPtn_DelChk01_Dtl | E11: L
A12: 10 | D12: insp_ptn_cd | E12: #MA.INSP_PTN_CD | G12: Inspection pattern cd. | H12: 検査パタンＣＤ | I12: E | K12: E
A13: 10 | D13: upd_cntr | E13: #MA.UPD_CNT | G13: Update counter | H13: 更新カウンタ | I13: E
D14: 詳細 :

Sheet InspPtn_Del01
A1: * | B1: * | D1: L | E1: 1
A2: * | D2: オペレーション実装仕様書 Operation Specification Implementation Sheet | E2: ModuleID : | F2: =IF(LogicCommon!C2="","",LogicCommon!C2) -> MA | G2: LogicID : | H2: =IF(LogicCommon!E2="","",LogicCommon!E2) -> MABCL0035 | I2: Ope.ID : | J2: InspPtn_Del01 | K2: Pj.ID : | L2: =IF(LogicCommon!G2="","",LogicCommon!G2) -> MC | M2: Ope.Body : | N2: "mcframe.serverMAUD.MAUDL6020.MAUDL_LCLRLDeleter"
A3: * | D3: =IF(LogicCommon!A3="","",LogicCommon!A3) | E3: SubModuleID : | F3: =IF(LogicCommon!C3="","",LogicCommon!C3) -> MABC | G3: LogicClass : | H3: =IF(LogicCommon!E3="","",LogicCommon!E3) -> MABCL_MultiReg | I3: Ope.Method : | J3: @ | K3: SuperClassPj.ID : | L3: =IF(LogicCommon!G3="","",LogicCommon!G3) | M3: ReportID : | O3: Gene.Type : | P3: ALL
A4: * | E4: Version : | F4: 000000 | G4: LogicName : | H4: =IF(LogicCommon!E4="","",LogicCommon!E4) -> マルチマスタ登録 | I4: Ope.Name : | J4: 削除 | K4: SuperLogicID : | L4: =IF(LogicCommon!G4="","",LogicCommon!G4) -> MA.MAUDL5010
A5: * | E5: ACType :
A6: * | D6: 概要 : | E6: 検査パタンマスタの削除を行います。 | L6: ID | N6: ID | P6: ID | R6: ID
A7: # | I7: U | K7: o | L7: UPDATE.updMaster1 | M7: o | N7: UPDATE.updMaster2 | O7: o | Q7: o
A8: # | D8: ブロック名 Block Name | E8: 型 Type | G8: super/share | H8: 対象ブロック名 Target Block Name | K8: TargetName | L8: DBC.MA.MAM_INSP_PTN | M8: TargetName | N8: DBC.MA.MAM_INSP_PTN_LCL | O8: TargetName | Q8: TargetName | U8: ブロック備考 Block Remarks
A9: # | D9: 項目名 Field Name | E9: 型 Type | F9: 桁 Digits | G9: フルネーム Full Name | H9: 日本語名 Japanese Name | I9: 上り項目 Request Message Field | J9: 下り項目 Response Message Field | S9: 条件および編集方法 Conditions and Editing Methods | U9: 項目備考 Field Remarks
A10: # | K10: 上り項目 Request Message Field | L10: 下り項目 Response Message Field | M10: 上り項目 Request Message Field | N10: 下り項目 Response Message Field | O10: 上り項目 Request Message Field | P10: 下り項目 Response Message Field | Q10: 上り項目 Request Message Field | R10: 下り項目 Response Message Field
A11: 10 | B11: * | D11: InspPtn_Del01_Dtl | E11: L | G11: $share$ | H11: MA.MABCL0035.InspPtn_DelChk01.InspPtn_DelChk01_Dtl | K11: L | M11: L
A12: 10 | D12: insp_ptn_cd | E12: #MA.INSP_PTN_CD | G12: Inspection pattern cd. | H12: 検査パタンＣＤ | I12: E | K12: E | M12: E
A13: 10 | D13: upd_cntr | E13: #MA.UPD_CNT | G13: Update counter | H13: 更新カウンタ | I13: E | K13: E
D14: 詳細 :

Sheet WkDay_UpdChk01
A1: * | B1: * | D1: L | E1: 1
A2: * | D2: オペレーション実装仕様書 Operation Specification Implementation Sheet | E2: ModuleID : | F2: =IF(LogicCommon!C2="","",LogicCommon!C2) -> MA | G2: LogicID : | H2: =IF(LogicCommon!E2="","",LogicCommon!E2) -> MABCL0035 | I2: Ope.ID : | J2: WkDay_UpdChk01 | K2: Pj.ID : | L2: =IF(LogicCommon!G2="","",LogicCommon!G2) -> MC | M2: Ope.Body : | N2: =L4 & ".Checker" -> MA.MAUDL5010.Checker
A3: * | D3: =IF(LogicCommon!A3="","",LogicCommon!A3) | E3: SubModuleID : | F3: =IF(LogicCommon!C3="","",LogicCommon!C3) -> MABC | G3: LogicClass : | H3: =IF(LogicCommon!E3="","",LogicCommon!E3) -> MABCL_MultiReg | I3: Ope.Method : | J3: @ | K3: SuperClassPj.ID : | L3: =IF(LogicCommon!G3="","",LogicCommon!G3) | M3: ReportID : | O3: Gene.Type : | P3: ALL
A4: * | E4: Version : | F4: 000000 | G4: LogicName : | H4: =IF(LogicCommon!E4="","",LogicCommon!E4) -> マルチマスタ登録 | I4: Ope.Name : | J4: チェック | K4: SuperLogicID : | L4: =IF(LogicCommon!G4="","",LogicCommon!G4) -> MA.MAUDL5010
A5: * | E5: ACType :
A6: * | D6: 概要 : | E6: 勤務種類マスタの登録前のチェックを行います。 | M6: ID
A7: # | I7: U | K7: K | L7: o
A8: # | D8: ブロック名 Block Name | E8: 型 Type | G8: super/share | H8: 対象ブロック名 Target Block Name | K8: REQUIRED | L8: TargetName | P8: ブロック備考 Block Remarks
A9: # | D9: 項目名 Field Name | E9: 型 Type | F9: 桁 Digits | G9: フルネーム Full Name | H9: 日本語名 Japanese Name | I9: 上り項目 Request Message Field | J9: 下り項目 Response Message Field | N9: 条件および編集方法 Conditions and Editing Methods | P9: 項目備考 Field Remarks
A10: # | L10: 上り項目 Request Message Field | M10: 下り項目 Response Message Field
A11: 10 | B11: * | D11: WkDay_UpdChk01_Dtl | E11: L | G11: $super$ | H11: DBC:MA.MAM_WK_DAY
A12: 10 | D12: wk_day_cd | E12: #MA.WK_DAY_CD | G12: Work type cd. | H12: 勤務種類ＣＤ | I12: E | K12: E
A13: 10 | D13: wk_day_nm | E13: #MA.WK_DAY_NM | G13: Standard work classification name | H13: 標準勤務種類名 | I13: E | K13: E
A14: 10 | D14: memo1 | E14: #MA.MST_MEMO1 | G14: Memo 1 | H14: メモ１ | I14: E
A15: 10 | D15: memo2 | E15: #MA.MST_MEMO2 | G15: Memo 2 | H15: メモ２ | I15: E
A16: 10 | D16: memo3 | E16: #MA.MST_MEMO3 | G16: Memo 3 | H16: メモ３ | I16: E
A17: 10 | D17: del_flg | E17: #MA.FLG | G17: Logical delete | H17: 論理削除 | I17: E
A18: 10 | D18: upd_cntr | E18: #MA.UPD_CNT | G18: Update counter | H18: 更新カウンタ | I18: E
D19: 詳細 :

Sheet WkDay_Upd01
A1: * | B1: * | D1: L | E1: 1
A2: * | D2: オペレーション実装仕様書 Operation Specification Implementation Sheet | E2: ModuleID : | F2: =IF(LogicCommon!C2="","",LogicCommon!C2) -> MA | G2: LogicID : | H2: =IF(LogicCommon!E2="","",LogicCommon!E2) -> MABCL0035 | I2: Ope.ID : | J2: WkDay_Upd01 | K2: Pj.ID : | L2: =IF(LogicCommon!G2="","",LogicCommon!G2) -> MC | M2: Ope.Body : | N2: "mcframe.serverMAUD.MAUDL6020.MAUDL_LCLRLUpdater"
A3: * | D3: =IF(LogicCommon!A3="","",LogicCommon!A3) | E3: SubModuleID : | F3: =IF(LogicCommon!C3="","",LogicCommon!C3) -> MABC | G3: LogicClass : | H3: =IF(LogicCommon!E3="","",LogicCommon!E3) -> MABCL_MultiReg | I3: Ope.Method : | J3: @ | K3: SuperClassPj.ID : | L3: =IF(LogicCommon!G3="","",LogicCommon!G3) | M3: ReportID : | O3: Gene.Type : | P3: ALL
A4: * | E4: Version : | F4: 000000 | G4: LogicName : | H4: =IF(LogicCommon!E4="","",LogicCommon!E4) -> マルチマスタ登録 | I4: Ope.Name : | J4: 登録 | K4: SuperLogicID : | L4: =IF(LogicCommon!G4="","",LogicCommon!G4) -> MA.MAUDL5010
A5: * | E5: ACType :
A6: * | D6: 概要 : | E6: 勤務種類マスタの登録を行います。 | L6: ID | N6: ID | P6: ID | R6: ID
A7: # | I7: U | K7: o | L7: UPDATE.updMaster | M7: o | N7: MAIN.chkMaster | O7: o | Q7: o
A8: # | D8: ブロック名 Block Name | E8: 型 Type | G8: super/share | H8: 対象ブロック名 Target Block Name | K8: TargetName | L8: DBC.MA.MAM_WK_DAY | M8: TargetName | N8: DBC.MA.MAM_WK_DAY | O8: TargetName | Q8: TargetName | U8: ブロック備考 Block Remarks
A9: # | D9: 項目名 Field Name | E9: 型 Type | F9: 桁 Digits | G9: フルネーム Full Name | H9: 日本語名 Japanese Name | I9: 上り項目 Request Message Field | J9: 下り項目 Response Message Field | S9: 条件および編集方法 Conditions and Editing Methods | U9: 項目備考 Field Remarks
A10: # | K10: 上り項目 Request Message Field | L10: 下り項目 Response Message Field | M10: 上り項目 Request Message Field | N10: 下り項目 Response Message Field | O10: 上り項目 Request Message Field | P10: 下り項目 Response Message Field | Q10: 上り項目 Request Message Field | R10: 下り項目 Response Message Field
A11: 10 | B11: * | D11: WkDay_Upd01_Dtl | E11: L | G11: $share$ | H11: MA.MABCL0035.WkDay_UpdChk01.WkDay_UpdChk01_Dtl | K11: L | M11: L
A12: 10 | D12: wk_day_cd | E12: #MA.WK_DAY_CD | G12: Work type cd. | H12: 勤務種類ＣＤ | I12: E | K12: E | M12: E
A13: 10 | D13: wk_day_nm | E13: #MA.WK_DAY_NM | G13: Standard work classification name | H13: 標準勤務種類名 | I13: E | K13: E | M13: E
A14: 10 | D14: memo1 | E14: #MA.MST_MEMO1 | G14: Memo 1 | H14: メモ１ | I14: E | K14: E | M14: E
A15: 10 | D15: memo2 | E15: #MA.MST_MEMO2 | G15: Memo 2 | H15: メモ２ | I15: E | K15: E | M15: E
A16: 10 | D16: memo3 | E16: #MA.MST_MEMO3 | G16: Memo 3 | H16: メモ３ | I16: E | K16: E | M16: E
A17: 10 | D17: del_flg | E17: #MA.FLG | G17: Logical delete | H17: 論理削除 | I17: E | K17: E | M17: E
A18: 10 | D18: upd_cntr | E18: #MA.UPD_CNT | G18: Update counter | H18: 更新カウンタ | I18: E | K18: E | M18: E
D19: 詳細 :

Sheet WkDayLcl_UpdChk01
A1: * | B1: * | D1: L | E1: 1
A2: * | D2: オペレーション実装仕様書 Operation Specification Implementation Sheet | E2: ModuleID : | F2: =IF(LogicCommon!C2="","",LogicCommon!C2) -> MA | G2: LogicID : | H2: =IF(LogicCommon!E2="","",LogicCommon!E2) -> MABCL0035 | I2: Ope.ID : | J2: WkDayLcl_UpdChk01 | K2: Pj.ID : | L2: =IF(LogicCommon!G2="","",LogicCommon!G2) -> MC | M2: Ope.Body : | N2: =L4 & ".Checker" -> MA.MAUDL5010.Checker
A3: * | D3: =IF(LogicCommon!A3="","",LogicCommon!A3) | E3: SubModuleID : | F3: =IF(LogicCommon!C3="","",LogicCommon!C3) -> MABC | G3: LogicClass : | H3: =IF(LogicCommon!E3="","",LogicCommon!E3) -> MABCL_MultiReg | I3: Ope.Method : | J3: @ | K3: SuperClassPj.ID : | L3: =IF(LogicCommon!G3="","",LogicCommon!G3) | M3: ReportID : | O3: Gene.Type : | P3: ALL
A4: * | E4: Version : | F4: 000000 | G4: LogicName : | H4: =IF(LogicCommon!E4="","",LogicCommon!E4) -> マルチマスタ登録 | I4: Ope.Name : | J4: チェック | K4: SuperLogicID : | L4: =IF(LogicCommon!G4="","",LogicCommon!G4) -> MA.MAUDL5010
A5: * | E5: ACType :
A6: * | D6: 概要 : | E6: 勤務種類マスタの登録前のチェックを行います。（ロケール用） | M6: ID
A7: # | I7: U | K7: K | L7: o | M7: EXISTS.chk01
A8: # | D8: ブロック名 Block Name | E8: 型 Type | G8: super/share | H8: 対象ブロック名 Target Block Name | K8: REQUIRED | L8: TargetName | M8: DBC.MA.MAM_WK_DAY | P8: ブロック備考 Block Remarks
A9: # | D9: 項目名 Field Name | E9: 型 Type | F9: 桁 Digits | G9: フルネーム Full Name | H9: 日本語名 Japanese Name | I9: 上り項目 Request Message Field | J9: 下り項目 Response Message Field | N9: 条件および編集方法 Conditions and Editing Methods | P9: 項目備考 Field Remarks
A10: # | L10: 上り項目 Request Message Field | M10: 下り項目 Response Message Field
A11: 10 | B11: * | D11: WkDayLcl_UpdChk01_Dtl | E11: L | G11: $super$ | H11: DBC:MA.MAM_WK_DAY_LCL | L11: L
A12: 10 | D12: wk_day_cd | E12: #MA.WK_DAY_CD | G12: Work type cd. | H12: 勤務種類ＣＤ | I12: E | K12: E | L12: E
A13: 10 | D13: lcl_cd | E13: #MA.LCL_CD | G13: Locale cd. | H13: ロケールＣＤ | I13: E | K13: E
A14: 10 | D14: wk_day_nm | E14: #MA.WK_DAY_NM | G14: Work type name | H14: 勤務種類名 | I14: E | K14: E
A15: 10 | D15: memo1 | E15: #MA.MST_MEMO1 | G15: Memo 1 | H15: メモ１ | I15: E
A16: 10 | D16: memo2 | E16: #MA.MST_MEMO2 | G16: Memo 2 | H16: メモ２ | I16: E
A17: 10 | D17: memo3 | E17: #MA.MST_MEMO3 | G17: Memo 3 | H17: メモ３ | I17: E
A18: 10 | D18: upd_cntr | E18: #MA.UPD_CNT | G18: Update counter | H18: 更新カウンタ | I18: E
D19: 詳細 :

Sheet WkDayLcl_Upd01
A1: * | B1: * | D1: L | E1: 1
A2: * | D2: オペレーション実装仕様書 Operation Specification Implementation Sheet | E2: ModuleID : | F2: =IF(LogicCommon!C2="","",LogicCommon!C2) -> MA | G2: LogicID : | H2: =IF(LogicCommon!E2="","",LogicCommon!E2) -> MABCL0035 | I2: Ope.ID : | J2: WkDayLcl_Upd01 | K2: Pj.ID : | L2: =IF(LogicCommon!G2="","",LogicCommon!G2) -> MC | M2: Ope.Body : | N2: "mcframe.serverMAUD.MAUDL6020.MAUDL_LCLRLUpdater"
A3: * | D3: =IF(LogicCommon!A3="","",LogicCommon!A3) | E3: SubModuleID : | F3: =IF(LogicCommon!C3="","",LogicCommon!C3) -> MABC | G3: LogicClass : | H3: =IF(LogicCommon!E3="","",LogicCommon!E3) -> MABCL_MultiReg | I3: Ope.Method : | J3: @ | K3: SuperClassPj.ID : | L3: =IF(LogicCommon!G3="","",LogicCommon!G3) | M3: ReportID : | O3: Gene.Type : | P3: ALL
A4: * | E4: Version : | F4: 000000 | G4: LogicName : | H4: =IF(LogicCommon!E4="","",LogicCommon!E4) -> マルチマスタ登録 | I4: Ope.Name : | J4: 登録 | K4: SuperLogicID : | L4: =IF(LogicCommon!G4="","",LogicCommon!G4) -> MA.MAUDL5010
A5: * | E5: ACType :
A6: * | D6: 概要 : | E6: 勤務種類マスタの登録を行います。（ロケール用） | L6: ID | N6: ID | P6: ID | R6: ID
A7: # | I7: U | K7: o | L7: UPDATE.updMaster | M7: o | N7: MAIN.chkMaster | O7: o | Q7: o
A8: # | D8: ブロック名 Block Name | E8: 型 Type | G8: super/share | H8: 対象ブロック名 Target Block Name | K8: TargetName | L8: DBC.MA.MAM_WK_DAY_LCL | M8: TargetName | N8: DBC.MA.MAM_WK_DAY_LCL | O8: TargetName | Q8: TargetName | U8: ブロック備考 Block Remarks
A9: # | D9: 項目名 Field Name | E9: 型 Type | F9: 桁 Digits | G9: フルネーム Full Name | H9: 日本語名 Japanese Name | I9: 上り項目 Request Message Field | J9: 下り項目 Response Message Field | S9: 条件および編集方法 Conditions and Editing Methods | U9: 項目備考 Field Remarks
A10: # | K10: 上り項目 Request Message Field | L10: 下り項目 Response Message Field | M10: 上り項目 Request Message Field | N10: 下り項目 Response Message Field | O10: 上り項目 Request Message Field | P10: 下り項目 Response Message Field | Q10: 上り項目 Request Message Field | R10: 下り項目 Response Message Field
A11: 10 | B11: * | D11: WkDayLcl_Upd01_Dtl | E11: L | G11: $share$ | H11: MA.MABCL0035.WkDayLcl_UpdChk01.WkDayLcl_UpdChk01_Dtl | K11: L | M11: L
A12: 10 | D12: wk_day_cd | E12: #MA.WK_DAY_CD | G12: Work type cd. | H12: 勤務種類ＣＤ | I12: E | K12: E | M12: E
A13: 10 | D13: lcl_cd | E13: #MA.LCL_CD | G13: Locale cd. | H13: ロケールＣＤ | I13: E | K13: E | M13: E
A14: 10 | D14: wk_day_nm | E14: #MA.WK_DAY_NM | G14: Work type name | H14: 勤務種類名 | I14: E | K14: E | M14: E
A15: 10 | D15: memo1 | E15: #MA.MST_MEMO1 | G15: Memo 1 | H15: メモ１ | I15: E | K15: E | M15: E
A16: 10 | D16: memo2 | E16: #MA.MST_MEMO2 | G16: Memo 2 | H16: メモ２ | I16: E | K16: E | M16: E
A17: 10 | D17: memo3 | E17: #MA.MST_MEMO3 | G17: Memo 3 | H17: メモ３ | I17: E | K17: E | M17: E
A18: 10 | D18: upd_cntr | E18: #MA.UPD_CNT | G18: Update counter | H18: 更新カウンタ | I18: E | K18: E | M18: E
D19: 詳細 :

Sheet WkDay_DelChk01
A1: * | B1: * | D1: L | E1: 1
A2: * | D2: オペレーション実装仕様書 Operation Specification Implementation Sheet | E2: ModuleID : | F2: =IF(LogicCommon!C2="","",LogicCommon!C2) -> MA | G2: LogicID : | H2: =IF(LogicCommon!E2="","",LogicCommon!E2) -> MABCL0035 | I2: Ope.ID : | J2: WkDay_DelChk01 | K2: Pj.ID : | L2: =IF(LogicCommon!G2="","",LogicCommon!G2) -> MC | M2: Ope.Body : | N2: =L4 & ".Checker" -> MA.MAUDL5010.Checker
A3: * | D3: =IF(LogicCommon!A3="","",LogicCommon!A3) | E3: SubModuleID : | F3: =IF(LogicCommon!C3="","",LogicCommon!C3) -> MABC | G3: LogicClass : | H3: =IF(LogicCommon!E3="","",LogicCommon!E3) -> MABCL_MultiReg | I3: Ope.Method : | J3: @ | K3: SuperClassPj.ID : | L3: =IF(LogicCommon!G3="","",LogicCommon!G3) | M3: ReportID : | O3: Gene.Type : | P3: ALL
A4: * | E4: Version : | F4: 000000 | G4: LogicName : | H4: =IF(LogicCommon!E4="","",LogicCommon!E4) -> マルチマスタ登録 | I4: Ope.Name : | J4: チェック | K4: SuperLogicID : | L4: =IF(LogicCommon!G4="","",LogicCommon!G4) -> MA.MAUDL5010
A5: * | E5: ACType :
A6: * | D6: 概要 : | E6: 勤務種類マスタの削除前のチェックを行います。 | M6: ID
A7: # | I7: U | K7: K | L7: o
A8: # | D8: ブロック名 Block Name | E8: 型 Type | G8: super/share | H8: 対象ブロック名 Target Block Name | K8: REQUIRED | L8: TargetName | P8: ブロック備考 Block Remarks
A9: # | D9: 項目名 Field Name | E9: 型 Type | F9: 桁 Digits | G9: フルネーム Full Name | H9: 日本語名 Japanese Name | I9: 上り項目 Request Message Field | J9: 下り項目 Response Message Field | N9: 条件および編集方法 Conditions and Editing Methods | P9: 項目備考 Field Remarks
A10: # | L10: 上り項目 Request Message Field | M10: 下り項目 Response Message Field
A11: 10 | B11: * | D11: WkDay_DelChk01_Dtl | E11: L
A12: 10 | D12: wk_day_cd | E12: #MA.WK_DAY_CD | G12: Work type cd. | H12: 勤務種類ＣＤ | I12: E | K12: E
A13: 10 | D13: upd_cntr | E13: #MA.UPD_CNT | G13: Update counter | H13: 更新カウンタ | I13: E
D14: 詳細 :

Sheet WkDay_Del01
A1: * | B1: * | D1: L | E1: 1
A2: * | D2: オペレーション実装仕様書 Operation Specification Implementation Sheet | E2: ModuleID : | F2: =IF(LogicCommon!C2="","",LogicCommon!C2) -> MA | G2: LogicID : | H2: =IF(LogicCommon!E2="","",LogicCommon!E2) -> MABCL0035 | I2: Ope.ID : | J2: WkDay_Del01 | K2: Pj.ID : | L2: =IF(LogicCommon!G2="","",LogicCommon!G2) -> MC | M2: Ope.Body : | N2: "mcframe.serverMAUD.MAUDL6020.MAUDL_LCLRLDeleter"
A3: * | D3: =IF(LogicCommon!A3="","",LogicCommon!A3) | E3: SubModuleID : | F3: =IF(LogicCommon!C3="","",LogicCommon!C3) -> MABC | G3: LogicClass : | H3: =IF(LogicCommon!E3="","",LogicCommon!E3) -> MABCL_MultiReg | I3: Ope.Method : | J3: @ | K3: SuperClassPj.ID : | L3: =IF(LogicCommon!G3="","",LogicCommon!G3) | M3: ReportID : | O3: Gene.Type : | P3: ALL
A4: * | E4: Version : | F4: 000000 | G4: LogicName : | H4: =IF(LogicCommon!E4="","",LogicCommon!E4) -> マルチマスタ登録 | I4: Ope.Name : | J4: 削除 | K4: SuperLogicID : | L4: =IF(LogicCommon!G4="","",LogicCommon!G4) -> MA.MAUDL5010
A5: * | E5: ACType :
A6: * | D6: 概要 : | E6: 勤務種類マスタの削除を行います。 | L6: ID | N6: ID | P6: ID | R6: ID
A7: # | I7: U | K7: o | L7: UPDATE.updMaster1 | M7: o | N7: UPDATE.updMaster2 | O7: o | Q7: o
A8: # | D8: ブロック名 Block Name | E8: 型 Type | G8: super/share | H8: 対象ブロック名 Target Block Name | K8: TargetName | L8: DBC.MA.MAM_WK_DAY | M8: TargetName | N8: DBC.MA.MAM_WK_DAY_LCL | O8: TargetName | Q8: TargetName | U8: ブロック備考 Block Remarks
A9: # | D9: 項目名 Field Name | E9: 型 Type | F9: 桁 Digits | G9: フルネーム Full Name | H9: 日本語名 Japanese Name | I9: 上り項目 Request Message Field | J9: 下り項目 Response Message Field | S9: 条件および編集方法 Conditions and Editing Methods | U9: 項目備考 Field Remarks
A10: # | K10: 上り項目 Request Message Field | L10: 下り項目 Response Message Field | M10: 上り項目 Request Message Field | N10: 下り項目 Response Message Field | O10: 上り項目 Request Message Field | P10: 下り項目 Response Message Field | Q10: 上り項目 Request Message Field | R10: 下り項目 Response Message Field
A11: 10 | B11: * | D11: WkDay_Del01_Dtl | E11: L | G11: $share$ | H11: MA.MABCL0035.WkDay_DelChk01.WkDay_DelChk01_Dtl | K11: L | M11: L
A12: 10 | D12: wk_day_cd | E12: #MA.WK_DAY_CD | G12: Work type cd. | H12: 勤務種類ＣＤ | I12: E | K12: E | M12: E
A13: 10 | D13: upd_cntr | E13: #MA.UPD_CNT | G13: Update counter | H13: 更新カウンタ | I13: E | K13: E
D14: 詳細 :

Sheet ShipTerm_UpdChk01
A1: * | B1: * | D1: L | E1: 1
A2: * | D2: オペレーション実装仕様書 Operation Specification Implementation Sheet | E2: ModuleID : | F2: =IF(LogicCommon!C2="","",LogicCommon!C2) -> MA | G2: LogicID : | H2: =IF(LogicCommon!E2="","",LogicCommon!E2) -> MABCL0035 | I2: Ope.ID : | J2: ShipTerm_UpdChk01 | K2: Pj.ID : | L2: =IF(LogicCommon!G2="","",LogicCommon!G2) -> MC | M2: Ope.Body : | N2: =L4 & ".Checker" -> MA.MAUDL5010.Checker
