Workbook

Sheet LogicCommon
A2: ロジック共通定義 | B2: ModuleID : | C2: MA | D2: LogicID : | E2: MABCL0400 | F2: Pj.ID : | G2: MC
B3: SubModuleID : | C3: MABC | D3: LogicClass : | E3: MABCL_ItmRlsReg | F3: SuperClassPj.ID :
D4: LogicName : | E4: 品目リリース登録 | F4: SuperLogicID : | G4: MA.MAUDL5010
A5: 概要 :
A6: 詳細 :

Sheet ItmRls_UpdChk01
A1: * | B1: * | D1: L | E1: 1
A2: * | D2: オペレーション実装仕様書 Operation Specification Implementation Sheet | E2: ModuleID : | F2: =IF(LogicCommon!C2="","",LogicCommon!C2) -> MA | G2: LogicID : | H2: =IF(LogicCommon!E2="","",LogicCommon!E2) -> MABCL0400 | I2: Ope.ID : | J2: ItmRls_UpdChk01 | K2: Pj.ID : | L2: =IF(LogicCommon!G2="","",LogicCommon!G2) -> MC | M2: Ope.Body : | N2: =L4 & ".Checker" -> MA.MAUDL5010.Checker
A3: * | D3: =IF(LogicCommon!A3="","",LogicCommon!A3) | E3: SubModuleID : | F3: =IF(LogicCommon!C3="","",LogicCommon!C3) -> MABC | G3: LogicClass : | H3: =IF(LogicCommon!E3="","",LogicCommon!E3) -> MABCL_ItmRlsReg | I3: Ope.Method : | J3: @ | K3: SuperClassPj.ID : | L3: =IF(LogicCommon!G3="","",LogicCommon!G3) | M3: ReportID : | O3: Gene.Type : | P3: ALL
A4: * | E4: Version : | F4: 000000 | G4: LogicName : | H4: =IF(LogicCommon!E4="","",LogicCommon!E4) -> 品目リリース登録 | I4: Ope.Name : | J4: 登録前チェック | K4: SuperLogicID : | L4: =IF(LogicCommon!G4="","",LogicCommon!G4) -> MA.MAUDL5010
A5: * | E5: ACType :
A6: * | D6: 概要 : | E6: 品目マスタのリリース情報を登録する前のチェックを行う | S6: ID
A7: # | I7: U | K7: K | L7: K | M7: K | N7: K | O7: K | P7: K | Q7: K | R7: o
A8: # | D8: ブロック名 Block Name | E8: 型 Type | G8: super/share | H8: 対象ブロック名 Target Block Name | K8: NULL_VAL | L8: REQUIRED | M8: LIST_LOGIC | N8: LIST_IN | O8: LIST_IN_BASE | P8: LIST_OUT | Q8: LIST_OUT_BASE | R8: TargetName | V8: ブロック備考 Block Remarks
A9: # | D9: 項目名 Field Name | E9: 型 Type | F9: 桁 Digits | G9: フルネーム Full Name | H9: 日本語名 Japanese Name | I9: 上り項目 Request Message Field | J9: 下り項目 Response Message Field | T9: 条件および編集方法 Conditions and Editing Methods | V9: 項目備考 Field Remarks
A10: # | R10: 上り項目 Request Message Field | S10: 下り項目 Response Message Field
A11: 10 | B11: * | D11: ItmRls_UpdChk01_Dtl | E11: L
A12: 10 | D12: itm_cd | E12: #MA.ITM_CD | G12: Item cd. | H12: 品目ＣＤ | I12: E | L12: E
A13: 10 | D13: itm_sub1 | E13: #MA.ITM_SUB1 | G13: Branch No. 1 | H13: 枝番１ | I13: E | K13: E
A14: 10 | D14: itm_sub2 | E14: #MA.ITM_SUB2 | G14: Branch No. 2 | H14: 枝番２ | I14: E | K14: E
A15: 10 | D15: itm_sub3 | E15: #MA.ITM_SUB3 | G15: Branch No. 3 | H15: 枝番３ | I15: E | K15: E | M15: MA.MAUAL0010.ItmSub3 | N15: MAC_ITM_IS_SRCH_TYP.COMM;itm_cd;itm_sub1;itm_sub2;true;true | O15: itm_is_srch_typ;itm_cd;itm_sub1;itm_sub2;release_flg_on;release_flg_off | P15: ship_unit_cd;mfg_unit_cd;purc_unit_cd;pckg_unit_cd | Q15: ship_unit_cd;mfg_unit_cd;purc_unit_cd;pckg_unit_cd
A16: 10 | D16: ship_unit_cd | E16: #MA.UNIT_CD | G16: Shipping unit cd. | H16: 出荷単位ＣＤ
A17: 10 | D17: mfg_unit_cd | E17: #MA.UNIT_CD | G17: Mfg. unit cd. | H17: 製造単位ＣＤ
A18: 10 | D18: purc_unit_cd | E18: #MA.UNIT_CD | G18: PO unit cd. | H18: 発注単位ＣＤ
A19: 10 | D19: pckg_unit_cd | E19: #MA.UNIT_CD | G19: Packing unit cd. | H19: 梱包単位ＣＤ
A20: 10 | D20: memo1 | E20: #MA.MST_MEMO1 | G20: Memo 1 | H20: メモ１ | I20: E
A21: 10 | D21: memo2 | E21: #MA.MST_MEMO2 | G21: Memo 2 | H21: メモ２ | I21: E
A22: 10 | D22: memo3 | E22: #MA.MST_MEMO3 | G22: Memo 3 | H22: メモ３ | I22: E
A23: 10 | D23: release_flg | E23: #MA.FLG | G23: Release | H23: リリース
A24: 10 | D24: release_usr_cd | E24: #MA.USR_CD | G24: Release PIC name cd. | H24: リリース担当者ＣＤ
A25: 10 | D25: release_tm | E25: #MA.TM | G25: Release date and time | H25: リリース日時
A26: 10 | D26: co_cd | E26: #MA.CO_CD | G26: Company cd. | H26: 会社ＣＤ
A27: 10 | D27: upd_cntr | E27: #MA.UPD_CNT | G27: Update counter | H27: 更新カウンタ | I27: E
D28: 詳細 :

Sheet ItmRls_Upd01
A1: * | B1: * | D1: L | E1: 1
A2: * | D2: オペレーション実装仕様書 Operation Specification Implementation Sheet | E2: ModuleID : | F2: =IF(LogicCommon!C2="","",LogicCommon!C2) -> MA | G2: LogicID : | H2: =IF(LogicCommon!E2="","",LogicCommon!E2) -> MABCL0400 | I2: Ope.ID : | J2: ItmRls_Upd01 | K2: Pj.ID : | L2: =IF(LogicCommon!G2="","",LogicCommon!G2) -> MC | M2: Ope.Body : | N2: "mcframe.serverMAUD.MAUDL6010.MAUDL_RLUpdater"
A3: * | D3: =IF(LogicCommon!A3="","",LogicCommon!A3) | E3: SubModuleID : | F3: =IF(LogicCommon!C3="","",LogicCommon!C3) -> MABC | G3: LogicClass : | H3: =IF(LogicCommon!E3="","",LogicCommon!E3) -> MABCL_ItmRlsReg | I3: Ope.Method : | J3: @ | K3: SuperClassPj.ID : | L3: =IF(LogicCommon!G3="","",LogicCommon!G3) | M3: ReportID : | O3: Gene.Type : | P3: ALL
A4: * | E4: Version : | F4: 000000 | G4: LogicName : | H4: =IF(LogicCommon!E4="","",LogicCommon!E4) -> 品目リリース登録 | I4: Ope.Name : | J4: 登録処理 | K4: SuperLogicID : | L4: =IF(LogicCommon!G4="","",LogicCommon!G4) -> MA.MAUDL5010
A5: * | E5: ACType :
A6: * | D6: 概要 : | E6: 品目マスタのリリース情報を登録する | L6: ID | N6: ID | P6: ID | R6: ID
A7: # | I7: U | K7: o | L7: UPDATE.updMaster | M7: o | N7: MAIN.chkMaster | O7: o | Q7: o
A8: # | D8: ブロック名 Block Name | E8: 型 Type | G8: super/share | H8: 対象ブロック名 Target Block Name | K8: TargetName | L8: DBC.MA.MAM_ITM_COM | M8: TargetName | N8: DBC.MA.MAM_ITM_COM | O8: TargetName | Q8: TargetName | U8: ブロック備考 Block Remarks
A9: # | D9: 項目名 Field Name | E9: 型 Type | F9: 桁 Digits | G9: フルネーム Full Name | H9: 日本語名 Japanese Name | I9: 上り項目 Request Message Field | J9: 下り項目 Response Message Field | S9: 条件および編集方法 Conditions and Editing Methods | U9: 項目備考 Field Remarks
A10: # | K10: 上り項目 Request Message Field | L10: 下り項目 Response Message Field | M10: 上り項目 Request Message Field | N10: 下り項目 Response Message Field | O10: 上り項目 Request Message Field | P10: 下り項目 Response Message Field | Q10: 上り項目 Request Message Field | R10: 下り項目 Response Message Field
A11: 10 | B11: * | D11: ItmRls_Upd01_Dtl | E11: L | G11: $share$ | H11: MA.MABCL0400.ItmRls_UpdChk01.ItmRls_UpdChk01_Dtl | K11: L | M11: L
A12: 10 | D12: itm_cd | E12: #MA.ITM_CD | G12: Item cd. | H12: 品目ＣＤ | I12: E | K12: E | M12: E
A13: 10 | D13: itm_sub1 | E13: #MA.ITM_SUB1 | G13: Branch No. 1 | H13: 枝番１ | I13: E | K13: E | M13: E
A14: 10 | D14: itm_sub2 | E14: #MA.ITM_SUB2 | G14: Branch No. 2 | H14: 枝番２ | I14: E | K14: E | M14: E
A15: 10 | D15: itm_sub3 | E15: #MA.ITM_SUB3 | G15: Branch No. 3 | H15: 枝番３ | I15: E | K15: E | M15: E
A16: 10 | D16: memo1 | E16: #MA.MST_MEMO1 | G16: Memo 1 | H16: メモ１ | I16: E | K16: E
A17: 10 | D17: memo2 | E17: #MA.MST_MEMO2 | G17: Memo 2 | H17: メモ２ | I17: E | K17: E
A18: 10 | D18: memo3 | E18: #MA.MST_MEMO3 | G18: Memo 3 | H18: メモ３ | I18: E | K18: E
A19: 10 | D19: release_flg | E19: #MA.FLG | G19: Release | H19: リリース | I19: E | K19: E
A20: 10 | D20: release_usr_cd | E20: #MA.USR_CD | G20: Release PIC name cd. | H20: リリース担当者ＣＤ | I20: E | K20: E
A21: 10 | D21: release_tm | E21: #MA.TM | G21: Release date and time | H21: リリース日時 | I21: E | K21: E
A22: 10 | D22: co_cd | E22: #MA.CO_CD | G22: Company cd. | H22: 会社ＣＤ | I22: E | K22: E
A23: 10 | D23: upd_cntr | E23: #MA.UPD_CNT | G23: Update counter | H23: 更新カウンタ | I23: E | K23: E
D24: 詳細 :

Sheet ItmRls_DelChk01
A1: * | B1: * | D1: L | E1: 1
A2: * | D2: オペレーション実装仕様書 Operation Specification Implementation Sheet | E2: ModuleID : | F2: =IF(LogicCommon!C2="","",LogicCommon!C2) -> MA | G2: LogicID : | H2: =IF(LogicCommon!E2="","",LogicCommon!E2) -> MABCL0400 | I2: Ope.ID : | J2: ItmRls_DelChk01 | K2: Pj.ID : | L2: =IF(LogicCommon!G2="","",LogicCommon!G2) -> MC | M2: Ope.Body : | N2: =L4 & ".Checker" -> MA.MAUDL5010.Checker
A3: * | D3: =IF(LogicCommon!A3="","",LogicCommon!A3) | E3: SubModuleID : | F3: =IF(LogicCommon!C3="","",LogicCommon!C3) -> MABC | G3: LogicClass : | H3: =IF(LogicCommon!E3="","",LogicCommon!E3) -> MABCL_ItmRlsReg | I3: Ope.Method : | J3: @ | K3: SuperClassPj.ID : | L3: =IF(LogicCommon!G3="","",LogicCommon!G3) | M3: ReportID : | O3: Gene.Type : | P3: ALL
A4: * | E4: Version : | F4: 000000 | G4: LogicName : | H4: =IF(LogicCommon!E4="","",LogicCommon!E4) -> 品目リリース登録 | I4: Ope.Name : | J4: 取消前チェック | K4: SuperLogicID : | L4: =IF(LogicCommon!G4="","",LogicCommon!G4) -> MA.MAUDL5010
A5: * | E5: ACType :
A6: * | D6: 概要 : | E6: 品目マスタのリリース情報を取り消す前のチェックを行う | N6: ID
A7: # | I7: U | K7: K | L7: K | M7: o
A8: # | D8: ブロック名 Block Name | E8: 型 Type | G8: super/share | H8: 対象ブロック名 Target Block Name | K8: NULL_VAL | L8: REQUIRED | M8: TargetName | Q8: ブロック備考 Block Remarks
A9: # | D9: 項目名 Field Name | E9: 型 Type | F9: 桁 Digits | G9: フルネーム Full Name | H9: 日本語名 Japanese Name | I9: 上り項目 Request Message Field | J9: 下り項目 Response Message Field | O9: 条件および編集方法 Conditions and Editing Methods | Q9: 項目備考 Field Remarks
A10: # | M10: 上り項目 Request Message Field | N10: 下り項目 Response Message Field
A11: 10 | B11: * | D11: ItmRls_DelChk01_Dtl | E11: L
A12: 10 | D12: itm_cd | E12: #MA.ITM_CD | G12: Item cd. | H12: 品目ＣＤ | I12: E | L12: E
A13: 10 | D13: itm_sub1 | E13: #MA.ITM_SUB1 | G13: Branch No. 1 | H13: 枝番１ | I13: E | L13: E
A14: 10 | D14: itm_sub2 | E14: #MA.ITM_SUB2 | G14: Branch No. 2 | H14: 枝番２ | I14: E | L14: E
A15: 10 | D15: itm_sub3 | E15: #MA.ITM_SUB3 | G15: Branch No. 3 | H15: 枝番３ | I15: E | L15: E
A16: 10 | D16: memo1 | E16: #MA.MST_MEMO1 | G16: Memo 1 | H16: メモ１ | I16: E
A17: 10 | D17: memo2 | E17: #MA.MST_MEMO2 | G17: Memo 2 | H17: メモ２ | I17: E
A18: 10 | D18: memo3 | E18: #MA.MST_MEMO3 | G18: Memo 3 | H18: メモ３ | I18: E
A19: 10 | D19: release_flg | E19: #MA.FLG | G19: Release | H19: リリース
A20: 10 | D20: release_usr_cd | E20: #MA.USR_CD | G20: Release PIC name cd. | H20: リリース担当者ＣＤ
A21: 10 | D21: release_tm | E21: #MA.TM | G21: Release date and time | H21: リリース日時
A22: 10 | D22: co_cd | E22: #MA.CO_CD | G22: Company cd. | H22: 会社ＣＤ
A23: 10 | D23: upd_cntr | E23: #MA.UPD_CNT | G23: Update counter | H23: 更新カウンタ | I23: E
D24: 詳細 :

Sheet ItmRls_Del01
A1: * | B1: * | D1: L | E1: 1
A2: * | D2: オペレーション実装仕様書 Operation Specification Implementation Sheet | E2: ModuleID : | F2: =IF(LogicCommon!C2="","",LogicCommon!C2) -> MA | G2: LogicID : | H2: =IF(LogicCommon!E2="","",LogicCommon!E2) -> MABCL0400 | I2: Ope.ID : | J2: ItmRls_Del01 | K2: Pj.ID : | L2: =IF(LogicCommon!G2="","",LogicCommon!G2) -> MC | M2: Ope.Body : | N2: "mcframe.serverMAUD.MAUDL6010.MAUDL_RLUpdater"
A3: * | D3: =IF(LogicCommon!A3="","",LogicCommon!A3) | E3: SubModuleID : | F3: =IF(LogicCommon!C3="","",LogicCommon!C3) -> MABC | G3: LogicClass : | H3: =IF(LogicCommon!E3="","",LogicCommon!E3) -> MABCL_ItmRlsReg | I3: Ope.Method : | J3: @ | K3: SuperClassPj.ID : | L3: =IF(LogicCommon!G3="","",LogicCommon!G3) | M3: ReportID : | O3: Gene.Type : | P3: ALL
A4: * | E4: Version : | F4: 000000 | G4: LogicName : | H4: =IF(LogicCommon!E4="","",LogicCommon!E4) -> 品目リリース登録 | I4: Ope.Name : | J4: 取消処理 | K4: SuperLogicID : | L4: =IF(LogicCommon!G4="","",LogicCommon!G4) -> MA.MAUDL5010
A5: * | E5: ACType :
A6: * | D6: 概要 : | E6: 品目マスタのリリース情報を取り消す | L6: ID | N6: ID
A7: # | I7: U | K7: o | L7: UPDATE.updMaster1 | M7: o | N7: MAIN.chkMaster
A8: # | D8: ブロック名 Block Name | E8: 型 Type | G8: super/share | H8: 対象ブロック名 Target Block Name | K8: TargetName | L8: DBC.MA.MAM_ITM_COM | M8: TargetName | N8: DBC.MA.MAM_ITM_COM | Q8: ブロック備考 Block Remarks
A9: # | D9: 項目名 Field Name | E9: 型 Type | F9: 桁 Digits | G9: フルネーム Full Name | H9: 日本語名 Japanese Name | I9: 上り項目 Request Message Field | J9: 下り項目 Response Message Field | O9: 条件および編集方法 Conditions and Editing Methods | Q9: 項目備考 Field Remarks
A10: # | K10: 上り項目 Request Message Field | L10: 下り項目 Response Message Field | M10: 上り項目 Request Message Field | N10: 下り項目 Response Message Field
A11: 10 | B11: * | D11: ItmRls_Del01_Dtl | E11: L | G11: $share$ | H11: MA.MABCL0400.ItmRls_DelChk01.ItmRls_DelChk01_Dtl | K11: L | M11: L
A12: 10 | D12: itm_cd | E12: #MA.ITM_CD | G12: Item cd. | H12: 品目ＣＤ | I12: E | K12: E | M12: E
A13: 10 | D13: itm_sub1 | E13: #MA.ITM_SUB1 | G13: Branch No. 1 | H13: 枝番１ | I13: E | K13: E | M13: E
A14: 10 | D14: itm_sub2 | E14: #MA.ITM_SUB2 | G14: Branch No. 2 | H14: 枝番２ | I14: E | K14: E | M14: E
A15: 10 | D15: itm_sub3 | E15: #MA.ITM_SUB3 | G15: Branch No. 3 | H15: 枝番３ | I15: E | K15: E | M15: E
A16: 10 | D16: memo1 | E16: #MA.MST_MEMO1 | G16: Memo 1 | H16: メモ１ | I16: E | K16: E
A17: 10 | D17: memo2 | E17: #MA.MST_MEMO2 | G17: Memo 2 | H17: メモ２ | I17: E | K17: E
A18: 10 | D18: memo3 | E18: #MA.MST_MEMO3 | G18: Memo 3 | H18: メモ３ | I18: E | K18: E
A19: 10 | D19: release_flg | E19: #MA.FLG | G19: Release | H19: リリース | I19: E | K19: E
A20: 10 | D20: release_usr_cd | E20: #MA.USR_CD | G20: Release PIC name cd. | H20: リリース担当者ＣＤ | I20: E | K20: E
A21: 10 | D21: release_tm | E21: #MA.TM | G21: Release date and time | H21: リリース日時 | I21: E | K21: E
A22: 10 | D22: co_cd | E22: #MA.CO_CD | G22: Company cd. | H22: 会社ＣＤ | I22: E | K22: E
A23: 10 | D23: upd_cntr | E23: #MA.UPD_CNT | G23: Update counter | H23: 更新カウンタ | I23: E | K23: E
D24: 詳細 :

Sheet ItmRls_UpdChk02
A1: * | B1: * | D1: L | E1: 1
A2: * | D2: オペレーション実装仕様書 Operation Specification Implementation Sheet | E2: ModuleID : | F2: =IF(LogicCommon!C2="","",LogicCommon!C2) -> MA | G2: LogicID : | H2: =IF(LogicCommon!E2="","",LogicCommon!E2) -> MABCL0400 | I2: Ope.ID : | J2: ItmRls_UpdChk02 | K2: Pj.ID : | L2: =IF(LogicCommon!G2="","",LogicCommon!G2) -> MC | M2: Ope.Body : | N2: =L4 & ".Checker" -> MA.MAUDL5010.Checker
A3: * | D3: =IF(LogicCommon!A3="","",LogicCommon!A3) | E3: SubModuleID : | F3: =IF(LogicCommon!C3="","",LogicCommon!C3) -> MABC | G3: LogicClass : | H3: =IF(LogicCommon!E3="","",LogicCommon!E3) -> MABCL_ItmRlsReg | I3: Ope.Method : | J3: @ | K3: SuperClassPj.ID : | L3: =IF(LogicCommon!G3="","",LogicCommon!G3) | M3: ReportID : | O3: Gene.Type : | P3: ALL
A4: * | E4: Version : | F4: 000000 | G4: LogicName : | H4: =IF(LogicCommon!E4="","",LogicCommon!E4) -> 品目リリース登録 | I4: Ope.Name : | J4: 登録前チェック（原価管理） | K4: SuperLogicID : | L4: =IF(LogicCommon!G4="","",LogicCommon!G4) -> MA.MAUDL5010
A5: * | E5: ACType :
A6: * | D6: 概要 : | E6: 品目マスタのリリース情報を原価管理に反映する前のチェックを行う | Q6: ID
A7: # | I7: U | K7: K | L7: K | M7: K | N7: K | O7: K | P7: o
A8: # | D8: ブロック名 Block Name | E8: 型 Type | G8: super/share | H8: 対象ブロック名 Target Block Name | K8: NULL_VAL | L8: REQUIRED | M8: LIST_LOGIC | N8: LIST_IN | O8: LIST_IN_BASE | P8: TargetName | T8: ブロック備考 Block Remarks
A9: # | D9: 項目名 Field Name | E9: 型 Type | F9: 桁 Digits | G9: フルネーム Full Name | H9: 日本語名 Japanese Name | I9: 上り項目 Request Message Field | J9: 下り項目 Response Message Field | R9: 条件および編集方法 Conditions and Editing Methods | T9: 項目備考 Field Remarks
A10: # | P10: 上り項目 Request Message Field | Q10: 下り項目 Response Message Field
A11: 10 | B11: * | D11: ItmRls_UpdChk02_Dtl | E11: L
A12: 10 | D12: itm_cd | E12: #MA.ITM_CD | G12: Item cd. | H12: 品目ＣＤ | I12: E | L12: E
A13: 10 | D13: itm_sub1 | E13: #MA.ITM_SUB1 | G13: Branch No. 1 | H13: 枝番１ | I13: E | K13: E
A14: 10 | D14: itm_sub2 | E14: #MA.ITM_SUB2 | G14: Branch No. 2 | H14: 枝番２ | I14: E | K14: E
A15: 10 | D15: itm_sub3 | E15: #MA.ITM_SUB3 | G15: Branch No. 3 | H15: 枝番３ | I15: E | K15: E | M15: MA.MAUAL0010.ItmSub3 | N15: MAC_ITM_IS_SRCH_TYP.COMM;itm_cd;itm_sub1;itm_sub2;true;true | O15: itm_is_srch_typ;itm_cd;itm_sub1;itm_sub2;release_flg_on;release_flg_off
P16: 上り項目 Request Message Field | Q16: 下り項目 Response Message Field
A17: 20 | B17: * | D17: ItmRls_UpdChk02_Cnd | E17: R
A18: 20 | D18: term | E18: #MA.YM | G18: Term | H18: 期 | I18: E | L18: E | M18: MA.MAUAL0010.Term
A19: 20 | D19: tgt_dt | E19: #MA.DT | G19: Date | H19: 対象日 | I19: E
D20: 詳細 :

Sheet ItmRls_Upd02
A1: * | B1: * | D1: L | E1: 1
A2: * | D2: オペレーション実装仕様書 Operation Specification Implementation Sheet | E2: ModuleID : | F2: =IF(LogicCommon!C2="","",LogicCommon!C2) -> MA | G2: LogicID : | H2: =IF(LogicCommon!E2="","",LogicCommon!E2) -> MABCL0400 | I2: Ope.ID : | J2: ItmRls_Upd02 | K2: Pj.ID : | L2: =IF(LogicCommon!G2="","",LogicCommon!G2) -> MC | M2: Ope.Body : | N2: "mcframe.serverMAUD.MAUDL6010.MAUDL_RLUpdater"
A3: * | D3: =IF(LogicCommon!A3="","",LogicCommon!A3) | E3: SubModuleID : | F3: =IF(LogicCommon!C3="","",LogicCommon!C3) -> MABC | G3: LogicClass : | H3: =IF(LogicCommon!E3="","",LogicCommon!E3) -> MABCL_ItmRlsReg | I3: Ope.Method : | J3: @ | K3: SuperClassPj.ID : | L3: =IF(LogicCommon!G3="","",LogicCommon!G3) | M3: ReportID : | O3: Gene.Type : | P3: ALL
A4: * | E4: Version : | F4: 000000 | G4: LogicName : | H4: =IF(LogicCommon!E4="","",LogicCommon!E4) -> 品目リリース登録 | I4: Ope.Name : | J4: 登録処理（原価管理） | K4: SuperLogicID : | L4: =IF(LogicCommon!G4="","",LogicCommon!G4) -> MA.MAUDL5010
A5: * | E5: ACType :
A6: * | D6: 概要 : | E6: 品目マスタのリリース情報を原価管理に反映する前のチェックを行う | L6: ID | N6: ID | P6: ID | R6: ID
A7: # | I7: U | K7: o | M7: o | O7: o | Q7: o
A8: # | D8: ブロック名 Block Name | E8: 型 Type | G8: super/share | H8: 対象ブロック名 Target Block Name | K8: TargetName | M8: TargetName | O8: TargetName | Q8: TargetName | U8: ブロック備考 Block Remarks
A9: # | D9: 項目名 Field Name | E9: 型 Type | F9: 桁 Digits | G9: フルネーム Full Name | H9: 日本語名 Japanese Name | I9: 上り項目 Request Message Field | J9: 下り項目 Response Message Field | S9: 条件および編集方法 Conditions and Editing Methods | U9: 項目備考 Field Remarks
A10: # | K10: 上り項目 Request Message Field | L10: 下り項目 Response Message Field | M10: 上り項目 Request Message Field | N10: 下り項目 Response Message Field | O10: 上り項目 Request Message Field | P10: 下り項目 Response Message Field | Q10: 上り項目 Request Message Field | R10: 下り項目 Response Message Field
A11: 10 | B11: * | D11: ItmRls_Upd02_Dtl | E11: L | G11: $share$ | H11: MA.MABCL0400.ItmRls_UpdChk02.ItmRls_UpdChk02_Dtl
A12: 10 | D12: itm_cd | E12: #MA.ITM_CD | G12: Item cd. | H12: 品目ＣＤ | I12: E
A13: 10 | D13: itm_sub1 | E13: #MA.ITM_SUB1 | G13: Branch No. 1 | H13: 枝番１ | I13: E
A14: 10 | D14: itm_sub2 | E14: #MA.ITM_SUB2 | G14: Branch No. 2 | H14: 枝番２ | I14: E
A15: 10 | D15: itm_sub3 | E15: #MA.ITM_SUB3 | G15: Branch No. 3 | H15: 枝番３ | I15: E
K16: 上り項目 Request Message Field | L16: 下り項目 Response Message Field | M16: 上り項目 Request Message Field | N16: 下り項目 Response Message Field | O16: 上り項目 Request Message Field | P16: 下り項目 Response Message Field | Q16: 上り項目 Request Message Field | R16: 下り項目 Response Message Field
A17: 20 | B17: * | D17: ItmRls_Upd02_Cnd | E17: R | G17: $share$ | H17: MA.MABCL0400.ItmRls_UpdChk02.ItmRls_UpdChk02_Cnd
A18: 20 | D18: term | E18: #MA.YM | G18: Term | H18: 期 | I18: E
A19: 20 | D19: tgt_dt | E19: #MA.DT | G19: Date | H19: 対象日 | I19: E
D20: 詳細 :

Sheet Srch01
A1: * | B1: * | D1: L | E1: 1
A2: * | D2: オペレーション実装仕様書 Operation Specification Implementation Sheet | E2: ModuleID : | F2: =IF(LogicCommon!C2="","",LogicCommon!C2) -> MA | G2: LogicID : | H2: =IF(LogicCommon!E2="","",LogicCommon!E2) -> MABCL0400 | I2: Ope.ID : | J2: Srch01 | K2: Pj.ID : | L2: =IF(LogicCommon!G2="","",LogicCommon!G2) -> MC | M2: Ope.Body : | N2: "mcframe.serverMAUD.MAUDL6010.MAUDL_RLSearcher"
A3: * | D3: =IF(LogicCommon!A3="","",LogicCommon!A3) | E3: SubModuleID : | F3: =IF(LogicCommon!C3="","",LogicCommon!C3) -> MABC | G3: LogicClass : | H3: =IF(LogicCommon!E3="","",LogicCommon!E3) -> MABCL_ItmRlsReg | I3: Ope.Method : | J3: @ | K3: SuperClassPj.ID : | L3: =IF(LogicCommon!G3="","",LogicCommon!G3) | M3: ReportID : | O3: Gene.Type : | P3: ALL
A4: * | E4: Version : | F4: 000000 | G4: LogicName : | H4: =IF(LogicCommon!E4="","",LogicCommon!E4) -> 品目リリース登録 | I4: Ope.Name : | J4: 検索 | K4: SuperLogicID : | L4: =IF(LogicCommon!G4="","",LogicCommon!G4) -> MA.MAUDL5010
A5: * | E5: ACType :
A6: * | D6: 概要 : | E6: 検索処理を行う | M6: ID | O6: ID
A7: # | I7: U | K7: K | L7: o | M7: SELECT.c0 | N7: o
A8: # | D8: ブロック名 Block Name | E8: 型 Type | G8: super/share | H8: 対象ブロック名 Target Block Name | K8: CONST | L8: TargetName | M8: DBC.MA.MAM_ITM_ | N8: TargetName | R8: ブロック備考 Block Remarks
A9: # | D9: 項目名 Field Name | E9: 型 Type | F9: 桁 Digits | G9: フルネーム Full Name | H9: 日本語名 Japanese Name | I9: 上り項目 Request Message Field | J9: 下り項目 Response Message Field | P9: 条件および編集方法 Conditions and Editing Methods | R9: 項目備考 Field Remarks
A10: # | L10: 上り項目 Request Message Field | M10: 下り項目 Response Message Field | N10: 上り項目 Request Message Field | O10: 下り項目 Response Message Field
A11: 10 | B11: * | D11: Srch01_Cnd | E11: R
A12: 10 | D12: itm_typ | E12: #MA.ITM_TYP | G12: Item type | H12: 品目区分 | I12: E
A13: 10 | D13: itm_typ_d_cd | E13: #MA.ITM_TYP_D_CD | G13: Item type details cd. | H13: 品目区分詳細ＣＤ | I13: E
A14: 10 | D14: itm_typ_d_nm | E14: #MA.ITM_TYP_D_NM | G14: Item type details name | H14: 品目区分詳細名 | I14: E
A15: 10 | D15: itm_cd | E15: #MA.ITM_CD | G15: Item cd. | H15: 品目ＣＤ | I15: E
A16: 10 | D16: itm_sub1 | E16: #MA.ITM_SUB1 | G16: Branch No. 1 | H16: 枝番１ | I16: E
A17: 10 | D17: itm_sub2 | E17: #MA.ITM_SUB2 | G17: Branch No. 2 | H17: 枝番２ | I17: E
A18: 10 | D18: itm_sub3 | E18: #MA.ITM_SUB3 | G18: Branch No. 3 | H18: 枝番３ | I18: E
A19: 10 | D19: itm_nm | E19: #MA.ITM_NM | G19: Item name | H19: 品名 | I19: E
A20: 10 | D20: release_flg_on | E20: #MA.FLG | G20: Release. On | H20: リリース.オン | I20: E
A21: 10 | D21: release_flg_off | E21: #MA.FLG | G21: Release. Off | H21: リリース.オフ | I21: E
A22: 10 | D22: memo1_c | E22: #MA.MST_MEMO1 | G22: Memo 1 (Common) | H22: メモ１(共通） | I22: E
A23: 10 | D23: memo2_c | E23: #MA.MST_MEMO2 | G23: Memo 2 (Common) | H23: メモ２(共通） | I23: E
... A63: 10 | D63: itm_grp_nm10 | E63: #MA.ITM_GRP_NM | G63: Item classification name 10 | H63: 品目分類名１０ | I63: E
A65: 20 | B65: * | D65: Srch01_Rslt1 | E65: L | M65: L
A66: 20 | D66: release_flg | E66: #MA.FLG | G66: Release | H66: リリース | J66: E | M66: E
A67: 20 | D67: itm_cd | E67: #MA.ITM_CD | G67: Item cd. | H67: 品目ＣＤ | J67: E | M67: E
A68: 20 | D68: itm_sub1 | E68: #MA.ITM_SUB1 | G68: Branch No. 1 | H68: 枝番１ | J68: E | M68: E
A69: 20 | D69: itm_sub2 | E69: #MA.ITM_SUB2 | G69: Branch No. 2 | H69: 枝番２ | J69: E | M69: E
A70: 20 | D70: itm_sub3 | E70: #MA.ITM_SUB3 | G70: Branch No. 3 | H70: 枝番３ | J70: E | M70: E
A71: 20 | D71: itm_nm | E71: #MA.ITM_NM | G71: Item name | H71: 品名 | J71: E | M71: E
A72: 20 | D72: itm_typ | E72: #MA.ITM_TYP | G72: Item type | H72: 品目区分 | J72: E | K72: MAC_ITM_TYP | M72: E
A73: 20 | D73: itm_typ_nm | E73: #MA.ITM_TYP_NM | G73: Item type name | H73: 品目区分名 | J73: E
A74: 20 | D74: itm_typ_d_cd | E74: #MA.ITM_TYP_D_CD | G74: Item type details cd. | H74: 品目区分詳細ＣＤ | J74: E | M74: E
A75: 20 | D75: itm_typ_d_nm | E75: #MA.ITM_TYP_D_NM | G75: Item type details name | H75: 品目区分詳細名 | J75: E | M75: E
A76: 20 | D76: sls_flg | E76: #MA.FLG | G76: For sales | H76: 販売対象 | J76: E | M76: E
A77: 20 | D77: sls_input_flg | E77: #MA.FLG | G77: Sales configured | H77: 販売設定済 | J77: E | M77: E
A78: 20 | D78: mfg_flg | E78: #MA.FLG | G78: For mfg. | H78: 製造対象 | J78: E | M78: E
A79: 20 | D79: mfg_input_flg | E79: #MA.FLG | G79: Mfg. configured | H79: 製造設定済 | J79: E | M79: E
A80: 20 | D80: purc_flg | E80: #MA.FLG | G80: For purchasing | H80: 購買対象 | J80: E | M80: E
...

Sheet Upd01
A1: * | B1: * | D1: L | E1: 1
A2: * | D2: オペレーション実装仕様書 Operation Specification Implementation Sheet | E2: ModuleID : | F2: =IF(LogicCommon!C2="","",LogicCommon!C2) -> MA | G2: LogicID : | H2: =IF(LogicCommon!E2="","",LogicCommon!E2) -> MABCL0400 | I2: Ope.ID : | J2: Upd01 | K2: Pj.ID : | L2: =IF(LogicCommon!G2="","",LogicCommon!G2) -> MC | M2: Ope.Body : | N2: "mcframe.serverMAUD.MAUDL6010.MAUDL_RLUpdater"
A3: * | D3: =IF(LogicCommon!A3="","",LogicCommon!A3) | E3: SubModuleID : | F3: =IF(LogicCommon!C3="","",LogicCommon!C3) -> MABC | G3: LogicClass : | H3: =IF(LogicCommon!E3="","",LogicCommon!E3) -> MABCL_ItmRlsReg | I3: Ope.Method : | J3: @ | K3: SuperClassPj.ID : | L3: =IF(LogicCommon!G3="","",LogicCommon!G3) | M3: ReportID : | O3: Gene.Type : | P3: ALL
A4: * | E4: Version : | F4: 000000 | G4: LogicName : | H4: =IF(LogicCommon!E4="","",LogicCommon!E4) -> 品目リリース登録 | I4: Ope.Name : | J4: 登録 | K4: SuperLogicID : | L4: =IF(LogicCommon!G4="","",LogicCommon!G4) -> MA.MAUDL5010
A5: * | E5: ACType :
A6: * | D6: 概要 : | E6: 登録処理を行う | L6: ID | N6: ID | P6: ID | R6: ID
A7: # | I7: U | K7: o | L7: CALL_OPE01.chk01 | M7: o | N7: CALL_OPE01.upd01 | O7: o | Q7: o
A8: # | D8: ブロック名 Block Name | E8: 型 Type | G8: super/share | H8: 対象ブロック名 Target Block Name | K8: TargetName | L8: OPE.MA.MABCL0400.ItmRls_UpdChk01 | M8: TargetName | N8: OPE.MA.MABCL0400.ItmRls_Upd01 | O8: TargetName | Q8: TargetName | U8: ブロック備考 Block Remarks
A9: # | D9: 項目名 Field Name | E9: 型 Type | F9: 桁 Digits | G9: フルネーム Full Name | H9: 日本語名 Japanese Name | I9: 上り項目 Request Message Field | J9: 下り項目 Response Message Field | S9: 条件および編集方法 Conditions and Editing Methods | U9: 項目備考 Field Remarks
A10: # | K10: 上り項目 Request Message Field | L10: 下り項目 Response Message Field | M10: 上り項目 Request Message Field | N10: 下り項目 Response Message Field | O10: 上り項目 Request Message Field | P10: 下り項目 Response Message Field | Q10: 上り項目 Request Message Field | R10: 下り項目 Response Message Field
A11: 10 | B11: * | D11: Upd01_Dtl1 | E11: L | G11: $share$ | H11: MA.MABCL0400.ItmRls_Upd01.ItmRls_Upd01_Dtl | K11: ItmRls_UpdChk01_Dtl | M11: ItmRls_Upd01_Dtl
A12: 10 | D12: itm_cd | E12: #MA.ITM_CD | G12: Item cd. | H12: 品目ＣＤ | I12: E | K12: E | M12: E
A13: 10 | D13: itm_sub1 | E13: #MA.ITM_SUB1 | G13: Branch No. 1 | H13: 枝番１ | I13: E | K13: E | M13: E
A14: 10 | D14: itm_sub2 | E14: #MA.ITM_SUB2 | G14: Branch No. 2 | H14: 枝番２ | I14: E | K14: E | M14: E
A15: 10 | D15: itm_sub3 | E15: #MA.ITM_SUB3 | G15: Branch No. 3 | H15: 枝番３ | I15: E | K15: E | M15: E
A16: 10 | D16: memo1 | E16: #MA.MST_MEMO1 | G16: Memo 1 | H16: メモ１ | I16: E | K16: E | M16: E
A17: 10 | D17: memo2 | E17: #MA.MST_MEMO2 | G17: Memo 2 | H17: メモ２ | I17: E | K17: E | M17: E
A18: 10 | D18: memo3 | E18: #MA.MST_MEMO3 | G18: Memo 3 | H18: メモ３ | I18: E | K18: E | M18: E
A19: 10 | D19: release_flg | E19: #MA.FLG | G19: Release | H19: リリース | M19: E
A20: 10 | D20: release_usr_cd | E20: #MA.USR_CD | G20: Release PIC name cd. | H20: リリース担当者ＣＤ | M20: E
A21: 10 | D21: release_tm | E21: #MA.TM | G21: Release date and time | H21: リリース日時 | M21: E
A22: 10 | D22: co_cd | E22: #MA.CO_CD | G22: Company cd. | H22: 会社ＣＤ | M22: E
A23: 10 | D23: upd_cntr | E23: #MA.UPD_CNT | G23: Update counter | H23: 更新カウンタ | I23: E | K23: E | M23: E
D24: 詳細 :

Sheet Del01
A1: * | B1: * | D1: L | E1: 1
A2: * | D2: オペレーション実装仕様書 Operation Specification Implementation Sheet | E2: ModuleID : | F2: =IF(LogicCommon!C2="","",LogicCommon!C2) -> MA | G2: LogicID : | H2: =IF(LogicCommon!E2="","",LogicCommon!E2) -> MABCL0400 | I2: Ope.ID : | J2: Del01 | K2: Pj.ID : | L2: =IF(LogicCommon!G2="","",LogicCommon!G2) -> MC | M2: Ope.Body : | N2: "mcframe.serverMAUD.MAUDL6010.MAUDL_RLUpdater"
A3: * | D3: =IF(LogicCommon!A3="","",LogicCommon!A3) | E3: SubModuleID : | F3: =IF(LogicCommon!C3="","",LogicCommon!C3) -> MABC | G3: LogicClass : | H3: =IF(LogicCommon!E3="","",LogicCommon!E3) -> MABCL_ItmRlsReg | I3: Ope.Method : | J3: @ | K3: SuperClassPj.ID : | L3: =IF(LogicCommon!G3="","",LogicCommon!G3) | M3: ReportID : | O3: Gene.Type : | P3: ALL
A4: * | E4: Version : | F4: 000000 | G4: LogicName : | H4: =IF(LogicCommon!E4="","",LogicCommon!E4) -> 品目リリース登録 | I4: Ope.Name : | J4: 取消 | K4: SuperLogicID : | L4: =IF(LogicCommon!G4="","",LogicCommon!G4) -> MA.MAUDL5010
A5: * | E5: ACType :
A6: * | D6: 概要 : | E6: 取消処理を行う | L6: ID | N6: ID
A7: # | I7: U | K7: o | L7: CALL_OPE01.chk01 | M7: o | N7: CALL_OPE01.upd01
A8: # | D8: ブロック名 Block Name | E8: 型 Type | G8: super/share | H8: 対象ブロック名 Target Block Name | K8: TargetName | L8: OPE.MA.MABCL0400.ItmRls_DelChk01 | M8: TargetName | N8: OPE.MA.MABCL0400.ItmRls_Del01 | Q8: ブロック備考 Block Remarks
A9: # | D9: 項目名 Field Name | E9: 型 Type | F9: 桁 Digits | G9: フルネーム Full Name | H9: 日本語名 Japanese Name | I9: 上り項目 Request Message Field | J9: 下り項目 Response Message Field | O9: 条件および編集方法 Conditions and Editing Methods | Q9: 項目備考 Field Remarks
A10: # | K10: 上り項目 Request Message Field | L10: 下り項目 Response Message Field | M10: 上り項目 Request Message Field | N10: 下り項目 Response Message Field
A11: 10 | B11: * | D11: Del01_Dtl1 | E11: L | G11: $share$ | H11: MA.MABCL0400.ItmRls_Del01.ItmRls_Del01_Dtl | K11: ItmRls_DelChk01_Dtl | M11: ItmRls_Del01_Dtl
A12: 10 | D12: itm_cd | E12: #MA.ITM_CD | G12: Item cd. | H12: 品目ＣＤ | I12: E | K12: E | M12: E
A13: 10 | D13: itm_sub1 | E13: #MA.ITM_SUB1 | G13: Branch No. 1 | H13: 枝番１ | I13: E | K13: E | M13: E
A14: 10 | D14: itm_sub2 | E14: #MA.ITM_SUB2 | G14: Branch No. 2 | H14: 枝番２ | I14: E | K14: E | M14: E
A15: 10 | D15: itm_sub3 | E15: #MA.ITM_SUB3 | G15: Branch No. 3 | H15: 枝番３ | I15: E | K15: E | M15: E
A16: 10 | D16: memo1 | E16: #MA.MST_MEMO1 | G16: Memo 1 | H16: メモ１ | I16: E | K16: E | M16: E
A17: 10 | D17: memo2 | E17: #MA.MST_MEMO2 | G17: Memo 2 | H17: メモ２ | I17: E | K17: E | M17: E
A18: 10 | D18: memo3 | E18: #MA.MST_MEMO3 | G18: Memo 3 | H18: メモ３ | I18: E | K18: E | M18: E
A19: 10 | D19: release_flg | E19: #MA.FLG | G19: Release | H19: リリース | M19: E
A20: 10 | D20: release_usr_cd | E20: #MA.USR_CD | G20: Release PIC name cd. | H20: リリース担当者ＣＤ | M20: E
A21: 10 | D21: release_tm | E21: #MA.TM | G21: Release date and time | H21: リリース日時 | M21: E
A22: 10 | D22: co_cd | E22: #MA.CO_CD | G22: Company cd. | H22: 会社ＣＤ | M22: E
A23: 10 | D23: upd_cntr | E23: #MA.UPD_CNT | G23: Update counter | H23: 更新カウンタ | I23: E | K23: E | M23: E
D24: 詳細 :

Sheet Upd02
A1: * | B1: * | D1: L | E1: 1
A2: * | D2: オペレーション実装仕様書 Operation Specification Implementation Sheet | E2: ModuleID : | F2: =IF(LogicCommon!C2="","",LogicCommon!C2) -> MA | G2: LogicID : | H2: =IF(LogicCommon!E2="","",LogicCommon!E2) -> MABCL0400 | I2: Ope.ID : | J2: Upd02 | K2: Pj.ID : | L2: =IF(LogicCommon!G2="","",LogicCommon!G2) -> MC | M2: Ope.Body : | N2: "mcframe.serverMAUD.MAUDL6010.MAUDL_RLUpdater"
A3: * | D3: =IF(LogicCommon!A3="","",LogicCommon!A3) | E3: SubModuleID : | F3: =IF(LogicCommon!C3="","",LogicCommon!C3) -> MABC | G3: LogicClass : | H3: =IF(LogicCommon!E3="","",LogicCommon!E3) -> MABCL_ItmRlsReg | I3: Ope.Method : | J3: @ | K3: SuperClassPj.ID : | L3: =IF(LogicCommon!G3="","",LogicCommon!G3) | M3: ReportID : | O3: Gene.Type : | P3: ALL
A4: * | E4: Version : | F4: 000000 | G4: LogicName : | H4: =IF(LogicCommon!E4="","",LogicCommon!E4) -> 品目リリース登録 | I4: Ope.Name : | J4: 登録（原価管理） | K4: SuperLogicID : | L4: =IF(LogicCommon!G4="","",LogicCommon!G4) -> MA.MAUDL5010
A5: * | E5: ACType :
A6: * | D6: 概要 : | E6: 登録処理（原価管理）を行う | L6: ID | N6: ID | P6: ID | R6: ID
A7: # | I7: U | K7: o | L7: CALL_OPE01.chk01 | M7: o | N7: CALL_OPE01.upd01 | O7: o | Q7: o
A8: # | D8: ブロック名 Block Name | E8: 型 Type | G8: super/share | H8: 対象ブロック名 Target Block Name | K8: TargetName | L8: OPE.MA.MABCL0400.ItmRls_UpdChk02 | M8: TargetName | N8: OPE.MA.MABCL0400.ItmRls_Upd02 | O8: TargetName | Q8: TargetName | U8: ブロック備考 Block Remarks
A9: # | D9: 項目名 Field Name | E9: 型 Type | F9: 桁 Digits | G9: フルネーム Full Name | H9: 日本語名 Japanese Name | I9: 上り項目 Request Message Field | J9: 下り項目 Response Message Field | S9: 条件および編集方法 Conditions and Editing Methods | U9: 項目備考 Field Remarks
A10: # | K10: 上り項目 Request Message Field | L10: 下り項目 Response Message Field | M10: 上り項目 Request Message Field | N10: 下り項目 Response Message Field | O10: 上り項目 Request Message Field | P10: 下り項目 Response Message Field | Q10: 上り項目 Request Message Field | R10: 下り項目 Response Message Field
A11: 10 | B11: * | D11: Upd02_Dtl1 | E11: L | G11: $share$ | H11: MA.MABCL0400.ItmRls_Upd02.ItmRls_Upd02_Dtl | K11: ItmRls_UpdChk02_Dtl | M11: ItmRls_Upd02_Dtl
A12: 10 | D12: itm_cd | E12: #MA.ITM_CD | G12: Item cd. | H12: 品目ＣＤ | I12: E | K12: E | M12: E
A13: 10 | D13: itm_sub1 | E13: #MA.ITM_SUB1 | G13: Branch No. 1 | H13: 枝番１ | I13: E | K13: E | M13: E
A14: 10 | D14: itm_sub2 | E14: #MA.ITM_SUB2 | G14: Branch No. 2 | H14: 枝番２ | I14: E | K14: E | M14: E
A15: 10 | D15: itm_sub3 | E15: #MA.ITM_SUB3 | G15: Branch No. 3 | H15: 枝番３ | I15: E | K15: E | M15: E
K16: 上り項目 Request Message Field | L16: 下り項目 Response Message Field | M16: 上り項目 Request Message Field | N16: 下り項目 Response Message Field | O16: 上り項目 Request Message Field | P16: 下り項目 Response Message Field | Q16: 上り項目 Request Message Field | R16: 下り項目 Response Message Field
A17: 20 | B17: * | D17: Upd02_Cnd | E17: R | G17: $share$ | H17: MA.MABCL0400.ItmRls_Upd02.ItmRls_Upd02_Cnd | K17: ItmRls_UpdChk02_Cnd | M17: ItmRls_Upd02_Cnd
A18: 20 | D18: term | E18: #MA.YM | G18: Term | H18: 期 | I18: E | K18: E | M18: E
A19: 20 | D19: tgt_dt | E19: #MA.DT | G19: Date | H19: 対象日 | I19: E | K19: E | M19: E
D20: 詳細 :

Sheet 来歴
A1: 変更来歴
A3: Rev. | H3: 修正番号 | O3: 変更内容 | AQ3: 変更箇所
A4: 1 | O4: 初版
A5: 1.1 | O5: 英語の名称を追記 | AQ5: 全般
