Workbook

Sheet LogicCommon
A2: ロジック共通定義 | B2: ModuleID : | C2: MA | D2: LogicID : | E2: MABCL0032 | F2: Pj.ID : | G2: MC
B3: SubModuleID : | C3: MABC | D3: LogicClass : | E3: MABCL_MultiReg | F3: SuperClassPj.ID :
D4: LogicName : | E4: マルチマスタ登録 | F4: SuperLogicID : | G4: MA.MAUDL5010
A5: 概要 :
A6: 詳細 :
B7: 対象マスタ
C8: 口座マスタ
C9: 為替レート基本マスタ
C10: カレンダ基本マスタ
C11: 品目仕訳マスタ
C12: 会計品目分類マスタ
C13: 会計理由マスタ
C14: 工場・物流倉庫マスタ
C15: 製造場所グループマスタ
C16: 物流グループマスタ
C17: 総量引当場所グループマスタ

Sheet BankAc_UpdChk01
A1: * | B1: * | D1: L | E1: 1
A2: * | D2: オペレーション実装仕様書 Operation Specification Implementation Sheet | E2: ModuleID : | F2: =IF(LogicCommon!C2="","",LogicCommon!C2) -> MA | G2: LogicID : | H2: =IF(LogicCommon!E2="","",LogicCommon!E2) -> MABCL0032 | I2: Ope.ID : | J2: BankAc_UpdChk01 | K2: Pj.ID : | L2: =IF(LogicCommon!G2="","",LogicCommon!G2) -> MC | M2: Ope.Body : | N2: =L4 & ".Checker" -> MA.MAUDL5010.Checker
A3: * | D3: =IF(LogicCommon!A3="","",LogicCommon!A3) | E3: SubModuleID : | F3: =IF(LogicCommon!C3="","",LogicCommon!C3) -> MABC | G3: LogicClass : | H3: =IF(LogicCommon!E3="","",LogicCommon!E3) -> MABCL_MultiReg | I3: Ope.Method : | J3: @ | K3: SuperClassPj.ID : | L3: =IF(LogicCommon!G3="","",LogicCommon!G3) | M3: ReportID : | O3: Gene.Type : | P3: ALL
A4: * | E4: Version : | F4: 000000 | G4: LogicName : | H4: =IF(LogicCommon!E4="","",LogicCommon!E4) -> マルチマスタ登録 | I4: Ope.Name : | J4: チェック | K4: SuperLogicID : | L4: =IF(LogicCommon!G4="","",LogicCommon!G4) -> MA.MAUDL5010
A5: * | E5: ACType :
A6: * | D6: 概要 : | E6: 口座マスタの登録前のチェックを行います。 | Q6: ID
A7: # | I7: U | K7: K | L7: K | M7: K | N7: K | O7: K | P7: o
A8: # | D8: ブロック名 Block Name | E8: 型 Type | G8: super/share | H8: 対象ブロック名 Target Block Name | K8: REQUIRED | L8: CONST | M8: LIST_LOGIC | N8: LIST_IN | O8: LIST_IN_BASE | P8: TargetName | T8: ブロック備考 Block Remarks
A9: # | D9: 項目名 Field Name | E9: 型 Type | F9: 桁 Digits | G9: フルネーム Full Name | H9: 日本語名 Japanese Name | I9: 上り項目 Request Message Field | J9: 下り項目 Response Message Field | R9: 条件および編集方法 Conditions and Editing Methods | T9: 項目備考 Field Remarks
A10: # | P10: 上り項目 Request Message Field | Q10: 下り項目 Response Message Field
A11: 10 | B11: * | D11: BankAc_UpdChk01_Dtl | E11: L | G11: $super$ | H11: DBC:MA.MAM_BANK_AC
A12: 10 | D12: bank_ac_cd | E12: #MA.BANK_AC_CD | G12: Bank account cd. | H12: 口座ＣＤ | I12: E | K12: E
A13: 10 | D13: bank_ac_nm | E13: #MA.BANK_AC_NM | G13: Standard account name | H13: 標準口座名 | I13: E | K13: E
A14: 10 | D14: ext_flg | E14: #MA.FLG | G14: External | H14: 社外 | I14: E | K14: E
A15: 10 | D15: bank_cd | E15: #MA.BANK_CD | G15: Bank cd. | H15: 銀行ＣＤ | I15: E | K15: E | M15: MA.MAUAL0010.Bank
A16: 10 | D16: branch_cd | E16: #MA.BANK_BRANCH_CD | G16: Bank branch cd. | H16: 銀行支店ＣＤ | I16: E | M16: MA.MAUAL0010.BankBranch | N16: bank_cd | O16: bank_cd
A17: 10 | D17: bank_ac_no | E17: #MA.BANK_AC_NO | G17: Bank account number | H17: 口座番号 | I17: E
A18: 10 | D18: bank_ac_typ | E18: #MA.BANK_AC_TYP | G18: Bank account type | H18: 口座区分 | I18: E | L18: MAC_BANK_AC_TYP
A19: 10 | D19: bank_ac_holder | E19: #MA.BANK_AC_HOLDER | G19: Bank account holder | H19: 口座名義 | I19: E
A20: 10 | D20: bank_ac_holder_sub | E20: #MA.BANK_AC_HOLDER_SUB | G20: Account holder alias name | H20: 口座名義別名 | I20: E
A21: 10 | D21: memo1 | E21: #MA.MST_MEMO1 | G21: Memo 1 | H21: メモ１ | I21: E
A22: 10 | D22: memo2 | E22: #MA.MST_MEMO2 | G22: Memo 2 | H22: メモ２ | I22: E
A23: 10 | D23: memo3 | E23: #MA.MST_MEMO3 | G23: Memo 3 | H23: メモ３ | I23: E
A24: 10 | D24: del_flg | E24: #MA.FLG | G24: Logical delete | H24: 論理削除 | I24: E
A25: 10 | D25: upd_cntr | E25: #MA.UPD_CNT | G25: Update counter | H25: 更新カウンタ | I25: E
D26: 詳細 :

Sheet BankAc_Upd01
A1: * | B1: * | D1: L | E1: 1
A2: * | D2: オペレーション実装仕様書 Operation Specification Implementation Sheet | E2: ModuleID : | F2: =IF(LogicCommon!C2="","",LogicCommon!C2) -> MA | G2: LogicID : | H2: =IF(LogicCommon!E2="","",LogicCommon!E2) -> MABCL0032 | I2: Ope.ID : | J2: BankAc_Upd01 | K2: Pj.ID : | L2: =IF(LogicCommon!G2="","",LogicCommon!G2) -> MC | M2: Ope.Body : | N2: "mcframe.serverMAUD.MAUDL6020.MAUDL_LCLRLUpdater"
A3: * | D3: =IF(LogicCommon!A3="","",LogicCommon!A3) | E3: SubModuleID : | F3: =IF(LogicCommon!C3="","",LogicCommon!C3) -> MABC | G3: LogicClass : | H3: =IF(LogicCommon!E3="","",LogicCommon!E3) -> MABCL_MultiReg | I3: Ope.Method : | J3: @ | K3: SuperClassPj.ID : | L3: =IF(LogicCommon!G3="","",LogicCommon!G3) | M3: ReportID : | O3: Gene.Type : | P3: ALL
A4: * | E4: Version : | F4: 000000 | G4: LogicName : | H4: =IF(LogicCommon!E4="","",LogicCommon!E4) -> マルチマスタ登録 | I4: Ope.Name : | J4: 登録 | K4: SuperLogicID : | L4: =IF(LogicCommon!G4="","",LogicCommon!G4) -> MA.MAUDL5010
A5: * | E5: ACType :
A6: * | D6: 概要 : | E6: 口座マスタの登録を行います。 | L6: ID | N6: ID | P6: ID | R6: ID
A7: # | I7: U | K7: o | L7: UPDATE.updMaster | M7: o | N7: MAIN.chkMaster | O7: o | Q7: o
A8: # | D8: ブロック名 Block Name | E8: 型 Type | G8: super/share | H8: 対象ブロック名 Target Block Name | K8: TargetName | L8: DBC.MA.MAM_BANK_AC | M8: TargetName | N8: DBC.MA.MAM_BANK_AC | O8: TargetName | Q8: TargetName | U8: ブロック備考 Block Remarks
A9: # | D9: 項目名 Field Name | E9: 型 Type | F9: 桁 Digits | G9: フルネーム Full Name | H9: 日本語名 Japanese Name | I9: 上り項目 Request Message Field | J9: 下り項目 Response Message Field | S9: 条件および編集方法 Conditions and Editing Methods | U9: 項目備考 Field Remarks
A10: # | K10: 上り項目 Request Message Field | L10: 下り項目 Response Message Field | M10: 上り項目 Request Message Field | N10: 下り項目 Response Message Field | O10: 上り項目 Request Message Field | P10: 下り項目 Response Message Field | Q10: 上り項目 Request Message Field | R10: 下り項目 Response Message Field
A11: 10 | B11: * | D11: BankAc_Upd01_Dtl | E11: L | G11: $share$ | H11: MA.MABCL0032.BankAc_UpdChk01.BankAc_UpdChk01_Dtl | K11: L | M11: L
A12: 10 | D12: bank_ac_cd | E12: #MA.BANK_AC_CD | G12: Bank account cd. | H12: 口座ＣＤ | I12: E | K12: E | M12: E
A13: 10 | D13: bank_ac_nm | E13: #MA.BANK_AC_NM | G13: Standard account name | H13: 標準口座名 | I13: E | K13: E | M13: E
A14: 10 | D14: ext_flg | E14: #MA.FLG | G14: External | H14: 社外 | I14: E | K14: E | M14: E
A15: 10 | D15: bank_cd | E15: #MA.BANK_CD | G15: Bank cd. | H15: 銀行ＣＤ | I15: E | K15: E | M15: E
A16: 10 | D16: branch_cd | E16: #MA.BANK_BRANCH_CD | G16: Bank branch cd. | H16: 銀行支店ＣＤ | I16: E | K16: E | M16: E
A17: 10 | D17: bank_ac_no | E17: #MA.BANK_AC_NO | G17: Bank account number | H17: 口座番号 | I17: E | K17: E | M17: E
A18: 10 | D18: bank_ac_typ | E18: #MA.BANK_AC_TYP | G18: Bank account type | H18: 口座区分 | I18: E | K18: E | M18: E
A19: 10 | D19: bank_ac_holder | E19: #MA.BANK_AC_HOLDER | G19: Bank account holder | H19: 口座名義 | I19: E | K19: E | M19: E
A20: 10 | D20: bank_ac_holder_sub | E20: #MA.BANK_AC_HOLDER_SUB | G20: Account holder alias name | H20: 口座名義別名 | I20: E | K20: E | M20: E
A21: 10 | D21: memo1 | E21: #MA.MST_MEMO1 | G21: Memo 1 | H21: メモ１ | I21: E | K21: E | M21: E
A22: 10 | D22: memo2 | E22: #MA.MST_MEMO2 | G22: Memo 2 | H22: メモ２ | I22: E | K22: E | M22: E
A23: 10 | D23: memo3 | E23: #MA.MST_MEMO3 | G23: Memo 3 | H23: メモ３ | I23: E | K23: E | M23: E
... A25: 10 | D25: upd_cntr | E25: #MA.UPD_CNT | G25: Update counter | H25: 更新カウンタ | I25: E | K25: E | M25: E
D26: 詳細 :

Sheet BankAcLcl_UpdChk01
A1: * | B1: * | D1: L | E1: 1
A2: * | D2: オペレーション実装仕様書 Operation Specification Implementation Sheet | E2: ModuleID : | F2: =IF(LogicCommon!C2="","",LogicCommon!C2) -> MA | G2: LogicID : | H2: =IF(LogicCommon!E2="","",LogicCommon!E2) -> MABCL0032 | I2: Ope.ID : | J2: BankAcLcl_UpdChk01 | K2: Pj.ID : | L2: =IF(LogicCommon!G2="","",LogicCommon!G2) -> MC | M2: Ope.Body : | N2: =L4 & ".Checker" -> MA.MAUDL5010.Checker
A3: * | D3: =IF(LogicCommon!A3="","",LogicCommon!A3) | E3: SubModuleID : | F3: =IF(LogicCommon!C3="","",LogicCommon!C3) -> MABC | G3: LogicClass : | H3: =IF(LogicCommon!E3="","",LogicCommon!E3) -> MABCL_MultiReg | I3: Ope.Method : | J3: @ | K3: SuperClassPj.ID : | L3: =IF(LogicCommon!G3="","",LogicCommon!G3) | M3: ReportID : | O3: Gene.Type : | P3: ALL
A4: * | E4: Version : | F4: 000000 | G4: LogicName : | H4: =IF(LogicCommon!E4="","",LogicCommon!E4) -> マルチマスタ登録 | I4: Ope.Name : | J4: チェック | K4: SuperLogicID : | L4: =IF(LogicCommon!G4="","",LogicCommon!G4) -> MA.MAUDL5010
A5: * | E5: ACType :
A6: * | D6: 概要 : | E6: 口座マスタの登録前のチェックを行います。（ロケール用） | M6: ID
A7: # | I7: U | K7: K | L7: o | M7: EXISTS.chk01
A8: # | D8: ブロック名 Block Name | E8: 型 Type | G8: super/share | H8: 対象ブロック名 Target Block Name | K8: REQUIRED | L8: TargetName | M8: DBC.MA.MAM_BANK_AC | P8: ブロック備考 Block Remarks
A9: # | D9: 項目名 Field Name | E9: 型 Type | F9: 桁 Digits | G9: フルネーム Full Name | H9: 日本語名 Japanese Name | I9: 上り項目 Request Message Field | J9: 下り項目 Response Message Field | N9: 条件および編集方法 Conditions and Editing Methods | P9: 項目備考 Field Remarks
A10: # | L10: 上り項目 Request Message Field | M10: 下り項目 Response Message Field
A11: 10 | B11: * | D11: BankAcLcl_UpdChk01_Dtl | E11: L | G11: $super$ | H11: DBC:MA.MAM_BANK_AC_LCL | L11: L
A12: 10 | D12: bank_ac_cd | E12: #MA.BANK_AC_CD | G12: Bank account cd. | H12: 口座ＣＤ | I12: E | K12: E | L12: E
A13: 10 | D13: lcl_cd | E13: #MA.LCL_CD | G13: Locale cd. | H13: ロケールＣＤ | I13: E | K13: E
A14: 10 | D14: bank_ac_nm | E14: #MA.BANK_AC_NM | G14: Bank account name | H14: 口座名 | I14: E | K14: E
A15: 10 | D15: memo1 | E15: #MA.MST_MEMO1 | G15: Memo 1 | H15: メモ１ | I15: E
A16: 10 | D16: memo2 | E16: #MA.MST_MEMO2 | G16: Memo 2 | H16: メモ２ | I16: E
A17: 10 | D17: memo3 | E17: #MA.MST_MEMO3 | G17: Memo 3 | H17: メモ３ | I17: E
A18: 10 | D18: upd_cntr | E18: #MA.UPD_CNT | G18: Update counter | H18: 更新カウンタ | I18: E
D19: 詳細 :

Sheet BankAcLcl_Upd01
A1: * | B1: * | D1: L | E1: 1
A2: * | D2: オペレーション実装仕様書 Operation Specification Implementation Sheet | E2: ModuleID : | F2: =IF(LogicCommon!C2="","",LogicCommon!C2) -> MA | G2: LogicID : | H2: =IF(LogicCommon!E2="","",LogicCommon!E2) -> MABCL0032 | I2: Ope.ID : | J2: BankAcLcl_Upd01 | K2: Pj.ID : | L2: =IF(LogicCommon!G2="","",LogicCommon!G2) -> MC | M2: Ope.Body : | N2: "mcframe.serverMAUD.MAUDL6020.MAUDL_LCLRLUpdater"
A3: * | D3: =IF(LogicCommon!A3="","",LogicCommon!A3) | E3: SubModuleID : | F3: =IF(LogicCommon!C3="","",LogicCommon!C3) -> MABC | G3: LogicClass : | H3: =IF(LogicCommon!E3="","",LogicCommon!E3) -> MABCL_MultiReg | I3: Ope.Method : | J3: @ | K3: SuperClassPj.ID : | L3: =IF(LogicCommon!G3="","",LogicCommon!G3) | M3: ReportID : | O3: Gene.Type : | P3: ALL
A4: * | E4: Version : | F4: 000000 | G4: LogicName : | H4: =IF(LogicCommon!E4="","",LogicCommon!E4) -> マルチマスタ登録 | I4: Ope.Name : | J4: 登録 | K4: SuperLogicID : | L4: =IF(LogicCommon!G4="","",LogicCommon!G4) -> MA.MAUDL5010
A5: * | E5: ACType :
A6: * | D6: 概要 : | E6: 口座マスタの登録を行います。（ロケール用） | L6: ID | N6: ID | P6: ID | R6: ID
A7: # | I7: U | K7: o | L7: UPDATE.updMaster | M7: o | N7: MAIN.chkMaster | O7: o | Q7: o
A8: # | D8: ブロック名 Block Name | E8: 型 Type | G8: super/share | H8: 対象ブロック名 Target Block Name | K8: TargetName | L8: DBC.MA.MAM_BANK_AC_LCL | M8: TargetName | N8: DBC.MA.MAM_BANK_AC_LCL | O8: TargetName | Q8: TargetName | U8: ブロック備考 Block Remarks
A9: # | D9: 項目名 Field Name | E9: 型 Type | F9: 桁 Digits | G9: フルネーム Full Name | H9: 日本語名 Japanese Name | I9: 上り項目 Request Message Field | J9: 下り項目 Response Message Field | S9: 条件および編集方法 Conditions and Editing Methods | U9: 項目備考 Field Remarks
A10: # | K10: 上り項目 Request Message Field | L10: 下り項目 Response Message Field | M10: 上り項目 Request Message Field | N10: 下り項目 Response Message Field | O10: 上り項目 Request Message Field | P10: 下り項目 Response Message Field | Q10: 上り項目 Request Message Field | R10: 下り項目 Response Message Field
A11: 10 | B11: * | D11: BankAcLcl_Upd01_Dtl | E11: L | G11: $share$ | H11: MA.MABCL0032.BankAcLcl_UpdChk01.BankAcLcl_UpdChk01_Dtl | K11: L | M11: L
A12: 10 | D12: bank_ac_cd | E12: #MA.BANK_AC_CD | G12: Bank account cd. | H12: 口座ＣＤ | I12: E | K12: E | M12: E
A13: 10 | D13: lcl_cd | E13: #MA.LCL_CD | G13: Locale cd. | H13: ロケールＣＤ | I13: E | K13: E | M13: E
A14: 10 | D14: bank_ac_nm | E14: #MA.BANK_AC_NM | G14: Bank account name | H14: 口座名 | I14: E | K14: E | M14: E
A15: 10 | D15: memo1 | E15: #MA.MST_MEMO1 | G15: Memo 1 | H15: メモ１ | I15: E | K15: E | M15: E
A16: 10 | D16: memo2 | E16: #MA.MST_MEMO2 | G16: Memo 2 | H16: メモ２ | I16: E | K16: E | M16: E
A17: 10 | D17: memo3 | E17: #MA.MST_MEMO3 | G17: Memo 3 | H17: メモ３ | I17: E | K17: E | M17: E
A18: 10 | D18: upd_cntr | E18: #MA.UPD_CNT | G18: Update counter | H18: 更新カウンタ | I18: E | K18: E | M18: E
D19: 詳細 :

Sheet BankAc_DelChk01
A1: * | B1: * | D1: L | E1: 1
A2: * | D2: オペレーション実装仕様書 Operation Specification Implementation Sheet | E2: ModuleID : | F2: =IF(LogicCommon!C2="","",LogicCommon!C2) -> MA | G2: LogicID : | H2: =IF(LogicCommon!E2="","",LogicCommon!E2) -> MABCL0032 | I2: Ope.ID : | J2: BankAc_DelChk01 | K2: Pj.ID : | L2: =IF(LogicCommon!G2="","",LogicCommon!G2) -> MC | M2: Ope.Body : | N2: =L4 & ".Checker" -> MA.MAUDL5010.Checker
A3: * | D3: =IF(LogicCommon!A3="","",LogicCommon!A3) | E3: SubModuleID : | F3: =IF(LogicCommon!C3="","",LogicCommon!C3) -> MABC | G3: LogicClass : | H3: =IF(LogicCommon!E3="","",LogicCommon!E3) -> MABCL_MultiReg | I3: Ope.Method : | J3: @ | K3: SuperClassPj.ID : | L3: =IF(LogicCommon!G3="","",LogicCommon!G3) | M3: ReportID : | O3: Gene.Type : | P3: ALL
A4: * | E4: Version : | F4: 000000 | G4: LogicName : | H4: =IF(LogicCommon!E4="","",LogicCommon!E4) -> マルチマスタ登録 | I4: Ope.Name : | J4: チェック | K4: SuperLogicID : | L4: =IF(LogicCommon!G4="","",LogicCommon!G4) -> MA.MAUDL5010
A5: * | E5: ACType :
A6: * | D6: 概要 : | E6: 口座マスタの削除前のチェックを行います。 | M6: ID
A7: # | I7: U | K7: K | L7: o
A8: # | D8: ブロック名 Block Name | E8: 型 Type | G8: super/share | H8: 対象ブロック名 Target Block Name | K8: REQUIRED | L8: TargetName | P8: ブロック備考 Block Remarks
A9: # | D9: 項目名 Field Name | E9: 型 Type | F9: 桁 Digits | G9: フルネーム Full Name | H9: 日本語名 Japanese Name | I9: 上り項目 Request Message Field | J9: 下り項目 Response Message Field | N9: 条件および編集方法 Conditions and Editing Methods | P9: 項目備考 Field Remarks
A10: # | L10: 上り項目 Request Message Field | M10: 下り項目 Response Message Field
A11: 10 | B11: * | D11: BankAc_DelChk01_Dtl | E11: L
A12: 10 | D12: bank_ac_cd | E12: #MA.BANK_AC_CD | G12: Bank account cd. | H12: 口座ＣＤ | I12: E | K12: E
A13: 10 | D13: upd_cntr | E13: #MA.UPD_CNT | G13: Update counter | H13: 更新カウンタ | I13: E
D14: 詳細 :

Sheet BankAc_Del01
A1: * | B1: * | D1: L | E1: 1
A2: * | D2: オペレーション実装仕様書 Operation Specification Implementation Sheet | E2: ModuleID : | F2: =IF(LogicCommon!C2="","",LogicCommon!C2) -> MA | G2: LogicID : | H2: =IF(LogicCommon!E2="","",LogicCommon!E2) -> MABCL0032 | I2: Ope.ID : | J2: BankAc_Del01 | K2: Pj.ID : | L2: =IF(LogicCommon!G2="","",LogicCommon!G2) -> MC | M2: Ope.Body : | N2: "mcframe.serverMAUD.MAUDL6020.MAUDL_LCLRLDeleter"
A3: * | D3: =IF(LogicCommon!A3="","",LogicCommon!A3) | E3: SubModuleID : | F3: =IF(LogicCommon!C3="","",LogicCommon!C3) -> MABC | G3: LogicClass : | H3: =IF(LogicCommon!E3="","",LogicCommon!E3) -> MABCL_MultiReg | I3: Ope.Method : | J3: @ | K3: SuperClassPj.ID : | L3: =IF(LogicCommon!G3="","",LogicCommon!G3) | M3: ReportID : | O3: Gene.Type : | P3: ALL
A4: * | E4: Version : | F4: 000000 | G4: LogicName : | H4: =IF(LogicCommon!E4="","",LogicCommon!E4) -> マルチマスタ登録 | I4: Ope.Name : | J4: 削除 | K4: SuperLogicID : | L4: =IF(LogicCommon!G4="","",LogicCommon!G4) -> MA.MAUDL5010
A5: * | E5: ACType :
A6: * | D6: 概要 : | E6: 口座マスタの削除を行います。 | L6: ID | N6: ID | P6: ID | R6: ID
A7: # | I7: U | K7: o | L7: UPDATE.updMaster1 | M7: o | N7: UPDATE.updMaster2 | O7: o | Q7: o
A8: # | D8: ブロック名 Block Name | E8: 型 Type | G8: super/share | H8: 対象ブロック名 Target Block Name | K8: TargetName | L8: DBC.MA.MAM_BANK_AC | M8: TargetName | N8: DBC.MA.MAM_BANK_AC_LCL | O8: TargetName | Q8: TargetName | U8: ブロック備考 Block Remarks
A9: # | D9: 項目名 Field Name | E9: 型 Type | F9: 桁 Digits | G9: フルネーム Full Name | H9: 日本語名 Japanese Name | I9: 上り項目 Request Message Field | J9: 下り項目 Response Message Field | S9: 条件および編集方法 Conditions and Editing Methods | U9: 項目備考 Field Remarks
A10: # | K10: 上り項目 Request Message Field | L10: 下り項目 Response Message Field | M10: 上り項目 Request Message Field | N10: 下り項目 Response Message Field | O10: 上り項目 Request Message Field | P10: 下り項目 Response Message Field | Q10: 上り項目 Request Message Field | R10: 下り項目 Response Message Field
A11: 10 | B11: * | D11: BankAc_Del01_Dtl | E11: L | G11: $share$ | H11: MA.MABCL0032.BankAc_DelChk01.BankAc_DelChk01_Dtl | K11: L | M11: L
A12: 10 | D12: bank_ac_cd | E12: #MA.BANK_AC_CD | G12: Bank account cd. | H12: 口座ＣＤ | I12: E | K12: E | M12: E
A13: 10 | D13: upd_cntr | E13: #MA.UPD_CNT | G13: Update counter | H13: 更新カウンタ | I13: E | K13: E
D14: 詳細 :

Sheet Xrate_UpdChk01
A1: * | B1: * | D1: L | E1: 1
A2: * | D2: オペレーション実装仕様書 Operation Specification Implementation Sheet | E2: ModuleID : | F2: =IF(LogicCommon!C2="","",LogicCommon!C2) -> MA | G2: LogicID : | H2: =IF(LogicCommon!E2="","",LogicCommon!E2) -> MABCL0032 | I2: Ope.ID : | J2: Xrate_UpdChk01 | K2: Pj.ID : | L2: =IF(LogicCommon!G2="","",LogicCommon!G2) -> MC | M2: Ope.Body : | N2: =L4 & ".Checker" -> MA.MAUDL5010.Checker
A3: * | D3: =IF(LogicCommon!A3="","",LogicCommon!A3) | E3: SubModuleID : | F3: =IF(LogicCommon!C3="","",LogicCommon!C3) -> MABC | G3: LogicClass : | H3: =IF(LogicCommon!E3="","",LogicCommon!E3) -> MABCL_MultiReg | I3: Ope.Method : | J3: @ | K3: SuperClassPj.ID : | L3: =IF(LogicCommon!G3="","",LogicCommon!G3) | M3: ReportID : | O3: Gene.Type : | P3: ALL
A4: * | E4: Version : | F4: 000000 | G4: LogicName : | H4: =IF(LogicCommon!E4="","",LogicCommon!E4) -> マルチマスタ登録 | I4: Ope.Name : | J4: チェック | K4: SuperLogicID : | L4: =IF(LogicCommon!G4="","",LogicCommon!G4) -> MA.MAUDL5010
A5: * | E5: ACType :
A6: * | D6: 概要 : | E6: 為替レート基本マスタの登録前のチェックを行います。 | M6: ID
A7: # | I7: U | K7: K | L7: o
A8: # | D8: ブロック名 Block Name | E8: 型 Type | G8: super/share | H8: 対象ブロック名 Target Block Name | K8: REQUIRED | L8: TargetName | P8: ブロック備考 Block Remarks
A9: # | D9: 項目名 Field Name | E9: 型 Type | F9: 桁 Digits | G9: フルネーム Full Name | H9: 日本語名 Japanese Name | I9: 上り項目 Request Message Field | J9: 下り項目 Response Message Field | N9: 条件および編集方法 Conditions and Editing Methods | P9: 項目備考 Field Remarks
A10: # | L10: 上り項目 Request Message Field | M10: 下り項目 Response Message Field
A11: 10 | B11: * | D11: Xrate_UpdChk01_Dtl | E11: L | G11: $super$ | H11: DBC:MA.MAM_XRATE
A12: 10 | D12: xrate_cd | E12: #MA.XRATE_CD | G12: Exchange rate cd. | H12: 為替レートＣＤ | I12: E | K12: E
A13: 10 | D13: xrate_nm | E13: #MA.XRATE_NM | G13: Standard exchange rate name | H13: 標準為替レート名 | I13: E | K13: E
A14: 10 | D14: memo1 | E14: #MA.MST_MEMO1 | G14: Memo 1 | H14: メモ１ | I14: E
A15: 10 | D15: memo2 | E15: #MA.MST_MEMO2 | G15: Memo 2 | H15: メモ２ | I15: E
A16: 10 | D16: memo3 | E16: #MA.MST_MEMO3 | G16: Memo 3 | H16: メモ３ | I16: E
A17: 10 | D17: del_flg | E17: #MA.FLG | G17: Logical delete | H17: 論理削除 | I17: E
A18: 10 | D18: upd_cntr | E18: #MA.UPD_CNT | G18: Update counter | H18: 更新カウンタ | I18: E
D19: 詳細 :

Sheet Xrate_Upd01
A1: * | B1: * | D1: L | E1: 1
A2: * | D2: オペレーション実装仕様書 Operation Specification Implementation Sheet | E2: ModuleID : | F2: =IF(LogicCommon!C2="","",LogicCommon!C2) -> MA | G2: LogicID : | H2: =IF(LogicCommon!E2="","",LogicCommon!E2) -> MABCL0032 | I2: Ope.ID : | J2: Xrate_Upd01 | K2: Pj.ID : | L2: =IF(LogicCommon!G2="","",LogicCommon!G2) -> MC | M2: Ope.Body : | N2: "mcframe.serverMAUD.MAUDL6020.MAUDL_LCLRLUpdater"
A3: * | D3: =IF(LogicCommon!A3="","",LogicCommon!A3) | E3: SubModuleID : | F3: =IF(LogicCommon!C3="","",LogicCommon!C3) -> MABC | G3: LogicClass : | H3: =IF(LogicCommon!E3="","",LogicCommon!E3) -> MABCL_MultiReg | I3: Ope.Method : | J3: @ | K3: SuperClassPj.ID : | L3: =IF(LogicCommon!G3="","",LogicCommon!G3) | M3: ReportID : | O3: Gene.Type : | P3: ALL
A4: * | E4: Version : | F4: 000000 | G4: LogicName : | H4: =IF(LogicCommon!E4="","",LogicCommon!E4) -> マルチマスタ登録 | I4: Ope.Name : | J4: 登録 | K4: SuperLogicID : | L4: =IF(LogicCommon!G4="","",LogicCommon!G4) -> MA.MAUDL5010
A5: * | E5: ACType :
A6: * | D6: 概要 : | E6: 為替レート基本マスタの登録を行います。 | L6: ID | N6: ID | P6: ID | R6: ID
A7: # | I7: U | K7: o | L7: UPDATE.updMaster | M7: o | N7: MAIN.chkMaster | O7: o | Q7: o
A8: # | D8: ブロック名 Block Name | E8: 型 Type | G8: super/share | H8: 対象ブロック名 Target Block Name | K8: TargetName | L8: DBC.MA.MAM_XRATE | M8: TargetName | N8: DBC.MA.MAM_XRATE | O8: TargetName | Q8: TargetName | U8: ブロック備考 Block Remarks
A9: # | D9: 項目名 Field Name | E9: 型 Type | F9: 桁 Digits | G9: フルネーム Full Name | H9: 日本語名 Japanese Name | I9: 上り項目 Request Message Field | J9: 下り項目 Response Message Field | S9: 条件および編集方法 Conditions and Editing Methods | U9: 項目備考 Field Remarks
A10: # | K10: 上り項目 Request Message Field | L10: 下り項目 Response Message Field | M10: 上り項目 Request Message Field | N10: 下り項目 Response Message Field | O10: 上り項目 Request Message Field | P10: 下り項目 Response Message Field | Q10: 上り項目 Request Message Field | R10: 下り項目 Response Message Field
A11: 10 | B11: * | D11: Xrate_Upd01_Dtl | E11: L | G11: $share$ | H11: MA.MABCL0032.Xrate_UpdChk01.Xrate_UpdChk01_Dtl | K11: L | M11: L
A12: 10 | D12: xrate_cd | E12: #MA.XRATE_CD | G12: Exchange rate cd. | H12: 為替レートＣＤ | I12: E | K12: E | M12: E
A13: 10 | D13: xrate_nm | E13: #MA.XRATE_NM | G13: Standard exchange rate name | H13: 標準為替レート名 | I13: E | K13: E | M13: E
A14: 10 | D14: memo1 | E14: #MA.MST_MEMO1 | G14: Memo 1 | H14: メモ１ | I14: E | K14: E | M14: E
A15: 10 | D15: memo2 | E15: #MA.MST_MEMO2 | G15: Memo 2 | H15: メモ２ | I15: E | K15: E | M15: E
A16: 10 | D16: memo3 | E16: #MA.MST_MEMO3 | G16: Memo 3 | H16: メモ３ | I16: E | K16: E | M16: E
A17: 10 | D17: del_flg | E17: #MA.FLG | G17: Logical delete | H17: 論理削除 | I17: E | K17: E | M17: E
A18: 10 | D18: upd_cntr | E18: #MA.UPD_CNT | G18: Update counter | H18: 更新カウンタ | I18: E | K18: E | M18: E
D19: 詳細 :

Sheet XrateLcl_UpdChk01
A1: * | B1: * | D1: L | E1: 1
A2: * | D2: オペレーション実装仕様書 Operation Specification Implementation Sheet | E2: ModuleID : | F2: =IF(LogicCommon!C2="","",LogicCommon!C2) -> MA | G2: LogicID : | H2: =IF(LogicCommon!E2="","",LogicCommon!E2) -> MABCL0032 | I2: Ope.ID : | J2: XrateLcl_UpdChk01 | K2: Pj.ID : | L2: =IF(LogicCommon!G2="","",LogicCommon!G2) -> MC | M2: Ope.Body : | N2: =L4 & ".Checker" -> MA.MAUDL5010.Checker
A3: * | D3: =IF(LogicCommon!A3="","",LogicCommon!A3) | E3: SubModuleID : | F3: =IF(LogicCommon!C3="","",LogicCommon!C3) -> MABC | G3: LogicClass : | H3: =IF(LogicCommon!E3="","",LogicCommon!E3) -> MABCL_MultiReg | I3: Ope.Method : | J3: @ | K3: SuperClassPj.ID : | L3: =IF(LogicCommon!G3="","",LogicCommon!G3) | M3: ReportID : | O3: Gene.Type : | P3: ALL
A4: * | E4: Version : | F4: 000000 | G4: LogicName : | H4: =IF(LogicCommon!E4="","",LogicCommon!E4) -> マルチマスタ登録 | I4: Ope.Name : | J4: チェック | K4: SuperLogicID : | L4: =IF(LogicCommon!G4="","",LogicCommon!G4) -> MA.MAUDL5010
A5: * | E5: ACType :
A6: * | D6: 概要 : | E6: 為替レート基本マスタの登録前のチェックを行います。（ロケール用） | M6: ID
A7: # | I7: U | K7: K | L7: o | M7: EXISTS.chk01
A8: # | D8: ブロック名 Block Name | E8: 型 Type | G8: super/share | H8: 対象ブロック名 Target Block Name | K8: REQUIRED | L8: TargetName | M8: DBC.MA.MAM_XRATE | P8: ブロック備考 Block Remarks
A9: # | D9: 項目名 Field Name | E9: 型 Type | F9: 桁 Digits | G9: フルネーム Full Name | H9: 日本語名 Japanese Name | I9: 上り項目 Request Message Field | J9: 下り項目 Response Message Field | N9: 条件および編集方法 Conditions and Editing Methods | P9: 項目備考 Field Remarks
A10: # | L10: 上り項目 Request Message Field | M10: 下り項目 Response Message Field
A11: 10 | B11: * | D11: XrateLcl_UpdChk01_Dtl | E11: L | G11: $super$ | H11: DBC:MA.MAM_XRATE_LCL | L11: L
A12: 10 | D12: xrate_cd | E12: #MA.XRATE_CD | G12: Exchange rate cd. | H12: 為替レートＣＤ | I12: E | K12: E | L12: E
A13: 10 | D13: lcl_cd | E13: #MA.LCL_CD | G13: Locale cd. | H13: ロケールＣＤ | I13: E | K13: E
A14: 10 | D14: xrate_nm | E14: #MA.XRATE_NM | G14: Exchange rate name | H14: 為替レート名 | I14: E | K14: E
A15: 10 | D15: memo1 | E15: #MA.MST_MEMO1 | G15: Memo 1 | H15: メモ１ | I15: E
A16: 10 | D16: memo2 | E16: #MA.MST_MEMO2 | G16: Memo 2 | H16: メモ２ | I16: E
A17: 10 | D17: memo3 | E17: #MA.MST_MEMO3 | G17: Memo 3 | H17: メモ３ | I17: E
A18: 10 | D18: upd_cntr | E18: #MA.UPD_CNT | G18: Update counter | H18: 更新カウンタ | I18: E
D19: 詳細 :

Sheet XrateLcl_Upd01
A1: * | B1: * | D1: L | E1: 1
A2: * | D2: オペレーション実装仕様書 Operation Specification Implementation Sheet | E2: ModuleID : | F2: =IF(LogicCommon!C2="","",LogicCommon!C2) -> MA | G2: LogicID : | H2: =IF(LogicCommon!E2="","",LogicCommon!E2) -> MABCL0032 | I2: Ope.ID : | J2: XrateLcl_Upd01 | K2: Pj.ID : | L2: =IF(LogicCommon!G2="","",LogicCommon!G2) -> MC | M2: Ope.Body : | N2: "mcframe.serverMAUD.MAUDL6020.MAUDL_LCLRLUpdater"
A3: * | D3: =IF(LogicCommon!A3="","",LogicCommon!A3) | E3: SubModuleID : | F3: =IF(LogicCommon!C3="","",LogicCommon!C3) -> MABC | G3: LogicClass : | H3: =IF(LogicCommon!E3="","",LogicCommon!E3) -> MABCL_MultiReg | I3: Ope.Method : | J3: @ | K3: SuperClassPj.ID : | L3: =IF(LogicCommon!G3="","",LogicCommon!G3) | M3: ReportID : | O3: Gene.Type : | P3: ALL
A4: * | E4: Version : | F4: 000000 | G4: LogicName : | H4: =IF(LogicCommon!E4="","",LogicCommon!E4) -> マルチマスタ登録 | I4: Ope.Name : | J4: 登録 | K4: SuperLogicID : | L4: =IF(LogicCommon!G4="","",LogicCommon!G4) -> MA.MAUDL5010
A5: * | E5: ACType :
A6: * | D6: 概要 : | E6: 為替レート基本マスタの登録を行います。（ロケール用） | L6: ID | N6: ID | P6: ID | R6: ID
A7: # | I7: U | K7: o | L7: UPDATE.updMaster | M7: o | N7: MAIN.chkMaster | O7: o | Q7: o
A8: # | D8: ブロック名 Block Name | E8: 型 Type | G8: super/share | H8: 対象ブロック名 Target Block Name | K8: TargetName | L8: DBC.MA.MAM_XRATE_LCL | M8: TargetName | N8: DBC.MA.MAM_XRATE_LCL | O8: TargetName | Q8: TargetName | U8: ブロック備考 Block Remarks
A9: # | D9: 項目名 Field Name | E9: 型 Type | F9: 桁 Digits | G9: フルネーム Full Name | H9: 日本語名 Japanese Name | I9: 上り項目 Request Message Field | J9: 下り項目 Response Message Field | S9: 条件および編集方法 Conditions and Editing Methods | U9: 項目備考 Field Remarks
A10: # | K10: 上り項目 Request Message Field | L10: 下り項目 Response Message Field | M10: 上り項目 Request Message Field | N10: 下り項目 Response Message Field | O10: 上り項目 Request Message Field | P10: 下り項目 Response Message Field | Q10: 上り項目 Request Message Field | R10: 下り項目 Response Message Field
A11: 10 | B11: * | D11: XrateLcl_Upd01_Dtl | E11: L | G11: $share$ | H11: MA.MABCL0032.XrateLcl_UpdChk01.XrateLcl_UpdChk01_Dtl | K11: L | M11: L
A12: 10 | D12: xrate_cd | E12: #MA.XRATE_CD | G12: Exchange rate cd. | H12: 為替レートＣＤ | I12: E | K12: E | M12: E
A13: 10 | D13: lcl_cd | E13: #MA.LCL_CD | G13: Locale cd. | H13: ロケールＣＤ | I13: E | K13: E | M13: E
A14: 10 | D14: xrate_nm | E14: #MA.XRATE_NM | G14: Exchange rate name | H14: 為替レート名 | I14: E | K14: E | M14: E
A15: 10 | D15: memo1 | E15: #MA.MST_MEMO1 | G15: Memo 1 | H15: メモ１ | I15: E | K15: E | M15: E
A16: 10 | D16: memo2 | E16: #MA.MST_MEMO2 | G16: Memo 2 | H16: メモ２ | I16: E | K16: E | M16: E
A17: 10 | D17: memo3 | E17: #MA.MST_MEMO3 | G17: Memo 3 | H17: メモ３ | I17: E | K17: E | M17: E
A18: 10 | D18: upd_cntr | E18: #MA.UPD_CNT | G18: Update counter | H18: 更新カウンタ | I18: E | K18: E | M18: E
D19: 詳細 :

Sheet Xrate_DelChk01
A1: * | B1: * | D1: L | E1: 1
A2: * | D2: オペレーション実装仕様書 Operation Specification Implementation Sheet | E2: ModuleID : | F2: =IF(LogicCommon!C2="","",LogicCommon!C2) -> MA | G2: LogicID : | H2: =IF(LogicCommon!E2="","",LogicCommon!E2) -> MABCL0032 | I2: Ope.ID : | J2: Xrate_DelChk01 | K2: Pj.ID : | L2: =IF(LogicCommon!G2="","",LogicCommon!G2) -> MC | M2: Ope.Body : | N2: =L4 & ".Checker" -> MA.MAUDL5010.Checker
A3: * | D3: =IF(LogicCommon!A3="","",LogicCommon!A3) | E3: SubModuleID : | F3: =IF(LogicCommon!C3="","",LogicCommon!C3) -> MABC | G3: LogicClass : | H3: =IF(LogicCommon!E3="","",LogicCommon!E3) -> MABCL_MultiReg | I3: Ope.Method : | J3: @ | K3: SuperClassPj.ID : | L3: =IF(LogicCommon!G3="","",LogicCommon!G3) | M3: ReportID : | O3: Gene.Type : | P3: ALL
A4: * | E4: Version : | F4: 000000 | G4: LogicName : | H4: =IF(LogicCommon!E4="","",LogicCommon!E4) -> マルチマスタ登録 | I4: Ope.Name : | J4: チェック | K4: SuperLogicID : | L4: =IF(LogicCommon!G4="","",LogicCommon!G4) -> MA.MAUDL5010
A5: * | E5: ACType :
A6: * | D6: 概要 : | E6: 為替レート基本マスタの削除前のチェックを行います。 | M6: ID
A7: # | I7: U | K7: K | L7: o
A8: # | D8: ブロック名 Block Name | E8: 型 Type | G8: super/share | H8: 対象ブロック名 Target Block Name | K8: REQUIRED | L8: TargetName | P8: ブロック備考 Block Remarks
A9: # | D9: 項目名 Field Name | E9: 型 Type | F9: 桁 Digits | G9: フルネーム Full Name | H9: 日本語名 Japanese Name | I9: 上り項目 Request Message Field | J9: 下り項目 Response Message Field | N9: 条件および編集方法 Conditions and Editing Methods | P9: 項目備考 Field Remarks
A10: # | L10: 上り項目 Request Message Field | M10: 下り項目 Response Message Field
A11: 10 | B11: * | D11: Xrate_DelChk01_Dtl | E11: L
A12: 10 | D12: xrate_cd | E12: #MA.XRATE_CD | G12: Exchange rate basic cd. | H12: 為替レート基本ＣＤ | I12: E | K12: E
A13: 10 | D13: upd_cntr | E13: #MA.UPD_CNT | G13: Update counter | H13: 更新カウンタ | I13: E
D14: 詳細 :

Sheet Xrate_Del01
A1: * | B1: * | D1: L | E1: 1
A2: * | D2: オペレーション実装仕様書 Operation Specification Implementation Sheet | E2: ModuleID : | F2: =IF(LogicCommon!C2="","",LogicCommon!C2) -> MA | G2: LogicID : | H2: =IF(LogicCommon!E2="","",LogicCommon!E2) -> MABCL0032 | I2: Ope.ID : | J2: Xrate_Del01 | K2: Pj.ID : | L2: =IF(LogicCommon!G2="","",LogicCommon!G2) -> MC | M2: Ope.Body : | N2: "mcframe.serverMAUD.MAUDL6020.MAUDL_LCLRLDeleter"
A3: * | D3: =IF(LogicCommon!A3="","",LogicCommon!A3) | E3: SubModuleID : | F3: =IF(LogicCommon!C3="","",LogicCommon!C3) -> MABC | G3: LogicClass : | H3: =IF(LogicCommon!E3="","",LogicCommon!E3) -> MABCL_MultiReg | I3: Ope.Method : | J3: @ | K3: SuperClassPj.ID : | L3: =IF(LogicCommon!G3="","",LogicCommon!G3) | M3: ReportID : | O3: Gene.Type : | P3: ALL
A4: * | E4: Version : | F4: 000000 | G4: LogicName : | H4: =IF(LogicCommon!E4="","",LogicCommon!E4) -> マルチマスタ登録 | I4: Ope.Name : | J4: 削除 | K4: SuperLogicID : | L4: =IF(LogicCommon!G4="","",LogicCommon!G4) -> MA.MAUDL5010
A5: * | E5: ACType :
A6: * | D6: 概要 : | E6: 為替レート基本マスタの削除を行います。 | L6: ID | N6: ID | P6: ID | R6: ID
A7: # | I7: U | K7: o | L7: UPDATE.updMaster1 | M7: o | N7: UPDATE.updMaster2 | O7: o | Q7: o
A8: # | D8: ブロック名 Block Name | E8: 型 Type | G8: super/share | H8: 対象ブロック名 Target Block Name | K8: TargetName | L8: DBC.MA.MAM_XRATE | M8: TargetName | N8: DBC.MA.MAM_XRATE_LCL | O8: TargetName | Q8: TargetName | U8: ブロック備考 Block Remarks
A9: # | D9: 項目名 Field Name | E9: 型 Type | F9: 桁 Digits | G9: フルネーム Full Name | H9: 日本語名 Japanese Name | I9: 上り項目 Request Message Field | J9: 下り項目 Response Message Field | S9: 条件および編集方法 Conditions and Editing Methods | U9: 項目備考 Field Remarks
A10: # | K10: 上り項目 Request Message Field | L10: 下り項目 Response Message Field | M10: 上り項目 Request Message Field | N10: 下り項目 Response Message Field | O10: 上り項目 Request Message Field | P10: 下り項目 Response Message Field | Q10: 上り項目 Request Message Field | R10: 下り項目 Response Message Field
A11: 10 | B11: * | D11: Xrate_Del01_Dtl | E11: L | G11: $share$ | H11: MA.MABCL0032.Xrate_DelChk01.Xrate_DelChk01_Dtl | K11: L | M11: L
A12: 10 | D12: xrate_cd | E12: #MA.XRATE_CD | G12: Exchange rate basic cd. | H12: 為替レート基本ＣＤ | I12: E | K12: E | M12: E
A13: 10 | D13: upd_cntr | E13: #MA.UPD_CNT | G13: Update counter | H13: 更新カウンタ | I13: E | K13: E
D14: 詳細 :

Sheet CalBase_UpdChk01
A1: * | B1: * | D1: L | E1: 1
A2: * | D2: オペレーション実装仕様書 Operation Specification Implementation Sheet | E2: ModuleID : | F2: =IF(LogicCommon!C2="","",LogicCommon!C2) -> MA | G2: LogicID : | H2: =IF(LogicCommon!E2="","",LogicCommon!E2) -> MABCL0032 | I2: Ope.ID : | J2: CalBase_UpdChk01 | K2: Pj.ID : | L2: =IF(LogicCommon!G2="","",LogicCommon!G2) -> MC | M2: Ope.Body : | N2: =L4 & ".Checker" -> MA.MAUDL5010.Checker
A3: * | D3: =IF(LogicCommon!A3="","",LogicCommon!A3) | E3: SubModuleID : | F3: =IF(LogicCommon!C3="","",LogicCommon!C3) -> MABC | G3: LogicClass : | H3: =IF(LogicCommon!E3="","",LogicCommon!E3) -> MABCL_MultiReg | I3: Ope.Method : | J3: @ | K3: SuperClassPj.ID : | L3: =IF(LogicCommon!G3="","",LogicCommon!G3) | M3: ReportID : | O3: Gene.Type : | P3: ALL
A4: * | E4: Version : | F4: 000000 | G4: LogicName : | H4: =IF(LogicCommon!E4="","",LogicCommon!E4) -> マルチマスタ登録 | I4: Ope.Name : | J4: チェック | K4: SuperLogicID : | L4: =IF(LogicCommon!G4="","",LogicCommon!G4) -> MA.MAUDL5010
A5: * | E5: ACType :
A6: * | D6: 概要 : | E6: カレンダ基本マスタの登録前のチェックを行います。 | M6: ID
A7: # | I7: U | K7: K | L7: o
A8: # | D8: ブロック名 Block Name | E8: 型 Type | G8: super/share | H8: 対象ブロック名 Target Block Name | K8: REQUIRED | L8: TargetName | P8: ブロック備考 Block Remarks
A9: # | D9: 項目名 Field Name | E9: 型 Type | F9: 桁 Digits | G9: フルネーム Full Name | H9: 日本語名 Japanese Name | I9: 上り項目 Request Message Field | J9: 下り項目 Response Message Field | N9: 条件および編集方法 Conditions and Editing Methods | P9: 項目備考 Field Remarks
A10: # | L10: 上り項目 Request Message Field | M10: 下り項目 Response Message Field
A11: 10 | B11: * | D11: CalBase_UpdChk01_Dtl | E11: L | G11: $super$ | H11: DBC:MA.MAM_CAL_BASE
A12: 10 | D12: cal_cd | E12: #MA.CAL_CD | G12: Calendar cd. | H12: カレンダＣＤ | I12: E | K12: E
A13: 10 | D13: cal_nm | E13: #MA.CAL_NM | G13: Standard calendar name | H13: 標準カレンダ名 | I13: E | K13: E
A14: 10 | D14: memo1 | E14: #MA.MST_MEMO1 | G14: Memo 1 | H14: メモ１ | I14: E
A15: 10 | D15: memo2 | E15: #MA.MST_MEMO2 | G15: Memo 2 | H15: メモ２ | I15: E
A16: 10 | D16: memo3 | E16: #MA.MST_MEMO3 | G16: Memo 3 | H16: メモ３ | I16: E
A17: 10 | D17: del_flg | E17: #MA.FLG | G17: Logical delete | H17: 論理削除 | I17: E
A18: 10 | D18: upd_cntr | E18: #MA.UPD_CNT | G18: Update counter | H18: 更新カウンタ | I18: E
D19: 詳細 :

Sheet CalBase_Upd01
A1: * | B1: * | D1: L | E1: 1
A2: * | D2: オペレーション実装仕様書 Operation Specification Implementation Sheet | E2: ModuleID : | F2: =IF(LogicCommon!C2="","",LogicCommon!C2) -> MA | G2: LogicID : | H2: =IF(LogicCommon!E2="","",LogicCommon!E2) -> MABCL0032 | I2: Ope.ID : | J2: CalBase_Upd01 | K2: Pj.ID : | L2: =IF(LogicCommon!G2="","",LogicCommon!G2) -> MC | M2: Ope.Body : | N2: "mcframe.serverMAUD.MAUDL6020.MAUDL_LCLRLUpdater"
A3: * | D3: =IF(LogicCommon!A3="","",LogicCommon!A3) | E3: SubModuleID : | F3: =IF(LogicCommon!C3="","",LogicCommon!C3) -> MABC | G3: LogicClass : | H3: =IF(LogicCommon!E3="","",LogicCommon!E3) -> MABCL_MultiReg | I3: Ope.Method : | J3: @ | K3: SuperClassPj.ID : | L3: =IF(LogicCommon!G3="","",LogicCommon!G3) | M3: ReportID : | O3: Gene.Type : | P3: ALL
A4: * | E4: Version : | F4: 000000 | G4: LogicName : | H4: =IF(LogicCommon!E4="","",LogicCommon!E4) -> マルチマスタ登録 | I4: Ope.Name : | J4: 登録 | K4: SuperLogicID : | L4: =IF(LogicCommon!G4="","",LogicCommon!G4) -> MA.MAUDL5010
A5: * | E5: ACType :
A6: * | D6: 概要 : | E6: カレンダ基本マスタの登録を行います。 | L6: ID | N6: ID | P6: ID | R6: ID
A7: # | I7: U | K7: o | L7: UPDATE.updMaster | M7: o | N7: MAIN.chkMaster | O7: o | Q7: o
A8: # | D8: ブロック名 Block Name | E8: 型 Type | G8: super/share | H8: 対象ブロック名 Target Block Name | K8: TargetName | L8: DBC.MA.MAM_CAL_BASE | M8: TargetName | N8: DBC.MA.MAM_CAL_BASE | O8: TargetName | Q8: TargetName | U8: ブロック備考 Block Remarks
A9: # | D9: 項目名 Field Name | E9: 型 Type | F9: 桁 Digits | G9: フルネーム Full Name | H9: 日本語名 Japanese Name | I9: 上り項目 Request Message Field | J9: 下り項目 Response Message Field | S9: 条件および編集方法 Conditions and Editing Methods | U9: 項目備考 Field Remarks
A10: # | K10: 上り項目 Request Message Field | L10: 下り項目 Response Message Field | M10: 上り項目 Request Message Field | N10: 下り項目 Response Message Field | O10: 上り項目 Request Message Field | P10: 下り項目 Response Message Field | Q10: 上り項目 Request Message Field | R10: 下り項目 Response Message Field
A11: 10 | B11: * | D11: CalBase_Upd01_Dtl | E11: L | G11: $share$ | H11: MA.MABCL0032.CalBase_UpdChk01.CalBase_UpdChk01_Dtl | K11: L | M11: L
A12: 10 | D12: cal_cd | E12: #MA.CAL_CD | G12: Calendar cd. | H12: カレンダＣＤ | I12: E | K12: E | M12: E
A13: 10 | D13: cal_nm | E13: #MA.CAL_NM | G13: Standard calendar name | H13: 標準カレンダ名 | I13: E | K13: E | M13: E
A14: 10 | D14: memo1 | E14: #MA.MST_MEMO1 | G14: Memo 1 | H14: メモ１ | I14: E | K14: E | M14: E
A15: 10 | D15: memo2 | E15: #MA.MST_MEMO2 | G15: Memo 2 | H15: メモ２ | I15: E | K15: E | M15: E
A16: 10 | D16: memo3 | E16: #MA.MST_MEMO3 | G16: Memo 3 | H16: メモ３ | I16: E | K16: E | M16: E
A17: 10 | D17: del_flg | E17: #MA.FLG | G17: Logical delete | H17: 論理削除 | I17: E | K17: E | M17: E
A18: 10 | D18: upd_cntr | E18: #MA.UPD_CNT | G18: Update counter | H18: 更新カウンタ | I18: E | K18: E | M18: E
D19: 詳細 :

Sheet CalBaseLcl_UpdChk01
A1: * | B1: * | D1: L | E1: 1
A2: * | D2: オペレーション実装仕様書 Operation Specification Implementation Sheet | E2: ModuleID : | F2: =IF(LogicCommon!C2="","",LogicCommon!C2) -> MA | G2: LogicID : | H2: =IF(LogicCommon!E2="","",LogicCommon!E2) -> MABCL0032 | I2: Ope.ID : | J2: CalBaseLcl_UpdChk01 | K2: Pj.ID : | L2: =IF(LogicCommon!G2="","",LogicCommon!G2) -> MC | M2: Ope.Body : | N2: =L4 & ".Checker" -> MA.MAUDL5010.Checker
A3: * | D3: =IF(LogicCommon!A3="","",LogicCommon!A3) | E3: SubModuleID : | F3: =IF(LogicCommon!C3="","",LogicCommon!C3) -> MABC | G3: LogicClass : | H3: =IF(LogicCommon!E3="","",LogicCommon!E3) -> MABCL_MultiReg | I3: Ope.Method : | J3: @ | K3: SuperClassPj.ID : | L3: =IF(LogicCommon!G3="","",LogicCommon!G3) | M3: ReportID : | O3: Gene.Type : | P3: ALL
A4: * | E4: Version : | F4: 000000 | G4: LogicName : | H4: =IF(LogicCommon!E4="","",LogicCommon!E4) -> マルチマスタ登録 | I4: Ope.Name : | J4: チェック | K4: SuperLogicID : | L4: =IF(LogicCommon!G4="","",LogicCommon!G4) -> MA.MAUDL5010
A5: * | E5: ACType :
A6: * | D6: 概要 : | E6: カレンダ基本マスタの登録前のチェックを行います。（ロケール用） | M6: ID
A7: # | I7: U | K7: K | L7: o | M7: EXISTS.chk01
A8: # | D8: ブロック名 Block Name | E8: 型 Type | G8: super/share | H8: 対象ブロック名 Target Block Name | K8: REQUIRED | L8: TargetName | M8: DBC.MA.MAM_CAL_BASE | P8: ブロック備考 Block Remarks
A9: # | D9: 項目名 Field Name | E9: 型 Type | F9: 桁 Digits | G9: フルネーム Full Name | H9: 日本語名 Japanese Name | I9: 上り項目 Request Message Field | J9: 下り項目 Response Message Field | N9: 条件および編集方法 Conditions and Editing Methods | P9: 項目備考 Field Remarks
A10: # | L10: 上り項目 Request Message Field | M10: 下り項目 Response Message Field
A11: 10 | B11: * | D11: CalBaseLcl_UpdChk01_Dtl | E11: L | G11: $super$ | H11: DBC:MA.MAM_CAL_BASE_LCL | L11: L
A12: 10 | D12: cal_cd | E12: #MA.CAL_CD | G12: Calendar cd. | H12: カレンダＣＤ | I12: E | K12: E | L12: E
A13: 10 | D13: lcl_cd | E13: #MA.LCL_CD | G13: Locale cd. | H13: ロケールＣＤ | I13: E | K13: E
A14: 10 | D14: cal_nm | E14: #MA.CAL_NM | G14: Calendar name | H14: カレンダ名 | I14: E | K14: E
A15: 10 | D15: memo1 | E15: #MA.MST_MEMO1 | G15: Memo 1 | H15: メモ１ | I15: E
A16: 10 | D16: memo2 | E16: #MA.MST_MEMO2 | G16: Memo 2 | H16: メモ２ | I16: E
A17: 10 | D17: memo3 | E17: #MA.MST_MEMO3 | G17: Memo 3 | H17: メモ３ | I17: E
A18: 10 | D18: upd_cntr | E18: #MA.UPD_CNT | G18: Update counter | H18: 更新カウンタ | I18: E
D19: 詳細 :

Sheet CalBaseLcl_Upd01
A1: * | B1: * | D1: L | E1: 1
A2: * | D2: オペレーション実装仕様書 Operation Specification Implementation Sheet | E2: ModuleID : | F2: =IF(LogicCommon!C2="","",LogicCommon!C2) -> MA | G2: LogicID : | H2: =IF(LogicCommon!E2="","",LogicCommon!E2) -> MABCL0032 | I2: Ope.ID : | J2: CalBaseLcl_Upd01 | K2: Pj.ID : | L2: =IF(LogicCommon!G2="","",LogicCommon!G2) -> MC | M2: Ope.Body : | N2: "mcframe.serverMAUD.MAUDL6020.MAUDL_LCLRLUpdater"
A3: * | D3: =IF(LogicCommon!A3="","",LogicCommon!A3) | E3: SubModuleID : | F3: =IF(LogicCommon!C3="","",LogicCommon!C3) -> MABC | G3: LogicClass : | H3: =IF(LogicCommon!E3="","",LogicCommon!E3) -> MABCL_MultiReg | I3: Ope.Method : | J3: @ | K3: SuperClassPj.ID : | L3: =IF(LogicCommon!G3="","",LogicCommon!G3) | M3: ReportID : | O3: Gene.Type : | P3: ALL
A4: * | E4: Version : | F4: 000000 | G4: LogicName : | H4: =IF(LogicCommon!E4="","",LogicCommon!E4) -> マルチマスタ登録 | I4: Ope.Name : | J4: 登録 | K4: SuperLogicID : | L4: =IF(LogicCommon!G4="","",LogicCommon!G4) -> MA.MAUDL5010
A5: * | E5: ACType :
A6: * | D6: 概要 : | E6: カレンダ基本マスタの登録を行います。（ロケール用） | L6: ID | N6: ID | P6: ID | R6: ID
A7: # | I7: U | K7: o | L7: UPDATE.updMaster | M7: o | N7: MAIN.chkMaster | O7: o | Q7: o
A8: # | D8: ブロック名 Block Name | E8: 型 Type | G8: super/share | H8: 対象ブロック名 Target Block Name | K8: TargetName | L8: DBC.MA.MAM_CAL_BASE_LCL | M8: TargetName | N8: DBC.MA.MAM_CAL_BASE_LCL | O8: TargetName | Q8: TargetName | U8: ブロック備考 Block Remarks
A9: # | D9: 項目名 Field Name | E9: 型 Type | F9: 桁 Digits | G9: フルネーム Full Name | H9: 日本語名 Japanese Name | I9: 上り項目 Request Message Field | J9: 下り項目 Response Message Field | S9: 条件および編集方法 Conditions and Editing Methods | U9: 項目備考 Field Remarks
A10: # | K10: 上り項目 Request Message Field | L10: 下り項目 Response Message Field | M10: 上り項目 Request Message Field | N10: 下り項目 Response Message Field | O10: 上り項目 Request Message Field | P10: 下り項目 Response Message Field | Q10: 上り項目 Request Message Field | R10: 下り項目 Response Message Field
A11: 10 | B11: * | D11: CalBaseLcl_Upd01_Dtl | E11: L | G11: $share$ | H11: MA.MABCL0032.CalBaseLcl_UpdChk01.CalBaseLcl_UpdChk01_Dtl | K11: L | M11: L
A12: 10 | D12: cal_cd | E12: #MA.CAL_CD | G12: Calendar cd. | H12: カレンダＣＤ | I12: E | K12: E | M12: E
A13: 10 | D13: lcl_cd | E13: #MA.LCL_CD | G13: Locale cd. | H13: ロケールＣＤ | I13: E | K13: E | M13: E
A14: 10 | D14: cal_nm | E14: #MA.CAL_NM | G14: Calendar name | H14: カレンダ名 | I14: E | K14: E | M14: E
A15: 10 | D15: memo1 | E15: #MA.MST_MEMO1 | G15: Memo 1 | H15: メモ１ | I15: E | K15: E | M15: E
A16: 10 | D16: memo2 | E16: #MA.MST_MEMO2 | G16: Memo 2 | H16: メモ２ | I16: E | K16: E | M16: E
A17: 10 | D17: memo3 | E17: #MA.MST_MEMO3 | G17: Memo 3 | H17: メモ３ | I17: E | K17: E | M17: E
A18: 10 | D18: upd_cntr | E18: #MA.UPD_CNT | G18: Update counter | H18: 更新カウンタ | I18: E | K18: E | M18: E
D19: 詳細 :

Sheet CalBase_DelChk01
A1: * | B1: * | D1: L | E1: 1
A2: * | D2: オペレーション実装仕様書 Operation Specification Implementation Sheet | E2: ModuleID : | F2: =IF(LogicCommon!C2="","",LogicCommon!C2) -> MA | G2: LogicID : | H2: =IF(LogicCommon!E2="","",LogicCommon!E2) -> MABCL0032 | I2: Ope.ID : | J2: CalBase_DelChk01 | K2: Pj.ID : | L2: =IF(LogicCommon!G2="","",LogicCommon!G2) -> MC | M2: Ope.Body : | N2: =L4 & ".Checker" -> MA.MAUDL5010.Checker
A3: * | D3: =IF(LogicCommon!A3="","",LogicCommon!A3) | E3: SubModuleID : | F3: =IF(LogicCommon!C3="","",LogicCommon!C3) -> MABC | G3: LogicClass : | H3: =IF(LogicCommon!E3="","",LogicCommon!E3) -> MABCL_MultiReg | I3: Ope.Method : | J3: @ | K3: SuperClassPj.ID : | L3: =IF(LogicCommon!G3="","",LogicCommon!G3) | M3: ReportID : | O3: Gene.Type : | P3: ALL
A4: * | E4: Version : | F4: 000000 | G4: LogicName : | H4: =IF(LogicCommon!E4="","",LogicCommon!E4) -> マルチマスタ登録 | I4: Ope.Name : | J4: チェック | K4: SuperLogicID : | L4: =IF(LogicCommon!G4="","",LogicCommon!G4) -> MA.MAUDL5010
A5: * | E5: ACType :
A6: * | D6: 概要 : | E6: カレンダ基本マスタの削除前のチェックを行います。 | M6: ID
A7: # | I7: U | K7: K | L7: o
A8: # | D8: ブロック名 Block Name | E8: 型 Type | G8: super/share | H8: 対象ブロック名 Target Block Name | K8: REQUIRED | L8: TargetName | P8: ブロック備考 Block Remarks
A9: # | D9: 項目名 Field Name | E9: 型 Type | F9: 桁 Digits | G9: フルネーム Full Name | H9: 日本語名 Japanese Name | I9: 上り項目 Request Message Field | J9: 下り項目 Response Message Field | N9: 条件および編集方法 Conditions and Editing Methods | P9: 項目備考 Field Remarks
A10: # | L10: 上り項目 Request Message Field | M10: 下り項目 Response Message Field
A11: 10 | B11: * | D11: CalBase_DelChk01_Dtl | E11: L
A12: 10 | D12: cal_cd | E12: #MA.CAL_CD | G12: Calendar basic cd. | H12: カレンダ基本ＣＤ | I12: E | K12: E
A13: 10 | D13: upd_cntr | E13: #MA.UPD_CNT | G13: Update counter | H13: 更新カウンタ | I13: E
D14: 詳細 :

Sheet CalBase_Del01
A1: * | B1: * | D1: L | E1: 1
A2: * | D2: オペレーション実装仕様書 Operation Specification Implementation Sheet | E2: ModuleID : | F2: =IF(LogicCommon!C2="","",LogicCommon!C2) -> MA | G2: LogicID : | H2: =IF(LogicCommon!E2="","",LogicCommon!E2) -> MABCL0032 | I2: Ope.ID : | J2: CalBase_Del01 | K2: Pj.ID : | L2: =IF(LogicCommon!G2="","",LogicCommon!G2) -> MC | M2: Ope.Body : | N2: "mcframe.serverMAUD.MAUDL6020.MAUDL_LCLRLDeleter"
A3: * | D3: =IF(LogicCommon!A3="","",LogicCommon!A3) | E3: SubModuleID : | F3: =IF(LogicCommon!C3="","",LogicCommon!C3) -> MABC | G3: LogicClass : | H3: =IF(LogicCommon!E3="","",LogicCommon!E3) -> MABCL_MultiReg | I3: Ope.Method : | J3: @ | K3: SuperClassPj.ID : | L3: =IF(LogicCommon!G3="","",LogicCommon!G3) | M3: ReportID : | O3: Gene.Type : | P3: ALL
A4: * | E4: Version : | F4: 000000 | G4: LogicName : | H4: =IF(LogicCommon!E4="","",LogicCommon!E4) -> マルチマスタ登録 | I4: Ope.Name : | J4: 削除 | K4: SuperLogicID : | L4: =IF(LogicCommon!G4="","",LogicCommon!G4) -> MA.MAUDL5010
A5: * | E5: ACType :
A6: * | D6: 概要 : | E6: カレンダ基本マスタの削除を行います。 | L6: ID | N6: ID | P6: ID | R6: ID
A7: # | I7: U | K7: o | L7: UPDATE.updMaster1 | M7: o | N7: UPDATE.updMaster2 | O7: o | Q7: o
A8: # | D8: ブロック名 Block Name | E8: 型 Type | G8: super/share | H8: 対象ブロック名 Target Block Name | K8: TargetName | L8: DBC.MA.MAM_CAL_BASE | M8: TargetName | N8: DBC.MA.MAM_CAL_BASE_LCL | O8: TargetName | Q8: TargetName | U8: ブロック備考 Block Remarks
A9: # | D9: 項目名 Field Name | E9: 型 Type | F9: 桁 Digits | G9: フルネーム Full Name | H9: 日本語名 Japanese Name | I9: 上り項目 Request Message Field | J9: 下り項目 Response Message Field | S9: 条件および編集方法 Conditions and Editing Methods | U9: 項目備考 Field Remarks
A10: # | K10: 上り項目 Request Message Field | L10: 下り項目 Response Message Field | M10: 上り項目 Request Message Field | N10: 下り項目 Response Message Field | O10: 上り項目 Request Message Field | P10: 下り項目 Response Message Field | Q10: 上り項目 Request Message Field | R10: 下り項目 Response Message Field
A11: 10 | B11: * | D11: CalBase_Del01_Dtl | E11: L | G11: $share$ | H11: MA.MABCL0032.CalBase_DelChk01.CalBase_DelChk01_Dtl | K11: L | M11: L
A12: 10 | D12: cal_cd | E12: #MA.CAL_CD | G12: Calendar basic cd. | H12: カレンダ基本ＣＤ | I12: E | K12: E | M12: E
A13: 10 | D13: upd_cntr | E13: #MA.UPD_CNT | G13: Update counter | H13: 更新カウンタ | I13: E | K13: E
D14: 詳細 :

Sheet ItmJnl_UpdChk01
A1: * | B1: * | D1: L | E1: 1
A2: * | D2: オペレーション実装仕様書 Operation Specification Implementation Sheet | E2: ModuleID : | F2: =IF(LogicCommon!C2="","",LogicCommon!C2) -> MA | G2: LogicID : | H2: =IF(LogicCommon!E2="","",LogicCommon!E2) -> MABCL0032 | I2: Ope.ID : | J2: ItmJnl_UpdChk01 | K2: Pj.ID : | L2: =IF(LogicCommon!G2="","",LogicCommon!G2) -> MC | M2: Ope.Body : | N2: =L4 & ".Checker" -> MA.MAUDL5010.Checker
A3: * | D3: =IF(LogicCommon!A3="","",LogicCommon!A3) | E3: SubModuleID : | F3: =IF(LogicCommon!C3="","",LogicCommon!C3) -> MABC | G3: LogicClass : | H3: =IF(LogicCommon!E3="","",LogicCommon!E3) -> MABCL_MultiReg | I3: Ope.Method : | J3: @ | K3: SuperClassPj.ID : | L3: =IF(LogicCommon!G3="","",LogicCommon!G3) | M3: ReportID : | O3: Gene.Type : | P3: ALL
A4: * | E4: Version : | F4: 000000 | G4: LogicName : | H4: =IF(LogicCommon!E4="","",LogicCommon!E4) -> マルチマスタ登録 | I4: Ope.Name : | J4: チェック | K4: SuperLogicID : | L4: =IF(LogicCommon!G4="","",LogicCommon!G4) -> MA.MAUDL5010
A5: * | E5: ACType :
A6: * | D6: 概要 : | E6: 品目仕訳マスタの登録前のチェックを行います。 | N6: ID
A7: # | I7: U | K7: K | L7: K | M7: o
A8: # | D8: ブロック名 Block Name | E8: 型 Type | G8: super/share | H8: 対象ブロック名 Target Block Name | K8: REQUIRED | L8: CONST | M8: TargetName | Q8: ブロック備考 Block Remarks
A9: # | D9: 項目名 Field Name | E9: 型 Type | F9: 桁 Digits | G9: フルネーム Full Name | H9: 日本語名 Japanese Name | I9: 上り項目 Request Message Field | J9: 下り項目 Response Message Field | O9: 条件および編集方法 Conditions and Editing Methods | Q9: 項目備考 Field Remarks
A10: # | M10: 上り項目 Request Message Field | N10: 下り項目 Response Message Field
A11: 10 | B11: * | D11: ItmJnl_UpdChk01_Dtl | E11: L | G11: $super$ | H11: DBC:MA.MAM_ITM_JNL
A12: 10 | D12: itm_jnl_cd | E12: #MA.ITM_JNL_CD | G12: Item journal cd. | H12: 品目仕訳ＣＤ | I12: E | K12: E
A13: 10 | D13: itm_jnl_nm | E13: #MA.ITM_JNL_NM | G13: Standard Item journal name | H13: 標準品目仕訳名 | I13: E | K13: E
A14: 10 | D14: ar_typ | E14: #MA.AR_TYP | G14: AR type | H14: 債権区分 | I14: E | L14: MAC_AR_TYP
A15: 10 | D15: ap_typ | E15: #MA.AP_TYP | G15: AP type | H15: 債務区分 | I15: E | L15: MAC_AP_TYP
A16: 10 | D16: memo1 | E16: #MA.MST_MEMO1 | G16: Memo 1 | H16: メモ１ | I16: E
A17: 10 | D17: memo2 | E17: #MA.MST_MEMO2 | G17: Memo 2 | H17: メモ２ | I17: E
A18: 10 | D18: memo3 | E18: #MA.MST_MEMO3 | G18: Memo 3 | H18: メモ３ | I18: E
A19: 10 | D19: del_flg | E19: #MA.FLG | G19: Logical delete | H19: 論理削除 | I19: E
A20: 10 | D20: upd_cntr | E20: #MA.UPD_CNT | G20: Update counter | H20: 更新カウンタ | I20: E
D21: 詳細 :

Sheet ItmJnl_Upd01
A1: * | B1: * | D1: L | E1: 1
A2: * | D2: オペレーション実装仕様書 Operation Specification Implementation Sheet | E2: ModuleID : | F2: =IF(LogicCommon!C2="","",LogicCommon!C2) -> MA | G2: LogicID : | H2: =IF(LogicCommon!E2="","",LogicCommon!E2) -> MABCL0032 | I2: Ope.ID : | J2: ItmJnl_Upd01 | K2: Pj.ID : | L2: =IF(LogicCommon!G2="","",LogicCommon!G2) -> MC | M2: Ope.Body : | N2: "mcframe.serverMAUD.MAUDL6020.MAUDL_LCLRLUpdater"
A3: * | D3: =IF(LogicCommon!A3="","",LogicCommon!A3) | E3: SubModuleID : | F3: =IF(LogicCommon!C3="","",LogicCommon!C3) -> MABC | G3: LogicClass : | H3: =IF(LogicCommon!E3="","",LogicCommon!E3) -> MABCL_MultiReg | I3: Ope.Method : | J3: @ | K3: SuperClassPj.ID : | L3: =IF(LogicCommon!G3="","",LogicCommon!G3) | M3: ReportID : | O3: Gene.Type : | P3: ALL
A4: * | E4: Version : | F4: 000000 | G4: LogicName : | H4: =IF(LogicCommon!E4="","",LogicCommon!E4) -> マルチマスタ登録 | I4: Ope.Name : | J4: 登録 | K4: SuperLogicID : | L4: =IF(LogicCommon!G4="","",LogicCommon!G4) -> MA.MAUDL5010
A5: * | E5: ACType :
A6: * | D6: 概要 : | E6: 品目仕訳マスタの登録を行います。 | L6: ID | N6: ID | P6: ID | R6: ID
A7: # | I7: U | K7: o | L7: UPDATE.updMaster | M7: o | N7: MAIN.chkMaster | O7: o | Q7: o
A8: # | D8: ブロック名 Block Name | E8: 型 Type | G8: super/share | H8: 対象ブロック名 Target Block Name | K8: TargetName | L8: DBC.MA.MAM_ITM_JNL | M8: TargetName | N8: DBC.MA.MAM_ITM_JNL | O8: TargetName | Q8: TargetName | U8: ブロック備考 Block Remarks
A9: # | D9: 項目名 Field Name | E9: 型 Type | F9: 桁 Digits | G9: フルネーム Full Name | H9: 日本語名 Japanese Name | I9: 上り項目 Request Message Field | J9: 下り項目 Response Message Field | S9: 条件および編集方法 Conditions and Editing Methods | U9: 項目備考 Field Remarks
A10: # | K10: 上り項目 Request Message Field | L10: 下り項目 Response Message Field | M10: 上り項目 Request Message Field | N10: 下り項目 Response Message Field | O10: 上り項目 Request Message Field | P10: 下り項目 Response Message Field | Q10: 上り項目 Request Message Field | R10: 下り項目 Response Message Field
A11: 10 | B11: * | D11: ItmJnl_Upd01_Dtl | E11: L | G11: $share$ | H11: MA.MABCL0032.ItmJnl_UpdChk01.ItmJnl_UpdChk01_Dtl | K11: L | M11: L
A12: 10 | D12: itm_jnl_cd | E12: #MA.ITM_JNL_CD | G12: Item journal cd. | H12: 品目仕訳ＣＤ | I12: E | K12: E | M12: E
A13: 10 | D13: itm_jnl_nm | E13: #MA.ITM_JNL_NM | G13: Standard Item journal name | H13: 標準品目仕訳名 | I13: E | K13: E | M13: E
A14: 10 | D14: ar_typ | E14: #MA.AR_TYP | G14: AR type | H14: 債権区分 | I14: E | K14: E | M14: E
A15: 10 | D15: ap_typ | E15: #MA.AP_TYP | G15: AP type | H15: 債務区分 | I15: E | K15: E | M15: E
A16: 10 | D16: memo1 | E16: #MA.MST_MEMO1 | G16: Memo 1 | H16: メモ１ | I16: E | K16: E | M16: E
A17: 10 | D17: memo2 | E17: #MA.MST_MEMO2 | G17: Memo 2 | H17: メモ２ | I17: E | K17: E | M17: E
A18: 10 | D18: memo3 | E18: #MA.MST_MEMO3 | G18: Memo 3 | H18: メモ３ | I18: E | K18: E | M18: E
A19: 10 | D19: del_flg | E19: #MA.FLG | G19: Logical delete | H19: 論理削除 | I19: E | K19: E | M19: E
A20: 10 | D20: upd_cntr | E20: #MA.UPD_CNT | G20: Update counter | H20: 更新カウンタ | I20: E | K20: E | M20: E
D21: 詳細 :

Sheet ItmJnlLcl_UpdChk01
A1: * | B1: * | D1: L | E1: 1
A2: * | D2: オペレーション実装仕様書 Operation Specification Implementation Sheet | E2: ModuleID : | F2: =IF(LogicCommon!C2="","",LogicCommon!C2) -> MA | G2: LogicID : | H2: =IF(LogicCommon!E2="","",LogicCommon!E2) -> MABCL0032 | I2: Ope.ID : | J2: ItmJnlLcl_UpdChk01 | K2: Pj.ID : | L2: =IF(LogicCommon!G2="","",LogicCommon!G2) -> MC | M2: Ope.Body : | N2: =L4 & ".Checker" -> MA.MAUDL5010.Checker
A3: * | D3: =IF(LogicCommon!A3="","",LogicCommon!A3) | E3: SubModuleID : | F3: =IF(LogicCommon!C3="","",LogicCommon!C3) -> MABC | G3: LogicClass : | H3: =IF(LogicCommon!E3="","",LogicCommon!E3) -> MABCL_MultiReg | I3: Ope.Method : | J3: @ | K3: SuperClassPj.ID : | L3: =IF(LogicCommon!G3="","",LogicCommon!G3) | M3: ReportID : | O3: Gene.Type : | P3: ALL
A4: * | E4: Version : | F4: 000000 | G4: LogicName : | H4: =IF(LogicCommon!E4="","",LogicCommon!E4) -> マルチマスタ登録 | I4: Ope.Name : | J4: チェック | K4: SuperLogicID : | L4: =IF(LogicCommon!G4="","",LogicCommon!G4) -> MA.MAUDL5010
A5: * | E5: ACType :
A6: * | D6: 概要 : | E6: 品目仕訳マスタの登録前のチェックを行います。（ロケール用） | M6: ID
A7: # | I7: U | K7: K | L7: o | M7: EXISTS.chk01
A8: # | D8: ブロック名 Block Name | E8: 型 Type | G8: super/share | H8: 対象ブロック名 Target Block Name | K8: REQUIRED | L8: TargetName | M8: DBC.MA.MAM_ITM_JNL | P8: ブロック備考 Block Remarks
A9: # | D9: 項目名 Field Name | E9: 型 Type | F9: 桁 Digits | G9: フルネーム Full Name | H9: 日本語名 Japanese Name | I9: 上り項目 Request Message Field | J9: 下り項目 Response Message Field | N9: 条件および編集方法 Conditions and Editing Methods | P9: 項目備考 Field Remarks
A10: # | L10: 上り項目 Request Message Field | M10: 下り項目 Response Message Field
A11: 10 | B11: * | D11: ItmJnlLcl_UpdChk01_Dtl | E11: L | G11: $super$ | H11: DBC:MA.MAM_ITM_JNL_LCL | L11: L
A12: 10 | D12: itm_jnl_cd | E12: #MA.ITM_JNL_CD | G12: Item journal cd. | H12: 品目仕訳ＣＤ | I12: E | K12: E | L12: E
A13: 10 | D13: lcl_cd | E13: #MA.LCL_CD | G13: Locale cd. | H13: ロケールＣＤ | I13: E | K13: E
A14: 10 | D14: itm_jnl_nm | E14: #MA.ITM_JNL_NM | G14: Item journal name | H14: 品目仕訳名 | I14: E | K14: E
A15: 10 | D15: memo1 | E15: #MA.MST_MEMO1 | G15: Memo 1 | H15: メモ１ | I15: E
A16: 10 | D16: memo2 | E16: #MA.MST_MEMO2 | G16: Memo 2 | H16: メモ２ | I16: E
A17: 10 | D17: memo3 | E17: #MA.MST_MEMO3 | G17: Memo 3 | H17: メモ３ | I17: E
A18: 10 | D18: upd_cntr | E18: #MA.UPD_CNT | G18: Update counter | H18: 更新カウンタ | I18: E
D19: 詳細 :

Sheet ItmJnlLcl_Upd01
A1: * | B1: * | D1: L | E1: 1
A2: * | D2: オペレーション実装仕様書 Operation Specification Implementation Sheet | E2: ModuleID : | F2: =IF(LogicCommon!C2="","",LogicCommon!C2) -> MA | G2: LogicID : | H2: =IF(LogicCommon!E2="","",LogicCommon!E2) -> MABCL0032 | I2: Ope.ID : | J2: ItmJnlLcl_Upd01 | K2: Pj.ID : | L2: =IF(LogicCommon!G2="","",LogicCommon!G2) -> MC | M2: Ope.Body : | N2: "mcframe.serverMAUD.MAUDL6020.MAUDL_LCLRLUpdater"
A3: * | D3: =IF(LogicCommon!A3="","",LogicCommon!A3) | E3: SubModuleID : | F3: =IF(LogicCommon!C3="","",LogicCommon!C3) -> MABC | G3: LogicClass : | H3: =IF(LogicCommon!E3="","",LogicCommon!E3) -> MABCL_MultiReg | I3: Ope.Method : | J3: @ | K3: SuperClassPj.ID : | L3: =IF(LogicCommon!G3="","",LogicCommon!G3) | M3: ReportID : | O3: Gene.Type : | P3: ALL
A4: * | E4: Version : | F4: 000000 | G4: LogicName : | H4: =IF(LogicCommon!E4="","",LogicCommon!E4) -> マルチマスタ登録 | I4: Ope.Name : | J4: 登録 | K4: SuperLogicID : | L4: =IF(LogicCommon!G4="","",LogicCommon!G4) -> MA.MAUDL5010
A5: * | E5: ACType :
A6: * | D6: 概要 : | E6: 品目仕訳マスタの登録を行います。（ロケール用） | L6: ID | N6: ID | P6: ID | R6: ID
A7: # | I7: U | K7: o | L7: UPDATE.updMaster | M7: o | N7: MAIN.chkMaster | O7: o | Q7: o
A8: # | D8: ブロック名 Block Name | E8: 型 Type | G8: super/share | H8: 対象ブロック名 Target Block Name | K8: TargetName | L8: DBC.MA.MAM_ITM_JNL_LCL | M8: TargetName | N8: DBC.MA.MAM_ITM_JNL_LCL | O8: TargetName | Q8: TargetName | U8: ブロック備考 Block Remarks
A9: # | D9: 項目名 Field Name | E9: 型 Type | F9: 桁 Digits | G9: フルネーム Full Name | H9: 日本語名 Japanese Name | I9: 上り項目 Request Message Field | J9: 下り項目 Response Message Field | S9: 条件および編集方法 Conditions and Editing Methods | U9: 項目備考 Field Remarks
A10: # | K10: 上り項目 Request Message Field | L10: 下り項目 Response Message Field | M10: 上り項目 Request Message Field | N10: 下り項目 Response Message Field | O10: 上り項目 Request Message Field | P10: 下り項目 Response Message Field | Q10: 上り項目 Request Message Field | R10: 下り項目 Response Message Field
A11: 10 | B11: * | D11: ItmJnlLcl_Upd01_Dtl | E11: L | G11: $share$ | H11: MA.MABCL0032.ItmJnlLcl_UpdChk01.ItmJnlLcl_UpdChk01_Dtl | K11: L | M11: L
A12: 10 | D12: itm_jnl_cd | E12: #MA.ITM_JNL_CD | G12: Item journal cd. | H12: 品目仕訳ＣＤ | I12: E | K12: E | M12: E
A13: 10 | D13: lcl_cd | E13: #MA.LCL_CD | G13: Locale cd. | H13: ロケールＣＤ | I13: E | K13: E | M13: E
A14: 10 | D14: itm_jnl_nm | E14: #MA.ITM_JNL_NM | G14: Item journal name | H14: 品目仕訳名 | I14: E | K14: E | M14: E
A15: 10 | D15: memo1 | E15: #MA.MST_MEMO1 | G15: Memo 1 | H15: メモ１ | I15: E | K15: E | M15: E
A16: 10 | D16: memo2 | E16: #MA.MST_MEMO2 | G16: Memo 2 | H16: メモ２ | I16: E | K16: E | M16: E
A17: 10 | D17: memo3 | E17: #MA.MST_MEMO3 | G17: Memo 3 | H17: メモ３ | I17: E | K17: E | M17: E
A18: 10 | D18: upd_cntr | E18: #MA.UPD_CNT | G18: Update counter | H18: 更新カウンタ | I18: E | K18: E | M18: E
D19: 詳細 :

Sheet ItmJnl_DelChk01
A1: * | B1: * | D1: L | E1: 1
A2: * | D2: オペレーション実装仕様書 Operation Specification Implementation Sheet | E2: ModuleID : | F2: =IF(LogicCommon!C2="","",LogicCommon!C2) -> MA | G2: LogicID : | H2: =IF(LogicCommon!E2="","",LogicCommon!E2) -> MABCL0032 | I2: Ope.ID : | J2: ItmJnl_DelChk01 | K2: Pj.ID : | L2: =IF(LogicCommon!G2="","",LogicCommon!G2) -> MC | M2: Ope.Body : | N2: =L4 & ".Checker" -> MA.MAUDL5010.Checker
A3: * | D3: =IF(LogicCommon!A3="","",LogicCommon!A3) | E3: SubModuleID : | F3: =IF(LogicCommon!C3="","",LogicCommon!C3) -> MABC | G3: LogicClass : | H3: =IF(LogicCommon!E3="","",LogicCommon!E3) -> MABCL_MultiReg | I3: Ope.Method : | J3: @ | K3: SuperClassPj.ID : | L3: =IF(LogicCommon!G3="","",LogicCommon!G3) | M3: ReportID : | O3: Gene.Type : | P3: ALL
A4: * | E4: Version : | F4: 000000 | G4: LogicName : | H4: =IF(LogicCommon!E4="","",LogicCommon!E4) -> マルチマスタ登録 | I4: Ope.Name : | J4: チェック | K4: SuperLogicID : | L4: =IF(LogicCommon!G4="","",LogicCommon!G4) -> MA.MAUDL5010
A5: * | E5: ACType :
A6: * | D6: 概要 : | E6: 品目仕訳マスタの削除前のチェックを行います。 | M6: ID
A7: # | I7: U | K7: K | L7: o
A8: # | D8: ブロック名 Block Name | E8: 型 Type | G8: super/share | H8: 対象ブロック名 Target Block Name | K8: REQUIRED | L8: TargetName | P8: ブロック備考 Block Remarks
A9: # | D9: 項目名 Field Name | E9: 型 Type | F9: 桁 Digits | G9: フルネーム Full Name | H9: 日本語名 Japanese Name | I9: 上り項目 Request Message Field | J9: 下り項目 Response Message Field | N9: 条件および編集方法 Conditions and Editing Methods | P9: 項目備考 Field Remarks
A10: # | L10: 上り項目 Request Message Field | M10: 下り項目 Response Message Field
A11: 10 | B11: * | D11: ItmJnl_DelChk01_Dtl | E11: L
A12: 10 | D12: itm_jnl_cd | E12: #MA.ITM_JNL_CD | G12: Item journal cd. | H12: 品目仕訳ＣＤ | I12: E | K12: E
A13: 10 | D13: upd_cntr | E13: #MA.UPD_CNT | G13: Update counter | H13: 更新カウンタ | I13: E
D14: 詳細 :

Sheet ItmJnl_Del01
A1: * | B1: * | D1: L | E1: 1
A2: * | D2: オペレーション実装仕様書 Operation Specification Implementation Sheet | E2: ModuleID : | F2: =IF(LogicCommon!C2="","",LogicCommon!C2) -> MA | G2: LogicID : | H2: =IF(LogicCommon!E2="","",LogicCommon!E2) -> MABCL0032 | I2: Ope.ID : | J2: ItmJnl_Del01 | K2: Pj.ID : | L2: =IF(LogicCommon!G2="","",LogicCommon!G2) -> MC | M2: Ope.Body : | N2: "mcframe.serverMAUD.MAUDL6020.MAUDL_LCLRLDeleter"
A3: * | D3: =IF(LogicCommon!A3="","",LogicCommon!A3) | E3: SubModuleID : | F3: =IF(LogicCommon!C3="","",LogicCommon!C3) -> MABC | G3: LogicClass : | H3: =IF(LogicCommon!E3="","",LogicCommon!E3) -> MABCL_MultiReg | I3: Ope.Method : | J3: @ | K3: SuperClassPj.ID : | L3: =IF(LogicCommon!G3="","",LogicCommon!G3) | M3: ReportID : | O3: Gene.Type : | P3: ALL
A4: * | E4: Version : | F4: 000000 | G4: LogicName : | H4: =IF(LogicCommon!E4="","",LogicCommon!E4) -> マルチマスタ登録 | I4: Ope.Name : | J4: 削除 | K4: SuperLogicID : | L4: =IF(LogicCommon!G4="","",LogicCommon!G4) -> MA.MAUDL5010
A5: * | E5: ACType :
A6: * | D6: 概要 : | E6: 品目仕訳マスタの削除を行います。 | L6: ID | N6: ID | P6: ID | R6: ID
A7: # | I7: U | K7: o | L7: UPDATE.updMaster1 | M7: o | N7: UPDATE.updMaster2 | O7: o | Q7: o
A8: # | D8: ブロック名 Block Name | E8: 型 Type | G8: super/share | H8: 対象ブロック名 Target Block Name | K8: TargetName | L8: DBC.MA.MAM_ITM_JNL | M8: TargetName | N8: DBC.MA.MAM_ITM_JNL_LCL | O8: TargetName | Q8: TargetName | U8: ブロック備考 Block Remarks
A9: # | D9: 項目名 Field Name | E9: 型 Type | F9: 桁 Digits | G9: フルネーム Full Name | H9: 日本語名 Japanese Name | I9: 上り項目 Request Message Field | J9: 下り項目 Response Message Field | S9: 条件および編集方法 Conditions and Editing Methods | U9: 項目備考 Field Remarks
