Workbook

Sheet LogicCommon
A2: ロジック共通定義 | B2: ModuleID : | C2: MA | D2: LogicID : | E2: MABCL0280 | F2: Pj.ID : | G2: MC
B3: SubModuleID : | C3: MABC | D3: LogicClass : | E3: MABCL_DptReg | F3: SuperClassPj.ID :
D4: LogicName : | E4: 部門マスタ登録 | F4: SuperLogicID : | G4: MA.MAUDL5010
A5: 概要 :
A6: 詳細 :

Sheet DptHis_UpdChk01
A1: * | B1: * | D1: L | E1: 1
A2: * | D2: オペレーション実装仕様書 Operation Specification Implementation Sheet | E2: ModuleID : | F2: =IF(LogicCommon!C2="","",LogicCommon!C2) -> MA | G2: LogicID : | H2: =IF(LogicCommon!E2="","",LogicCommon!E2) -> MABCL0280 | I2: Ope.ID : | J2: DptHis_UpdChk01 | K2: Pj.ID : | L2: =IF(LogicCommon!G2="","",LogicCommon!G2) -> MC | M2: Ope.Body : | N2: =L4 & ".Checker" -> MA.MAUDL5010.Checker
A3: * | D3: =IF(LogicCommon!A3="","",LogicCommon!A3) | E3: SubModuleID : | F3: =IF(LogicCommon!C3="","",LogicCommon!C3) -> MABC | G3: LogicClass : | H3: =IF(LogicCommon!E3="","",LogicCommon!E3) -> MABCL_DptReg | I3: Ope.Method : | J3: @ | K3: SuperClassPj.ID : | L3: =IF(LogicCommon!G3="","",LogicCommon!G3) | M3: ReportID : | O3: Gene.Type : | P3: ALL
A4: * | E4: Version : | F4: 000000 | G4: LogicName : | H4: =IF(LogicCommon!E4="","",LogicCommon!E4) -> 部門マスタ登録 | I4: Ope.Name : | J4: 登録前チェック(変更履歴) | K4: SuperLogicID : | L4: =IF(LogicCommon!G4="","",LogicCommon!G4) -> MA.MAUDL5010
A5: * | E5: ACType :
A6: * | D6: 概要 : | E6: 部門変更履歴マスタを登録する前のチェックを行う | N6: ID
A7: # | I7: U | K7: K | L7: K | M7: o
A8: # | D8: ブロック名 Block Name | E8: 型 Type | G8: super/share | H8: 対象ブロック名 Target Block Name | K8: REQUIRED | L8: BEFORE_AFTER | M8: TargetName | Q8: ブロック備考 Block Remarks
A9: # | D9: 項目名 Field Name | E9: 型 Type | F9: 桁 Digits | G9: フルネーム Full Name | H9: 日本語名 Japanese Name | I9: 上り項目 Request Message Field | J9: 下り項目 Response Message Field | O9: 条件および編集方法 Conditions and Editing Methods | Q9: 項目備考 Field Remarks
A10: # | M10: 上り項目 Request Message Field | N10: 下り項目 Response Message Field
A11: 10 | B11: * | D11: DptHis_UpdChk01_Dtl | E11: L | G11: $super$ | H11: DBC:MA.MAM_DPT_HIS
A12: 10 | D12: st_dt | E12: #MA.DT | G12: Application start date | H12: 適用開始日 | I12: E | K12: E | L12: E:BF
A13: 10 | D13: st_dt_key | E13: #MA.DT | G13: Application start date_[Before change] | H13: 適用開始日_[変更前] | I13: E
A14: 10 | D14: end_dt | E14: #MA.DT | G14: Application end date | H14: 適用終了日 | I14: E | K14: E | L14: E:AF
A15: 10 | D15: dpt_his_rmrks | E15: #MA.DPT_HIS_RMRKS | G15: Organizational changes remarks | H15: 組織変更備考 | I15: E | K15: E
A16: 10 | D16: memo1 | E16: #MA.MST_MEMO1 | G16: Memo 1 | H16: メモ１ | I16: E
A17: 10 | D17: memo2 | E17: #MA.MST_MEMO2 | G17: Memo 2 | H17: メモ２ | I17: E
A18: 10 | D18: memo3 | E18: #MA.MST_MEMO3 | G18: Memo 3 | H18: メモ３ | I18: E
A19: 10 | D19: upd_cntr | E19: #MA.UPD_CNT | G19: Update counter | H19: 更新カウンタ | I19: E
D20: 詳細 :

Sheet DptHis_Upd01
A1: * | B1: * | D1: L | E1: 1
A2: * | D2: オペレーション実装仕様書 Operation Specification Implementation Sheet | E2: ModuleID : | F2: =IF(LogicCommon!C2="","",LogicCommon!C2) -> MA | G2: LogicID : | H2: =IF(LogicCommon!E2="","",LogicCommon!E2) -> MABCL0280 | I2: Ope.ID : | J2: DptHis_Upd01 | K2: Pj.ID : | L2: =IF(LogicCommon!G2="","",LogicCommon!G2) -> MC | M2: Ope.Body : | N2: "mcframe.serverMAUD.MAUDL6010.MAUDL_RLUpdater"
A3: * | D3: =IF(LogicCommon!A3="","",LogicCommon!A3) | E3: SubModuleID : | F3: =IF(LogicCommon!C3="","",LogicCommon!C3) -> MABC | G3: LogicClass : | H3: =IF(LogicCommon!E3="","",LogicCommon!E3) -> MABCL_DptReg | I3: Ope.Method : | J3: @ | K3: SuperClassPj.ID : | L3: =IF(LogicCommon!G3="","",LogicCommon!G3) | M3: ReportID : | O3: Gene.Type : | P3: ALL
A4: * | E4: Version : | F4: 000000 | G4: LogicName : | H4: =IF(LogicCommon!E4="","",LogicCommon!E4) -> 部門マスタ登録 | I4: Ope.Name : | J4: 登録処理 | K4: SuperLogicID : | L4: =IF(LogicCommon!G4="","",LogicCommon!G4) -> MA.MAUDL5010
A5: * | E5: ACType :
A6: * | D6: 概要 : | E6: 部門変更履歴マスタを登録する | L6: ID | N6: ID | P6: ID | R6: ID
A7: # | I7: U | K7: o | L7: UPDATE.updMaster | M7: o | N7: MAIN.chkMaster | O7: o | Q7: o
A8: # | D8: ブロック名 Block Name | E8: 型 Type | G8: super/share | H8: 対象ブロック名 Target Block Name | K8: TargetName | L8: DBC.MA.MAM_DPT_HIS | M8: TargetName | N8: DBC.MA.MAM_DPT_HIS | O8: TargetName | Q8: TargetName | U8: ブロック備考 Block Remarks
A9: # | D9: 項目名 Field Name | E9: 型 Type | F9: 桁 Digits | G9: フルネーム Full Name | H9: 日本語名 Japanese Name | I9: 上り項目 Request Message Field | J9: 下り項目 Response Message Field | S9: 条件および編集方法 Conditions and Editing Methods | U9: 項目備考 Field Remarks
A10: # | K10: 上り項目 Request Message Field | L10: 下り項目 Response Message Field | M10: 上り項目 Request Message Field | N10: 下り項目 Response Message Field | O10: 上り項目 Request Message Field | P10: 下り項目 Response Message Field | Q10: 上り項目 Request Message Field | R10: 下り項目 Response Message Field
A11: 10 | B11: * | D11: DptHis_Upd01_Dtl | E11: L | G11: $share$ | H11: MA.MABCL0280.DptHis_UpdChk01.DptHis_UpdChk01_Dtl | K11: L | M11: L
A12: 10 | D12: st_dt | E12: #MA.DT | G12: Application start date | H12: 適用開始日 | I12: E | K12: E | M12: E
A13: 10 | D13: st_dt_key | E13: #MA.DT | G13: Application start date_[Before change] | H13: 適用開始日_[変更前] | I13: E
A14: 10 | D14: end_dt | E14: #MA.DT | G14: Application end date | H14: 適用終了日 | I14: E | K14: E | M14: E
A15: 10 | D15: dpt_his_rmrks | E15: #MA.DPT_HIS_RMRKS | G15: Organizational changes remarks | H15: 組織変更備考 | I15: E | K15: E | M15: E
A16: 10 | D16: memo1 | E16: #MA.MST_MEMO1 | G16: Memo 1 | H16: メモ１ | I16: E | K16: E | M16: E
A17: 10 | D17: memo2 | E17: #MA.MST_MEMO2 | G17: Memo 2 | H17: メモ２ | I17: E | K17: E | M17: E
A18: 10 | D18: memo3 | E18: #MA.MST_MEMO3 | G18: Memo 3 | H18: メモ３ | I18: E | K18: E | M18: E
A19: 10 | D19: upd_cntr | E19: #MA.UPD_CNT | G19: Update counter | H19: 更新カウンタ | I19: E | K19: E | M19: E
D20: 詳細 :

Sheet Dpt_UpdChk01
A1: * | B1: * | D1: L | E1: 1
A2: * | D2: オペレーション実装仕様書 Operation Specification Implementation Sheet | E2: ModuleID : | F2: =IF(LogicCommon!C2="","",LogicCommon!C2) -> MA | G2: LogicID : | H2: =IF(LogicCommon!E2="","",LogicCommon!E2) -> MABCL0280 | I2: Ope.ID : | J2: Dpt_UpdChk01 | K2: Pj.ID : | L2: =IF(LogicCommon!G2="","",LogicCommon!G2) -> MC | M2: Ope.Body : | N2: =L4 & ".Checker" -> MA.MAUDL5010.Checker
A3: * | D3: =IF(LogicCommon!A3="","",LogicCommon!A3) | E3: SubModuleID : | F3: =IF(LogicCommon!C3="","",LogicCommon!C3) -> MABC | G3: LogicClass : | H3: =IF(LogicCommon!E3="","",LogicCommon!E3) -> MABCL_DptReg | I3: Ope.Method : | J3: @ | K3: SuperClassPj.ID : | L3: =IF(LogicCommon!G3="","",LogicCommon!G3) | M3: ReportID : | O3: Gene.Type : | P3: ALL
A4: * | E4: Version : | F4: 000000 | G4: LogicName : | H4: =IF(LogicCommon!E4="","",LogicCommon!E4) -> 部門マスタ登録 | I4: Ope.Name : | J4: 登録前チェック | K4: SuperLogicID : | L4: =IF(LogicCommon!G4="","",LogicCommon!G4) -> MA.MAUDL5010
A5: * | E5: ACType :
A6: * | D6: 概要 : | E6: 部門マスタを登録する前のチェックを行う | U6: ID
A7: # | I7: U | K7: K | L7: K | M7: K | N7: K | O7: K | P7: K | Q7: K | R7: K | S7: K | T7: o
A8: # | D8: ブロック名 Block Name | E8: 型 Type | G8: super/share | H8: 対象ブロック名 Target Block Name | K8: REQUIRED | L8: BEFORE_AFTER | M8: DUPLICATE | N8: LIST_LOGIC | O8: LIST_IN | P8: LIST_IN_BASE | Q8: LIST_OUT | R8: LIST_OUT_BASE | S8: CHK_PTN | T8: TargetName | X8: ブロック備考 Block Remarks
A9: # | D9: 項目名 Field Name | E9: 型 Type | F9: 桁 Digits | G9: フルネーム Full Name | H9: 日本語名 Japanese Name | I9: 上り項目 Request Message Field | J9: 下り項目 Response Message Field | V9: 条件および編集方法 Conditions and Editing Methods | X9: 項目備考 Field Remarks
A10: # | T10: 上り項目 Request Message Field | U10: 下り項目 Response Message Field
A11: 10 | B11: * | D11: Dpt_UpdChk01_Dtl | E11: L | G11: $super$ | H11: DBC:MA.MAM_DPT
A12: 10 | D12: dpt_cd | E12: #MA.DPT_CD | G12: Dept. cd. | H12: 部門ＣＤ | I12: E | K12: E | M12: key
A13: 10 | D13: dpt_cd_key | E13: #MA.DPT_CD | G13: Dept. cd_[Before change] | H13: 部門ＣＤ_[変更前] | I13: E
A14: 10 | D14: st_dt | E14: #MA.DT | G14: Application start date | H14: 適用開始日 | I14: E | K14: E | L14: E:BF
A15: 10 | D15: st_dt_key | E15: #MA.DT | G15: Application start date_[Before change] | H15: 適用開始日_[変更前] | I15: E
A16: 10 | D16: end_dt | E16: #MA.DT | G16: Application end date | H16: 適用終了日 | I16: E | K16: E | L16: E:AF
A17: 10 | D17: dpt_nm | E17: #MA.DPT_NM | G17: Standard dept. name | H17: 標準部門名 | I17: E | K17: E
A18: 10 | D18: dpt_lvl_cd | E18: #MA.DPT_LVL_CD | G18: Dept. hierarchy cd. | H18: 部門階層ＣＤ | I18: E | K18: E | N18: MA.MAUAL0010.DptLvl
A19: 10 | D19: up_lv_dpt_cd | E19: #MA.DPT_CD | G19: Upper dept. cd. | H19: 上位部門ＣＤ | I19: E | N19: MA.MAUAL0010.DptBase
A20: 10 | D20: new_dpt_cd | E20: #MA.DPT_CD | G20: New dept. cd. | H20: 新部門ＣＤ | I20: E | N20: MA.MAUAL0010.DptBase
A21: 10 | D21: zip_cd | E21: #MA.ZIP_CD | G21: Zip code | H21: 郵便番号 | I21: E | S21: ZIP
A22: 10 | D22: addr1 | E22: #MA.ADDR1 | G22: Address 1 | H22: 住所１ | I22: E | K22: E
A23: 10 | D23: addr2 | E23: #MA.ADDR2 | G23: Address 2 | H23: 住所２ | I23: E
A24: 10 | D24: addr3 | E24: #MA.ADDR3 | G24: Address 3 | H24: 住所３ | I24: E
A25: 10 | D25: addr4 | E25: #MA.ADDR4 | G25: Address 4 | H25: 住所４ | I25: E
A26: 10 | D26: tel | E26: #MA.TEL | G26: TEL | H26: ＴＥＬ | I26: E | S26: TEL
A27: 10 | D27: fax | E27: #MA.TEL | G27: FAX | H27: ＦＡＸ | I27: E | S27: TEL
A28: 10 | D28: wg_cd | E28: #MA.WG_CD | G28: WG cd. | H28: ワーキンググループＣＤ | I28: E | N28: MA.MAUAL0010.Wg | Q28: sls_flg;lg_flg;mfg_flg;purc_flg;ar_flg;ap_flg;sd_flg | R28: sls_flg;lg_flg;mfg_flg;purc_flg;ar_flg;ap_flg;sd_flg
A29: 10 | D29: rcv_bank_ac_cd | E29: #MA.BANK_AC_CD | G29: Payment received bank account cd. | H29: 入金口座ＣＤ | I29: E | N29: MA.MAUAL0010.BankAc
A30: 10 | D30: pay_bank_ac_cd | E30: #MA.BANK_AC_CD | G30: Payment account cd. | H30: 支払口座ＣＤ | I30: E | N30: MA.MAUAL0010.BankAc
A31: 10 | D31: cal_cd | E31: #MA.CAL_CD | G31: Calendar cd. | H31: カレンダＣＤ | I31: E | N31: MA.MAUAL0010.CalBase
A32: 10 | D32: asst_dpt_flg | E32: #MA.FLG | G32: Asset management dept. | H32: 資産管理部門 | I32: E
A33: 10 | D33: ar_dpt_flg | E33: #MA.FLG | G33: AR dept. | H33: 債権部門 | I33: E
A34: 10 | D34: ap_dpt_flg | E34: #MA.FLG | G34: AP dept. | H34: 債務部門 | I34: E
A35: 10 | D35: sls_dpt_flg | E35: #MA.FLG | G35: Sales dept. | H35: 営業部門 | I35: E
A36: 10 | D36: purc_dpt_flg | E36: #MA.FLG | G36: Purchasing dept. | H36: 購買部門 | I36: E
A37: 10 | D37: ship_dpt_flg | E37: #MA.FLG | G37: Shipping dept. | H37: 出荷部門 | I37: E
A38: 10 | D38: arr_dpt_flg | E38: #MA.FLG | G38: Receipt dept. | H38: 入荷部門 | I38: E
A39: 10 | D39: mfg_dpt_flg | E39: #MA.FLG | G39: Mfg. dept. | H39: 製造部門 | I39: E
A40: 10 | D40: sd_dpt_flg | E40: #MA.FLG | G40: Demand and supply dept. | H40: 需給部門 | I40: E
...

Sheet Dpt_Upd01
A1: * | B1: * | D1: L | E1: 1
A2: * | D2: オペレーション実装仕様書 Operation Specification Implementation Sheet | E2: ModuleID : | F2: =IF(LogicCommon!C2="","",LogicCommon!C2) -> MA | G2: LogicID : | H2: =IF(LogicCommon!E2="","",LogicCommon!E2) -> MABCL0280 | I2: Ope.ID : | J2: Dpt_Upd01 | K2: Pj.ID : | L2: =IF(LogicCommon!G2="","",LogicCommon!G2) -> MC | M2: Ope.Body : | N2: "mcframe.serverMAUD.MAUDL6010.MAUDL_RLUpdater"
A3: * | D3: =IF(LogicCommon!A3="","",LogicCommon!A3) | E3: SubModuleID : | F3: =IF(LogicCommon!C3="","",LogicCommon!C3) -> MABC | G3: LogicClass : | H3: =IF(LogicCommon!E3="","",LogicCommon!E3) -> MABCL_DptReg | I3: Ope.Method : | J3: @ | K3: SuperClassPj.ID : | L3: =IF(LogicCommon!G3="","",LogicCommon!G3) | M3: ReportID : | O3: Gene.Type : | P3: ALL
A4: * | E4: Version : | F4: 000000 | G4: LogicName : | H4: =IF(LogicCommon!E4="","",LogicCommon!E4) -> 部門マスタ登録 | I4: Ope.Name : | J4: 登録処理 | K4: SuperLogicID : | L4: =IF(LogicCommon!G4="","",LogicCommon!G4) -> MA.MAUDL5010
A5: * | E5: ACType :
A6: * | D6: 概要 : | E6: 部門マスタを登録する | L6: ID | N6: ID | P6: ID | R6: ID
A7: # | I7: U | K7: o | L7: UPDATE.updMaster | M7: o | N7: MAIN.chkMaster | O7: o | Q7: o
A8: # | D8: ブロック名 Block Name | E8: 型 Type | G8: super/share | H8: 対象ブロック名 Target Block Name | K8: TargetName | L8: DBC.MA.MAM_DPT | M8: TargetName | N8: DBC.MA.MAM_DPT | O8: TargetName | Q8: TargetName | U8: ブロック備考 Block Remarks
A9: # | D9: 項目名 Field Name | E9: 型 Type | F9: 桁 Digits | G9: フルネーム Full Name | H9: 日本語名 Japanese Name | I9: 上り項目 Request Message Field | J9: 下り項目 Response Message Field | S9: 条件および編集方法 Conditions and Editing Methods | U9: 項目備考 Field Remarks
A10: # | K10: 上り項目 Request Message Field | L10: 下り項目 Response Message Field | M10: 上り項目 Request Message Field | N10: 下り項目 Response Message Field | O10: 上り項目 Request Message Field | P10: 下り項目 Response Message Field | Q10: 上り項目 Request Message Field | R10: 下り項目 Response Message Field
A11: 10 | B11: * | D11: Dpt_Upd01_Dtl | E11: L | G11: $share$ | H11: MA.MABCL0280.Dpt_UpdChk01.Dpt_UpdChk01_Dtl | K11: L | M11: L
A12: 10 | D12: dpt_cd | E12: #MA.DPT_CD | G12: Dept. cd. | H12: 部門ＣＤ | I12: E | K12: E | M12: E
A13: 10 | D13: dpt_cd_key | E13: #MA.DPT_CD | G13: Dept. cd_[Before change] | H13: 部門ＣＤ_[変更前] | I13: E
A14: 10 | D14: st_dt | E14: #MA.DT | G14: Application start date | H14: 適用開始日 | I14: E | K14: E | M14: E
A15: 10 | D15: st_dt_key | E15: #MA.DT | G15: Application start date_[Before change] | H15: 適用開始日_[変更前] | I15: E
A16: 10 | D16: end_dt | E16: #MA.DT | G16: Application end date | H16: 適用終了日 | I16: E | K16: E | M16: E
A17: 10 | D17: dpt_nm | E17: #MA.DPT_NM | G17: Standard dept. name | H17: 標準部門名 | I17: E | K17: E | M17: E
A18: 10 | D18: dpt_lvl_cd | E18: #MA.DPT_LVL_CD | G18: Dept. hierarchy cd. | H18: 部門階層ＣＤ | I18: E | K18: E | M18: E
A19: 10 | D19: up_lv_dpt_cd | E19: #MA.DPT_CD | G19: Upper dept. cd. | H19: 上位部門ＣＤ | I19: E | K19: E | M19: E
A20: 10 | D20: new_dpt_cd | E20: #MA.DPT_CD | G20: New dept. cd. | H20: 新部門ＣＤ | I20: E | K20: E | M20: E
A21: 10 | D21: zip_cd | E21: #MA.ZIP_CD | G21: Zip code | H21: 郵便番号 | I21: E | K21: E | M21: E
A22: 10 | D22: addr1 | E22: #MA.ADDR1 | G22: Address 1 | H22: 住所１ | I22: E | K22: E | M22: E
A23: 10 | D23: addr2 | E23: #MA.ADDR2 | G23: Address 2 | H23: 住所２ | I23: E | K23: E | M23: E
A24: 10 | D24: addr3 | E24: #MA.ADDR3 | G24: Address 3 | H24: 住所３ | I24: E | K24: E | M24: E
A25: 10 | D25: addr4 | E25: #MA.ADDR4 | G25: Address 4 | H25: 住所４ | I25: E | K25: E | M25: E
A26: 10 | D26: tel | E26: #MA.TEL | G26: TEL | H26: ＴＥＬ | I26: E | K26: E | M26: E
A27: 10 | D27: fax | E27: #MA.TEL | G27: FAX | H27: ＦＡＸ | I27: E | K27: E | M27: E
... A49: 10 | D49: upd_cntr | E49: #MA.UPD_CNT | G49: Update counter | H49: 更新カウンタ | I49: E | K49: E | M49: E
D50: 詳細 :

Sheet DptMap_UpdChk01
A1: * | B1: * | D1: L | E1: 1
A2: * | D2: オペレーション実装仕様書 Operation Specification Implementation Sheet | E2: ModuleID : | F2: =IF(LogicCommon!C2="","",LogicCommon!C2) -> MA | G2: LogicID : | H2: =IF(LogicCommon!E2="","",LogicCommon!E2) -> MABCL0280 | I2: Ope.ID : | J2: DptMap_UpdChk01 | K2: Pj.ID : | L2: =IF(LogicCommon!G2="","",LogicCommon!G2) -> MC | M2: Ope.Body : | N2: =L4 & ".Checker" -> MA.MAUDL5010.Checker
A3: * | D3: =IF(LogicCommon!A3="","",LogicCommon!A3) | E3: SubModuleID : | F3: =IF(LogicCommon!C3="","",LogicCommon!C3) -> MABC | G3: LogicClass : | H3: =IF(LogicCommon!E3="","",LogicCommon!E3) -> MABCL_DptReg | I3: Ope.Method : | J3: @ | K3: SuperClassPj.ID : | L3: =IF(LogicCommon!G3="","",LogicCommon!G3) | M3: ReportID : | O3: Gene.Type : | P3: ALL
A4: * | E4: Version : | F4: 000000 | G4: LogicName : | H4: =IF(LogicCommon!E4="","",LogicCommon!E4) -> 部門マスタ登録 | I4: Ope.Name : | J4: 登録前チェック(変更対応) | K4: SuperLogicID : | L4: =IF(LogicCommon!G4="","",LogicCommon!G4) -> MA.MAUDL5010
A5: * | E5: ACType :
A6: * | D6: 概要 : | E6: 部門変更対応マスタを登録する前のチェックを行う | N6: ID
A7: # | I7: U | K7: K | L7: K | M7: o
A8: # | D8: ブロック名 Block Name | E8: 型 Type | G8: super/share | H8: 対象ブロック名 Target Block Name | K8: REQUIRED | L8: BEFORE_AFTER | M8: TargetName | Q8: ブロック備考 Block Remarks
A9: # | D9: 項目名 Field Name | E9: 型 Type | F9: 桁 Digits | G9: フルネーム Full Name | H9: 日本語名 Japanese Name | I9: 上り項目 Request Message Field | J9: 下り項目 Response Message Field | O9: 条件および編集方法 Conditions and Editing Methods | Q9: 項目備考 Field Remarks
A10: # | M10: 上り項目 Request Message Field | N10: 下り項目 Response Message Field
A11: 10 | B11: * | D11: DptMap_UpdChk01_Dtl | E11: L | G11: $super$ | H11: DBC:MA.MAM_DPT_MAP
A12: 10 | D12: old_dpt_cd | E12: #MA.DPT_CD | G12: Old dept. cd. | H12: 旧部門ＣＤ | I12: E | K12: E
A13: 10 | D13: old_dpt_cd_key | E13: #MA.DPT_CD | G13: Old dept. cd._[Before change] | H13: 旧部門ＣＤ_[変更前] | I13: E
A14: 10 | D14: st_dt | E14: #MA.DT | G14: Application start date | H14: 適用開始日 | I14: E | K14: E | L14: E:BF
A15: 10 | D15: st_dt_key | E15: #MA.DT | G15: Application start date_[Before change] | H15: 適用開始日_[変更前] | I15: E
A16: 10 | D16: end_dt | E16: #MA.DT | G16: Application end date | H16: 適用終了日 | I16: E | K16: E | L16: E:AF
A17: 10 | D17: new_dpt_cd | E17: #MA.DPT_CD | G17: New dept. cd. | H17: 新部門ＣＤ | I17: E | K17: E
A18: 10 | D18: upd_cntr | E18: #MA.UPD_CNT | G18: Update counter | H18: 更新カウンタ | I18: E
D19: 詳細 :

Sheet DptMap_Upd01
A1: * | B1: * | D1: L | E1: 1
A2: * | D2: オペレーション実装仕様書 Operation Specification Implementation Sheet | E2: ModuleID : | F2: =IF(LogicCommon!C2="","",LogicCommon!C2) -> MA | G2: LogicID : | H2: =IF(LogicCommon!E2="","",LogicCommon!E2) -> MABCL0280 | I2: Ope.ID : | J2: DptMap_Upd01 | K2: Pj.ID : | L2: =IF(LogicCommon!G2="","",LogicCommon!G2) -> MC | M2: Ope.Body : | N2: "mcframe.serverMAUD.MAUDL6010.MAUDL_RLUpdater"
A3: * | D3: =IF(LogicCommon!A3="","",LogicCommon!A3) | E3: SubModuleID : | F3: =IF(LogicCommon!C3="","",LogicCommon!C3) -> MABC | G3: LogicClass : | H3: =IF(LogicCommon!E3="","",LogicCommon!E3) -> MABCL_DptReg | I3: Ope.Method : | J3: @ | K3: SuperClassPj.ID : | L3: =IF(LogicCommon!G3="","",LogicCommon!G3) | M3: ReportID : | O3: Gene.Type : | P3: ALL
A4: * | E4: Version : | F4: 000000 | G4: LogicName : | H4: =IF(LogicCommon!E4="","",LogicCommon!E4) -> 部門マスタ登録 | I4: Ope.Name : | J4: 登録処理(変更対応) | K4: SuperLogicID : | L4: =IF(LogicCommon!G4="","",LogicCommon!G4) -> MA.MAUDL5010
A5: * | E5: ACType :
A6: * | D6: 概要 : | E6: 部門変更対応マスタを登録する | L6: ID | N6: ID | P6: ID | R6: ID
A7: # | I7: U | K7: o | L7: UPDATE.updMaster | M7: o | N7: MAIN.chkMaster | O7: o | Q7: o
A8: # | D8: ブロック名 Block Name | E8: 型 Type | G8: super/share | H8: 対象ブロック名 Target Block Name | K8: TargetName | L8: DBC.MA.MAM_DPT_MAP | M8: TargetName | N8: DBC.MA.MAM_DPT_MAP | O8: TargetName | Q8: TargetName | U8: ブロック備考 Block Remarks
A9: # | D9: 項目名 Field Name | E9: 型 Type | F9: 桁 Digits | G9: フルネーム Full Name | H9: 日本語名 Japanese Name | I9: 上り項目 Request Message Field | J9: 下り項目 Response Message Field | S9: 条件および編集方法 Conditions and Editing Methods | U9: 項目備考 Field Remarks
A10: # | K10: 上り項目 Request Message Field | L10: 下り項目 Response Message Field | M10: 上り項目 Request Message Field | N10: 下り項目 Response Message Field | O10: 上り項目 Request Message Field | P10: 下り項目 Response Message Field | Q10: 上り項目 Request Message Field | R10: 下り項目 Response Message Field
A11: 10 | B11: * | D11: DptMap_Upd01_Dtl | E11: L | G11: $share$ | H11: MA.MABCL0280.DptMap_UpdChk01.DptMap_UpdChk01_Dtl | K11: L | M11: L
A12: 10 | D12: old_dpt_cd | E12: #MA.DPT_CD | G12: Old dept. cd. | H12: 旧部門ＣＤ | I12: E | K12: E | M12: E
A13: 10 | D13: old_dpt_cd_key | E13: #MA.DPT_CD | G13: Old dept. cd._[Before change] | H13: 旧部門ＣＤ_[変更前] | I13: E
A14: 10 | D14: st_dt | E14: #MA.DT | G14: Application start date | H14: 適用開始日 | I14: E | K14: E | M14: E
A15: 10 | D15: st_dt_key | E15: #MA.DT | G15: Application start date_[Before change] | H15: 適用開始日_[変更前] | I15: E
A16: 10 | D16: end_dt | E16: #MA.DT | G16: Application end date | H16: 適用終了日 | I16: E | K16: E | M16: E
A17: 10 | D17: new_dpt_cd | E17: #MA.DPT_CD | G17: New dept. cd. | H17: 新部門ＣＤ | I17: E | K17: E | M17: E
A18: 10 | D18: upd_cntr | E18: #MA.UPD_CNT | G18: Update counter | H18: 更新カウンタ | I18: E | K18: E | M18: E
D19: 詳細 :

Sheet Dpt_DelChk01
A1: * | B1: * | D1: L | E1: 1
A2: * | D2: オペレーション実装仕様書 Operation Specification Implementation Sheet | E2: ModuleID : | F2: =IF(LogicCommon!C2="","",LogicCommon!C2) -> MA | G2: LogicID : | H2: =IF(LogicCommon!E2="","",LogicCommon!E2) -> MABCL0280 | I2: Ope.ID : | J2: Dpt_DelChk01 | K2: Pj.ID : | L2: =IF(LogicCommon!G2="","",LogicCommon!G2) -> MC | M2: Ope.Body : | N2: =L4 & ".Checker" -> MA.MAUDL5010.Checker
A3: * | D3: =IF(LogicCommon!A3="","",LogicCommon!A3) | E3: SubModuleID : | F3: =IF(LogicCommon!C3="","",LogicCommon!C3) -> MABC | G3: LogicClass : | H3: =IF(LogicCommon!E3="","",LogicCommon!E3) -> MABCL_DptReg | I3: Ope.Method : | J3: @ | K3: SuperClassPj.ID : | L3: =IF(LogicCommon!G3="","",LogicCommon!G3) | M3: ReportID : | O3: Gene.Type : | P3: ALL
A4: * | E4: Version : | F4: 000000 | G4: LogicName : | H4: =IF(LogicCommon!E4="","",LogicCommon!E4) -> 部門マスタ登録 | I4: Ope.Name : | J4: 削除前チェック | K4: SuperLogicID : | L4: =IF(LogicCommon!G4="","",LogicCommon!G4) -> MA.MAUDL5010
A5: * | E5: ACType :
A6: * | D6: 概要 : | E6: 部門マスタ、組織変更履歴マスタ、部門変更対応マスタ、部門マスタ（ロケール別情報）を削除する前のチェックを行う | M6: ID
A7: # | I7: U | K7: K | L7: o
A8: # | D8: ブロック名 Block Name | E8: 型 Type | G8: super/share | H8: 対象ブロック名 Target Block Name | K8: REQUIRED | L8: TargetName | P8: ブロック備考 Block Remarks
A9: # | D9: 項目名 Field Name | E9: 型 Type | F9: 桁 Digits | G9: フルネーム Full Name | H9: 日本語名 Japanese Name | I9: 上り項目 Request Message Field | J9: 下り項目 Response Message Field | N9: 条件および編集方法 Conditions and Editing Methods | P9: 項目備考 Field Remarks
A10: # | L10: 上り項目 Request Message Field | M10: 下り項目 Response Message Field
A11: 10 | B11: * | D11: Dpt_DelChk01_Dtl | E11: L
A12: 10 | D12: dpt_cd | E12: #MA.DPT_CD | G12: Dept. cd. | H12: 部門ＣＤ | I12: E | K12: E
A13: 10 | D13: st_dt | E13: #MA.DT | G13: Application start date | H13: 適用開始日 | I13: E | K13: E
A14: 10 | D14: upd_cntr | E14: #MA.UPD_CNT | G14: Update counter | H14: 更新カウンタ | I14: E
D15: 詳細 :

Sheet Dpt_Del01
A1: * | B1: * | D1: L | E1: 1
A2: * | D2: オペレーション実装仕様書 Operation Specification Implementation Sheet | E2: ModuleID : | F2: =IF(LogicCommon!C2="","",LogicCommon!C2) -> MA | G2: LogicID : | H2: =IF(LogicCommon!E2="","",LogicCommon!E2) -> MABCL0280 | I2: Ope.ID : | J2: Dpt_Del01 | K2: Pj.ID : | L2: =IF(LogicCommon!G2="","",LogicCommon!G2) -> MC | M2: Ope.Body : | N2: "mcframe.serverMAUD.MAUDL6010.MAUDL_RLDeleter"
A3: * | D3: =IF(LogicCommon!A3="","",LogicCommon!A3) | E3: SubModuleID : | F3: =IF(LogicCommon!C3="","",LogicCommon!C3) -> MABC | G3: LogicClass : | H3: =IF(LogicCommon!E3="","",LogicCommon!E3) -> MABCL_DptReg | I3: Ope.Method : | J3: @ | K3: SuperClassPj.ID : | L3: =IF(LogicCommon!G3="","",LogicCommon!G3) | M3: ReportID : | O3: Gene.Type : | P3: ALL
A4: * | E4: Version : | F4: 000000 | G4: LogicName : | H4: =IF(LogicCommon!E4="","",LogicCommon!E4) -> 部門マスタ登録 | I4: Ope.Name : | J4: 削除処理 | K4: SuperLogicID : | L4: =IF(LogicCommon!G4="","",LogicCommon!G4) -> MA.MAUDL5010
A5: * | E5: ACType :
A6: * | D6: 概要 : | E6: 部門マスタ、組織変更履歴マスタ、部門変更対応マスタ、部門マスタ（ロケール別情報）を削除する | L6: ID | N6: ID | P6: ID | R6: ID | T6: ID
A7: # | I7: U | K7: o | L7: UPDATE.updMaster1 | M7: o | O7: o | Q7: o | S7: o
A8: # | D8: ブロック名 Block Name | E8: 型 Type | G8: super/share | H8: 対象ブロック名 Target Block Name | K8: TargetName | L8: DBC.MA.MAM_DPT | M8: TargetName | O8: TargetName | Q8: TargetName | S8: TargetName | W8: ブロック備考 Block Remarks
A9: # | D9: 項目名 Field Name | E9: 型 Type | F9: 桁 Digits | G9: フルネーム Full Name | H9: 日本語名 Japanese Name | I9: 上り項目 Request Message Field | J9: 下り項目 Response Message Field | U9: 条件および編集方法 Conditions and Editing Methods | W9: 項目備考 Field Remarks
A10: # | K10: 上り項目 Request Message Field | L10: 下り項目 Response Message Field | M10: 上り項目 Request Message Field | N10: 下り項目 Response Message Field | O10: 上り項目 Request Message Field | P10: 下り項目 Response Message Field | Q10: 上り項目 Request Message Field | R10: 下り項目 Response Message Field | S10: 上り項目 Request Message Field | T10: 下り項目 Response Message Field
A11: 10 | B11: * | D11: Dpt_Del01_Dtl | E11: L | G11: $share$ | H11: MA.MABCL0280.Dpt_DelChk01.Dpt_DelChk01_Dtl | K11: L
A12: 10 | D12: dpt_cd | E12: #MA.DPT_CD | G12: Dept. cd. | H12: 部門ＣＤ | I12: E | K12: E
A13: 10 | D13: st_dt | E13: #MA.DT | G13: Application start date | H13: 適用開始日 | I13: E | K13: E
A14: 10 | D14: upd_cntr | E14: #MA.UPD_CNT | G14: Update counter | H14: 更新カウンタ | I14: E | K14: E
D15: 詳細 :

Sheet Srch01
A1: * | B1: * | D1: L | E1: 1
A2: * | D2: オペレーション実装仕様書 Operation Specification Implementation Sheet | E2: ModuleID : | F2: =IF(LogicCommon!C2="","",LogicCommon!C2) -> MA | G2: LogicID : | H2: =IF(LogicCommon!E2="","",LogicCommon!E2) -> MABCL0280 | I2: Ope.ID : | J2: Srch01 | K2: Pj.ID : | L2: =IF(LogicCommon!G2="","",LogicCommon!G2) -> MC | M2: Ope.Body : | N2: "mcframe.serverMAUD.MAUDL6010.MAUDL_RLSearcher"
A3: * | D3: =IF(LogicCommon!A3="","",LogicCommon!A3) | E3: SubModuleID : | F3: =IF(LogicCommon!C3="","",LogicCommon!C3) -> MABC | G3: LogicClass : | H3: =IF(LogicCommon!E3="","",LogicCommon!E3) -> MABCL_DptReg | I3: Ope.Method : | J3: @ | K3: SuperClassPj.ID : | L3: =IF(LogicCommon!G3="","",LogicCommon!G3) | M3: ReportID : | O3: Gene.Type : | P3: ALL
A4: * | E4: Version : | F4: 000000 | G4: LogicName : | H4: =IF(LogicCommon!E4="","",LogicCommon!E4) -> 部門マスタ登録 | I4: Ope.Name : | J4: 検索 | K4: SuperLogicID : | L4: =IF(LogicCommon!G4="","",LogicCommon!G4) -> MA.MAUDL5010
A5: * | E5: ACType :
A6: * | D6: 概要 : | E6: 検索処理を行う | L6: ID | N6: ID | P6: ID
A7: # | I7: U | K7: o | L7: SELECT.c0 | M7: o | N7: SELECT1.c1 | O7: o | P7: SELECT2.c2
A8: # | D8: ブロック名 Block Name | E8: 型 Type | G8: super/share | H8: 対象ブロック名 Target Block Name | K8: TargetName | L8: DBC.MA.MAM_DPT_HIS | M8: TargetName | N8: DBC.MA.MAM_DPT | O8: TargetName | P8: DBC.MA.MAM_DPT_MAP | S8: ブロック備考 Block Remarks
A9: # | D9: 項目名 Field Name | E9: 型 Type | F9: 桁 Digits | G9: フルネーム Full Name | H9: 日本語名 Japanese Name | I9: 上り項目 Request Message Field | J9: 下り項目 Response Message Field | Q9: 条件および編集方法 Conditions and Editing Methods | S9: 項目備考 Field Remarks
A10: # | K10: 上り項目 Request Message Field | L10: 下り項目 Response Message Field | M10: 上り項目 Request Message Field | N10: 下り項目 Response Message Field | O10: 上り項目 Request Message Field | P10: 下り項目 Response Message Field
A11: 10 | B11: * | D11: Srch01_Cnd | E11: R
A12: 10 | D12: st_dt | E12: #MA.DT | G12: Application start date | H12: 適用開始日 | I12: E
A13: 10 | D13: del_flg | E13: #MA.FLG | G13: Including logical delete | H13: 論理削除を含む | I13: E
A14: 10 | D14: ope | E14: C | G14: Operation type | H14: 操作種別 | I14: E
A16: 20 | B16: * | D16: Srch01_Rslt1 | E16: L | L16: L
A17: 20 | D17: st_dt | E17: #MA.DT | G17: Application start date | H17: 適用開始日 | J17: E | L17: E
A18: 20 | D18: end_dt | E18: #MA.DT | G18: Application end date | H18: 適用終了日 | J18: E | L18: E
A19: 20 | D19: dpt_his_rmrks | E19: #MA.DPT_HIS_RMRKS | G19: Organizational changes remarks | H19: 組織変更備考 | J19: E | L19: E
A20: 20 | D20: memo1 | E20: #MA.MST_MEMO1 | G20: Memo 1 | H20: メモ１ | J20: E | L20: E
A21: 20 | D21: memo2 | E21: #MA.MST_MEMO2 | G21: Memo 2 | H21: メモ２ | J21: E | L21: E
A22: 20 | D22: memo3 | E22: #MA.MST_MEMO3 | G22: Memo 3 | H22: メモ３ | J22: E | L22: E
A23: 20 | D23: upd_cntr | E23: #MA.UPD_CNT | G23: Update counter | H23: 更新カウンタ | J23: E | L23: E
A24: 20 | D24: upd_ts | E24: #MA.SYS_TS | G24: Update date and time | H24: 更新日時
A26: 30 | B26: * | D26: Srch01_Rslt2 | E26: L | N26: L
A27: 30 | D27: dpt_cd | E27: #MA.DPT_CD | G27: Dept. cd. | H27: 部門ＣＤ | J27: E | N27: E
A28: 30 | D28: st_dt | E28: #MA.DT | G28: Application start date | H28: 適用開始日 | J28: E | N28: E
A29: 30 | D29: end_dt | E29: #MA.DT | G29: Application end date | H29: 適用終了日 | J29: E | N29: base_end_dt
A30: 30 | D30: dpt_nm_lcl | E30: #MA.DPT_NM | G30: Dept. name | H30: 部門名 | J30: E | N30: dpt_nm
A31: 30 | D31: dpt_nm | E31: #MA.DPT_NM | G31: Standard dept. name | H31: 標準部門名 | J31: E | N31: base_dpt_nm
A32: 30 | D32: dpt_lvl_cd | E32: #MA.DPT_LVL_CD | G32: Dept. hierarchy cd. | H32: 部門階層ＣＤ | J32: E | N32: E
A33: 30 | D33: dpt_lvl_nm | E33: #MA.DPT_LVL_NM | G33: Dept. hierarchy name | H33: 部門階層名 | J33: E | N33: E
A34: 30 | D34: up_lv_dpt_cd | E34: #MA.DPT_CD | G34: Upper dept. cd. | H34: 上位部門ＣＤ | J34: E | N34: E
A35: 30 | D35: up_lv_dpt_nm | E35: #MA.DPT_NM | G35: Upper dept. name | H35: 上位部門名 | J35: E | N35: E
A36: 30 | D36: new_dpt_cd | E36: #MA.DPT_CD | G36: New dept. cd. | H36: 新部門ＣＤ | J36: E | N36: E
A37: 30 | D37: zip_cd | E37: #MA.ZIP_CD | G37: Zip code | H37: 郵便番号 | J37: E | N37: base_zip_cd
A38: 30 | D38: addr1 | E38: #MA.ADDR1 | G38: Address 1 | H38: 住所１ | J38: E | N38: base_addr1
... A81: 30 | D81: ins_func_id | E81: #MA.FUNC_ID | G81: Entry function ID | H81: 登録機能ＩＤ | J81: E | N81: E
A82: 30 | D82: ins_func_nm | E82: #MA.FUNC_NM | G82: Entry function name | H82: 登録機能名 | J82: E
A83: 30 | D83: upd_cntr | E83: #MA.UPD_CNT | G83: Update counter | H83: 更新カウンタ | J83: E | N83: E
A84: 30 | D84: upd_usr_id | E84: #MA.FCM_USR_ID | G84: Update user ID | H84: 更新ユーザＩＤ | J84: E | N84: E
...

Sheet Upd01
A1: * | B1: * | D1: L | E1: 1
A2: * | D2: オペレーション実装仕様書 Operation Specification Implementation Sheet | E2: ModuleID : | F2: =IF(LogicCommon!C2="","",LogicCommon!C2) -> MA | G2: LogicID : | H2: =IF(LogicCommon!E2="","",LogicCommon!E2) -> MABCL0280 | I2: Ope.ID : | J2: Upd01 | K2: Pj.ID : | L2: =IF(LogicCommon!G2="","",LogicCommon!G2) -> MC | M2: Ope.Body : | N2: "mcframe.serverMAUD.MAUDL6010.MAUDL_RLUpdater"
A3: * | D3: =IF(LogicCommon!A3="","",LogicCommon!A3) | E3: SubModuleID : | F3: =IF(LogicCommon!C3="","",LogicCommon!C3) -> MABC | G3: LogicClass : | H3: =IF(LogicCommon!E3="","",LogicCommon!E3) -> MABCL_DptReg | I3: Ope.Method : | J3: @ | K3: SuperClassPj.ID : | L3: =IF(LogicCommon!G3="","",LogicCommon!G3) | M3: ReportID : | O3: Gene.Type : | P3: ALL
A4: * | E4: Version : | F4: 000000 | G4: LogicName : | H4: =IF(LogicCommon!E4="","",LogicCommon!E4) -> 部門マスタ登録 | I4: Ope.Name : | J4: 登録 | K4: SuperLogicID : | L4: =IF(LogicCommon!G4="","",LogicCommon!G4) -> MA.MAUDL5010
A5: * | E5: ACType :
A6: * | D6: 概要 : | E6: 登録処理を行う | L6: ID | N6: ID | P6: ID | R6: ID | T6: ID | V6: ID
A7: # | I7: U | K7: o | L7: CALL_OPE01.chk01 | M7: o | N7: CALL_OPE01.upd01 | O7: o | P7: CALL_OPE02.chk02 | Q7: o | R7: CALL_OPE02.upd02 | S7: o | T7: CALL_OPE03.chk03 | U7: o | V7: CALL_OPE03.upd03
A8: # | D8: ブロック名 Block Name | E8: 型 Type | G8: super/share | H8: 対象ブロック名 Target Block Name | K8: TargetName | L8: OPE.MA.MABCL0280.DptHis_UpdChk01 | M8: TargetName | N8: OPE.MA.MABCL0280.DptHis_Upd01 | O8: TargetName | P8: OPE.MA.MABCL0280.Dpt_UpdChk01 | Q8: TargetName | R8: OPE.MA.MABCL0280.Dpt_Upd01 | S8: TargetName | T8: OPE.MA.MABCL0280.DptMap_UpdChk01 | U8: TargetName | V8: OPE.MA.MABCL0280.DptMap_Upd01 | Y8: ブロック備考 Block Remarks
A9: # | D9: 項目名 Field Name | E9: 型 Type | F9: 桁 Digits | G9: フルネーム Full Name | H9: 日本語名 Japanese Name | I9: 上り項目 Request Message Field | J9: 下り項目 Response Message Field | W9: 条件および編集方法 Conditions and Editing Methods | Y9: 項目備考 Field Remarks
A10: # | K10: 上り項目 Request Message Field | L10: 下り項目 Response Message Field | M10: 上り項目 Request Message Field | N10: 下り項目 Response Message Field | O10: 上り項目 Request Message Field | P10: 下り項目 Response Message Field | Q10: 上り項目 Request Message Field | R10: 下り項目 Response Message Field | S10: 上り項目 Request Message Field | T10: 下り項目 Response Message Field | U10: 上り項目 Request Message Field | V10: 下り項目 Response Message Field
A11: 10 | B11: * | D11: Upd01_Dtl1 | E11: L | G11: $share$ | H11: MA.MABCL0280.DptHis_Upd01.DptHis_Upd01_Dtl | K11: DptHis_UpdChk01_Dtl | M11: DptHis_Upd01_Dtl
A12: 10 | D12: st_dt | E12: #MA.DT | G12: Application start date | H12: 適用開始日 | I12: E | K12: E | M12: E
A13: 10 | D13: st_dt_key | E13: #MA.DT | G13: Application start date_[Before change] | H13: 適用開始日_[変更前] | I13: E | K13: E | M13: E
A14: 10 | D14: end_dt | E14: #MA.DT | G14: Application end date | H14: 適用終了日 | I14: E | K14: E | M14: E
A15: 10 | D15: dpt_his_rmrks | E15: #MA.DPT_HIS_RMRKS | G15: Organizational changes remarks | H15: 組織変更備考 | I15: E | K15: E | M15: E
A16: 10 | D16: memo1 | E16: #MA.MST_MEMO1 | G16: Memo 1 | H16: メモ１ | I16: E | K16: E | M16: E
A17: 10 | D17: memo2 | E17: #MA.MST_MEMO2 | G17: Memo 2 | H17: メモ２ | I17: E | K17: E | M17: E
A18: 10 | D18: memo3 | E18: #MA.MST_MEMO3 | G18: Memo 3 | H18: メモ３ | I18: E | K18: E | M18: E
A19: 10 | D19: upd_cntr | E19: #MA.UPD_CNT | G19: Update counter | H19: 更新カウンタ | I19: E | K19: E | M19: E
A21: 20 | B21: * | D21: Upd01_Dtl2 | E21: L | G21: $super$ | H21: MA.MABCL0280.Dpt_Upd01.Dpt_Upd01_Dtl | O21: Dpt_UpdChk01_Dtl | Q21: Dpt_Upd01_Dtl
A22: 20 | D22: dpt_cd | E22: #MA.DPT_CD | G22: Dept. cd. | H22: 部門ＣＤ | I22: E | O22: E | Q22: E
A23: 20 | D23: dpt_cd_key | E23: #MA.DPT_CD | G23: Dept. cd_[Before change] | H23: 部門ＣＤ_[変更前] | I23: E | O23: E | Q23: E
A24: 20 | D24: st_dt | E24: #MA.DT | G24: Application start date | H24: 適用開始日 | I24: E | O24: E | Q24: E
A25: 20 | D25: st_dt_key | E25: #MA.DT | G25: Application start date_[Before change] | H25: 適用開始日_[変更前] | I25: E | O25: E | Q25: E
A26: 20 | D26: end_dt | E26: #MA.DT | G26: Application end date | H26: 適用終了日 | I26: E | O26: E | Q26: E
A27: 20 | D27: dpt_nm | E27: #MA.DPT_NM | G27: Standard dept. name | H27: 標準部門名 | I27: E | O27: E | Q27: E
A28: 20 | D28: dpt_lvl_cd | E28: #MA.DPT_LVL_CD | G28: Dept. hierarchy cd. | H28: 部門階層ＣＤ | I28: E | O28: E | Q28: E
A29: 20 | D29: up_lv_dpt_cd | E29: #MA.DPT_CD | G29: Upper dept. cd. | H29: 上位部門ＣＤ | I29: E | O29: E | Q29: E
A30: 20 | D30: new_dpt_cd | E30: #MA.DPT_CD | G30: New dept. cd. | H30: 新部門ＣＤ | I30: E | O30: E | Q30: E
A31: 20 | D31: zip_cd | E31: #MA.ZIP_CD | G31: Zip code | H31: 郵便番号 | I31: E | O31: E | Q31: E
A32: 20 | D32: addr1 | E32: #MA.ADDR1 | G32: Address 1 | H32: 住所１ | I32: E | O32: E | Q32: E
A33: 20 | D33: addr2 | E33: #MA.ADDR2 | G33: Address 2 | H33: 住所２ | I33: E | O33: E | Q33: E
... A59: 20 | D59: upd_cntr | E59: #MA.UPD_CNT | G59: Update counter | H59: 更新カウンタ | I59: E | O59: E | Q59: E
A60: 20 | D60: new_flg | E60: #MA.FLG | G60: New organization flg. | H60: 新組織ＦＬＧ | I60: E
A62: 30 | B62: * | D62: Upd01_Dtl3 | E62: L | G62: $share$ | H62: MA.MABCL0280.DptMap_Upd01.DptMap_Upd01_Dtl | S62: DptMap_UpdChk01_Dtl | U62: DptMap_Upd01_Dtl
A63: 30 | D63: old_dpt_cd | E63: #MA.DPT_CD | G63: Old dept. cd. | H63: 旧部門ＣＤ | I63: E | S63: E | U63: E
A64: 30 | D64: old_dpt_cd_key | E64: #MA.DPT_CD | G64: Old dept. cd._[Before change] | H64: 旧部門ＣＤ_[変更前] | I64: E | S64: E | U64: E
A65: 30 | D65: st_dt | E65: #MA.DT | G65: Application start date | H65: 適用開始日 | I65: E | S65: E | U65: E
A66: 30 | D66: st_dt_key | E66: #MA.DT | G66: Application start date_[Before change] | H66: 適用開始日_[変更前] | I66: E | S66: E | U66: E
A67: 30 | D67: end_dt | E67: #MA.DT | G67: Application end date | H67: 適用終了日 | I67: E | S67: E | U67: E
...

Sheet Del01
A1: * | B1: * | D1: L | E1: 1
A2: * | D2: オペレーション実装仕様書 Operation Specification Implementation Sheet | E2: ModuleID : | F2: =IF(LogicCommon!C2="","",LogicCommon!C2) -> MA | G2: LogicID : | H2: =IF(LogicCommon!E2="","",LogicCommon!E2) -> MABCL0280 | I2: Ope.ID : | J2: Del01 | K2: Pj.ID : | L2: =IF(LogicCommon!G2="","",LogicCommon!G2) -> MC | M2: Ope.Body : | N2: "mcframe.serverMAUD.MAUDL6010.MAUDL_RLDeleter"
A3: * | D3: =IF(LogicCommon!A3="","",LogicCommon!A3) | E3: SubModuleID : | F3: =IF(LogicCommon!C3="","",LogicCommon!C3) -> MABC | G3: LogicClass : | H3: =IF(LogicCommon!E3="","",LogicCommon!E3) -> MABCL_DptReg | I3: Ope.Method : | J3: @ | K3: SuperClassPj.ID : | L3: =IF(LogicCommon!G3="","",LogicCommon!G3) | M3: ReportID : | O3: Gene.Type : | P3: ALL
A4: * | E4: Version : | F4: 000000 | G4: LogicName : | H4: =IF(LogicCommon!E4="","",LogicCommon!E4) -> 部門マスタ登録 | I4: Ope.Name : | J4: 削除 | K4: SuperLogicID : | L4: =IF(LogicCommon!G4="","",LogicCommon!G4) -> MA.MAUDL5010
A5: * | E5: ACType :
A6: * | D6: 概要 : | E6: 削除処理を行う | L6: ID | N6: ID
A7: # | I7: U | K7: o | L7: CALL_OPE01.chk01 | M7: o | N7: CALL_OPE01.del01
A8: # | D8: ブロック名 Block Name | E8: 型 Type | G8: super/share | H8: 対象ブロック名 Target Block Name | K8: TargetName | L8: OPE.MA.MABCL0280.Dpt_DelChk01 | M8: TargetName | N8: OPE.MA.MABCL0280.Dpt_Del01 | Q8: ブロック備考 Block Remarks
A9: # | D9: 項目名 Field Name | E9: 型 Type | F9: 桁 Digits | G9: フルネーム Full Name | H9: 日本語名 Japanese Name | I9: 上り項目 Request Message Field | J9: 下り項目 Response Message Field | O9: 条件および編集方法 Conditions and Editing Methods | Q9: 項目備考 Field Remarks
A10: # | K10: 上り項目 Request Message Field | L10: 下り項目 Response Message Field | M10: 上り項目 Request Message Field | N10: 下り項目 Response Message Field
A11: 10 | B11: * | D11: Del01_Dtl1 | E11: L | G11: $share$ | H11: MA.MABCL0280.Dpt_Del01.Dpt_Del01_Dtl | K11: Dpt_DelChk01_Dtl | M11: Dpt_Del01_Dtl
A12: 10 | D12: dpt_cd | E12: #MA.DPT_CD | G12: Dept. cd. | H12: 部門ＣＤ | I12: E | K12: E | M12: E
A13: 10 | D13: st_dt | E13: #MA.DT | G13: Application start date | H13: 適用開始日 | I13: E | K13: E | M13: E
A14: 10 | D14: upd_cntr | E14: #MA.UPD_CNT | G14: Update counter | H14: 更新カウンタ | I14: E | K14: E | M14: E
D15: 詳細 :

Sheet 来歴
A1: 変更来歴
A3: Rev. | H3: 修正番号 | O3: 変更内容 | AQ3: 変更箇所
A4: 1 | O4: 初版
A5: 1.1 | O5: 英語の名称を追記 | AQ5: 全般
