Workbook

Sheet LogicCommon
A2: ロジック共通定義 | B2: ModuleID : | C2: MA | D2: LogicID : | E2: MABCL0033 | F2: Pj.ID : | G2: MC
B3: SubModuleID : | C3: MABC | D3: LogicClass : | E3: MABCL_MultiReg | F3: SuperClassPj.ID :
D4: LogicName : | E4: マルチマスタ登録 | F4: SuperLogicID : | G4: MA.MAUDL5010
A5: 概要 :
A6: 詳細 :
B7: 対象マスタ
C8: ＷＧマスタ
C9: 工程マスタ
C10: 工数管理マスタ
C11: 工数理由マスタ
C12: 販売単価分類マスタ
C13: 販売単価ランクマスタ
C14: 相殺グループマスタ
C15: 出荷有効期限グループマスタ
C16: 品目出荷グループマスタ
C17: 輸送方法マスタ

Sheet Wg_UpdChk01
A1: * | B1: * | D1: L | E1: 1
A2: * | D2: オペレーション実装仕様書 Operation Specification Implementation Sheet | E2: ModuleID : | F2: =IF(LogicCommon!C2="","",LogicCommon!C2) -> MA | G2: LogicID : | H2: =IF(LogicCommon!E2="","",LogicCommon!E2) -> MABCL0033 | I2: Ope.ID : | J2: Wg_UpdChk01 | K2: Pj.ID : | L2: =IF(LogicCommon!G2="","",LogicCommon!G2) -> MC | M2: Ope.Body : | N2: =L4 & ".Checker" -> MA.MAUDL5010.Checker
A3: * | D3: =IF(LogicCommon!A3="","",LogicCommon!A3) | E3: SubModuleID : | F3: =IF(LogicCommon!C3="","",LogicCommon!C3) -> MABC | G3: LogicClass : | H3: =IF(LogicCommon!E3="","",LogicCommon!E3) -> MABCL_MultiReg | I3: Ope.Method : | J3: @ | K3: SuperClassPj.ID : | L3: =IF(LogicCommon!G3="","",LogicCommon!G3) | M3: ReportID : | O3: Gene.Type : | P3: ALL
A4: * | E4: Version : | F4: 000000 | G4: LogicName : | H4: =IF(LogicCommon!E4="","",LogicCommon!E4) -> マルチマスタ登録 | I4: Ope.Name : | J4: チェック | K4: SuperLogicID : | L4: =IF(LogicCommon!G4="","",LogicCommon!G4) -> MA.MAUDL5010
A5: * | E5: ACType :
A6: * | D6: 概要 : | E6: ＷＧマスタの登録前のチェックを行います。 | P6: ID
A7: # | I7: U | K7: K | L7: K | M7: K | N7: K | O7: o
A8: # | D8: ブロック名 Block Name | E8: 型 Type | G8: super/share | H8: 対象ブロック名 Target Block Name | K8: REQUIRED | L8: AT_LEAST_ONE | M8: CONST | N8: SMALL_LARGE | O8: TargetName | S8: ブロック備考 Block Remarks
A9: # | D9: 項目名 Field Name | E9: 型 Type | F9: 桁 Digits | G9: フルネーム Full Name | H9: 日本語名 Japanese Name | I9: 上り項目 Request Message Field | J9: 下り項目 Response Message Field | Q9: 条件および編集方法 Conditions and Editing Methods | S9: 項目備考 Field Remarks
A10: # | O10: 上り項目 Request Message Field | P10: 下り項目 Response Message Field
A11: 10 | B11: * | D11: Wg_UpdChk01_Dtl | E11: L | G11: $super$ | H11: DBC:MA.MAM_WG
A12: 10 | D12: wg_cd | E12: #MA.WG_CD | G12: WG cd. | H12: ワーキンググループＣＤ | I12: E | K12: E
A13: 10 | D13: wg_nm | E13: #MA.WG_NM | G13: Standard WG name | H13: 標準ワーキンググループ名 | I13: E | K13: E
A14: 10 | D14: sls_flg | E14: #MA.FLG | G14: Sales | H14: 販売 | I14: E
A15: 10 | D15: lg_flg | E15: #MA.FLG | G15: Distribution | H15: 物流 | I15: E
A16: 10 | D16: mfg_flg | E16: #MA.FLG | G16: Mfg. | H16: 製造 | I16: E
A17: 10 | D17: purc_flg | E17: #MA.FLG | G17: Purchase | H17: 購買 | I17: E
A18: 10 | D18: ar_flg | E18: #MA.FLG | G18: AR | H18: 債権 | I18: E
A19: 10 | D19: ap_flg | E19: #MA.FLG | G19: AP | H19: 債務 | I19: E
A20: 10 | D20: sd_flg | E20: #MA.FLG | G20: Demand and supply management | H20: 需給 | I20: E
A21: 10 | D21: mrp_prefix | E21: #MA.MRP_PREFIX | G21: Prefix for MRP numbering | H21: ＭＲＰ発番用接頭語 | I21: E
A22: 10 | D22: mfg_inst_unit_typ | E22: #MA.MFG_INST_UNIT_TYP | G22: Mfg. order unit type | H22: 製造指図単位区分 | I22: E | M22: MAC_MFG_INST_UNIT_TYP
A23: 10 | D23: mrp_proc_typ | E23: #MA.MRP_PROC_TYP | G23: MRP process type | H23: ＭＲＰ処理区分 | I23: E | M23: MAC_MRP_PROC_TYP
A24: 10 | D24: alloc_margin_days | E24: #MA.DAYS | G24: Allocation extra days | H24: 引当余裕日数 | I24: E
A25: 10 | D25: not_xfr_flg | E25: #MA.FLG | G25: Not for movement/transport allocation | H25: 移動・移送引当対象外 | I25: E
A26: 10 | D26: mrp_alloc_margin_days | E26: #MA.DAYS | G26: MRP allocation extra days | H26: ＭＲＰ引当余裕日数 | I26: E | N26: 1:
A27: 10 | D27: mrp_opn_xfr_days | E27: #MA.DAYS | G27: Days to consider unfirm transport request in MRP | H27: ＭＲＰ未確定移送依頼考慮日数 | I27: E | N27: 0:
A28: 10 | D28: rqmt_typ | E28: #MA.RQMT_TYP | G28: Requirements type | H28: 所要区分 | I28: E | M28: MAC_RQMT_TYP
A29: 10 | D29: prod_pln_typ | E29: #MA.PROD_PLN_TYP | G29: Production planning type | H29: 生産計画立案区分 | I29: E | M29: MAC_PROD_PLN_TYP
A30: 10 | D30: dmnd_date_div_mons | E30: #MA.MONS | G30: Number of months for demand disaggregation by day | H30: 需要日ばらし月数 | I30: E | N30: 0:
A31: 10 | D31: plm_flg | E31: #MA.FLG | G31: PLM | H31: ＰＬＭ | I31: E
A32: 10 | D32: calc_seq | E32: #MA.INT3 | G32: Calculation sequence | H32: 計算順序 | I32: E | N32: 0:999
A33: 10 | D33: cmn_upri_flg | E33: #MA.FLG | G33: Common unit price | H33: 共通単価 | I33: E
A34: 10 | D34: memo1 | E34: #MA.MST_MEMO1 | G34: Memo 1 | H34: メモ１ | I34: E
A35: 10 | D35: memo2 | E35: #MA.MST_MEMO2 | G35: Memo 2 | H35: メモ２ | I35: E
A36: 10 | D36: memo3 | E36: #MA.MST_MEMO3 | G36: Memo 3 | H36: メモ３ | I36: E
A37: 10 | D37: del_flg | E37: #MA.FLG | G37: Logical delete | H37: 論理削除 | I37: E
A38: 10 | D38: upd_cntr | E38: #MA.UPD_CNT | G38: Update counter | H38: 更新カウンタ | I38: E
D39: 詳細 :

Sheet Wg_Upd01
A1: * | B1: * | D1: L | E1: 1
A2: * | D2: オペレーション実装仕様書 Operation Specification Implementation Sheet | E2: ModuleID : | F2: =IF(LogicCommon!C2="","",LogicCommon!C2) -> MA | G2: LogicID : | H2: =IF(LogicCommon!E2="","",LogicCommon!E2) -> MABCL0033 | I2: Ope.ID : | J2: Wg_Upd01 | K2: Pj.ID : | L2: =IF(LogicCommon!G2="","",LogicCommon!G2) -> MC | M2: Ope.Body : | N2: "mcframe.serverMAUD.MAUDL6020.MAUDL_LCLRLUpdater"
A3: * | D3: =IF(LogicCommon!A3="","",LogicCommon!A3) | E3: SubModuleID : | F3: =IF(LogicCommon!C3="","",LogicCommon!C3) -> MABC | G3: LogicClass : | H3: =IF(LogicCommon!E3="","",LogicCommon!E3) -> MABCL_MultiReg | I3: Ope.Method : | J3: @ | K3: SuperClassPj.ID : | L3: =IF(LogicCommon!G3="","",LogicCommon!G3) | M3: ReportID : | O3: Gene.Type : | P3: ALL
A4: * | E4: Version : | F4: 000000 | G4: LogicName : | H4: =IF(LogicCommon!E4="","",LogicCommon!E4) -> マルチマスタ登録 | I4: Ope.Name : | J4: 登録 | K4: SuperLogicID : | L4: =IF(LogicCommon!G4="","",LogicCommon!G4) -> MA.MAUDL5010
A5: * | E5: ACType :
A6: * | D6: 概要 : | E6: ＷＧマスタの登録を行います。 | L6: ID | N6: ID | P6: ID | R6: ID
A7: # | I7: U | K7: o | L7: UPDATE.updMaster | M7: o | N7: MAIN.chkMaster | O7: o | Q7: o
A8: # | D8: ブロック名 Block Name | E8: 型 Type | G8: super/share | H8: 対象ブロック名 Target Block Name | K8: TargetName | L8: DBC.MA.MAM_WG | M8: TargetName | N8: DBC.MA.MAM_WG | O8: TargetName | Q8: TargetName | U8: ブロック備考 Block Remarks
A9: # | D9: 項目名 Field Name | E9: 型 Type | F9: 桁 Digits | G9: フルネーム Full Name | H9: 日本語名 Japanese Name | I9: 上り項目 Request Message Field | J9: 下り項目 Response Message Field | S9: 条件および編集方法 Conditions and Editing Methods | U9: 項目備考 Field Remarks
A10: # | K10: 上り項目 Request Message Field | L10: 下り項目 Response Message Field | M10: 上り項目 Request Message Field | N10: 下り項目 Response Message Field | O10: 上り項目 Request Message Field | P10: 下り項目 Response Message Field | Q10: 上り項目 Request Message Field | R10: 下り項目 Response Message Field
A11: 10 | B11: * | D11: Wg_Upd01_Dtl | E11: L | G11: $share$ | H11: MA.MABCL0033.Wg_UpdChk01.Wg_UpdChk01_Dtl | K11: L | M11: L
A12: 10 | D12: wg_cd | E12: #MA.WG_CD | G12: WG cd. | H12: ワーキンググループＣＤ | I12: E | K12: E | M12: E
A13: 10 | D13: wg_nm | E13: #MA.WG_NM | G13: Standard WG name | H13: 標準ワーキンググループ名 | I13: E | K13: E | M13: E
A14: 10 | D14: sls_flg | E14: #MA.FLG | G14: Sales | H14: 販売 | I14: E | K14: E | M14: E
A15: 10 | D15: lg_flg | E15: #MA.FLG | G15: Distribution | H15: 物流 | I15: E | K15: E | M15: E
A16: 10 | D16: mfg_flg | E16: #MA.FLG | G16: Mfg. | H16: 製造 | I16: E | K16: E | M16: E
A17: 10 | D17: purc_flg | E17: #MA.FLG | G17: Purchase | H17: 購買 | I17: E | K17: E | M17: E
A18: 10 | D18: ar_flg | E18: #MA.FLG | G18: AR | H18: 債権 | I18: E | K18: E | M18: E
A19: 10 | D19: ap_flg | E19: #MA.FLG | G19: AP | H19: 債務 | I19: E | K19: E | M19: E
A20: 10 | D20: sd_flg | E20: #MA.FLG | G20: Demand and supply management | H20: 需給 | I20: E | K20: E | M20: E
A21: 10 | D21: mrp_prefix | E21: #MA.MRP_PREFIX | G21: Prefix for MRP numbering | H21: ＭＲＰ発番用接頭語 | I21: E | K21: E | M21: E
A22: 10 | D22: mfg_inst_unit_typ | E22: #MA.MFG_INST_UNIT_TYP | G22: Mfg. order unit type | H22: 製造指図単位区分 | I22: E | K22: E | M22: E
A23: 10 | D23: mrp_proc_typ | E23: #MA.MRP_PROC_TYP | G23: MRP process type | H23: ＭＲＰ処理区分 | I23: E | K23: E | M23: E
... A38: 10 | D38: upd_cntr | E38: #MA.UPD_CNT | G38: Update counter | H38: 更新カウンタ | I38: E | K38: E | M38: E
D39: 詳細 :

Sheet WgLcl_UpdChk01
A1: * | B1: * | D1: L | E1: 1
A2: * | D2: オペレーション実装仕様書 Operation Specification Implementation Sheet | E2: ModuleID : | F2: =IF(LogicCommon!C2="","",LogicCommon!C2) -> MA | G2: LogicID : | H2: =IF(LogicCommon!E2="","",LogicCommon!E2) -> MABCL0033 | I2: Ope.ID : | J2: WgLcl_UpdChk01 | K2: Pj.ID : | L2: =IF(LogicCommon!G2="","",LogicCommon!G2) -> MC | M2: Ope.Body : | N2: =L4 & ".Checker" -> MA.MAUDL5010.Checker
A3: * | D3: =IF(LogicCommon!A3="","",LogicCommon!A3) | E3: SubModuleID : | F3: =IF(LogicCommon!C3="","",LogicCommon!C3) -> MABC | G3: LogicClass : | H3: =IF(LogicCommon!E3="","",LogicCommon!E3) -> MABCL_MultiReg | I3: Ope.Method : | J3: @ | K3: SuperClassPj.ID : | L3: =IF(LogicCommon!G3="","",LogicCommon!G3) | M3: ReportID : | O3: Gene.Type : | P3: ALL
A4: * | E4: Version : | F4: 000000 | G4: LogicName : | H4: =IF(LogicCommon!E4="","",LogicCommon!E4) -> マルチマスタ登録 | I4: Ope.Name : | J4: チェック | K4: SuperLogicID : | L4: =IF(LogicCommon!G4="","",LogicCommon!G4) -> MA.MAUDL5010
A5: * | E5: ACType :
A6: * | D6: 概要 : | E6: ＷＧマスタの登録前のチェックを行います。（ロケール用） | M6: ID
A7: # | I7: U | K7: K | L7: o | M7: EXISTS.chk01
A8: # | D8: ブロック名 Block Name | E8: 型 Type | G8: super/share | H8: 対象ブロック名 Target Block Name | K8: REQUIRED | L8: TargetName | M8: DBC.MA.MAM_WG | P8: ブロック備考 Block Remarks
A9: # | D9: 項目名 Field Name | E9: 型 Type | F9: 桁 Digits | G9: フルネーム Full Name | H9: 日本語名 Japanese Name | I9: 上り項目 Request Message Field | J9: 下り項目 Response Message Field | N9: 条件および編集方法 Conditions and Editing Methods | P9: 項目備考 Field Remarks
A10: # | L10: 上り項目 Request Message Field | M10: 下り項目 Response Message Field
A11: 10 | B11: * | D11: WgLcl_UpdChk01_Dtl | E11: L | G11: $super$ | H11: DBC:MA.MAM_WG_LCL | L11: L
A12: 10 | D12: wg_cd | E12: #MA.WG_CD | G12: WG cd. | H12: ワーキンググループＣＤ | I12: E | K12: E | L12: E
A13: 10 | D13: lcl_cd | E13: #MA.LCL_CD | G13: Locale cd. | H13: ロケールＣＤ | I13: E | K13: E
A14: 10 | D14: wg_nm | E14: #MA.WG_NM | G14: WG name | H14: ワーキンググループ名 | I14: E | K14: E
A15: 10 | D15: memo1 | E15: #MA.MST_MEMO1 | G15: Memo 1 | H15: メモ１ | I15: E
A16: 10 | D16: memo2 | E16: #MA.MST_MEMO2 | G16: Memo 2 | H16: メモ２ | I16: E
A17: 10 | D17: memo3 | E17: #MA.MST_MEMO3 | G17: Memo 3 | H17: メモ３ | I17: E
A18: 10 | D18: upd_cntr | E18: #MA.UPD_CNT | G18: Update counter | H18: 更新カウンタ | I18: E
D19: 詳細 :

Sheet WgLcl_Upd01
A1: * | B1: * | D1: L | E1: 1
A2: * | D2: オペレーション実装仕様書 Operation Specification Implementation Sheet | E2: ModuleID : | F2: =IF(LogicCommon!C2="","",LogicCommon!C2) -> MA | G2: LogicID : | H2: =IF(LogicCommon!E2="","",LogicCommon!E2) -> MABCL0033 | I2: Ope.ID : | J2: WgLcl_Upd01 | K2: Pj.ID : | L2: =IF(LogicCommon!G2="","",LogicCommon!G2) -> MC | M2: Ope.Body : | N2: "mcframe.serverMAUD.MAUDL6020.MAUDL_LCLRLUpdater"
A3: * | D3: =IF(LogicCommon!A3="","",LogicCommon!A3) | E3: SubModuleID : | F3: =IF(LogicCommon!C3="","",LogicCommon!C3) -> MABC | G3: LogicClass : | H3: =IF(LogicCommon!E3="","",LogicCommon!E3) -> MABCL_MultiReg | I3: Ope.Method : | J3: @ | K3: SuperClassPj.ID : | L3: =IF(LogicCommon!G3="","",LogicCommon!G3) | M3: ReportID : | O3: Gene.Type : | P3: ALL
A4: * | E4: Version : | F4: 000000 | G4: LogicName : | H4: =IF(LogicCommon!E4="","",LogicCommon!E4) -> マルチマスタ登録 | I4: Ope.Name : | J4: 登録 | K4: SuperLogicID : | L4: =IF(LogicCommon!G4="","",LogicCommon!G4) -> MA.MAUDL5010
A5: * | E5: ACType :
A6: * | D6: 概要 : | E6: ＷＧマスタの登録を行います。（ロケール用） | L6: ID | N6: ID | P6: ID | R6: ID
A7: # | I7: U | K7: o | L7: UPDATE.updMaster | M7: o | N7: MAIN.chkMaster | O7: o | Q7: o
A8: # | D8: ブロック名 Block Name | E8: 型 Type | G8: super/share | H8: 対象ブロック名 Target Block Name | K8: TargetName | L8: DBC.MA.MAM_WG_LCL | M8: TargetName | N8: DBC.MA.MAM_WG_LCL | O8: TargetName | Q8: TargetName | U8: ブロック備考 Block Remarks
A9: # | D9: 項目名 Field Name | E9: 型 Type | F9: 桁 Digits | G9: フルネーム Full Name | H9: 日本語名 Japanese Name | I9: 上り項目 Request Message Field | J9: 下り項目 Response Message Field | S9: 条件および編集方法 Conditions and Editing Methods | U9: 項目備考 Field Remarks
A10: # | K10: 上り項目 Request Message Field | L10: 下り項目 Response Message Field | M10: 上り項目 Request Message Field | N10: 下り項目 Response Message Field | O10: 上り項目 Request Message Field | P10: 下り項目 Response Message Field | Q10: 上り項目 Request Message Field | R10: 下り項目 Response Message Field
A11: 10 | B11: * | D11: WgLcl_Upd01_Dtl | E11: L | G11: $share$ | H11: MA.MABCL0033.WgLcl_UpdChk01.WgLcl_UpdChk01_Dtl | K11: L | M11: L
A12: 10 | D12: wg_cd | E12: #MA.WG_CD | G12: WG cd. | H12: ワーキンググループＣＤ | I12: E | K12: E | M12: E
A13: 10 | D13: lcl_cd | E13: #MA.LCL_CD | G13: Locale cd. | H13: ロケールＣＤ | I13: E | K13: E | M13: E
A14: 10 | D14: wg_nm | E14: #MA.WG_NM | G14: WG name | H14: ワーキンググループ名 | I14: E | K14: E | M14: E
A15: 10 | D15: memo1 | E15: #MA.MST_MEMO1 | G15: Memo 1 | H15: メモ１ | I15: E | K15: E | M15: E
A16: 10 | D16: memo2 | E16: #MA.MST_MEMO2 | G16: Memo 2 | H16: メモ２ | I16: E | K16: E | M16: E
A17: 10 | D17: memo3 | E17: #MA.MST_MEMO3 | G17: Memo 3 | H17: メモ３ | I17: E | K17: E | M17: E
A18: 10 | D18: upd_cntr | E18: #MA.UPD_CNT | G18: Update counter | H18: 更新カウンタ | I18: E | K18: E | M18: E
D19: 詳細 :

Sheet Wg_DelChk01
A1: * | B1: * | D1: L | E1: 1
A2: * | D2: オペレーション実装仕様書 Operation Specification Implementation Sheet | E2: ModuleID : | F2: =IF(LogicCommon!C2="","",LogicCommon!C2) -> MA | G2: LogicID : | H2: =IF(LogicCommon!E2="","",LogicCommon!E2) -> MABCL0033 | I2: Ope.ID : | J2: Wg_DelChk01 | K2: Pj.ID : | L2: =IF(LogicCommon!G2="","",LogicCommon!G2) -> MC | M2: Ope.Body : | N2: =L4 & ".Checker" -> MA.MAUDL5010.Checker
A3: * | D3: =IF(LogicCommon!A3="","",LogicCommon!A3) | E3: SubModuleID : | F3: =IF(LogicCommon!C3="","",LogicCommon!C3) -> MABC | G3: LogicClass : | H3: =IF(LogicCommon!E3="","",LogicCommon!E3) -> MABCL_MultiReg | I3: Ope.Method : | J3: @ | K3: SuperClassPj.ID : | L3: =IF(LogicCommon!G3="","",LogicCommon!G3) | M3: ReportID : | O3: Gene.Type : | P3: ALL
A4: * | E4: Version : | F4: 000000 | G4: LogicName : | H4: =IF(LogicCommon!E4="","",LogicCommon!E4) -> マルチマスタ登録 | I4: Ope.Name : | J4: チェック | K4: SuperLogicID : | L4: =IF(LogicCommon!G4="","",LogicCommon!G4) -> MA.MAUDL5010
A5: * | E5: ACType :
A6: * | D6: 概要 : | E6: ＷＧマスタの削除前のチェックを行います。 | M6: ID
A7: # | I7: U | K7: K | L7: o
A8: # | D8: ブロック名 Block Name | E8: 型 Type | G8: super/share | H8: 対象ブロック名 Target Block Name | K8: REQUIRED | L8: TargetName | P8: ブロック備考 Block Remarks
A9: # | D9: 項目名 Field Name | E9: 型 Type | F9: 桁 Digits | G9: フルネーム Full Name | H9: 日本語名 Japanese Name | I9: 上り項目 Request Message Field | J9: 下り項目 Response Message Field | N9: 条件および編集方法 Conditions and Editing Methods | P9: 項目備考 Field Remarks
A10: # | L10: 上り項目 Request Message Field | M10: 下り項目 Response Message Field
A11: 10 | B11: * | D11: Wg_DelChk01_Dtl | E11: L
A12: 10 | D12: wg_cd | E12: #MA.WG_CD | G12: WG cd. | H12: ワーキンググループＣＤ | I12: E | K12: E
A13: 10 | D13: upd_cntr | E13: #MA.UPD_CNT | G13: Update counter | H13: 更新カウンタ | I13: E
D14: 詳細 :

Sheet Wg_Del01
A1: * | B1: * | D1: L | E1: 1
A2: * | D2: オペレーション実装仕様書 Operation Specification Implementation Sheet | E2: ModuleID : | F2: =IF(LogicCommon!C2="","",LogicCommon!C2) -> MA | G2: LogicID : | H2: =IF(LogicCommon!E2="","",LogicCommon!E2) -> MABCL0033 | I2: Ope.ID : | J2: Wg_Del01 | K2: Pj.ID : | L2: =IF(LogicCommon!G2="","",LogicCommon!G2) -> MC | M2: Ope.Body : | N2: "mcframe.serverMAUD.MAUDL6020.MAUDL_LCLRLDeleter"
A3: * | D3: =IF(LogicCommon!A3="","",LogicCommon!A3) | E3: SubModuleID : | F3: =IF(LogicCommon!C3="","",LogicCommon!C3) -> MABC | G3: LogicClass : | H3: =IF(LogicCommon!E3="","",LogicCommon!E3) -> MABCL_MultiReg | I3: Ope.Method : | J3: @ | K3: SuperClassPj.ID : | L3: =IF(LogicCommon!G3="","",LogicCommon!G3) | M3: ReportID : | O3: Gene.Type : | P3: ALL
A4: * | E4: Version : | F4: 000000 | G4: LogicName : | H4: =IF(LogicCommon!E4="","",LogicCommon!E4) -> マルチマスタ登録 | I4: Ope.Name : | J4: 削除 | K4: SuperLogicID : | L4: =IF(LogicCommon!G4="","",LogicCommon!G4) -> MA.MAUDL5010
A5: * | E5: ACType :
A6: * | D6: 概要 : | E6: ＷＧマスタの削除を行います。 | L6: ID | N6: ID | P6: ID | R6: ID
A7: # | I7: U | K7: o | L7: UPDATE.updMaster1 | M7: o | N7: UPDATE.updMaster2 | O7: o | Q7: o
A8: # | D8: ブロック名 Block Name | E8: 型 Type | G8: super/share | H8: 対象ブロック名 Target Block Name | K8: TargetName | L8: DBC.MA.MAM_WG | M8: TargetName | N8: DBC.MA.MAM_WG_LCL | O8: TargetName | Q8: TargetName | U8: ブロック備考 Block Remarks
A9: # | D9: 項目名 Field Name | E9: 型 Type | F9: 桁 Digits | G9: フルネーム Full Name | H9: 日本語名 Japanese Name | I9: 上り項目 Request Message Field | J9: 下り項目 Response Message Field | S9: 条件および編集方法 Conditions and Editing Methods | U9: 項目備考 Field Remarks
A10: # | K10: 上り項目 Request Message Field | L10: 下り項目 Response Message Field | M10: 上り項目 Request Message Field | N10: 下り項目 Response Message Field | O10: 上り項目 Request Message Field | P10: 下り項目 Response Message Field | Q10: 上り項目 Request Message Field | R10: 下り項目 Response Message Field
A11: 10 | B11: * | D11: Wg_Del01_Dtl | E11: L | G11: $share$ | H11: MA.MABCL0033.Wg_DelChk01.Wg_DelChk01_Dtl | K11: L | M11: L
A12: 10 | D12: wg_cd | E12: #MA.WG_CD | G12: WG cd. | H12: ワーキンググループＣＤ | I12: E | K12: E | M12: E
A13: 10 | D13: upd_cntr | E13: #MA.UPD_CNT | G13: Update counter | H13: 更新カウンタ | I13: E | K13: E
D14: 詳細 :

Sheet Oper_UpdChk01
A1: * | B1: * | D1: L | E1: 1
A2: * | D2: オペレーション実装仕様書 Operation Specification Implementation Sheet | E2: ModuleID : | F2: =IF(LogicCommon!C2="","",LogicCommon!C2) -> MA | G2: LogicID : | H2: =IF(LogicCommon!E2="","",LogicCommon!E2) -> MABCL0033 | I2: Ope.ID : | J2: Oper_UpdChk01 | K2: Pj.ID : | L2: =IF(LogicCommon!G2="","",LogicCommon!G2) -> MC | M2: Ope.Body : | N2: =L4 & ".Checker" -> MA.MAUDL5010.Checker
A3: * | D3: =IF(LogicCommon!A3="","",LogicCommon!A3) | E3: SubModuleID : | F3: =IF(LogicCommon!C3="","",LogicCommon!C3) -> MABC | G3: LogicClass : | H3: =IF(LogicCommon!E3="","",LogicCommon!E3) -> MABCL_MultiReg | I3: Ope.Method : | J3: @ | K3: SuperClassPj.ID : | L3: =IF(LogicCommon!G3="","",LogicCommon!G3) | M3: ReportID : | O3: Gene.Type : | P3: ALL
A4: * | E4: Version : | F4: 000000 | G4: LogicName : | H4: =IF(LogicCommon!E4="","",LogicCommon!E4) -> マルチマスタ登録 | I4: Ope.Name : | J4: チェック | K4: SuperLogicID : | L4: =IF(LogicCommon!G4="","",LogicCommon!G4) -> MA.MAUDL5010
A5: * | E5: ACType :
A6: * | D6: 概要 : | E6: 工程マスタの登録前のチェックを行います。 | M6: ID
A7: # | I7: U | K7: K | L7: o
A8: # | D8: ブロック名 Block Name | E8: 型 Type | G8: super/share | H8: 対象ブロック名 Target Block Name | K8: REQUIRED | L8: TargetName | P8: ブロック備考 Block Remarks
A9: # | D9: 項目名 Field Name | E9: 型 Type | F9: 桁 Digits | G9: フルネーム Full Name | H9: 日本語名 Japanese Name | I9: 上り項目 Request Message Field | J9: 下り項目 Response Message Field | N9: 条件および編集方法 Conditions and Editing Methods | P9: 項目備考 Field Remarks
A10: # | L10: 上り項目 Request Message Field | M10: 下り項目 Response Message Field
A11: 10 | B11: * | D11: Oper_UpdChk01_Dtl | E11: L | G11: $super$ | H11: DBC:MA.MAM_OPER
A12: 10 | D12: oper_cd | E12: #MA.OPER_CD | G12: Operation cd. | H12: 工程ＣＤ | I12: E | K12: E
A13: 10 | D13: oper_nm | E13: #MA.OPER_NM | G13: Standard operation name | H13: 標準工程名 | I13: E | K13: E
A14: 10 | D14: oper_alc_grp | E14: #MA.OPER_ALC_GRP | G14: Operation allocation group | H14: 工程配賦グループ | I14: E
A15: 10 | D15: memo1 | E15: #MA.MST_MEMO1 | G15: Memo 1 | H15: メモ１ | I15: E
A16: 10 | D16: memo2 | E16: #MA.MST_MEMO2 | G16: Memo 2 | H16: メモ２ | I16: E
A17: 10 | D17: memo3 | E17: #MA.MST_MEMO3 | G17: Memo 3 | H17: メモ３ | I17: E
A18: 10 | D18: del_flg | E18: #MA.FLG | G18: Logical delete | H18: 論理削除 | I18: E
A19: 10 | D19: upd_cntr | E19: #MA.UPD_CNT | G19: Update counter | H19: 更新カウンタ | I19: E
D20: 詳細 :

Sheet Oper_Upd01
A1: * | B1: * | D1: L | E1: 1
A2: * | D2: オペレーション実装仕様書 Operation Specification Implementation Sheet | E2: ModuleID : | F2: =IF(LogicCommon!C2="","",LogicCommon!C2) -> MA | G2: LogicID : | H2: =IF(LogicCommon!E2="","",LogicCommon!E2) -> MABCL0033 | I2: Ope.ID : | J2: Oper_Upd01 | K2: Pj.ID : | L2: =IF(LogicCommon!G2="","",LogicCommon!G2) -> MC | M2: Ope.Body : | N2: "mcframe.serverMAUD.MAUDL6020.MAUDL_LCLRLUpdater"
A3: * | D3: =IF(LogicCommon!A3="","",LogicCommon!A3) | E3: SubModuleID : | F3: =IF(LogicCommon!C3="","",LogicCommon!C3) -> MABC | G3: LogicClass : | H3: =IF(LogicCommon!E3="","",LogicCommon!E3) -> MABCL_MultiReg | I3: Ope.Method : | J3: @ | K3: SuperClassPj.ID : | L3: =IF(LogicCommon!G3="","",LogicCommon!G3) | M3: ReportID : | O3: Gene.Type : | P3: ALL
A4: * | E4: Version : | F4: 000000 | G4: LogicName : | H4: =IF(LogicCommon!E4="","",LogicCommon!E4) -> マルチマスタ登録 | I4: Ope.Name : | J4: 登録 | K4: SuperLogicID : | L4: =IF(LogicCommon!G4="","",LogicCommon!G4) -> MA.MAUDL5010
A5: * | E5: ACType :
A6: * | D6: 概要 : | E6: 工程マスタの登録を行います。 | L6: ID | N6: ID | P6: ID | R6: ID
A7: # | I7: U | K7: o | L7: UPDATE.updMaster | M7: o | N7: MAIN.chkMaster | O7: o | Q7: o
A8: # | D8: ブロック名 Block Name | E8: 型 Type | G8: super/share | H8: 対象ブロック名 Target Block Name | K8: TargetName | L8: DBC.MA.MAM_OPER | M8: TargetName | N8: DBC.MA.MAM_OPER | O8: TargetName | Q8: TargetName | U8: ブロック備考 Block Remarks
A9: # | D9: 項目名 Field Name | E9: 型 Type | F9: 桁 Digits | G9: フルネーム Full Name | H9: 日本語名 Japanese Name | I9: 上り項目 Request Message Field | J9: 下り項目 Response Message Field | S9: 条件および編集方法 Conditions and Editing Methods | U9: 項目備考 Field Remarks
A10: # | K10: 上り項目 Request Message Field | L10: 下り項目 Response Message Field | M10: 上り項目 Request Message Field | N10: 下り項目 Response Message Field | O10: 上り項目 Request Message Field | P10: 下り項目 Response Message Field | Q10: 上り項目 Request Message Field | R10: 下り項目 Response Message Field
A11: 10 | B11: * | D11: Oper_Upd01_Dtl | E11: L | G11: $share$ | H11: MA.MABCL0033.Oper_UpdChk01.Oper_UpdChk01_Dtl | K11: L | M11: L
A12: 10 | D12: oper_cd | E12: #MA.OPER_CD | G12: Operation cd. | H12: 工程ＣＤ | I12: E | K12: E | M12: E
A13: 10 | D13: oper_nm | E13: #MA.OPER_NM | G13: Standard operation name | H13: 標準工程名 | I13: E | K13: E | M13: E
A14: 10 | D14: oper_alc_grp | E14: #MA.OPER_ALC_GRP | G14: Operation allocation group | H14: 工程配賦グループ | I14: E | K14: E | M14: E
A15: 10 | D15: memo1 | E15: #MA.MST_MEMO1 | G15: Memo 1 | H15: メモ１ | I15: E | K15: E | M15: E
A16: 10 | D16: memo2 | E16: #MA.MST_MEMO2 | G16: Memo 2 | H16: メモ２ | I16: E | K16: E | M16: E
A17: 10 | D17: memo3 | E17: #MA.MST_MEMO3 | G17: Memo 3 | H17: メモ３ | I17: E | K17: E | M17: E
A18: 10 | D18: del_flg | E18: #MA.FLG | G18: Logical delete | H18: 論理削除 | I18: E | K18: E | M18: E
A19: 10 | D19: upd_cntr | E19: #MA.UPD_CNT | G19: Update counter | H19: 更新カウンタ | I19: E | K19: E | M19: E
D20: 詳細 :

Sheet OperLcl_UpdChk01
A1: * | B1: * | D1: L | E1: 1
A2: * | D2: オペレーション実装仕様書 Operation Specification Implementation Sheet | E2: ModuleID : | F2: =IF(LogicCommon!C2="","",LogicCommon!C2) -> MA | G2: LogicID : | H2: =IF(LogicCommon!E2="","",LogicCommon!E2) -> MABCL0033 | I2: Ope.ID : | J2: OperLcl_UpdChk01 | K2: Pj.ID : | L2: =IF(LogicCommon!G2="","",LogicCommon!G2) -> MC | M2: Ope.Body : | N2: =L4 & ".Checker" -> MA.MAUDL5010.Checker
A3: * | D3: =IF(LogicCommon!A3="","",LogicCommon!A3) | E3: SubModuleID : | F3: =IF(LogicCommon!C3="","",LogicCommon!C3) -> MABC | G3: LogicClass : | H3: =IF(LogicCommon!E3="","",LogicCommon!E3) -> MABCL_MultiReg | I3: Ope.Method : | J3: @ | K3: SuperClassPj.ID : | L3: =IF(LogicCommon!G3="","",LogicCommon!G3) | M3: ReportID : | O3: Gene.Type : | P3: ALL
A4: * | E4: Version : | F4: 000000 | G4: LogicName : | H4: =IF(LogicCommon!E4="","",LogicCommon!E4) -> マルチマスタ登録 | I4: Ope.Name : | J4: チェック | K4: SuperLogicID : | L4: =IF(LogicCommon!G4="","",LogicCommon!G4) -> MA.MAUDL5010
A5: * | E5: ACType :
A6: * | D6: 概要 : | E6: 工程マスタの登録前のチェックを行います。（ロケール用） | M6: ID
A7: # | I7: U | K7: K | L7: o | M7: EXISTS.chk01
A8: # | D8: ブロック名 Block Name | E8: 型 Type | G8: super/share | H8: 対象ブロック名 Target Block Name | K8: REQUIRED | L8: TargetName | M8: DBC.MA.MAM_OPER | P8: ブロック備考 Block Remarks
A9: # | D9: 項目名 Field Name | E9: 型 Type | F9: 桁 Digits | G9: フルネーム Full Name | H9: 日本語名 Japanese Name | I9: 上り項目 Request Message Field | J9: 下り項目 Response Message Field | N9: 条件および編集方法 Conditions and Editing Methods | P9: 項目備考 Field Remarks
A10: # | L10: 上り項目 Request Message Field | M10: 下り項目 Response Message Field
A11: 10 | B11: * | D11: OperLcl_UpdChk01_Dtl | E11: L | G11: $super$ | H11: DBC:MA.MAM_OPER_LCL | L11: L
A12: 10 | D12: oper_cd | E12: #MA.OPER_CD | G12: Operation cd. | H12: 工程ＣＤ | I12: E | K12: E | L12: E
A13: 10 | D13: lcl_cd | E13: #MA.LCL_CD | G13: Locale cd. | H13: ロケールＣＤ | I13: E | K13: E
A14: 10 | D14: oper_nm | E14: #MA.OPER_NM | G14: Operation name | H14: 工程名 | I14: E | K14: E
A15: 10 | D15: memo1 | E15: #MA.MST_MEMO1 | G15: Memo 1 | H15: メモ１ | I15: E
A16: 10 | D16: memo2 | E16: #MA.MST_MEMO2 | G16: Memo 2 | H16: メモ２ | I16: E
A17: 10 | D17: memo3 | E17: #MA.MST_MEMO3 | G17: Memo 3 | H17: メモ３ | I17: E
A18: 10 | D18: upd_cntr | E18: #MA.UPD_CNT | G18: Update counter | H18: 更新カウンタ | I18: E
D19: 詳細 :

Sheet OperLcl_Upd01
A1: * | B1: * | D1: L | E1: 1
A2: * | D2: オペレーション実装仕様書 Operation Specification Implementation Sheet | E2: ModuleID : | F2: =IF(LogicCommon!C2="","",LogicCommon!C2) -> MA | G2: LogicID : | H2: =IF(LogicCommon!E2="","",LogicCommon!E2) -> MABCL0033 | I2: Ope.ID : | J2: OperLcl_Upd01 | K2: Pj.ID : | L2: =IF(LogicCommon!G2="","",LogicCommon!G2) -> MC | M2: Ope.Body : | N2: "mcframe.serverMAUD.MAUDL6020.MAUDL_LCLRLUpdater"
A3: * | D3: =IF(LogicCommon!A3="","",LogicCommon!A3) | E3: SubModuleID : | F3: =IF(LogicCommon!C3="","",LogicCommon!C3) -> MABC | G3: LogicClass : | H3: =IF(LogicCommon!E3="","",LogicCommon!E3) -> MABCL_MultiReg | I3: Ope.Method : | J3: @ | K3: SuperClassPj.ID : | L3: =IF(LogicCommon!G3="","",LogicCommon!G3) | M3: ReportID : | O3: Gene.Type : | P3: ALL
A4: * | E4: Version : | F4: 000000 | G4: LogicName : | H4: =IF(LogicCommon!E4="","",LogicCommon!E4) -> マルチマスタ登録 | I4: Ope.Name : | J4: 登録 | K4: SuperLogicID : | L4: =IF(LogicCommon!G4="","",LogicCommon!G4) -> MA.MAUDL5010
A5: * | E5: ACType :
A6: * | D6: 概要 : | E6: 工程マスタの登録を行います。（ロケール用） | L6: ID | N6: ID | P6: ID | R6: ID
A7: # | I7: U | K7: o | L7: UPDATE.updMaster | M7: o | N7: MAIN.chkMaster | O7: o | Q7: o
A8: # | D8: ブロック名 Block Name | E8: 型 Type | G8: super/share | H8: 対象ブロック名 Target Block Name | K8: TargetName | L8: DBC.MA.MAM_OPER_LCL | M8: TargetName | N8: DBC.MA.MAM_OPER_LCL | O8: TargetName | Q8: TargetName | U8: ブロック備考 Block Remarks
A9: # | D9: 項目名 Field Name | E9: 型 Type | F9: 桁 Digits | G9: フルネーム Full Name | H9: 日本語名 Japanese Name | I9: 上り項目 Request Message Field | J9: 下り項目 Response Message Field | S9: 条件および編集方法 Conditions and Editing Methods | U9: 項目備考 Field Remarks
A10: # | K10: 上り項目 Request Message Field | L10: 下り項目 Response Message Field | M10: 上り項目 Request Message Field | N10: 下り項目 Response Message Field | O10: 上り項目 Request Message Field | P10: 下り項目 Response Message Field | Q10: 上り項目 Request Message Field | R10: 下り項目 Response Message Field
A11: 10 | B11: * | D11: OperLcl_Upd01_Dtl | E11: L | G11: $share$ | H11: MA.MABCL0033.OperLcl_UpdChk01.OperLcl_UpdChk01_Dtl | K11: L | M11: L
A12: 10 | D12: oper_cd | E12: #MA.OPER_CD | G12: Operation cd. | H12: 工程ＣＤ | I12: E | K12: E | M12: E
A13: 10 | D13: lcl_cd | E13: #MA.LCL_CD | G13: Locale cd. | H13: ロケールＣＤ | I13: E | K13: E | M13: E
A14: 10 | D14: oper_nm | E14: #MA.OPER_NM | G14: Operation name | H14: 工程名 | I14: E | K14: E | M14: E
A15: 10 | D15: memo1 | E15: #MA.MST_MEMO1 | G15: Memo 1 | H15: メモ１ | I15: E | K15: E | M15: E
A16: 10 | D16: memo2 | E16: #MA.MST_MEMO2 | G16: Memo 2 | H16: メモ２ | I16: E | K16: E | M16: E
A17: 10 | D17: memo3 | E17: #MA.MST_MEMO3 | G17: Memo 3 | H17: メモ３ | I17: E | K17: E | M17: E
A18: 10 | D18: upd_cntr | E18: #MA.UPD_CNT | G18: Update counter | H18: 更新カウンタ | I18: E | K18: E | M18: E
D19: 詳細 :

Sheet Oper_DelChk01
A1: * | B1: * | D1: L | E1: 1
A2: * | D2: オペレーション実装仕様書 Operation Specification Implementation Sheet | E2: ModuleID : | F2: =IF(LogicCommon!C2="","",LogicCommon!C2) -> MA | G2: LogicID : | H2: =IF(LogicCommon!E2="","",LogicCommon!E2) -> MABCL0033 | I2: Ope.ID : | J2: Oper_DelChk01 | K2: Pj.ID : | L2: =IF(LogicCommon!G2="","",LogicCommon!G2) -> MC | M2: Ope.Body : | N2: =L4 & ".Checker" -> MA.MAUDL5010.Checker
A3: * | D3: =IF(LogicCommon!A3="","",LogicCommon!A3) | E3: SubModuleID : | F3: =IF(LogicCommon!C3="","",LogicCommon!C3) -> MABC | G3: LogicClass : | H3: =IF(LogicCommon!E3="","",LogicCommon!E3) -> MABCL_MultiReg | I3: Ope.Method : | J3: @ | K3: SuperClassPj.ID : | L3: =IF(LogicCommon!G3="","",LogicCommon!G3) | M3: ReportID : | O3: Gene.Type : | P3: ALL
A4: * | E4: Version : | F4: 000000 | G4: LogicName : | H4: =IF(LogicCommon!E4="","",LogicCommon!E4) -> マルチマスタ登録 | I4: Ope.Name : | J4: チェック | K4: SuperLogicID : | L4: =IF(LogicCommon!G4="","",LogicCommon!G4) -> MA.MAUDL5010
A5: * | E5: ACType :
A6: * | D6: 概要 : | E6: 工程マスタの削除前のチェックを行います。 | M6: ID
A7: # | I7: U | K7: K | L7: o
A8: # | D8: ブロック名 Block Name | E8: 型 Type | G8: super/share | H8: 対象ブロック名 Target Block Name | K8: REQUIRED | L8: TargetName | P8: ブロック備考 Block Remarks
A9: # | D9: 項目名 Field Name | E9: 型 Type | F9: 桁 Digits | G9: フルネーム Full Name | H9: 日本語名 Japanese Name | I9: 上り項目 Request Message Field | J9: 下り項目 Response Message Field | N9: 条件および編集方法 Conditions and Editing Methods | P9: 項目備考 Field Remarks
A10: # | L10: 上り項目 Request Message Field | M10: 下り項目 Response Message Field
A11: 10 | B11: * | D11: Oper_DelChk01_Dtl | E11: L
A12: 10 | D12: oper_cd | E12: #MA.OPER_CD | G12: Operation cd. | H12: 工程ＣＤ | I12: E | K12: E
A13: 10 | D13: upd_cntr | E13: #MA.UPD_CNT | G13: Update counter | H13: 更新カウンタ | I13: E
D14: 詳細 :

Sheet Oper_Del01
A1: * | B1: * | D1: L | E1: 1
A2: * | D2: オペレーション実装仕様書 Operation Specification Implementation Sheet | E2: ModuleID : | F2: =IF(LogicCommon!C2="","",LogicCommon!C2) -> MA | G2: LogicID : | H2: =IF(LogicCommon!E2="","",LogicCommon!E2) -> MABCL0033 | I2: Ope.ID : | J2: Oper_Del01 | K2: Pj.ID : | L2: =IF(LogicCommon!G2="","",LogicCommon!G2) -> MC | M2: Ope.Body : | N2: "mcframe.serverMAUD.MAUDL6020.MAUDL_LCLRLDeleter"
A3: * | D3: =IF(LogicCommon!A3="","",LogicCommon!A3) | E3: SubModuleID : | F3: =IF(LogicCommon!C3="","",LogicCommon!C3) -> MABC | G3: LogicClass : | H3: =IF(LogicCommon!E3="","",LogicCommon!E3) -> MABCL_MultiReg | I3: Ope.Method : | J3: @ | K3: SuperClassPj.ID : | L3: =IF(LogicCommon!G3="","",LogicCommon!G3) | M3: ReportID : | O3: Gene.Type : | P3: ALL
A4: * | E4: Version : | F4: 000000 | G4: LogicName : | H4: =IF(LogicCommon!E4="","",LogicCommon!E4) -> マルチマスタ登録 | I4: Ope.Name : | J4: 削除 | K4: SuperLogicID : | L4: =IF(LogicCommon!G4="","",LogicCommon!G4) -> MA.MAUDL5010
A5: * | E5: ACType :
A6: * | D6: 概要 : | E6: 工程マスタの削除を行います。 | L6: ID | N6: ID | P6: ID | R6: ID
A7: # | I7: U | K7: o | L7: UPDATE.updMaster1 | M7: o | N7: UPDATE.updMaster2 | O7: o | Q7: o
A8: # | D8: ブロック名 Block Name | E8: 型 Type | G8: super/share | H8: 対象ブロック名 Target Block Name | K8: TargetName | L8: DBC.MA.MAM_OPER | M8: TargetName | N8: DBC.MA.MAM_OPER_LCL | O8: TargetName | Q8: TargetName | U8: ブロック備考 Block Remarks
A9: # | D9: 項目名 Field Name | E9: 型 Type | F9: 桁 Digits | G9: フルネーム Full Name | H9: 日本語名 Japanese Name | I9: 上り項目 Request Message Field | J9: 下り項目 Response Message Field | S9: 条件および編集方法 Conditions and Editing Methods | U9: 項目備考 Field Remarks
A10: # | K10: 上り項目 Request Message Field | L10: 下り項目 Response Message Field | M10: 上り項目 Request Message Field | N10: 下り項目 Response Message Field | O10: 上り項目 Request Message Field | P10: 下り項目 Response Message Field | Q10: 上り項目 Request Message Field | R10: 下り項目 Response Message Field
A11: 10 | B11: * | D11: Oper_Del01_Dtl | E11: L | G11: $share$ | H11: MA.MABCL0033.Oper_DelChk01.Oper_DelChk01_Dtl | K11: L | M11: L
A12: 10 | D12: oper_cd | E12: #MA.OPER_CD | G12: Operation cd. | H12: 工程ＣＤ | I12: E | K12: E | M12: E
A13: 10 | D13: upd_cntr | E13: #MA.UPD_CNT | G13: Update counter | H13: 更新カウンタ | I13: E | K13: E
D14: 詳細 :

Sheet WkCost_UpdChk01
A1: * | B1: * | D1: L | E1: 1
A2: * | D2: オペレーション実装仕様書 Operation Specification Implementation Sheet | E2: ModuleID : | F2: =IF(LogicCommon!C2="","",LogicCommon!C2) -> MA | G2: LogicID : | H2: =IF(LogicCommon!E2="","",LogicCommon!E2) -> MABCL0033 | I2: Ope.ID : | J2: WkCost_UpdChk01 | K2: Pj.ID : | L2: =IF(LogicCommon!G2="","",LogicCommon!G2) -> MC | M2: Ope.Body : | N2: =L4 & ".Checker" -> MA.MAUDL5010.Checker
A3: * | D3: =IF(LogicCommon!A3="","",LogicCommon!A3) | E3: SubModuleID : | F3: =IF(LogicCommon!C3="","",LogicCommon!C3) -> MABC | G3: LogicClass : | H3: =IF(LogicCommon!E3="","",LogicCommon!E3) -> MABCL_MultiReg | I3: Ope.Method : | J3: @ | K3: SuperClassPj.ID : | L3: =IF(LogicCommon!G3="","",LogicCommon!G3) | M3: ReportID : | O3: Gene.Type : | P3: ALL
A4: * | E4: Version : | F4: 000000 | G4: LogicName : | H4: =IF(LogicCommon!E4="","",LogicCommon!E4) -> マルチマスタ登録 | I4: Ope.Name : | J4: チェック | K4: SuperLogicID : | L4: =IF(LogicCommon!G4="","",LogicCommon!G4) -> MA.MAUDL5010
A5: * | E5: ACType :
A6: * | D6: 概要 : | E6: 工数管理マスタの登録前のチェックを行います。 | O6: ID
A7: # | I7: U | K7: K | L7: K | M7: K | N7: o
A8: # | D8: ブロック名 Block Name | E8: 型 Type | G8: super/share | H8: 対象ブロック名 Target Block Name | K8: REQUIRED | L8: CONST | M8: SMALL_LARGE | N8: TargetName | R8: ブロック備考 Block Remarks
A9: # | D9: 項目名 Field Name | E9: 型 Type | F9: 桁 Digits | G9: フルネーム Full Name | H9: 日本語名 Japanese Name | I9: 上り項目 Request Message Field | J9: 下り項目 Response Message Field | P9: 条件および編集方法 Conditions and Editing Methods | R9: 項目備考 Field Remarks
A10: # | N10: 上り項目 Request Message Field | O10: 下り項目 Response Message Field
A11: 10 | B11: * | D11: WkCost_UpdChk01_Dtl | E11: L | G11: $super$ | H11: DBC:MA.MAM_WK_COST
A12: 10 | D12: wk_cost_cd | E12: #MA.WK_COST_CD | G12: Work element cd. | H12: 工数管理ＣＤ | I12: E | K12: E
A13: 10 | D13: wk_cost_nm | E13: #MA.WK_COST_NM | G13: Standard work element name | H13: 標準工数管理名 | I13: E | K13: E
A14: 10 | D14: wk_cost_unit_nm | E14: #MA.WK_COST_UNIT_NM | G14: Work element unit name | H14: 工数管理単位名 | I14: E | K14: E
A15: 10 | D15: dec_place | E15: #MA.DEC_PLACE | G15: Number of decimal places | H15: 小数部有効桁数 | I15: E | K15: E | M15: 0:8
A16: 10 | D16: rnd_typ | E16: #MA.RND_TYP | G16: Rounding type | H16: 端数処理区分 | I16: E | K16: E | L16: MAC_RND_TYP
A17: 10 | D17: memo1 | E17: #MA.MST_MEMO1 | G17: Memo 1 | H17: メモ１ | I17: E
A18: 10 | D18: memo2 | E18: #MA.MST_MEMO2 | G18: Memo 2 | H18: メモ２ | I18: E
A19: 10 | D19: memo3 | E19: #MA.MST_MEMO3 | G19: Memo 3 | H19: メモ３ | I19: E
A20: 10 | D20: del_flg | E20: #MA.FLG | G20: Logical delete | H20: 論理削除 | I20: E
A21: 10 | D21: upd_cntr | E21: #MA.UPD_CNT | G21: Update counter | H21: 更新カウンタ | I21: E
D22: 詳細 :

Sheet WkCost_Upd01
A1: * | B1: * | D1: L | E1: 1
A2: * | D2: オペレーション実装仕様書 Operation Specification Implementation Sheet | E2: ModuleID : | F2: =IF(LogicCommon!C2="","",LogicCommon!C2) -> MA | G2: LogicID : | H2: =IF(LogicCommon!E2="","",LogicCommon!E2) -> MABCL0033 | I2: Ope.ID : | J2: WkCost_Upd01 | K2: Pj.ID : | L2: =IF(LogicCommon!G2="","",LogicCommon!G2) -> MC | M2: Ope.Body : | N2: "mcframe.serverMAUD.MAUDL6020.MAUDL_LCLRLUpdater"
A3: * | D3: =IF(LogicCommon!A3="","",LogicCommon!A3) | E3: SubModuleID : | F3: =IF(LogicCommon!C3="","",LogicCommon!C3) -> MABC | G3: LogicClass : | H3: =IF(LogicCommon!E3="","",LogicCommon!E3) -> MABCL_MultiReg | I3: Ope.Method : | J3: @ | K3: SuperClassPj.ID : | L3: =IF(LogicCommon!G3="","",LogicCommon!G3) | M3: ReportID : | O3: Gene.Type : | P3: ALL
A4: * | E4: Version : | F4: 000000 | G4: LogicName : | H4: =IF(LogicCommon!E4="","",LogicCommon!E4) -> マルチマスタ登録 | I4: Ope.Name : | J4: 登録 | K4: SuperLogicID : | L4: =IF(LogicCommon!G4="","",LogicCommon!G4) -> MA.MAUDL5010
A5: * | E5: ACType :
A6: * | D6: 概要 : | E6: 工数管理マスタの登録を行います。 | L6: ID | N6: ID | P6: ID | R6: ID
A7: # | I7: U | K7: o | L7: UPDATE.updMaster | M7: o | N7: MAIN.chkMaster | O7: o | Q7: o
A8: # | D8: ブロック名 Block Name | E8: 型 Type | G8: super/share | H8: 対象ブロック名 Target Block Name | K8: TargetName | L8: DBC.MA.MAM_WK_COST | M8: TargetName | N8: DBC.MA.MAM_WK_COST | O8: TargetName | Q8: TargetName | U8: ブロック備考 Block Remarks
A9: # | D9: 項目名 Field Name | E9: 型 Type | F9: 桁 Digits | G9: フルネーム Full Name | H9: 日本語名 Japanese Name | I9: 上り項目 Request Message Field | J9: 下り項目 Response Message Field | S9: 条件および編集方法 Conditions and Editing Methods | U9: 項目備考 Field Remarks
A10: # | K10: 上り項目 Request Message Field | L10: 下り項目 Response Message Field | M10: 上り項目 Request Message Field | N10: 下り項目 Response Message Field | O10: 上り項目 Request Message Field | P10: 下り項目 Response Message Field | Q10: 上り項目 Request Message Field | R10: 下り項目 Response Message Field
A11: 10 | B11: * | D11: WkCost_Upd01_Dtl | E11: L | G11: $share$ | H11: MA.MABCL0033.WkCost_UpdChk01.WkCost_UpdChk01_Dtl | K11: L | M11: L
A12: 10 | D12: wk_cost_cd | E12: #MA.WK_COST_CD | G12: Work element cd. | H12: 工数管理ＣＤ | I12: E | K12: E | M12: E
A13: 10 | D13: wk_cost_nm | E13: #MA.WK_COST_NM | G13: Standard work element name | H13: 標準工数管理名 | I13: E | K13: E | M13: E
A14: 10 | D14: wk_cost_unit_nm | E14: #MA.WK_COST_UNIT_NM | G14: Work element unit name | H14: 工数管理単位名 | I14: E | K14: E | M14: E
A15: 10 | D15: dec_place | E15: #MA.DEC_PLACE | G15: Number of decimal places | H15: 小数部有効桁数 | I15: E | K15: E | M15: E
A16: 10 | D16: rnd_typ | E16: #MA.RND_TYP | G16: Rounding type | H16: 端数処理区分 | I16: E | K16: E | M16: E
A17: 10 | D17: memo1 | E17: #MA.MST_MEMO1 | G17: Memo 1 | H17: メモ１ | I17: E | K17: E | M17: E
A18: 10 | D18: memo2 | E18: #MA.MST_MEMO2 | G18: Memo 2 | H18: メモ２ | I18: E | K18: E | M18: E
A19: 10 | D19: memo3 | E19: #MA.MST_MEMO3 | G19: Memo 3 | H19: メモ３ | I19: E | K19: E | M19: E
A20: 10 | D20: del_flg | E20: #MA.FLG | G20: Logical delete | H20: 論理削除 | I20: E | K20: E | M20: E
A21: 10 | D21: upd_cntr | E21: #MA.UPD_CNT | G21: Update counter | H21: 更新カウンタ | I21: E | K21: E | M21: E
D22: 詳細 :

Sheet WkCostLcl_UpdChk01
A1: * | B1: * | D1: L | E1: 1
A2: * | D2: オペレーション実装仕様書 Operation Specification Implementation Sheet | E2: ModuleID : | F2: =IF(LogicCommon!C2="","",LogicCommon!C2) -> MA | G2: LogicID : | H2: =IF(LogicCommon!E2="","",LogicCommon!E2) -> MABCL0033 | I2: Ope.ID : | J2: WkCostLcl_UpdChk01 | K2: Pj.ID : | L2: =IF(LogicCommon!G2="","",LogicCommon!G2) -> MC | M2: Ope.Body : | N2: =L4 & ".Checker" -> MA.MAUDL5010.Checker
A3: * | D3: =IF(LogicCommon!A3="","",LogicCommon!A3) | E3: SubModuleID : | F3: =IF(LogicCommon!C3="","",LogicCommon!C3) -> MABC | G3: LogicClass : | H3: =IF(LogicCommon!E3="","",LogicCommon!E3) -> MABCL_MultiReg | I3: Ope.Method : | J3: @ | K3: SuperClassPj.ID : | L3: =IF(LogicCommon!G3="","",LogicCommon!G3) | M3: ReportID : | O3: Gene.Type : | P3: ALL
A4: * | E4: Version : | F4: 000000 | G4: LogicName : | H4: =IF(LogicCommon!E4="","",LogicCommon!E4) -> マルチマスタ登録 | I4: Ope.Name : | J4: チェック | K4: SuperLogicID : | L4: =IF(LogicCommon!G4="","",LogicCommon!G4) -> MA.MAUDL5010
A5: * | E5: ACType :
A6: * | D6: 概要 : | E6: 工数管理マスタの登録前のチェックを行います。（ロケール用） | M6: ID
A7: # | I7: U | K7: K | L7: o | M7: EXISTS.chk01
A8: # | D8: ブロック名 Block Name | E8: 型 Type | G8: super/share | H8: 対象ブロック名 Target Block Name | K8: REQUIRED | L8: TargetName | M8: DBC.MA.MAM_WK_COST | P8: ブロック備考 Block Remarks
A9: # | D9: 項目名 Field Name | E9: 型 Type | F9: 桁 Digits | G9: フルネーム Full Name | H9: 日本語名 Japanese Name | I9: 上り項目 Request Message Field | J9: 下り項目 Response Message Field | N9: 条件および編集方法 Conditions and Editing Methods | P9: 項目備考 Field Remarks
A10: # | L10: 上り項目 Request Message Field | M10: 下り項目 Response Message Field
A11: 10 | B11: * | D11: WkCostLcl_UpdChk01_Dtl | E11: L | G11: $super$ | H11: DBC:MA.MAM_WK_COST_LCL | L11: L
A12: 10 | D12: wk_cost_cd | E12: #MA.WK_COST_CD | G12: Work element cd. | H12: 工数管理ＣＤ | I12: E | K12: E | L12: E
A13: 10 | D13: lcl_cd | E13: #MA.LCL_CD | G13: Locale cd. | H13: ロケールＣＤ | I13: E | K13: E
A14: 10 | D14: wk_cost_nm | E14: #MA.WK_COST_NM | G14: Work element name | H14: 工数管理名 | I14: E | K14: E
A15: 10 | D15: wk_cost_unit_nm | E15: #MA.WK_COST_UNIT_NM | G15: Work element unit name | H15: 工数管理単位名 | I15: E | K15: E
A16: 10 | D16: memo1 | E16: #MA.MST_MEMO1 | G16: Memo 1 | H16: メモ１ | I16: E
A17: 10 | D17: memo2 | E17: #MA.MST_MEMO2 | G17: Memo 2 | H17: メモ２ | I17: E
A18: 10 | D18: memo3 | E18: #MA.MST_MEMO3 | G18: Memo 3 | H18: メモ３ | I18: E
A19: 10 | D19: upd_cntr | E19: #MA.UPD_CNT | G19: Update counter | H19: 更新カウンタ | I19: E
D20: 詳細 :

Sheet WkCostLcl_Upd01
A1: * | B1: * | D1: L | E1: 1
A2: * | D2: オペレーション実装仕様書 Operation Specification Implementation Sheet | E2: ModuleID : | F2: =IF(LogicCommon!C2="","",LogicCommon!C2) -> MA | G2: LogicID : | H2: =IF(LogicCommon!E2="","",LogicCommon!E2) -> MABCL0033 | I2: Ope.ID : | J2: WkCostLcl_Upd01 | K2: Pj.ID : | L2: =IF(LogicCommon!G2="","",LogicCommon!G2) -> MC | M2: Ope.Body : | N2: "mcframe.serverMAUD.MAUDL6020.MAUDL_LCLRLUpdater"
A3: * | D3: =IF(LogicCommon!A3="","",LogicCommon!A3) | E3: SubModuleID : | F3: =IF(LogicCommon!C3="","",LogicCommon!C3) -> MABC | G3: LogicClass : | H3: =IF(LogicCommon!E3="","",LogicCommon!E3) -> MABCL_MultiReg | I3: Ope.Method : | J3: @ | K3: SuperClassPj.ID : | L3: =IF(LogicCommon!G3="","",LogicCommon!G3) | M3: ReportID : | O3: Gene.Type : | P3: ALL
A4: * | E4: Version : | F4: 000000 | G4: LogicName : | H4: =IF(LogicCommon!E4="","",LogicCommon!E4) -> マルチマスタ登録 | I4: Ope.Name : | J4: 登録 | K4: SuperLogicID : | L4: =IF(LogicCommon!G4="","",LogicCommon!G4) -> MA.MAUDL5010
A5: * | E5: ACType :
A6: * | D6: 概要 : | E6: 工数管理マスタの登録を行います。（ロケール用） | L6: ID | N6: ID | P6: ID | R6: ID
A7: # | I7: U | K7: o | L7: UPDATE.updMaster | M7: o | N7: MAIN.chkMaster | O7: o | Q7: o
A8: # | D8: ブロック名 Block Name | E8: 型 Type | G8: super/share | H8: 対象ブロック名 Target Block Name | K8: TargetName | L8: DBC.MA.MAM_WK_COST_LCL | M8: TargetName | N8: DBC.MA.MAM_WK_COST_LCL | O8: TargetName | Q8: TargetName | U8: ブロック備考 Block Remarks
A9: # | D9: 項目名 Field Name | E9: 型 Type | F9: 桁 Digits | G9: フルネーム Full Name | H9: 日本語名 Japanese Name | I9: 上り項目 Request Message Field | J9: 下り項目 Response Message Field | S9: 条件および編集方法 Conditions and Editing Methods | U9: 項目備考 Field Remarks
A10: # | K10: 上り項目 Request Message Field | L10: 下り項目 Response Message Field | M10: 上り項目 Request Message Field | N10: 下り項目 Response Message Field | O10: 上り項目 Request Message Field | P10: 下り項目 Response Message Field | Q10: 上り項目 Request Message Field | R10: 下り項目 Response Message Field
A11: 10 | B11: * | D11: WkCostLcl_Upd01_Dtl | E11: L | G11: $share$ | H11: MA.MABCL0033.WkCostLcl_UpdChk01.WkCostLcl_UpdChk01_Dtl | K11: L | M11: L
A12: 10 | D12: wk_cost_cd | E12: #MA.WK_COST_CD | G12: Work element cd. | H12: 工数管理ＣＤ | I12: E | K12: E | M12: E
A13: 10 | D13: lcl_cd | E13: #MA.LCL_CD | G13: Locale cd. | H13: ロケールＣＤ | I13: E | K13: E | M13: E
A14: 10 | D14: wk_cost_nm | E14: #MA.WK_COST_NM | G14: Work element name | H14: 工数管理名 | I14: E | K14: E | M14: E
A15: 10 | D15: wk_cost_unit_nm | E15: #MA.WK_COST_UNIT_NM | G15: Work element unit name | H15: 工数管理単位名 | I15: E | K15: E | M15: E
A16: 10 | D16: memo1 | E16: #MA.MST_MEMO1 | G16: Memo 1 | H16: メモ１ | I16: E | K16: E | M16: E
A17: 10 | D17: memo2 | E17: #MA.MST_MEMO2 | G17: Memo 2 | H17: メモ２ | I17: E | K17: E | M17: E
A18: 10 | D18: memo3 | E18: #MA.MST_MEMO3 | G18: Memo 3 | H18: メモ３ | I18: E | K18: E | M18: E
A19: 10 | D19: upd_cntr | E19: #MA.UPD_CNT | G19: Update counter | H19: 更新カウンタ | I19: E | K19: E | M19: E
D20: 詳細 :

Sheet WkCost_DelChk01
A1: * | B1: * | D1: L | E1: 1
A2: * | D2: オペレーション実装仕様書 Operation Specification Implementation Sheet | E2: ModuleID : | F2: =IF(LogicCommon!C2="","",LogicCommon!C2) -> MA | G2: LogicID : | H2: =IF(LogicCommon!E2="","",LogicCommon!E2) -> MABCL0033 | I2: Ope.ID : | J2: WkCost_DelChk01 | K2: Pj.ID : | L2: =IF(LogicCommon!G2="","",LogicCommon!G2) -> MC | M2: Ope.Body : | N2: =L4 & ".Checker" -> MA.MAUDL5010.Checker
A3: * | D3: =IF(LogicCommon!A3="","",LogicCommon!A3) | E3: SubModuleID : | F3: =IF(LogicCommon!C3="","",LogicCommon!C3) -> MABC | G3: LogicClass : | H3: =IF(LogicCommon!E3="","",LogicCommon!E3) -> MABCL_MultiReg | I3: Ope.Method : | J3: @ | K3: SuperClassPj.ID : | L3: =IF(LogicCommon!G3="","",LogicCommon!G3) | M3: ReportID : | O3: Gene.Type : | P3: ALL
A4: * | E4: Version : | F4: 000000 | G4: LogicName : | H4: =IF(LogicCommon!E4="","",LogicCommon!E4) -> マルチマスタ登録 | I4: Ope.Name : | J4: チェック | K4: SuperLogicID : | L4: =IF(LogicCommon!G4="","",LogicCommon!G4) -> MA.MAUDL5010
A5: * | E5: ACType :
A6: * | D6: 概要 : | E6: 工数管理マスタの削除前のチェックを行います。 | M6: ID
A7: # | I7: U | K7: K | L7: o
A8: # | D8: ブロック名 Block Name | E8: 型 Type | G8: super/share | H8: 対象ブロック名 Target Block Name | K8: REQUIRED | L8: TargetName | P8: ブロック備考 Block Remarks
A9: # | D9: 項目名 Field Name | E9: 型 Type | F9: 桁 Digits | G9: フルネーム Full Name | H9: 日本語名 Japanese Name | I9: 上り項目 Request Message Field | J9: 下り項目 Response Message Field | N9: 条件および編集方法 Conditions and Editing Methods | P9: 項目備考 Field Remarks
A10: # | L10: 上り項目 Request Message Field | M10: 下り項目 Response Message Field
A11: 10 | B11: * | D11: WkCost_DelChk01_Dtl | E11: L
A12: 10 | D12: wk_cost_cd | E12: #MA.WK_COST_CD | G12: Work element cd. | H12: 工数管理ＣＤ | I12: E | K12: E
A13: 10 | D13: upd_cntr | E13: #MA.UPD_CNT | G13: Update counter | H13: 更新カウンタ | I13: E
D14: 詳細 :

Sheet WkCost_Del01
A1: * | B1: * | D1: L | E1: 1
A2: * | D2: オペレーション実装仕様書 Operation Specification Implementation Sheet | E2: ModuleID : | F2: =IF(LogicCommon!C2="","",LogicCommon!C2) -> MA | G2: LogicID : | H2: =IF(LogicCommon!E2="","",LogicCommon!E2) -> MABCL0033 | I2: Ope.ID : | J2: WkCost_Del01 | K2: Pj.ID : | L2: =IF(LogicCommon!G2="","",LogicCommon!G2) -> MC | M2: Ope.Body : | N2: "mcframe.serverMAUD.MAUDL6020.MAUDL_LCLRLDeleter"
A3: * | D3: =IF(LogicCommon!A3="","",LogicCommon!A3) | E3: SubModuleID : | F3: =IF(LogicCommon!C3="","",LogicCommon!C3) -> MABC | G3: LogicClass : | H3: =IF(LogicCommon!E3="","",LogicCommon!E3) -> MABCL_MultiReg | I3: Ope.Method : | J3: @ | K3: SuperClassPj.ID : | L3: =IF(LogicCommon!G3="","",LogicCommon!G3) | M3: ReportID : | O3: Gene.Type : | P3: ALL
A4: * | E4: Version : | F4: 000000 | G4: LogicName : | H4: =IF(LogicCommon!E4="","",LogicCommon!E4) -> マルチマスタ登録 | I4: Ope.Name : | J4: 削除 | K4: SuperLogicID : | L4: =IF(LogicCommon!G4="","",LogicCommon!G4) -> MA.MAUDL5010
A5: * | E5: ACType :
A6: * | D6: 概要 : | E6: 工数管理マスタの削除を行います。 | L6: ID | N6: ID | P6: ID | R6: ID
A7: # | I7: U | K7: o | L7: UPDATE.updMaster1 | M7: o | N7: UPDATE.updMaster2 | O7: o | Q7: o
A8: # | D8: ブロック名 Block Name | E8: 型 Type | G8: super/share | H8: 対象ブロック名 Target Block Name | K8: TargetName | L8: DBC.MA.MAM_WK_COST | M8: TargetName | N8: DBC.MA.MAM_WK_COST_LCL | O8: TargetName | Q8: TargetName | U8: ブロック備考 Block Remarks
A9: # | D9: 項目名 Field Name | E9: 型 Type | F9: 桁 Digits | G9: フルネーム Full Name | H9: 日本語名 Japanese Name | I9: 上り項目 Request Message Field | J9: 下り項目 Response Message Field | S9: 条件および編集方法 Conditions and Editing Methods | U9: 項目備考 Field Remarks
A10: # | K10: 上り項目 Request Message Field | L10: 下り項目 Response Message Field | M10: 上り項目 Request Message Field | N10: 下り項目 Response Message Field | O10: 上り項目 Request Message Field | P10: 下り項目 Response Message Field | Q10: 上り項目 Request Message Field | R10: 下り項目 Response Message Field
A11: 10 | B11: * | D11: WkCost_Del01_Dtl | E11: L | G11: $share$ | H11: MA.MABCL0033.WkCost_DelChk01.WkCost_DelChk01_Dtl | K11: L | M11: L
A12: 10 | D12: wk_cost_cd | E12: #MA.WK_COST_CD | G12: Work element cd. | H12: 工数管理ＣＤ | I12: E | K12: E | M12: E
A13: 10 | D13: upd_cntr | E13: #MA.UPD_CNT | G13: Update counter | H13: 更新カウンタ | I13: E | K13: E
D14: 詳細 :

Sheet WkRsn_UpdChk01
A1: * | B1: * | D1: L | E1: 1
A2: * | D2: オペレーション実装仕様書 Operation Specification Implementation Sheet | E2: ModuleID : | F2: =IF(LogicCommon!C2="","",LogicCommon!C2) -> MA | G2: LogicID : | H2: =IF(LogicCommon!E2="","",LogicCommon!E2) -> MABCL0033 | I2: Ope.ID : | J2: WkRsn_UpdChk01 | K2: Pj.ID : | L2: =IF(LogicCommon!G2="","",LogicCommon!G2) -> MC | M2: Ope.Body : | N2: =L4 & ".Checker" -> MA.MAUDL5010.Checker
A3: * | D3: =IF(LogicCommon!A3="","",LogicCommon!A3) | E3: SubModuleID : | F3: =IF(LogicCommon!C3="","",LogicCommon!C3) -> MABC | G3: LogicClass : | H3: =IF(LogicCommon!E3="","",LogicCommon!E3) -> MABCL_MultiReg | I3: Ope.Method : | J3: @ | K3: SuperClassPj.ID : | L3: =IF(LogicCommon!G3="","",LogicCommon!G3) | M3: ReportID : | O3: Gene.Type : | P3: ALL
A4: * | E4: Version : | F4: 000000 | G4: LogicName : | H4: =IF(LogicCommon!E4="","",LogicCommon!E4) -> マルチマスタ登録 | I4: Ope.Name : | J4: チェック | K4: SuperLogicID : | L4: =IF(LogicCommon!G4="","",LogicCommon!G4) -> MA.MAUDL5010
A5: * | E5: ACType :
A6: * | D6: 概要 : | E6: 工数理由マスタの登録前のチェックを行います。 | M6: ID
A7: # | I7: U | K7: K | L7: o
A8: # | D8: ブロック名 Block Name | E8: 型 Type | G8: super/share | H8: 対象ブロック名 Target Block Name | K8: REQUIRED | L8: TargetName | P8: ブロック備考 Block Remarks
A9: # | D9: 項目名 Field Name | E9: 型 Type | F9: 桁 Digits | G9: フルネーム Full Name | H9: 日本語名 Japanese Name | I9: 上り項目 Request Message Field | J9: 下り項目 Response Message Field | N9: 条件および編集方法 Conditions and Editing Methods | P9: 項目備考 Field Remarks
A10: # | L10: 上り項目 Request Message Field | M10: 下り項目 Response Message Field
A11: 10 | B11: * | D11: WkRsn_UpdChk01_Dtl | E11: L | G11: $super$ | H11: DBC:MA.MAM_WK_RSN
A12: 10 | D12: wk_rsn_cd | E12: #MA.WK_RSN_CD | G12: Man-hour reason cd. | H12: 工数理由ＣＤ | I12: E | K12: E
A13: 10 | D13: wk_rsn_nm | E13: #MA.WK_RSN_NM | G13: Standard man-hour reason name | H13: 標準工数理由名 | I13: E | K13: E
A14: 10 | D14: memo1 | E14: #MA.MST_MEMO1 | G14: Memo 1 | H14: メモ１ | I14: E
A15: 10 | D15: memo2 | E15: #MA.MST_MEMO2 | G15: Memo 2 | H15: メモ２ | I15: E
A16: 10 | D16: memo3 | E16: #MA.MST_MEMO3 | G16: Memo 3 | H16: メモ３ | I16: E
A17: 10 | D17: del_flg | E17: #MA.FLG | G17: Logical delete | H17: 論理削除 | I17: E
A18: 10 | D18: upd_cntr | E18: #MA.UPD_CNT | G18: Update counter | H18: 更新カウンタ | I18: E
D19: 詳細 :

Sheet WkRsn_Upd01
A1: * | B1: * | D1: L | E1: 1
A2: * | D2: オペレーション実装仕様書 Operation Specification Implementation Sheet | E2: ModuleID : | F2: =IF(LogicCommon!C2="","",LogicCommon!C2) -> MA | G2: LogicID : | H2: =IF(LogicCommon!E2="","",LogicCommon!E2) -> MABCL0033 | I2: Ope.ID : | J2: WkRsn_Upd01 | K2: Pj.ID : | L2: =IF(LogicCommon!G2="","",LogicCommon!G2) -> MC | M2: Ope.Body : | N2: "mcframe.serverMAUD.MAUDL6020.MAUDL_LCLRLUpdater"
A3: * | D3: =IF(LogicCommon!A3="","",LogicCommon!A3) | E3: SubModuleID : | F3: =IF(LogicCommon!C3="","",LogicCommon!C3) -> MABC | G3: LogicClass : | H3: =IF(LogicCommon!E3="","",LogicCommon!E3) -> MABCL_MultiReg | I3: Ope.Method : | J3: @ | K3: SuperClassPj.ID : | L3: =IF(LogicCommon!G3="","",LogicCommon!G3) | M3: ReportID : | O3: Gene.Type : | P3: ALL
A4: * | E4: Version : | F4: 000000 | G4: LogicName : | H4: =IF(LogicCommon!E4="","",LogicCommon!E4) -> マルチマスタ登録 | I4: Ope.Name : | J4: 登録 | K4: SuperLogicID : | L4: =IF(LogicCommon!G4="","",LogicCommon!G4) -> MA.MAUDL5010
A5: * | E5: ACType :
A6: * | D6: 概要 : | E6: 工数理由マスタの登録を行います。 | L6: ID | N6: ID | P6: ID | R6: ID
A7: # | I7: U | K7: o | L7: UPDATE.updMaster | M7: o | N7: MAIN.chkMaster | O7: o | Q7: o
A8: # | D8: ブロック名 Block Name | E8: 型 Type | G8: super/share | H8: 対象ブロック名 Target Block Name | K8: TargetName | L8: DBC.MA.MAM_WK_RSN | M8: TargetName | N8: DBC.MA.MAM_WK_RSN | O8: TargetName | Q8: TargetName | U8: ブロック備考 Block Remarks
A9: # | D9: 項目名 Field Name | E9: 型 Type | F9: 桁 Digits | G9: フルネーム Full Name | H9: 日本語名 Japanese Name | I9: 上り項目 Request Message Field | J9: 下り項目 Response Message Field | S9: 条件および編集方法 Conditions and Editing Methods | U9: 項目備考 Field Remarks
A10: # | K10: 上り項目 Request Message Field | L10: 下り項目 Response Message Field | M10: 上り項目 Request Message Field | N10: 下り項目 Response Message Field | O10: 上り項目 Request Message Field | P10: 下り項目 Response Message Field | Q10: 上り項目 Request Message Field | R10: 下り項目 Response Message Field
A11: 10 | B11: * | D11: WkRsn_Upd01_Dtl | E11: L | G11: $share$ | H11: MA.MABCL0033.WkRsn_UpdChk01.WkRsn_UpdChk01_Dtl | K11: L | M11: L
A12: 10 | D12: wk_rsn_cd | E12: #MA.WK_RSN_CD | G12: Man-hour reason cd. | H12: 工数理由ＣＤ | I12: E | K12: E | M12: E
A13: 10 | D13: wk_rsn_nm | E13: #MA.WK_RSN_NM | G13: Standard man-hour reason name | H13: 標準工数理由名 | I13: E | K13: E | M13: E
A14: 10 | D14: memo1 | E14: #MA.MST_MEMO1 | G14: Memo 1 | H14: メモ１ | I14: E | K14: E | M14: E
A15: 10 | D15: memo2 | E15: #MA.MST_MEMO2 | G15: Memo 2 | H15: メモ２ | I15: E | K15: E | M15: E
A16: 10 | D16: memo3 | E16: #MA.MST_MEMO3 | G16: Memo 3 | H16: メモ３ | I16: E | K16: E | M16: E
A17: 10 | D17: del_flg | E17: #MA.FLG | G17: Logical delete | H17: 論理削除 | I17: E | K17: E | M17: E
A18: 10 | D18: upd_cntr | E18: #MA.UPD_CNT | G18: Update counter | H18: 更新カウンタ | I18: E | K18: E | M18: E
D19: 詳細 :

Sheet WkRsnLcl_UpdChk01
A1: * | B1: * | D1: L | E1: 1
A2: * | D2: オペレーション実装仕様書 Operation Specification Implementation Sheet | E2: ModuleID : | F2: =IF(LogicCommon!C2="","",LogicCommon!C2) -> MA | G2: LogicID : | H2: =IF(LogicCommon!E2="","",LogicCommon!E2) -> MABCL0033 | I2: Ope.ID : | J2: WkRsnLcl_UpdChk01 | K2: Pj.ID : | L2: =IF(LogicCommon!G2="","",LogicCommon!G2) -> MC | M2: Ope.Body : | N2: =L4 & ".Checker" -> MA.MAUDL5010.Checker
A3: * | D3: =IF(LogicCommon!A3="","",LogicCommon!A3) | E3: SubModuleID : | F3: =IF(LogicCommon!C3="","",LogicCommon!C3) -> MABC | G3: LogicClass : | H3: =IF(LogicCommon!E3="","",LogicCommon!E3) -> MABCL_MultiReg | I3: Ope.Method : | J3: @ | K3: SuperClassPj.ID : | L3: =IF(LogicCommon!G3="","",LogicCommon!G3) | M3: ReportID : | O3: Gene.Type : | P3: ALL
A4: * | E4: Version : | F4: 000000 | G4: LogicName : | H4: =IF(LogicCommon!E4="","",LogicCommon!E4) -> マルチマスタ登録 | I4: Ope.Name : | J4: チェック | K4: SuperLogicID : | L4: =IF(LogicCommon!G4="","",LogicCommon!G4) -> MA.MAUDL5010
A5: * | E5: ACType :
A6: * | D6: 概要 : | E6: 工数理由マスタの登録前のチェックを行います。（ロケール用） | M6: ID
A7: # | I7: U | K7: K | L7: o | M7: EXISTS.chk01
A8: # | D8: ブロック名 Block Name | E8: 型 Type | G8: super/share | H8: 対象ブロック名 Target Block Name | K8: REQUIRED | L8: TargetName | M8: DBC.MA.MAM_WK_RSN | P8: ブロック備考 Block Remarks
A9: # | D9: 項目名 Field Name | E9: 型 Type | F9: 桁 Digits | G9: フルネーム Full Name | H9: 日本語名 Japanese Name | I9: 上り項目 Request Message Field | J9: 下り項目 Response Message Field | N9: 条件および編集方法 Conditions and Editing Methods | P9: 項目備考 Field Remarks
A10: # | L10: 上り項目 Request Message Field | M10: 下り項目 Response Message Field
A11: 10 | B11: * | D11: WkRsnLcl_UpdChk01_Dtl | E11: L | G11: $super$ | H11: DBC:MA.MAM_WK_RSN_LCL | L11: L
A12: 10 | D12: wk_rsn_cd | E12: #MA.WK_RSN_CD | G12: Man-hour reason cd. | H12: 工数理由ＣＤ | I12: E | K12: E | L12: E
A13: 10 | D13: lcl_cd | E13: #MA.LCL_CD | G13: Locale cd. | H13: ロケールＣＤ | I13: E | K13: E
A14: 10 | D14: wk_rsn_nm | E14: #MA.WK_RSN_NM | G14: Man-hour reason name | H14: 工数理由名 | I14: E | K14: E
A15: 10 | D15: memo1 | E15: #MA.MST_MEMO1 | G15: Memo 1 | H15: メモ１ | I15: E
A16: 10 | D16: memo2 | E16: #MA.MST_MEMO2 | G16: Memo 2 | H16: メモ２ | I16: E
A17: 10 | D17: memo3 | E17: #MA.MST_MEMO3 | G17: Memo 3 | H17: メモ３ | I17: E
A18: 10 | D18: upd_cntr | E18: #MA.UPD_CNT | G18: Update counter | H18: 更新カウンタ | I18: E
D19: 詳細 :

Sheet WkRsnLcl_Upd01
A1: * | B1: * | D1: L | E1: 1
A2: * | D2: オペレーション実装仕様書 Operation Specification Implementation Sheet | E2: ModuleID : | F2: =IF(LogicCommon!C2="","",LogicCommon!C2) -> MA | G2: LogicID : | H2: =IF(LogicCommon!E2="","",LogicCommon!E2) -> MABCL0033 | I2: Ope.ID : | J2: WkRsnLcl_Upd01 | K2: Pj.ID : | L2: =IF(LogicCommon!G2="","",LogicCommon!G2) -> MC | M2: Ope.Body : | N2: "mcframe.serverMAUD.MAUDL6020.MAUDL_LCLRLUpdater"
A3: * | D3: =IF(LogicCommon!A3="","",LogicCommon!A3) | E3: SubModuleID : | F3: =IF(LogicCommon!C3="","",LogicCommon!C3) -> MABC | G3: LogicClass : | H3: =IF(LogicCommon!E3="","",LogicCommon!E3) -> MABCL_MultiReg | I3: Ope.Method : | J3: @ | K3: SuperClassPj.ID : | L3: =IF(LogicCommon!G3="","",LogicCommon!G3) | M3: ReportID : | O3: Gene.Type : | P3: ALL
A4: * | E4: Version : | F4: 000000 | G4: LogicName : | H4: =IF(LogicCommon!E4="","",LogicCommon!E4) -> マルチマスタ登録 | I4: Ope.Name : | J4: 登録 | K4: SuperLogicID : | L4: =IF(LogicCommon!G4="","",LogicCommon!G4) -> MA.MAUDL5010
A5: * | E5: ACType :
A6: * | D6: 概要 : | E6: 工数理由マスタの登録を行います。（ロケール用） | L6: ID | N6: ID | P6: ID | R6: ID
A7: # | I7: U | K7: o | L7: UPDATE.updMaster | M7: o | N7: MAIN.chkMaster | O7: o | Q7: o
A8: # | D8: ブロック名 Block Name | E8: 型 Type | G8: super/share | H8: 対象ブロック名 Target Block Name | K8: TargetName | L8: DBC.MA.MAM_WK_RSN_LCL | M8: TargetName | N8: DBC.MA.MAM_WK_RSN_LCL | O8: TargetName | Q8: TargetName | U8: ブロック備考 Block Remarks
A9: # | D9: 項目名 Field Name | E9: 型 Type | F9: 桁 Digits | G9: フルネーム Full Name | H9: 日本語名 Japanese Name | I9: 上り項目 Request Message Field | J9: 下り項目 Response Message Field | S9: 条件および編集方法 Conditions and Editing Methods | U9: 項目備考 Field Remarks
A10: # | K10: 上り項目 Request Message Field | L10: 下り項目 Response Message Field | M10: 上り項目 Request Message Field | N10: 下り項目 Response Message Field | O10: 上り項目 Request Message Field | P10: 下り項目 Response Message Field | Q10: 上り項目 Request Message Field | R10: 下り項目 Response Message Field
A11: 10 | B11: * | D11: WkRsnLcl_Upd01_Dtl | E11: L | G11: $share$ | H11: MA.MABCL0033.WkRsnLcl_UpdChk01.WkRsnLcl_UpdChk01_Dtl | K11: L | M11: L
A12: 10 | D12: wk_rsn_cd | E12: #MA.WK_RSN_CD | G12: Man-hour reason cd. | H12: 工数理由ＣＤ | I12: E | K12: E | M12: E
A13: 10 | D13: lcl_cd | E13: #MA.LCL_CD | G13: Locale cd. | H13: ロケールＣＤ | I13: E | K13: E | M13: E
A14: 10 | D14: wk_rsn_nm | E14: #MA.WK_RSN_NM | G14: Man-hour reason name | H14: 工数理由名 | I14: E | K14: E | M14: E
A15: 10 | D15: memo1 | E15: #MA.MST_MEMO1 | G15: Memo 1 | H15: メモ１ | I15: E | K15: E | M15: E
A16: 10 | D16: memo2 | E16: #MA.MST_MEMO2 | G16: Memo 2 | H16: メモ２ | I16: E | K16: E | M16: E
A17: 10 | D17: memo3 | E17: #MA.MST_MEMO3 | G17: Memo 3 | H17: メモ３ | I17: E | K17: E | M17: E
A18: 10 | D18: upd_cntr | E18: #MA.UPD_CNT | G18: Update counter | H18: 更新カウンタ | I18: E | K18: E | M18: E
D19: 詳細 :

Sheet WkRsn_DelChk01
A1: * | B1: * | D1: L | E1: 1
A2: * | D2: オペレーション実装仕様書 Operation Specification Implementation Sheet | E2: ModuleID : | F2: =IF(LogicCommon!C2="","",LogicCommon!C2) -> MA | G2: LogicID : | H2: =IF(LogicCommon!E2="","",LogicCommon!E2) -> MABCL0033 | I2: Ope.ID : | J2: WkRsn_DelChk01 | K2: Pj.ID : | L2: =IF(LogicCommon!G2="","",LogicCommon!G2) -> MC | M2: Ope.Body : | N2: =L4 & ".Checker" -> MA.MAUDL5010.Checker
A3: * | D3: =IF(LogicCommon!A3="","",LogicCommon!A3) | E3: SubModuleID : | F3: =IF(LogicCommon!C3="","",LogicCommon!C3) -> MABC | G3: LogicClass : | H3: =IF(LogicCommon!E3="","",LogicCommon!E3) -> MABCL_MultiReg | I3: Ope.Method : | J3: @ | K3: SuperClassPj.ID : | L3: =IF(LogicCommon!G3="","",LogicCommon!G3) | M3: ReportID : | O3: Gene.Type : | P3: ALL
A4: * | E4: Version : | F4: 000000 | G4: LogicName : | H4: =IF(LogicCommon!E4="","",LogicCommon!E4) -> マルチマスタ登録 | I4: Ope.Name : | J4: チェック | K4: SuperLogicID : | L4: =IF(LogicCommon!G4="","",LogicCommon!G4) -> MA.MAUDL5010
A5: * | E5: ACType :
A6: * | D6: 概要 : | E6: 工数理由マスタの削除前のチェックを行います。 | M6: ID
A7: # | I7: U | K7: K | L7: o
A8: # | D8: ブロック名 Block Name | E8: 型 Type | G8: super/share | H8: 対象ブロック名 Target Block Name | K8: REQUIRED | L8: TargetName | P8: ブロック備考 Block Remarks
A9: # | D9: 項目名 Field Name | E9: 型 Type | F9: 桁 Digits | G9: フルネーム Full Name | H9: 日本語名 Japanese Name | I9: 上り項目 Request Message Field | J9: 下り項目 Response Message Field | N9: 条件および編集方法 Conditions and Editing Methods | P9: 項目備考 Field Remarks
A10: # | L10: 上り項目 Request Message Field | M10: 下り項目 Response Message Field
A11: 10 | B11: * | D11: WkRsn_DelChk01_Dtl | E11: L
A12: 10 | D12: wk_rsn_cd | E12: #MA.WK_RSN_CD | G12: Man-hour reason cd. | H12: 工数理由ＣＤ | I12: E | K12: E
A13: 10 | D13: upd_cntr | E13: #MA.UPD_CNT | G13: Update counter | H13: 更新カウンタ | I13: E
D14: 詳細 :

Sheet WkRsn_Del01
A1: * | B1: * | D1: L | E1: 1
