Workbook

Sheet LogicCommon
A2: ロジック共通定義 | B2: ModuleID : | C2: MA | D2: LogicID : | E2: MABCL0870 | F2: Pj.ID : | G2: MC
B3: SubModuleID : | C3: MABC | D3: LogicClass : | E3: MABCL_ItmCopyReg | F3: SuperClassPj.ID :
D4: LogicName : | E4: 品目系マスタ確認＆コピー | F4: SuperLogicID : | G4: MA.MAUDL5010
A5: 概要 :
A6: 詳細 :

Sheet ItmCopy_UpdChk01
A1: * | B1: * | D1: L | E1: 1
A2: * | D2: オペレーション実装仕様書 Operation Specification Implementation Sheet | E2: ModuleID : | F2: =IF(LogicCommon!C2="","",LogicCommon!C2) -> MA | G2: LogicID : | H2: =IF(LogicCommon!E2="","",LogicCommon!E2) -> MABCL0870 | I2: Ope.ID : | J2: ItmCopy_UpdChk01 | K2: Pj.ID : | L2: =IF(LogicCommon!G2="","",LogicCommon!G2) -> MC | M2: Ope.Body : | N2: =L4 & ".Checker" -> MA.MAUDL5010.Checker
A3: * | D3: =IF(LogicCommon!A3="","",LogicCommon!A3) | E3: SubModuleID : | F3: =IF(LogicCommon!C3="","",LogicCommon!C3) -> MABC | G3: LogicClass : | H3: =IF(LogicCommon!E3="","",LogicCommon!E3) -> MABCL_ItmCopyReg | I3: Ope.Method : | J3: @ | K3: SuperClassPj.ID : | L3: =IF(LogicCommon!G3="","",LogicCommon!G3) | M3: ReportID : | O3: Gene.Type : | P3: ALL
A4: * | E4: Version : | F4: 000000 | G4: LogicName : | H4: =IF(LogicCommon!E4="","",LogicCommon!E4) -> 品目系マスタ確認＆コピー | I4: Ope.Name : | J4: チェック | K4: SuperLogicID : | L4: =IF(LogicCommon!G4="","",LogicCommon!G4) -> MA.MAUDL5010
A5: * | E5: ACType :
A6: * | D6: 概要 : | E6: 品目系マスタのコピー登録前のチェックを行います。 | U6: ID
A7: # | I7: U | K7: K | L7: K | M7: K | N7: K | O7: K | P7: K | Q7: K | R7: K | S7: K | T7: o
A8: # | D8: ブロック名 Block Name | E8: 型 Type | G8: super/share | H8: 対象ブロック名 Target Block Name | K8: TNAME | L8: NULL_VAL | M8: REQUIRED | N8: DUPLICATE | O8: LIST_LOGIC | P8: LIST_IN | Q8: LIST_IN_BASE | R8: LIST_OUT | S8: LIST_OUT_BASE | T8: TargetName | X8: ブロック備考 Block Remarks
A9: # | D9: 項目名 Field Name | E9: 型 Type | F9: 桁 Digits | G9: フルネーム Full Name | H9: 日本語名 Japanese Name | I9: 上り項目 Request Message Field | J9: 下り項目 Response Message Field | V9: 条件および編集方法 Conditions and Editing Methods | X9: 項目備考 Field Remarks
A10: # | T10: 上り項目 Request Message Field | U10: 下り項目 Response Message Field
A11: 10 | B11: * | D11: ItmCopy_UpdChk01_Dtl | E11: L
A12: 10 | D12: itm_cd | E12: #MA.ITM_CD | G12: Item cd. | H12: 品目ＣＤ | I12: E | M12: E
A13: 10 | D13: itm_sub1 | E13: #MA.ITM_SUB1 | G13: Branch No. 1 | H13: 枝番１ | I13: E | M13: E
A14: 10 | D14: itm_sub2 | E14: #MA.ITM_SUB2 | G14: Branch No. 2 | H14: 枝番２ | I14: E | M14: E
A15: 10 | D15: itm_sub3 | E15: #MA.ITM_SUB3 | G15: Branch No. 3 | H15: 枝番３ | I15: E | M15: E
A16: 10 | D16: dest_itm_cd | E16: #MA.ITM_CD | G16: (Copy-to) Item cd. | H16: （コピー先）品目ＣＤ | I16: E | M16: E | N16: E
A17: 10 | D17: dest_itm_sub1 | E17: #MA.ITM_SUB1 | G17: (Copy-to) Branch No. 1 | H17: （コピー先）枝番１ | I17: E | L17: E | M17: E | N17: E
A18: 10 | D18: dest_itm_sub2 | E18: #MA.ITM_SUB2 | G18: (Copy-to) Branch No. 2 | H18: （コピー先）枝番２ | I18: E | L18: E | M18: E | N18: E
A19: 10 | D19: dest_itm_sub3 | E19: #MA.ITM_SUB3 | G19: (Copy-to) Branch No. 3 | H19: （コピー先）枝番３ | I19: E | L19: E | M19: E | N19: E
A20: 10 | D20: dest_itm_nm | E20: #MA.ITM_NM | G20: (Copy-to) Item name | H20: （コピー先）品名 | I20: E | M20: E
A21: 10 | D21: memo1 | E21: #MA.MST_MEMO1 | G21: Memo 1 | H21: メモ１ | I21: E
A22: 10 | D22: memo2 | E22: #MA.MST_MEMO2 | G22: Memo 2 | H22: メモ２ | I22: E
A23: 10 | D23: memo3 | E23: #MA.MST_MEMO3 | G23: Memo 3 | H23: メモ３ | I23: E
A25: 10 | D25: itm_flg | E25: #MA.FLG | G25: Item | H25: 品目 | I25: E | K25: MAM_ITM_
A26: 10 | D26: itm_sub_flg | E26: #MA.FLG | G26: Item auxiliary | H26: 品目補助 | I26: E | K26: MAM_ITM_SUB
A27: 10 | D27: itm_unit_flg | E27: #MA.FLG | G27: Item unit | H27: 品目単位 | I27: E | K27: MAM_ITM_UNIT_
A28: 10 | D28: attach_info_flg | E28: #MA.FLG | G28: Item additional info. | H28: 品目付加情報 | I28: E | K28: MAM_ATTACH_INFO
A29: 10 | D29: itm_stop_flg | E29: #MA.FLG | G29: Item prohibit | H29: 品目禁止 | I29: E | K29: MAM_ITM_STOP
A30: 10 | D30: itm_not_fix_flg | E30: #MA.FLG | G30: Item procurement disapproval | H30: 品目手配不許可 | I30: E | K30: MAM_ITM_NOT_FIX
A31: 10 | D31: stdcost_flg | E31: #MA.FLG | G31: Standard unit cost | H31: 標準単価 | I31: E | K31: MAM_STDCOST_
A32: 10 | D32: sundry_itm_flg | E32: #MA.FLG | G32: Miscellaneous item | H32: 諸口品 | I32: E | K32: MAM_SUNDRY_ITM
A33: 10 | D33: itm_strg_flg | E33: #MA.FLG | G33: Item storage | H33: 品目格納先 | I33: E | K33: MAM_ITM_STRG
A34: 10 | D34: alloc_ctl_flg | E34: #MA.FLG | G34: Mfg. allocation control | H34: 製造引当制御 | I34: E | K34: MAM_ALLOC_CTL
A35: 10 | D35: stk_rpl_flg | E35: #MA.FLG | G35: Inventory replenishment | H35: 在庫補充 | I35: E | K35: MAM_STK_RPL
A36: 10 | D36: alt_itm_flg | E36: #MA.FLG | G36: Alternative item | H36: 代替品目 | I36: E | K36: MAM_ALT_ITM
... A75: 10 | D75: itm_str_ln_flg | E75: #MA.FLG | G75: Item rack/line | H75: 品目棚・ライン | I75: E | K75: MAM_ITM_STR_LN
K76: 上り項目 Request Message Field | L76: 下り項目 Response Message Field | M76: 上り項目 Request Message Field | N76: 下り項目 Response Message Field | O76: 上り項目 Request Message Field | P76: 下り項目 Response Message Field | Q76: 上り項目 Request Message Field | R76: 下り項目 Response Message Field | S76: 上り項目 Request Message Field | T76: 下り項目 Response Message Field
A77: 20 | B77: * | D77: ItmCopy_UpdChk01_Cnd | E77: R
A78: 20 | D78: ex_on_del_flg | E78: #MA.FLG | G78: Exclude logically deleted data | H78: 論理削除がオンは除く | I78: E
A79: 20 | D79: ex_past_end_dt | E79: #MA.DT | G79: Exclude data with past application end dates | H79: 過去の適用終了日は除く | I79: E
...

Sheet ItmCopy_Upd01
A1: * | B1: * | D1: L | E1: 1
A2: * | D2: オペレーション実装仕様書 Operation Specification Implementation Sheet | E2: ModuleID : | F2: =IF(LogicCommon!C2="","",LogicCommon!C2) -> MA | G2: LogicID : | H2: =IF(LogicCommon!E2="","",LogicCommon!E2) -> MABCL0870 | I2: Ope.ID : | J2: ItmCopy_Upd01 | K2: Pj.ID : | L2: =IF(LogicCommon!G2="","",LogicCommon!G2) -> MC | M2: Ope.Body : | N2: "mcframe.serverMAUD.MAUDL6010.MAUDL_RLUpdater"
A3: * | D3: =IF(LogicCommon!A3="","",LogicCommon!A3) | E3: SubModuleID : | F3: =IF(LogicCommon!C3="","",LogicCommon!C3) -> MABC | G3: LogicClass : | H3: =IF(LogicCommon!E3="","",LogicCommon!E3) -> MABCL_ItmCopyReg | I3: Ope.Method : | J3: @ | K3: SuperClassPj.ID : | L3: =IF(LogicCommon!G3="","",LogicCommon!G3) | M3: ReportID : | O3: Gene.Type : | P3: ALL
A4: * | E4: Version : | F4: 000000 | G4: LogicName : | H4: =IF(LogicCommon!E4="","",LogicCommon!E4) -> 品目系マスタ確認＆コピー | I4: Ope.Name : | J4: 登録 | K4: SuperLogicID : | L4: =IF(LogicCommon!G4="","",LogicCommon!G4) -> MA.MAUDL5010
A5: * | E5: ACType :
A6: * | D6: 概要 : | E6: 品目系マスタのコピー登録を行います。 | L6: ID | N6: ID | P6: ID | R6: ID | T6: ID
A7: # | I7: U | K7: o | M7: o | O7: o | Q7: o | S7: o
A8: # | D8: ブロック名 Block Name | E8: 型 Type | G8: super/share | H8: 対象ブロック名 Target Block Name | K8: TargetName | M8: TargetName | O8: TargetName | Q8: TargetName | S8: TargetName | W8: ブロック備考 Block Remarks
A9: # | D9: 項目名 Field Name | E9: 型 Type | F9: 桁 Digits | G9: フルネーム Full Name | H9: 日本語名 Japanese Name | I9: 上り項目 Request Message Field | J9: 下り項目 Response Message Field | U9: 条件および編集方法 Conditions and Editing Methods | W9: 項目備考 Field Remarks
A10: # | K10: 上り項目 Request Message Field | L10: 下り項目 Response Message Field | M10: 上り項目 Request Message Field | N10: 下り項目 Response Message Field | O10: 上り項目 Request Message Field | P10: 下り項目 Response Message Field | Q10: 上り項目 Request Message Field | R10: 下り項目 Response Message Field | S10: 上り項目 Request Message Field | T10: 下り項目 Response Message Field
A11: 10 | B11: * | D11: ItmCopy_Upd01_Dtl | E11: L | G11: $share$ | H11: MA.MABCL0870.ItmCopy_UpdChk01.ItmCopy_UpdChk01_Dtl
A12: 10 | D12: itm_cd | E12: #MA.ITM_CD | G12: Item cd. | H12: 品目ＣＤ | I12: E
A13: 10 | D13: itm_sub1 | E13: #MA.ITM_SUB1 | G13: Branch No. 1 | H13: 枝番１ | I13: E
A14: 10 | D14: itm_sub2 | E14: #MA.ITM_SUB2 | G14: Branch No. 2 | H14: 枝番２ | I14: E
A15: 10 | D15: itm_sub3 | E15: #MA.ITM_SUB3 | G15: Branch No. 3 | H15: 枝番３ | I15: E
A16: 10 | D16: dest_itm_cd | E16: #MA.ITM_CD | G16: (Copy-to) Item cd. | H16: （コピー先）品目ＣＤ | I16: E
A17: 10 | D17: dest_itm_sub1 | E17: #MA.ITM_SUB1 | G17: (Copy-to) Branch No. 1 | H17: （コピー先）枝番１ | I17: E
A18: 10 | D18: dest_itm_sub2 | E18: #MA.ITM_SUB2 | G18: (Copy-to) Branch No. 2 | H18: （コピー先）枝番２ | I18: E
A19: 10 | D19: dest_itm_sub3 | E19: #MA.ITM_SUB3 | G19: (Copy-to) Branch No. 3 | H19: （コピー先）枝番３ | I19: E
A20: 10 | D20: dest_itm_nm | E20: #MA.ITM_NM | G20: (Copy-to) Item name | H20: （コピー先）品名 | I20: E
A21: 10 | D21: memo1 | E21: #MA.MST_MEMO1 | G21: Memo 1 | H21: メモ１ | I21: E
A22: 10 | D22: memo2 | E22: #MA.MST_MEMO2 | G22: Memo 2 | H22: メモ２ | I22: E
A23: 10 | D23: memo3 | E23: #MA.MST_MEMO3 | G23: Memo 3 | H23: メモ３ | I23: E
... A75: 10 | D75: itm_str_ln_flg | E75: #MA.FLG | G75: Item rack/line | H75: 品目棚・ライン | I75: E
K76: 上り項目 Request Message Field | L76: 下り項目 Response Message Field | M76: 上り項目 Request Message Field | N76: 下り項目 Response Message Field | O76: 上り項目 Request Message Field | P76: 下り項目 Response Message Field | Q76: 上り項目 Request Message Field | R76: 下り項目 Response Message Field | S76: 上り項目 Request Message Field | T76: 下り項目 Response Message Field
A77: 20 | B77: * | D77: ItmCopy_Upd01_Cnd | E77: R | G77: $share$ | H77: MA.MABCL0870.ItmCopy_UpdChk01.ItmCopy_UpdChk01_Cnd
A78: 20 | D78: ex_on_del_flg | E78: #MA.FLG | G78: Exclude logically deleted data | H78: 論理削除がオンは除く | I78: E
A79: 20 | D79: ex_past_end_dt | E79: #MA.DT | G79: Exclude data with past application end dates | H79: 過去の適用終了日は除く | I79: E
D80: 詳細 :

Sheet ItmCopy_DelChk01
A1: * | B1: * | D1: L | E1: 1
A2: * | D2: オペレーション実装仕様書 Operation Specification Implementation Sheet | E2: ModuleID : | F2: =IF(LogicCommon!C2="","",LogicCommon!C2) -> MA | G2: LogicID : | H2: =IF(LogicCommon!E2="","",LogicCommon!E2) -> MABCL0870 | I2: Ope.ID : | J2: ItmCopy_DelChk01 | K2: Pj.ID : | L2: =IF(LogicCommon!G2="","",LogicCommon!G2) -> MC | M2: Ope.Body : | N2: =L4 & ".Checker" -> MA.MAUDL5010.Checker
A3: * | D3: =IF(LogicCommon!A3="","",LogicCommon!A3) | E3: SubModuleID : | F3: =IF(LogicCommon!C3="","",LogicCommon!C3) -> MABC | G3: LogicClass : | H3: =IF(LogicCommon!E3="","",LogicCommon!E3) -> MABCL_ItmCopyReg | I3: Ope.Method : | J3: @ | K3: SuperClassPj.ID : | L3: =IF(LogicCommon!G3="","",LogicCommon!G3) | M3: ReportID : | O3: Gene.Type : | P3: ALL
A4: * | E4: Version : | F4: 000000 | G4: LogicName : | H4: =IF(LogicCommon!E4="","",LogicCommon!E4) -> 品目系マスタ確認＆コピー | I4: Ope.Name : | J4: チェック | K4: SuperLogicID : | L4: =IF(LogicCommon!G4="","",LogicCommon!G4) -> MA.MAUDL5010
A5: * | E5: ACType :
A6: * | D6: 概要 : | E6: 品目系マスタの削除前のチェックを行います。 | N6: ID | P6: ID
A7: # | I7: U | K7: K | L7: K | M7: o | O7: o
A8: # | D8: ブロック名 Block Name | E8: 型 Type | G8: super/share | H8: 対象ブロック名 Target Block Name | K8: TNAME | L8: REQUIRED | M8: TargetName | O8: TargetName | S8: ブロック備考 Block Remarks
A9: # | D9: 項目名 Field Name | E9: 型 Type | F9: 桁 Digits | G9: フルネーム Full Name | H9: 日本語名 Japanese Name | I9: 上り項目 Request Message Field | J9: 下り項目 Response Message Field | Q9: 条件および編集方法 Conditions and Editing Methods | S9: 項目備考 Field Remarks
A10: # | M10: 上り項目 Request Message Field | N10: 下り項目 Response Message Field | O10: 上り項目 Request Message Field | P10: 下り項目 Response Message Field
A11: 10 | B11: * | D11: ItmCopy_DelChk01_Dtl | E11: L
A12: 10 | D12: itm_cd | E12: #MA.ITM_CD | G12: Item cd. | H12: 品目ＣＤ | I12: E | L12: E
A13: 10 | D13: itm_sub1 | E13: #MA.ITM_SUB1 | G13: Branch No. 1 | H13: 枝番１ | I13: E | L13: E
A14: 10 | D14: itm_sub2 | E14: #MA.ITM_SUB2 | G14: Branch No. 2 | H14: 枝番２ | I14: E | L14: E
A15: 10 | D15: itm_sub3 | E15: #MA.ITM_SUB3 | G15: Branch No. 3 | H15: 枝番３ | I15: E | L15: E
A17: 10 | D17: itm_flg | E17: #MA.FLG | G17: Item | H17: 品目 | I17: E | K17: MAM_ITM_
A18: 10 | D18: itm_sub_flg | E18: #MA.FLG | G18: Item auxiliary | H18: 品目補助 | I18: E | K18: MAM_ITM_SUB
A19: 10 | D19: itm_unit_flg | E19: #MA.FLG | G19: Item unit | H19: 品目単位 | I19: E | K19: MAM_ITM_UNIT_
A20: 10 | D20: attach_info_flg | E20: #MA.FLG | G20: Item additional info. | H20: 品目付加情報 | I20: E | K20: MAM_ATTACH_INFO
A21: 10 | D21: itm_stop_flg | E21: #MA.FLG | G21: Item prohibit | H21: 品目禁止 | I21: E | K21: MAM_ITM_STOP
A22: 10 | D22: itm_not_fix_flg | E22: #MA.FLG | G22: Item procurement disapproval | H22: 品目手配不許可 | I22: E | K22: MAM_ITM_NOT_FIX
A23: 10 | D23: stdcost_flg | E23: #MA.FLG | G23: Standard unit cost | H23: 標準単価 | I23: E | K23: MAM_STDCOST_
A24: 10 | D24: sundry_itm_flg | E24: #MA.FLG | G24: Miscellaneous item | H24: 諸口品 | I24: E | K24: MAM_SUNDRY_ITM
A25: 10 | D25: itm_strg_flg | E25: #MA.FLG | G25: Item storage | H25: 品目格納先 | I25: E | K25: MAM_ITM_STRG
A26: 10 | D26: alloc_ctl_flg | E26: #MA.FLG | G26: Mfg. allocation control | H26: 製造引当制御 | I26: E | K26: MAM_ALLOC_CTL
A27: 10 | D27: stk_rpl_flg | E27: #MA.FLG | G27: Inventory replenishment | H27: 在庫補充 | I27: E | K27: MAM_STK_RPL
A28: 10 | D28: alt_itm_flg | E28: #MA.FLG | G28: Alternative item | H28: 代替品目 | I28: E | K28: MAM_ALT_ITM
... A67: 10 | D67: itm_str_ln_flg | E67: #MA.FLG | G67: Item rack/line | H67: 品目棚・ライン | I67: E | K67: MAM_ITM_STR_LN
D68: 詳細 :

Sheet ItmCopy_Del01
A1: * | B1: * | D1: L | E1: 1
A2: * | D2: オペレーション実装仕様書 Operation Specification Implementation Sheet | E2: ModuleID : | F2: =IF(LogicCommon!C2="","",LogicCommon!C2) -> MA | G2: LogicID : | H2: =IF(LogicCommon!E2="","",LogicCommon!E2) -> MABCL0870 | I2: Ope.ID : | J2: ItmCopy_Del01 | K2: Pj.ID : | L2: =IF(LogicCommon!G2="","",LogicCommon!G2) -> MC | M2: Ope.Body : | N2: "mcframe.serverMAUD.MAUDL6010.MAUDL_RLDeleter"
A3: * | D3: =IF(LogicCommon!A3="","",LogicCommon!A3) | E3: SubModuleID : | F3: =IF(LogicCommon!C3="","",LogicCommon!C3) -> MABC | G3: LogicClass : | H3: =IF(LogicCommon!E3="","",LogicCommon!E3) -> MABCL_ItmCopyReg | I3: Ope.Method : | J3: @ | K3: SuperClassPj.ID : | L3: =IF(LogicCommon!G3="","",LogicCommon!G3) | M3: ReportID : | O3: Gene.Type : | P3: ALL
A4: * | E4: Version : | F4: 000000 | G4: LogicName : | H4: =IF(LogicCommon!E4="","",LogicCommon!E4) -> 品目系マスタ確認＆コピー | I4: Ope.Name : | J4: 削除 | K4: SuperLogicID : | L4: =IF(LogicCommon!G4="","",LogicCommon!G4) -> MA.MAUDL5010
A5: * | E5: ACType :
A6: * | D6: 概要 : | E6: 品目系マスタの削除を行います。 | L6: ID | N6: ID | P6: ID
A7: # | I7: U | K7: o | M7: o | O7: o
A8: # | D8: ブロック名 Block Name | E8: 型 Type | G8: super/share | H8: 対象ブロック名 Target Block Name | K8: TargetName | M8: TargetName | O8: TargetName | S8: ブロック備考 Block Remarks
A9: # | D9: 項目名 Field Name | E9: 型 Type | F9: 桁 Digits | G9: フルネーム Full Name | H9: 日本語名 Japanese Name | I9: 上り項目 Request Message Field | J9: 下り項目 Response Message Field | Q9: 条件および編集方法 Conditions and Editing Methods | S9: 項目備考 Field Remarks
A10: # | K10: 上り項目 Request Message Field | L10: 下り項目 Response Message Field | M10: 上り項目 Request Message Field | N10: 下り項目 Response Message Field | O10: 上り項目 Request Message Field | P10: 下り項目 Response Message Field
A11: 10 | B11: * | D11: ItmCopy_Del01_Dtl | E11: L | G11: $share$ | H11: MA.MABCL0870.ItmCopy_DelChk01.ItmCopy_DelChk01_Dtl
A12: 10 | D12: itm_cd | E12: #MA.ITM_CD | G12: Item cd. | H12: 品目ＣＤ | I12: E
A13: 10 | D13: itm_sub1 | E13: #MA.ITM_SUB1 | G13: Branch No. 1 | H13: 枝番１ | I13: E
A14: 10 | D14: itm_sub2 | E14: #MA.ITM_SUB2 | G14: Branch No. 2 | H14: 枝番２ | I14: E
A15: 10 | D15: itm_sub3 | E15: #MA.ITM_SUB3 | G15: Branch No. 3 | H15: 枝番３ | I15: E
A17: 10 | D17: itm_flg | E17: #MA.FLG | G17: Item | H17: 品目 | I17: E
A18: 10 | D18: itm_sub_flg | E18: #MA.FLG | G18: Item auxiliary | H18: 品目補助 | I18: E
A19: 10 | D19: itm_unit_flg | E19: #MA.FLG | G19: Item unit | H19: 品目単位 | I19: E
A20: 10 | D20: attach_info_flg | E20: #MA.FLG | G20: Item additional info. | H20: 品目付加情報 | I20: E
A21: 10 | D21: itm_stop_flg | E21: #MA.FLG | G21: Item prohibit | H21: 品目禁止 | I21: E
A22: 10 | D22: itm_not_fix_flg | E22: #MA.FLG | G22: Item procurement disapproval | H22: 品目手配不許可 | I22: E
A23: 10 | D23: stdcost_flg | E23: #MA.FLG | G23: Standard unit cost | H23: 標準単価 | I23: E
A24: 10 | D24: sundry_itm_flg | E24: #MA.FLG | G24: Miscellaneous item | H24: 諸口品 | I24: E
... A67: 10 | D67: itm_str_ln_flg | E67: #MA.FLG | G67: Item rack/line | H67: 品目棚・ライン | I67: E
D68: 詳細 :

Sheet Srch01
A1: * | B1: * | D1: L | E1: 1
A2: * | D2: オペレーション実装仕様書 Operation Specification Implementation Sheet | E2: ModuleID : | F2: =IF(LogicCommon!C2="","",LogicCommon!C2) -> MA | G2: LogicID : | H2: =IF(LogicCommon!E2="","",LogicCommon!E2) -> MABCL0870 | I2: Ope.ID : | J2: Srch01 | K2: Pj.ID : | L2: =IF(LogicCommon!G2="","",LogicCommon!G2) -> MC | M2: Ope.Body : | N2: "mcframe.serverMAUD.MAUDL6010.MAUDL_RLSearcher"
A3: * | D3: =IF(LogicCommon!A3="","",LogicCommon!A3) | E3: SubModuleID : | F3: =IF(LogicCommon!C3="","",LogicCommon!C3) -> MABC | G3: LogicClass : | H3: =IF(LogicCommon!E3="","",LogicCommon!E3) -> MABCL_ItmCopyReg | I3: Ope.Method : | J3: @ | K3: SuperClassPj.ID : | L3: =IF(LogicCommon!G3="","",LogicCommon!G3) | M3: ReportID : | O3: Gene.Type : | P3: ALL
A4: * | E4: Version : | F4: 000000 | G4: LogicName : | H4: =IF(LogicCommon!E4="","",LogicCommon!E4) -> 品目系マスタ確認＆コピー | I4: Ope.Name : | J4: 検索 | K4: SuperLogicID : | L4: =IF(LogicCommon!G4="","",LogicCommon!G4) -> MA.MAUDL5010
A5: * | E5: ACType :
A6: * | D6: 概要 : | E6: 品目系マスタの検索を行います。 | M6: ID | O6: ID | Q6: ID | S6: ID | U6: ID | W6: ID | Y6: ID | AA6: ID | AC6: ID | AE6: ID | AG6: ID | AI6: ID | AK6: ID | AM6: ID | AO6: ID | AQ6: ID | AS6: ID | AU6: ID | AW6: ID | AY6: ID | BA6: ID | BC6: ID | BE6: ID | BG6: ID | BI6: ID | BK6: ID | BM6: ID | BO6: ID | BQ6: ID | BS6: ID | BU6: ID | BW6: ID | BY6: ID | CA6: ID | CC6: ID | CE6: ID | CG6: ID | CI6: ID | CK6: ID | CM6: ID | CO6: ID | CQ6: ID | CS6: ID | CU6: ID | CW6: ID | CY6: ID | DA6: ID | DC6: ID | DE6: ID | DG6: ID | DI6: ID | DK6: ID
A7: # | I7: U | K7: K | L7: o | M7: SELECT.c0 | N7: o | O7: PI.s0 | P7: o | Q7: PI.s1 | R7: o | S7: PI.s2 | T7: o | U7: PI.s3 | V7: o | W7: PI.s4 | X7: o | Y7: PI.s5 | Z7: o | AA7: PI.s6 | AB7: o | AC7: PI.s7 | AD7: o | AE7: PI.s8 | AF7: o | AG7: PI.s9 | AH7: o | AI7: PI.s10 | AJ7: o | AK7: PI.s11 | AL7: o | AM7: PI.s12 | AN7: o | AO7: PI.s13 | AP7: o | AQ7: PI.s14 | AR7: o | AS7: PI.s15 | AT7: o | AU7: PI.s16 | AV7: o | AW7: PI.s17 | AX7: o | AY7: PI.s18 | AZ7: o | BA7: PI.s19 | BB7: o | BC7: PI.s20 | BD7: o | BE7: PI.s21 | BF7: o | BG7: PI.s22 | BH7: o | BI7: PI.s23 | BJ7: o | BK7: PI.s24 | BL7: o | BM7: PI.s25 | BN7: o | BO7: PI.s26 | BP7: o | BQ7: PI.s27 | BR7: o | BS7: PI.s28 | BT7: o | BU7: PI.s29 | BV7: o | BW7: PI.s30 | BX7: o | BY7: PI.s31 | BZ7: o | CA7: PI.s32 | CB7: o | CC7: PI.s33 | CD7: o | CE7: PI.s34 | CF7: o | CG7: PI.s35 | CH7: o | CI7: PI.s36 | CJ7: o | CK7: PI.s37 | CL7: o | CM7: PI.s38 | CN7: o | CO7: PI.s39 | CP7: o | CQ7: PI.s40 | CR7: o | CS7: PI.s41 | CT7: o | CU7: PI.s42 | CV7: o | CW7: PI.s43 | CX7: o | CY7: PI.s44 | CZ7: o | DA7: PI.s45 | DB7: o | DC7: PI.s46 | DD7: o | DE7: PI.s47 | DF7: o | DG7: PI.s48 | DH7: o | DI7: PI.s49 | DJ7: o | DK7: PI.s50
A8: # | D8: ブロック名 Block Name | E8: 型 Type | G8: super/share | H8: 対象ブロック名 Target Block Name | K8: CONST | L8: TargetName | M8: DBC.MA.MAM_ITM_ | N8: TargetName | O8: DBC.MA.MAM_ITM_ | P8: TargetName | Q8: DBC.MA.MAM_ITM_SUB | R8: TargetName | S8: DBC.MA.MAM_ITM_UNIT_ | T8: TargetName | U8: DBC.MA.MAM_ATTACH_INFO | V8: TargetName | W8: DBC.MA.MAM_ITM_STOP | X8: TargetName | Y8: DBC.MA.MAM_ITM_NOT_FIX | Z8: TargetName | AA8: DBC.MA.MAM_STDCOST_ | AB8: TargetName | AC8: DBC.MA.MAM_SUNDRY_ITM | AD8: TargetName | AE8: DBC.MA.MAM_ITM_STRG | AF8: TargetName | AG8: DBC.MA.MAM_ALLOC_CTL | AH8: TargetName | AI8: DBC.MA.MAM_STK_RPL | AJ8: TargetName | AK8: DBC.MA.MAM_ALT_ITM | AL8: TargetName | AM8: DBC.MA.MAM_ITM_WG_ | AN8: TargetName | AO8: DBC.MA.MAM_ITM_DTL_ | AP8: TargetName | AQ8: DBC.MA.MAM_ITM_OPER | AR8: TargetName | AS8: DBC.MA.MAM_BOM | AT8: TargetName | AU8: DBC.MA.MAM_BOM | AV8: TargetName | AW8: DBC.MA.MAM_OPER_WK_COST | AX8: TargetName | AY8: DBC.MA.MAM_ITM_INSP_PTN | AZ8: TargetName | BA8: DBC.MA.MAM_ITM_INSP | BB8: TargetName | BC8: DBC.MA.MAM_INSP_SPEC | BD8: TargetName | BE8: DBC.MA.MAM_ITM_SITE | BF8: TargetName | BG8: DBC.MA.MAM_ITM_VER | BH8: TargetName | BI8: DBC.MA.MAM_LOT_INH_SRC | BJ8: TargetName | BK8: DBC.MA.MAM_LOT_INH_SRC | BL8: TargetName | BM8: DBC.MA.MAM_ITM_SPEC | BN8: TargetName | BO8: DBC.MA.MAM_ITM_SPEC_DESC | BP8: TargetName | BQ8: DBC.MA.MAM_ITM_COMP | BR8: TargetName | BS8: DBC.MA.MAM_ITM_COMP | BT8: TargetName | BU8: DBC.MA.MAM_MPS_ITM_ | BV8: TargetName | BW8: DBC.MA.MAM_SPLN_ITM_CONF | BX8: TargetName | BY8: DBC.MA.MAM_PURC_DDLV_LT | BZ8: TargetName | CA8: DBC.MA.MAM_BP_ITM | CB8: TargetName | CC8: DBC.MA.MAM_PROC_UPRI_ | CD8: TargetName | CE8: DBC.MA.MAM_PROV_UPRI_ | CF8: TargetName | CG8: DBC.MA.MAM_PURC_UPRI_ | CH8: TargetName | CI8: DBC.MA.MAM_STD_SLS_UPRI_ | CJ8: TargetName | CK8: DBC.MA.MAM_ITM_SLS_UPRI_ | CL8: TargetName | CM8: DBC.MA.MAM_CST_SLS_UPRI_ | CN8: TargetName | CO8: DBC.MA.MAM_SET_ITM | CP8: TargetName | CQ8: DBC.MA.MAM_SET_ITM | CR8: TargetName | CS8: DBC.MA.MAM_IF_X | CT8: TargetName | CU8: DBC.MA.MAM_CTG_CONFIG | CV8: TargetName | CW8: DBC.MA.MAM_JNL_PTN | CX8: TargetName | CY8: DBC.MA.MAM_COEF_CONFIG | CZ8: TargetName | DA8: DBC.MA.MAM_ALC_EXPNS | DB8: TargetName | DC8: DBC.MA.MAM_ALC_INPT | DD8: TargetName | DE8: DBC.MA.MAM_COST_ITM_OUT | DF8: TargetName | DG8: DBC.MA.MAM_XPNS_PURC_ALC | DH8: TargetName | DI8: DBC.MA.MAM_ITM_LG_GRP | DJ8: TargetName | DK8: DBC.MA.MAM_ITM_STR_LN | DN8: ブロック備考 Block Remarks
A9: # | D9: 項目名 Field Name | E9: 型 Type | F9: 桁 Digits | G9: フルネーム Full Name | H9: 日本語名 Japanese Name | I9: 上り項目 Request Message Field | J9: 下り項目 Response Message Field | DL9: 条件および編集方法 Conditions and Editing Methods | DN9: 項目備考 Field Remarks
A10: # | L10: 上り項目 Request Message Field | M10: 下り項目 Response Message Field | N10: 上り項目 Request Message Field | O10: 下り項目 Response Message Field | P10: 上り項目 Request Message Field | Q10: 下り項目 Response Message Field | R10: 上り項目 Request Message Field | S10: 下り項目 Response Message Field | T10: 上り項目 Request Message Field | U10: 下り項目 Response Message Field | V10: 上り項目 Request Message Field | W10: 下り項目 Response Message Field | X10: 上り項目 Request Message Field | Y10: 下り項目 Response Message Field | Z10: 上り項目 Request Message Field | AA10: 下り項目 Response Message Field | AB10: 上り項目 Request Message Field | AC10: 下り項目 Response Message Field | AD10: 上り項目 Request Message Field | AE10: 下り項目 Response Message Field | AF10: 上り項目 Request Message Field | AG10: 下り項目 Response Message Field | AH10: 上り項目 Request Message Field | AI10: 下り項目 Response Message Field | AJ10: 上り項目 Request Message Field | AK10: 下り項目 Response Message Field | AL10: 上り項目 Request Message Field | AM10: 下り項目 Response Message Field | AN10: 上り項目 Request Message Field | AO10: 下り項目 Response Message Field | AP10: 上り項目 Request Message Field | AQ10: 下り項目 Response Message Field | AR10: 上り項目 Request Message Field | AS10: 下り項目 Response Message Field | AT10: 上り項目 Request Message Field | AU10: 下り項目 Response Message Field | AV10: 上り項目 Request Message Field | AW10: 下り項目 Response Message Field | AX10: 上り項目 Request Message Field | AY10: 下り項目 Response Message Field | AZ10: 上り項目 Request Message Field | BA10: 下り項目 Response Message Field | BB10: 上り項目 Request Message Field | BC10: 下り項目 Response Message Field | BD10: 上り項目 Request Message Field | BE10: 下り項目 Response Message Field | BF10: 上り項目 Request Message Field | BG10: 下り項目 Response Message Field | BH10: 上り項目 Request Message Field | BI10: 下り項目 Response Message Field | BJ10: 上り項目 Request Message Field | BK10: 下り項目 Response Message Field | BL10: 上り項目 Request Message Field | BM10: 下り項目 Response Message Field | BN10: 上り項目 Request Message Field | BO10: 下り項目 Response Message Field | BP10: 上り項目 Request Message Field | BQ10: 下り項目 Response Message Field | BR10: 上り項目 Request Message Field | BS10: 下り項目 Response Message Field | BT10: 上り項目 Request Message Field | BU10: 下り項目 Response Message Field | BV10: 上り項目 Request Message Field | BW10: 下り項目 Response Message Field | BX10: 上り項目 Request Message Field | BY10: 下り項目 Response Message Field | BZ10: 上り項目 Request Message Field | CA10: 下り項目 Response Message Field | CB10: 上り項目 Request Message Field | CC10: 下り項目 Response Message Field | CD10: 上り項目 Request Message Field | CE10: 下り項目 Response Message Field | CF10: 上り項目 Request Message Field | CG10: 下り項目 Response Message Field | CH10: 上り項目 Request Message Field | CI10: 下り項目 Response Message Field | CJ10: 上り項目 Request Message Field | CK10: 下り項目 Response Message Field | CL10: 上り項目 Request Message Field | CM10: 下り項目 Response Message Field | CN10: 上り項目 Request Message Field | CO10: 下り項目 Response Message Field | CP10: 上り項目 Request Message Field | CQ10: 下り項目 Response Message Field | CR10: 上り項目 Request Message Field | CS10: 下り項目 Response Message Field | CT10: 上り項目 Request Message Field | CU10: 下り項目 Response Message Field | CV10: 上り項目 Request Message Field | CW10: 下り項目 Response Message Field | CX10: 上り項目 Request Message Field | CY10: 下り項目 Response Message Field | CZ10: 上り項目 Request Message Field | DA10: 下り項目 Response Message Field | DB10: 上り項目 Request Message Field | DC10: 下り項目 Response Message Field | DD10: 上り項目 Request Message Field | DE10: 下り項目 Response Message Field | DF10: 上り項目 Request Message Field | DG10: 下り項目 Response Message Field | DH10: 上り項目 Request Message Field | DI10: 下り項目 Response Message Field | DJ10: 上り項目 Request Message Field | DK10: 下り項目 Response Message Field
A11: 10 | B11: * | D11: Srch01_Cnd | E11: R
A12: 10 | D12: ope | E12: C | G12: Operation type | H12: 操作種別 | I12: E
A13: 10 | D13: st_dt_fr | E13: #MA.DT | G13: Application start date FROM | H13: 適用開始日ＦＲＯＭ | I13: E
A14: 10 | D14: st_dt_to | E14: #MA.DT | G14: Application start date TO | H14: 適用開始日ＴＯ | I14: E
A15: 10 | D15: end_dt_fr | E15: #MA.DT | G15: Application end date FROM | H15: 適用終了日ＦＲＯＭ | I15: E
A16: 10 | D16: end_dt_to | E16: #MA.DT | G16: Application end date TO | H16: 適用終了日ＴＯ | I16: E
A17: 10 | D17: itm_cd | E17: #MA.ITM_CD | G17: Item cd. | H17: 品目ＣＤ | I17: E
A18: 10 | D18: itm_sub1 | E18: #MA.ITM_SUB1 | G18: Branch No. 1 | H18: 枝番１ | I18: E
A19: 10 | D19: itm_sub2 | E19: #MA.ITM_SUB2 | G19: Branch No. 2 | H19: 枝番２ | I19: E
A20: 10 | D20: itm_sub3 | E20: #MA.ITM_SUB3 | G20: Branch No. 3 | H20: 枝番３ | I20: E
A21: 10 | D21: itm_nm | E21: #MA.ITM_NM | G21: Item name | H21: 品名 | I21: E
A22: 10 | D22: itm_typ | E22: #MA.ITM_TYP | G22: Item type | H22: 品目区分 | I22: E
A23: 10 | D23: itm_typ_d_cd | E23: #MA.ITM_TYP_D_CD | G23: Item type details cd. | H23: 品目区分詳細ＣＤ | I23: E
... A60: 10 | D60: itm_grp_nm10 | E60: #MA.ITM_GRP_NM | G60: Item classification name 10 | H60: 品目分類名１０ | I60: E
A62: 20 | B62: * | D62: Srch01_Rslt | E62: L | M62: L
A63: 20 | D63: del_flg | E63: #MA.FLG | G63: Logical delete | H63: 論理削除 | J63: E | M63: E
A64: 20 | D64: itm_cd | E64: #MA.ITM_CD | G64: Item cd. | H64: 品目ＣＤ | J64: E | M64: E
A65: 20 | D65: itm_sub1 | E65: #MA.ITM_SUB1 | G65: Branch No. 1 | H65: 枝番１ | J65: E | M65: E
A66: 20 | D66: itm_sub2 | E66: #MA.ITM_SUB2 | G66: Branch No. 2 | H66: 枝番２ | J66: E | M66: E
A67: 20 | D67: itm_sub3 | E67: #MA.ITM_SUB3 | G67: Branch No. 3 | H67: 枝番３ | J67: E | M67: E
A68: 20 | D68: itm_nm | E68: #MA.ITM_NM | G68: Item name | H68: 品名 | J68: E | M68: E
A69: 20 | D69: base_itm_nm | E69: #MA.ITM_NM | G69: Standard Item name | H69: 標準品名 | J69: E | M69: E
A70: 20 | D70: itm_typ | E70: #MA.ITM_TYP | G70: Item type | H70: 品目区分 | J70: E | K70: MAC_ITM_TYP | M70: E
A71: 20 | D71: itm_typ_nm | E71: #MA.ITM_TYP_NM | G71: Item type name | H71: 品目区分名 | J71: E
A72: 20 | D72: itm_typ_d_cd | E72: #MA.ITM_TYP_D_CD | G72: Item type details cd. | H72: 品目区分詳細ＣＤ | J72: E | M72: E
A73: 20 | D73: itm_typ_d_nm | E73: #MA.ITM_TYP_D_NM | G73: Item type details name | H73: 品目区分詳細名 | J73: E | M73: E
A74: 20 | D74: chng_no | E74: #MA.CHNG_NO | G74: Change No. | H74: 変更ＮＯ | J74: E | M74: E
A75: 20 | D75: itm_cnt | E75: #MA.INT | G75: Item master | H75: 品目マスタ | J75: E
A76: 20 | D76: itm_sub_cnt | E76: #MA.INT | G76: Item auxiliary master | H76: 品目補助マスタ | J76: E
A77: 20 | D77: itm_unit_cnt | E77: #MA.INT | G77: Item unit master | H77: 品目単位マスタ | J77: E
...

Sheet Srch02
A1: * | B1: * | D1: L | E1: 1
A2: * | D2: オペレーション実装仕様書 Operation Specification Implementation Sheet | E2: ModuleID : | F2: =IF(LogicCommon!C2="","",LogicCommon!C2) -> MA | G2: LogicID : | H2: =IF(LogicCommon!E2="","",LogicCommon!E2) -> MABCL0870 | I2: Ope.ID : | J2: Srch02 | K2: Pj.ID : | L2: =IF(LogicCommon!G2="","",LogicCommon!G2) -> MC | M2: Ope.Body : | N2: "mcframe.serverMAUD.MAUDL6010.MAUDL_RLSearcher"
A3: * | D3: =IF(LogicCommon!A3="","",LogicCommon!A3) | E3: SubModuleID : | F3: =IF(LogicCommon!C3="","",LogicCommon!C3) -> MABC | G3: LogicClass : | H3: =IF(LogicCommon!E3="","",LogicCommon!E3) -> MABCL_ItmCopyReg | I3: Ope.Method : | J3: @ | K3: SuperClassPj.ID : | L3: =IF(LogicCommon!G3="","",LogicCommon!G3) | M3: ReportID : | O3: Gene.Type : | P3: ALL
A4: * | E4: Version : | F4: 000000 | G4: LogicName : | H4: =IF(LogicCommon!E4="","",LogicCommon!E4) -> 品目系マスタ確認＆コピー | I4: Ope.Name : | J4: 検索（参照品目） | K4: SuperLogicID : | L4: =IF(LogicCommon!G4="","",LogicCommon!G4) -> MA.MAUDL5010
A5: * | E5: ACType :
A6: * | D6: 概要 : | E6: 品目系マスタ（参照品目）の検索を行います。 | M6: ID | O6: ID | Q6: ID | S6: ID | U6: ID | W6: ID | Y6: ID | AA6: ID | AC6: ID | AE6: ID | AG6: ID | AI6: ID | AK6: ID | AM6: ID | AO6: ID | AQ6: ID | AS6: ID | AU6: ID | AW6: ID | AY6: ID | BA6: ID | BC6: ID | BE6: ID | BG6: ID | BI6: ID | BK6: ID | BM6: ID | BO6: ID | BQ6: ID | BS6: ID | BU6: ID | BW6: ID | BY6: ID | CA6: ID | CC6: ID | CE6: ID | CG6: ID | CI6: ID | CK6: ID | CM6: ID | CO6: ID | CQ6: ID | CS6: ID | CU6: ID | CW6: ID | CY6: ID | DA6: ID | DC6: ID | DE6: ID | DG6: ID | DI6: ID | DK6: ID
A7: # | I7: U | K7: K | L7: o | M7: SELECT.c0 | N7: o | O7: PI.s0 | P7: o | Q7: PI.s1 | R7: o | S7: PI.s2 | T7: o | U7: PI.s3 | V7: o | W7: PI.s4 | X7: o | Y7: PI.s5 | Z7: o | AA7: PI.s6 | AB7: o | AC7: PI.s7 | AD7: o | AE7: PI.s8 | AF7: o | AG7: PI.s9 | AH7: o | AI7: PI.s10 | AJ7: o | AK7: PI.s11 | AL7: o | AM7: PI.s12 | AN7: o | AO7: PI.s13 | AP7: o | AQ7: PI.s14 | AR7: o | AS7: PI.s15 | AT7: o | AU7: PI.s16 | AV7: o | AW7: PI.s17 | AX7: o | AY7: PI.s18 | AZ7: o | BA7: PI.s19 | BB7: o | BC7: PI.s20 | BD7: o | BE7: PI.s21 | BF7: o | BG7: PI.s22 | BH7: o | BI7: PI.s23 | BJ7: o | BK7: PI.s24 | BL7: o | BM7: PI.s25 | BN7: o | BO7: PI.s26 | BP7: o | BQ7: PI.s27 | BR7: o | BS7: PI.s28 | BT7: o | BU7: PI.s29 | BV7: o | BW7: PI.s30 | BX7: o | BY7: PI.s31 | BZ7: o | CA7: PI.s32 | CB7: o | CC7: PI.s33 | CD7: o | CE7: PI.s34 | CF7: o | CG7: PI.s35 | CH7: o | CI7: PI.s36 | CJ7: o | CK7: PI.s37 | CL7: o | CM7: PI.s38 | CN7: o | CO7: PI.s39 | CP7: o | CQ7: PI.s40 | CR7: o | CS7: PI.s41 | CT7: o | CU7: PI.s42 | CV7: o | CW7: PI.s43 | CX7: o | CY7: PI.s44 | CZ7: o | DA7: PI.s45 | DB7: o | DC7: PI.s46 | DD7: o | DE7: PI.s47 | DF7: o | DG7: PI.s48 | DH7: o | DI7: PI.s49 | DJ7: o | DK7: PI.s50
A8: # | D8: ブロック名 Block Name | E8: 型 Type | G8: super/share | H8: 対象ブロック名 Target Block Name | K8: CONST | L8: TargetName | M8: DBC.MA.MAM_ITM_ | N8: TargetName | O8: DBC.MA.MAM_ITM_ | P8: TargetName | Q8: DBC.MA.MAM_ITM_SUB | R8: TargetName | S8: DBC.MA.MAM_ITM_UNIT_ | T8: TargetName | U8: DBC.MA.MAM_ATTACH_INFO | V8: TargetName | W8: DBC.MA.MAM_ITM_STOP | X8: TargetName | Y8: DBC.MA.MAM_ITM_NOT_FIX | Z8: TargetName | AA8: DBC.MA.MAM_STDCOST_ | AB8: TargetName | AC8: DBC.MA.MAM_SUNDRY_ITM | AD8: TargetName | AE8: DBC.MA.MAM_ITM_STRG | AF8: TargetName | AG8: DBC.MA.MAM_ALLOC_CTL | AH8: TargetName | AI8: DBC.MA.MAM_STK_RPL | AJ8: TargetName | AK8: DBC.MA.MAM_ALT_ITM | AL8: TargetName | AM8: DBC.MA.MAM_ITM_WG_ | AN8: TargetName | AO8: DBC.MA.MAM_ITM_DTL_ | AP8: TargetName | AQ8: DBC.MA.MAM_ITM_OPER | AR8: TargetName | AS8: DBC.MA.MAM_BOM | AT8: TargetName | AU8: DBC.MA.MAM_BOM | AV8: TargetName | AW8: DBC.MA.MAM_OPER_WK_COST | AX8: TargetName | AY8: DBC.MA.MAM_ITM_INSP_PTN | AZ8: TargetName | BA8: DBC.MA.MAM_ITM_INSP | BB8: TargetName | BC8: DBC.MA.MAM_INSP_SPEC | BD8: TargetName | BE8: DBC.MA.MAM_ITM_SITE | BF8: TargetName | BG8: DBC.MA.MAM_ITM_VER | BH8: TargetName | BI8: DBC.MA.MAM_LOT_INH_SRC | BJ8: TargetName | BK8: DBC.MA.MAM_LOT_INH_SRC | BL8: TargetName | BM8: DBC.MA.MAM_ITM_SPEC | BN8: TargetName | BO8: DBC.MA.MAM_ITM_SPEC_DESC | BP8: TargetName | BQ8: DBC.MA.MAM_ITM_COMP | BR8: TargetName | BS8: DBC.MA.MAM_ITM_COMP | BT8: TargetName | BU8: DBC.MA.MAM_MPS_ITM_ | BV8: TargetName | BW8: DBC.MA.MAM_SPLN_ITM_CONF | BX8: TargetName | BY8: DBC.MA.MAM_PURC_DDLV_LT | BZ8: TargetName | CA8: DBC.MA.MAM_BP_ITM | CB8: TargetName | CC8: DBC.MA.MAM_PROC_UPRI_ | CD8: TargetName | CE8: DBC.MA.MAM_PROV_UPRI_ | CF8: TargetName | CG8: DBC.MA.MAM_PURC_UPRI_ | CH8: TargetName | CI8: DBC.MA.MAM_STD_SLS_UPRI_ | CJ8: TargetName | CK8: DBC.MA.MAM_ITM_SLS_UPRI_ | CL8: TargetName | CM8: DBC.MA.MAM_CST_SLS_UPRI_ | CN8: TargetName | CO8: DBC.MA.MAM_SET_ITM | CP8: TargetName | CQ8: DBC.MA.MAM_SET_ITM | CR8: TargetName | CS8: DBC.MA.MAM_IF_X | CT8: TargetName | CU8: DBC.MA.MAM_CTG_CONFIG | CV8: TargetName | CW8: DBC.MA.MAM_JNL_PTN | CX8: TargetName | CY8: DBC.MA.MAM_COEF_CONFIG | CZ8: TargetName | DA8: DBC.MA.MAM_ALC_EXPNS | DB8: TargetName | DC8: DBC.MA.MAM_ALC_INPT | DD8: TargetName | DE8: DBC.MA.MAM_COST_ITM_OUT | DF8: TargetName | DG8: DBC.MA.MAM_XPNS_PURC_ALC | DH8: TargetName | DI8: DBC.MA.MAM_ITM_LG_GRP | DJ8: TargetName | DK8: DBC.MA.MAM_ITM_STR_LN | DN8: ブロック備考 Block Remarks
A9: # | D9: 項目名 Field Name | E9: 型 Type | F9: 桁 Digits | G9: フルネーム Full Name | H9: 日本語名 Japanese Name | I9: 上り項目 Request Message Field | J9: 下り項目 Response Message Field | DL9: 条件および編集方法 Conditions and Editing Methods | DN9: 項目備考 Field Remarks
A10: # | L10: 上り項目 Request Message Field | M10: 下り項目 Response Message Field | N10: 上り項目 Request Message Field | O10: 下り項目 Response Message Field | P10: 上り項目 Request Message Field | Q10: 下り項目 Response Message Field | R10: 上り項目 Request Message Field | S10: 下り項目 Response Message Field | T10: 上り項目 Request Message Field | U10: 下り項目 Response Message Field | V10: 上り項目 Request Message Field | W10: 下り項目 Response Message Field | X10: 上り項目 Request Message Field | Y10: 下り項目 Response Message Field | Z10: 上り項目 Request Message Field | AA10: 下り項目 Response Message Field | AB10: 上り項目 Request Message Field | AC10: 下り項目 Response Message Field | AD10: 上り項目 Request Message Field | AE10: 下り項目 Response Message Field | AF10: 上り項目 Request Message Field | AG10: 下り項目 Response Message Field | AH10: 上り項目 Request Message Field | AI10: 下り項目 Response Message Field | AJ10: 上り項目 Request Message Field | AK10: 下り項目 Response Message Field | AL10: 上り項目 Request Message Field | AM10: 下り項目 Response Message Field | AN10: 上り項目 Request Message Field | AO10: 下り項目 Response Message Field | AP10: 上り項目 Request Message Field | AQ10: 下り項目 Response Message Field | AR10: 上り項目 Request Message Field | AS10: 下り項目 Response Message Field | AT10: 上り項目 Request Message Field | AU10: 下り項目 Response Message Field | AV10: 上り項目 Request Message Field | AW10: 下り項目 Response Message Field | AX10: 上り項目 Request Message Field | AY10: 下り項目 Response Message Field | AZ10: 上り項目 Request Message Field | BA10: 下り項目 Response Message Field | BB10: 上り項目 Request Message Field | BC10: 下り項目 Response Message Field | BD10: 上り項目 Request Message Field | BE10: 下り項目 Response Message Field | BF10: 上り項目 Request Message Field | BG10: 下り項目 Response Message Field | BH10: 上り項目 Request Message Field | BI10: 下り項目 Response Message Field | BJ10: 上り項目 Request Message Field | BK10: 下り項目 Response Message Field | BL10: 上り項目 Request Message Field | BM10: 下り項目 Response Message Field | BN10: 上り項目 Request Message Field | BO10: 下り項目 Response Message Field | BP10: 上り項目 Request Message Field | BQ10: 下り項目 Response Message Field | BR10: 上り項目 Request Message Field | BS10: 下り項目 Response Message Field | BT10: 上り項目 Request Message Field | BU10: 下り項目 Response Message Field | BV10: 上り項目 Request Message Field | BW10: 下り項目 Response Message Field | BX10: 上り項目 Request Message Field | BY10: 下り項目 Response Message Field | BZ10: 上り項目 Request Message Field | CA10: 下り項目 Response Message Field | CB10: 上り項目 Request Message Field | CC10: 下り項目 Response Message Field | CD10: 上り項目 Request Message Field | CE10: 下り項目 Response Message Field | CF10: 上り項目 Request Message Field | CG10: 下り項目 Response Message Field | CH10: 上り項目 Request Message Field | CI10: 下り項目 Response Message Field | CJ10: 上り項目 Request Message Field | CK10: 下り項目 Response Message Field | CL10: 上り項目 Request Message Field | CM10: 下り項目 Response Message Field | CN10: 上り項目 Request Message Field | CO10: 下り項目 Response Message Field | CP10: 上り項目 Request Message Field | CQ10: 下り項目 Response Message Field | CR10: 上り項目 Request Message Field | CS10: 下り項目 Response Message Field | CT10: 上り項目 Request Message Field | CU10: 下り項目 Response Message Field | CV10: 上り項目 Request Message Field | CW10: 下り項目 Response Message Field | CX10: 上り項目 Request Message Field | CY10: 下り項目 Response Message Field | CZ10: 上り項目 Request Message Field | DA10: 下り項目 Response Message Field | DB10: 上り項目 Request Message Field | DC10: 下り項目 Response Message Field | DD10: 上り項目 Request Message Field | DE10: 下り項目 Response Message Field | DF10: 上り項目 Request Message Field | DG10: 下り項目 Response Message Field | DH10: 上り項目 Request Message Field | DI10: 下り項目 Response Message Field | DJ10: 上り項目 Request Message Field | DK10: 下り項目 Response Message Field
A11: 10 | B11: * | D11: Srch02_Cnd | E11: R | G11: $share$ | H11: MA.MABCL0870.Srch01.Srch01_Cnd
A12: 10 | D12: ope | E12: C | G12: Operation type | H12: 操作種別 | I12: E
A13: 10 | D13: st_dt_fr | E13: #MA.DT | G13: Application start date FROM | H13: 適用開始日ＦＲＯＭ | I13: E
A14: 10 | D14: st_dt_to | E14: #MA.DT | G14: Application start date TO | H14: 適用開始日ＴＯ | I14: E
A15: 10 | D15: end_dt_fr | E15: #MA.DT | G15: Application end date FROM | H15: 適用終了日ＦＲＯＭ | I15: E
A16: 10 | D16: end_dt_to | E16: #MA.DT | G16: Application end date TO | H16: 適用終了日ＴＯ | I16: E
A17: 10 | D17: itm_cd | E17: #MA.ITM_CD | G17: Item cd. | H17: 品目ＣＤ | I17: E
A18: 10 | D18: itm_sub1 | E18: #MA.ITM_SUB1 | G18: Branch No. 1 | H18: 枝番１ | I18: E
A19: 10 | D19: itm_sub2 | E19: #MA.ITM_SUB2 | G19: Branch No. 2 | H19: 枝番２ | I19: E
A20: 10 | D20: itm_sub3 | E20: #MA.ITM_SUB3 | G20: Branch No. 3 | H20: 枝番３ | I20: E
A21: 10 | D21: itm_nm | E21: #MA.ITM_NM | G21: Item name | H21: 品名 | I21: E
A22: 10 | D22: itm_typ | E22: #MA.ITM_TYP | G22: Item type | H22: 品目区分 | I22: E
A23: 10 | D23: itm_typ_d_cd | E23: #MA.ITM_TYP_D_CD | G23: Item type details cd. | H23: 品目区分詳細ＣＤ | I23: E
... A60: 10 | D60: itm_grp_nm10 | E60: #MA.ITM_GRP_NM | G60: Item classification name 10 | H60: 品目分類名１０ | I60: E
A62: 20 | B62: * | D62: Srch02_Rslt | E62: L | M62: L
A63: 20 | D63: ref_del_flg | E63: #MA.FLG | G63: Reference item logical delete | H63: 参照品目論理削除 | J63: E | M63: E
A64: 20 | D64: ref_itm_cd | E64: #MA.ITM_CD | G64: Reference item cd. | H64: 参照品目ＣＤ | J64: E | M64: E
A65: 20 | D65: ref_itm_sub1 | E65: #MA.ITM_SUB1 | G65: Reference branch No. 1 | H65: 参照枝番１ | J65: E | M65: E
A66: 20 | D66: ref_itm_sub2 | E66: #MA.ITM_SUB2 | G66: Reference branch No. 2 | H66: 参照枝番２ | J66: E | M66: E
A67: 20 | D67: ref_itm_sub3 | E67: #MA.ITM_SUB3 | G67: Reference branch No. 3 | H67: 参照枝番３ | J67: E | M67: E
A68: 20 | D68: ref_itm_nm | E68: #MA.ITM_NM | G68: Reference item name | H68: 参照品名 | J68: E | M68: E
A69: 20 | D69: ref_base_itm_nm | E69: #MA.ITM_NM | G69: Reference standard item name | H69: 参照標準品名 | J69: E | M69: E
A70: 20 | D70: ref_itm_typ | E70: #MA.ITM_TYP | G70: Reference item type | H70: 参照品目区分 | J70: E | K70: MAC_ITM_TYP | M70: E
A71: 20 | D71: ref_itm_typ_nm | E71: #MA.ITM_TYP_NM | G71: Reference item type name | H71: 参照品目区分名 | J71: E
A72: 20 | D72: ref_itm_typ_d_cd | E72: #MA.ITM_TYP_D_CD | G72: Reference item type details cd. | H72: 参照品目区分詳細ＣＤ | J72: E | M72: E
A73: 20 | D73: ref_itm_typ_d_nm | E73: #MA.ITM_TYP_D_NM | G73: Reference item type details name | H73: 参照品目区分詳細名 | J73: E | M73: E
A74: 20 | D74: itm_cd | E74: #MA.ITM_CD | G74: Item cd. | H74: 品目ＣＤ | J74: E | M74: E
A75: 20 | D75: itm_sub1 | E75: #MA.ITM_SUB1 | G75: Branch No. 1 | H75: 枝番１ | J75: E | M75: E
A76: 20 | D76: itm_sub2 | E76: #MA.ITM_SUB2 | G76: Branch No. 2 | H76: 枝番２ | J76: E | M76: E
A77: 20 | D77: itm_sub3 | E77: #MA.ITM_SUB3 | G77: Branch No. 3 | H77: 枝番３ | J77: E | M77: E
...

Sheet Upd01
A1: * | B1: * | D1: L | E1: 1
A2: * | D2: オペレーション実装仕様書 Operation Specification Implementation Sheet | E2: ModuleID : | F2: =IF(LogicCommon!C2="","",LogicCommon!C2) -> MA | G2: LogicID : | H2: =IF(LogicCommon!E2="","",LogicCommon!E2) -> MABCL0870 | I2: Ope.ID : | J2: Upd01 | K2: Pj.ID : | L2: =IF(LogicCommon!G2="","",LogicCommon!G2) -> MC | M2: Ope.Body : | N2: "mcframe.serverMAUD.MAUDL6010.MAUDL_RLUpdater"
A3: * | D3: =IF(LogicCommon!A3="","",LogicCommon!A3) | E3: SubModuleID : | F3: =IF(LogicCommon!C3="","",LogicCommon!C3) -> MABC | G3: LogicClass : | H3: =IF(LogicCommon!E3="","",LogicCommon!E3) -> MABCL_ItmCopyReg | I3: Ope.Method : | J3: @ | K3: SuperClassPj.ID : | L3: =IF(LogicCommon!G3="","",LogicCommon!G3) | M3: ReportID : | O3: Gene.Type : | P3: ALL
A4: * | E4: Version : | F4: 000000 | G4: LogicName : | H4: =IF(LogicCommon!E4="","",LogicCommon!E4) -> 品目系マスタ確認＆コピー | I4: Ope.Name : | J4: 登録 | K4: SuperLogicID : | L4: =IF(LogicCommon!G4="","",LogicCommon!G4) -> MA.MAUDL5010
A5: * | E5: ACType :
A6: * | D6: 概要 : | E6: 品目系マスタのコピー登録を行います。（マスタ画面用） | L6: ID | N6: ID | P6: ID | R6: ID | T6: ID
A7: # | I7: U | K7: o | L7: CALL_OPE01.chk01 | M7: o | N7: CALL_OPE01.upd01 | O7: o | Q7: o | S7: o
A8: # | D8: ブロック名 Block Name | E8: 型 Type | G8: super/share | H8: 対象ブロック名 Target Block Name | K8: TargetName | L8: OPE.MA.MABCL0870.ItmCopy_UpdChk01 | M8: TargetName | N8: OPE.MA.MABCL0870.ItmCopy_Upd01 | O8: TargetName | Q8: TargetName | S8: TargetName | W8: ブロック備考 Block Remarks
A9: # | D9: 項目名 Field Name | E9: 型 Type | F9: 桁 Digits | G9: フルネーム Full Name | H9: 日本語名 Japanese Name | I9: 上り項目 Request Message Field | J9: 下り項目 Response Message Field | U9: 条件および編集方法 Conditions and Editing Methods | W9: 項目備考 Field Remarks
A10: # | K10: 上り項目 Request Message Field | L10: 下り項目 Response Message Field | M10: 上り項目 Request Message Field | N10: 下り項目 Response Message Field | O10: 上り項目 Request Message Field | P10: 下り項目 Response Message Field | Q10: 上り項目 Request Message Field | R10: 下り項目 Response Message Field | S10: 上り項目 Request Message Field | T10: 下り項目 Response Message Field
A11: 10 | B11: * | D11: Upd01_Dtl | E11: L | G11: $share$ | H11: MA.MABCL0870.ItmCopy_Upd01.ItmCopy_Upd01_Dtl | K11: ItmCopy_UpdChk01_Dtl | M11: ItmCopy_Upd01_Dtl
A12: 10 | D12: itm_cd | E12: #MA.ITM_CD | G12: Item cd. | H12: 品目ＣＤ | I12: E | K12: E | M12: E
A13: 10 | D13: itm_sub1 | E13: #MA.ITM_SUB1 | G13: Branch No. 1 | H13: 枝番１ | I13: E | K13: E | M13: E
A14: 10 | D14: itm_sub2 | E14: #MA.ITM_SUB2 | G14: Branch No. 2 | H14: 枝番２ | I14: E | K14: E | M14: E
A15: 10 | D15: itm_sub3 | E15: #MA.ITM_SUB3 | G15: Branch No. 3 | H15: 枝番３ | I15: E | K15: E | M15: E
A16: 10 | D16: dest_itm_cd | E16: #MA.ITM_CD | G16: (Copy-to) Item cd. | H16: （コピー先）品目ＣＤ | I16: E | K16: E | M16: E
A17: 10 | D17: dest_itm_sub1 | E17: #MA.ITM_SUB1 | G17: (Copy-to) Branch No. 1 | H17: （コピー先）枝番１ | I17: E | K17: E | M17: E
A18: 10 | D18: dest_itm_sub2 | E18: #MA.ITM_SUB2 | G18: (Copy-to) Branch No. 2 | H18: （コピー先）枝番２ | I18: E | K18: E | M18: E
A19: 10 | D19: dest_itm_sub3 | E19: #MA.ITM_SUB3 | G19: (Copy-to) Branch No. 3 | H19: （コピー先）枝番３ | I19: E | K19: E | M19: E
A20: 10 | D20: dest_itm_nm | E20: #MA.ITM_NM | G20: (Copy-to) Item name | H20: （コピー先）品名 | I20: E | K20: E | M20: E
A21: 10 | D21: memo1 | E21: #MA.MST_MEMO1 | G21: Memo 1 | H21: メモ１ | I21: E | K21: E | M21: E
A22: 10 | D22: memo2 | E22: #MA.MST_MEMO2 | G22: Memo 2 | H22: メモ２ | I22: E | K22: E | M22: E
A23: 10 | D23: memo3 | E23: #MA.MST_MEMO3 | G23: Memo 3 | H23: メモ３ | I23: E | K23: E | M23: E
... A75: 10 | D75: itm_str_ln_flg | E75: #MA.FLG | G75: Item rack/line | H75: 品目棚・ライン | I75: E | K75: E | M75: E
K76: 上り項目 Request Message Field | L76: 下り項目 Response Message Field | M76: 上り項目 Request Message Field | N76: 下り項目 Response Message Field | O76: 上り項目 Request Message Field | P76: 下り項目 Response Message Field | Q76: 上り項目 Request Message Field | R76: 下り項目 Response Message Field | S76: 上り項目 Request Message Field | T76: 下り項目 Response Message Field
A77: 20 | B77: * | D77: Upd01_Cnd | E77: R | G77: $share$ | H77: MA.MABCL0870.ItmCopy_Upd01.ItmCopy_Upd01_Cnd | K77: ItmCopy_UpdChk01_Cnd | M77: ItmCopy_Upd01_Cnd
A78: 20 | D78: ex_on_del_flg | E78: #MA.FLG | G78: Exclude logically deleted data | H78: 論理削除がオンは除く | I78: E | K78: E | M78: E
A79: 20 | D79: ex_past_end_dt | E79: #MA.DT | G79: Exclude data with past application end dates | H79: 過去の適用終了日は除く | I79: E | K79: E | M79: E
D80: 詳細 :

Sheet Del01
A1: * | B1: * | D1: L | E1: 1
A2: * | D2: オペレーション実装仕様書 Operation Specification Implementation Sheet | E2: ModuleID : | F2: =IF(LogicCommon!C2="","",LogicCommon!C2) -> MA | G2: LogicID : | H2: =IF(LogicCommon!E2="","",LogicCommon!E2) -> MABCL0870 | I2: Ope.ID : | J2: Del01 | K2: Pj.ID : | L2: =IF(LogicCommon!G2="","",LogicCommon!G2) -> MC | M2: Ope.Body : | N2: "mcframe.serverMAUD.MAUDL6010.MAUDL_RLDeleter"
A3: * | D3: =IF(LogicCommon!A3="","",LogicCommon!A3) | E3: SubModuleID : | F3: =IF(LogicCommon!C3="","",LogicCommon!C3) -> MABC | G3: LogicClass : | H3: =IF(LogicCommon!E3="","",LogicCommon!E3) -> MABCL_ItmCopyReg | I3: Ope.Method : | J3: @ | K3: SuperClassPj.ID : | L3: =IF(LogicCommon!G3="","",LogicCommon!G3) | M3: ReportID : | O3: Gene.Type : | P3: ALL
A4: * | E4: Version : | F4: 000000 | G4: LogicName : | H4: =IF(LogicCommon!E4="","",LogicCommon!E4) -> 品目系マスタ確認＆コピー | I4: Ope.Name : | J4: 削除 | K4: SuperLogicID : | L4: =IF(LogicCommon!G4="","",LogicCommon!G4) -> MA.MAUDL5010
A5: * | E5: ACType :
A6: * | D6: 概要 : | E6: 品目系マスタの削除を行います。（マスタ画面用） | L6: ID | N6: ID | P6: ID | R6: ID
A7: # | I7: U | K7: o | L7: CALL_OPE01.chk01 | M7: o | N7: CALL_OPE01.del01 | O7: o | Q7: o
A8: # | D8: ブロック名 Block Name | E8: 型 Type | G8: super/share | H8: 対象ブロック名 Target Block Name | K8: TargetName | L8: OPE.MA.MABCL0870.ItmCopy_DelChk01 | M8: TargetName | N8: OPE.MA.MABCL0870.ItmCopy_Del01 | O8: TargetName | Q8: TargetName | U8: ブロック備考 Block Remarks
A9: # | D9: 項目名 Field Name | E9: 型 Type | F9: 桁 Digits | G9: フルネーム Full Name | H9: 日本語名 Japanese Name | I9: 上り項目 Request Message Field | J9: 下り項目 Response Message Field | S9: 条件および編集方法 Conditions and Editing Methods | U9: 項目備考 Field Remarks
A10: # | K10: 上り項目 Request Message Field | L10: 下り項目 Response Message Field | M10: 上り項目 Request Message Field | N10: 下り項目 Response Message Field
A11: 10 | B11: * | D11: Del01_Dtl | E11: L | G11: $share$ | H11: MA.MABCL0870.ItmCopy_Del01.ItmCopy_Del01_Dtl | K11: ItmCopy_DelChk01_Dtl | M11: ItmCopy_Del01_Dtl
A12: 10 | D12: itm_cd | E12: #MA.ITM_CD | G12: Item cd. | H12: 品目ＣＤ | I12: E | K12: E | M12: E
A13: 10 | D13: itm_sub1 | E13: #MA.ITM_SUB1 | G13: Branch No. 1 | H13: 枝番１ | I13: E | K13: E | M13: E
A14: 10 | D14: itm_sub2 | E14: #MA.ITM_SUB2 | G14: Branch No. 2 | H14: 枝番２ | I14: E | K14: E | M14: E
A15: 10 | D15: itm_sub3 | E15: #MA.ITM_SUB3 | G15: Branch No. 3 | H15: 枝番３ | I15: E | K15: E | M15: E
A17: 10 | D17: itm_flg | E17: #MA.FLG | G17: Item | H17: 品目 | I17: E | K17: E | M17: E
A18: 10 | D18: itm_sub_flg | E18: #MA.FLG | G18: Item auxiliary | H18: 品目補助 | I18: E | K18: E | M18: E
A19: 10 | D19: itm_unit_flg | E19: #MA.FLG | G19: Item unit | H19: 品目単位 | I19: E | K19: E | M19: E
A20: 10 | D20: attach_info_flg | E20: #MA.FLG | G20: Item additional info. | H20: 品目付加情報 | I20: E | K20: E | M20: E
A21: 10 | D21: itm_stop_flg | E21: #MA.FLG | G21: Item prohibit | H21: 品目禁止 | I21: E | K21: E | M21: E
A22: 10 | D22: itm_not_fix_flg | E22: #MA.FLG | G22: Item procurement disapproval | H22: 品目手配不許可 | I22: E | K22: E | M22: E
A23: 10 | D23: stdcost_flg | E23: #MA.FLG | G23: Standard unit cost | H23: 標準単価 | I23: E | K23: E | M23: E
A24: 10 | D24: sundry_itm_flg | E24: #MA.FLG | G24: Miscellaneous item | H24: 諸口品 | I24: E | K24: E | M24: E
... A67: 10 | D67: itm_str_ln_flg | E67: #MA.FLG | G67: Item rack/line | H67: 品目棚・ライン | I67: E | K67: E | M67: E
D68: 詳細 :

Sheet 来歴
A1: 変更来歴
A3: Rev. | H3: 修正番号 | O3: 変更内容 | AQ3: 変更箇所
A4: 1 | O4: 初版
A5: 1.1 | O5: 英語の名称を追記 | AQ5: 全般
