Workbook

Sheet LogicCommon
A2: ロジック共通定義 | B2: ModuleID : | C2: MA | D2: LogicID : | E2: MABCL0030 | F2: Pj.ID : | G2: MC
B3: SubModuleID : | C3: MABC | D3: LogicClass : | E3: MABCL_MultiReg | F3: SuperClassPj.ID :
D4: LogicName : | E4: マルチマスタ登録 | F4: SuperLogicID : | G4: MA.MAUDL5010
A5: 概要 :
A6: 詳細 :
B7: MABCL0031 | C7: データアクセス基本マスタ
C8: 部門基本マスタ
C9: 部門階層マスタ
C10: 承認役割マスタ
C11: 国マスタ
C12: 地域マスタ
C13: 通貨マスタ
C14: 単位マスタ
C15: 銀行マスタ
C16: 銀行支店マスタ
B18: MABCL0032 | C18: 口座マスタ
C19: 為替レート基本マスタ
C20: カレンダ基本マスタ
C21: 品目仕訳マスタ
C22: 会計品目分類マスタ
C23: 会計理由マスタ
C24: 工場・物流倉庫マスタ
C25: 製造場所グループマスタ
C26: 物流グループマスタ
C27: 総量引当場所グループマスタ
B29: MABCL0033 | C29: ワーキンググループマスタ
C30: 工程マスタ
C31: 工数管理マスタ
C32: 工数理由マスタ
C33: 販売単価分類マスタ
C34: 販売単価ランクマスタ
C35: 相殺グループマスタ
C36: 出荷有効期限グループマスタ
C37: 品目出荷グループマスタ
C38: 輸送方法マスタ
B40: MABCL0034 | C40: 梱包容器マスタ
C41: 港マスタ
C42: 格付マスタ
C43: 取引マスタ
C44: 伝票帳票マスタ
...

Sheet Srch01
A1: * | B1: * | D1: L | E1: 1
A2: * | D2: オペレーション実装仕様書 Operation Specification Implementation Sheet | E2: ModuleID : | F2: =IF(LogicCommon!C2="","",LogicCommon!C2) -> MA | G2: LogicID : | H2: =IF(LogicCommon!E2="","",LogicCommon!E2) -> MABCL0030 | I2: Ope.ID : | J2: Srch01 | K2: Pj.ID : | L2: =IF(LogicCommon!G2="","",LogicCommon!G2) -> MC | M2: Ope.Body : | N2: "mcframe.serverMAUD.MAUDL6020.MAUDL_LCLRLSearcher"
A3: * | D3: =IF(LogicCommon!A3="","",LogicCommon!A3) | E3: SubModuleID : | F3: =IF(LogicCommon!C3="","",LogicCommon!C3) -> MABC | G3: LogicClass : | H3: =IF(LogicCommon!E3="","",LogicCommon!E3) -> MABCL_MultiReg | I3: Ope.Method : | J3: @ | K3: SuperClassPj.ID : | L3: =IF(LogicCommon!G3="","",LogicCommon!G3) | M3: ReportID : | O3: Gene.Type : | P3: ALL
A4: * | E4: Version : | F4: 000000 | G4: LogicName : | H4: =IF(LogicCommon!E4="","",LogicCommon!E4) -> マルチマスタ登録 | I4: Ope.Name : | J4: 検索 | K4: SuperLogicID : | L4: =IF(LogicCommon!G4="","",LogicCommon!G4) -> MA.MAUDL5010
A5: * | E5: ACType : | L5: 0 | N5: 1 | P5: 2 | R5: 3 | T5: 4 | V5: 5 | X5: 6 | Z5: 7 | AB5: 8 | AD5: 9 | AF5: 10 | AH5: 11 | AJ5: 12 | AL5: 13 | AN5: 14 | AP5: 15 | AR5: 16 | AT5: 17 | AV5: 18 | AX5: 19 | AZ5: 20 | BB5: 21 | BD5: 22 | BF5: 23 | BH5: 24 | BJ5: 25 | BL5: 26 | BN5: 27 | BP5: 28 | BR5: 29 | BT5: 30 | BV5: 31 | BX5: 32 | BZ5: 33 | CB5: 34 | CD5: 35 | CF5: 36 | CH5: 37 | CJ5: 38 | CL5: 39 | CN5: 40 | CP5: 41 | CR5: 42 | CT5: 43 | CV5: 44 | CX5: 45 | CZ5: 46 | DB5: 47 | DD5: 48 | DF5: 49 | DH5: 50 | DJ5: 51 | DL5: 52 | DN5: 53 | DP5: 54 | DR5: 55 | DT5: 56 | DV5: 57 | DX5: 58 | DZ5: 59 | EB5: 60 | ED5: 61 | EF5: 62 | EH5: 63 | EJ5: 64 | EL5: 65 | EN5: 66 | EP5: 67 | ER5: 68 | ET5: 69 | EV5: 70 | EX5: 71 | EZ5: 72 | FB5: 73 | FD5: 74 | FF5: 75 | FH5: 76 | FJ5: 77 | FL5: 78 | FN5: 79 | FP5: 80 | FR5: 81 | FT5: 82 | FV5: 83 | FX5: 84 | FZ5: 85 | GB5: 86 | GD5: 87 | GF5: 88 | GH5: 89 | GJ5: 90 | GL5: 91 | GN5: 92 | GP5: 93 | GR5: 94 | GT5: 95 | GV5: 96 | GX5: 97 | GZ5: 98 | HB5: 99 | HD5: 100 | HF5: 101 | HH5: 102 | HJ5: 103 | HL5: 104 | HN5: 105 | HP5: 106 | HR5: 107 | HT5: 108 | HV5: 109 | HX5: 110 | HZ5: 111
A6: * | D6: 概要 : | E6: 複数のマスタ、名称マスタの検索を行います。 | L6: DA | M6: ID | O6: ID | P6: DPT_BASE | Q6: ID | S6: ID | T6: DPT_LVL | U6: ID | W6: ID | X6: APRV_ROLE | Y6: ID | AA6: ID | AB6: CNTRY | AC6: ID | AE6: ID | AF6: AREA | AG6: ID | AI6: ID | AJ6: CUR | AK6: ID | AM6: ID | AN6: UNIT | AO6: ID | AQ6: ID | AR6: BANK | AS6: ID | AU6: ID | AV6: BANK_BRANCH | AW6: ID | AY6: ID | AZ6: BANK_AC | BA6: ID | BC6: ID | BD6: XRATE | BE6: ID | BG6: ID | BH6: CAL_BASE | BI6: ID | BK6: ID | BL6: ITM_JNL | BM6: ID | BO6: ID | BP6: AC_ITM_GRP | BQ6: ID | BS6: ID | BT6: AC_RSN | BU6: ID | BW6: ID | BX6: SITE | BY6: ID | CA6: ID | CB6: LOC_GRP | CC6: ID | CE6: ID | CF6: LG_GRP | CG6: ID | CI6: ID | CJ6: ALLOC_GRP | CK6: ID | CM6: ID | CN6: WG | CO6: ID | CQ6: ID | CR6: OPER | CS6: ID | CU6: ID | CV6: WK_COST | CW6: ID | CY6: ID | CZ6: WK_RSN | DA6: ID | DC6: ID | DD6: SLS_UPRI_GRP | DE6: ID | DG6: ID | DH6: SLS_UPRI_RANK | DI6: ID | DK6: ID | DL6: SETOFF_GRP | DM6: ID | DO6: ID | DP6: SHIP_VALID | DQ6: ID | DS6: ID | DT6: ITM_SHIP_GRP | DU6: ID | DW6: ID | DX6: TRNSPT | DY6: ID | EA6: ID | EB6: EX_CNTNR | EC6: ID | EE6: ID | EF6: EXIM_PORT | EG6: ID | EI6: ID | EJ6: STK_GD | EK6: ID | EM6: ID | EN6: TRD | EO6: ID | EQ6: ID | ER6: SLIP_FORM | ES6: ID | EU6: ID | EV6: PF_GRP | EW6: ID | EY6: ID | EZ6: ITM_SPEC_GRP | FA6: ID | FC6: ID | FD6: ITM_COMP_GRP | FE6: ID | FG6: ID | FH6: JNL_ACT | FI6: ID | FK6: ID | FL6: JNL_GRP | FM6: ID | FO6: ID | FP6: JNL_PTN_BASE | FQ6: ID | FS6: ID | FT6: AUTO_JNL_KEY | FU6: ID | FW6: ID | FX6: INSP_PTN | FY6: ID | GA6: ID | GB6: WK_DAY | GC6: ID | GE6: ID | GF6: SHIP_TERM | GG6: ID | GI6: ID | GJ6: SHIP_WK | GK6: ID | GM6: ID | GN6: RSRC | GO6: ID | GQ6: ID | GR6: HS_GRP | GS6: ID | GU6: ID | GV6: ALC_PTN | GW6: ID | GY6: ID | GZ6: CTG_GRP | HA6: ID | HC6: ID | HD6: ACT_PTN | HE6: ID | HG6: ID | HH6: GP_ALC | HI6: ID | HK6: ID | HL6: CALC_CTG | HM6: ID | HO6: ID | HP6: RPT_PTN | HQ6: ID | HS6: ID | HT6: COST_MENU | HU6: ID | HW6: ID | HX6: SITE_CO | HY6: ID | IA6: ID
A7: # | I7: U | K7: K | L7: o | M7: =L6&".c"&L5 -> DA.c0 | N7: o | O7: =L6&"_LCL.c"&N5 -> DA_LCL.c1 | P7: o | Q7: =P6&".c"&P5 -> DPT_BASE.c2 | R7: o | S7: =P6&"_LCL.c"&R5 -> DPT_BASE_LCL.c3 | T7: o | U7: =T6&".c"&T5 -> DPT_LVL.c4 | V7: o | W7: =T6&"_LCL.c"&V5 -> DPT_LVL_LCL.c5 | X7: o | Y7: =X6&".c"&X5 -> APRV_ROLE.c6 | Z7: o | AA7: =X6&"_LCL.c"&Z5 -> APRV_ROLE_LCL.c7 | AB7: o | AC7: =AB6&".c"&AB5 -> CNTRY.c8 | AD7: o | AE7: =AB6&"_LCL.c"&AD5 -> CNTRY_LCL.c9 | AF7: o | AG7: =AF6&".c"&AF5 -> AREA.c10 | AH7: o | AI7: =AF6&"_LCL.c"&AH5 -> AREA_LCL.c11 | AJ7: o | AK7: =AJ6&".c"&AJ5 -> CUR.c12 | AL7: o | AM7: =AJ6&"_LCL.c"&AL5 -> CUR_LCL.c13 | AN7: o | AO7: =AN6&".c"&AN5 -> UNIT.c14 | AP7: o | AQ7: =AN6&"_LCL.c"&AP5 -> UNIT_LCL.c15 | AR7: o | AS7: =AR6&".c"&AR5 -> BANK.c16 | AT7: o | AU7: =AR6&"_LCL.c"&AT5 -> BANK_LCL.c17 | AV7: o | AW7: =AV6&".c"&AV5 -> BANK_BRANCH.c18 | AX7: o | AY7: =AV6&"_LCL.c"&AX5 -> BANK_BRANCH_LCL.c19 | AZ7: o | BA7: =AZ6&".c"&AZ5 -> BANK_AC.c20 | BB7: o | BC7: =AZ6&"_LCL.c"&BB5 -> BANK_AC_LCL.c21 | BD7: o | BE7: =BD6&".c"&BD5 -> XRATE.c22 | BF7: o | BG7: =BD6&"_LCL.c"&BF5 -> XRATE_LCL.c23 | BH7: o | BI7: =BH6&".c"&BH5 -> CAL_BASE.c24 | BJ7: o | BK7: =BH6&"_LCL.c"&BJ5 -> CAL_BASE_LCL.c25 | BL7: o | BM7: =BL6&".c"&BL5 -> ITM_JNL.c26 | BN7: o | BO7: =BL6&"_LCL.c"&BN5 -> ITM_JNL_LCL.c27 | BP7: o | BQ7: =BP6&".c"&BP5 -> AC_ITM_GRP.c28 | BR7: o | BS7: =BP6&"_LCL.c"&BR5 -> AC_ITM_GRP_LCL.c29 | BT7: o | BU7: =BT6&".c"&BT5 -> AC_RSN.c30 | BV7: o | BW7: =BT6&"_LCL.c"&BV5 -> AC_RSN_LCL.c31 | BX7: o | BY7: =BX6&".c"&BX5 -> SITE.c32 | BZ7: o | CA7: =BX6&"_LCL.c"&BZ5 -> SITE_LCL.c33 | CB7: o | CC7: =CB6&".c"&CB5 -> LOC_GRP.c34 | CD7: o | CE7: =CB6&"_LCL.c"&CD5 -> LOC_GRP_LCL.c35 | CF7: o | CG7: =CF6&".c"&CF5 -> LG_GRP.c36 | CH7: o | CI7: =CF6&"_LCL.c"&CH5 -> LG_GRP_LCL.c37 | CJ7: o | CK7: =CJ6&".c"&CJ5 -> ALLOC_GRP.c38 | CL7: o | CM7: =CJ6&"_LCL.c"&CL5 -> ALLOC_GRP_LCL.c39 | CN7: o | CO7: =CN6&".c"&CN5 -> WG.c40 | CP7: o | CQ7: =CN6&"_LCL.c"&CP5 -> WG_LCL.c41 | CR7: o | CS7: =CR6&".c"&CR5 -> OPER.c42 | CT7: o | CU7: =CR6&"_LCL.c"&CT5 -> OPER_LCL.c43 | CV7: o | CW7: =CV6&".c"&CV5 -> WK_COST.c44 | CX7: o | CY7: =CV6&"_LCL.c"&CX5 -> WK_COST_LCL.c45 | CZ7: o | DA7: =CZ6&".c"&CZ5 -> WK_RSN.c46 | DB7: o | DC7: =CZ6&"_LCL.c"&DB5 -> WK_RSN_LCL.c47 | DD7: o | DE7: =DD6&".c"&DD5 -> SLS_UPRI_GRP.c48 | DF7: o | DG7: =DD6&"_LCL.c"&DF5 -> SLS_UPRI_GRP_LCL.c49 | DH7: o | DI7: =DH6&".c"&DH5 -> SLS_UPRI_RANK.c50 | DJ7: o | DK7: =DH6&"_LCL.c"&DJ5 -> SLS_UPRI_RANK_LCL.c51 | DL7: o | DM7: =DL6&".c"&DL5 -> SETOFF_GRP.c52 | DN7: o | DO7: =DL6&"_LCL.c"&DN5 -> SETOFF_GRP_LCL.c53 | DP7: o | DQ7: =DP6&".c"&DP5 -> SHIP_VALID.c54 | DR7: o | DS7: =DP6&"_LCL.c"&DR5 -> SHIP_VALID_LCL.c55 | DT7: o | DU7: =DT6&".c"&DT5 -> ITM_SHIP_GRP.c56 | DV7: o | DW7: =DT6&"_LCL.c"&DV5 -> ITM_SHIP_GRP_LCL.c57 | DX7: o | DY7: =DX6&".c"&DX5 -> TRNSPT.c58 | DZ7: o | EA7: =DX6&"_LCL.c"&DZ5 -> TRNSPT_LCL.c59 | EB7: o | EC7: =EB6&".c"&EB5 -> EX_CNTNR.c60 | ED7: o | EE7: =EB6&"_LCL.c"&ED5 -> EX_CNTNR_LCL.c61 | EF7: o | EG7: =EF6&".c"&EF5 -> EXIM_PORT.c62 | EH7: o | EI7: =EF6&"_LCL.c"&EH5 -> EXIM_PORT_LCL.c63 | EJ7: o | EK7: =EJ6&".c"&EJ5 -> STK_GD.c64 | EL7: o | EM7: =EJ6&"_LCL.c"&EL5 -> STK_GD_LCL.c65 | EN7: o | EO7: =EN6&".c"&EN5 -> TRD.c66 | EP7: o | EQ7: =EN6&"_LCL.c"&EP5 -> TRD_LCL.c67 | ER7: o | ES7: =ER6&".c"&ER5 -> SLIP_FORM.c68 | ET7: o | EU7: =ER6&"_LCL.c"&ET5 -> SLIP_FORM_LCL.c69 | EV7: o | EW7: =EV6&".c"&EV5 -> PF_GRP.c70 | EX7: o | EY7: =EV6&"_LCL.c"&EX5 -> PF_GRP_LCL.c71 | EZ7: o | FA7: =EZ6&".c"&EZ5 -> ITM_SPEC_GRP.c72 | FB7: o | FC7: =EZ6&"_LCL.c"&FB5 -> ITM_SPEC_GRP_LCL.c73 | FD7: o | FE7: =FD6&".c"&FD5 -> ITM_COMP_GRP.c74 | FF7: o | FG7: =FD6&"_LCL.c"&FF5 -> ITM_COMP_GRP_LCL.c75 | FH7: o | FI7: =FH6&".c"&FH5 -> JNL_ACT.c76 | FJ7: o | FK7: =FH6&"_LCL.c"&FJ5 -> JNL_ACT_LCL.c77 | FL7: o | FM7: =FL6&".c"&FL5 -> JNL_GRP.c78 | FN7: o | FO7: =FL6&"_LCL.c"&FN5 -> JNL_GRP_LCL.c79 | FP7: o | FQ7: =FP6&".c"&FP5 -> JNL_PTN_BASE.c80 | FR7: o | FS7: =FP6&"_LCL.c"&FR5 -> JNL_PTN_BASE_LCL.c81 | FT7: o | FU7: =FT6&".c"&FT5 -> AUTO_JNL_KEY.c82 | FV7: o | FW7: =FT6&"_LCL.c"&FV5 -> AUTO_JNL_KEY_LCL.c83 | FX7: o | FY7: =FX6&".c"&FX5 -> INSP_PTN.c84 | FZ7: o | GA7: =FX6&"_LCL.c"&FZ5 -> INSP_PTN_LCL.c85 | GB7: o | GC7: =GB6&".c"&GB5 -> WK_DAY.c86 | GD7: o | GE7: =GB6&"_LCL.c"&GD5 -> WK_DAY_LCL.c87 | GF7: o | GG7: =GF6&".c"&GF5 -> SHIP_TERM.c88 | GH7: o | GI7: =GF6&"_LCL.c"&GH5 -> SHIP_TERM_LCL.c89 | GJ7: o | GK7: =GJ6&".c"&GJ5 -> SHIP_WK.c90 | GL7: o | GM7: =GJ6&"_LCL.c"&GL5 -> SHIP_WK_LCL.c91 | GN7: o | GO7: =GN6&".c"&GN5 -> RSRC.c92 | GP7: o | GQ7: =GN6&"_LCL.c"&GP5 -> RSRC_LCL.c93 | GR7: o | GS7: =GR6&".c"&GR5 -> HS_GRP.c94 | GT7: o | GU7: =GR6&"_LCL.c"&GT5 -> HS_GRP_LCL.c95 | GV7: o | GW7: =GV6&".c"&GV5 -> ALC_PTN.c96 | GX7: o | GY7: =GV6&"_LCL.c"&GX5 -> ALC_PTN_LCL.c97 | GZ7: o | HA7: =GZ6&".c"&GZ5 -> CTG_GRP.c98 | HB7: o | HC7: =GZ6&"_LCL.c"&HB5 -> CTG_GRP_LCL.c99 | HD7: o | HE7: =HD6&".c"&HD5 -> ACT_PTN.c100 | HF7: o | HG7: =HD6&"_LCL.c"&HF5 -> ACT_PTN_LCL.c101 | HH7: o | HI7: =HH6&".c"&HH5 -> GP_ALC.c102 | HJ7: o | HK7: =HH6&"_LCL.c"&HJ5 -> GP_ALC_LCL.c103 | HL7: o | HM7: =HL6&".c"&HL5 -> CALC_CTG.c104 | HN7: o | HO7: =HL6&"_LCL.c"&HN5 -> CALC_CTG_LCL.c105 | HP7: o | HQ7: =HP6&".c"&HP5 -> RPT_PTN.c106 | HR7: o | HS7: =HP6&"_LCL.c"&HR5 -> RPT_PTN_LCL.c107 | HT7: o | HU7: =HT6&".c"&HT5 -> COST_MENU.c108 | HV7: o | HW7: =HT6&"_LCL.c"&HV5 -> COST_MENU_LCL.c109 | HX7: o | HY7: =HX6&".c"&HX5 -> SITE_CO.c110 | HZ7: o | IA7: =HX6&"_LCL.c"&HZ5 -> SITE_CO_LCL.c111
A8: # | D8: ブロック名 Block Name | E8: 型 Type | G8: super/share | H8: 対象ブロック名 Target Block Name | K8: CONST | L8: TargetName | M8: ="DBC.MA.MAM_"&L6 -> DBC.MA.MAM_DA | N8: TargetName | O8: ="DBC.MA.MAM_"&L6&"_LCL" -> DBC.MA.MAM_DA_LCL | P8: TargetName | Q8: ="DBC.MA.MAM_"&P6 -> DBC.MA.MAM_DPT_BASE | R8: TargetName | S8: ="DBC.MA.MAM_"&P6&"_LCL" -> DBC.MA.MAM_DPT_BASE_LCL | T8: TargetName | U8: ="DBC.MA.MAM_"&T6 -> DBC.MA.MAM_DPT_LVL | V8: TargetName | W8: ="DBC.MA.MAM_"&T6&"_LCL" -> DBC.MA.MAM_DPT_LVL_LCL | X8: TargetName | Y8: ="DBC.MA.MAM_"&X6 -> DBC.MA.MAM_APRV_ROLE | Z8: TargetName | AA8: ="DBC.MA.MAM_"&X6&"_LCL" -> DBC.MA.MAM_APRV_ROLE_LCL | AB8: TargetName | AC8: ="DBC.MA.MAM_"&AB6 -> DBC.MA.MAM_CNTRY | AD8: TargetName | AE8: ="DBC.MA.MAM_"&AB6&"_LCL" -> DBC.MA.MAM_CNTRY_LCL | AF8: TargetName | AG8: ="DBC.MA.MAM_"&AF6 -> DBC.MA.MAM_AREA | AH8: TargetName | AI8: ="DBC.MA.MAM_"&AF6&"_LCL" -> DBC.MA.MAM_AREA_LCL | AJ8: TargetName | AK8: ="DBC.MA.MAM_"&AJ6 -> DBC.MA.MAM_CUR | AL8: TargetName | AM8: ="DBC.MA.MAM_"&AJ6&"_LCL" -> DBC.MA.MAM_CUR_LCL | AN8: TargetName | AO8: ="DBC.MA.MAM_"&AN6 -> DBC.MA.MAM_UNIT | AP8: TargetName | AQ8: ="DBC.MA.MAM_"&AN6&"_LCL" -> DBC.MA.MAM_UNIT_LCL | AR8: TargetName | AS8: ="DBC.MA.MAM_"&AR6 -> DBC.MA.MAM_BANK | AT8: TargetName | AU8: ="DBC.MA.MAM_"&AR6&"_LCL" -> DBC.MA.MAM_BANK_LCL | AV8: TargetName | AW8: ="DBC.MA.MAM_"&AV6 -> DBC.MA.MAM_BANK_BRANCH | AX8: TargetName | AY8: ="DBC.MA.MAM_"&AV6&"_LCL" -> DBC.MA.MAM_BANK_BRANCH_LCL | AZ8: TargetName | BA8: ="DBC.MA.MAM_"&AZ6 -> DBC.MA.MAM_BANK_AC | BB8: TargetName | BC8: ="DBC.MA.MAM_"&AZ6&"_LCL" -> DBC.MA.MAM_BANK_AC_LCL | BD8: TargetName | BE8: ="DBC.MA.MAM_"&BD6 -> DBC.MA.MAM_XRATE | BF8: TargetName | BG8: ="DBC.MA.MAM_"&BD6&"_LCL" -> DBC.MA.MAM_XRATE_LCL | BH8: TargetName | BI8: ="DBC.MA.MAM_"&BH6 -> DBC.MA.MAM_CAL_BASE | BJ8: TargetName | BK8: ="DBC.MA.MAM_"&BH6&"_LCL" -> DBC.MA.MAM_CAL_BASE_LCL | BL8: TargetName | BM8: ="DBC.MA.MAM_"&BL6 -> DBC.MA.MAM_ITM_JNL | BN8: TargetName | BO8: ="DBC.MA.MAM_"&BL6&"_LCL" -> DBC.MA.MAM_ITM_JNL_LCL | BP8: TargetName | BQ8: ="DBC.MA.MAM_"&BP6 -> DBC.MA.MAM_AC_ITM_GRP | BR8: TargetName | BS8: ="DBC.MA.MAM_"&BP6&"_LCL" -> DBC.MA.MAM_AC_ITM_GRP_LCL | BT8: TargetName | BU8: ="DBC.MA.MAM_"&BT6 -> DBC.MA.MAM_AC_RSN | BV8: TargetName | BW8: ="DBC.MA.MAM_"&BT6&"_LCL" -> DBC.MA.MAM_AC_RSN_LCL | BX8: TargetName | BY8: ="DBC.MA.MAM_"&BX6 -> DBC.MA.MAM_SITE | BZ8: TargetName | CA8: ="DBC.MA.MAM_"&BX6&"_LCL" -> DBC.MA.MAM_SITE_LCL | CB8: TargetName | CC8: ="DBC.MA.MAM_"&CB6 -> DBC.MA.MAM_LOC_GRP | CD8: TargetName | CE8: ="DBC.MA.MAM_"&CB6&"_LCL" -> DBC.MA.MAM_LOC_GRP_LCL | CF8: TargetName | CG8: ="DBC.MA.MAM_"&CF6 -> DBC.MA.MAM_LG_GRP | CH8: TargetName | CI8: ="DBC.MA.MAM_"&CF6&"_LCL" -> DBC.MA.MAM_LG_GRP_LCL | CJ8: TargetName | CK8: ="DBC.MA.MAM_"&CJ6 -> DBC.MA.MAM_ALLOC_GRP | CL8: TargetName | CM8: ="DBC.MA.MAM_"&CJ6&"_LCL" -> DBC.MA.MAM_ALLOC_GRP_LCL | CN8: TargetName | CO8: ="DBC.MA.MAM_"&CN6 -> DBC.MA.MAM_WG | CP8: TargetName | CQ8: ="DBC.MA.MAM_"&CN6&"_LCL" -> DBC.MA.MAM_WG_LCL | CR8: TargetName | CS8: ="DBC.MA.MAM_"&CR6 -> DBC.MA.MAM_OPER | CT8: TargetName | CU8: ="DBC.MA.MAM_"&CR6&"_LCL" -> DBC.MA.MAM_OPER_LCL | CV8: TargetName | CW8: ="DBC.MA.MAM_"&CV6 -> DBC.MA.MAM_WK_COST | CX8: TargetName | CY8: ="DBC.MA.MAM_"&CV6&"_LCL" -> DBC.MA.MAM_WK_COST_LCL | CZ8: TargetName | DA8: ="DBC.MA.MAM_"&CZ6 -> DBC.MA.MAM_WK_RSN | DB8: TargetName | DC8: ="DBC.MA.MAM_"&CZ6&"_LCL" -> DBC.MA.MAM_WK_RSN_LCL | DD8: TargetName | DE8: ="DBC.MA.MAM_"&DD6 -> DBC.MA.MAM_SLS_UPRI_GRP | DF8: TargetName | DG8: ="DBC.MA.MAM_"&DD6&"_LCL" -> DBC.MA.MAM_SLS_UPRI_GRP_LCL | DH8: TargetName | DI8: ="DBC.MA.MAM_"&DH6 -> DBC.MA.MAM_SLS_UPRI_RANK | DJ8: TargetName | DK8: ="DBC.MA.MAM_"&DH6&"_LCL" -> DBC.MA.MAM_SLS_UPRI_RANK_LCL | DL8: TargetName | DM8: ="DBC.MA.MAM_"&DL6 -> DBC.MA.MAM_SETOFF_GRP | DN8: TargetName | DO8: ="DBC.MA.MAM_"&DL6&"_LCL" -> DBC.MA.MAM_SETOFF_GRP_LCL | DP8: TargetName | DQ8: ="DBC.MA.MAM_"&DP6 -> DBC.MA.MAM_SHIP_VALID | DR8: TargetName | DS8: ="DBC.MA.MAM_"&DP6&"_LCL" -> DBC.MA.MAM_SHIP_VALID_LCL | DT8: TargetName | DU8: ="DBC.MA.MAM_"&DT6 -> DBC.MA.MAM_ITM_SHIP_GRP | DV8: TargetName | DW8: ="DBC.MA.MAM_"&DT6&"_LCL" -> DBC.MA.MAM_ITM_SHIP_GRP_LCL | DX8: TargetName | DY8: ="DBC.MA.MAM_"&DX6 -> DBC.MA.MAM_TRNSPT | DZ8: TargetName | EA8: ="DBC.MA.MAM_"&DX6&"_LCL" -> DBC.MA.MAM_TRNSPT_LCL | EB8: TargetName | EC8: ="DBC.MA.MAM_"&EB6 -> DBC.MA.MAM_EX_CNTNR | ED8: TargetName | EE8: ="DBC.MA.MAM_"&EB6&"_LCL" -> DBC.MA.MAM_EX_CNTNR_LCL | EF8: TargetName | EG8: ="DBC.MA.MAM_"&EF6 -> DBC.MA.MAM_EXIM_PORT | EH8: TargetName | EI8: ="DBC.MA.MAM_"&EF6&"_LCL" -> DBC.MA.MAM_EXIM_PORT_LCL | EJ8: TargetName | EK8: ="DBC.MA.MAM_"&EJ6 -> DBC.MA.MAM_STK_GD | EL8: TargetName | EM8: ="DBC.MA.MAM_"&EJ6&"_LCL" -> DBC.MA.MAM_STK_GD_LCL | EN8: TargetName | EO8: ="DBC.MA.MAM_"&EN6 -> DBC.MA.MAM_TRD | EP8: TargetName | EQ8: ="DBC.MA.MAM_"&EN6&"_LCL" -> DBC.MA.MAM_TRD_LCL | ER8: TargetName | ES8: ="DBC.MA.MAM_"&ER6 -> DBC.MA.MAM_SLIP_FORM | ET8: TargetName | EU8: ="DBC.MA.MAM_"&ER6&"_LCL" -> DBC.MA.MAM_SLIP_FORM_LCL | EV8: TargetName | EW8: ="DBC.MA.MAM_"&EV6 -> DBC.MA.MAM_PF_GRP | EX8: TargetName | EY8: ="DBC.MA.MAM_"&EV6&"_LCL" -> DBC.MA.MAM_PF_GRP_LCL | EZ8: TargetName | FA8: ="DBC.MA.MAM_"&EZ6 -> DBC.MA.MAM_ITM_SPEC_GRP | FB8: TargetName | FC8: ="DBC.MA.MAM_"&EZ6&"_LCL" -> DBC.MA.MAM_ITM_SPEC_GRP_LCL | FD8: TargetName | FE8: ="DBC.MA.MAM_"&FD6 -> DBC.MA.MAM_ITM_COMP_GRP | FF8: TargetName | FG8: ="DBC.MA.MAM_"&FD6&"_LCL" -> DBC.MA.MAM_ITM_COMP_GRP_LCL | FH8: TargetName | FI8: ="DBC.MA.MAM_"&FH6 -> DBC.MA.MAM_JNL_ACT | FJ8: TargetName | FK8: ="DBC.MA.MAM_"&FH6&"_LCL" -> DBC.MA.MAM_JNL_ACT_LCL | FL8: TargetName | FM8: ="DBC.MA.MAM_"&FL6 -> DBC.MA.MAM_JNL_GRP | FN8: TargetName | FO8: ="DBC.MA.MAM_"&FL6&"_LCL" -> DBC.MA.MAM_JNL_GRP_LCL | FP8: TargetName | FQ8: ="DBC.MA.MAM_"&FP6 -> DBC.MA.MAM_JNL_PTN_BASE | FR8: TargetName | FS8: ="DBC.MA.MAM_"&FP6&"_LCL" -> DBC.MA.MAM_JNL_PTN_BASE_LCL | FT8: TargetName | FU8: ="DBC.MA.MAM_"&FT6 -> DBC.MA.MAM_AUTO_JNL_KEY | FV8: TargetName | FW8: ="DBC.MA.MAM_"&FT6&"_LCL" -> DBC.MA.MAM_AUTO_JNL_KEY_LCL | FX8: TargetName | FY8: ="DBC.MA.MAM_"&FX6 -> DBC.MA.MAM_INSP_PTN | FZ8: TargetName | GA8: ="DBC.MA.MAM_"&FX6&"_LCL" -> DBC.MA.MAM_INSP_PTN_LCL | GB8: TargetName | GC8: ="DBC.MA.MAM_"&GB6 -> DBC.MA.MAM_WK_DAY | GD8: TargetName | GE8: ="DBC.MA.MAM_"&GB6&"_LCL" -> DBC.MA.MAM_WK_DAY_LCL | GF8: TargetName | GG8: ="DBC.MA.MAM_"&GF6 -> DBC.MA.MAM_SHIP_TERM | GH8: TargetName | GI8: ="DBC.MA.MAM_"&GF6&"_LCL" -> DBC.MA.MAM_SHIP_TERM_LCL | GJ8: TargetName | GK8: ="DBC.MA.MAM_"&GJ6 -> DBC.MA.MAM_SHIP_WK | GL8: TargetName | GM8: ="DBC.MA.MAM_"&GJ6&"_LCL" -> DBC.MA.MAM_SHIP_WK_LCL | GN8: TargetName | GO8: ="DBC.MA.MAM_"&GN6 -> DBC.MA.MAM_RSRC | GP8: TargetName | GQ8: ="DBC.MA.MAM_"&GN6&"_LCL" -> DBC.MA.MAM_RSRC_LCL | GR8: TargetName | GS8: ="DBC.MA.MAM_"&GR6 -> DBC.MA.MAM_HS_GRP | GT8: TargetName | GU8: ="DBC.MA.MAM_"&GR6&"_LCL" -> DBC.MA.MAM_HS_GRP_LCL | GV8: TargetName | GW8: ="DBC.MA.MAM_"&GV6 -> DBC.MA.MAM_ALC_PTN | GX8: TargetName | GY8: ="DBC.MA.MAM_"&GV6&"_LCL" -> DBC.MA.MAM_ALC_PTN_LCL | GZ8: TargetName | HA8: ="DBC.MA.MAM_"&GZ6 -> DBC.MA.MAM_CTG_GRP | HB8: TargetName | HC8: ="DBC.MA.MAM_"&GZ6&"_LCL" -> DBC.MA.MAM_CTG_GRP_LCL | HD8: TargetName | HE8: ="DBC.MA.MAM_"&HD6 -> DBC.MA.MAM_ACT_PTN | HF8: TargetName | HG8: ="DBC.MA.MAM_"&HD6&"_LCL" -> DBC.MA.MAM_ACT_PTN_LCL | HH8: TargetName | HI8: ="DBC.MA.MAM_"&HH6 -> DBC.MA.MAM_GP_ALC | HJ8: TargetName | HK8: ="DBC.MA.MAM_"&HH6&"_LCL" -> DBC.MA.MAM_GP_ALC_LCL | HL8: TargetName | HM8: ="DBC.MA.MAM_"&HL6 -> DBC.MA.MAM_CALC_CTG | HN8: TargetName | HO8: ="DBC.MA.MAM_"&HL6&"_LCL" -> DBC.MA.MAM_CALC_CTG_LCL | HP8: TargetName | HQ8: ="DBC.MA.MAM_"&HP6 -> DBC.MA.MAM_RPT_PTN | HR8: TargetName | HS8: ="DBC.MA.MAM_"&HP6&"_LCL" -> DBC.MA.MAM_RPT_PTN_LCL | HT8: TargetName | HU8: ="DBC.MA.MAM_"&HT6 -> DBC.MA.MAM_COST_MENU | HV8: TargetName | HW8: ="DBC.MA.MAM_"&HT6&"_LCL" -> DBC.MA.MAM_COST_MENU_LCL | HX8: TargetName | HY8: ="DBC.MA.MAM_"&HX6 -> DBC.MA.MAM_SITE_CO | HZ8: TargetName | IA8: ="DBC.MA.MAM_"&HX6&"_LCL" -> DBC.MA.MAM_SITE_CO_LCL | ID8: ブロック備考 Block Remarks
A9: # | D9: 項目名 Field Name | E9: 型 Type | F9: 桁 Digits | G9: フルネーム Full Name | H9: 日本語名 Japanese Name | I9: 上り項目 Request Message Field | J9: 下り項目 Response Message Field | IB9: 条件および編集方法 Conditions and Editing Methods | ID9: 項目備考 Field Remarks
A10: # | L10: 上り項目 Request Message Field | M10: 下り項目 Response Message Field | N10: 上り項目 Request Message Field | O10: 下り項目 Response Message Field | P10: 上り項目 Request Message Field | Q10: 下り項目 Response Message Field | R10: 上り項目 Request Message Field | S10: 下り項目 Response Message Field | T10: 上り項目 Request Message Field | U10: 下り項目 Response Message Field | V10: 上り項目 Request Message Field | W10: 下り項目 Response Message Field | X10: 上り項目 Request Message Field | Y10: 下り項目 Response Message Field | Z10: 上り項目 Request Message Field | AA10: 下り項目 Response Message Field | AB10: 上り項目 Request Message Field | AC10: 下り項目 Response Message Field | AD10: 上り項目 Request Message Field | AE10: 下り項目 Response Message Field | AF10: 上り項目 Request Message Field | AG10: 下り項目 Response Message Field | AH10: 上り項目 Request Message Field | AI10: 下り項目 Response Message Field | AJ10: 上り項目 Request Message Field | AK10: 下り項目 Response Message Field | AL10: 上り項目 Request Message Field | AM10: 下り項目 Response Message Field | AN10: 上り項目 Request Message Field | AO10: 下り項目 Response Message Field | AP10: 上り項目 Request Message Field | AQ10: 下り項目 Response Message Field | AR10: 上り項目 Request Message Field | AS10: 下り項目 Response Message Field | AT10: 上り項目 Request Message Field | AU10: 下り項目 Response Message Field | AV10: 上り項目 Request Message Field | AW10: 下り項目 Response Message Field | AX10: 上り項目 Request Message Field | AY10: 下り項目 Response Message Field | AZ10: 上り項目 Request Message Field | BA10: 下り項目 Response Message Field | BB10: 上り項目 Request Message Field | BC10: 下り項目 Response Message Field | BD10: 上り項目 Request Message Field | BE10: 下り項目 Response Message Field | BF10: 上り項目 Request Message Field | BG10: 下り項目 Response Message Field | BH10: 上り項目 Request Message Field | BI10: 下り項目 Response Message Field | BJ10: 上り項目 Request Message Field | BK10: 下り項目 Response Message Field | BL10: 上り項目 Request Message Field | BM10: 下り項目 Response Message Field | BN10: 上り項目 Request Message Field | BO10: 下り項目 Response Message Field | BP10: 上り項目 Request Message Field | BQ10: 下り項目 Response Message Field | BR10: 上り項目 Request Message Field | BS10: 下り項目 Response Message Field | BT10: 上り項目 Request Message Field | BU10: 下り項目 Response Message Field | BV10: 上り項目 Request Message Field | BW10: 下り項目 Response Message Field | BX10: 上り項目 Request Message Field | BY10: 下り項目 Response Message Field | BZ10: 上り項目 Request Message Field | CA10: 下り項目 Response Message Field | CB10: 上り項目 Request Message Field | CC10: 下り項目 Response Message Field | CD10: 上り項目 Request Message Field | CE10: 下り項目 Response Message Field | CF10: 上り項目 Request Message Field | CG10: 下り項目 Response Message Field | CH10: 上り項目 Request Message Field | CI10: 下り項目 Response Message Field | CJ10: 上り項目 Request Message Field | CK10: 下り項目 Response Message Field | CL10: 上り項目 Request Message Field | CM10: 下り項目 Response Message Field | CN10: 上り項目 Request Message Field | CO10: 下り項目 Response Message Field | CP10: 上り項目 Request Message Field | CQ10: 下り項目 Response Message Field | CR10: 上り項目 Request Message Field | CS10: 下り項目 Response Message Field | CT10: 上り項目 Request Message Field | CU10: 下り項目 Response Message Field | CV10: 上り項目 Request Message Field | CW10: 下り項目 Response Message Field | CX10: 上り項目 Request Message Field | CY10: 下り項目 Response Message Field | CZ10: 上り項目 Request Message Field | DA10: 下り項目 Response Message Field | DB10: 上り項目 Request Message Field | DC10: 下り項目 Response Message Field | DD10: 上り項目 Request Message Field | DE10: 下り項目 Response Message Field | DF10: 上り項目 Request Message Field | DG10: 下り項目 Response Message Field | DH10: 上り項目 Request Message Field | DI10: 下り項目 Response Message Field | DJ10: 上り項目 Request Message Field | DK10: 下り項目 Response Message Field | DL10: 上り項目 Request Message Field | DM10: 下り項目 Response Message Field | DN10: 上り項目 Request Message Field | DO10: 下り項目 Response Message Field | DP10: 上り項目 Request Message Field | DQ10: 下り項目 Response Message Field | DR10: 上り項目 Request Message Field | DS10: 下り項目 Response Message Field | DT10: 上り項目 Request Message Field | DU10: 下り項目 Response Message Field | DV10: 上り項目 Request Message Field | DW10: 下り項目 Response Message Field | DX10: 上り項目 Request Message Field | DY10: 下り項目 Response Message Field | DZ10: 上り項目 Request Message Field | EA10: 下り項目 Response Message Field | EB10: 上り項目 Request Message Field | EC10: 下り項目 Response Message Field | ED10: 上り項目 Request Message Field | EE10: 下り項目 Response Message Field | EF10: 上り項目 Request Message Field | EG10: 下り項目 Response Message Field | EH10: 上り項目 Request Message Field | EI10: 下り項目 Response Message Field | EJ10: 上り項目 Request Message Field | EK10: 下り項目 Response Message Field | EL10: 上り項目 Request Message Field | EM10: 下り項目 Response Message Field | EN10: 上り項目 Request Message Field | EO10: 下り項目 Response Message Field | EP10: 上り項目 Request Message Field | EQ10: 下り項目 Response Message Field | ER10: 上り項目 Request Message Field | ES10: 下り項目 Response Message Field | ET10: 上り項目 Request Message Field | EU10: 下り項目 Response Message Field | EV10: 上り項目 Request Message Field | EW10: 下り項目 Response Message Field | EX10: 上り項目 Request Message Field | EY10: 下り項目 Response Message Field | EZ10: 上り項目 Request Message Field | FA10: 下り項目 Response Message Field | FB10: 上り項目 Request Message Field | FC10: 下り項目 Response Message Field | FD10: 上り項目 Request Message Field | FE10: 下り項目 Response Message Field | FF10: 上り項目 Request Message Field | FG10: 下り項目 Response Message Field | FH10: 上り項目 Request Message Field | FI10: 下り項目 Response Message Field | FJ10: 上り項目 Request Message Field | FK10: 下り項目 Response Message Field | FL10: 上り項目 Request Message Field | FM10: 下り項目 Response Message Field | FN10: 上り項目 Request Message Field | FO10: 下り項目 Response Message Field | FP10: 上り項目 Request Message Field | FQ10: 下り項目 Response Message Field | FR10: 上り項目 Request Message Field | FS10: 下り項目 Response Message Field | FT10: 上り項目 Request Message Field | FU10: 下り項目 Response Message Field | FV10: 上り項目 Request Message Field | FW10: 下り項目 Response Message Field | FX10: 上り項目 Request Message Field | FY10: 下り項目 Response Message Field | FZ10: 上り項目 Request Message Field | GA10: 下り項目 Response Message Field | GB10: 上り項目 Request Message Field | GC10: 下り項目 Response Message Field | GD10: 上り項目 Request Message Field | GE10: 下り項目 Response Message Field | GF10: 上り項目 Request Message Field | GG10: 下り項目 Response Message Field | GH10: 上り項目 Request Message Field | GI10: 下り項目 Response Message Field | GJ10: 上り項目 Request Message Field | GK10: 下り項目 Response Message Field | GL10: 上り項目 Request Message Field | GM10: 下り項目 Response Message Field | GN10: 上り項目 Request Message Field | GO10: 下り項目 Response Message Field | GP10: 上り項目 Request Message Field | GQ10: 下り項目 Response Message Field | GR10: 上り項目 Request Message Field | GS10: 下り項目 Response Message Field | GT10: 上り項目 Request Message Field | GU10: 下り項目 Response Message Field | GV10: 上り項目 Request Message Field | GW10: 下り項目 Response Message Field | GX10: 上り項目 Request Message Field | GY10: 下り項目 Response Message Field | GZ10: 上り項目 Request Message Field | HA10: 下り項目 Response Message Field | HB10: 上り項目 Request Message Field | HC10: 下り項目 Response Message Field | HD10: 上り項目 Request Message Field | HE10: 下り項目 Response Message Field | HF10: 上り項目 Request Message Field | HG10: 下り項目 Response Message Field | HH10: 上り項目 Request Message Field | HI10: 下り項目 Response Message Field | HJ10: 上り項目 Request Message Field | HK10: 下り項目 Response Message Field | HL10: 上り項目 Request Message Field | HM10: 下り項目 Response Message Field | HN10: 上り項目 Request Message Field | HO10: 下り項目 Response Message Field | HP10: 上り項目 Request Message Field | HQ10: 下り項目 Response Message Field | HR10: 上り項目 Request Message Field | HS10: 下り項目 Response Message Field | HT10: 上り項目 Request Message Field | HU10: 下り項目 Response Message Field | HV10: 上り項目 Request Message Field | HW10: 下り項目 Response Message Field | HX10: 上り項目 Request Message Field | HY10: 下り項目 Response Message Field | HZ10: 上り項目 Request Message Field | IA10: 下り項目 Response Message Field
A11: 10 | B11: * | D11: Srch01_Cnd | E11: R | L11: R | P11: R | T11: R | X11: R | AB11: R | AF11: R | AJ11: R | AN11: R | AR11: R | AV11: R | AZ11: R | BD11: R | BH11: R | BL11: R | BP11: R | BT11: R | BX11: R | CB11: R | CF11: R | CJ11: R | CN11: R | CR11: R | CV11: R | CZ11: R | DD11: R | DH11: R | DL11: R | DP11: R | DT11: R | DX11: R | EB11: R | EF11: R | EJ11: R | EN11: R | ER11: R | EV11: R | EZ11: R | FD11: R | FH11: R | FL11: R | FP11: R | FT11: R | FX11: R | GB11: R | GF11: R | GJ11: R | GN11: R | GR11: R | GV11: R | GZ11: R | HD11: R | HH11: R | HL11: R | HP11: R | HT11: R | HX11: R
A12: 10 | D12: mst_nm | E12: #MA.ORA_OBJ_NM | G12: Master name | H12: マスタ名 | I12: E
A13: 10 | D13: cd | E13: C | G13: CD | H13: ＣＤ | I13: E | L13: da_cd | P13: dpt_cd | T13: dpt_lvl_cd | X13: aprv_role_cd | AB13: cntry_cd | AF13: area_cd | AJ13: cur_cd | AN13: unit_cd | AR13: bank_cd | AV13: bank_cd | AZ13: bank_ac_cd | BD13: xrate_cd | BH13: cal_cd | BL13: itm_jnl_cd | BP13: ac_itm_grp_cd | BT13: ac_rsn_cd | BX13: site_cd | CB13: loc_grp_cd | CF13: lg_grp_cd | CJ13: alloc_grp_cd | CN13: wg_cd | CR13: oper_cd | CV13: wk_cost_cd | CZ13: wk_rsn_cd | DD13: sls_upri_grp_cd | DH13: sls_upri_rank_cd | DL13: setoff_grp_cd | DP13: ship_valid_grp_cd | DT13: itm_ship_grp_cd | DX13: trnspt_cd | EB13: cntnr_cd | EF13: port_cd | EJ13: gd_cd | EN13: trd_cd | ER13: slip_form_cd | EV13: pf_grp_cd | EZ13: itm_spec_grp_cd | FD13: itm_comp_grp_cd | FH13: jnl_act_cd | FL13: jnl_grp_cd | FP13: jnl_ptn_cd | FT13: auto_jnl_key_cd | FX13: insp_ptn_cd | GB13: wk_day_cd | GF13: ship_term_cd | GJ13: ship_wk_cd | GN13: rsrc_cd | GR13: hs_grp_cd | GV13: alc_ptn_cd | GZ13: ctg_grp_cd | HD13: act_ptn_cd | HH13: gp_alc_cd | HL13: calc_ctg_cd | HP13: rpt_ptn_cd | HT13: menu_cd | HX13: site_co_cd
A14: 10 | D14: nm | E14: C | G14: Name | H14: 名 | I14: E | L14: da_nm | P14: def_dpt_nm | T14: dpt_lvl_nm | X14: aprv_role_nm | AB14: cntry_nm | AF14: area_nm | AJ14: cur_nm | AN14: unit_nm | AR14: bank_nm | AV14: branch_nm | AZ14: bank_ac_nm | BD14: xrate_nm | BH14: cal_nm | BL14: itm_jnl_nm | BP14: ac_itm_grp_nm | BT14: ac_rsn_nm | BX14: site_nm | CB14: loc_grp_nm | CF14: lg_grp_nm | CJ14: alloc_grp_nm | CN14: wg_nm | CR14: oper_nm | CV14: wk_cost_nm | CZ14: wk_rsn_nm | DD14: sls_upri_grp_nm | DH14: sls_upri_rank_nm | DL14: setoff_grp_nm | DP14: ship_valid_grp_nm | DT14: itm_ship_grp_nm | DX14: trnspt_nm | EB14: cntnr_nm | EF14: port_nm | EJ14: gd_nm | EN14: trd_nm | ER14: slip_form_nm | EV14: pf_grp_nm | EZ14: itm_spec_grp_nm | FD14: itm_comp_grp_nm | FH14: jnl_act_nm | FL14: jnl_grp_nm | FP14: jnl_ptn_nm | FT14: auto_jnl_key_nm | FX14: insp_ptn_nm | GB14: wk_day_nm | GF14: ship_term_nm | GJ14: ship_wk_nm | GN14: rsrc_nm | GR14: hs_grp_nm | GV14: alc_ptn_nm | GZ14: ctg_grp_nm | HD14: act_ptn_nm | HH14: gp_alc_nm | HL14: calc_ctg_nm | HP14: rpt_ptn_nm | HT14: menu_nm | HX14: site_co_nm
A15: 10 | D15: memo1 | E15: #MA.MST_MEMO1 | G15: Memo 1 | H15: メモ１ | I15: E
A16: 10 | D16: memo2 | E16: #MA.MST_MEMO2 | G16: Memo 2 | H16: メモ２ | I16: E
A17: 10 | D17: memo3 | E17: #MA.MST_MEMO3 | G17: Memo 3 | H17: メモ３ | I17: E
A18: 10 | D18: off_del_flg | E18: #MA.FLG | G18: Logical delete. Off | H18: 論理削除.オフ | I18: E
A19: 10 | D19: on_del_flg | E19: #MA.FLG | G19: Logical delete. On | H19: 論理削除.オン | I19: E
A20: 10 | D20: match_typ | E20: C | G20: Match type | H20: マッチタイプ | I20: E
A22: 20 | B22: * | D22: Srch01_Rslt1 | E22: L | M22: L | Q22: L | U22: L | Y22: L | AC22: L | AG22: L | AK22: L | AO22: L | AS22: L | AW22: L | BA22: L | BE22: L | BI22: L | BM22: L | BQ22: L | BU22: L | BY22: L | CC22: L | CG22: L | CK22: L | CO22: L | CS22: L | CW22: L | DA22: L | DE22: L | DI22: L | DM22: L | DQ22: L | DU22: L | DY22: L | EC22: L | EG22: L | EK22: L | EO22: L | ES22: L | EW22: L | FA22: L | FE22: L | FI22: L | FM22: L | FQ22: L | FU22: L | FY22: L | GC22: L | GG22: L | GK22: L | GO22: L | GS22: L | GW22: L | HA22: L | HE22: L | HI22: L | HM22: L | HQ22: L | HU22: L | HY22: L
A23: 20 | D23: del_flg | E23: #MA.FLG | G23: Logical delete | H23: 論理削除 | J23: E | M23: E | Q23: E | U23: E | Y23: E | AC23: E | AG23: E | AK23: E | AO23: E | AS23: E | AW23: E | BA23: E | BE23: E | BI23: E | BM23: E | BQ23: E | BU23: E | BY23: E | CC23: E | CG23: E | CK23: E | CO23: E | CS23: E | CW23: E | DA23: E | DE23: E | DI23: E | DM23: E | DQ23: E | DU23: E | DY23: E | EC23: E | EG23: E | EK23: E | EO23: E | ES23: E | EW23: E | FA23: E | FE23: E | FI23: E | FM23: E | FQ23: E | FU23: E | FY23: E | GC23: E | GG23: E | GK23: E | GO23: E | GS23: E | GW23: E | HA23: E | HE23: E | HI23: E | HM23: E | HQ23: E | HU23: E | HY23: E
A24: 20 | D24: da_cd | E24: #MA.DA_CD | G24: Data access cd. | H24: データアクセスＣＤ | J24: E | M24: E
A25: 20 | D25: da_nm_lcl | E25: #MA.DA_NM | G25: Data access name | H25: データアクセス名 | J25: E | M25: da_nm
A26: 20 | D26: da_nm | E26: #MA.DA_NM | G26: Standard data access name | H26: 標準データアクセス名 | J26: E | M26: base_da_nm
A27: 20 | D27: dpt_cd | E27: #MA.DPT_CD | G27: Dept. cd. | H27: 部門ＣＤ | J27: E | Q27: E
A28: 20 | D28: def_dpt_nm_lcl | E28: #MA.DPT_NM | G28: Dept. name | H28: 部門名 | J28: E | Q28: def_dpt_nm
A29: 20 | D29: def_dpt_nm | E29: #MA.DPT_NM | G29: Standard dept. name | H29: 標準部門名 | J29: E | Q29: base_def_dpt_nm
A30: 20 | D30: dpt_lvl_cd | E30: #MA.DPT_LVL_CD | G30: Dept. hierarchy cd. | H30: 部門階層ＣＤ | J30: E | U30: E
A31: 20 | D31: dpt_lvl_nm_lcl | E31: #MA.DPT_LVL_NM | G31: Dept. hierarchy name | H31: 部門階層名 | J31: E | U31: dpt_lvl_nm
A32: 20 | D32: dpt_lvl_nm | E32: #MA.DPT_LVL_NM | G32: Standard dept. hierarchy name | H32: 標準部門階層名 | J32: E | U32: base_dpt_lvl_nm
A33: 20 | D33: aprv_role_cd | E33: #MA.APRV_ROLE_CD | G33: Approval role cd. | H33: 承認役割ＣＤ | J33: E | Y33: E
A34: 20 | D34: aprv_role_nm_lcl | E34: #MA.APRV_ROLE_NM | G34: Approval role name | H34: 承認役割名 | J34: E | Y34: aprv_role_nm
A35: 20 | D35: aprv_role_nm | E35: #MA.APRV_ROLE_NM | G35: Standard approval role name | H35: 標準承認役割名 | J35: E | Y35: base_aprv_role_nm
A36: 20 | D36: cntry_cd | E36: #MA.CNTRY_CD | G36: Country cd. | H36: 国ＣＤ | J36: E | AC36: E
A37: 20 | D37: cntry_nm_lcl | E37: #MA.CNTRY_NM | G37: Country name | H37: 国名 | J37: E | AC37: cntry_nm
A38: 20 | D38: cntry_nm | E38: #MA.CNTRY_NM | G38: Standard Country name | H38: 標準国名 | J38: E | AC38: base_cntry_nm
A39: 20 | D39: area_cd | E39: #MA.AREA_CD | G39: Region cd. | H39: 地域ＣＤ | J39: E | AG39: E
A40: 20 | D40: area_nm_lcl | E40: #MA.AREA_NM | G40: Region name | H40: 地域名 | J40: E | AG40: area_nm
A41: 20 | D41: area_nm | E41: #MA.AREA_NM | G41: Standard Region name | H41: 標準地域名 | J41: E | AG41: base_area_nm
...

Sheet Upd01
A1: * | B1: * | D1: L | E1: 1
A2: * | D2: オペレーション実装仕様書 Operation Specification Implementation Sheet | E2: ModuleID : | F2: =IF(LogicCommon!C2="","",LogicCommon!C2) -> MA | G2: LogicID : | H2: =IF(LogicCommon!E2="","",LogicCommon!E2) -> MABCL0030 | I2: Ope.ID : | J2: Upd01 | K2: Pj.ID : | L2: =IF(LogicCommon!G2="","",LogicCommon!G2) -> MC | M2: Ope.Body : | N2: "mcframe.serverMAUD.MAUDL6020.MAUDL_LCLRLUpdater"
A3: * | D3: =IF(LogicCommon!A3="","",LogicCommon!A3) | E3: SubModuleID : | F3: =IF(LogicCommon!C3="","",LogicCommon!C3) -> MABC | G3: LogicClass : | H3: =IF(LogicCommon!E3="","",LogicCommon!E3) -> MABCL_MultiReg | I3: Ope.Method : | J3: @ | K3: SuperClassPj.ID : | L3: =IF(LogicCommon!G3="","",LogicCommon!G3) | M3: ReportID : | O3: Gene.Type : | P3: ALL
A4: * | E4: Version : | F4: 000000 | G4: LogicName : | H4: =IF(LogicCommon!E4="","",LogicCommon!E4) -> マルチマスタ登録 | I4: Ope.Name : | J4: 登録 | K4: SuperLogicID : | L4: =IF(LogicCommon!G4="","",LogicCommon!G4) -> MA.MAUDL5010
A5: * | E5: ACType : | K5: 1 | O5: 2 | S5: 3 | W5: 4 | AA5: 5 | AE5: 6 | AI5: 7 | AM5: 8 | AQ5: 9 | AU5: 10 | AY5: 11 | BC5: 12 | BG5: 13 | BK5: 14 | BO5: 15 | BS5: 16 | BW5: 17 | CA5: 18 | CE5: 19 | CI5: 20 | CM5: 21 | CQ5: 22 | CU5: 23 | CY5: 24 | DC5: 25 | DG5: 26 | DK5: 27 | DO5: 28 | DS5: 29 | DW5: 30 | EA5: 31 | EE5: 32 | EI5: 33 | EM5: 34 | EQ5: 35 | EU5: 36 | EY5: 37 | FC5: 38 | FG5: 39 | FK5: 40 | FO5: 41 | FS5: 42 | FW5: 43 | GA5: 44 | GE5: 45 | GI5: 46 | GM5: 47 | GQ5: 48 | GU5: 49 | GY5: 50 | HC5: 51 | HG5: 52 | HK5: 53 | HO5: 54 | HS5: 55 | HW5: 56 | IA5: 57 | IE5: 58 | II5: 59 | IM5: 60 | IQ5: 61 | IU5: 62 | IY5: 63 | JC5: 64 | JG5: 65 | JK5: 66 | JO5: 67 | JS5: 68 | JW5: 69 | KA5: 70 | KE5: 71 | KI5: 72 | KM5: 73 | KQ5: 74 | KU5: 75 | KY5: 76 | LC5: 77 | LG5: 78 | LK5: 79 | LO5: 80 | LS5: 81 | LW5: 82 | MA5: 83 | ME5: 84 | MI5: 85 | MM5: 86 | MQ5: 87 | MU5: 88 | MY5: 89 | NC5: 90 | NG5: 91 | NK5: 92 | NO5: 93 | NS5: 94 | NW5: 95 | OA5: 96 | OE5: 97 | OI5: 98 | OM5: 99 | OQ5: 100 | OU5: 101 | OY5: 102 | PC5: 103 | PG5: 104 | PK5: 105 | PO5: 106 | PS5: 107 | PW5: 108 | QA5: 109 | QE5: 110 | QI5: 111 | QM5: 112
A6: * | D6: 概要 : | E6: 複数のマスタ、名称マスタの登録を行います。（マスタ画面用） | K6: Da | L6: MABCL0031 | S6: Dpt_Base | T6: MABCL0031 | AA6: Dpt_Lvl | AB6: MABCL0031 | AI6: Aprv_Role | AJ6: MABCL0031 | AQ6: Cntry | AR6: MABCL0031 | AY6: Area | AZ6: MABCL0031 | BG6: Cur | BH6: MABCL0031 | BO6: Unit | BP6: MABCL0031 | BW6: Bank | BX6: MABCL0031 | CE6: Bank_Branch | CF6: MABCL0031 | CM6: Bank_Ac | CN6: MABCL0032 | CU6: Xrate | CV6: MABCL0032 | DC6: Cal_Base | DD6: MABCL0032 | DK6: Itm_Jnl | DL6: MABCL0032 | DS6: Ac_Itm_Grp | DT6: MABCL0032 | EA6: Ac_Rsn | EB6: MABCL0032 | EI6: Site | EJ6: MABCL0032 | EQ6: Loc_Grp | ER6: MABCL0032 | EY6: Lg_Grp | EZ6: MABCL0032 | FG6: Alloc_Grp | FH6: MABCL0032 | FO6: Wg | FP6: MABCL0033 | FW6: Oper | FX6: MABCL0033 | GE6: Wk_Cost | GF6: MABCL0033 | GM6: Wk_Rsn | GN6: MABCL0033 | GU6: Sls_Upri_Grp | GV6: MABCL0033 | HC6: Sls_Upri_Rank | HD6: MABCL0033 | HK6: Setoff_Grp | HL6: MABCL0033 | HS6: Ship_Valid | HT6: MABCL0033 | IA6: Itm_Ship_Grp | IB6: MABCL0033 | II6: Trnspt | IJ6: MABCL0033 | IQ6: Ex_Cntnr | IR6: MABCL0034 | IY6: Exim_Port | IZ6: MABCL0034 | JG6: Stk_Gd | JH6: MABCL0034 | JO6: Trd | JP6: MABCL0034 | JW6: Slip_Form | JX6: MABCL0034 | KE6: Pf_Grp | KF6: MABCL0034 | KM6: Itm_Spec_Grp | KN6: MABCL0034 | KU6: Itm_Comp_Grp | KV6: MABCL0034 | LC6: Jnl_Act | LD6: MABCL0034 | LK6: Jnl_Grp | LL6: MABCL0034 | LS6: Jnl_Ptn_Base | LT6: MABCL0035 | MA6: Auto_Jnl_Key | MB6: MABCL0035 | MI6: Insp_Ptn | MJ6: MABCL0035 | MQ6: Wk_Day | MR6: MABCL0035 | MY6: Ship_Term | MZ6: MABCL0035 | NG6: Ship_Wk | NH6: MABCL0035 | NO6: Rsrc | NP6: MABCL0035 | NW6: Hs_Grp | NX6: MABCL0035 | OE6: Alc_Ptn | OF6: MABCL0035 | OM6: Ctg_Grp | ON6: MABCL0035 | OU6: Act_Ptn | OV6: MABCL0035 | PC6: Gp_Alc | PD6: MABCL0036 | PK6: Calc_Ctg | PL6: MABCL0036 | PS6: Rpt_Ptn | PT6: MABCL0036 | QA6: Cost_Menu | QB6: MABCL0036 | QI6: Site_Co | QJ6: MABCL0036
A7: # | I7: U | K7: o | L7: =UPPER(K6)&".chk"&TEXT(K5,"00") -> DA.chk01 | M7: o | N7: =UPPER(K6)&".upd"&TEXT(K5,"00") -> DA.upd01 | O7: o | P7: =UPPER(K6)&".chk"&TEXT(O5,"00") -> DA.chk02 | Q7: o | R7: =UPPER(K6)&".upd"&TEXT(O5,"00") -> DA.upd02 | S7: o | T7: =UPPER(S6)&".chk"&TEXT(S5,"00") -> DPT_BASE.chk03 | U7: o | V7: =UPPER(S6)&".upd"&TEXT(S5,"00") -> DPT_BASE.upd03 | W7: o | X7: =UPPER(S6)&".chk"&TEXT(W5,"00") -> DPT_BASE.chk04 | Y7: o | Z7: =UPPER(S6)&".upd"&TEXT(W5,"00") -> DPT_BASE.upd04 | AA7: o | AB7: =UPPER(AA6)&".chk"&TEXT(AA5,"00") -> DPT_LVL.chk05 | AC7: o | AD7: =UPPER(AA6)&".upd"&TEXT(AA5,"00") -> DPT_LVL.upd05 | AE7: o | AF7: =UPPER(AA6)&".chk"&TEXT(AE5,"00") -> DPT_LVL.chk06 | AG7: o | AH7: =UPPER(AA6)&".upd"&TEXT(AE5,"00") -> DPT_LVL.upd06 | AI7: o | AJ7: =UPPER(AI6)&".chk"&TEXT(AI5,"00") -> APRV_ROLE.chk07 | AK7: o | AL7: =UPPER(AI6)&".upd"&TEXT(AI5,"00") -> APRV_ROLE.upd07 | AM7: o | AN7: =UPPER(AI6)&".chk"&TEXT(AM5,"00") -> APRV_ROLE.chk08 | AO7: o | AP7: =UPPER(AI6)&".upd"&TEXT(AM5,"00") -> APRV_ROLE.upd08 | AQ7: o | AR7: =UPPER(AQ6)&".chk"&TEXT(AQ5,"00") -> CNTRY.chk09 | AS7: o | AT7: =UPPER(AQ6)&".upd"&TEXT(AQ5,"00") -> CNTRY.upd09 | AU7: o | AV7: =UPPER(AQ6)&".chk"&TEXT(AU5,"00") -> CNTRY.chk10 | AW7: o | AX7: =UPPER(AQ6)&".upd"&TEXT(AU5,"00") -> CNTRY.upd10 | AY7: o | AZ7: =UPPER(AY6)&".chk"&TEXT(AY5,"00") -> AREA.chk11 | BA7: o | BB7: =UPPER(AY6)&".upd"&TEXT(AY5,"00") -> AREA.upd11 | BC7: o | BD7: =UPPER(AY6)&".chk"&TEXT(BC5,"00") -> AREA.chk12 | BE7: o | BF7: =UPPER(AY6)&".upd"&TEXT(BC5,"00") -> AREA.upd12 | BG7: o | BH7: =UPPER(BG6)&".chk"&TEXT(BG5,"00") -> CUR.chk13 | BI7: o | BJ7: =UPPER(BG6)&".upd"&TEXT(BG5,"00") -> CUR.upd13 | BK7: o | BL7: =UPPER(BG6)&".chk"&TEXT(BK5,"00") -> CUR.chk14 | BM7: o | BN7: =UPPER(BG6)&".upd"&TEXT(BK5,"00") -> CUR.upd14 | BO7: o | BP7: =UPPER(BO6)&".chk"&TEXT(BO5,"00") -> UNIT.chk15 | BQ7: o | BR7: =UPPER(BO6)&".upd"&TEXT(BO5,"00") -> UNIT.upd15 | BS7: o | BT7: =UPPER(BO6)&".chk"&TEXT(BS5,"00") -> UNIT.chk16 | BU7: o | BV7: =UPPER(BO6)&".upd"&TEXT(BS5,"00") -> UNIT.upd16 | BW7: o | BX7: =UPPER(BW6)&".chk"&TEXT(BW5,"00") -> BANK.chk17 | BY7: o | BZ7: =UPPER(BW6)&".upd"&TEXT(BW5,"00") -> BANK.upd17 | CA7: o | CB7: =UPPER(BW6)&".chk"&TEXT(CA5,"00") -> BANK.chk18 | CC7: o | CD7: =UPPER(BW6)&".upd"&TEXT(CA5,"00") -> BANK.upd18 | CE7: o | CF7: =UPPER(CE6)&".chk"&TEXT(CE5,"00") -> BANK_BRANCH.chk19 | CG7: o | CH7: =UPPER(CE6)&".upd"&TEXT(CE5,"00") -> BANK_BRANCH.upd19 | CI7: o | CJ7: =UPPER(CE6)&".chk"&TEXT(CI5,"00") -> BANK_BRANCH.chk20 | CK7: o | CL7: =UPPER(CE6)&".upd"&TEXT(CI5,"00") -> BANK_BRANCH.upd20 | CM7: o | CN7: =UPPER(CM6)&".chk"&TEXT(CM5,"00") -> BANK_AC.chk21 | CO7: o | CP7: =UPPER(CM6)&".upd"&TEXT(CM5,"00") -> BANK_AC.upd21 | CQ7: o | CR7: =UPPER(CM6)&".chk"&TEXT(CQ5,"00") -> BANK_AC.chk22 | CS7: o | CT7: =UPPER(CM6)&".upd"&TEXT(CQ5,"00") -> BANK_AC.upd22 | CU7: o | CV7: =UPPER(CU6)&".chk"&TEXT(CU5,"00") -> XRATE.chk23 | CW7: o | CX7: =UPPER(CU6)&".upd"&TEXT(CU5,"00") -> XRATE.upd23 | CY7: o | CZ7: =UPPER(CU6)&".chk"&TEXT(CY5,"00") -> XRATE.chk24 | DA7: o | DB7: =UPPER(CU6)&".upd"&TEXT(CY5,"00") -> XRATE.upd24 | DC7: o | DD7: =UPPER(DC6)&".chk"&TEXT(DC5,"00") -> CAL_BASE.chk25 | DE7: o | DF7: =UPPER(DC6)&".upd"&TEXT(DC5,"00") -> CAL_BASE.upd25 | DG7: o | DH7: =UPPER(DC6)&".chk"&TEXT(DG5,"00") -> CAL_BASE.chk26 | DI7: o | DJ7: =UPPER(DC6)&".upd"&TEXT(DG5,"00") -> CAL_BASE.upd26 | DK7: o | DL7: =UPPER(DK6)&".chk"&TEXT(DK5,"00") -> ITM_JNL.chk27 | DM7: o | DN7: =UPPER(DK6)&".upd"&TEXT(DK5,"00") -> ITM_JNL.upd27 | DO7: o | DP7: =UPPER(DK6)&".chk"&TEXT(DO5,"00") -> ITM_JNL.chk28 | DQ7: o | DR7: =UPPER(DK6)&".upd"&TEXT(DO5,"00") -> ITM_JNL.upd28 | DS7: o | DT7: =UPPER(DS6)&".chk"&TEXT(DS5,"00") -> AC_ITM_GRP.chk29 | DU7: o | DV7: =UPPER(DS6)&".upd"&TEXT(DS5,"00") -> AC_ITM_GRP.upd29 | DW7: o | DX7: =UPPER(DS6)&".chk"&TEXT(DW5,"00") -> AC_ITM_GRP.chk30 | DY7: o | DZ7: =UPPER(DS6)&".upd"&TEXT(DW5,"00") -> AC_ITM_GRP.upd30 | EA7: o | EB7: =UPPER(EA6)&".chk"&TEXT(EA5,"00") -> AC_RSN.chk31 | EC7: o | ED7: =UPPER(EA6)&".upd"&TEXT(EA5,"00") -> AC_RSN.upd31 | EE7: o | EF7: =UPPER(EA6)&".chk"&TEXT(EE5,"00") -> AC_RSN.chk32 | EG7: o | EH7: =UPPER(EA6)&".upd"&TEXT(EE5,"00") -> AC_RSN.upd32 | EI7: o | EJ7: =UPPER(EI6)&".chk"&TEXT(EI5,"00") -> SITE.chk33 | EK7: o | EL7: =UPPER(EI6)&".upd"&TEXT(EI5,"00") -> SITE.upd33 | EM7: o | EN7: =UPPER(EI6)&".chk"&TEXT(EM5,"00") -> SITE.chk34 | EO7: o | EP7: =UPPER(EI6)&".upd"&TEXT(EM5,"00") -> SITE.upd34 | EQ7: o | ER7: =UPPER(EQ6)&".chk"&TEXT(EQ5,"00") -> LOC_GRP.chk35 | ES7: o | ET7: =UPPER(EQ6)&".upd"&TEXT(EQ5,"00") -> LOC_GRP.upd35 | EU7: o | EV7: =UPPER(EQ6)&".chk"&TEXT(EU5,"00") -> LOC_GRP.chk36 | EW7: o | EX7: =UPPER(EQ6)&".upd"&TEXT(EU5,"00") -> LOC_GRP.upd36 | EY7: o | EZ7: =UPPER(EY6)&".chk"&TEXT(EY5,"00") -> LG_GRP.chk37 | FA7: o | FB7: =UPPER(EY6)&".upd"&TEXT(EY5,"00") -> LG_GRP.upd37 | FC7: o | FD7: =UPPER(EY6)&".chk"&TEXT(FC5,"00") -> LG_GRP.chk38 | FE7: o | FF7: =UPPER(EY6)&".upd"&TEXT(FC5,"00") -> LG_GRP.upd38 | FG7: o | FH7: =UPPER(FG6)&".chk"&TEXT(FG5,"00") -> ALLOC_GRP.chk39 | FI7: o | FJ7: =UPPER(FG6)&".upd"&TEXT(FG5,"00") -> ALLOC_GRP.upd39 | FK7: o | FL7: =UPPER(FG6)&".chk"&TEXT(FK5,"00") -> ALLOC_GRP.chk40 | FM7: o | FN7: =UPPER(FG6)&".upd"&TEXT(FK5,"00") -> ALLOC_GRP.upd40 | FO7: o | FP7: =UPPER(FO6)&".chk"&TEXT(FO5,"00") -> WG.chk41 | FQ7: o | FR7: =UPPER(FO6)&".upd"&TEXT(FO5,"00") -> WG.upd41 | FS7: o | FT7: =UPPER(FO6)&".chk"&TEXT(FS5,"00") -> WG.chk42 | FU7: o | FV7: =UPPER(FO6)&".upd"&TEXT(FS5,"00") -> WG.upd42 | FW7: o | FX7: =UPPER(FW6)&".chk"&TEXT(FW5,"00") -> OPER.chk43 | FY7: o | FZ7: =UPPER(FW6)&".upd"&TEXT(FW5,"00") -> OPER.upd43 | GA7: o | GB7: =UPPER(FW6)&".chk"&TEXT(GA5,"00") -> OPER.chk44 | GC7: o | GD7: =UPPER(FW6)&".upd"&TEXT(GA5,"00") -> OPER.upd44 | GE7: o | GF7: =UPPER(GE6)&".chk"&TEXT(GE5,"00") -> WK_COST.chk45 | GG7: o | GH7: =UPPER(GE6)&".upd"&TEXT(GE5,"00") -> WK_COST.upd45 | GI7: o | GJ7: =UPPER(GE6)&".chk"&TEXT(GI5,"00") -> WK_COST.chk46 | GK7: o | GL7: =UPPER(GE6)&".upd"&TEXT(GI5,"00") -> WK_COST.upd46 | GM7: o | GN7: =UPPER(GM6)&".chk"&TEXT(GM5,"00") -> WK_RSN.chk47 | GO7: o | GP7: =UPPER(GM6)&".upd"&TEXT(GM5,"00") -> WK_RSN.upd47 | GQ7: o | GR7: =UPPER(GM6)&".chk"&TEXT(GQ5,"00") -> WK_RSN.chk48 | GS7: o | GT7: =UPPER(GM6)&".upd"&TEXT(GQ5,"00") -> WK_RSN.upd48 | GU7: o | GV7: =UPPER(GU6)&".chk"&TEXT(GU5,"00") -> SLS_UPRI_GRP.chk49 | GW7: o | GX7: =UPPER(GU6)&".upd"&TEXT(GU5,"00") -> SLS_UPRI_GRP.upd49 | GY7: o | GZ7: =UPPER(GU6)&".chk"&TEXT(GY5,"00") -> SLS_UPRI_GRP.chk50 | HA7: o | HB7: =UPPER(GU6)&".upd"&TEXT(GY5,"00") -> SLS_UPRI_GRP.upd50 | HC7: o | HD7: =UPPER(HC6)&".chk"&TEXT(HC5,"00") -> SLS_UPRI_RANK.chk51 | HE7: o | HF7: =UPPER(HC6)&".upd"&TEXT(HC5,"00") -> SLS_UPRI_RANK.upd51 | HG7: o | HH7: =UPPER(HC6)&".chk"&TEXT(HG5,"00") -> SLS_UPRI_RANK.chk52 | HI7: o | HJ7: =UPPER(HC6)&".upd"&TEXT(HG5,"00") -> SLS_UPRI_RANK.upd52 | HK7: o | HL7: =UPPER(HK6)&".chk"&TEXT(HK5,"00") -> SETOFF_GRP.chk53 | HM7: o | HN7: =UPPER(HK6)&".upd"&TEXT(HK5,"00") -> SETOFF_GRP.upd53 | HO7: o | HP7: =UPPER(HK6)&".chk"&TEXT(HO5,"00") -> SETOFF_GRP.chk54 | HQ7: o | HR7: =UPPER(HK6)&".upd"&TEXT(HO5,"00") -> SETOFF_GRP.upd54 | HS7: o | HT7: =UPPER(HS6)&".chk"&TEXT(HS5,"00") -> SHIP_VALID.chk55 | HU7: o | HV7: =UPPER(HS6)&".upd"&TEXT(HS5,"00") -> SHIP_VALID.upd55 | HW7: o | HX7: =UPPER(HS6)&".chk"&TEXT(HW5,"00") -> SHIP_VALID.chk56 | HY7: o | HZ7: =UPPER(HS6)&".upd"&TEXT(HW5,"00") -> SHIP_VALID.upd56 | IA7: o | IB7: =UPPER(IA6)&".chk"&TEXT(IA5,"00") -> ITM_SHIP_GRP.chk57 | IC7: o | ID7: =UPPER(IA6)&".upd"&TEXT(IA5,"00") -> ITM_SHIP_GRP.upd57 | IE7: o | IF7: =UPPER(IA6)&".chk"&TEXT(IE5,"00") -> ITM_SHIP_GRP.chk58 | IG7: o | IH7: =UPPER(IA6)&".upd"&TEXT(IE5,"00") -> ITM_SHIP_GRP.upd58 | II7: o | IJ7: =UPPER(II6)&".chk"&TEXT(II5,"00") -> TRNSPT.chk59 | IK7: o | IL7: =UPPER(II6)&".upd"&TEXT(II5,"00") -> TRNSPT.upd59 | IM7: o | IN7: =UPPER(II6)&".chk"&TEXT(IM5,"00") -> TRNSPT.chk60 | IO7: o | IP7: =UPPER(II6)&".upd"&TEXT(IM5,"00") -> TRNSPT.upd60 | IQ7: o | IR7: =UPPER(IQ6)&".chk"&TEXT(IQ5,"00") -> EX_CNTNR.chk61 | IS7: o | IT7: =UPPER(IQ6)&".upd"&TEXT(IQ5,"00") -> EX_CNTNR.upd61 | IU7: o | IV7: =UPPER(IQ6)&".chk"&TEXT(IU5,"00") -> EX_CNTNR.chk62 | IW7: o | IX7: =UPPER(IQ6)&".upd"&TEXT(IU5,"00") -> EX_CNTNR.upd62 | IY7: o | IZ7: =UPPER(IY6)&".chk"&TEXT(IY5,"00") -> EXIM_PORT.chk63 | JA7: o | JB7: =UPPER(IY6)&".upd"&TEXT(IY5,"00") -> EXIM_PORT.upd63 | JC7: o | JD7: =UPPER(IY6)&".chk"&TEXT(JC5,"00") -> EXIM_PORT.chk64 | JE7: o | JF7: =UPPER(IY6)&".upd"&TEXT(JC5,"00") -> EXIM_PORT.upd64 | JG7: o | JH7: =UPPER(JG6)&".chk"&TEXT(JG5,"00") -> STK_GD.chk65 | JI7: o | JJ7: =UPPER(JG6)&".upd"&TEXT(JG5,"00") -> STK_GD.upd65 | JK7: o | JL7: =UPPER(JG6)&".chk"&TEXT(JK5,"00") -> STK_GD.chk66 | JM7: o | JN7: =UPPER(JG6)&".upd"&TEXT(JK5,"00") -> STK_GD.upd66 | JO7: o | JP7: =UPPER(JO6)&".chk"&TEXT(JO5,"00") -> TRD.chk67 | JQ7: o | JR7: =UPPER(JO6)&".upd"&TEXT(JO5,"00") -> TRD.upd67 | JS7: o | JT7: =UPPER(JO6)&".chk"&TEXT(JS5,"00") -> TRD.chk68 | JU7: o | JV7: =UPPER(JO6)&".upd"&TEXT(JS5,"00") -> TRD.upd68 | JW7: o | JX7: =UPPER(JW6)&".chk"&TEXT(JW5,"00") -> SLIP_FORM.chk69 | JY7: o | JZ7: =UPPER(JW6)&".upd"&TEXT(JW5,"00") -> SLIP_FORM.upd69 | KA7: o | KB7: =UPPER(JW6)&".chk"&TEXT(KA5,"00") -> SLIP_FORM.chk70 | KC7: o | KD7: =UPPER(JW6)&".upd"&TEXT(KA5,"00") -> SLIP_FORM.upd70 | KE7: o | KF7: =UPPER(KE6)&".chk"&TEXT(KE5,"00") -> PF_GRP.chk71 | KG7: o | KH7: =UPPER(KE6)&".upd"&TEXT(KE5,"00") -> PF_GRP.upd71 | KI7: o | KJ7: =UPPER(KE6)&".chk"&TEXT(KI5,"00") -> PF_GRP.chk72 | KK7: o | KL7: =UPPER(KE6)&".upd"&TEXT(KI5,"00") -> PF_GRP.upd72 | KM7: o | KN7: =UPPER(KM6)&".chk"&TEXT(KM5,"00") -> ITM_SPEC_GRP.chk73 | KO7: o | KP7: =UPPER(KM6)&".upd"&TEXT(KM5,"00") -> ITM_SPEC_GRP.upd73 | KQ7: o | KR7: =UPPER(KM6)&".chk"&TEXT(KQ5,"00") -> ITM_SPEC_GRP.chk74 | KS7: o | KT7: =UPPER(KM6)&".upd"&TEXT(KQ5,"00") -> ITM_SPEC_GRP.upd74 | KU7: o | KV7: =UPPER(KU6)&".chk"&TEXT(KU5,"00") -> ITM_COMP_GRP.chk75 | KW7: o | KX7: =UPPER(KU6)&".upd"&TEXT(KU5,"00") -> ITM_COMP_GRP.upd75 | KY7: o | KZ7: =UPPER(KU6)&".chk"&TEXT(KY5,"00") -> ITM_COMP_GRP.chk76 | LA7: o | LB7: =UPPER(KU6)&".upd"&TEXT(KY5,"00") -> ITM_COMP_GRP.upd76 | LC7: o | LD7: =UPPER(LC6)&".chk"&TEXT(LC5,"00") -> JNL_ACT.chk77 | LE7: o | LF7: =UPPER(LC6)&".upd"&TEXT(LC5,"00") -> JNL_ACT.upd77 | LG7: o | LH7: =UPPER(LC6)&".chk"&TEXT(LG5,"00") -> JNL_ACT.chk78 | LI7: o | LJ7: =UPPER(LC6)&".upd"&TEXT(LG5,"00") -> JNL_ACT.upd78 | LK7: o | LL7: =UPPER(LK6)&".chk"&TEXT(LK5,"00") -> JNL_GRP.chk79 | LM7: o | LN7: =UPPER(LK6)&".upd"&TEXT(LK5,"00") -> JNL_GRP.upd79 | LO7: o | LP7: =UPPER(LK6)&".chk"&TEXT(LO5,"00") -> JNL_GRP.chk80 | LQ7: o | LR7: =UPPER(LK6)&".upd"&TEXT(LO5,"00") -> JNL_GRP.upd80 | LS7: o | LT7: =UPPER(LS6)&".chk"&TEXT(LS5,"00") -> JNL_PTN_BASE.chk81 | LU7: o | LV7: =UPPER(LS6)&".upd"&TEXT(LS5,"00") -> JNL_PTN_BASE.upd81 | LW7: o | LX7: =UPPER(LS6)&".chk"&TEXT(LW5,"00") -> JNL_PTN_BASE.chk82 | LY7: o | LZ7: =UPPER(LS6)&".upd"&TEXT(LW5,"00") -> JNL_PTN_BASE.upd82 | MA7: o | MB7: =UPPER(MA6)&".chk"&TEXT(MA5,"00") -> AUTO_JNL_KEY.chk83 | MC7: o | MD7: =UPPER(MA6)&".upd"&TEXT(MA5,"00") -> AUTO_JNL_KEY.upd83 | ME7: o | MF7: =UPPER(MA6)&".chk"&TEXT(ME5,"00") -> AUTO_JNL_KEY.chk84 | MG7: o | MH7: =UPPER(MA6)&".upd"&TEXT(ME5,"00") -> AUTO_JNL_KEY.upd84 | MI7: o | MJ7: =UPPER(MI6)&".chk"&TEXT(MI5,"00") -> INSP_PTN.chk85 | MK7: o | ML7: =UPPER(MI6)&".upd"&TEXT(MI5,"00") -> INSP_PTN.upd85 | MM7: o | MN7: =UPPER(MI6)&".chk"&TEXT(MM5,"00") -> INSP_PTN.chk86 | MO7: o | MP7: =UPPER(MI6)&".upd"&TEXT(MM5,"00") -> INSP_PTN.upd86 | MQ7: o | MR7: =UPPER(MQ6)&".chk"&TEXT(MQ5,"00") -> WK_DAY.chk87 | MS7: o | MT7: =UPPER(MQ6)&".upd"&TEXT(MQ5,"00") -> WK_DAY.upd87 | MU7: o | MV7: =UPPER(MQ6)&".chk"&TEXT(MU5,"00") -> WK_DAY.chk88 | MW7: o | MX7: =UPPER(MQ6)&".upd"&TEXT(MU5,"00") -> WK_DAY.upd88 | MY7: o | MZ7: =UPPER(MY6)&".chk"&TEXT(MY5,"00") -> SHIP_TERM.chk89 | NA7: o | NB7: =UPPER(MY6)&".upd"&TEXT(MY5,"00") -> SHIP_TERM.upd89 | NC7: o | ND7: =UPPER(MY6)&".chk"&TEXT(NC5,"00") -> SHIP_TERM.chk90 | NE7: o | NF7: =UPPER(MY6)&".upd"&TEXT(NC5,"00") -> SHIP_TERM.upd90 | NG7: o | NH7: =UPPER(NG6)&".chk"&TEXT(NG5,"00") -> SHIP_WK.chk91 | NI7: o | NJ7: =UPPER(NG6)&".upd"&TEXT(NG5,"00") -> SHIP_WK.upd91 | NK7: o | NL7: =UPPER(NG6)&".chk"&TEXT(NK5,"00") -> SHIP_WK.chk92 | NM7: o | NN7: =UPPER(NG6)&".upd"&TEXT(NK5,"00") -> SHIP_WK.upd92 | NO7: o | NP7: =UPPER(NO6)&".chk"&TEXT(NO5,"00") -> RSRC.chk93 | NQ7: o | NR7: =UPPER(NO6)&".upd"&TEXT(NO5,"00") -> RSRC.upd93 | NS7: o | NT7: =UPPER(NO6)&".chk"&TEXT(NS5,"00") -> RSRC.chk94 | NU7: o | NV7: =UPPER(NO6)&".upd"&TEXT(NS5,"00") -> RSRC.upd94 | NW7: o | NX7: =UPPER(NW6)&".chk"&TEXT(NW5,"00") -> HS_GRP.chk95 | NY7: o | NZ7: =UPPER(NW6)&".upd"&TEXT(NW5,"00") -> HS_GRP.upd95 | OA7: o | OB7: =UPPER(NW6)&".chk"&TEXT(OA5,"00") -> HS_GRP.chk96 | OC7: o | OD7: =UPPER(NW6)&".upd"&TEXT(OA5,"00") -> HS_GRP.upd96 | OE7: o | OF7: =UPPER(OE6)&".chk"&TEXT(OE5,"00") -> ALC_PTN.chk97 | OG7: o | OH7: =UPPER(OE6)&".upd"&TEXT(OE5,"00") -> ALC_PTN.upd97 | OI7: o | OJ7: =UPPER(OE6)&".chk"&TEXT(OI5,"00") -> ALC_PTN.chk98 | OK7: o | OL7: =UPPER(OE6)&".upd"&TEXT(OI5,"00") -> ALC_PTN.upd98 | OM7: o | ON7: =UPPER(OM6)&".chk"&TEXT(OM5,"00") -> CTG_GRP.chk99 | OO7: o | OP7: =UPPER(OM6)&".upd"&TEXT(OM5,"00") -> CTG_GRP.upd99 | OQ7: o | OR7: =UPPER(OM6)&".chk"&TEXT(OQ5,"00") -> CTG_GRP.chk100 | OS7: o | OT7: =UPPER(OM6)&".upd"&TEXT(OQ5,"00") -> CTG_GRP.upd100 | OU7: o | OV7: =UPPER(OU6)&".chk"&TEXT(OU5,"00") -> ACT_PTN.chk101 | OW7: o | OX7: =UPPER(OU6)&".upd"&TEXT(OU5,"00") -> ACT_PTN.upd101 | OY7: o | OZ7: =UPPER(OU6)&".chk"&TEXT(OY5,"00") -> ACT_PTN.chk102 | PA7: o | PB7: =UPPER(OU6)&".upd"&TEXT(OY5,"00") -> ACT_PTN.upd102 | PC7: o | PD7: =UPPER(PC6)&".chk"&TEXT(PC5,"00") -> GP_ALC.chk103 | PE7: o | PF7: =UPPER(PC6)&".upd"&TEXT(PC5,"00") -> GP_ALC.upd103 | PG7: o | PH7: =UPPER(PC6)&".chk"&TEXT(PG5,"00") -> GP_ALC.chk104 | PI7: o | PJ7: =UPPER(PC6)&".upd"&TEXT(PG5,"00") -> GP_ALC.upd104 | PK7: o | PL7: =UPPER(PK6)&".chk"&TEXT(PK5,"00") -> CALC_CTG.chk105 | PM7: o | PN7: =UPPER(PK6)&".upd"&TEXT(PK5,"00") -> CALC_CTG.upd105 | PO7: o | PP7: =UPPER(PK6)&".chk"&TEXT(PO5,"00") -> CALC_CTG.chk106 | PQ7: o | PR7: =UPPER(PK6)&".upd"&TEXT(PO5,"00") -> CALC_CTG.upd106 | PS7: o | PT7: =UPPER(PS6)&".chk"&TEXT(PS5,"00") -> RPT_PTN.chk107 | PU7: o | PV7: =UPPER(PS6)&".upd"&TEXT(PS5,"00") -> RPT_PTN.upd107 | PW7: o | PX7: =UPPER(PS6)&".chk"&TEXT(PW5,"00") -> RPT_PTN.chk108 | PY7: o | PZ7: =UPPER(PS6)&".upd"&TEXT(PW5,"00") -> RPT_PTN.upd108 | QA7: o | QB7: =UPPER(QA6)&".chk"&TEXT(QA5,"00") -> COST_MENU.chk109 | QC7: o | QD7: =UPPER(QA6)&".upd"&TEXT(QA5,"00") -> COST_MENU.upd109 | QE7: o | QF7: =UPPER(QA6)&".chk"&TEXT(QE5,"00") -> COST_MENU.chk110 | QG7: o | QH7: =UPPER(QA6)&".upd"&TEXT(QE5,"00") -> COST_MENU.upd110 | QI7: o | QJ7: =UPPER(QI6)&".chk"&TEXT(QI5,"00") -> SITE_CO.chk111 | QK7: o | QL7: =UPPER(QI6)&".upd"&TEXT(QI5,"00") -> SITE_CO.upd111 | QM7: o | QN7: =UPPER(QI6)&".chk"&TEXT(QM5,"00") -> SITE_CO.chk112 | QO7: o | QP7: =UPPER(QI6)&".upd"&TEXT(QM5,"00") -> SITE_CO.upd112
