Workbook

Sheet LogicCommon
A2: オペレーション実装仕様書 | B2: ModuleID : | C2: MG | D2: LogicID : | E2: MGBGL0200 | F2: Pj.ID : | G2: MC
B3: SubModuleID : | C3: MGBG | D3: LogicClass : | E3: MGBGL_AlcRateReg | F3: SuperClassPj.ID :
D4: LogicName : | E4: 予定配賦率登録 | F4: SuperLogicID : | G4: MG.MGUDL5010
A5: 概要 :
A6: 詳細 :

Sheet Srch01
A1: * | B1: * | D1: L | E1: 1
A2: * | D2: オペレーション実装仕様書 Operation Specification Implementation Sheet | E2: ModuleID : | F2: =IF(LogicCommon!C2="","",LogicCommon!C2) -> MG | G2: LogicID : | H2: =IF(LogicCommon!E2="","",LogicCommon!E2) -> MGBGL0200 | I2: Ope.ID : | J2: Srch01 | K2: Pj.ID : | L2: =IF(LogicCommon!G2="","",LogicCommon!G2) -> MC | M2: Ope.Body : | N2: "mcframe.serverMAUD.MAUDL5010.MAUDL_Searcher"
A3: * | D3: =IF(LogicCommon!A3="","",LogicCommon!A3) | E3: SubModuleID : | F3: =IF(LogicCommon!C3="","",LogicCommon!C3) -> MGBG | G3: LogicClass : | H3: =IF(LogicCommon!E3="","",LogicCommon!E3) -> MGBGL_AlcRateReg | I3: Ope.Method : | J3: @ | K3: SuperClassPj.ID : | L3: =IF(LogicCommon!G3="","",LogicCommon!G3) | O3: Gene.Type : | P3: ALL
A4: * | E4: Version : | F4: 000000 | G4: LogicName : | H4: =IF(LogicCommon!E4="","",LogicCommon!E4) -> 予定配賦率登録 | I4: Ope.Name : | J4: 検索 | K4: SuperLogicID : | L4: =IF(LogicCommon!G4="","",LogicCommon!G4) -> MG.MGUDL5010 | M4: ImplOpe.ID:
A5: * | E5: ACType :
A6: * | D6: 概要 : | E6: 検索処理をする | N6: ID | P6: ID | R6: ID
A7: # | I7: U | K7: K | M7: o | O7: o | Q7: o
A8: # | D8: ブロック名 Block Name | E8: 型 Type | G8: super/share | H8: 対象ブロック名 Target Block Name | K8: CONST | M8: TargetName | O8: TargetName | Q8: TargetName | U8: ブロック備考 Block Remarks
A9: # | D9: 項目名 Field Name | E9: 型 Type | F9: 桁 Digits | G9: フルネーム Full Name | H9: 日本語名 Japanese Name | I9: 上り項目 Request Message Field | J9: 下り項目 Response Message Field | S9: 条件および編集方法 Conditions and Editing Methods | U9: 項目備考 Field Remarks
A10: # | M10: 上り項目 Request Message Field | N10: 下り項目 Response Message Field | O10: 上り項目 Request Message Field | P10: 下り項目 Response Message Field | Q10: 上り項目 Request Message Field | R10: 下り項目 Response Message Field
A11: 10 | B11: * | D11: Srch01_Cnd | E11: R
A12: 10 | D12: calc_ctg_cd | E12: #MA.CALC_CTG_CD | G12: Calculation category cd. | H12: 計算カテゴリＣＤ | I12: E | J12: -
A13: 10 | D13: calc_ctg_nm | E13: #MA.CALC_CTG_NM | G13: Calculation category name | H13: 計算カテゴリ名 | I13: E | J13: -
A14: 10 | D14: wg_cd | E14: #MA.WG_CD | G14: WG cd. | H14: ワーキンググループＣＤ | I14: E | J14: -
A15: 10 | D15: wg_nm | E15: #MA.WG_NM | G15: WG name | H15: ワーキンググループ名 | I15: E | J15: -
A16: 10 | D16: ym_fr | E16: #MA.YM | G16: Month FROM | H16: 年月ＦＲＯＭ | I16: E | J16: -
A17: 10 | D17: ym_to | E17: #MA.YM | G17: Month TO | H17: 年月ＴＯ | I17: E | J17: -
A18: 10 | D18: alc_ac_cd | E18: #MA.ALC_AC_CD | G18: Allocation account cd. | H18: 配賦科目ＣＤ | I18: E | J18: -
A19: 10 | D19: alc_ac_nm | E19: #MA.ALC_AC_NM | G19: Allocation account name | H19: 配賦科目名 | I19: E | J19: -
A20: 10 | D20: alc_ac_grp_cd1 | E20: #MA.ALC_AC_GRP_CD | G20: Allocation account group cd. 1 | H20: 配賦科目グループＣＤ１ | I20: E | J20: -
A21: 10 | D21: alc_ac_grp_nm1 | E21: #MA.ALC_AC_GRP_NM | G21: Allocation account group name 1 | H21: 配賦科目グループ名１ | I21: E | J21: -
A22: 10 | D22: alc_ac_grp_cd2 | E22: #MA.ALC_AC_GRP_CD | G22: Allocation account group cd. 2 | H22: 配賦科目グループＣＤ２ | I22: E | J22: -
A23: 10 | D23: alc_ac_grp_nm2 | E23: #MA.ALC_AC_GRP_NM | G23: Allocation account group name 2 | H23: 配賦科目グループ名２ | I23: E | J23: -
... A59: 10 | D59: no_calc_flg | E59: #MA.FLG | G59: Not to calculate | H59: 計算対象外 | I59: E | J59: -
M60: 上り項目 Request Message Field | N60: 下り項目 Response Message Field | O60: 上り項目 Request Message Field | P60: 下り項目 Response Message Field | Q60: 上り項目 Request Message Field | R60: 下り項目 Response Message Field
A61: 20 | B61: * | D61: Srch01_Rslt | E61: L
A62: 20 | D62: calc_ctg_cd | E62: #MA.CALC_CTG_CD | G62: Calculation category cd. | H62: 計算カテゴリＣＤ | I62: - | J62: E
A63: 20 | D63: calc_ctg_nm | E63: #MA.CALC_CTG_NM | G63: Calculation category name | H63: 計算カテゴリ名 | I63: - | J63: E
A64: 20 | D64: wg_cd | E64: #MA.WG_CD | G64: WG cd. | H64: ワーキンググループＣＤ | I64: - | J64: E
A65: 20 | D65: wg_nm | E65: #MA.WG_NM | G65: WG name | H65: ワーキンググループ名 | I65: - | J65: E
A66: 20 | D66: ym | E66: #MA.YM | G66: Year month | H66: 年月 | I66: - | J66: E
A67: 20 | D67: alc_ac_cd | E67: #MA.ALC_AC_CD | G67: Allocation account cd. | H67: 配賦科目ＣＤ | I67: - | J67: E
A68: 20 | D68: alc_ac_nm | E68: #MA.ALC_AC_NM | G68: Allocation account name | H68: 配賦科目名 | I68: - | J68: E
A69: 20 | D69: dpt_cd | E69: #MA.COST_DPT_CD | G69: Dept. cd. | H69: 部門ＣＤ | I69: - | J69: E
A70: 20 | D70: dpt_nm | E70: #MA.COST_DPT_NM | G70: Dept. name | H70: 部門名 | I70: - | J70: E
A71: 20 | D71: loc_cd | E71: #MA.LOC_CD | G71: Location cd. | H71: 場所ＣＤ | I71: - | J71: E
A72: 20 | D72: loc_nm | E72: #MA.LOC_NM | G72: Location name | H72: 場所名 | I72: - | J72: E
A73: 20 | D73: oper_cd | E73: #MA.OPER_CD | G73: Operation cd. | H73: 工程ＣＤ | I73: - | J73: E
... A83: 20 | D83: itm_nm | E83: #MA.ITM_NM | G83: Item name | H83: 品名 | I83: - | J83: E
A84: 20 | D84: itm_typ | E84: #MA.ITM_TYP | G84: Item type | H84: 品目区分 | I84: - | J84: E | K84: MAC_ITM_TYP
...

Sheet Chk01
A1: * | B1: * | D1: L | E1: 1
A2: * | D2: オペレーション実装仕様書 Operation Specification Implementation Sheet | E2: ModuleID : | F2: =IF(LogicCommon!C2="","",LogicCommon!C2) -> MG | G2: LogicID : | H2: =IF(LogicCommon!E2="","",LogicCommon!E2) -> MGBGL0200 | I2: Ope.ID : | J2: Chk01 | K2: Pj.ID : | L2: =IF(LogicCommon!G2="","",LogicCommon!G2) -> MC | M2: Ope.Body : | N2: MA.MAUDL5010.Checker
A3: * | D3: =IF(LogicCommon!A3="","",LogicCommon!A3) | E3: SubModuleID : | F3: =IF(LogicCommon!C3="","",LogicCommon!C3) -> MGBG | G3: LogicClass : | H3: =IF(LogicCommon!E3="","",LogicCommon!E3) -> MGBGL_AlcRateReg | I3: Ope.Method : | J3: @ | K3: SuperClassPj.ID : | L3: =IF(LogicCommon!G3="","",LogicCommon!G3) | O3: Gene.Type : | P3: ALL
A4: * | E4: Version : | F4: 000000 | G4: LogicName : | H4: =IF(LogicCommon!E4="","",LogicCommon!E4) -> 予定配賦率登録 | I4: Ope.Name : | J4: 登録・訂正前チェック | K4: SuperLogicID : | L4: =IF(LogicCommon!G4="","",LogicCommon!G4) -> MG.MGUDL5010 | M4: ImplOpe.ID:
A5: * | E5: ACType :
A6: * | D6: 概要 : | E6: 登録・訂正する前のチェックを行う | AD6: ID | AF6: ID | AH6: ID
A7: # | I7: U | K7: K | L7: K | M7: K | N7: K | O7: K | P7: K | Q7: K | R7: K | S7: K | T7: K | U7: K | V7: K | W7: K | X7: K | Y7: K | Z7: K | AA7: K | AB7: K | AC7: o | AE7: o | AG7: o
A8: # | D8: ブロック名 Block Name | E8: 型 Type | G8: super/share | H8: 対象ブロック名 Target Block Name | K8: REQ_UPD_CNT_CHK | L8: REQUIRED | M8: CHK_NUM | N8: SMALL_LARGE | O8: CHK_DT | P8: BEFORE_AFTER | Q8: CHK_PTN | R8: DUPLICATE | S8: TOO_MANY_INPUTS | T8: AT_LEAST_ONE | U8: ONLY_ONE_INPUT | V8: LIST_LOGIC | W8: LIST_OUT | X8: LIST_OUT_BASE | Y8: LIST_IN | Z8: LIST_IN_BASE | AA8: CONST | AB8: NULL_VAL | AC8: TargetName | AE8: TargetName | AG8: TargetName | AK8: ブロック備考 Block Remarks
A9: # | D9: 項目名 Field Name | E9: 型 Type | F9: 桁 Digits | G9: フルネーム Full Name | H9: 日本語名 Japanese Name | I9: 上り項目 Request Message Field | J9: 下り項目 Response Message Field | AI9: 条件および編集方法 Conditions and Editing Methods | AK9: 項目備考 Field Remarks
A10: # | AC10: 上り項目 Request Message Field | AD10: 下り項目 Response Message Field | AE10: 上り項目 Request Message Field | AF10: 下り項目 Response Message Field | AG10: 上り項目 Request Message Field | AH10: 下り項目 Response Message Field
A11: 10 | B11: * | D11: Chk01_Rslt | E11: L
A12: 10 | D12: peg_no | E12: #MA.INT | G12: Pegging No. | H12: 紐付けＮＯ | I12: E | J12: E
A13: 10 | D13: err_flg | E13: #MA.FLG | G13: Error | H13: エラー | I13: - | J13: E
A14: 10 | D14: rtn_sts_typ | E14: #MA.RTN_STS_TYP | G14: Process result status type | H14: 処理結果状況区分 | I14: - | J14: E
A15: 10 | D15: dbc | E15: R | F15: DBC:MGT_ALC_RATE
A16: 10 | D16: dbc.calc_ctg_cd# | E16: RI | G16: Calculation category cd. | H16: 計算カテゴリＣＤ | I16: E | J16: E | K16: I,U | R16: Key | V16: MA.MAUAL0010.CalcCtg | W16: calc_ctg_nm
A17: 10 | D17: dbc.wg_cd# | E17: RI | G17: WG cd. | H17: ワーキンググループＣＤ | I17: E | J17: E | K17: I,U | R17: Key | V17: MA.MAUAL0010.CostWg | W17: wg_nm
A18: 10 | D18: dbc.ym# | E18: RI | G18: Year month | H18: 年月 | I18: E | J18: E | K18: I,U | R18: Key
A19: 10 | D19: dbc.alc_ac_cd# | E19: RI | G19: Allocation account cd. | H19: 配賦科目ＣＤ | I19: E | J19: E | K19: I,U | R19: Key | V19: MA.MAUAL0010.AlcAc | W19: alc_ac_nm
A20: 10 | D20: dbc.dpt_cd# | E20: RI | G20: Dept. cd. | H20: 部門ＣＤ | I20: E | J20: E | R20: Key | V20: MA.MAUAL0010.CostDpt | W20: dpt_nm | Y20: ym | Z20: ym
A21: 10 | D21: dbc.loc_cd# | E21: RI | G21: Location cd. | H21: 場所ＣＤ | I21: E | J21: E | R21: Key | V21: MA.MAUAL0010.Loc | W21: loc_nm | Y21: MAC_LOC_IS_SRCH_TYP.MFG_WG_ALL | Z21: loc_is_srch_typ
A22: 10 | D22: dbc.oper_cd# | E22: RI | G22: Operation cd. | H22: 工程ＣＤ | I22: E | J22: E | R22: Key | V22: MA.MAUAL0010.Oper | W22: oper_nm
A23: 10 | D23: dbc.bp_cd# | E23: RI | G23: BP cd. | H23: 取引先ＣＤ | I23: E | J23: E | R23: Key | V23: MA.MAUAL0010.Bp | W23: bp_nm | Y23: MAC_BP_IS_SRCH_TYP.COMM | Z23: bp_is_srch_typ
A24: 10 | D24: dbc.ctg_cd# | E24: RI | G24: Item category cd. | H24: 品群ＣＤ | I24: E | J24: E | R24: Key | V24: MA.MAUAL0010.CostCtg | W24: ctg_nm
A25: 10 | D25: dbc.itm_cd# | E25: RI | G25: Item cd. | H25: 品目ＣＤ | I25: E | J25: E | R25: Key
A26: 10 | D26: dbc.itm_sub1# | E26: RI | G26: Branch No. 1 | H26: 枝番１ | I26: E | J26: E | R26: Key | AB26: E
A27: 10 | D27: dbc.itm_sub2# | E27: RI | G27: Branch No. 2 | H27: 枝番２ | I27: E | J27: E | R27: Key | AB27: E
A28: 10 | D28: dbc.itm_sub3# | E28: RI | G28: Branch No. 3 | H28: 枝番３ | I28: E | J28: E | R28: Key | V28: MA.MAUAL0010.ItmSub3 | W28: itm_nm;itm_typ;itm_typ_nm;itm_typ_d_cd;itm_typ_d_nm | Y28: MAC_ITM_IS_SRCH_TYP.NOT_ASSET3;itm_cd;itm_sub1;itm_sub2 | Z28: itm_is_srch_typ;itm_cd;itm_sub1;itm_sub2 | AB28: E
A29: 10 | D29: dbc.lot_no# | E29: RI | G29: Lot No. | H29: ロットＮＯ | I29: E | J29: E | R29: Key
A30: 10 | D30: dbc.sublot_no# | E30: RI | G30: Sublot No. | H30: サブロットＮＯ | I30: E | J30: E | R30: Key
A31: 10 | D31: dbc.sno1# | E31: RI | G31: SEIBAN No. 1 | H31: 手配ＮＯ１ | I31: E | J31: E | R31: Key
A32: 10 | D32: dbc.sno2# | E32: RI | G32: SEIBAN No. 2 | H32: 手配ＮＯ２ | I32: E | J32: E | R32: Key
A33: 10 | D33: dbc.sno3# | E33: RI | G33: SEIBAN No. 3 | H33: 手配ＮＯ３ | I33: E | J33: E | R33: Key
A34: 10 | D34: dbc.sno4# | E34: RI | G34: SEIBAN No. 4 | H34: 手配ＮＯ４ | I34: E | J34: E | R34: Key
A35: 10 | D35: dbc.itm_mfg_inst_no# | E35: RI | G35: Item mfg. order No. | H35: 品目製造指図ＮＯ | I35: E | J35: E | R35: Key
A36: 10 | D36: dbc.iv_no# | E36: RI | G36: Invoice No. | H36: インボイスＮＯ | I36: E | J36: E | R36: Key
A37: 10 | D37: dbc.po_no# | E37: RI | G37: PO No. | H37: 発注ＮＯ | I37: E | J37: E | R37: Key
A38: 10 | D38: dbc.slo_no# | E38: RI | G38: Sales order No. | H38: 受注ＮＯ | I38: E | J38: E | R38: Key
A39: 10 | D39: dbc.alc_rate# | E39: RI | G39: Allocation rate | H39: 配賦率 | I39: E | J39: E | L39: E | M39: notZero
A40: 10 | D40: dbc.no_calc_flg# | E40: RI | G40: Not to calculate | H40: 計算対象外 | I40: E | J40: E | L40: E
...

Sheet Chk02
A1: * | B1: * | D1: L | E1: 1
A2: * | D2: オペレーション実装仕様書 Operation Specification Implementation Sheet | E2: ModuleID : | F2: =IF(LogicCommon!C2="","",LogicCommon!C2) -> MG | G2: LogicID : | H2: =IF(LogicCommon!E2="","",LogicCommon!E2) -> MGBGL0200 | I2: Ope.ID : | J2: Chk02 | K2: Pj.ID : | L2: =IF(LogicCommon!G2="","",LogicCommon!G2) -> MC | M2: Ope.Body : | N2: MA.MAUDL5010.Checker
A3: * | D3: =IF(LogicCommon!A3="","",LogicCommon!A3) | E3: SubModuleID : | F3: =IF(LogicCommon!C3="","",LogicCommon!C3) -> MGBG | G3: LogicClass : | H3: =IF(LogicCommon!E3="","",LogicCommon!E3) -> MGBGL_AlcRateReg | I3: Ope.Method : | J3: @ | K3: SuperClassPj.ID : | L3: =IF(LogicCommon!G3="","",LogicCommon!G3) | O3: Gene.Type : | P3: ALL
A4: * | E4: Version : | F4: 000000 | G4: LogicName : | H4: =IF(LogicCommon!E4="","",LogicCommon!E4) -> 予定配賦率登録 | I4: Ope.Name : | J4: 削除前チェック | K4: SuperLogicID : | L4: =IF(LogicCommon!G4="","",LogicCommon!G4) -> MG.MGUDL5010 | M4: ImplOpe.ID:
A5: * | E5: ACType :
A6: * | D6: 概要 : | E6: 削除する前のチェックを行う | AD6: ID | AF6: ID | AH6: ID
A7: # | I7: U | K7: K | L7: K | M7: K | N7: K | O7: K | P7: K | Q7: K | R7: K | S7: K | T7: K | U7: K | V7: K | W7: K | X7: K | Y7: K | Z7: K | AA7: K | AB7: K | AC7: o | AE7: o | AG7: o
A8: # | D8: ブロック名 Block Name | E8: 型 Type | G8: super/share | H8: 対象ブロック名 Target Block Name | K8: REQ_UPD_CNT_CHK | L8: REQUIRED | M8: CHK_NUM | N8: SMALL_LARGE | O8: CHK_DT | P8: BEFORE_AFTER | Q8: CHK_PTN | R8: DUPLICATE | S8: TOO_MANY_INPUTS | T8: AT_LEAST_ONE | U8: ONLY_ONE_INPUT | V8: LIST_LOGIC | W8: LIST_OUT | X8: LIST_OUT_BASE | Y8: LIST_IN | Z8: LIST_IN_BASE | AA8: CONST | AB8: NULL_VAL | AC8: TargetName | AE8: TargetName | AG8: TargetName | AK8: ブロック備考 Block Remarks
A9: # | D9: 項目名 Field Name | E9: 型 Type | F9: 桁 Digits | G9: フルネーム Full Name | H9: 日本語名 Japanese Name | I9: 上り項目 Request Message Field | J9: 下り項目 Response Message Field | AI9: 条件および編集方法 Conditions and Editing Methods | AK9: 項目備考 Field Remarks
A10: # | AC10: 上り項目 Request Message Field | AD10: 下り項目 Response Message Field | AE10: 上り項目 Request Message Field | AF10: 下り項目 Response Message Field | AG10: 上り項目 Request Message Field | AH10: 下り項目 Response Message Field
A11: 10 | B11: * | D11: Chk02_Rslt | E11: L
A12: 10 | D12: peg_no | E12: #MA.INT | G12: Pegging No. | H12: 紐付けＮＯ | I12: E | J12: E
A13: 10 | D13: err_flg | E13: #MA.FLG | G13: Error | H13: エラー | I13: - | J13: E
A14: 10 | D14: rtn_sts_typ | E14: #MA.RTN_STS_TYP | G14: Process result status type | H14: 処理結果状況区分 | I14: - | J14: E
A15: 10 | D15: dbc | E15: R | F15: DBC:MGT_ALC_RATE
A16: 10 | D16: dbc.calc_ctg_cd# | E16: RI | G16: Calculation category cd. | H16: 計算カテゴリＣＤ | I16: E | J16: E | K16: E
A17: 10 | D17: dbc.wg_cd# | E17: RI | G17: WG cd. | H17: ワーキンググループＣＤ | I17: E | J17: E | K17: E
A18: 10 | D18: dbc.ym# | E18: RI | G18: Year month | H18: 年月 | I18: E | J18: E | K18: E
A19: 10 | D19: dbc.alc_ac_cd# | E19: RI | G19: Allocation account cd. | H19: 配賦科目ＣＤ | I19: E | J19: E | K19: E
A20: 10 | D20: dbc.dpt_cd# | E20: RI | G20: Dept. cd. | H20: 部門ＣＤ | I20: E | J20: E
A21: 10 | D21: dbc.loc_cd# | E21: RI | G21: Location cd. | H21: 場所ＣＤ | I21: E | J21: E
A22: 10 | D22: dbc.oper_cd# | E22: RI | G22: Operation cd. | H22: 工程ＣＤ | I22: E | J22: E
A23: 10 | D23: dbc.bp_cd# | E23: RI | G23: BP cd. | H23: 取引先ＣＤ | I23: E | J23: E
A24: 10 | D24: dbc.ctg_cd# | E24: RI | G24: Item category cd. | H24: 品群ＣＤ | I24: E | J24: E
A25: 10 | D25: dbc.itm_cd# | E25: RI | G25: Item cd. | H25: 品目ＣＤ | I25: E | J25: E
A26: 10 | D26: dbc.itm_sub1# | E26: RI | G26: Branch No. 1 | H26: 枝番１ | I26: E | J26: E
A27: 10 | D27: dbc.itm_sub2# | E27: RI | G27: Branch No. 2 | H27: 枝番２ | I27: E | J27: E
A28: 10 | D28: dbc.itm_sub3# | E28: RI | G28: Branch No. 3 | H28: 枝番３ | I28: E | J28: E
A29: 10 | D29: dbc.lot_no# | E29: RI | G29: Lot No. | H29: ロットＮＯ | I29: E | J29: E
A30: 10 | D30: dbc.sublot_no# | E30: RI | G30: Sublot No. | H30: サブロットＮＯ | I30: E | J30: E
A31: 10 | D31: dbc.sno1# | E31: RI | G31: SEIBAN No. 1 | H31: 手配ＮＯ１ | I31: E | J31: E
... A39: 10 | D39: dbc.upd_cntr# | E39: RI | G39: Update counter | H39: 更新カウンタ | I39: E | J39: E
D40: 詳細 :

Sheet Chk03
A1: * | B1: * | D1: L | E1: 1
A2: * | D2: オペレーション実装仕様書 Operation Specification Implementation Sheet | E2: ModuleID : | F2: =IF(LogicCommon!C2="","",LogicCommon!C2) -> MG | G2: LogicID : | H2: =IF(LogicCommon!E2="","",LogicCommon!E2) -> MGBGL0200 | I2: Ope.ID : | J2: Chk03 | K2: Pj.ID : | L2: =IF(LogicCommon!G2="","",LogicCommon!G2) -> MC | M2: Ope.Body : | N2: MA.MAUDL5010.Checker
A3: * | D3: =IF(LogicCommon!A3="","",LogicCommon!A3) | E3: SubModuleID : | F3: =IF(LogicCommon!C3="","",LogicCommon!C3) -> MGBG | G3: LogicClass : | H3: =IF(LogicCommon!E3="","",LogicCommon!E3) -> MGBGL_AlcRateReg | I3: Ope.Method : | J3: @ | K3: SuperClassPj.ID : | L3: =IF(LogicCommon!G3="","",LogicCommon!G3) | O3: Gene.Type : | P3: ALL
A4: * | E4: Version : | F4: 000000 | G4: LogicName : | H4: =IF(LogicCommon!E4="","",LogicCommon!E4) -> 予定配賦率登録 | I4: Ope.Name : | J4: 一括削除前チェック | K4: SuperLogicID : | L4: =IF(LogicCommon!G4="","",LogicCommon!G4) -> MG.MGUDL5010 | M4: ImplOpe.ID:
A5: * | E5: ACType :
A6: * | D6: 概要 : | E6: 一括削除する前のチェックを行う | AD6: ID | AF6: ID | AH6: ID
A7: # | I7: U | K7: K | L7: K | M7: K | N7: K | O7: K | P7: K | Q7: K | R7: K | S7: K | T7: K | U7: K | V7: K | W7: K | X7: K | Y7: K | Z7: K | AA7: K | AB7: K | AC7: o | AE7: o | AG7: o
A8: # | D8: ブロック名 Block Name | E8: 型 Type | G8: super/share | H8: 対象ブロック名 Target Block Name | K8: REQ_UPD_CNT_CHK | L8: REQUIRED | M8: CHK_NUM | N8: SMALL_LARGE | O8: CHK_DT | P8: BEFORE_AFTER | Q8: CHK_PTN | R8: DUPLICATE | S8: TOO_MANY_INPUTS | T8: AT_LEAST_ONE | U8: ONLY_ONE_INPUT | V8: LIST_LOGIC | W8: LIST_OUT | X8: LIST_OUT_BASE | Y8: LIST_IN | Z8: LIST_IN_BASE | AA8: CONST | AB8: NULL_VAL | AC8: TargetName | AE8: TargetName | AG8: TargetName | AK8: ブロック備考 Block Remarks
A9: # | D9: 項目名 Field Name | E9: 型 Type | F9: 桁 Digits | G9: フルネーム Full Name | H9: 日本語名 Japanese Name | I9: 上り項目 Request Message Field | J9: 下り項目 Response Message Field | AI9: 条件および編集方法 Conditions and Editing Methods | AK9: 項目備考 Field Remarks
A10: # | AC10: 上り項目 Request Message Field | AD10: 下り項目 Response Message Field | AE10: 上り項目 Request Message Field | AF10: 下り項目 Response Message Field | AG10: 上り項目 Request Message Field | AH10: 下り項目 Response Message Field
A11: 10 | B11: * | D11: Chk03_Cnd | E11: R
A12: 10 | D12: calc_ctg_cd | E12: #MA.CALC_CTG_CD | G12: Calculation category cd. | H12: 計算カテゴリＣＤ | I12: E | J12: E | L12: E
A13: 10 | D13: wg_cd | E13: #MA.WG_CD | G13: WG cd. | H13: ワーキンググループＣＤ | I13: E | J13: E | L13: E
A14: 10 | D14: ym_fr | E14: #MA.YM | G14: Month FROM | H14: 年月ＦＲＯＭ | I14: E | J14: E | L14: E | P14: ym:BF
A15: 10 | D15: ym_to | E15: #MA.YM | G15: Month TO | H15: 年月ＴＯ | I15: E | J15: E | L15: E | P15: ym:AF
A16: 10 | D16: alc_ac_cd | E16: C | G16: Allocation account cd. | H16: 配賦科目ＣＤ | I16: E | J16: E
A17: 10 | D17: dpt_cd | E17: C | G17: Dept. cd. | H17: 部門ＣＤ | I17: E | J17: E
D18: 詳細 :

Sheet Imp01
A1: * | B1: * | D1: L | E1: 1
A2: * | D2: オペレーション実装仕様書 Operation Specification Implementation Sheet | E2: ModuleID : | F2: =IF(LogicCommon!C2="","",LogicCommon!C2) -> MG | G2: LogicID : | H2: =IF(LogicCommon!E2="","",LogicCommon!E2) -> MGBGL0200 | I2: Ope.ID : | J2: Imp01 | K2: Pj.ID : | L2: =IF(LogicCommon!G2="","",LogicCommon!G2) -> MC | M2: Ope.Body : | N2: "mcframe.serverMAUD.MAUDL5010.MAUDL_Operation"
A3: * | D3: =IF(LogicCommon!A3="","",LogicCommon!A3) | E3: SubModuleID : | F3: =IF(LogicCommon!C3="","",LogicCommon!C3) -> MGBG | G3: LogicClass : | H3: =IF(LogicCommon!E3="","",LogicCommon!E3) -> MGBGL_AlcRateReg | I3: Ope.Method : | J3: @ | K3: SuperClassPj.ID : | L3: =IF(LogicCommon!G3="","",LogicCommon!G3) | O3: Gene.Type : | P3: ALL
A4: * | E4: Version : | F4: 000000 | G4: LogicName : | H4: =IF(LogicCommon!E4="","",LogicCommon!E4) -> 予定配賦率登録 | I4: Ope.Name : | J4: ファイル入力 | K4: SuperLogicID : | L4: =IF(LogicCommon!G4="","",LogicCommon!G4) -> MG.MGUDL5010 | M4: ImplOpe.ID:
A5: * | E5: ACType :
A6: * | D6: 概要 : | E6: ファイル入力処理をする | M6: ID | O6: ID | Q6: ID
A7: # | I7: U | L7: o | N7: o | P7: o
A8: # | D8: ブロック名 Block Name | E8: 型 Type | G8: super/share | H8: 対象ブロック名 Target Block Name | L8: TargetName | N8: TargetName | P8: TargetName | T8: ブロック備考 Block Remarks
A9: # | D9: 項目名 Field Name | E9: 型 Type | F9: 桁 Digits | G9: フルネーム Full Name | H9: 日本語名 Japanese Name | I9: 上り項目 Request Message Field | J9: 下り項目 Response Message Field | R9: 条件および編集方法 Conditions and Editing Methods | T9: 項目備考 Field Remarks
A10: # | L10: 上り項目 Request Message Field | M10: 下り項目 Response Message Field | N10: 上り項目 Request Message Field | O10: 下り項目 Response Message Field | P10: 上り項目 Request Message Field | Q10: 下り項目 Response Message Field
A11: 10 | B11: * | D11: Imp01_Rslt | E11: L | G11: $share$ | H11: MG.MGBGL0200.Chk01.Chk01_Rslt
A12: 10 | D12: peg_no | E12: #MA.INT | G12: Pegging No. | H12: 紐付けＮＯ | I12: - | J12: -
A13: 10 | D13: err_flg | E13: #MA.FLG | G13: Error | H13: エラー | I13: - | J13: -
A14: 10 | D14: rtn_sts_typ | E14: #MA.RTN_STS_TYP | G14: Process result status type | H14: 処理結果状況区分 | I14: - | J14: E
A15: 10 | D15: dbc | E15: R | F15: DBC:MGT_ALC_RATE
A16: 10 | D16: dbc.calc_ctg_cd# | E16: RI | G16: Calculation category cd. | H16: 計算カテゴリＣＤ | I16: E | J16: E
A17: 10 | D17: dbc.wg_cd# | E17: RI | G17: WG cd. | H17: ワーキンググループＣＤ | I17: E | J17: E
A18: 10 | D18: dbc.ym# | E18: RI | G18: Year month | H18: 年月 | I18: E | J18: E
A19: 10 | D19: dbc.alc_ac_cd# | E19: RI | G19: Allocation account cd. | H19: 配賦科目ＣＤ | I19: E | J19: E
A20: 10 | D20: dbc.dpt_cd# | E20: RI | G20: Dept. cd. | H20: 部門ＣＤ | I20: E | J20: E
A21: 10 | D21: dbc.loc_cd# | E21: RI | G21: Location cd. | H21: 場所ＣＤ | I21: E | J21: E
A22: 10 | D22: dbc.oper_cd# | E22: RI | G22: Operation cd. | H22: 工程ＣＤ | I22: E | J22: E
A23: 10 | D23: dbc.bp_cd# | E23: RI | G23: BP cd. | H23: 取引先ＣＤ | I23: E | J23: E
A24: 10 | D24: dbc.ctg_cd# | E24: RI | G24: Item category cd. | H24: 品群ＣＤ | I24: E | J24: E
A25: 10 | D25: dbc.itm_cd# | E25: RI | G25: Item cd. | H25: 品目ＣＤ | I25: E | J25: E
A26: 10 | D26: dbc.itm_sub1# | E26: RI | G26: Branch No. 1 | H26: 枝番１ | I26: E | J26: E
A27: 10 | D27: dbc.itm_sub2# | E27: RI | G27: Branch No. 2 | H27: 枝番２ | I27: E | J27: E
... A58: 10 | D58: itm_typ_d_nm | E58: #MA.ITM_TYP_D_NM | G58: Item type details name | H58: 品目区分詳細名 | I58: - | J58: E
D59: 詳細 :

Sheet Upd01
A1: * | B1: * | D1: L | E1: 1
A2: * | D2: オペレーション実装仕様書 Operation Specification Implementation Sheet | E2: ModuleID : | F2: =IF(LogicCommon!C2="","",LogicCommon!C2) -> MG | G2: LogicID : | H2: =IF(LogicCommon!E2="","",LogicCommon!E2) -> MGBGL0200 | I2: Ope.ID : | J2: Upd01 | K2: Pj.ID : | L2: =IF(LogicCommon!G2="","",LogicCommon!G2) -> MC | M2: Ope.Body : | N2: "mcframe.serverMAUD.MAUDL5010.MAUDL_Operation"
A3: * | D3: =IF(LogicCommon!A3="","",LogicCommon!A3) | E3: SubModuleID : | F3: =IF(LogicCommon!C3="","",LogicCommon!C3) -> MGBG | G3: LogicClass : | H3: =IF(LogicCommon!E3="","",LogicCommon!E3) -> MGBGL_AlcRateReg | I3: Ope.Method : | J3: @ | K3: SuperClassPj.ID : | L3: =IF(LogicCommon!G3="","",LogicCommon!G3) | O3: Gene.Type : | P3: ALL
A4: * | E4: Version : | F4: 000000 | G4: LogicName : | H4: =IF(LogicCommon!E4="","",LogicCommon!E4) -> 予定配賦率登録 | I4: Ope.Name : | J4: 登録・訂正 | K4: SuperLogicID : | L4: =IF(LogicCommon!G4="","",LogicCommon!G4) -> MG.MGUDL5010 | M4: ImplOpe.ID:
A5: * | E5: ACType :
A6: * | D6: 概要 : | E6: 登録・訂正処理をする | M6: ID | O6: ID | Q6: ID
A7: # | I7: U | K7: K | L7: o | N7: o | P7: o
A8: # | D8: ブロック名 Block Name | E8: 型 Type | G8: super/share | H8: 対象ブロック名 Target Block Name | L8: TargetName | N8: TargetName | P8: TargetName | T8: ブロック備考 Block Remarks
A9: # | D9: 項目名 Field Name | E9: 型 Type | F9: 桁 Digits | G9: フルネーム Full Name | H9: 日本語名 Japanese Name | I9: 上り項目 Request Message Field | J9: 下り項目 Response Message Field | R9: 条件および編集方法 Conditions and Editing Methods | T9: 項目備考 Field Remarks
A10: # | L10: 上り項目 Request Message Field | M10: 下り項目 Response Message Field | N10: 上り項目 Request Message Field | O10: 下り項目 Response Message Field | P10: 上り項目 Request Message Field | Q10: 下り項目 Response Message Field
A11: 10 | B11: * | D11: Upd01_Rslt | E11: L | G11: $share$ | H11: MG.MGBGL0200.Chk01.Chk01_Rslt
A12: 10 | D12: peg_no | E12: #MA.INT | G12: Pegging No. | H12: 紐付けＮＯ | I12: - | J12: -
A13: 10 | D13: err_flg | E13: #MA.FLG | G13: Error | H13: エラー | I13: - | J13: -
A14: 10 | D14: rtn_sts_typ | E14: #MA.RTN_STS_TYP | G14: Process result status type | H14: 処理結果状況区分 | I14: - | J14: E
A15: 10 | D15: dbc | E15: R | F15: DBC:MGT_ALC_RATE
A16: 10 | D16: dbc.calc_ctg_cd# | E16: RI | G16: Calculation category cd. | H16: 計算カテゴリＣＤ | I16: E | J16: -
A17: 10 | D17: dbc.wg_cd# | E17: RI | G17: WG cd. | H17: ワーキンググループＣＤ | I17: E | J17: -
A18: 10 | D18: dbc.ym# | E18: RI | G18: Year month | H18: 年月 | I18: E | J18: -
A19: 10 | D19: dbc.alc_ac_cd# | E19: RI | G19: Allocation account cd. | H19: 配賦科目ＣＤ | I19: E | J19: -
A20: 10 | D20: dbc.dpt_cd# | E20: RI | G20: Dept. cd. | H20: 部門ＣＤ | I20: E | J20: -
A21: 10 | D21: dbc.loc_cd# | E21: RI | G21: Location cd. | H21: 場所ＣＤ | I21: E | J21: -
A22: 10 | D22: dbc.oper_cd# | E22: RI | G22: Operation cd. | H22: 工程ＣＤ | I22: E | J22: -
A23: 10 | D23: dbc.bp_cd# | E23: RI | G23: BP cd. | H23: 取引先ＣＤ | I23: E | J23: -
A24: 10 | D24: dbc.ctg_cd# | E24: RI | G24: Item category cd. | H24: 品群ＣＤ | I24: E | J24: -
A25: 10 | D25: dbc.itm_cd# | E25: RI | G25: Item cd. | H25: 品目ＣＤ | I25: E | J25: -
A26: 10 | D26: dbc.itm_sub1# | E26: RI | G26: Branch No. 1 | H26: 枝番１ | I26: E | J26: -
A27: 10 | D27: dbc.itm_sub2# | E27: RI | G27: Branch No. 2 | H27: 枝番２ | I27: E | J27: -
... A45: 10 | D45: dbc.upd_cntr# | E45: RI | G45: Update counter | H45: 更新カウンタ | I45: E | J45: -
D46: 詳細 :

Sheet Del01
A1: * | B1: * | D1: L | E1: 1
A2: * | D2: オペレーション実装仕様書 Operation Specification Implementation Sheet | E2: ModuleID : | F2: =IF(LogicCommon!C2="","",LogicCommon!C2) -> MG | G2: LogicID : | H2: =IF(LogicCommon!E2="","",LogicCommon!E2) -> MGBGL0200 | I2: Ope.ID : | J2: Del01 | K2: Pj.ID : | L2: =IF(LogicCommon!G2="","",LogicCommon!G2) -> MC | M2: Ope.Body : | N2: "mcframe.serverMAUD.MAUDL5010.MAUDL_Operation"
A3: * | D3: =IF(LogicCommon!A3="","",LogicCommon!A3) | E3: SubModuleID : | F3: =IF(LogicCommon!C3="","",LogicCommon!C3) -> MGBG | G3: LogicClass : | H3: =IF(LogicCommon!E3="","",LogicCommon!E3) -> MGBGL_AlcRateReg | I3: Ope.Method : | J3: @ | K3: SuperClassPj.ID : | L3: =IF(LogicCommon!G3="","",LogicCommon!G3) | O3: Gene.Type : | P3: ALL
A4: * | E4: Version : | F4: 000000 | G4: LogicName : | H4: =IF(LogicCommon!E4="","",LogicCommon!E4) -> 予定配賦率登録 | I4: Ope.Name : | J4: 削除 | K4: SuperLogicID : | L4: =IF(LogicCommon!G4="","",LogicCommon!G4) -> MG.MGUDL5010 | M4: ImplOpe.ID:
A5: * | E5: ACType :
A6: * | D6: 概要 : | E6: 削除処理をする | M6: ID | O6: ID | Q6: ID
A7: # | I7: U | K7: K | L7: o | N7: o | P7: o
A8: # | D8: ブロック名 Block Name | E8: 型 Type | G8: super/share | H8: 対象ブロック名 Target Block Name | L8: TargetName | N8: TargetName | P8: TargetName | T8: ブロック備考 Block Remarks
A9: # | D9: 項目名 Field Name | E9: 型 Type | F9: 桁 Digits | G9: フルネーム Full Name | H9: 日本語名 Japanese Name | I9: 上り項目 Request Message Field | J9: 下り項目 Response Message Field | R9: 条件および編集方法 Conditions and Editing Methods | T9: 項目備考 Field Remarks
A10: # | L10: 上り項目 Request Message Field | M10: 下り項目 Response Message Field | N10: 上り項目 Request Message Field | O10: 下り項目 Response Message Field | P10: 上り項目 Request Message Field | Q10: 下り項目 Response Message Field
A11: 10 | B11: * | D11: Del01_Rslt | E11: L | G11: $share$ | H11: MG.MGBGL0200.Chk02.Chk02_Rslt
A12: 10 | D12: peg_no | E12: #MA.INT | G12: Pegging No. | H12: 紐付けＮＯ | I12: - | J12: -
A13: 10 | D13: err_flg | E13: #MA.FLG | G13: Error | H13: エラー | I13: - | J13: -
A14: 10 | D14: rtn_sts_typ | E14: #MA.RTN_STS_TYP | G14: Process result status type | H14: 処理結果状況区分 | I14: - | J14: E
A15: 10 | D15: dbc | E15: R | F15: DBC:MGT_ALC_RATE
A16: 10 | D16: dbc.calc_ctg_cd# | E16: RI | G16: Calculation category cd. | H16: 計算カテゴリＣＤ | I16: E | J16: -
A17: 10 | D17: dbc.wg_cd# | E17: RI | G17: WG cd. | H17: ワーキンググループＣＤ | I17: E | J17: -
A18: 10 | D18: dbc.ym# | E18: RI | G18: Year month | H18: 年月 | I18: E | J18: -
A19: 10 | D19: dbc.alc_ac_cd# | E19: RI | G19: Allocation account cd. | H19: 配賦科目ＣＤ | I19: E | J19: -
A20: 10 | D20: dbc.dpt_cd# | E20: RI | G20: Dept. cd. | H20: 部門ＣＤ | I20: E | J20: -
A21: 10 | D21: dbc.loc_cd# | E21: RI | G21: Location cd. | H21: 場所ＣＤ | I21: E | J21: -
A22: 10 | D22: dbc.oper_cd# | E22: RI | G22: Operation cd. | H22: 工程ＣＤ | I22: E | J22: -
A23: 10 | D23: dbc.bp_cd# | E23: RI | G23: BP cd. | H23: 取引先ＣＤ | I23: E | J23: -
A24: 10 | D24: dbc.ctg_cd# | E24: RI | G24: Item category cd. | H24: 品群ＣＤ | I24: E | J24: -
A25: 10 | D25: dbc.itm_cd# | E25: RI | G25: Item cd. | H25: 品目ＣＤ | I25: E | J25: -
A26: 10 | D26: dbc.itm_sub1# | E26: RI | G26: Branch No. 1 | H26: 枝番１ | I26: E | J26: -
A27: 10 | D27: dbc.itm_sub2# | E27: RI | G27: Branch No. 2 | H27: 枝番２ | I27: E | J27: -
... A39: 10 | D39: dbc.upd_cntr# | E39: RI | G39: Update counter | H39: 更新カウンタ | I39: E | J39: -
D40: 詳細 :

Sheet Del02
A1: * | B1: * | D1: L | E1: 1
A2: * | D2: オペレーション実装仕様書 Operation Specification Implementation Sheet | E2: ModuleID : | F2: =IF(LogicCommon!C2="","",LogicCommon!C2) -> MG | G2: LogicID : | H2: =IF(LogicCommon!E2="","",LogicCommon!E2) -> MGBGL0200 | I2: Ope.ID : | J2: Del02 | K2: Pj.ID : | L2: =IF(LogicCommon!G2="","",LogicCommon!G2) -> MC | M2: Ope.Body : | N2: "mcframe.serverMAUD.MAUDL5010.MAUDL_Operation"
A3: * | D3: =IF(LogicCommon!A3="","",LogicCommon!A3) | E3: SubModuleID : | F3: =IF(LogicCommon!C3="","",LogicCommon!C3) -> MGBG | G3: LogicClass : | H3: =IF(LogicCommon!E3="","",LogicCommon!E3) -> MGBGL_AlcRateReg | I3: Ope.Method : | J3: @ | K3: SuperClassPj.ID : | L3: =IF(LogicCommon!G3="","",LogicCommon!G3) | O3: Gene.Type : | P3: ALL
A4: * | E4: Version : | F4: 000000 | G4: LogicName : | H4: =IF(LogicCommon!E4="","",LogicCommon!E4) -> 予定配賦率登録 | I4: Ope.Name : | J4: 一括削除 | K4: SuperLogicID : | L4: =IF(LogicCommon!G4="","",LogicCommon!G4) -> MG.MGUDL5010 | M4: ImplOpe.ID:
A5: * | E5: ACType :
A6: * | D6: 概要 : | E6: 一括削除処理をする | M6: ID | O6: ID | Q6: ID
A7: # | I7: U | K7: K | L7: o | N7: o | P7: o
A8: # | D8: ブロック名 Block Name | E8: 型 Type | G8: super/share | H8: 対象ブロック名 Target Block Name | L8: TargetName | N8: TargetName | P8: TargetName | T8: ブロック備考 Block Remarks
A9: # | D9: 項目名 Field Name | E9: 型 Type | F9: 桁 Digits | G9: フルネーム Full Name | H9: 日本語名 Japanese Name | I9: 上り項目 Request Message Field | J9: 下り項目 Response Message Field | R9: 条件および編集方法 Conditions and Editing Methods | T9: 項目備考 Field Remarks
A10: # | L10: 上り項目 Request Message Field | M10: 下り項目 Response Message Field | N10: 上り項目 Request Message Field | O10: 下り項目 Response Message Field | P10: 上り項目 Request Message Field | Q10: 下り項目 Response Message Field
A11: 10 | B11: * | D11: Del02_Cnd | E11: R | G11: $share$ | H11: MG.MGBGL0200.Chk03.Chk03_Cnd
A12: 10 | D12: calc_ctg_cd | E12: #MA.CALC_CTG_CD | G12: Calculation category cd. | H12: 計算カテゴリＣＤ | I12: E | J12: -
A13: 10 | D13: wg_cd | E13: #MA.WG_CD | G13: WG cd. | H13: ワーキンググループＣＤ | I13: E | J13: -
A14: 10 | D14: ym_fr | E14: #MA.YM | G14: Month FROM | H14: 年月ＦＲＯＭ | I14: E | J14: -
A15: 10 | D15: ym_to | E15: #MA.YM | G15: Month TO | H15: 年月ＴＯ | I15: E | J15: -
A16: 10 | D16: alc_ac_cd | E16: #MA.ALC_AC_CD | G16: Allocation account cd. | H16: 配賦科目ＣＤ | I16: E | J16: -
A17: 10 | D17: dpt_cd | E17: #MA.COST_DPT_CD | G17: Dept. cd. | H17: 部門ＣＤ | I17: E | J17: -
D18: 詳細 :

Sheet Ins01
A1: * | B1: * | D1: L | E1: 1
A2: * | D2: オペレーション実装仕様書 Operation Specification Implementation Sheet | E2: ModuleID : | F2: =IF(LogicCommon!C2="","",LogicCommon!C2) -> MG | G2: LogicID : | H2: =IF(LogicCommon!E2="","",LogicCommon!E2) -> MGBGL0200 | I2: Ope.ID : | J2: Ins01 | K2: Pj.ID : | L2: =IF(LogicCommon!G2="","",LogicCommon!G2) -> MC | M2: Ope.Body : | N2: "mcframe.serverMAUD.MAUDL5010.MAUDL_Operation"
A3: * | D3: =IF(LogicCommon!A3="","",LogicCommon!A3) | E3: SubModuleID : | F3: =IF(LogicCommon!C3="","",LogicCommon!C3) -> MGBG | G3: LogicClass : | H3: =IF(LogicCommon!E3="","",LogicCommon!E3) -> MGBGL_AlcRateReg | I3: Ope.Method : | J3: @ | K3: SuperClassPj.ID : | L3: =IF(LogicCommon!G3="","",LogicCommon!G3) | O3: Gene.Type : | P3: ALL
A4: * | E4: Version : | F4: 000000 | G4: LogicName : | H4: =IF(LogicCommon!E4="","",LogicCommon!E4) -> 予定配賦率登録 | I4: Ope.Name : | J4: ファイル取込 | K4: SuperLogicID : | L4: =IF(LogicCommon!G4="","",LogicCommon!G4) -> MG.MGUDL5010 | M4: ImplOpe.ID:
A5: * | E5: ACType :
A6: * | D6: 概要 : | E6: ファイル取込処理をする | M6: ID | O6: ID | Q6: ID
A7: # | I7: U | K7: K | L7: o | N7: o | P7: o
A8: # | D8: ブロック名 Block Name | E8: 型 Type | G8: super/share | H8: 対象ブロック名 Target Block Name | L8: TargetName | N8: TargetName | P8: TargetName | T8: ブロック備考 Block Remarks
A9: # | D9: 項目名 Field Name | E9: 型 Type | F9: 桁 Digits | G9: フルネーム Full Name | H9: 日本語名 Japanese Name | I9: 上り項目 Request Message Field | J9: 下り項目 Response Message Field | R9: 条件および編集方法 Conditions and Editing Methods | T9: 項目備考 Field Remarks
A10: # | L10: 上り項目 Request Message Field | M10: 下り項目 Response Message Field | N10: 上り項目 Request Message Field | O10: 下り項目 Response Message Field | P10: 上り項目 Request Message Field | Q10: 下り項目 Response Message Field
A11: 10 | B11: * | D11: Ins01_Rslt | E11: L | G11: $share$ | H11: MG.MGBGL0200.Chk01.Chk01_Rslt
A12: 10 | D12: peg_no | E12: #MA.INT | G12: Pegging No. | H12: 紐付けＮＯ | I12: - | J12: -
A13: 10 | D13: err_flg | E13: #MA.FLG | G13: Error | H13: エラー | I13: - | J13: -
A14: 10 | D14: rtn_sts_typ | E14: #MA.RTN_STS_TYP | G14: Process result status type | H14: 処理結果状況区分 | I14: - | J14: -
A15: 10 | D15: dbc | E15: R | F15: DBC:MGT_ALC_RATE
A16: 10 | D16: dbc.calc_ctg_cd# | E16: RI | G16: Calculation category cd. | H16: 計算カテゴリＣＤ | I16: E | J16: -
A17: 10 | D17: dbc.wg_cd# | E17: RI | G17: WG cd. | H17: ワーキンググループＣＤ | I17: E | J17: -
A18: 10 | D18: dbc.ym# | E18: RI | G18: Year month | H18: 年月 | I18: E | J18: -
A19: 10 | D19: dbc.alc_ac_cd# | E19: RI | G19: Allocation account cd. | H19: 配賦科目ＣＤ | I19: E | J19: -
A20: 10 | D20: dbc.dpt_cd# | E20: RI | G20: Dept. cd. | H20: 部門ＣＤ | I20: E | J20: -
A21: 10 | D21: dbc.loc_cd# | E21: RI | G21: Location cd. | H21: 場所ＣＤ | I21: E | J21: -
A22: 10 | D22: dbc.oper_cd# | E22: RI | G22: Operation cd. | H22: 工程ＣＤ | I22: E | J22: -
A23: 10 | D23: dbc.bp_cd# | E23: RI | G23: BP cd. | H23: 取引先ＣＤ | I23: E | J23: -
A24: 10 | D24: dbc.ctg_cd# | E24: RI | G24: Item category cd. | H24: 品群ＣＤ | I24: E | J24: -
A25: 10 | D25: dbc.itm_cd# | E25: RI | G25: Item cd. | H25: 品目ＣＤ | I25: E | J25: -
A26: 10 | D26: dbc.itm_sub1# | E26: RI | G26: Branch No. 1 | H26: 枝番１ | I26: E | J26: -
A27: 10 | D27: dbc.itm_sub2# | E27: RI | G27: Branch No. 2 | H27: 枝番２ | I27: E | J27: -
... A45: 10 | D45: dbc.upd_cntr# | E45: RI | G45: Update counter | H45: 更新カウンタ | I45: - | J45: -
D46: 詳細 :

Sheet Ins02
A1: * | B1: * | D1: L | E1: 1
A2: * | D2: オペレーション実装仕様書 Operation Specification Implementation Sheet | E2: ModuleID : | F2: =IF(LogicCommon!C2="","",LogicCommon!C2) -> MG | G2: LogicID : | H2: =IF(LogicCommon!E2="","",LogicCommon!E2) -> MGBGL0200 | I2: Ope.ID : | J2: Ins02 | K2: Pj.ID : | L2: =IF(LogicCommon!G2="","",LogicCommon!G2) -> MC | M2: Ope.Body : | N2: "mcframe.serverMAUD.MAUDL5010.MAUDL_Operation"
A3: * | D3: =IF(LogicCommon!A3="","",LogicCommon!A3) | E3: SubModuleID : | F3: =IF(LogicCommon!C3="","",LogicCommon!C3) -> MGBG | G3: LogicClass : | H3: =IF(LogicCommon!E3="","",LogicCommon!E3) -> MGBGL_AlcRateReg | I3: Ope.Method : | J3: @ | K3: SuperClassPj.ID : | L3: =IF(LogicCommon!G3="","",LogicCommon!G3) | O3: Gene.Type : | P3: ALL
A4: * | E4: Version : | F4: 000000 | G4: LogicName : | H4: =IF(LogicCommon!E4="","",LogicCommon!E4) -> 予定配賦率登録 | I4: Ope.Name : | J4: 一括削除後ファイル取込 | K4: SuperLogicID : | L4: =IF(LogicCommon!G4="","",LogicCommon!G4) -> MG.MGUDL5010 | M4: ImplOpe.ID:
A5: * | E5: ACType :
A6: * | D6: 概要 : | E6: 一括削除後ファイル取込処理をする | M6: ID | O6: ID | Q6: ID
A7: # | I7: U | K7: K | L7: o | N7: o | P7: o
A8: # | D8: ブロック名 Block Name | E8: 型 Type | G8: super/share | H8: 対象ブロック名 Target Block Name | L8: TargetName | N8: TargetName | P8: TargetName | T8: ブロック備考 Block Remarks
A9: # | D9: 項目名 Field Name | E9: 型 Type | F9: 桁 Digits | G9: フルネーム Full Name | H9: 日本語名 Japanese Name | I9: 上り項目 Request Message Field | J9: 下り項目 Response Message Field | R9: 条件および編集方法 Conditions and Editing Methods | T9: 項目備考 Field Remarks
A10: # | L10: 上り項目 Request Message Field | M10: 下り項目 Response Message Field | N10: 上り項目 Request Message Field | O10: 下り項目 Response Message Field | P10: 上り項目 Request Message Field | Q10: 下り項目 Response Message Field
A11: 10 | B11: * | D11: Ins02_Cnd | E11: R | G11: $share$ | H11: MG.MGBGL0200.Del02.Del02_Cnd
A12: 10 | D12: calc_ctg_cd | E12: #MA.CALC_CTG_CD | G12: Calculation category cd. | H12: 計算カテゴリＣＤ | I12: E | J12: -
A13: 10 | D13: wg_cd | E13: #MA.WG_CD | G13: WG cd. | H13: ワーキンググループＣＤ | I13: E | J13: -
A14: 10 | D14: ym_fr | E14: #MA.YM | G14: Month FROM | H14: 年月ＦＲＯＭ | I14: E | J14: -
A15: 10 | D15: ym_to | E15: #MA.YM | G15: Year/month/year/month TO | H15: 年月年月ＴＯ | I15: E | J15: -
A16: 10 | D16: alc_ac_cd | E16: #MA.ALC_AC_CD | G16: Allocation account cd. | H16: 配賦科目ＣＤ | I16: E | J16: -
A17: 10 | D17: dpt_cd | E17: #MA.COST_DPT_CD | G17: Dept. cd. | H17: 部門ＣＤ | I17: E | J17: -
L18: 上り項目 Request Message Field | M18: 下り項目 Response Message Field | N18: 上り項目 Request Message Field | O18: 下り項目 Response Message Field | P18: 上り項目 Request Message Field | Q18: 下り項目 Response Message Field
A19: 20 | B19: * | D19: Ins02_Rslt | E19: L | G19: $share$ | H19: MG.MGBGL0200.Chk01.Chk01_Rslt
A20: 20 | D20: peg_no | E20: #MA.INT | G20: Pegging No. | H20: 紐付けＮＯ | I20: - | J20: -
A21: 20 | D21: err_flg | E21: #MA.FLG | G21: Error | H21: エラー | I21: - | J21: -
A22: 20 | D22: rtn_sts_typ | E22: #MA.RTN_STS_TYP | G22: Process result status type | H22: 処理結果状況区分 | I22: - | J22: -
A23: 20 | D23: dbc | E23: R | F23: DBC:MGT_ALC_RATE | J23: -
A24: 20 | D24: dbc.calc_ctg_cd# | E24: RI | G24: Calculation category cd. | H24: 計算カテゴリＣＤ | I24: E | J24: -
A25: 20 | D25: dbc.wg_cd# | E25: RI | G25: WG cd. | H25: ワーキンググループＣＤ | I25: E | J25: -
A26: 20 | D26: dbc.ym# | E26: RI | G26: Year month | H26: 年月 | I26: E | J26: -
A27: 20 | D27: dbc.alc_ac_cd# | E27: RI | G27: Allocation account cd. | H27: 配賦科目ＣＤ | I27: E | J27: -
A28: 20 | D28: dbc.dpt_cd# | E28: RI | G28: Dept. cd. | H28: 部門ＣＤ | I28: E | J28: -
A29: 20 | D29: dbc.loc_cd# | E29: RI | G29: Location cd. | H29: 場所ＣＤ | I29: E | J29: -
A30: 20 | D30: dbc.oper_cd# | E30: RI | G30: Operation cd. | H30: 工程ＣＤ | I30: E | J30: -
A31: 20 | D31: dbc.bp_cd# | E31: RI | G31: BP cd. | H31: 取引先ＣＤ | I31: E | J31: -
A32: 20 | D32: dbc.ctg_cd# | E32: RI | G32: Item category cd. | H32: 品群ＣＤ | I32: E | J32: -
A33: 20 | D33: dbc.itm_cd# | E33: RI | G33: Item cd. | H33: 品目ＣＤ | I33: E | J33: -
A34: 20 | D34: dbc.itm_sub1# | E34: RI | G34: Branch No. 1 | H34: 枝番１ | I34: E | J34: -
A35: 20 | D35: dbc.itm_sub2# | E35: RI | G35: Branch No. 2 | H35: 枝番２ | I35: E | J35: -
... A53: 20 | D53: dbc.upd_cntr# | E53: RI | G53: Update counter | H53: 更新カウンタ | I53: - | J53: -
D54: 詳細 :

Sheet 来歴
A1: 変更来歴
A3: Rev. | H3: 修正番号 | O3: 変更内容 | AQ3: 変更箇所
A4: 1 | O4: 初版
A5: 1.1 | H5: MG7031#003 | O5: Chk01_Rsltブロックのdbc.loc_cd#の項目属性「LIST_IN」「LIST_IN_BASE」を修正 | AQ5: Chk01シート
A6: 1.2 | O6: 英語の名称を追記 | AQ6: 全般
