Workbook

Sheet LogicCommon
A2: オペレーション実装仕様書 | B2: ModuleID : | C2: MS | D2: LogicID : | E2: MSBCL6050 | F2: Pj.ID : | G2: MC
B3: SubModuleID : | C3: MSBC | D3: LogicClass : | E3: MSBCL_MfgActRegService | F3: SuperClassPj.ID :
D4: LogicName : | E4: 製造実績登録サービス | F4: SuperLogicID : | G4: MS.MSUDL5010
A5: 概要 : | B5: 製造実績を登録する。
A6: 詳細 :

Sheet MfgActReg_Chk01
A1: * | B1: * | D1: L | E1: 1
A2: * | D2: オペレーション実装仕様書 Operation Specification Implementation Sheet | E2: ModuleID : | F2: =IF(LogicCommon!C2="","",LogicCommon!C2) -> MS | G2: LogicID : | H2: =IF(LogicCommon!E2="","",LogicCommon!E2) -> MSBCL6050 | I2: Ope.ID : | J2: MfgActReg_Chk01 | K2: Pj.ID : | L2: =IF(LogicCommon!G2="","",LogicCommon!G2) -> MC | M2: Ope.Body : | N2: MA.MAUDL5010.Checker
A3: * | D3: =IF(LogicCommon!A3="","",LogicCommon!A3) | E3: SubModuleID : | F3: =IF(LogicCommon!C3="","",LogicCommon!C3) -> MSBC | G3: LogicClass : | H3: =IF(LogicCommon!E3="","",LogicCommon!E3) -> MSBCL_MfgActRegService | I3: Ope.Method : | J3: MfgActReg_Chk01 | K3: SuperClassPj.ID : | L3: =IF(LogicCommon!G3="","",LogicCommon!G3) | O3: Gene.Type : | P3: ALL
A4: * | E4: Version : | F4: 000000 | G4: LogicName : | H4: =IF(LogicCommon!E4="","",LogicCommon!E4) -> 製造実績登録サービス | I4: Ope.Name : | J4: 登録・訂正・取消 | K4: SuperLogicID : | L4: =IF(LogicCommon!G4="","",LogicCommon!G4) -> MS.MSUDL5010 | M4: ImplOpe.ID:
A5: * | E5: ACType :
A6: * | D6: 概要 : | E6: 製造実績の登録・訂正・取消前チェックの共通処理 | AD6: ID | AF6: ID
A7: # | I7: U | K7: K | L7: K | M7: K | N7: K | O7: K | P7: K | Q7: K | R7: K | S7: K | T7: K | U7: K | V7: K | W7: K | X7: K | Y7: K | Z7: K | AA7: K | AB7: K | AC7: o | AE7: o
A8: # | D8: ブロック名 Block Name | E8: 型 Type | G8: super/share | H8: 対象ブロック名 Target Block Name | K8: REQ_UPD_CNT_CHK | L8: REQUIRED | M8: CHK_NUM | N8: SMALL_LARGE | O8: CHK_DT | P8: BEFORE_AFTER | Q8: CHK_PTN | R8: DUPLICATE | S8: TOO_MANY_INPUTS | T8: AT_LEAST_ONE | U8: ONLY_ONE_INPUT | V8: LIST_LOGIC | W8: LIST_OUT | X8: LIST_OUT_BASE | Y8: LIST_IN | Z8: LIST_IN_BASE | AA8: CONST | AB8: NULL_VAL | AC8: TargetName | AE8: TargetName | AI8: ブロック備考 Block Remarks
A9: # | D9: 項目名 Field Name | E9: 型 Type | F9: 桁 Digits | G9: フルネーム Full Name | H9: 日本語名 Japanese Name | I9: 上り項目 Request Message Field | J9: 下り項目 Response Message Field | AG9: 条件および編集方法 Conditions and Editing Methods | AI9: 項目備考 Field Remarks
A10: # | AC10: 上り項目 Request Message Field | AD10: 下り項目 Response Message Field | AE10: 上り項目 Request Message Field | AF10: 下り項目 Response Message Field
A11: 10 | B11: * | D11: MfgActReg_Chk01_Hdr | E11: L
A12: 10 | D12: data_crud_typ | E12: #MA.DATA_CRUD_TYP | G12: Data update type | H12: データ更新区分 | I12: - | J12: E
A13: 10 | D13: peg_no | E13: #MA.INT | G13: Pegging No. | H13: 紐付けＮＯ | I13: E | J13: E | R13: E
A14: 10 | D14: err_flg | E14: #MA.FLG | G14: Error | H14: エラー | I14: - | J14: E
A15: 10 | D15: rtn_sts_typ | E15: #MA.RTN_STS_TYP | G15: Process result status type | H15: 処理結果状況区分 | I15: - | J15: E
A16: 10 | D16: mfg_sts_typ | E16: #MS.MFG_STS_TYP | G16: Mfg. status type | H16: 製造状況区分 | I16: E | J16: E | L16: E | AA16: MSC_MFG_STS_TYP
A17: 10 | D17: mfg_sts_typ_nm | E17: #MS.MFG_STS_TYP_NM | G17: Mfg. status name | H17: 製造状況区分名 | I17: - | J17: -
A18: 10 | D18: itm_cd | E18: #MA.ITM_CD | G18: Item cd. | H18: 品目ＣＤ | I18: - | J18: E
A19: 10 | D19: itm_sub1 | E19: #MA.ITM_SUB1 | G19: Branch No. 1 | H19: 枝番１ | I19: - | J19: E
A20: 10 | D20: itm_sub2 | E20: #MA.ITM_SUB2 | G20: Branch No. 2 | H20: 枝番２ | I20: - | J20: E
A21: 10 | D21: itm_sub3 | E21: #MA.ITM_SUB3 | G21: Branch No. 3 | H21: 枝番３ | I21: - | J21: E
A22: 10 | D22: inst_lot_no | E22: #MA.LOT_NO | G22: Lot No. (Order) | H22: ロットＮＯ（指図） | I22: - | J22: E
A23: 10 | D23: inst_sublot_no | E23: #MA.SUBLOT_NO | G23: Sublot No. (Order) | H23: サブロットＮＯ（指図） | I23: - | J23: E
A24: 10 | D24: sno1 | E24: #MA.SNO1 | G24: SEIBAN No. 1 | H24: 手配ＮＯ１ | I24: - | J24: E
A25: 10 | D25: sno2 | E25: #MA.SNO2 | G25: SEIBAN No. 2 | H25: 手配ＮＯ２ | I25: - | J25: E
A26: 10 | D26: sno3 | E26: #MA.SNO3 | G26: SEIBAN No. 3 | H26: 手配ＮＯ３ | I26: - | J26: E
A27: 10 | D27: sno4 | E27: #MA.SNO4 | G27: SEIBAN No. 4 | H27: 手配ＮＯ４ | I27: - | J27: E
A28: 10 | D28: sno1_mng_typ | E28: #MA.SNO_MNG_TYP | G28: SEIBAN No. 1 management type | H28: 手配ＮＯ１管理区分 | I28: - | J28: E
... A31: 10 | D31: sno4_mng_typ | E31: #MA.SNO_MNG_TYP | G31: SEIBAN No. 4 management type | H31: 手配ＮＯ４管理区分 | I31: - | J31: E
A32: 10 | D32: st_act_tm | E32: #MA.TM | G32: Actual start date and time | H32: 着手実績日時 | I32: E | J32: E | L32: E | O32: tmBfToday | P32: st_end_act:BF
A33: 10 | D33: st_ac_dt | E33: #MA.DT | G33: Start recording date | H33: 着手計上日 | I33: E | J33: E | L33: E | O33: bfToday | P33: st_end_ac:BF
A34: 10 | D34: old_st_ac_dt | E34: #MA.DT | G34: Start recording date before update | H34: 更新前着手計上日 | I34: - | J34: -
A35: 10 | D35: end_act_tm | E35: #MA.TM | G35: Actual end date and time | H35: 終了実績日時 | I35: E | J35: E | O35: tmBfToday | P35: st_end_act:AF
A36: 10 | D36: end_ac_dt | E36: #MA.DT | G36: End recording date | H36: 終了計上日 | I36: E | J36: E | O36: bfToday | P36: st_end_ac:AF
A37: 10 | D37: old_end_ac_dt | E37: #MA.DT | G37: End recording date before update | H37: 更新前終了計上日 | I37: - | J37: -
A38: 10 | D38: itm_mfg_inst_qty | E38: #MA.QTY | G38: Item mfg. order qty. | H38: 品目製造指図数量 | I38: - | J38: E
A39: 10 | D39: base_unit_st_act_qty | E39: #MA.QTY | G39: Start qty. | H39: 着手数量 | I39: E | J39: E | L39: E | M39: positive
A40: 10 | D40: base_unit_yield_qty | E40: #MA.QTY | G40: Conforming qty. | H40: 良品数量 | I40: - | J40: E
A41: 10 | D41: base_unit_dfct_qty | E41: #MA.QTY | G41: Defective qty. | H41: 不良数量 | I41: - | J41: E
A42: 10 | D42: rem_abort_flg | E42: #MA.FLG | G42: Cancel remaining qty. | H42: 残数打切 | I42: E | J42: E
...

Sheet MfgActReg_Chk02
A1: * | B1: * | D1: L | E1: 1
A2: * | D2: オペレーション実装仕様書 Operation Specification Implementation Sheet | E2: ModuleID : | F2: =IF(LogicCommon!C2="","",LogicCommon!C2) -> MS | G2: LogicID : | H2: =IF(LogicCommon!E2="","",LogicCommon!E2) -> MSBCL6050 | I2: Ope.ID : | J2: MfgActReg_Chk02 | K2: Pj.ID : | L2: =IF(LogicCommon!G2="","",LogicCommon!G2) -> MC | M2: Ope.Body : | N2: MA.MAUDL5010.Checker
A3: * | D3: =IF(LogicCommon!A3="","",LogicCommon!A3) | E3: SubModuleID : | F3: =IF(LogicCommon!C3="","",LogicCommon!C3) -> MSBC | G3: LogicClass : | H3: =IF(LogicCommon!E3="","",LogicCommon!E3) -> MSBCL_MfgActRegService | I3: Ope.Method : | J3: MfgActReg_Chk02 | K3: SuperClassPj.ID : | L3: =IF(LogicCommon!G3="","",LogicCommon!G3) | O3: Gene.Type : | P3: ALL
A4: * | E4: Version : | F4: 000000 | G4: LogicName : | H4: =IF(LogicCommon!E4="","",LogicCommon!E4) -> 製造実績登録サービス | I4: Ope.Name : | J4: 取消前チェック | K4: SuperLogicID : | L4: =IF(LogicCommon!G4="","",LogicCommon!G4) -> MS.MSUDL5010 | M4: ImplOpe.ID:
A5: * | E5: ACType :
A6: * | D6: 概要 : | E6: 製造実績の取消前チェックの共通処理 | AD6: ID | AF6: ID | AH6: ID
A7: # | I7: U | K7: K | L7: K | M7: K | N7: K | O7: K | P7: K | Q7: K | R7: K | S7: K | T7: K | U7: K | V7: K | W7: K | X7: K | Y7: K | Z7: K | AA7: K | AB7: K | AC7: o | AD7: MAR.chk01 | AE7: o | AG7: o
A8: # | D8: ブロック名 Block Name | E8: 型 Type | G8: super/share | H8: 対象ブロック名 Target Block Name | K8: REQ_UPD_CNT_CHK | L8: REQUIRED | M8: CHK_NUM | N8: SMALL_LARGE | O8: CHK_DT | P8: BEFORE_AFTER | Q8: CHK_PTN | R8: DUPLICATE | S8: TOO_MANY_INPUTS | T8: AT_LEAST_ONE | U8: ONLY_ONE_INPUT | V8: LIST_LOGIC | W8: LIST_OUT | X8: LIST_OUT_BASE | Y8: LIST_IN | Z8: LIST_IN_BASE | AA8: CONST | AB8: NULL_VAL | AC8: TargetName | AD8: OPE.MS.MSBCL6050.MfgActReg_Chk01 | AE8: TargetName | AG8: TargetName | AK8: ブロック備考 Block Remarks
A9: # | D9: 項目名 Field Name | E9: 型 Type | F9: 桁 Digits | G9: フルネーム Full Name | H9: 日本語名 Japanese Name | I9: 上り項目 Request Message Field | J9: 下り項目 Response Message Field | AI9: 条件および編集方法 Conditions and Editing Methods | AK9: 項目備考 Field Remarks
A10: # | AC10: 上り項目 Request Message Field | AD10: 下り項目 Response Message Field | AE10: 上り項目 Request Message Field | AF10: 下り項目 Response Message Field | AG10: 上り項目 Request Message Field | AH10: 下り項目 Response Message Field
A11: 10 | B11: * | D11: MfgActReg_Chk02_Hdr | E11: L | AC11: MfgActReg_Chk01_Hdr | AD11: MfgActReg_Chk01_Hdr
A12: 10 | D12: data_crud_typ | E12: #MA.DATA_CRUD_TYP | G12: Data update type | H12: データ更新区分 | I12: - | J12: E | AD12: E
A13: 10 | D13: peg_no | E13: #MA.INT | G13: Pegging No. | H13: 紐付けＮＯ | I13: E | J13: E | AC13: E | AD13: E
A14: 10 | D14: err_flg | E14: #MA.FLG | G14: Error | H14: エラー | I14: - | J14: E | AD14: E
A15: 10 | D15: rtn_sts_typ | E15: #MA.RTN_STS_TYP | G15: Process result status type | H15: 処理結果状況区分 | I15: - | J15: E | AD15: E
A16: 10 | D16: itm_cd | E16: #MA.ITM_CD | G16: Item cd. | H16: 品目ＣＤ | I16: - | J16: E | AD16: E
A17: 10 | D17: itm_sub1 | E17: #MA.ITM_SUB1 | G17: Branch No. 1 | H17: 枝番１ | I17: - | J17: E | AD17: E
A18: 10 | D18: itm_sub2 | E18: #MA.ITM_SUB2 | G18: Branch No. 2 | H18: 枝番２ | I18: - | J18: E | AD18: E
A19: 10 | D19: itm_sub3 | E19: #MA.ITM_SUB3 | G19: Branch No. 3 | H19: 枝番３ | I19: - | J19: E | AD19: E
A20: 10 | D20: sno1 | E20: #MA.SNO1 | G20: SEIBAN No. 1 | H20: 手配ＮＯ１ | I20: - | J20: E | AD20: E
A21: 10 | D21: sno2 | E21: #MA.SNO2 | G21: SEIBAN No. 2 | H21: 手配ＮＯ２ | I21: - | J21: E | AD21: E
A22: 10 | D22: sno3 | E22: #MA.SNO3 | G22: SEIBAN No. 3 | H22: 手配ＮＯ３ | I22: - | J22: E | AD22: E
A23: 10 | D23: sno4 | E23: #MA.SNO4 | G23: SEIBAN No. 4 | H23: 手配ＮＯ４ | I23: - | J23: E | AD23: E
A24: 10 | D24: base_unit_st_act_qty | E24: #MA.QTY | G24: Start qty. | H24: 着手数量 | I24: - | J24: E | AD24: E
A25: 10 | D25: base_unit_yield_qty | E25: #MA.QTY | G25: Conforming qty. | H25: 良品数量 | I25: - | J25: E | AD25: E
... A36: 10 | D36: old_end_act_tm | E36: #MA.TM | G36: Actual end time before update | H36: 更新前終了実績日時 | I36: - | J36: E | AD36: E
A37: 10 | D37: mfg_inst_no | E37: #MA.MFG_INST_NO | G37: Mfg. order No. | H37: 製造指図ＮＯ | I37: E | J37: E | AC37: E | AD37: E
A38: 10 | D38: mfg_inst_upd_cntr | E38: #MA.UPD_CNT | G38: Mfg. order update counter | H38: 製造指図更新カウンタ | I38: E | J38: E | AC38: E | AD38: E
A39: 10 | D39: mfg_inst_pr_upd_cntr | E39: #MA.UPD_CNT | G39: Production order progress update counter | H39: 製造指図進捗更新カウンタ | I39: E | J39: E | AC39: E | AD39: E
A40: 10 | D40: mfg_act_upd_cntr | E40: #MA.UPD_CNT | G40: Mfg. result update counter | H40: 製造実績更新カウンタ | I40: E | J40: E | AC40: E | AD40: E
A41: 10 | D41: div_seq | E41: #MS.DIV_SEQ | G41: Split sequence number | H41: 分割連番 | I41: E | J41: E | AC41: E | AD41: E
A42: 10 | D42: mfg_act_no | E42: #MA.MFG_ACT_NO | G42: Mfg. result No. | H42: 製造実績ＮＯ | I42: E | J42: E | AC42: E | AD42: E
A43: 10 | D43: itm_ord_no | E43: #MA.ITM_ORD_NO | G43: Item order No. | H43: 品目オーダＮＯ | I43: - | J43: E | AD43: E
A44: 10 | D44: itm_mfg_inst_no | E44: #MA.ITM_MFG_INST_NO | G44: Item mfg. order No. | H44: 品目製造指図ＮＯ | I44: - | J44: E | AD44: E
A45: 10 | D45: upd_cntr_chk_flg | E45: #MA.FLG | G45: Check for update counter | H45: 更新カウンタチェック | I45: E | J45: - | AC45: E
A46: 10 | D46: lst_del_flg | E46: #MA.FLG | G46: Bulk cancellation flg. | H46: 一括取消ＦＬＧ | I46: E | J46: -
A47: 10 | D47: is_src_batch_flg | E47: #MA.FLG | G47: Caller batch process | H47: 呼出元バッチ処理 | I47: E | J47: E | AC47: E | AD47: E
A49: 20 | B49: * | D49: MfgActReg_Chk02_DtlOper | E49: L | AC49: MfgActReg_Chk01_DtlOper | AD49: MfgActReg_Chk01_DtlOper
A50: 20 | D50: data_crud_typ | E50: #MA.DATA_CRUD_TYP | G50: Data update type | H50: データ更新区分 | I50: - | J50: E | AD50: E
A51: 20 | D51: hdr_peg_no | E51: #MA.INT | G51: Header pegging No. | H51: ヘッダ紐付けＮＯ | I51: - | J51: E | AC51: E | AD51: E
...

Sheet MfgActReg_Chk03
A1: * | B1: * | D1: L | E1: 1
A2: * | D2: オペレーション実装仕様書 Operation Specification Implementation Sheet | E2: ModuleID : | F2: =IF(LogicCommon!C2="","",LogicCommon!C2) -> MS | G2: LogicID : | H2: =IF(LogicCommon!E2="","",LogicCommon!E2) -> MSBCL6050 | I2: Ope.ID : | J2: MfgActReg_Chk03 | K2: Pj.ID : | L2: =IF(LogicCommon!G2="","",LogicCommon!G2) -> MC | M2: Ope.Body : | N2: MA.MAUDL5010.Checker
A3: * | D3: =IF(LogicCommon!A3="","",LogicCommon!A3) | E3: SubModuleID : | F3: =IF(LogicCommon!C3="","",LogicCommon!C3) -> MSBC | G3: LogicClass : | H3: =IF(LogicCommon!E3="","",LogicCommon!E3) -> MSBCL_MfgActRegService | I3: Ope.Method : | J3: MfgActReg_Chk03 | K3: SuperClassPj.ID : | L3: =IF(LogicCommon!G3="","",LogicCommon!G3) | O3: Gene.Type : | P3: ALL
A4: * | E4: Version : | F4: 000000 | G4: LogicName : | H4: =IF(LogicCommon!E4="","",LogicCommon!E4) -> 製造実績登録サービス | I4: Ope.Name : | J4: 一括登録・訂正前チェック | K4: SuperLogicID : | L4: =IF(LogicCommon!G4="","",LogicCommon!G4) -> MS.MSUDL5010 | M4: ImplOpe.ID:
A5: * | E5: ACType :
A6: * | D6: 概要 : | E6: 製造実績の一括登録・訂正前チェックの共通処理 | AD6: ID | AE6: ID | AF6: ID
A7: # | I7: U | K7: K | L7: K | M7: K | N7: K | O7: K | P7: K | Q7: K | R7: K | S7: K | T7: K | U7: K | V7: K | W7: K | X7: K | Y7: K | Z7: K | AA7: K | AB7: K | AC7: o | AE7: o
A8: # | D8: ブロック名 Block Name | E8: 型 Type | G8: super/share | H8: 対象ブロック名 Target Block Name | K8: REQ_UPD_CNT_CHK | L8: REQUIRED | M8: CHK_NUM | N8: SMALL_LARGE | O8: CHK_DT | P8: BEFORE_AFTER | Q8: CHK_PTN | R8: DUPLICATE | S8: TOO_MANY_INPUTS | T8: AT_LEAST_ONE | U8: ONLY_ONE_INPUT | V8: LIST_LOGIC | W8: LIST_OUT | X8: LIST_OUT_BASE | Y8: LIST_IN | Z8: LIST_IN_BASE | AA8: CONST | AB8: NULL_VAL | AC8: TargetName | AE8: TargetName | AI8: ブロック備考 Block Remarks
A9: # | D9: 項目名 Field Name | E9: 型 Type | F9: 桁 Digits | G9: フルネーム Full Name | H9: 日本語名 Japanese Name | I9: 上り項目 Request Message Field | J9: 下り項目 Response Message Field | AG9: 条件および編集方法 Conditions and Editing Methods | AI9: 項目備考 Field Remarks
A10: # | AC10: 上り項目 Request Message Field | AD10: 下り項目 Response Message Field | AE10: 上り項目 Request Message Field | AF10: 下り項目 Response Message Field
A11: 10 | B11: * | D11: MfgActReg_Chk03_Ctrl | E11: R
A12: 10 | D12: oper_unit_flg | E12: #MA.FLG | G12: Operation unit result | H12: 工程単位実績 | I12: E
A13: 10 | D13: is_src_batch_flg | E13: #MA.FLG | G13: Caller batch process | H13: 呼出元バッチ処理 | I13: E
A14: 10 | D14: upd_cntr_chk_flg | E14: #MA.FLG | G14: Check for update counter | H14: 更新カウンタチェック | I14: E
A16: 20 | B16: * | D16: MfgActReg_Chk03_Hdr1 | E16: L
A17: 20 | D17: peg_no | E17: #MA.INT | G17: Pegging No. | H17: 紐付けＮＯ | I17: E | J17: E | L17: E | R17: E
A18: 20 | D18: err_flg | E18: #MA.FLG | G18: Error | H18: エラー | J18: E
A19: 20 | D19: rtn_sts_typ | E19: #MA.RTN_STS_TYP | G19: Process result status type | H19: 処理結果状況区分 | J19: E
A20: 20 | D20: st_act_tm | E20: #MA.TM | G20: Actual start date | H20: 着手実績日 | I20: E | L20: E
A21: 20 | D21: st_ac_dt | E21: #MA.DT | G21: Start recording date | H21: 着手計上日 | I21: E | L21: E
A22: 20 | D22: end_act_tm | E22: #MA.TM | G22: Actual end date | H22: 終了実績日 | I22: E
A23: 20 | D23: end_ac_dt | E23: #MA.DT | G23: End recording date | H23: 終了計上日 | I23: E
A24: 20 | D24: base_unit_st_act_qty | E24: #MA.QTY | G24: Start qty. | H24: 着手数量 | I24: E | L24: E | M24: positive
A25: 20 | D25: oper_unit_act_qty | E25: #MA.QTY | G25: Operation unit result qty. | H25: 工程単位実績数量 | I25: E | L25: E | N25: 0:
A26: 20 | D26: mfg_inst_no | E26: #MA.MFG_INST_NO | G26: Mfg. order No. | H26: 製造指図ＮＯ | I26: E | K26: E
A27: 20 | D27: div_seq | E27: #MS.DIV_SEQ | G27: Split sequence number | H27: 分割連番 | I27: E
A28: 20 | D28: mfg_act_no | E28: #MA.MFG_ACT_NO | G28: Mfg. result No. | H28: 製造実績ＮＯ | I28: E
A29: 20 | D29: mfg_inst_upd_cntr | E29: #MA.UPD_CNT | G29: Mfg. order update counter | H29: 製造指図更新カウンタ | I29: E
A30: 20 | D30: mfg_inst_pr_upd_cntr | E30: #MA.UPD_CNT | G30: Production order progress update counter | H30: 製造指図進捗更新カウンタ | I30: E
A31: 20 | D31: mfg_act_upd_cntr | E31: #MA.UPD_CNT | G31: Mfg. result update counter | H31: 製造実績更新カウンタ | I31: E
A33: 30 | B33: * | D33: MfgActReg_Chk03_Hdr2 | E33: L
A34: 30 | D34: peg_no | E34: #MA.INT | G34: Pegging No. | H34: 紐付けＮＯ | I34: E | J34: E | L34: E | R34: E
A35: 30 | D35: err_flg | E35: #MA.FLG | G35: Error | H35: エラー | J35: E
A36: 30 | D36: mfg_sts_typ | E36: #MS.MFG_STS_TYP | G36: Mfg. status type | H36: 製造状況区分 | I36: E | J36: E | L36: E
A37: 30 | D37: st_act_tm | E37: #MA.TM | G37: Actual start date | H37: 着手実績日 | I37: E | L37: E
A38: 30 | D38: st_ac_dt | E38: #MA.DT | G38: Start recording date | H38: 着手計上日 | I38: E | L38: E
A39: 30 | D39: end_act_tm | E39: #MA.TM | G39: Actual end date | H39: 終了実績日 | I39: E
A40: 30 | D40: end_ac_dt | E40: #MA.DT | G40: End recording date | H40: 終了計上日 | I40: E
A41: 30 | D41: base_unit_st_act_qty | E41: #MA.QTY | G41: Start qty. | H41: 着手数量 | I41: E | M41: positive
A42: 30 | D42: mfg_inst_no | E42: #MA.MFG_INST_NO | G42: Mfg. order No. | H42: 製造指図ＮＯ | I42: E | K42: E
...

Sheet MfgActReg_Chk04
A1: * | B1: * | D1: L | E1: 1
A2: * | D2: オペレーション実装仕様書 Operation Specification Implementation Sheet | E2: ModuleID : | F2: =IF(LogicCommon!C2="","",LogicCommon!C2) -> MS | G2: LogicID : | H2: =IF(LogicCommon!E2="","",LogicCommon!E2) -> MSBCL6050 | I2: Ope.ID : | J2: MfgActReg_Chk04 | K2: Pj.ID : | L2: =IF(LogicCommon!G2="","",LogicCommon!G2) -> MC | M2: Ope.Body : | N2: MA.MAUDL5010.Checker
A3: * | D3: =IF(LogicCommon!A3="","",LogicCommon!A3) | E3: SubModuleID : | F3: =IF(LogicCommon!C3="","",LogicCommon!C3) -> MSBC | G3: LogicClass : | H3: =IF(LogicCommon!E3="","",LogicCommon!E3) -> MSBCL_MfgActRegService | I3: Ope.Method : | J3: MfgActReg_Chk04 | K3: SuperClassPj.ID : | L3: =IF(LogicCommon!G3="","",LogicCommon!G3) | O3: Gene.Type : | P3: ALL
A4: * | E4: Version : | F4: 000000 | G4: LogicName : | H4: =IF(LogicCommon!E4="","",LogicCommon!E4) -> 製造実績登録サービス | I4: Ope.Name : | J4: 工数実績登録・訂正前チェック | K4: SuperLogicID : | L4: =IF(LogicCommon!G4="","",LogicCommon!G4) -> MS.MSUDL5010 | M4: ImplOpe.ID:
A5: * | E5: ACType :
A6: * | D6: 概要 : | E6: 工数実績の登録・訂正前チェックを行う。 | AD6: ID | AF6: ID | AH6: ID
A7: # | I7: U | K7: K | L7: K | M7: K | N7: K | O7: K | P7: K | Q7: K | R7: K | S7: K | T7: K | U7: K | V7: K | W7: K | X7: K | Y7: K | Z7: K | AA7: K | AB7: K | AC7: o | AE7: o | AG7: o
A8: # | D8: ブロック名 Block Name | E8: 型 Type | G8: super/share | H8: 対象ブロック名 Target Block Name | K8: REQ_UPD_CNT_CHK | L8: REQUIRED | M8: CHK_NUM | N8: SMALL_LARGE | O8: CHK_DT | P8: BEFORE_AFTER | Q8: CHK_PTN | R8: DUPLICATE | S8: TOO_MANY_INPUTS | T8: AT_LEAST_ONE | U8: ONLY_ONE_INPUT | V8: LIST_LOGIC | W8: LIST_OUT | X8: LIST_OUT_BASE | Y8: LIST_IN | Z8: LIST_IN_BASE | AA8: CONST | AB8: NULL_VAL | AE8: TargetName | AG8: TargetName | AK8: ブロック備考 Block Remarks
A9: # | D9: 項目名 Field Name | E9: 型 Type | F9: 桁 Digits | G9: フルネーム Full Name | H9: 日本語名 Japanese Name | I9: 上り項目 Request Message Field | J9: 下り項目 Response Message Field | AI9: 条件および編集方法 Conditions and Editing Methods | AK9: 項目備考 Field Remarks
A10: # | AC10: 上り項目 Request Message Field | AD10: 下り項目 Response Message Field | AE10: 上り項目 Request Message Field | AF10: 下り項目 Response Message Field | AG10: 上り項目 Request Message Field | AH10: 下り項目 Response Message Field
A11: 10 | B11: * | D11: MfgActReg_Chk04_Rslt | E11: L
A12: 10 | D12: peg_no | E12: #MA.INT | G12: Pegging No. | H12: 紐付けＮＯ | I12: E | J12: E
A13: 10 | D13: err_flg | E13: #MA.FLG | G13: Error flg. | H13: エラーＦＬＧ | I13: - | J13: E
A14: 10 | D14: data_crud_typ | E14: #MA.DATA_CRUD_TYP | G14: Data update type | H14: データ更新区分 | I14: E | J14: E
A15: 10 | D15: inst_wk_act_flg | E15: #MA.FLG | G15: Order direct man-hour result | H15: 指図工数実績 | I15: E | J15: E
A16: 10 | D16: mfg_inst_no | E16: #MA.MFG_INST_NO | G16: Mfg. order No. | H16: 製造指図ＮＯ | I16: E | J16: E
A17: 10 | D17: div_seq | E17: #MS.DIV_SEQ | G17: Split sequence number | H17: 分割連番 | I17: E | J17: E
A18: 10 | D18: disp_seq | E18: #MA.INT | G18: Display order | H18: 表示順 | I18: - | J18: -
A19: 10 | D19: oper_ptn | E19: #MA.OPER_PTN | G19: Operation pattern | H19: 工程パタン | I19: - | J19: -
A20: 10 | D20: oper_disp_seq | E20: #MA.INT | G20: Routing | H20: 工順 | I20: - | J20: -
A21: 10 | D21: oper_cd | E21: #MA.OPER_CD | G21: Operation cd. | H21: 工程ＣＤ | I21: E | J21: E | V21: MA.MAUAL0010.Oper | W21: oper_nm | Y21: true | Z21: mode_nullval_flg
A22: 10 | D22: oper_nm | E22: #MA.OPER_NM | G22: Operation name | H22: 工程名 | I22: - | J22: E
A23: 10 | D23: oper_seq | E23: #MA.OPER_SEQ | G23: Operation sequence number | H23: 工程連番 | I23: - | J23: -
A24: 10 | D24: wk_cost_cd | E24: #MA.WK_COST_CD | G24: Work element cd. | H24: 工数管理ＣＤ | I24: E | J24: E | V24: MA.MAUAL0010.WkCost | W24: wk_cost_nm;wk_cost_unit_nm;wk_cost_dec_place;wk_cost_rnd_typ | X24: wk_cost_nm;wk_cost_unit_nm;dec_place;rnd_typ
A25: 10 | D25: wk_cost_nm | E25: #MA.WK_COST_NM | G25: Work element name | H25: 工数管理名 | I25: - | J25: E
A26: 10 | D26: ac_dt | E26: #MA.DT | G26: Recording date | H26: 計上日 | I26: E | J26: E | L26: E | O26: bfToday
A27: 10 | D27: old_ac_dt | E27: #MA.DT | G27: Recording date before update | H27: 更新前計上日 | I27: - | J27: E
A28: 10 | D28: st_tm | E28: #MA.TM | G28: Start time | H28: 着手時刻 | I28: E | J28: E
A29: 10 | D29: end_tm | E29: #MA.TM | G29: End time | H29: 終了時刻 | I29: E | J29: E
A30: 10 | D30: brk_pd | E30: #MA.INT4 | G30: Downtime | H30: 中断時間 | I30: E | J30: E | N30: 0:1440
A31: 10 | D31: schd_sum_wk_cost | E31: #MA.WK_COST_QTY | G31: Schedule man-hour | H31: 予定工数 | I31: - | J31: -
A32: 10 | D32: schd_wk_cost | E32: #MA.WK_COST_QTY | G32: Schedule man-hour (Qty.-dependent) | H32: 予定工数（数量依存） | I32: - | J32: -
A33: 10 | D33: schd_fxd_wk_cost | E33: #MA.WK_COST_QTY | G33: Schedule man-hour (Constant) | H33: 予定工数（固定） | I33: - | J33: -
A34: 10 | D34: act_wk_cost | E34: #MA.WK_COST_QTY | G34: Result man-hour | H34: 実績工数 | I34: E | J34: E
A35: 10 | D35: abort_flg | E35: #MA.FLG | G35: Cancel remaining | H35: 打切 | I35: E | J35: E
A36: 10 | D36: rem_wk_cost | E36: #MA.WK_COST_QTY | G36: Remaining man-hour | H36: 残工数 | I36: - | J36: -
A37: 10 | D37: wk_cost_unit_nm | E37: #MA.WK_COST_UNIT_NM | G37: Work element unit name | H37: 工数管理単位名 | I37: - | J37: E
A38: 10 | D38: wk_cost_dec_place | E38: #MA.DEC_PLACE | G38: Number of decimal places | H38: 小数部有効桁数 | I38: - | J38: E
A39: 10 | D39: wk_cost_rnd_typ | E39: #MA.RND_TYP | G39: Rounding type | H39: 端数処理区分 | I39: - | J39: E
A40: 10 | D40: wk_day_cd | E40: #MA.WK_DAY_CD | G40: Work type cd. | H40: 勤務種類ＣＤ | I40: E | J40: E | V40: MA.MAUAL0010.WkDay | W40: wk_day_nm
...

Sheet MfgActReg_Chk05
A1: * | B1: * | D1: L | E1: 1
A2: * | D2: オペレーション実装仕様書 Operation Specification Implementation Sheet | E2: ModuleID : | F2: =IF(LogicCommon!C2="","",LogicCommon!C2) -> MS | G2: LogicID : | H2: =IF(LogicCommon!E2="","",LogicCommon!E2) -> MSBCL6050 | I2: Ope.ID : | J2: MfgActReg_Chk05 | K2: Pj.ID : | L2: =IF(LogicCommon!G2="","",LogicCommon!G2) -> MC | M2: Ope.Body : | N2: MA.MAUDL5010.Checker
A3: * | D3: =IF(LogicCommon!A3="","",LogicCommon!A3) | E3: SubModuleID : | F3: =IF(LogicCommon!C3="","",LogicCommon!C3) -> MSBC | G3: LogicClass : | H3: =IF(LogicCommon!E3="","",LogicCommon!E3) -> MSBCL_MfgActRegService | I3: Ope.Method : | J3: MfgActReg_Chk05 | K3: SuperClassPj.ID : | L3: =IF(LogicCommon!G3="","",LogicCommon!G3) | O3: Gene.Type : | P3: ALL
A4: * | E4: Version : | F4: 000000 | G4: LogicName : | H4: =IF(LogicCommon!E4="","",LogicCommon!E4) -> 製造実績登録サービス | I4: Ope.Name : | J4: 工数実績取消前チェック | K4: SuperLogicID : | L4: =IF(LogicCommon!G4="","",LogicCommon!G4) -> MS.MSUDL5010 | M4: ImplOpe.ID:
A5: * | E5: ACType :
A6: * | D6: 概要 : | E6: 工数実績の取消前チェックを行う。 | AA6: ID | AC6: ID | AE6: ID
A7: # | I7: U | K7: K | L7: K | M7: K | N7: K | O7: K | P7: K | Q7: K | R7: K | S7: K | T7: K | U7: K | V7: K | W7: K | X7: K | Y7: K | Z7: o | AB7: o | AD7: o
A8: # | D8: ブロック名 Block Name | E8: 型 Type | G8: super/share | H8: 対象ブロック名 Target Block Name | K8: REQ_UPD_CNT_CHK | L8: REQUIRED | M8: CHK_NUM | N8: SMALL_LARGE | O8: CHK_DT | P8: BEFORE_AFTER | Q8: CHK_PTN | R8: DUPLICATE | S8: TOO_MANY_INPUTS | T8: AT_LEAST_ONE | U8: ONLY_ONE_INPUT | V8: LIST_LOGIC | W8: LIST_OUT | X8: LIST_OUT_BASE | Y8: CONST | Z8: TargetName | AB8: TargetName | AD8: TargetName | AH8: ブロック備考 Block Remarks
A9: # | D9: 項目名 Field Name | E9: 型 Type | F9: 桁 Digits | G9: フルネーム Full Name | H9: 日本語名 Japanese Name | I9: 上り項目 Request Message Field | J9: 下り項目 Response Message Field | AF9: 条件および編集方法 Conditions and Editing Methods | AH9: 項目備考 Field Remarks
A10: # | Z10: 上り項目 Request Message Field | AA10: 下り項目 Response Message Field | AB10: 上り項目 Request Message Field | AC10: 下り項目 Response Message Field | AD10: 上り項目 Request Message Field | AE10: 下り項目 Response Message Field
A11: 10 | B11: * | D11: MfgActReg_Chk05_Rslt | E11: L | G11: $share$ | H11: MS.MSBCL6050.MfgActReg_Chk04.MfgActReg_Chk04_Rslt
A12: 10 | D12: peg_no | E12: #MA.INT | G12: Pegging No. | H12: 紐付けＮＯ | I12: E | J12: E
A13: 10 | D13: err_flg | E13: #MA.FLG | G13: Error flg. | H13: エラーＦＬＧ | I13: - | J13: E
A14: 10 | D14: data_crud_typ | E14: #MA.DATA_CRUD_TYP | G14: Data update type | H14: データ更新区分 | I14: E | J14: E
A15: 10 | D15: inst_wk_act_flg | E15: #MA.FLG | G15: Order direct man-hour result | H15: 指図工数実績 | I15: E | J15: E
A16: 10 | D16: mfg_inst_no | E16: #MA.MFG_INST_NO | G16: Mfg. order No. | H16: 製造指図ＮＯ | I16: E | J16: E
A17: 10 | D17: div_seq | E17: #MS.DIV_SEQ | G17: Split sequence number | H17: 分割連番 | I17: E | J17: E
A18: 10 | D18: disp_seq | E18: #MA.INT | G18: Display order | H18: 表示順 | I18: - | J18: -
A19: 10 | D19: oper_ptn | E19: #MA.OPER_PTN | G19: Operation pattern | H19: 工程パタン | I19: - | J19: -
A20: 10 | D20: oper_disp_seq | E20: #MA.INT | G20: Routing | H20: 工順 | I20: - | J20: -
A21: 10 | D21: oper_cd | E21: #MA.OPER_CD | G21: Operation cd. | H21: 工程ＣＤ | I21: - | J21: -
A22: 10 | D22: oper_nm | E22: #MA.OPER_NM | G22: Operation name | H22: 工程名 | I22: - | J22: -
A23: 10 | D23: oper_seq | E23: #MA.OPER_SEQ | G23: Operation sequence number | H23: 工程連番 | I23: - | J23: -
... A101: 10 | D101: oper_act_no | E101: #MA.OPER_ACT_NO | G101: Operation result No. | H101: 工程実績ＮＯ | I101: E | J101: E
A102: 10 | D102: wk_act_no | E102: #MA.WK_ACT_NO | G102: Man-hour result No. | H102: 工数実績ＮＯ | I102: E | J102: E | K102: E
A103: 10 | D103: dpt_wg_cd | E103: #MA.WG_CD | G103: Dept. WG cd. | H103: 部門ワーキンググループＣＤ | I103: - | J103: -
A104: 10 | D104: dpt_wg_nm | E104: #MA.WG_NM | G104: Dept. WG name | H104: 部門ワーキンググループ名 | I104: - | J104: -
A105: 10 | D105: loc_wg_cd | E105: #MA.WG_CD | G105: Location WG cd. | H105: 場所ワーキンググループＣＤ | I105: - | J105: -
A106: 10 | D106: loc_wg_nm | E106: #MA.WG_NM | G106: Location WG name | H106: 場所ワーキンググループ名 | I106: - | J106: -
A107: 10 | D107: loc_grp_cd | E107: #MA.LOC_GRP_CD | G107: Location group cd. | H107: 場所グループＣＤ | I107: - | J107: -
A108: 10 | D108: loc_grp_nm | E108: #MA.LOC_GRP_NM | G108: Location group name | H108: 場所グループ名 | I108: - | J108: -
A109: 10 | D109: site_cd | E109: #MA.SITE_CD | G109: Factory/Distribution warehouse cd. | H109: 工場・物流倉庫ＣＤ | I109: - | J109: -
A110: 10 | D110: site_nm | E110: #MA.SITE_NM | G110: Factory/Distribution warehouse name | H110: 工場・物流倉庫名 | I110: - | J110: -
A111: 10 | D111: itm_typ | E111: #MA.ITM_TYP | G111: Item type | H111: 品目区分 | I111: - | J111: -
A112: 10 | D112: itm_typ_nm | E112: #MA.ITM_TYP_NM | G112: Item type name | H112: 品目区分名 | I112: - | J112: -
A113: 10 | D113: itm_typ_d_cd | E113: #MA.ITM_TYP_D_CD | G113: Item type details cd. | H113: 品目区分詳細ＣＤ | I113: - | J113: -
A114: 10 | D114: itm_typ_d_nm | E114: #MA.ITM_TYP_D_NM | G114: Item type details name | H114: 品目区分詳細名 | I114: - | J114: -
... A151: 10 | D151: ext_wk_act_no | E151: #MA.EXT_WK_ACT_NO | G151: External man-hour result No. | H151: 外部工数実績ＮＯ | I151: - | J151: -
A153: 20 | B153: * | D153: MfgActReg_Chk05_Ctrl | E153: R
A154: 20 | D154: upd_cntr_chk_flg | E154: #MA.FLG | G154: Check for update counter | H154: 更新カウンタチェック | I154: E | J154: -
...

Sheet MfgActReg_Upd01
A1: * | B1: * | D1: L | E1: 1
A2: * | D2: オペレーション実装仕様書 Operation Specification Implementation Sheet | E2: ModuleID : | F2: =IF(LogicCommon!C2="","",LogicCommon!C2) -> MS | G2: LogicID : | H2: =IF(LogicCommon!E2="","",LogicCommon!E2) -> MSBCL6050 | I2: Ope.ID : | J2: MfgActReg_Upd01 | K2: Pj.ID : | L2: =IF(LogicCommon!G2="","",LogicCommon!G2) -> MC | M2: Ope.Body : | N2: "mcframe.serverMAUD.MAUDL5010.MAUDL_Operation"
A3: * | D3: =IF(LogicCommon!A3="","",LogicCommon!A3) | E3: SubModuleID : | F3: =IF(LogicCommon!C3="","",LogicCommon!C3) -> MSBC | G3: LogicClass : | H3: =IF(LogicCommon!E3="","",LogicCommon!E3) -> MSBCL_MfgActRegService | I3: Ope.Method : | J3: MfgActReg_Upd01 | K3: SuperClassPj.ID : | L3: =IF(LogicCommon!G3="","",LogicCommon!G3) | O3: Gene.Type : | P3: ALL
A4: * | E4: Version : | F4: 000000 | G4: LogicName : | H4: =IF(LogicCommon!E4="","",LogicCommon!E4) -> 製造実績登録サービス | I4: Ope.Name : | J4: 登録・訂正・取消 | K4: SuperLogicID : | L4: =IF(LogicCommon!G4="","",LogicCommon!G4) -> MS.MSUDL5010 | M4: ImplOpe.ID:
A5: * | E5: ACType :
A6: * | D6: 概要 : | E6: 製造実績の登録・訂正・取消の共通処理 | M6: ID | O6: ID | Q6: ID | S6: ID | U6: ID | W6: ID
A7: # | I7: U | K7: K | L7: o | M7: MAT.matUpd01 | N7: o | O7: MAT.matUpd02 | P7: o | Q7: MAT.matUpd03 | R7: o | S7: MATI.matUpd04 | T7: o | U7: MAT.matUpd05 | V7: o | W7: MAT.matUpd06
A8: # | D8: ブロック名 Block Name | E8: 型 Type | G8: super/share | H8: 対象ブロック名 Target Block Name | L8: TargetName | M8: OPE.MS.MSBCL6060.MfgActTblReg_Upd01 | N8: TargetName | O8: OPE.MS.MSBCL6060.MfgActTblReg_Upd02 | P8: TargetName | Q8: OPE.MS.MSBCL6060.MfgActTblReg_Upd03 | R8: TargetName | S8: OPE.MS.MSBCL6060.MfgActTblReg_Upd04 | T8: TargetName | U8: OPE.MS.MSBCL6060.MfgActTblReg_Upd05 | V8: TargetName | W8: OPE.MS.MSBCL6060.MfgActTblReg_Upd06 | Z8: ブロック備考 Block Remarks
A9: # | D9: 項目名 Field Name | E9: 型 Type | F9: 桁 Digits | G9: フルネーム Full Name | H9: 日本語名 Japanese Name | I9: 上り項目 Request Message Field | J9: 下り項目 Response Message Field | X9: 条件および編集方法 Conditions and Editing Methods | Z9: 項目備考 Field Remarks
A10: # | L10: 上り項目 Request Message Field | M10: 下り項目 Response Message Field | N10: 上り項目 Request Message Field | O10: 下り項目 Response Message Field | P10: 上り項目 Request Message Field | Q10: 下り項目 Response Message Field | R10: 上り項目 Request Message Field | S10: 下り項目 Response Message Field | T10: 上り項目 Request Message Field | U10: 下り項目 Response Message Field | V10: 上り項目 Request Message Field | W10: 下り項目 Response Message Field
A11: 10 | B11: * | D11: MfgActReg_Upd01_Hdr | E11: L | L11: MfgActTblReg_Upd01_Dtl | R11: MfgActTblReg_Upd04_Hdr
A12: 10 | D12: data_crud_typ | E12: #MA.DATA_CRUD_TYP | G12: Data update type | H12: データ更新区分 | I12: E | J12: - | L12: E
A13: 10 | D13: peg_no | E13: #MA.INT | G13: Pegging No. | H13: 紐付けＮＯ | I13: E | J13: E | L13: E | R13: hdr_peg_no
A14: 10 | D14: err_flg | E14: #MA.FLG | G14: Error | H14: エラー | I14: - | J14: -
A15: 10 | D15: rtn_sts_typ | E15: #MA.RTN_STS_TYP | G15: Process result status type | H15: 処理結果状況区分 | I15: - | J15: E
A16: 10 | D16: mfg_sts_typ | E16: #MS.MFG_STS_TYP | G16: Mfg. status type | H16: 製造状況区分 | I16: E | J16: E
A17: 10 | D17: mfg_sts_typ_nm | E17: #MS.MFG_STS_TYP_NM | G17: Mfg. status name | H17: 製造状況区分名 | I17: - | J17: E
A18: 10 | D18: itm_cd | E18: #MA.ITM_CD | G18: Item cd. | H18: 品目ＣＤ | I18: E | J18: -
A19: 10 | D19: itm_sub1 | E19: #MA.ITM_SUB1 | G19: Branch No. 1 | H19: 枝番１ | I19: E | J19: -
A20: 10 | D20: itm_sub2 | E20: #MA.ITM_SUB2 | G20: Branch No. 2 | H20: 枝番２ | I20: E | J20: -
A21: 10 | D21: itm_sub3 | E21: #MA.ITM_SUB3 | G21: Branch No. 3 | H21: 枝番３ | I21: E | J21: -
A22: 10 | D22: itm_nm | E22: #MA.ITM_NM | G22: Item name | H22: 品名 | I22: E | J22: -
A23: 10 | D23: inst_lot_no | E23: #MA.LOT_NO | G23: Lot No. (Order) | H23: ロットＮＯ（指図） | I23: E | J23: -
A24: 10 | D24: inst_sublot_no | E24: #MA.SUBLOT_NO | G24: Sublot No. (Order) | H24: サブロットＮＯ（指図） | I24: E | J24: -
A25: 10 | D25: sno1 | E25: #MA.SNO1 | G25: SEIBAN No. 1 | H25: 手配ＮＯ１ | I25: E | J25: -
... A32: 10 | D32: sno4_mng_typ | E32: #MA.SNO_MNG_TYP | G32: SEIBAN No. 4 management type | H32: 手配ＮＯ４管理区分 | I32: E | J32: -
A33: 10 | D33: st_act_tm | E33: #MA.TM | G33: Actual start date and time | H33: 着手実績日時 | I33: E | J33: - | L33: E
A34: 10 | D34: st_ac_dt | E34: #MA.DT | G34: Start recording date | H34: 着手計上日 | I34: E | J34: - | L34: E
A35: 10 | D35: end_act_tm | E35: #MA.TM | G35: Actual end date and time | H35: 終了実績日時 | I35: E | J35: - | L35: E
A36: 10 | D36: end_ac_dt | E36: #MA.DT | G36: End recording date | H36: 終了計上日 | I36: E | J36: - | L36: E
A37: 10 | D37: itm_mfg_inst_qty | E37: #MA.QTY | G37: Item mfg. order qty. | H37: 品目製造指図数量 | I37: E | J37: -
A38: 10 | D38: base_unit_st_act_qty | E38: #MA.QTY | G38: Start qty. | H38: 着手数量 | I38: E | J38: -
A39: 10 | D39: rem_abort_flg | E39: #MA.FLG | G39: Cancel remaining qty. | H39: 残数打切 | I39: E | J39: -
A40: 10 | D40: base_unit_dec_place | E40: #MA.DEC_PLACE | G40: Base unit number of decimal places | H40: 基準単位小数部有効桁数 | I40: E | J40: -
A41: 10 | D41: base_unit_conv_rnd_typ | E41: #MA.RND_TYP | G41: Base unit rounding type | H41: 基準単位端数処理区分 | I41: E | J41: -
A42: 10 | D42: base_unit_yield_qty | E42: #MA.QTY | G42: Conforming qty. | H42: 良品数量 | I42: E | J42: - | L42: E
A43: 10 | D43: base_unit_dfct_qty | E43: #MA.QTY | G43: Defective qty. | H43: 不良数量 | I43: E | J43: - | L43: E
A44: 10 | D44: base_unit_cd | E44: #MA.UNIT_CD | G44: Base unit cd. | H44: 基準単位ＣＤ | I44: E | J44: - | L44: E
A45: 10 | D45: act_usr_cd | E45: #MA.USR_CD | G45: Result management PIC cd. | H45: 実績責任者ＣＤ | I45: E | J45: - | L45: E
A46: 10 | D46: act_dpt_cd | E46: #MA.DPT_CD | G46: Result dept. cd. | H46: 実績部門ＣＤ | I46: E | J46: - | L46: E
...

Sheet MfgActReg_Upd02
A1: * | B1: * | D1: L | E1: 1
A2: * | D2: オペレーション実装仕様書 Operation Specification Implementation Sheet | E2: ModuleID : | F2: =IF(LogicCommon!C2="","",LogicCommon!C2) -> MS | G2: LogicID : | H2: =IF(LogicCommon!E2="","",LogicCommon!E2) -> MSBCL6050 | I2: Ope.ID : | J2: MfgActReg_Upd02 | K2: Pj.ID : | L2: =IF(LogicCommon!G2="","",LogicCommon!G2) -> MC | M2: Ope.Body : | N2: "mcframe.serverMAUD.MAUDL5010.MAUDL_Operation"
A3: * | D3: =IF(LogicCommon!A3="","",LogicCommon!A3) | E3: SubModuleID : | F3: =IF(LogicCommon!C3="","",LogicCommon!C3) -> MSBC | G3: LogicClass : | H3: =IF(LogicCommon!E3="","",LogicCommon!E3) -> MSBCL_MfgActRegService | I3: Ope.Method : | J3: MfgActReg_Upd02 | K3: SuperClassPj.ID : | L3: =IF(LogicCommon!G3="","",LogicCommon!G3) | O3: Gene.Type : | P3: ALL
A4: * | E4: Version : | F4: 000000 | G4: LogicName : | H4: =IF(LogicCommon!E4="","",LogicCommon!E4) -> 製造実績登録サービス | I4: Ope.Name : | J4: 一括登録・訂正 | K4: SuperLogicID : | L4: =IF(LogicCommon!G4="","",LogicCommon!G4) -> MS.MSUDL5010 | M4: ImplOpe.ID:
A5: * | E5: ACType :
A6: * | D6: 概要 : | E6: 製造実績の一括登録・訂正処理 | M6: ID | O6: ID | Q6: ID
A7: # | I7: U | K7: K | L7: o | M7: MAR1.marUpd01 | N7: o | O7: MAR2.marChk03 | P7: o
A8: # | D8: ブロック名 Block Name | E8: 型 Type | G8: super/share | H8: 対象ブロック名 Target Block Name | L8: TargetName | M8: OPE.MS.MSBCL6050.MfgActReg_Upd01 | N8: TargetName | O8: OPE.MS.MSBCL6050.MfgActReg_Chk03 | P8: TargetName | T8: ブロック備考 Block Remarks
A9: # | D9: 項目名 Field Name | E9: 型 Type | F9: 桁 Digits | G9: フルネーム Full Name | H9: 日本語名 Japanese Name | I9: 上り項目 Request Message Field | J9: 下り項目 Response Message Field | R9: 条件および編集方法 Conditions and Editing Methods | T9: 項目備考 Field Remarks
A10: # | L10: 上り項目 Request Message Field | M10: 下り項目 Response Message Field | N10: 上り項目 Request Message Field | O10: 下り項目 Response Message Field | P10: 上り項目 Request Message Field | Q10: 下り項目 Response Message Field
A11: 10 | B11: * | D11: MfgActReg_Upd02_Ctrl | E11: R | N11: MfgActReg_Chk03_Ctrl
A12: 10 | D12: oper_unit_flg | E12: #MA.FLG | G12: Operation unit result | H12: 工程単位実績 | I12: E | J12: - | N12: E
A13: 10 | D13: act_immed_prnt_flg | E13: #MA.FLG | G13: Record sheet immediate issue | H13: 記録書即時発行 | I13: E | J13: -
A14: 10 | D14: not_bkf_upd_flg | E14: #MA.FLG | G14: Not update BF | H14: ＢＦ更新しない | I14: E | J14: -
A15: 10 | D15: not_wk_cost_upd_calc_flg | E15: #MA.FLG | G15: Do not auto-calculate man-hour | H15: 自動工数計算しない | I15: E | J15: -
A16: 10 | D16: not_io_act_srv_exec_flg | E16: #MA.FLG | G16: GR/GI result service call not required | H16: 受払実績サービス呼び出し不要 | I16: E | J16: -
A17: 10 | D17: is_src_batch_flg | E17: #MA.FLG | G17: Caller batch process | H17: 呼出元バッチ処理 | I17: E | J17: - | N17: E
A18: 10 | D18: upd_cntr_chk_flg | E18: #MA.FLG | G18: Check for update counter | H18: 更新カウンタチェック | I18: E | J18: - | N18: E
A19: 10 | D19: not_commit_flg | E19: #MA.FLG | G19: Do not commit | H19: コミットしない | I19: E | J19: -
A20: 10 | D20: is_oper_act_cmpl_batch_flg | E20: #MA.FLG | G20: Call from operation result completion batch | H20: 工程実績完了バッチから呼び出す | I20: E | J20: -
A22: 20 | B22: * | D22: MfgActReg_Upd02_Hdr1 | E22: L | N22: MfgActReg_Chk03_Hdr1
A23: 20 | D23: peg_no | E23: #MA.INT | G23: Pegging No. | H23: 紐付けＮＯ | I23: E | J23: E | N23: E
A24: 20 | D24: mfg_sts_typ | E24: #MS.MFG_STS_TYP | G24: Mfg. status type | H24: 製造状況区分 | I24: E | J24: E
A25: 20 | D25: mfg_sts_typ_nm | E25: #MS.MFG_STS_TYP_NM | G25: Mfg. status name | H25: 製造状況区分名 | I25: - | J25: E
A26: 20 | D26: st_act_tm | E26: #MA.TM | G26: Actual start date | H26: 着手実績日 | I26: E | J26: - | N26: E
A27: 20 | D27: st_ac_dt | E27: #MA.DT | G27: Start recording date | H27: 着手計上日 | I27: E | J27: - | N27: E
A28: 20 | D28: end_act_tm | E28: #MA.TM | G28: Actual end date | H28: 終了実績日 | I28: E | J28: - | N28: E
A29: 20 | D29: end_ac_dt | E29: #MA.DT | G29: End recording date | H29: 終了計上日 | I29: E | J29: - | N29: E
A30: 20 | D30: base_unit_st_act_qty | E30: #MA.QTY | G30: Start qty. | H30: 着手数量 | I30: E | J30: - | N30: E
A31: 20 | D31: rem_abort_flg | E31: #MA.FLG | G31: Cancel remaining qty. | H31: 残数打切 | I31: E | J31: -
A32: 20 | D32: act_usr_cd | E32: #MA.USR_CD | G32: Result management PIC cd. | H32: 実績責任者ＣＤ | I32: E | J32: -
A33: 20 | D33: act_dpt_cd | E33: #MA.DPT_CD | G33: Result dept. cd. | H33: 実績部門ＣＤ | I33: E | J33: -
A34: 20 | D34: mfg_act_rpt_rmrks | E34: #MS.MFG_ACT_RPT_RMRKS | G34: Mfg. record sheet remarks | H34: 製造記録書備考 | I34: E | J34: -
A35: 20 | D35: mfg_act_intr_rmrks | E35: #MS.MFG_ACT_INTR_RMRKS | G35: Internal remarks | H35: 内部備考 | I35: E | J35: -
A36: 20 | D36: mfg_act_sub_char1 | E36: #MS.MFG_ACT_SUB_CHAR1 | G36: Mfg. result spare 1 | H36: 製造実績予備１ | I36: E | J36: -
A37: 20 | D37: mfg_act_sub_char2 | E37: #MS.MFG_ACT_SUB_CHAR2 | G37: Mfg. result spare 2 | H37: 製造実績予備２ | I37: E | J37: -
A38: 20 | D38: mfg_act_sub_char3 | E38: #MS.MFG_ACT_SUB_CHAR3 | G38: Mfg. result spare 3 | H38: 製造実績予備３ | I38: E | J38: -
A39: 20 | D39: itm_yield | E39: #MA.YIELD | G39: Item actual yield | H39: 品目実際収率 | I39: E | J39: -
A40: 20 | D40: oper_unit_act_qty | E40: #MA.QTY | G40: Operation unit result qty. | H40: 工程単位実績数量 | I40: E | J40: - | N40: E
A41: 20 | D41: oper_act_intr_rmrks | E41: #MS.OPER_ACT_INTR_RMRKS | G41: Operation internal remarks | H41: 工程内部備考 | I41: E | J41: -
...

Sheet MfgActReg_Upd03
A1: * | B1: * | D1: L | E1: 1
A2: * | D2: オペレーション実装仕様書 Operation Specification Implementation Sheet | E2: ModuleID : | F2: =IF(LogicCommon!C2="","",LogicCommon!C2) -> MS | G2: LogicID : | H2: =IF(LogicCommon!E2="","",LogicCommon!E2) -> MSBCL6050 | I2: Ope.ID : | J2: MfgActReg_Upd03 | K2: Pj.ID : | L2: =IF(LogicCommon!G2="","",LogicCommon!G2) -> MC | M2: Ope.Body : | N2: "mcframe.serverMAUD.MAUDL5010.MAUDL_Operation"
A3: * | D3: =IF(LogicCommon!A3="","",LogicCommon!A3) | E3: SubModuleID : | F3: =IF(LogicCommon!C3="","",LogicCommon!C3) -> MSBC | G3: LogicClass : | H3: =IF(LogicCommon!E3="","",LogicCommon!E3) -> MSBCL_MfgActRegService | I3: Ope.Method : | J3: MfgActReg_Upd03 | K3: SuperClassPj.ID : | L3: =IF(LogicCommon!G3="","",LogicCommon!G3) | O3: Gene.Type : | P3: ALL
A4: * | E4: Version : | F4: 000000 | G4: LogicName : | H4: =IF(LogicCommon!E4="","",LogicCommon!E4) -> 製造実績登録サービス | I4: Ope.Name : | J4: 工数実績登録・訂正 | K4: SuperLogicID : | L4: =IF(LogicCommon!G4="","",LogicCommon!G4) -> MS.MSUDL5010 | M4: ImplOpe.ID:
A5: * | E5: ACType :
A6: * | D6: 概要 : | E6: 工数実績の登録・訂正処理 | M6: ID | O6: ID | Q6: ID
A7: # | I7: U | K7: K | L7: o | N7: o | P7: o
A8: # | D8: ブロック名 Block Name | E8: 型 Type | G8: super/share | H8: 対象ブロック名 Target Block Name | L8: TargetName | N8: TargetName | P8: TargetName | T8: ブロック備考 Block Remarks
A9: # | D9: 項目名 Field Name | E9: 型 Type | F9: 桁 Digits | G9: フルネーム Full Name | H9: 日本語名 Japanese Name | I9: 上り項目 Request Message Field | J9: 下り項目 Response Message Field | R9: 条件および編集方法 Conditions and Editing Methods | T9: 項目備考 Field Remarks
A10: # | L10: 上り項目 Request Message Field | M10: 下り項目 Response Message Field | N10: 上り項目 Request Message Field | O10: 下り項目 Response Message Field | P10: 上り項目 Request Message Field | Q10: 下り項目 Response Message Field
A11: 10 | B11: * | D11: MfgActReg_Upd03_Rslt | E11: L | G11: $share$ | H11: MS.MSBCL6050.MfgActReg_Chk04.MfgActReg_Chk04_Rslt
A12: 10 | D12: peg_no | E12: #MA.INT | G12: Pegging No. | H12: 紐付けＮＯ | I12: E | J12: E
A13: 10 | D13: err_flg | E13: #MA.FLG | G13: Error flg. | H13: エラーＦＬＧ | I13: E | J13: E
A14: 10 | D14: data_crud_typ | E14: #MA.DATA_CRUD_TYP | G14: Data update type | H14: データ更新区分 | I14: E | J14: -
A15: 10 | D15: inst_wk_act_flg | E15: #MA.FLG | G15: Order direct man-hour result | H15: 指図工数実績 | I15: E | J15: -
A16: 10 | D16: mfg_inst_no | E16: #MA.MFG_INST_NO | G16: Mfg. order No. | H16: 製造指図ＮＯ | I16: E | J16: -
A17: 10 | D17: div_seq | E17: #MS.DIV_SEQ | G17: Split sequence number | H17: 分割連番 | I17: E | J17: -
A18: 10 | D18: disp_seq | E18: #MA.INT | G18: Display order | H18: 表示順 | I18: - | J18: -
A19: 10 | D19: oper_ptn | E19: #MA.OPER_PTN | G19: Operation pattern | H19: 工程パタン | I19: - | J19: -
A20: 10 | D20: oper_disp_seq | E20: #MA.INT | G20: Routing | H20: 工順 | I20: - | J20: -
A21: 10 | D21: oper_cd | E21: #MA.OPER_CD | G21: Operation cd. | H21: 工程ＣＤ | I21: E | J21: -
A22: 10 | D22: oper_nm | E22: #MA.OPER_NM | G22: Operation name | H22: 工程名 | I22: E | J22: -
A23: 10 | D23: oper_seq | E23: #MA.OPER_SEQ | G23: Operation sequence number | H23: 工程連番 | I23: - | J23: -
... A151: 10 | D151: ext_wk_act_no | E151: #MA.EXT_WK_ACT_NO | G151: External man-hour result No. | H151: 外部工数実績ＮＯ | I151: E | J151: -
A153: 20 | B153: * | D153: MfgActReg_Upd03_Ctrl | E153: R
A154: 20 | D154: not_commit_flg | E154: #MA.FLG | G154: Do not commit | H154: コミットしない | I154: E | J154: -
D155: 詳細 :

Sheet MfgActReg_Upd04
A1: * | B1: * | D1: L | E1: 1
A2: * | D2: オペレーション実装仕様書 Operation Specification Implementation Sheet | E2: ModuleID : | F2: =IF(LogicCommon!C2="","",LogicCommon!C2) -> MS | G2: LogicID : | H2: =IF(LogicCommon!E2="","",LogicCommon!E2) -> MSBCL6050 | I2: Ope.ID : | J2: MfgActReg_Upd04 | K2: Pj.ID : | L2: =IF(LogicCommon!G2="","",LogicCommon!G2) -> MC | M2: Ope.Body : | N2: "mcframe.serverMAUD.MAUDL5010.MAUDL_Operation"
A3: * | D3: =IF(LogicCommon!A3="","",LogicCommon!A3) | E3: SubModuleID : | F3: =IF(LogicCommon!C3="","",LogicCommon!C3) -> MSBC | G3: LogicClass : | H3: =IF(LogicCommon!E3="","",LogicCommon!E3) -> MSBCL_MfgActRegService | I3: Ope.Method : | J3: MfgActReg_Upd04 | K3: SuperClassPj.ID : | L3: =IF(LogicCommon!G3="","",LogicCommon!G3) | O3: Gene.Type : | P3: ALL
A4: * | E4: Version : | F4: 000000 | G4: LogicName : | H4: =IF(LogicCommon!E4="","",LogicCommon!E4) -> 製造実績登録サービス | I4: Ope.Name : | J4: 工程実績完了 | K4: SuperLogicID : | L4: =IF(LogicCommon!G4="","",LogicCommon!G4) -> MS.MSUDL5010 | M4: ImplOpe.ID:
A5: * | E5: ACType :
A6: * | D6: 概要 : | E6: 製造実績受信ＩＦで自動作成された工程実績に紐付くすべての実績が完了になった場合、工程実績を完了にする。 | M6: ID | O6: ID | Q6: ID
A7: # | I7: U | K7: K | L7: o | N7: o | P7: o
A8: # | D8: ブロック名 Block Name | E8: 型 Type | G8: super/share | H8: 対象ブロック名 Target Block Name | L8: TargetName | N8: TargetName | P8: TargetName | T8: ブロック備考 Block Remarks
A9: # | D9: 項目名 Field Name | E9: 型 Type | F9: 桁 Digits | G9: フルネーム Full Name | H9: 日本語名 Japanese Name | I9: 上り項目 Request Message Field | J9: 下り項目 Response Message Field | R9: 条件および編集方法 Conditions and Editing Methods | T9: 項目備考 Field Remarks
A10: # | L10: 上り項目 Request Message Field | M10: 下り項目 Response Message Field | N10: 上り項目 Request Message Field | O10: 下り項目 Response Message Field | P10: 上り項目 Request Message Field | Q10: 下り項目 Response Message Field
A11: 10 | B11: * | D11: MfgActReg_Upd04_Ctrl | E11: R
A12: 10 | D12: is_src_batch_flg | E12: #MA.FLG | G12: Caller batch process | H12: 呼出元バッチ処理 | I12: E | J12: -
A13: 10 | D13: upd_cntr_chk_flg | E13: #MA.FLG | G13: Check for update counter | H13: 更新カウンタチェック | I13: E | J13: -
A14: 10 | D14: not_commit_flg | E14: #MA.FLG | G14: Do not commit | H14: コミットしない | I14: E | J14: -
A15: 10 | D15: not_wk_cost_upd_calc_flg | E15: #MA.FLG | G15: Do not auto-calculate man-hour | H15: 自動工数計算しない | I15: E | J15: -
A17: 20 | B17: * | D17: MfgActReg_Upd04_DtlOper | E17: L
A18: 20 | D18: peg_no | E18: #MA.INT | G18: Pegging No. | H18: 紐付けＮＯ | I18: E | J18: E
A19: 20 | D19: oper_act_no | E19: #MA.OPER_ACT_NO | G19: Operation result No. | H19: 工程実績ＮＯ | I19: E | J19: -
A20: 20 | D20: mfg_inst_no | E20: #MA.MFG_INST_NO | G20: Mfg. order No. | H20: 製造指図ＮＯ | I20: - | J20: -
A21: 20 | D21: rtn_sts_typ | E21: #MA.RTN_STS_TYP | G21: Process result status type | H21: 処理結果状況区分 | I21: - | J21: E
D22: 詳細 :

Sheet MfgActReg_Del01
A1: * | B1: * | D1: L | E1: 1
A2: * | D2: オペレーション実装仕様書 Operation Specification Implementation Sheet | E2: ModuleID : | F2: =IF(LogicCommon!C2="","",LogicCommon!C2) -> MS | G2: LogicID : | H2: =IF(LogicCommon!E2="","",LogicCommon!E2) -> MSBCL6050 | I2: Ope.ID : | J2: MfgActReg_Del01 | K2: Pj.ID : | L2: =IF(LogicCommon!G2="","",LogicCommon!G2) -> MC | M2: Ope.Body : | N2: "mcframe.serverMAUD.MAUDL5010.MAUDL_Operation"
A3: * | D3: =IF(LogicCommon!A3="","",LogicCommon!A3) | E3: SubModuleID : | F3: =IF(LogicCommon!C3="","",LogicCommon!C3) -> MSBC | G3: LogicClass : | H3: =IF(LogicCommon!E3="","",LogicCommon!E3) -> MSBCL_MfgActRegService | I3: Ope.Method : | J3: MfgActReg_Del01 | K3: SuperClassPj.ID : | L3: =IF(LogicCommon!G3="","",LogicCommon!G3) | O3: Gene.Type : | P3: ALL
A4: * | E4: Version : | F4: 000000 | G4: LogicName : | H4: =IF(LogicCommon!E4="","",LogicCommon!E4) -> 製造実績登録サービス | I4: Ope.Name : | J4: 取消 | K4: SuperLogicID : | L4: =IF(LogicCommon!G4="","",LogicCommon!G4) -> MS.MSUDL5010 | M4: ImplOpe.ID:
A5: * | E5: ACType :
A6: * | D6: 概要 : | E6: 製造実績の取消の共通処理 | M6: ID | O6: ID | Q6: ID
A7: # | I7: U | K7: K | L7: o | M7: MA.maChk02 | N7: o | P7: o
A8: # | D8: ブロック名 Block Name | E8: 型 Type | G8: super/share | H8: 対象ブロック名 Target Block Name | L8: TargetName | M8: OPE.MS.MSBCL6050.MfgActReg_Chk02 | N8: TargetName | P8: TargetName | T8: ブロック備考 Block Remarks
A9: # | D9: 項目名 Field Name | E9: 型 Type | F9: 桁 Digits | G9: フルネーム Full Name | H9: 日本語名 Japanese Name | I9: 上り項目 Request Message Field | J9: 下り項目 Response Message Field | R9: 条件および編集方法 Conditions and Editing Methods | T9: 項目備考 Field Remarks
A10: # | L10: 上り項目 Request Message Field | M10: 下り項目 Response Message Field | N10: 上り項目 Request Message Field | O10: 下り項目 Response Message Field | P10: 上り項目 Request Message Field | Q10: 下り項目 Response Message Field
A11: 10 | B11: * | D11: MfgActReg_Del01_Ctrl | E11: R | L11: MfgActReg_Chk02_Ctrl
A12: 10 | D12: lst_del_flg | E12: #MA.FLG | G12: Bulk cancellation flg. | H12: 一括取消ＦＬＧ | I12: E | J12: - | L12: E
A13: 10 | D13: upd_cntr_chk_flg | E13: #MA.FLG | G13: Check for update counter | H13: 更新カウンタチェック | I13: E | J13: - | L13: E
A14: 10 | D14: is_src_batch_flg | E14: #MA.FLG | G14: Caller batch process | H14: 呼出元バッチ処理 | I14: E | J14: - | L14: E
A15: 10 | D15: not_commit_flg | E15: #MA.FLG | G15: Do not commit | H15: コミットしない | I15: E | J15: - | L15: -
A17: 20 | B17: * | D17: MfgActReg_Del01_Hdr | E17: L | L17: MfgActReg_Chk02_Hdr | M17: MfgActReg_Chk02_Hdr
A18: 20 | D18: peg_no | E18: #MA.INT | G18: Pegging No. | H18: 紐付けＮＯ | I18: E | J18: E | L18: E
A19: 20 | D19: mfg_act_no | E19: #MA.MFG_ACT_NO | G19: Mfg. result No. | H19: 製造実績ＮＯ | I19: E | J19: - | L19: E
A20: 20 | D20: mfg_inst_upd_cntr | E20: #MA.UPD_CNT | G20: Mfg. order update counter | H20: 製造指図更新カウンタ | I20: E | J20: - | L20: E
A21: 20 | D21: mfg_inst_pr_upd_cntr | E21: #MA.UPD_CNT | G21: Production order progress update counter | H21: 製造指図進捗更新カウンタ | I21: E | L21: E
A22: 20 | D22: mfg_act_upd_cntr | E22: #MA.UPD_CNT | G22: Mfg. result update counter | H22: 製造実績更新カウンタ | I22: E | J22: - | L22: E
A23: 20 | D23: mfg_inst_no | E23: #MA.MFG_INST_NO | G23: Mfg. order No. | H23: 製造指図ＮＯ | I23: E | J23: - | L23: E
A24: 20 | D24: div_seq | E24: #MS.DIV_SEQ | G24: Split sequence number | H24: 分割連番 | I24: E | J24: - | L24: E
A25: 20 | D25: err_flg | E25: #MA.FLG | G25: Error | H25: エラー | I25: - | J25: E | L25: - | M25: E
A26: 20 | D26: rtn_sts_typ | E26: #MA.RTN_STS_TYP | G26: Process result status type | H26: 処理結果状況区分 | I26: - | J26: E | L26: - | M26: E
A27: 20 | D27: upd_cntr_chk_flg | E27: #MA.FLG | G27: Check for update counter | H27: 更新カウンタチェック | I27: - | J27: - | L27: E
A28: 20 | D28: is_src_batch_flg | E28: #MA.FLG | G28: Caller batch process | H28: 呼出元バッチ処理 | I28: - | J28: - | L28: E
A30: 30 | B30: * | D30: MfgActReg_Del01_DtlInpt | E30: L | L30: MfgActReg_Chk02_DtlInpt
A31: 30 | D31: inpt_act_no | E31: #MA.INPT_ACT_NO | G31: Input result No. | H31: 投入実績ＮＯ | I31: E | J31: - | L31: E
A32: 30 | D32: can_ac_dt | E32: #MA.DT | G32: Cancellation recording date | H32: 取消計上日 | I32: E | J32: - | L32: E
A34: 40 | B34: * | D34: MfgActReg_Del01_DtlYield | E34: L | L34: MfgActReg_Chk02_DtlYield
A35: 40 | D35: yield_act_no | E35: #MA.YIELD_ACT_NO | G35: Output result No. | H35: 出来高実績ＮＯ | I35: E | J35: - | L35: E
A36: 40 | D36: can_ac_dt | E36: #MA.DT | G36: Cancellation recording date | H36: 取消計上日 | I36: E | J36: - | L36: E
A38: 50 | B38: * | D38: MfgActReg_Del01_DtlByProd | E38: L | L38: MfgActReg_Chk02_DtlByProd
A39: 50 | D39: yield_act_no | E39: #MA.YIELD_ACT_NO | G39: Output result No. | H39: 出来高実績ＮＯ | I39: E | J39: - | L39: E
A40: 50 | D40: can_ac_dt | E40: #MA.DT | G40: Cancellation recording date | H40: 取消計上日 | I40: E | J40: - | L40: E
D41: 詳細 :

Sheet MfgActReg_Del02
A1: * | B1: * | D1: L | E1: 1
A2: * | D2: オペレーション実装仕様書 Operation Specification Implementation Sheet | E2: ModuleID : | F2: =IF(LogicCommon!C2="","",LogicCommon!C2) -> MS | G2: LogicID : | H2: =IF(LogicCommon!E2="","",LogicCommon!E2) -> MSBCL6050 | I2: Ope.ID : | J2: MfgActReg_Del02 | K2: Pj.ID : | L2: =IF(LogicCommon!G2="","",LogicCommon!G2) -> MC | M2: Ope.Body : | N2: "mcframe.serverMAUD.MAUDL5010.MAUDL_Operation"
A3: * | D3: =IF(LogicCommon!A3="","",LogicCommon!A3) | E3: SubModuleID : | F3: =IF(LogicCommon!C3="","",LogicCommon!C3) -> MSBC | G3: LogicClass : | H3: =IF(LogicCommon!E3="","",LogicCommon!E3) -> MSBCL_MfgActRegService | I3: Ope.Method : | J3: MfgActReg_Del02 | K3: SuperClassPj.ID : | L3: =IF(LogicCommon!G3="","",LogicCommon!G3) | O3: Gene.Type : | P3: ALL
A4: * | E4: Version : | F4: 000000 | G4: LogicName : | H4: =IF(LogicCommon!E4="","",LogicCommon!E4) -> 製造実績登録サービス | I4: Ope.Name : | J4: 工数実績取消 | K4: SuperLogicID : | L4: =IF(LogicCommon!G4="","",LogicCommon!G4) -> MS.MSUDL5010 | M4: ImplOpe.ID:
A5: * | E5: ACType :
A6: * | D6: 概要 : | E6: 工数実績の取消処理 | M6: ID | O6: ID | Q6: ID
A7: # | I7: U | K7: K | L7: o | N7: o | P7: o
A8: # | D8: ブロック名 Block Name | E8: 型 Type | G8: super/share | H8: 対象ブロック名 Target Block Name | L8: TargetName | N8: TargetName | P8: TargetName | T8: ブロック備考 Block Remarks
A9: # | D9: 項目名 Field Name | E9: 型 Type | F9: 桁 Digits | G9: フルネーム Full Name | H9: 日本語名 Japanese Name | I9: 上り項目 Request Message Field | J9: 下り項目 Response Message Field | R9: 条件および編集方法 Conditions and Editing Methods | T9: 項目備考 Field Remarks
A10: # | L10: 上り項目 Request Message Field | M10: 下り項目 Response Message Field | N10: 上り項目 Request Message Field | O10: 下り項目 Response Message Field | P10: 上り項目 Request Message Field | Q10: 下り項目 Response Message Field
A11: 10 | B11: * | D11: MfgActReg_Del02_Rslt | E11: L | G11: $share$ | H11: MS.MSBCL6050.MfgActReg_Chk04.MfgActReg_Chk04_Rslt
A12: 10 | D12: peg_no | E12: #MA.INT | G12: Pegging No. | H12: 紐付けＮＯ | I12: E | J12: E
A13: 10 | D13: err_flg | E13: #MA.FLG | G13: Error flg. | H13: エラーＦＬＧ | I13: E | J13: E
A14: 10 | D14: data_crud_typ | E14: #MA.DATA_CRUD_TYP | G14: Data update type | H14: データ更新区分 | I14: E | J14: -
A15: 10 | D15: inst_wk_act_flg | E15: #MA.FLG | G15: Order direct man-hour result | H15: 指図工数実績 | I15: E | J15: -
A16: 10 | D16: mfg_inst_no | E16: #MA.MFG_INST_NO | G16: Mfg. order No. | H16: 製造指図ＮＯ | I16: E | J16: -
A17: 10 | D17: div_seq | E17: #MS.DIV_SEQ | G17: Split sequence number | H17: 分割連番 | I17: E | J17: -
A18: 10 | D18: disp_seq | E18: #MA.INT | G18: Display order | H18: 表示順 | I18: - | J18: -
A19: 10 | D19: oper_ptn | E19: #MA.OPER_PTN | G19: Operation pattern | H19: 工程パタン | I19: - | J19: -
A20: 10 | D20: oper_disp_seq | E20: #MA.INT | G20: Routing | H20: 工順 | I20: - | J20: -
A21: 10 | D21: oper_cd | E21: #MA.OPER_CD | G21: Operation cd. | H21: 工程ＣＤ | I21: - | J21: -
A22: 10 | D22: oper_nm | E22: #MA.OPER_NM | G22: Operation name | H22: 工程名 | I22: - | J22: -
A23: 10 | D23: oper_seq | E23: #MA.OPER_SEQ | G23: Operation sequence number | H23: 工程連番 | I23: - | J23: -
... A151: 10 | D151: ext_wk_act_no | E151: #MA.EXT_WK_ACT_NO | G151: External man-hour result No. | H151: 外部工数実績ＮＯ | I151: - | J151: -
A153: 20 | B153: * | D153: MfgActReg_Del02_Ctrl | E153: R
A154: 20 | D154: not_commit_flg | E154: #MA.FLG | G154: Do not commit | H154: コミットしない | I154: E | J154: -
D155: 詳細 :

Sheet Sheet1

Sheet 来歴
A1: 変更来歴
A3: Rev. | H3: 修正番号 | O3: 変更内容 | AQ3: 変更箇所
A4: 1 | O4: 初版
A5: 1.1 | H5: MS7032#065 | O5: MfgActReg_Chk01_Hdrブロックにis_md_src_mfg_srv_flgを追加 | AQ5: MfgActReg_Chk01
A6: 〃 | H6: 〃 | O6: MfgActReg_Upd01_HdrブロックとMfgActReg_Upd01_DtlInptブロックにis_src_md_mfg_srv_flgを追加 | AQ6: MfgActReg_Upd01
A7: 1.2 | H7: MS7032#174 | O7: MfgActReg_Chk01_DtlInptブロックにis_only_abort_flgを追加 | AQ7: MfgActReg_Chk01
A8: 〃 | H8: 〃 | O8: MfgActReg_Upd01_DtlInptブロックにis_only_abort_flgを追加 | AQ8: MfgActReg_Upd01
A9: 〃 | H9: 〃 | O9: MfgActReg_Upd02_DtlInptブロックにis_only_abort_flgを追加 | AQ9: MfgActReg_Upd02
A10: 1.3 | O10: 英語の名称を追記 | AQ10: 全般
