Workbook

Sheet LogicCommon
A2: オペレーション実装仕様書 | B2: ModuleID : | C2: MS | D2: LogicID : | E2: MSBCL0140 | F2: Pj.ID : | G2: MC
B3: SubModuleID : | C3: MSBC | D3: LogicClass : | E3: MSBCL_PrcdOrdReg | F3: SuperClassPj.ID :
D4: LogicName : | E4: 先行手配オーダ訂正 | F4: SuperLogicID : | G4: MS.MSUDL5010
A5: 概要 :
A6: 詳細 :

Sheet Srch01
A1: * | B1: * | D1: L | E1: 1
A2: * | D2: オペレーション実装仕様書 Operation Specification Implementation Sheet | E2: ModuleID : | F2: =IF(LogicCommon!C2="","",LogicCommon!C2) -> MS | G2: LogicID : | H2: =IF(LogicCommon!E2="","",LogicCommon!E2) -> MSBCL0140 | I2: Ope.ID : | J2: Srch01 | K2: Pj.ID : | L2: =IF(LogicCommon!G2="","",LogicCommon!G2) -> MC | M2: Ope.Body : | N2: "mcframe.serverMAUD.MAUDL5010.MAUDL_Searcher"
A3: * | D3: =IF(LogicCommon!A3="","",LogicCommon!A3) | E3: SubModuleID : | F3: =IF(LogicCommon!C3="","",LogicCommon!C3) -> MSBC | G3: LogicClass : | H3: =IF(LogicCommon!E3="","",LogicCommon!E3) -> MSBCL_PrcdOrdReg | I3: Ope.Method : | J3: Srch01 | K3: SuperClassPj.ID : | L3: =IF(LogicCommon!G3="","",LogicCommon!G3) | O3: Gene.Type : | P3: ALL
A4: * | E4: Version : | F4: 000000 | G4: LogicName : | H4: =IF(LogicCommon!E4="","",LogicCommon!E4) -> 先行手配オーダ訂正 | I4: Ope.Name : | J4: 検索 | K4: SuperLogicID : | L4: =IF(LogicCommon!G4="","",LogicCommon!G4) -> MS.MSUDL5010 | M4: ImplOpe.ID:
A5: * | E5: ACType :
A6: * | D6: 概要 : | M6: ID | O6: ID | Q6: ID
A7: # | I7: U | K7: K | L7: o | N7: o | P7: o
A8: # | D8: ブロック名 Block Name | E8: 型 Type | G8: super/share | H8: 対象ブロック名 Target Block Name | K8: CONST | L8: TargetName | N8: TargetName | P8: TargetName | T8: ブロック備考 Block Remarks
A9: # | D9: 項目名 Field Name | E9: 型 Type | F9: 桁 Digits | G9: フルネーム Full Name | H9: 日本語名 Japanese Name | I9: 上り項目 Request Message Field | J9: 下り項目 Response Message Field | R9: 条件および編集方法 Conditions and Editing Methods | T9: 項目備考 Field Remarks
A10: # | L10: 上り項目 Request Message Field | M10: 下り項目 Response Message Field | N10: 上り項目 Request Message Field | O10: 下り項目 Response Message Field | P10: 上り項目 Request Message Field | Q10: 下り項目 Response Message Field
A11: 10 | B11: * | D11: Srch01_Cnd | E11: R
A12: 10 | D12: itm_ord_no | E12: #MA.ITM_ORD_NO | G12: Item order No. | H12: 品目オーダＮＯ | I12: E | J12: -
L13: 上り項目 Request Message Field | M13: 下り項目 Response Message Field | N13: 上り項目 Request Message Field | O13: 下り項目 Response Message Field | P13: 上り項目 Request Message Field | Q13: 下り項目 Response Message Field
A14: 20 | B14: * | D14: Srch01_Hdr | E14: R
A15: 20 | D15: itm_ord_no | E15: #MA.ITM_ORD_NO | G15: Item order No. | H15: 品目オーダＮＯ | I15: - | J15: E
A16: 20 | D16: itm_ord_sts_typ | E16: #MS.ITM_ORD_STS_TYP | G16: Item order status type | H16: 品目オーダ状況区分 | I16: - | J16: E | K16: MSC_ITM_ORD_STS_TYP
A17: 20 | D17: itm_ord_sts_typ_nm | E17: #MS.ITM_ORD_STS_TYP_NM | G17: Item order status type name | H17: 品目オーダ状況区分名 | I17: - | J17: E
A18: 20 | D18: master_dt | E18: #MA.DT | G18: Master application date | H18: マスタ適用日 | I18: - | J18: E
A19: 20 | D19: itm_cd | E19: #MA.ITM_CD | G19: Item cd. | H19: 品目ＣＤ | I19: - | J19: E
A20: 20 | D20: itm_sub1 | E20: #MA.ITM_SUB1 | G20: Branch No. 1 | H20: 枝番１ | I20: - | J20: E
A21: 20 | D21: itm_sub2 | E21: #MA.ITM_SUB2 | G21: Branch No. 2 | H21: 枝番２ | I21: - | J21: E
A22: 20 | D22: itm_sub3 | E22: #MA.ITM_SUB3 | G22: Branch No. 3 | H22: 枝番３ | I22: - | J22: E
A23: 20 | D23: itm_nm | E23: #MA.ITM_NM | G23: Item name | H23: 品名 | I23: - | J23: E
A24: 20 | D24: strg_loc_cd | E24: #MA.LOC_CD | G24: Storage location cd. | H24: 格納場所ＣＤ | I24: - | J24: E
A25: 20 | D25: strg_loc_nm | E25: #MA.LOC_NM | G25: Storage location name | H25: 格納場所名 | I25: - | J25: E
A26: 20 | D26: strg_site_cd | E26: #MA.SITE_CD | G26: Storage factory/distribution warehouse cd. | H26: 格納工場・物流倉庫ＣＤ | I26: - | J26: E
A27: 20 | D27: strg_site_nm | E27: #MA.SITE_NM | G27: Storage factory/distribution warehouse name | H27: 格納工場・物流倉庫名 | I27: - | J27: E
A28: 20 | D28: wg_cd | E28: #MA.WG_CD | G28: WG cd. | H28: ワーキンググループＣＤ | I28: - | J28: E
... A30: 20 | D30: strg_sppl_cd | E30: #MA.BP_CD | G30: Storage location supplier cd. | H30: 格納場所発注先ＣＤ | I30: - | J30: E
A31: 20 | D31: itm_ord_typ | E31: #MS.ITM_ORD_TYP | G31: Order type | H31: オーダ区分 | I31: - | J31: E | K31: MSC_ITM_ORD_TYP
A32: 20 | D32: itm_ord_typ_nm | E32: #MS.ITM_ORD_TYP_NM | G32: Order type name | H32: オーダ区分名 | I32: - | J32: E
A33: 20 | D33: bom_ptn | E33: #MA.BOM_PTN | G33: BOM pattern | H33: 構成パタン | I33: - | J33: E
A34: 20 | D34: mst_mfg_loc_cd | E34: #MA.LOC_CD | G34: Master mfg. location cd. | H34: マスタ製造場所ＣＤ | I34: - | J34: E
A35: 20 | D35: mfg_loc_cd | E35: #MA.LOC_CD | G35: Mfg. location cd. | H35: 製造場所ＣＤ | I35: - | J35: E
A36: 20 | D36: mfg_loc_nm | E36: #MA.LOC_NM | G36: Mfg. location name | H36: 製造場所名 | I36: - | J36: E
A37: 20 | D37: mfg_sppl_cd | E37: #MA.BP_CD | G37: Mfg. location supplier cd. | H37: 製造場所発注先ＣＤ | I37: - | J37: E
A38: 20 | D38: mfg_maker_cd | E38: #MA.BP_CD | G38: Mfg. location maker cd. | H38: 製造場所メーカＣＤ | I38: - | J38: E
A39: 20 | D39: sppl_cd | E39: #MA.BP_CD | G39: Supplier cd. | H39: 発注先ＣＤ | I39: - | J39: E
A40: 20 | D40: sppl_nm | E40: #MA.BP_NM | G40: Supplier name | H40: 発注先名 | I40: - | J40: E
A41: 20 | D41: maker_cd | E41: #MA.BP_CD | G41: Maker cd. | H41: メーカＣＤ | I41: - | J41: E
...

Sheet Sprt01
A1: * | B1: * | D1: L | E1: 1
A2: * | D2: オペレーション実装仕様書 Operation Specification Implementation Sheet | E2: ModuleID : | F2: =IF(LogicCommon!C2="","",LogicCommon!C2) -> MS | G2: LogicID : | H2: =IF(LogicCommon!E2="","",LogicCommon!E2) -> MSBCL0140 | I2: Ope.ID : | J2: Sprt01 | K2: Pj.ID : | L2: =IF(LogicCommon!G2="","",LogicCommon!G2) -> MC | M2: Ope.Body : | N2: "mcframe.serverMAUD.MAUDL5010.MAUDL_Operation"
A3: * | D3: =IF(LogicCommon!A3="","",LogicCommon!A3) | E3: SubModuleID : | F3: =IF(LogicCommon!C3="","",LogicCommon!C3) -> MSBC | G3: LogicClass : | H3: =IF(LogicCommon!E3="","",LogicCommon!E3) -> MSBCL_PrcdOrdReg | I3: Ope.Method : | J3: @ | K3: SuperClassPj.ID : | L3: =IF(LogicCommon!G3="","",LogicCommon!G3) | O3: Gene.Type : | P3: ALL
A4: * | E4: Version : | F4: 000000 | G4: LogicName : | H4: =IF(LogicCommon!E4="","",LogicCommon!E4) -> 先行手配オーダ訂正 | I4: Ope.Name : | J4: 日付計算 | K4: SuperLogicID : | L4: =IF(LogicCommon!G4="","",LogicCommon!G4) -> MS.MSUDL5010 | M4: ImplOpe.ID:
A5: * | E5: ACType :
A6: * | D6: 概要 : | M6: ID | O6: ID | Q6: ID
A7: # | I7: U | L7: o | N7: o | P7: o
A8: # | D8: ブロック名 Block Name | E8: 型 Type | G8: super/share | H8: 対象ブロック名 Target Block Name | L8: TargetName | N8: TargetName | P8: TargetName | T8: ブロック備考 Block Remarks
A9: # | D9: 項目名 Field Name | E9: 型 Type | F9: 桁 Digits | G9: フルネーム Full Name | H9: 日本語名 Japanese Name | I9: 上り項目 Request Message Field | J9: 下り項目 Response Message Field | R9: 条件および編集方法 Conditions and Editing Methods | T9: 項目備考 Field Remarks
A10: # | L10: 上り項目 Request Message Field | M10: 下り項目 Response Message Field | N10: 上り項目 Request Message Field | O10: 下り項目 Response Message Field | P10: 上り項目 Request Message Field | Q10: 下り項目 Response Message Field
A11: 10 | B11: * | D11: Sprt01_Cnd | E11: R
A12: 10 | D12: master_dt | E12: #MA.DT | G12: Master application date | H12: マスタ適用日 | I12: E | J12: -
A13: 10 | D13: itm_cd | E13: #MA.ITM_CD | G13: Item cd. | H13: 品目ＣＤ | I13: E | J13: -
A14: 10 | D14: itm_sub1 | E14: #MA.ITM_SUB1 | G14: Branch No. 1 | H14: 枝番１ | I14: E | J14: -
A15: 10 | D15: itm_sub2 | E15: #MA.ITM_SUB2 | G15: Branch No. 2 | H15: 枝番２ | I15: E | J15: -
A16: 10 | D16: itm_sub3 | E16: #MA.ITM_SUB3 | G16: Branch No. 3 | H16: 枝番３ | I16: E | J16: -
A17: 10 | D17: strg_loc_cd | E17: #MA.LOC_CD | G17: Storage location cd. | H17: 格納場所ＣＤ | I17: E | J17: -
A18: 10 | D18: itm_ord_typ | E18: #MS.ITM_ORD_TYP | G18: Order type | H18: オーダ区分 | I18: E | J18: -
A19: 10 | D19: mfg_loc_cd | E19: #MA.LOC_CD | G19: Mfg. location cd. | H19: 製造場所ＣＤ | I19: E | J19: -
A20: 10 | D20: sppl_cd | E20: #MA.BP_CD | G20: Supplier cd. | H20: 発注先ＣＤ | I20: E | J20: -
A21: 10 | D21: maker_cd | E21: #MA.BP_CD | G21: Maker cd. | H21: メーカＣＤ | I21: E | J21: -
A22: 10 | D22: rqst_loc_cd | E22: #MA.LOC_CD | G22: Requested location cd. | H22: 依頼先場所ＣＤ | I22: E | J22: -
A23: 10 | D23: bom_ptn | E23: #MA.BOM_PTN | G23: BOM pattern | H23: 構成パタン | I23: E | J23: -
... A40: 10 | D40: insp_flg | E40: #MA.FLG | G40: For inspection | H40: 検査対象 | I40: - | J40: E
D41: 詳細 :

Sheet Sprt02
A1: * | B1: * | D1: L | E1: 1
A2: * | D2: オペレーション実装仕様書 Operation Specification Implementation Sheet | E2: ModuleID : | F2: =IF(LogicCommon!C2="","",LogicCommon!C2) -> MS | G2: LogicID : | H2: =IF(LogicCommon!E2="","",LogicCommon!E2) -> MSBCL0140 | I2: Ope.ID : | J2: Sprt02 | K2: Pj.ID : | L2: =IF(LogicCommon!G2="","",LogicCommon!G2) -> MC | M2: Ope.Body : | N2: "mcframe.serverMAUD.MAUDL5010.MAUDL_Operation"
A3: * | D3: =IF(LogicCommon!A3="","",LogicCommon!A3) | E3: SubModuleID : | F3: =IF(LogicCommon!C3="","",LogicCommon!C3) -> MSBC | G3: LogicClass : | H3: =IF(LogicCommon!E3="","",LogicCommon!E3) -> MSBCL_PrcdOrdReg | I3: Ope.Method : | J3: @ | K3: SuperClassPj.ID : | L3: =IF(LogicCommon!G3="","",LogicCommon!G3) | O3: Gene.Type : | P3: ALL
A4: * | E4: Version : | F4: 000000 | G4: LogicName : | H4: =IF(LogicCommon!E4="","",LogicCommon!E4) -> 先行手配オーダ訂正 | I4: Ope.Name : | J4: 工程オーダ展開 | K4: SuperLogicID : | L4: =IF(LogicCommon!G4="","",LogicCommon!G4) -> MS.MSUDL5010 | M4: ImplOpe.ID:
A5: * | E5: ACType :
A6: * | D6: 概要 : | M6: ID | O6: ID | Q6: ID
A7: # | I7: U | K7: K | L7: o | N7: o | P7: o
A8: # | D8: ブロック名 Block Name | E8: 型 Type | G8: super/share | H8: 対象ブロック名 Target Block Name | K8: CONST | L8: TargetName | N8: TargetName | P8: TargetName | T8: ブロック備考 Block Remarks
A9: # | D9: 項目名 Field Name | E9: 型 Type | F9: 桁 Digits | G9: フルネーム Full Name | H9: 日本語名 Japanese Name | I9: 上り項目 Request Message Field | J9: 下り項目 Response Message Field | R9: 条件および編集方法 Conditions and Editing Methods | T9: 項目備考 Field Remarks
A10: # | L10: 上り項目 Request Message Field | M10: 下り項目 Response Message Field | N10: 上り項目 Request Message Field | O10: 下り項目 Response Message Field | P10: 上り項目 Request Message Field | Q10: 下り項目 Response Message Field
A11: 10 | B11: * | D11: Sprt02_Cnd | E11: R
A12: 10 | D12: master_dt | E12: #MA.DT | G12: Master application date | H12: マスタ適用日 | I12: E | J12: -
A13: 10 | D13: itm_cd | E13: #MA.ITM_CD | G13: Item cd. | H13: 品目ＣＤ | I13: E | J13: -
A14: 10 | D14: itm_sub1 | E14: #MA.ITM_SUB1 | G14: Branch No. 1 | H14: 枝番１ | I14: E | J14: -
A15: 10 | D15: itm_sub2 | E15: #MA.ITM_SUB2 | G15: Branch No. 2 | H15: 枝番２ | I15: E | J15: -
A16: 10 | D16: itm_sub3 | E16: #MA.ITM_SUB3 | G16: Branch No. 3 | H16: 枝番３ | I16: E | J16: -
A17: 10 | D17: itm_ord_typ | E17: #MS.ITM_ORD_TYP | G17: Item order type | H17: 品目オーダ区分 | I17: E | J17: -
A18: 10 | D18: bom_ptn | E18: #MA.BOM_PTN | G18: BOM pattern | H18: 構成パタン | I18: E | J18: -
A19: 10 | D19: mfg_loc_cd | E19: #MA.LOC_CD | G19: Mfg. location cd. | H19: 製造場所ＣＤ | I19: E | J19: -
A20: 10 | D20: oper_ptn | E20: #MA.OPER_PTN | G20: Operation pattern | H20: 工程パタン | I20: E | J20: -
A21: 10 | D21: sno1 | E21: #MA.SNO1 | G21: SEIBAN No. 1 | H21: 手配ＮＯ１ | I21: E | J21: -
A22: 10 | D22: sno2 | E22: #MA.SNO2 | G22: SEIBAN No. 2 | H22: 手配ＮＯ２ | I22: E | J22: -
A23: 10 | D23: sno3 | E23: #MA.SNO3 | G23: SEIBAN No. 3 | H23: 手配ＮＯ３ | I23: E | J23: -
... A27: 10 | D27: mfg_end_schd_dt | E27: #MA.DT | G27: Scheduled mfg. end date | H27: 製造終了予定日 | I27: E | J27: -
L28: 上り項目 Request Message Field | M28: 下り項目 Response Message Field | N28: 上り項目 Request Message Field | O28: 下り項目 Response Message Field | P28: 上り項目 Request Message Field | Q28: 下り項目 Response Message Field
A29: 20 | B29: * | D29: Sprt02_Rslt | E29: L
A30: 20 | D30: oper_ord_sts_typ | E30: #MS.OPER_ORD_STS_TYP | G30: Operation order status type | H30: 工程オーダ状況区分 | I30: - | J30: E | K30: MSC_OPER_ORD_STS_TYP
A31: 20 | D31: oper_ord_sts_typ_nm | E31: #MS.OPER_ORD_STS_TYP_NM | G31: Operation order status type name | H31: 工程オーダ状況区分名 | I31: - | J31: E
A32: 20 | D32: oper_cd | E32: #MA.OPER_CD | G32: Operation cd. | H32: 工程ＣＤ | I32: - | J32: E
A33: 20 | D33: oper_nm | E33: #MA.OPER_NM | G33: Operation name | H33: 工程名 | I33: - | J33: E
A34: 20 | D34: oper_seq | E34: #MA.OPER_SEQ | G34: Operation sequence number | H34: 工程連番 | I34: - | J34: E
A35: 20 | D35: mst_mfg_loc_cd | E35: #MA.LOC_CD | G35: Master mfg. location cd. | H35: マスタ製造場所ＣＤ | I35: - | J35: E
A36: 20 | D36: loc_cd | E36: #MA.LOC_CD | G36: Location cd. | H36: 場所ＣＤ | I36: - | J36: E
A37: 20 | D37: loc_nm | E37: #MA.LOC_NM | G37: Location name | H37: 場所名 | I37: - | J37: E
A38: 20 | D38: disp_seq | E38: #MA.INT | G38: Routing | H38: 工順 | I38: - | J38: E
A39: 20 | D39: oper_schd_qty | E39: #MA.QTY | G39: Operation order scheduled qty. | H39: 工程指図予定数量 | I39: - | J39: E
A40: 20 | D40: base_unit_cd | E40: #MA.UNIT_CD | G40: Base unit cd. | H40: 基準単位ＣＤ | I40: - | J40: E
A41: 20 | D41: base_unit_nm | E41: #MA.UNIT_NM | G41: Base unit name | H41: 基準単位名 | I41: - | J41: E
A42: 20 | D42: base_dec_place | E42: #MA.DEC_PLACE | G42: Base unit number of decimal places | H42: 基準単位小数部有効桁数 | I42: - | J42: E
... A55: 20 | D55: oper_lt | E55: #MA.LT | G55: Operation LT | H55: 工程ＬＴ | I55: - | J55: E
...

Sheet Sprt03
A1: * | B1: * | D1: L | E1: 1
A2: * | D2: オペレーション実装仕様書 Operation Specification Implementation Sheet | E2: ModuleID : | F2: =IF(LogicCommon!C2="","",LogicCommon!C2) -> MS | G2: LogicID : | H2: =IF(LogicCommon!E2="","",LogicCommon!E2) -> MSBCL0140 | I2: Ope.ID : | J2: Sprt03 | K2: Pj.ID : | L2: =IF(LogicCommon!G2="","",LogicCommon!G2) -> MC | M2: Ope.Body : | N2: "mcframe.serverMAUD.MAUDL5010.MAUDL_Operation"
A3: * | D3: =IF(LogicCommon!A3="","",LogicCommon!A3) | E3: SubModuleID : | F3: =IF(LogicCommon!C3="","",LogicCommon!C3) -> MSBC | G3: LogicClass : | H3: =IF(LogicCommon!E3="","",LogicCommon!E3) -> MSBCL_PrcdOrdReg | I3: Ope.Method : | J3: @ | K3: SuperClassPj.ID : | L3: =IF(LogicCommon!G3="","",LogicCommon!G3) | O3: Gene.Type : | P3: ALL
A4: * | E4: Version : | F4: 000000 | G4: LogicName : | H4: =IF(LogicCommon!E4="","",LogicCommon!E4) -> 先行手配オーダ訂正 | I4: Ope.Name : | J4: 検査対象取得 | K4: SuperLogicID : | L4: =IF(LogicCommon!G4="","",LogicCommon!G4) -> MS.MSUDL5010 | M4: ImplOpe.ID:
A5: * | E5: ACType :
A6: * | D6: 概要 : | M6: ID | O6: ID | Q6: ID
A7: # | I7: U | L7: o | N7: o | P7: o
A8: # | D8: ブロック名 Block Name | E8: 型 Type | G8: super/share | H8: 対象ブロック名 Target Block Name | L8: TargetName | N8: TargetName | P8: TargetName | T8: ブロック備考 Block Remarks
A9: # | D9: 項目名 Field Name | E9: 型 Type | F9: 桁 Digits | G9: フルネーム Full Name | H9: 日本語名 Japanese Name | I9: 上り項目 Request Message Field | J9: 下り項目 Response Message Field | R9: 条件および編集方法 Conditions and Editing Methods | T9: 項目備考 Field Remarks
A10: # | L10: 上り項目 Request Message Field | M10: 下り項目 Response Message Field | N10: 上り項目 Request Message Field | O10: 下り項目 Response Message Field | P10: 上り項目 Request Message Field | Q10: 下り項目 Response Message Field
A11: 10 | B11: * | D11: Sprt03_Cnd | E11: R
A12: 10 | D12: peg_no | E12: #MA.INT | G12: Pegging No. | H12: 紐付けＮＯ | I12: - | J12: -
A13: 10 | D13: master_dt | E13: #MA.DT | G13: Master application date | H13: マスタ適用日 | I13: E | J13: -
A14: 10 | D14: itm_cd | E14: #MA.ITM_CD | G14: Item cd. | H14: 品目ＣＤ | I14: E | J14: -
A15: 10 | D15: itm_sub1 | E15: #MA.ITM_SUB1 | G15: Branch No. 1 | H15: 枝番１ | I15: E | J15: -
A16: 10 | D16: itm_sub2 | E16: #MA.ITM_SUB2 | G16: Branch No. 2 | H16: 枝番２ | I16: E | J16: -
A17: 10 | D17: itm_sub3 | E17: #MA.ITM_SUB3 | G17: Branch No. 3 | H17: 枝番３ | I17: E | J17: -
A18: 10 | D18: strg_loc_cd | E18: #MA.LOC_CD | G18: Storage location cd. | H18: 格納場所ＣＤ | I18: E | J18: -
A19: 10 | D19: itm_ord_typ | E19: #MS.ITM_ORD_TYP | G19: Order type | H19: オーダ区分 | I19: E | J19: -
A20: 10 | D20: mfg_loc_cd | E20: #MA.LOC_CD | G20: Mfg. location cd. | H20: 製造場所ＣＤ | I20: E | J20: -
A21: 10 | D21: mfg_sppl_cd | E21: #MA.BP_CD | G21: Mfg. location supplier cd. | H21: 製造場所発注先ＣＤ | I21: E | J21: -
A22: 10 | D22: mfg_maker_cd | E22: #MA.BP_CD | G22: Mfg. location maker cd. | H22: 製造場所メーカＣＤ | I22: E | J22: -
A23: 10 | D23: sppl_cd | E23: #MA.BP_CD | G23: Supplier cd. | H23: 発注先ＣＤ | I23: E | J23: -
... A29: 10 | D29: strg_schd_dt | E29: #MA.DT | G29: Scheduled storage completion date | H29: 格納完了予定日 | I29: E | J29: -
D30: 詳細 :

Sheet Chk01
A1: * | B1: * | D1: L | E1: 1
A2: * | D2: オペレーション実装仕様書 Operation Specification Implementation Sheet | E2: ModuleID : | F2: =IF(LogicCommon!C2="","",LogicCommon!C2) -> MS | G2: LogicID : | H2: =IF(LogicCommon!E2="","",LogicCommon!E2) -> MSBCL0140 | I2: Ope.ID : | J2: Chk01 | K2: Pj.ID : | L2: =IF(LogicCommon!G2="","",LogicCommon!G2) -> MC | M2: Ope.Body : | N2: MA.MAUDL5010.Checker
A3: * | D3: =IF(LogicCommon!A3="","",LogicCommon!A3) | E3: SubModuleID : | F3: =IF(LogicCommon!C3="","",LogicCommon!C3) -> MSBC | G3: LogicClass : | H3: =IF(LogicCommon!E3="","",LogicCommon!E3) -> MSBCL_PrcdOrdReg | I3: Ope.Method : | J3: Chk01 | K3: SuperClassPj.ID : | L3: =IF(LogicCommon!G3="","",LogicCommon!G3) | O3: Gene.Type : | P3: ALL
A4: * | E4: Version : | F4: 000000 | G4: LogicName : | H4: =IF(LogicCommon!E4="","",LogicCommon!E4) -> 先行手配オーダ訂正 | I4: Ope.Name : | J4: 更新前チェック | K4: SuperLogicID : | L4: =IF(LogicCommon!G4="","",LogicCommon!G4) -> MS.MSUDL5010 | M4: ImplOpe.ID:
A5: * | E5: ACType :
A6: * | D6: 概要 : | U6: ID | W6: ID | Y6: ID
A7: # | I7: U | K7: K | L7: K | M7: K | N7: K | O7: K | P7: K | Q7: K | R7: K | S7: K | T7: o | V7: o | X7: o
A8: # | D8: ブロック名 Block Name | E8: 型 Type | G8: super/share | H8: 対象ブロック名 Target Block Name | K8: CONST | L8: REQ_UPD_CNT_CHK | M8: NULL_VAL | N8: CHK_NUM | O8: LIST_LOGIC | P8: LIST_OUT | Q8: LIST_OUT_BASE | R8: LIST_IN | S8: LIST_IN_BASE | T8: TargetName | V8: TargetName | X8: TargetName | AB8: ブロック備考 Block Remarks
A9: # | D9: 項目名 Field Name | E9: 型 Type | F9: 桁 Digits | G9: フルネーム Full Name | H9: 日本語名 Japanese Name | I9: 上り項目 Request Message Field | J9: 下り項目 Response Message Field | Z9: 条件および編集方法 Conditions and Editing Methods | AB9: 項目備考 Field Remarks
A10: # | T10: 上り項目 Request Message Field | U10: 下り項目 Response Message Field | V10: 上り項目 Request Message Field | W10: 下り項目 Response Message Field | X10: 上り項目 Request Message Field | Y10: 下り項目 Response Message Field
A11: 10 | B11: * | D11: Chk01_Hdr | E11: R
A12: 10 | D12: peg_no | E12: #MA.INT | G12: Pegging No. | H12: 紐付けＮＯ | I12: E | J12: E
A13: 10 | D13: err_flg | E13: #MA.FLG | G13: Error | H13: エラー | I13: - | J13: E
A14: 10 | D14: mrp_typ | E14: #MS.MRP_TYP | G14: MRP type | H14: ＭＲＰタイプ | I14: - | J14: -
A15: 10 | D15: data_crud_typ | E15: #MA.DATA_CRUD_TYP | G15: Data update type | H15: データ更新区分 | I15: E | J15: -
A16: 10 | D16: ord | E16: R | F16: DBC:MS.MST_PRCD_ITM_ORDER
A17: 10 | D17: ord.itm_ord_no# | E17: RI | G17: Item order No. | H17: 品目オーダＮＯ | I17: E | J17: - | L17: E
A18: 10 | D18: ord.itm_ord_typ# | E18: RI | G18: Order type | H18: オーダ区分 | I18: E | J18: -
A19: 10 | D19: ord.ord_gnrt_typ# | E19: RI | G19: Order generation type | H19: オーダ生成区分 | I19: - | J19: -
A20: 10 | D20: ord.itm_cd# | E20: RI | G20: Item cd. | H20: 品目ＣＤ | I20: - | J20: -
A21: 10 | D21: ord.itm_sub1# | E21: RI | G21: Branch No. 1 | H21: 枝番１ | I21: - | J21: -
A22: 10 | D22: ord.itm_sub2# | E22: RI | G22: Branch No. 2 | H22: 枝番２ | I22: - | J22: -
A23: 10 | D23: ord.itm_sub3# | E23: RI | G23: Branch No. 3 | H23: 枝番３ | I23: - | J23: -
A24: 10 | D24: ord.ver_no# | E24: RI | G24: Version No. | H24: 版ＮＯ | I24: - | J24: -
A25: 10 | D25: ord.strg_loc_cd# | E25: RI | G25: Storage location cd. | H25: 格納場所ＣＤ | I25: E | J25: - | O25: MA.MAUAL0010.Loc | P25: wg_cd | Q25: wg_cd | R25: strg_loc_cd;MAC_DPT_IS_SRCH_TYP.COMM | S25: loc_cd;loc_is_srch_typ
A26: 10 | D26: ord.mfg_loc_cd# | E26: RI | G26: Mfg. location cd. | H26: 製造場所ＣＤ | I26: E | J26: -
A27: 10 | D27: ord.mst_mfg_loc_cd# | E27: RI | G27: Master mfg. location cd. | H27: マスタ製造場所ＣＤ | I27: - | J27: -
A28: 10 | D28: ord.sppl_cd# | E28: RI | G28: Supplier cd. | H28: 発注先ＣＤ | I28: E | J28: -
A29: 10 | D29: ord.maker_cd# | E29: RI | G29: Maker cd. | H29: メーカＣＤ | I29: E | J29: -
A30: 10 | D30: ord.rqst_loc_cd# | E30: RI | G30: Requested location cd. | H30: 依頼先場所ＣＤ | I30: E | J30: -
A31: 10 | D31: ord.rqst_wg_cd# | E31: RI | G31: Requested WG cd. | H31: 依頼先ワーキンググループＣＤ | I31: E | J31: -
A32: 10 | D32: ord.bom_ptn# | E32: RI | G32: BOM pattern | H32: 構成パタン | I32: E | J32: -
A33: 10 | D33: ord.oper_ptn# | E33: RI | G33: Operation pattern | H33: 工程パタン | I33: E | J33: -
A34: 10 | D34: ord.inst_qty# | E34: RI | G34: Order scheduled qty. | H34: 指図予定数量 | I34: E | J34: -
A35: 10 | D35: ord.yield_schd_qty# | E35: RI | G35: Output scheduled qty. | H35: 出来高予定数量 | I35: E | J35: -
A36: 10 | D36: ord.nmr_qty# | E36: RI | G36: Yield numerator | H36: 歩留分子 | I36: - | J36: -
A37: 10 | D37: ord.dnm_qty# | E37: RI | G37: Yield denominator | H37: 歩留分母 | I37: - | J37: -
A38: 10 | D38: ord.fxd_yield_qty# | E38: RI | G38: Constant yield qty. | H38: 固定歩留数量 | I38: - | J38: -
A39: 10 | D39: ord.itm_ord_sts_typ# | E39: RI | G39: Item order status type | H39: 品目オーダ状況区分 | I39: - | J39: - | K39: MSC_ITM_ORD_STS_TYP
A40: 10 | D40: ord.po_schd_dt# | E40: RI | G40: Scheduled PO date | H40: 発注予定日 | I40: E | J40: -
...

Sheet Chk02
A1: * | B1: * | D1: L | E1: 1
A2: * | D2: オペレーション実装仕様書 Operation Specification Implementation Sheet | E2: ModuleID : | F2: =IF(LogicCommon!C2="","",LogicCommon!C2) -> MS | G2: LogicID : | H2: =IF(LogicCommon!E2="","",LogicCommon!E2) -> MSBCL0140 | I2: Ope.ID : | J2: Chk02 | K2: Pj.ID : | L2: =IF(LogicCommon!G2="","",LogicCommon!G2) -> MC | M2: Ope.Body : | N2: MA.MAUDL5010.Checker
A3: * | D3: =IF(LogicCommon!A3="","",LogicCommon!A3) | E3: SubModuleID : | F3: =IF(LogicCommon!C3="","",LogicCommon!C3) -> MSBC | G3: LogicClass : | H3: =IF(LogicCommon!E3="","",LogicCommon!E3) -> MSBCL_PrcdOrdReg | I3: Ope.Method : | J3: Chk02 | K3: SuperClassPj.ID : | L3: =IF(LogicCommon!G3="","",LogicCommon!G3) | O3: Gene.Type : | P3: ALL
A4: * | E4: Version : | F4: 000000 | G4: LogicName : | H4: =IF(LogicCommon!E4="","",LogicCommon!E4) -> 先行手配オーダ訂正 | I4: Ope.Name : | J4: 取消前チェック | K4: SuperLogicID : | L4: =IF(LogicCommon!G4="","",LogicCommon!G4) -> MS.MSUDL5010 | M4: ImplOpe.ID:
A5: * | E5: ACType :
A6: * | D6: 概要 : | M6: ID | O6: ID | Q6: ID
A7: # | I7: U | K7: K | L7: o | N7: o | P7: o
A8: # | D8: ブロック名 Block Name | E8: 型 Type | G8: super/share | H8: 対象ブロック名 Target Block Name | K8: REQ_UPD_CNT_CHK | L8: TargetName | N8: TargetName | P8: TargetName | T8: ブロック備考 Block Remarks
A9: # | D9: 項目名 Field Name | E9: 型 Type | F9: 桁 Digits | G9: フルネーム Full Name | H9: 日本語名 Japanese Name | I9: 上り項目 Request Message Field | J9: 下り項目 Response Message Field | R9: 条件および編集方法 Conditions and Editing Methods | T9: 項目備考 Field Remarks
A10: # | L10: 上り項目 Request Message Field | M10: 下り項目 Response Message Field | N10: 上り項目 Request Message Field | O10: 下り項目 Response Message Field | P10: 上り項目 Request Message Field | Q10: 下り項目 Response Message Field
A11: 10 | B11: * | D11: Chk02_Hdr | E11: R
A12: 10 | D12: peg_no | E12: #MA.INT | G12: Pegging number | H12: 紐付け番号 | I12: E | J12: E
A13: 10 | D13: err_flg | E13: #MA.FLG | G13: Error | H13: エラー | I13: - | J13: E
A14: 10 | D14: mrp_typ | E14: #MS.MRP_TYP | G14: MRP type | H14: ＭＲＰタイプ | I14: - | J14: E
A15: 10 | D15: data_crud_typ | E15: #MA.DATA_CRUD_TYP | G15: Data update type | H15: データ更新区分 | I15: - | J15: E
A16: 10 | D16: ord | E16: R | F16: DBC:MS.MST_PRCD_ITM_ORDER | I16: - | J16: -
A17: 10 | D17: ord.itm_ord_no# | E17: RI | G17: Item order No. | H17: 品目オーダＮＯ | I17: E | J17: E | K17: E
A18: 10 | D18: ord.rqmt_no# | E18: RI | G18: Requirements No. | H18: 所要ＮＯ | I18: E | J18: -
A19: 10 | D19: ord.upd_cntr#itm_order_upd_cntr | E19: RI | G19: Item order update counter | H19: 品目オーダ更新カウンタ | I19: E | J19: -
D20: 詳細 :

Sheet Upd01
A1: * | B1: * | D1: L | E1: 1
A2: * | D2: オペレーション実装仕様書 Operation Specification Implementation Sheet | E2: ModuleID : | F2: =IF(LogicCommon!C2="","",LogicCommon!C2) -> MS | G2: LogicID : | H2: =IF(LogicCommon!E2="","",LogicCommon!E2) -> MSBCL0140 | I2: Ope.ID : | J2: Upd01 | K2: Pj.ID : | L2: =IF(LogicCommon!G2="","",LogicCommon!G2) -> MC | M2: Ope.Body : | N2: "mcframe.serverMAUD.MAUDL5010.MAUDL_Operation"
A3: * | D3: =IF(LogicCommon!A3="","",LogicCommon!A3) | E3: SubModuleID : | F3: =IF(LogicCommon!C3="","",LogicCommon!C3) -> MSBC | G3: LogicClass : | H3: =IF(LogicCommon!E3="","",LogicCommon!E3) -> MSBCL_PrcdOrdReg | I3: Ope.Method : | J3: Upd01 | K3: SuperClassPj.ID : | L3: =IF(LogicCommon!G3="","",LogicCommon!G3) | O3: Gene.Type : | P3: ALL
A4: * | E4: Version : | F4: 000000 | G4: LogicName : | H4: =IF(LogicCommon!E4="","",LogicCommon!E4) -> 先行手配オーダ訂正 | I4: Ope.Name : | J4: 訂正する | K4: SuperLogicID : | L4: =IF(LogicCommon!G4="","",LogicCommon!G4) -> MS.MSUDL5010 | M4: ImplOpe.ID:
A5: * | E5: ACType :
A6: * | D6: 概要 : | M6: ID | O6: ID | Q6: ID
A7: # | I7: U | K7: K | L7: o | N7: o | P7: o
A8: # | D8: ブロック名 Block Name | E8: 型 Type | G8: super/share | H8: 対象ブロック名 Target Block Name | L8: TargetName | N8: TargetName | P8: TargetName | T8: ブロック備考 Block Remarks
A9: # | D9: 項目名 Field Name | E9: 型 Type | F9: 桁 Digits | G9: フルネーム Full Name | H9: 日本語名 Japanese Name | I9: 上り項目 Request Message Field | J9: 下り項目 Response Message Field | R9: 条件および編集方法 Conditions and Editing Methods | T9: 項目備考 Field Remarks
A10: # | L10: 上り項目 Request Message Field | M10: 下り項目 Response Message Field | N10: 上り項目 Request Message Field | O10: 下り項目 Response Message Field | P10: 上り項目 Request Message Field | Q10: 下り項目 Response Message Field
A11: 10 | B11: * | D11: Upd01_Hdr | E11: R | G11: $share$ | H11: MS.MSBCL0140.Chk01.Chk01_Hdr
A12: 10 | D12: peg_no | E12: #MA.INT | G12: Pegging No. | H12: 紐付けＮＯ | I12: - | J12: -
A13: 10 | D13: err_flg | E13: #MA.FLG | G13: Error | H13: エラー | I13: - | J13: -
A14: 10 | D14: mrp_typ | E14: #MS.MRP_TYP | G14: MRP type | H14: ＭＲＰタイプ | I14: - | J14: -
A15: 10 | D15: data_crud_typ | E15: #MA.DATA_CRUD_TYP | G15: Data update type | H15: データ更新区分 | I15: - | J15: -
A16: 10 | D16: ord | E16: R | F16: DBC:MS.MST_PRCD_ITM_ORDER
A17: 10 | D17: ord.itm_ord_no# | E17: RI | G17: Item order No. | H17: 品目オーダＮＯ | I17: E | J17: E
A18: 10 | D18: ord.itm_ord_typ# | E18: RI | G18: Order type | H18: オーダ区分 | I18: E | J18: -
A19: 10 | D19: ord.ord_gnrt_typ# | E19: RI | G19: Order generation type | H19: オーダ生成区分 | I19: - | J19: -
A20: 10 | D20: ord.itm_cd# | E20: RI | G20: Item cd. | H20: 品目ＣＤ | I20: - | J20: -
A21: 10 | D21: ord.itm_sub1# | E21: RI | G21: Branch No. 1 | H21: 枝番１ | I21: - | J21: -
A22: 10 | D22: ord.itm_sub2# | E22: RI | G22: Branch No. 2 | H22: 枝番２ | I22: - | J22: -
A23: 10 | D23: ord.itm_sub3# | E23: RI | G23: Branch No. 3 | H23: 枝番３ | I23: - | J23: -
A24: 10 | D24: ord.ver_no# | E24: RI | G24: Version No. | H24: 版ＮＯ | I24: - | J24: -
A25: 10 | D25: ord.strg_loc_cd# | E25: RI | G25: Storage location cd. | H25: 格納場所ＣＤ | I25: E | J25: -
A26: 10 | D26: ord.mfg_loc_cd# | E26: RI | G26: Mfg. location cd. | H26: 製造場所ＣＤ | I26: E | J26: -
A27: 10 | D27: ord.mst_mfg_loc_cd# | E27: RI | G27: Master mfg. location cd. | H27: マスタ製造場所ＣＤ | I27: - | J27: -
A28: 10 | D28: ord.sppl_cd# | E28: RI | G28: Supplier cd. | H28: 発注先ＣＤ | I28: E | J28: -
... A81: 10 | D81: ord.upd_func_id# | E81: RI | G81: Update function ID | H81: 更新機能ＩＤ | I81: - | J81: -
D82: ord.upd_ts# | E82: RI | H82: 更新日時 | I82: - | J82: -
A83: 10 | D83: ord.upd_srv_req_no# | E83: RI | G83: Update request No. | H83: 更新リクエストＮＯ | I83: - | J83: -
A84: 10 | D84: itm_ord_sts_typ_nm | E84: #MS.ITM_ORD_STS_TYP_NM | G84: Order status type name | H84: オーダ状況区分名 | I84: - | J84: -
A85: 10 | D85: strg_lg_grp_cd | E85: #MA.LG_GRP_CD | G85: Storage location distribution group cd. | H85: 格納場所物流グループＣＤ | I85: - | J85: -
A86: 10 | D86: strg_sppl_cd | E86: #MA.BP_CD | G86: Storage location supplier cd. | H86: 格納場所発注先ＣＤ | I86: - | J86: -
A87: 10 | D87: mfg_sppl_cd | E87: #MA.BP_CD | G87: Subcontractor cd. | H87: 外注発注先ＣＤ | I87: - | J87: -
A88: 10 | D88: mfg_maker_cd | E88: #MA.BP_CD | G88: Subcontracting maker cd. | H88: 外注メーカＣＤ | I88: - | J88: -
A89: 10 | D89: rqst_to_lg_grp_cd | E89: #MA.LG_GRP_CD | G89: Requested location distribution group cd. | H89: 依頼先場所物流グループＣＤ | I89: - | J89: -
A90: 10 | D90: unit_cd | E90: #MA.UNIT_CD | G90: Base unit cd. | H90: 基準単位ＣＤ | I90: - | J90: -
A91: 10 | D91: oper_ord_pr_flg | E91: #MA.FLG | G91: Operation order generation | H91: 工程オーダ生成 | I91: - | J91: -
A92: 10 | D92: io_schd_pr_flg | E92: #MA.FLG | G92: Generate GR/GI schedule | H92: 受払予定生成 | I92: - | J92: -
...

Sheet Del01
A1: * | B1: * | D1: L | E1: 1
A2: * | D2: オペレーション実装仕様書 Operation Specification Implementation Sheet | E2: ModuleID : | F2: =IF(LogicCommon!C2="","",LogicCommon!C2) -> MS | G2: LogicID : | H2: =IF(LogicCommon!E2="","",LogicCommon!E2) -> MSBCL0140 | I2: Ope.ID : | J2: Del01 | K2: Pj.ID : | L2: =IF(LogicCommon!G2="","",LogicCommon!G2) -> MC | M2: Ope.Body : | N2: "mcframe.serverMAUD.MAUDL5010.MAUDL_Operation"
A3: * | D3: =IF(LogicCommon!A3="","",LogicCommon!A3) | E3: SubModuleID : | F3: =IF(LogicCommon!C3="","",LogicCommon!C3) -> MSBC | G3: LogicClass : | H3: =IF(LogicCommon!E3="","",LogicCommon!E3) -> MSBCL_PrcdOrdReg | I3: Ope.Method : | J3: Del01 | K3: SuperClassPj.ID : | L3: =IF(LogicCommon!G3="","",LogicCommon!G3) | O3: Gene.Type : | P3: ALL
A4: * | E4: Version : | F4: 000000 | G4: LogicName : | H4: =IF(LogicCommon!E4="","",LogicCommon!E4) -> 先行手配オーダ訂正 | I4: Ope.Name : | J4: 取り消す | K4: SuperLogicID : | L4: =IF(LogicCommon!G4="","",LogicCommon!G4) -> MS.MSUDL5010 | M4: ImplOpe.ID:
A5: * | E5: ACType :
A6: * | D6: 概要 : | M6: ID | O6: ID | Q6: ID
A7: # | I7: U | K7: K | L7: o | N7: o | P7: o
A8: # | D8: ブロック名 Block Name | E8: 型 Type | G8: super/share | H8: 対象ブロック名 Target Block Name | L8: TargetName | N8: TargetName | P8: TargetName | T8: ブロック備考 Block Remarks
A9: # | D9: 項目名 Field Name | E9: 型 Type | F9: 桁 Digits | G9: フルネーム Full Name | H9: 日本語名 Japanese Name | I9: 上り項目 Request Message Field | J9: 下り項目 Response Message Field | R9: 条件および編集方法 Conditions and Editing Methods | T9: 項目備考 Field Remarks
A10: # | L10: 上り項目 Request Message Field | M10: 下り項目 Response Message Field | N10: 上り項目 Request Message Field | O10: 下り項目 Response Message Field | P10: 上り項目 Request Message Field | Q10: 下り項目 Response Message Field
A11: 10 | B11: * | D11: Del01_Hdr | E11: R | G11: $share$ | H11: MS.MSBCL0140.Chk02.Chk02_Hdr
A12: 10 | D12: peg_no | E12: #MA.INT | G12: Pegging No. | H12: 紐付けＮＯ | I12: - | J12: -
A13: 10 | D13: err_flg | E13: #MA.FLG | G13: Error | H13: エラー | I13: - | J13: -
A14: 10 | D14: mrp_typ | E14: #MS.MRP_TYP | G14: MRP type | H14: ＭＲＰタイプ | I14: - | J14: -
A15: 10 | D15: data_crud_typ | E15: #MA.DATA_CRUD_TYP | G15: Data update type | H15: データ更新区分 | I15: - | J15: -
A16: 10 | D16: ord | E16: R | F16: DBC:MS.MST_PRCD_ITM_ORDER | I16: - | J16: -
A17: 10 | D17: ord.itm_ord_no# | E17: RI | G17: Item order No. | H17: 品目オーダＮＯ | I17: E | J17: -
A18: 10 | D18: ord.rqmt_no# | E18: RI | G18: Requirements No. | H18: 所要ＮＯ | I18: - | J18: -
A19: 10 | D19: ord.upd_cntr#itm_order_upd_cntr | E19: RI | G19: Item order update counter | H19: 品目オーダ更新カウンタ | I19: E | J19: -
D20: 詳細 :

Sheet 来歴
A1: 変更来歴
A3: Rev. | H3: 修正番号 | O3: 変更内容 | AQ3: 変更箇所
A4: 1 | O4: 初版
A5: 1.1 | O5: 英語の名称を追記 | AQ5: 全般
