Workbook

Sheet LogicCommon
A2: オペレーション実装仕様書 | B2: ModuleID : | C2: MS | D2: LogicID : | E2: MSBCL0030 | F2: Pj.ID : | G2: MC
B3: SubModuleID : | C3: MSBC | D3: LogicClass : | E3: MSBCL_MlyRqmtReg | F3: SuperClassPj.ID :
D4: LogicName : | E4: 月次生産依頼登録 | F4: SuperLogicID : | G4: MS.MSUDL5010
A5: 概要 :
A6: 詳細 :

Sheet Srch01
A1: * | B1: * | D1: L | E1: 1
A2: * | D2: オペレーション実装仕様書 Operation Specification Implementation Sheet | E2: ModuleID : | F2: =IF(LogicCommon!C2="","",LogicCommon!C2) -> MS | G2: LogicID : | H2: =IF(LogicCommon!E2="","",LogicCommon!E2) -> MSBCL0030 | I2: Ope.ID : | J2: Srch01 | K2: Pj.ID : | L2: =IF(LogicCommon!G2="","",LogicCommon!G2) -> MC | M2: Ope.Body : | N2: "mcframe.serverMAUD.MAUDL5010.MAUDL_Searcher"
A3: * | D3: =IF(LogicCommon!A3="","",LogicCommon!A3) | E3: SubModuleID : | F3: =IF(LogicCommon!C3="","",LogicCommon!C3) -> MSBC | G3: LogicClass : | H3: =IF(LogicCommon!E3="","",LogicCommon!E3) -> MSBCL_MlyRqmtReg | I3: Ope.Method : | J3: Srch01 | K3: SuperClassPj.ID : | L3: =IF(LogicCommon!G3="","",LogicCommon!G3) | O3: Gene.Type : | P3: ALL
A4: * | E4: Version : | F4: 000000 | G4: LogicName : | H4: =IF(LogicCommon!E4="","",LogicCommon!E4) -> 月次生産依頼登録 | I4: Ope.Name : | J4: 検索 | K4: SuperLogicID : | L4: =IF(LogicCommon!G4="","",LogicCommon!G4) -> MS.MSUDL5010 | M4: ImplOpe.ID:
A5: * | E5: ACType :
A6: * | D6: 概要 : | E6: 月次生産依頼を登録・訂正するために、月次生産依頼を検索する。 | M6: ID | O6: ID | Q6: ID
A7: # | I7: U | K7: K | L7: o | N7: o | P7: o
A8: # | D8: ブロック名 Block Name | E8: 型 Type | G8: super/share | H8: 対象ブロック名 Target Block Name | K8: CONST | L8: TargetName | N8: TargetName | P8: TargetName | T8: ブロック備考 Block Remarks
A9: # | D9: 項目名 Field Name | E9: 型 Type | F9: 桁 Digits | G9: フルネーム Full Name | H9: 日本語名 Japanese Name | I9: 上り項目 Request Message Field | J9: 下り項目 Response Message Field | R9: 条件および編集方法 Conditions and Editing Methods | T9: 項目備考 Field Remarks
A10: # | L10: 上り項目 Request Message Field | M10: 下り項目 Response Message Field | N10: 上り項目 Request Message Field | O10: 下り項目 Response Message Field | P10: 上り項目 Request Message Field | Q10: 下り項目 Response Message Field
A11: 10 | B11: * | D11: Srch01_Cnd | E11: R
A12: 10 | D12: ope | E12: C | G12: Operation type | H12: 操作種別 | I12: E | J12: -
A13: 10 | D13: ym_fr | E13: #MA.YM | G13: Plan month FROM | H13: 計画年月ＦＲＯＭ | I13: E | J13: -
A14: 10 | D14: ym_to | E14: #MA.YM | G14: Plan month TO | H14: 計画年月ＴＯ | I14: E | J14: -
A15: 10 | D15: prod_ym_fr | E15: #MA.YM | G15: Production month FROM | H15: 生産年月ＦＲＯＭ | I15: E | J15: -
A16: 10 | D16: prod_ym_to | E16: #MA.YM | G16: Production month TO | H16: 生産年月ＴＯ | I16: E | J16: -
A17: 10 | D17: mps_grp_cd | E17: #MA.MPS_GRP_CD | G17: MPS group cd. | H17: ＭＰＳグループＣＤ | I17: E | J17: -
A18: 10 | D18: mps_grp_nm | E18: #MA.MPS_GRP_NM | G18: MPS group name | H18: ＭＰＳグループ名 | I18: E | J18: -
A19: 10 | D19: site_cd | E19: #MA.SITE_CD | G19: Factory/Distribution warehouse cd. | H19: 工場・物流倉庫ＣＤ | I19: E | J19: -
A20: 10 | D20: site_nm | E20: #MA.SITE_NM | G20: Factory/Distribution warehouse name | H20: 工場・物流倉庫名 | I20: E | J20: -
A21: 10 | D21: wg_cd | E21: #MA.WG_CD | G21: WG cd. | H21: ワーキンググループＣＤ | I21: E | J21: -
A22: 10 | D22: wg_nm | E22: #MA.WG_NM | G22: WG name | H22: ワーキンググループ名 | I22: E | J22: -
A23: 10 | D23: strg_loc_grp_cd | E23: #MA.LOC_GRP_CD | G23: Storage mfg. location group cd. | H23: 格納先製造場所グループＣＤ | I23: E | J23: -
... A28: 10 | D28: itm_typ_d_cd | E28: #MA.ITM_TYP_D_CD | G28: Item type details cd. | H28: 品目区分詳細ＣＤ | I28: E | J28: -
A29: 10 | D29: itm_typ_d_nm | E29: #MA.ITM_TYP_D_NM | G29: Item type details name | H29: 品目区分詳細名 | I29: E
A30: 10 | D30: itm_cd | E30: #MA.ITM_CD | G30: Item cd. | H30: 品目ＣＤ | I30: E | J30: -
A31: 10 | D31: itm_sub1 | E31: #MA.ITM_SUB1 | G31: Branch No. 1 | H31: 枝番１ | I31: E | J31: -
A32: 10 | D32: itm_sub2 | E32: #MA.ITM_SUB2 | G32: Branch No. 2 | H32: 枝番２ | I32: E | J32: -
A33: 10 | D33: itm_sub3 | E33: #MA.ITM_SUB3 | G33: Branch No. 3 | H33: 枝番３ | I33: E | J33: -
A34: 10 | D34: itm_nm | E34: #MA.ITM_NM | G34: Item name | H34: 品名 | I34: E | J34: -
A35: 10 | D35: intr_rmrks | E35: #MS.MLYRQST_INTR_RMRKS | G35: Internal remarks | H35: 内部備考 | I35: E | J35: -
A36: 10 | D36: sub_char1 | E36: #MS.MLYRQST_SUB_CHAR1 | G36: Spare 1 | H36: 予備１ | I36: E | J36: -
A37: 10 | D37: sub_char2 | E37: #MS.MLYRQST_SUB_CHAR2 | G37: Spare 2 | H37: 予備２ | I37: E | J37: -
A38: 10 | D38: sub_char3 | E38: #MS.MLYRQST_SUB_CHAR3 | G38: Spare 3 | H38: 予備３ | I38: E | J38: -
A39: 10 | D39: itm_grp_flg1 | E39: #MA.FLG | G39: Item classification 1 | H39: 品目分類１ | I39: E | J39: -
A40: 10 | D40: itm_grp_cd1 | E40: #MA.ITM_GRP_CD | G40: Item classification cd. 1 | H40: 品目分類ＣＤ１ | I40: E | J40: -
A41: 10 | D41: itm_grp_nm1 | E41: #MA.ITM_GRP_NM | G41: Item classification name 1 | H41: 品目分類名１ | I41: E | J41: -
... A68: 10 | D68: itm_grp_nm10 | E68: #MA.ITM_GRP_NM | G68: Item classification name 10 | H68: 品目分類名１０ | I68: E | J68: -
L69: 上り項目 Request Message Field | M69: 下り項目 Response Message Field | N69: 上り項目 Request Message Field | O69: 下り項目 Response Message Field | P69: 上り項目 Request Message Field | Q69: 下り項目 Response Message Field
A70: 20 | B70: * | D70: Srch01_Rslt | E70: L
...

Sheet Chk01
A1: * | B1: * | D1: L | E1: 1
A2: * | D2: オペレーション実装仕様書 Operation Specification Implementation Sheet | E2: ModuleID : | F2: =IF(LogicCommon!C2="","",LogicCommon!C2) -> MS | G2: LogicID : | H2: =IF(LogicCommon!E2="","",LogicCommon!E2) -> MSBCL0030 | I2: Ope.ID : | J2: Chk01 | K2: Pj.ID : | L2: =IF(LogicCommon!G2="","",LogicCommon!G2) -> MC | M2: Ope.Body : | N2: MA.MAUDL5010.Checker
A3: * | D3: =IF(LogicCommon!A3="","",LogicCommon!A3) | E3: SubModuleID : | F3: =IF(LogicCommon!C3="","",LogicCommon!C3) -> MSBC | G3: LogicClass : | H3: =IF(LogicCommon!E3="","",LogicCommon!E3) -> MSBCL_MlyRqmtReg | I3: Ope.Method : | J3: Chk01 | K3: SuperClassPj.ID : | L3: =IF(LogicCommon!G3="","",LogicCommon!G3) | O3: Gene.Type : | P3: ALL
A4: * | E4: Version : | F4: 000000 | G4: LogicName : | H4: =IF(LogicCommon!E4="","",LogicCommon!E4) -> 月次生産依頼登録 | I4: Ope.Name : | J4: 登録・訂正前チェック | K4: SuperLogicID : | L4: =IF(LogicCommon!G4="","",LogicCommon!G4) -> MS.MSUDL5010 | M4: ImplOpe.ID:
A5: * | E5: ACType :
A6: * | D6: 概要 : | E6: 月次生産依頼を登録・訂正するために、チェックを行う。 | AC6: ID | AE6: ID | AG6: ID
A7: # | I7: U | K7: K | L7: K | M7: K | N7: K | O7: K | P7: K | Q7: K | R7: K | S7: K | T7: K | U7: K | V7: K | AB7: o | AD7: o | AF7: o
A8: # | D8: ブロック名 Block Name | E8: 型 Type | G8: super/share | H8: 対象ブロック名 Target Block Name | K8: REQ_UPD_CNT_CHK | L8: REQUIRED | M8: CHK_NUM | N8: DUPLICATE | O8: AT_LEAST_ONE | P8: TOO_MANY_INPUTS | Q8: LIST_LOGIC | R8: LIST_OUT | S8: LIST_OUT_BASE | T8: LIST_IN | U8: LIST_IN_BASE | V8: NULL_VAL | W8: SMALL_LARGE | X8: CHK_DT | Y8: BEFORE_AFTER | Z8: CHK_PTN | AA8: CONST | AB8: TargetName | AD8: TargetName | AF8: TargetName | AJ8: ブロック備考 Block Remarks
A9: # | D9: 項目名 Field Name | E9: 型 Type | F9: 桁 Digits | G9: フルネーム Full Name | H9: 日本語名 Japanese Name | I9: 上り項目 Request Message Field | J9: 下り項目 Response Message Field | AH9: 条件および編集方法 Conditions and Editing Methods | AJ9: 項目備考 Field Remarks
A10: # | AB10: 上り項目 Request Message Field | AC10: 下り項目 Response Message Field | AD10: 上り項目 Request Message Field | AE10: 下り項目 Response Message Field | AF10: 上り項目 Request Message Field | AG10: 下り項目 Response Message Field
A11: 10 | B11: * | D11: Chk01_Rslt | E11: L
A12: 10 | D12: peg_no | E12: #MA.INT | G12: Pegging No. | H12: 紐付けＮＯ | I12: E | J12: E
A13: 10 | D13: err_flg | E13: #MA.FLG | G13: Error | H13: エラー | I13: - | J13: E
A14: 10 | D14: data_crud_typ | E14: #MA.DATA_CRUD_TYP | G14: Data update type | H14: データ更新区分 | I14: E | J14: E
A15: 10 | D15: rtn_sts_typ | E15: #MA.RTN_STS_TYP | G15: Process result status type | H15: 処理結果状況区分 | I15: - | J15: E
A16: 10 | D16: ym | E16: #MA.YM | G16: Plan month | H16: 計画年月 | I16: E | J16: E
A17: 10 | D17: ym_key | E17: #MA.YM | G17: Plan month | H17: 計画年月 | I17: E | J17: E | K17: E
A18: 10 | D18: itm_cd | E18: #MA.ITM_CD | G18: Item cd. | H18: 品目ＣＤ | I18: E | J18: E
A19: 10 | D19: itm_cd_key | E19: #MA.ITM_CD | G19: Item cd. | H19: 品目ＣＤ | I19: E | J19: E | K19: E
A20: 10 | D20: itm_sub1 | E20: #MA.ITM_SUB1 | G20: Branch No. 1 | H20: 枝番１ | I20: E | J20: E
A21: 10 | D21: itm_sub1_key | E21: #MA.ITM_SUB1 | G21: Branch No. 1 | H21: 枝番１ | I21: E | J21: E | K21: E
A22: 10 | D22: itm_sub2 | E22: #MA.ITM_SUB2 | G22: Branch No. 2 | H22: 枝番２ | I22: E | J22: E
A23: 10 | D23: itm_sub2_key | E23: #MA.ITM_SUB2 | G23: Branch No. 2 | H23: 枝番２ | I23: E | J23: E | K23: E
A24: 10 | D24: itm_sub3 | E24: #MA.ITM_SUB3 | G24: Branch No. 3 | H24: 枝番３ | I24: E | J24: E
A25: 10 | D25: itm_sub3_key | E25: #MA.ITM_SUB3 | G25: Branch No. 3 | H25: 枝番３ | I25: E | J25: E | K25: E
A26: 10 | D26: itm_nm | E26: #MA.ITM_NM | G26: Item name | H26: 品名 | I26: - | J26: E
A27: 10 | D27: mps_grp_cd | E27: #MA.MPS_GRP_CD | G27: MPS group cd. | H27: ＭＰＳグループＣＤ | I27: E | J27: E
A28: 10 | D28: mps_grp_cd_key | E28: #MA.MPS_GRP_CD | G28: MPS group cd. | H28: ＭＰＳグループＣＤ | I28: E | J28: E | K28: E
A29: 10 | D29: mps_grp_nm | E29: #MA.MPS_GRP_NM | G29: MPS group name | H29: ＭＰＳグループ名 | I29: - | J29: E
A30: 10 | D30: strg_loc_cd | E30: #MA.LOC_CD | G30: Storage location cd. | H30: 格納場所ＣＤ | I30: - | J30: E
A31: 10 | D31: strg_loc_nm | E31: #MA.LOC_NM | G31: Storage location name | H31: 格納場所名 | I31: - | J31: E
A32: 10 | D32: strg_loc_grp_cd | E32: #MA.LOC_GRP_CD | G32: Storage mfg. location group cd. | H32: 格納先製造場所グループＣＤ | I32: - | J32: E
A33: 10 | D33: strg_loc_grp_nm | E33: #MA.LOC_GRP_NM | G33: Storage mfg. location group name | H33: 格納先製造場所グループ名 | I33: - | J33: E
A34: 10 | D34: site_cd | E34: #MA.SITE_CD | G34: Factory/Distribution warehouse cd. | H34: 工場・物流倉庫ＣＤ | I34: - | J34: E
A35: 10 | D35: site_nm | E35: #MA.SITE_NM | G35: Factory/Distribution warehouse name | H35: 工場・物流倉庫名 | I35: - | J35: E
A36: 10 | D36: mfg_loc_cd | E36: #MA.LOC_CD | G36: Mfg. location cd. | H36: 製造場所ＣＤ | I36: - | J36: E
A37: 10 | D37: mfg_loc_nm | E37: #MA.LOC_NM | G37: Mfg. location name | H37: 製造場所名 | I37: - | J37: E
A38: 10 | D38: sppl_cd | E38: #MA.BP_CD | G38: Supplier cd. | H38: 発注先ＣＤ | I38: - | J38: E
A39: 10 | D39: sppl_nm | E39: #MA.BP_NM | G39: Supplier name | H39: 発注先名 | I39: - | J39: E
A40: 10 | D40: rqst_loc_cd | E40: #MA.LOC_CD | G40: Requested location cd. | H40: 依頼先場所ＣＤ | I40: - | J40: E
...

Sheet Chk02
A1: * | B1: * | D1: L | E1: 1
A2: * | D2: オペレーション実装仕様書 Operation Specification Implementation Sheet | E2: ModuleID : | F2: =IF(LogicCommon!C2="","",LogicCommon!C2) -> MS | G2: LogicID : | H2: =IF(LogicCommon!E2="","",LogicCommon!E2) -> MSBCL0030 | I2: Ope.ID : | J2: Chk02 | K2: Pj.ID : | L2: =IF(LogicCommon!G2="","",LogicCommon!G2) -> MC | M2: Ope.Body : | N2: MA.MAUDL5010.Checker
A3: * | D3: =IF(LogicCommon!A3="","",LogicCommon!A3) | E3: SubModuleID : | F3: =IF(LogicCommon!C3="","",LogicCommon!C3) -> MSBC | G3: LogicClass : | H3: =IF(LogicCommon!E3="","",LogicCommon!E3) -> MSBCL_MlyRqmtReg | I3: Ope.Method : | J3: Chk02 | K3: SuperClassPj.ID : | L3: =IF(LogicCommon!G3="","",LogicCommon!G3) | O3: Gene.Type : | P3: ALL
A4: * | E4: Version : | F4: 000000 | G4: LogicName : | H4: =IF(LogicCommon!E4="","",LogicCommon!E4) -> 月次生産依頼登録 | I4: Ope.Name : | J4: 取消前チェック | K4: SuperLogicID : | L4: =IF(LogicCommon!G4="","",LogicCommon!G4) -> MS.MSUDL5010 | M4: ImplOpe.ID:
A5: * | E5: ACType :
A6: * | D6: 概要 : | E6: 月次生産依頼を取り消すために、チェックを行う。 | AD6: ID | AF6: ID | AH6: ID
A7: # | I7: U | K7: K | L7: K | M7: K | N7: K | O7: K | P7: K | Q7: K | R7: K | S7: K | T7: K | U7: K | V7: K | W7: K | X7: K | Y7: K | Z7: K | AA7: K | AB7: K | AC7: o | AE7: o | AG7: o
A8: # | D8: ブロック名 Block Name | E8: 型 Type | G8: super/share | H8: 対象ブロック名 Target Block Name | K8: REQ_UPD_CNT_CHK | L8: REQUIRED | M8: CHK_NUM | N8: SMALL_LARGE | O8: CHK_DT | P8: BEFORE_AFTER | Q8: CHK_PTN | R8: DUPLICATE | S8: TOO_MANY_INPUTS | T8: AT_LEAST_ONE | U8: ONLY_ONE_INPUT | V8: LIST_LOGIC | W8: LIST_OUT | X8: LIST_OUT_BASE | Y8: LIST_IN | Z8: LIST_IN_BASE | AA8: CONST | AB8: NULL_VAL | AC8: TargetName | AE8: TargetName | AG8: TargetName | AK8: ブロック備考 Block Remarks
A9: # | D9: 項目名 Field Name | E9: 型 Type | F9: 桁 Digits | G9: フルネーム Full Name | H9: 日本語名 Japanese Name | I9: 上り項目 Request Message Field | J9: 下り項目 Response Message Field | AI9: 条件および編集方法 Conditions and Editing Methods | AK9: 項目備考 Field Remarks
A10: # | AC10: 上り項目 Request Message Field | AD10: 下り項目 Response Message Field | AE10: 上り項目 Request Message Field | AF10: 下り項目 Response Message Field | AG10: 上り項目 Request Message Field | AH10: 下り項目 Response Message Field
A11: 10 | B11: * | D11: Chk02_Rslt | E11: L
A12: 10 | D12: peg_no | E12: #MA.INT | G12: Pegging No. | H12: 紐付けＮＯ | I12: E | J12: E
A13: 10 | D13: err_flg | E13: #MA.FLG | G13: Error | H13: エラー | I13: - | J13: E
A14: 10 | D14: data_crud_typ | E14: #MA.DATA_CRUD_TYP | G14: Data update type | H14: データ更新区分 | I14: - | J14: -
A15: 10 | D15: rtn_sts_typ | E15: #MA.RTN_STS_TYP | G15: Process result status type | H15: 処理結果状況区分 | I15: - | J15: -
A16: 10 | D16: ym | E16: #MA.YM | G16: Plan month | H16: 計画年月 | I16: E | J16: E | K16: E
A17: 10 | D17: itm_cd | E17: #MA.ITM_CD | G17: Item cd. | H17: 品目ＣＤ | I17: E | J17: E | K17: E
A18: 10 | D18: itm_sub1 | E18: #MA.ITM_SUB1 | G18: Branch No. 1 | H18: 枝番１ | I18: E | J18: E | K18: E
A19: 10 | D19: itm_sub2 | E19: #MA.ITM_SUB2 | G19: Branch No. 2 | H19: 枝番２ | I19: E | J19: E | K19: E
A20: 10 | D20: itm_sub3 | E20: #MA.ITM_SUB3 | G20: Branch No. 3 | H20: 枝番３ | I20: E | J20: E | K20: E
A21: 10 | D21: mps_grp_cd | E21: #MA.MPS_GRP_CD | G21: MPS group cd. | H21: ＭＰＳグループＣＤ | I21: E | J21: E | K21: E
A22: 10 | D22: prod_ym | E22: #MA.YM | G22: Production month | H22: 生産年月 | I22: E | J22: E | K22: E
A23: 10 | D23: upd_cntr | E23: #MA.UPD_CNT | G23: Update counter | H23: 更新カウンタ | I23: E | J23: -
D24: 詳細 :

Sheet Chk03
A1: * | B1: * | D1: L | E1: 1
A2: * | D2: オペレーション実装仕様書 Operation Specification Implementation Sheet | E2: ModuleID : | F2: =IF(LogicCommon!C2="","",LogicCommon!C2) -> MS | G2: LogicID : | H2: =IF(LogicCommon!E2="","",LogicCommon!E2) -> MSBCL0030 | I2: Ope.ID : | J2: Chk03 | K2: Pj.ID : | L2: =IF(LogicCommon!G2="","",LogicCommon!G2) -> MC | M2: Ope.Body : | N2: MA.MAUDL5010.Checker
A3: * | D3: =IF(LogicCommon!A3="","",LogicCommon!A3) | E3: SubModuleID : | F3: =IF(LogicCommon!C3="","",LogicCommon!C3) -> MSBC | G3: LogicClass : | H3: =IF(LogicCommon!E3="","",LogicCommon!E3) -> MSBCL_MlyRqmtReg | I3: Ope.Method : | J3: Chk03 | K3: SuperClassPj.ID : | L3: =IF(LogicCommon!G3="","",LogicCommon!G3) | O3: Gene.Type : | P3: ALL
A4: * | E4: Version : | F4: 000000 | G4: LogicName : | H4: =IF(LogicCommon!E4="","",LogicCommon!E4) -> 月次生産依頼登録 | I4: Ope.Name : | J4: 日次計画作成チェック | K4: SuperLogicID : | L4: =IF(LogicCommon!G4="","",LogicCommon!G4) -> MS.MSUDL5010 | M4: ImplOpe.ID:
A5: * | E5: ACType :
A6: * | D6: 概要 : | E6: 月次生産依頼から日次生産依頼を作成する日ばらし処理を実行するために、チェックを行う。 | AD6: ID | AF6: ID | AH6: ID
A7: # | I7: U | K7: K | L7: K | M7: K | N7: K | O7: K | P7: K | Q7: K | R7: K | S7: K | T7: K | U7: K | V7: K | W7: K | X7: K | Y7: K | Z7: K | AA7: K | AB7: K | AC7: o | AE7: o | AG7: o
A8: # | D8: ブロック名 Block Name | E8: 型 Type | G8: super/share | H8: 対象ブロック名 Target Block Name | K8: REQ_UPD_CNT_CHK | L8: REQUIRED | M8: CHK_NUM | N8: SMALL_LARGE | O8: CHK_DT | P8: BEFORE_AFTER | Q8: CHK_PTN | R8: DUPLICATE | S8: TOO_MANY_INPUTS | T8: AT_LEAST_ONE | U8: ONLY_ONE_INPUT | V8: LIST_LOGIC | W8: LIST_OUT | X8: LIST_OUT_BASE | Y8: LIST_IN | Z8: LIST_IN_BASE | AA8: CONST | AB8: NULL_VAL | AC8: TargetName | AE8: TargetName | AG8: TargetName | AK8: ブロック備考 Block Remarks
A9: # | D9: 項目名 Field Name | E9: 型 Type | F9: 桁 Digits | G9: フルネーム Full Name | H9: 日本語名 Japanese Name | I9: 上り項目 Request Message Field | J9: 下り項目 Response Message Field | AI9: 条件および編集方法 Conditions and Editing Methods | AK9: 項目備考 Field Remarks
A10: # | AC10: 上り項目 Request Message Field | AD10: 下り項目 Response Message Field | AE10: 上り項目 Request Message Field | AF10: 下り項目 Response Message Field | AG10: 上り項目 Request Message Field | AH10: 下り項目 Response Message Field
A11: 10 | B11: * | D11: Chk03_Cnd | E11: R
A12: 10 | D12: err_flg | E12: #MA.FLG | G12: Error | H12: エラー | I12: - | J12: E
A13: 10 | D13: wg_cd | E13: #MA.WG_CD | G13: WG cd. | H13: ワーキンググループＣＤ | I13: E | J13: - | T13: E1
A14: 10 | D14: mps_grp_cd | E14: #MA.MPS_GRP_CD | G14: MPS group cd. | H14: ＭＰＳグループＣＤ | I14: E | J14: - | T14: E1
A15: 10 | D15: ym | E15: #MA.YM | G15: Start month | H15: 開始年月 | I15: E | J15: -
D16: 詳細 :

Sheet Upd01
A1: * | B1: * | D1: L | E1: 1
A2: * | D2: オペレーション実装仕様書 Operation Specification Implementation Sheet | E2: ModuleID : | F2: =IF(LogicCommon!C2="","",LogicCommon!C2) -> MS | G2: LogicID : | H2: =IF(LogicCommon!E2="","",LogicCommon!E2) -> MSBCL0030 | I2: Ope.ID : | J2: Upd01 | K2: Pj.ID : | L2: =IF(LogicCommon!G2="","",LogicCommon!G2) -> MC | M2: Ope.Body : | N2: "mcframe.serverMAUD.MAUDL5010.MAUDL_Operation"
A3: * | D3: =IF(LogicCommon!A3="","",LogicCommon!A3) | E3: SubModuleID : | F3: =IF(LogicCommon!C3="","",LogicCommon!C3) -> MSBC | G3: LogicClass : | H3: =IF(LogicCommon!E3="","",LogicCommon!E3) -> MSBCL_MlyRqmtReg | I3: Ope.Method : | J3: Upd01 | K3: SuperClassPj.ID : | L3: =IF(LogicCommon!G3="","",LogicCommon!G3) | O3: Gene.Type : | P3: ALL
A4: * | E4: Version : | F4: 000000 | G4: LogicName : | H4: =IF(LogicCommon!E4="","",LogicCommon!E4) -> 月次生産依頼登録 | I4: Ope.Name : | J4: 登録・訂正 | K4: SuperLogicID : | L4: =IF(LogicCommon!G4="","",LogicCommon!G4) -> MS.MSUDL5010 | M4: ImplOpe.ID:
A5: * | E5: ACType :
A6: * | D6: 概要 : | E6: 月次生産依頼を登録、更新する。 | M6: ID | O6: ID | Q6: ID
A7: # | I7: U | K7: K | L7: o | N7: o | P7: o
A8: # | D8: ブロック名 Block Name | E8: 型 Type | G8: super/share | H8: 対象ブロック名 Target Block Name | L8: TargetName | N8: TargetName | P8: TargetName | T8: ブロック備考 Block Remarks
A9: # | D9: 項目名 Field Name | E9: 型 Type | F9: 桁 Digits | G9: フルネーム Full Name | H9: 日本語名 Japanese Name | I9: 上り項目 Request Message Field | J9: 下り項目 Response Message Field | R9: 条件および編集方法 Conditions and Editing Methods | T9: 項目備考 Field Remarks
A10: # | L10: 上り項目 Request Message Field | M10: 下り項目 Response Message Field | N10: 上り項目 Request Message Field | O10: 下り項目 Response Message Field | P10: 上り項目 Request Message Field | Q10: 下り項目 Response Message Field
A11: 10 | B11: * | D11: Upd01_Rslt | E11: L | G11: $share$ | H11: MS.MSBCL0030.Chk01.Chk01_Rslt
A12: 10 | D12: peg_no | E12: #MA.INT | G12: Pegging No. | H12: 紐付けＮＯ | I12: - | J12: -
A13: 10 | D13: err_flg | E13: #MA.FLG | G13: Error | H13: エラー | I13: - | J13: -
A14: 10 | D14: data_crud_typ | E14: #MA.DATA_CRUD_TYP | G14: Data update type | H14: データ更新区分 | I14: - | J14: -
A15: 10 | D15: rtn_sts_typ | E15: #MA.RTN_STS_TYP | G15: Process result status type | H15: 処理結果状況区分 | I15: - | J15: E
A16: 10 | D16: ym | E16: #MA.YM | G16: Plan month | H16: 計画年月 | I16: E | J16: E
A17: 10 | D17: ym_key | E17: #MA.YM | G17: Plan month | H17: 計画年月 | I17: E | J17: -
A18: 10 | D18: itm_cd | E18: #MA.ITM_CD | G18: Item cd. | H18: 品目ＣＤ | I18: E | J18: E
A19: 10 | D19: itm_cd_key | E19: #MA.ITM_CD | G19: Item cd. | H19: 品目ＣＤ | I19: E | J19: -
A20: 10 | D20: itm_sub1 | E20: #MA.ITM_SUB1 | G20: Branch No. 1 | H20: 枝番１ | I20: E | J20: E
A21: 10 | D21: itm_sub1_key | E21: #MA.ITM_SUB1 | G21: Branch No. 1 | H21: 枝番１ | I21: E | J21: -
A22: 10 | D22: itm_sub2 | E22: #MA.ITM_SUB2 | G22: Branch No. 2 | H22: 枝番２ | I22: E | J22: E
A23: 10 | D23: itm_sub2_key | E23: #MA.ITM_SUB2 | G23: Branch No. 2 | H23: 枝番２ | I23: E | J23: -
... A46: 10 | D46: upd_cntr | E46: #MA.UPD_CNT | G46: Update counter | H46: 更新カウンタ | I46: E | J46: -
D47: 詳細 :

Sheet Del01
A1: * | B1: * | D1: L | E1: 1
A2: * | D2: オペレーション実装仕様書 Operation Specification Implementation Sheet | E2: ModuleID : | F2: =IF(LogicCommon!C2="","",LogicCommon!C2) -> MS | G2: LogicID : | H2: =IF(LogicCommon!E2="","",LogicCommon!E2) -> MSBCL0030 | I2: Ope.ID : | J2: Del01 | K2: Pj.ID : | L2: =IF(LogicCommon!G2="","",LogicCommon!G2) -> MC | M2: Ope.Body : | N2: "mcframe.serverMAUD.MAUDL5010.MAUDL_Operation"
A3: * | D3: =IF(LogicCommon!A3="","",LogicCommon!A3) | E3: SubModuleID : | F3: =IF(LogicCommon!C3="","",LogicCommon!C3) -> MSBC | G3: LogicClass : | H3: =IF(LogicCommon!E3="","",LogicCommon!E3) -> MSBCL_MlyRqmtReg | I3: Ope.Method : | J3: Del01 | K3: SuperClassPj.ID : | L3: =IF(LogicCommon!G3="","",LogicCommon!G3) | O3: Gene.Type : | P3: ALL
A4: * | E4: Version : | F4: 000000 | G4: LogicName : | H4: =IF(LogicCommon!E4="","",LogicCommon!E4) -> 月次生産依頼登録 | I4: Ope.Name : | J4: 取り消す | K4: SuperLogicID : | L4: =IF(LogicCommon!G4="","",LogicCommon!G4) -> MS.MSUDL5010 | M4: ImplOpe.ID:
A5: * | E5: ACType :
A6: * | D6: 概要 : | E6: 月次生産依頼を取り消す。 | M6: ID | O6: ID | Q6: ID
A7: # | I7: U | K7: K | L7: o | N7: o | P7: o
A8: # | D8: ブロック名 Block Name | E8: 型 Type | G8: super/share | H8: 対象ブロック名 Target Block Name | L8: TargetName | N8: TargetName | P8: TargetName | T8: ブロック備考 Block Remarks
A9: # | D9: 項目名 Field Name | E9: 型 Type | F9: 桁 Digits | G9: フルネーム Full Name | H9: 日本語名 Japanese Name | I9: 上り項目 Request Message Field | J9: 下り項目 Response Message Field | R9: 条件および編集方法 Conditions and Editing Methods | T9: 項目備考 Field Remarks
A10: # | L10: 上り項目 Request Message Field | M10: 下り項目 Response Message Field | N10: 上り項目 Request Message Field | O10: 下り項目 Response Message Field | P10: 上り項目 Request Message Field | Q10: 下り項目 Response Message Field
A11: 10 | B11: * | D11: Del01_Rslt | E11: L | G11: $share$ | H11: MS.MSBCL0030.Chk02.Chk02_Rslt
A12: 10 | D12: peg_no | E12: #MA.INT | G12: Pegging No. | H12: 紐付けＮＯ | I12: - | J12: -
A13: 10 | D13: err_flg | E13: #MA.FLG | G13: Error | H13: エラー | I13: - | J13: -
A14: 10 | D14: data_crud_typ | E14: #MA.DATA_CRUD_TYP | G14: Data update type | H14: データ更新区分 | I14: - | J14: -
A15: 10 | D15: rtn_sts_typ | E15: #MA.RTN_STS_TYP | G15: Process result status type | H15: 処理結果状況区分 | I15: - | J15: E
A16: 10 | D16: ym | E16: #MA.YM | G16: Plan month | H16: 計画年月 | I16: E | J16: E
A17: 10 | D17: itm_cd | E17: #MA.ITM_CD | G17: Item cd. | H17: 品目ＣＤ | I17: E | J17: E
A18: 10 | D18: itm_sub1 | E18: #MA.ITM_SUB1 | G18: Branch No. 1 | H18: 枝番１ | I18: E | J18: E
A19: 10 | D19: itm_sub2 | E19: #MA.ITM_SUB2 | G19: Branch No. 2 | H19: 枝番２ | I19: E | J19: E
A20: 10 | D20: itm_sub3 | E20: #MA.ITM_SUB3 | G20: Branch No. 3 | H20: 枝番３ | I20: E | J20: E
A21: 10 | D21: mps_grp_cd | E21: #MA.MPS_GRP_CD | G21: MPS group cd. | H21: ＭＰＳグループＣＤ | I21: E | J21: E
A22: 10 | D22: prod_ym | E22: #MA.YM | G22: Production month | H22: 生産年月 | I22: E | J22: E
A23: 10 | D23: upd_cntr | E23: #MA.UPD_CNT | G23: Update counter | H23: 更新カウンタ | I23: E | J23: -
D24: 詳細 :

Sheet Imp01
A1: * | B1: * | D1: L | E1: 1
A2: * | D2: オペレーション実装仕様書 Operation Specification Implementation Sheet | E2: ModuleID : | F2: =IF(LogicCommon!C2="","",LogicCommon!C2) -> MS | G2: LogicID : | H2: =IF(LogicCommon!E2="","",LogicCommon!E2) -> MSBCL0030 | I2: Ope.ID : | J2: Imp01 | K2: Pj.ID : | L2: =IF(LogicCommon!G2="","",LogicCommon!G2) -> MC | M2: Ope.Body : | N2: "mcframe.serverMAUD.MAUDL5010.MAUDL_Operation"
A3: * | D3: =IF(LogicCommon!A3="","",LogicCommon!A3) | E3: SubModuleID : | F3: =IF(LogicCommon!C3="","",LogicCommon!C3) -> MSBC | G3: LogicClass : | H3: =IF(LogicCommon!E3="","",LogicCommon!E3) -> MSBCL_MlyRqmtReg | I3: Ope.Method : | J3: Imp01 | K3: SuperClassPj.ID : | L3: =IF(LogicCommon!G3="","",LogicCommon!G3) | O3: Gene.Type : | P3: ALL
A4: * | E4: Version : | F4: 000000 | G4: LogicName : | H4: =IF(LogicCommon!E4="","",LogicCommon!E4) -> 月次生産依頼登録 | I4: Ope.Name : | J4: ファイル入力 | K4: SuperLogicID : | L4: =IF(LogicCommon!G4="","",LogicCommon!G4) -> MS.MSUDL5010 | M4: ImplOpe.ID:
A5: * | E5: ACType :
A6: * | D6: 概要 : | E6: ファイルから取り込んだ月次生産依頼のチェック処理を行う。 | M6: ID | O6: ID | Q6: ID
A7: # | I7: U | K7: K | L7: o | N7: o | P7: o
A8: # | D8: ブロック名 Block Name | E8: 型 Type | G8: super/share | H8: 対象ブロック名 Target Block Name | L8: TargetName | N8: TargetName | P8: TargetName | T8: ブロック備考 Block Remarks
A9: # | D9: 項目名 Field Name | E9: 型 Type | F9: 桁 Digits | G9: フルネーム Full Name | H9: 日本語名 Japanese Name | I9: 上り項目 Request Message Field | J9: 下り項目 Response Message Field | R9: 条件および編集方法 Conditions and Editing Methods | T9: 項目備考 Field Remarks
A10: # | L10: 上り項目 Request Message Field | M10: 下り項目 Response Message Field | N10: 上り項目 Request Message Field | O10: 下り項目 Response Message Field | P10: 上り項目 Request Message Field | Q10: 下り項目 Response Message Field
A11: 10 | B11: * | D11: Imp01_Rslt | E11: L | G11: $share$ | H11: MS.MSBCL0030.Chk01.Chk01_Rslt
A12: 10 | D12: peg_no | E12: #MA.INT | G12: Pegging No. | H12: 紐付けＮＯ | I12: - | J12: -
A13: 10 | D13: err_flg | E13: #MA.FLG | G13: Error | H13: エラー | I13: - | J13: -
A14: 10 | D14: data_crud_typ | E14: #MA.DATA_CRUD_TYP | G14: Data update type | H14: データ更新区分 | I14: - | J14: -
A15: 10 | D15: rtn_sts_typ | E15: #MA.RTN_STS_TYP | G15: Process result status type | H15: 処理結果状況区分 | I15: - | J15: E
A16: 10 | D16: ym | E16: #MA.YM | G16: Plan month | H16: 計画年月 | I16: E | J16: E
A17: 10 | D17: ym_key | E17: #MA.YM | G17: Plan month | H17: 計画年月 | I17: E | J17: E
A18: 10 | D18: itm_cd | E18: #MA.ITM_CD | G18: Item cd. | H18: 品目ＣＤ | I18: E | J18: E
A19: 10 | D19: itm_cd_key | E19: #MA.ITM_CD | G19: Item cd. | H19: 品目ＣＤ | I19: E | J19: E
A20: 10 | D20: itm_sub1 | E20: #MA.ITM_SUB1 | G20: Branch No. 1 | H20: 枝番１ | I20: E | J20: E
A21: 10 | D21: itm_sub1_key | E21: #MA.ITM_SUB1 | G21: Branch No. 1 | H21: 枝番１ | I21: E | J21: E
A22: 10 | D22: itm_sub2 | E22: #MA.ITM_SUB2 | G22: Branch No. 2 | H22: 枝番２ | I22: E | J22: E
A23: 10 | D23: itm_sub2_key | E23: #MA.ITM_SUB2 | G23: Branch No. 2 | H23: 枝番２ | I23: E | J23: E
... A55: 10 | D55: upd_cntr | E55: #MA.UPD_CNT | G55: Update counter | H55: 更新カウンタ | I55: - | J55: E
D56: 詳細 :

Sheet Upd02
A1: * | B1: * | D1: L | E1: 1
A2: * | D2: オペレーション実装仕様書 Operation Specification Implementation Sheet | E2: ModuleID : | F2: =IF(LogicCommon!C2="","",LogicCommon!C2) -> MS | G2: LogicID : | H2: =IF(LogicCommon!E2="","",LogicCommon!E2) -> MSBCL0030 | I2: Ope.ID : | J2: Upd02 | K2: Pj.ID : | L2: =IF(LogicCommon!G2="","",LogicCommon!G2) -> MC | M2: Ope.Body : | N2: "mcframe.serverMAUD.MAUDL5010.MAUDL_Operation"
A3: * | D3: =IF(LogicCommon!A3="","",LogicCommon!A3) | E3: SubModuleID : | F3: =IF(LogicCommon!C3="","",LogicCommon!C3) -> MSBC | G3: LogicClass : | H3: =IF(LogicCommon!E3="","",LogicCommon!E3) -> MSBCL_MlyRqmtReg | I3: Ope.Method : | J3: Upd02 | K3: SuperClassPj.ID : | L3: =IF(LogicCommon!G3="","",LogicCommon!G3) | O3: Gene.Type : | P3: ALL
A4: * | E4: Version : | F4: 000000 | G4: LogicName : | H4: =IF(LogicCommon!E4="","",LogicCommon!E4) -> 月次生産依頼登録 | I4: Ope.Name : | J4: 日次計画作成 | K4: SuperLogicID : | L4: =IF(LogicCommon!G4="","",LogicCommon!G4) -> MS.MSUDL5010 | M4: ImplOpe.ID:
A5: * | E5: ACType :
A6: * | D6: 概要 : | E6: 月次生産依頼から日次生産依頼を作成する日ばらし処理を実行する。 | M6: ID | O6: ID | Q6: ID
A7: # | I7: U | K7: K | L7: o | N7: o | P7: o
A8: # | D8: ブロック名 Block Name | E8: 型 Type | G8: super/share | H8: 対象ブロック名 Target Block Name | L8: TargetName | N8: TargetName | P8: TargetName | T8: ブロック備考 Block Remarks
A9: # | D9: 項目名 Field Name | E9: 型 Type | F9: 桁 Digits | G9: フルネーム Full Name | H9: 日本語名 Japanese Name | I9: 上り項目 Request Message Field | J9: 下り項目 Response Message Field | R9: 条件および編集方法 Conditions and Editing Methods | T9: 項目備考 Field Remarks
A10: # | L10: 上り項目 Request Message Field | M10: 下り項目 Response Message Field | N10: 上り項目 Request Message Field | O10: 下り項目 Response Message Field | P10: 上り項目 Request Message Field | Q10: 下り項目 Response Message Field
A11: 10 | B11: * | D11: Upd02_Cnd | E11: R | G11: $share$ | H11: MS.MSBCL0030.Chk03.Chk03_Cnd
A12: 10 | D12: wg_cd | E12: #MA.WG_CD | G12: WG cd. | H12: ワーキンググループＣＤ | I12: E | J12: -
A13: 10 | D13: mps_grp_cd | E13: #MA.MPS_GRP_CD | G13: MPS group cd. | H13: ＭＰＳグループＣＤ | I13: E | J13: -
A14: 10 | D14: ym | E14: #MA.YM | G14: Start month | H14: 開始年月 | I14: E | J14: -
D15: 詳細 :

Sheet 来歴
A1: 変更来歴
A3: Rev. | H3: 修正番号 | O3: 変更内容 | AQ3: 変更箇所
A4: 1 | O4: 初版
A5: 1.1 | O5: 英語の名称を追記 | AQ5: 全般
