Workbook

Sheet LogicCommon
A2: オペレーション実装仕様書 | B2: ModuleID : | C2: MS | D2: LogicID : | E2: MSBCL6080 | F2: Pj.ID : | G2: MC
B3: SubModuleID : | C3: MSBC | D3: LogicClass : | E3: MSBCL_MfgActRcptIFService | F3: SuperClassPj.ID :
D4: LogicName : | E4: 製造実績受信ＩＦサービス | F4: SuperLogicID : | G4: MS.MSUDL5010
A5: 概要 : | B5: 製造実績を外部システムから登録、更新、取消するための処理を提供する。
A6: 詳細 :

Sheet MfgActIF_Upd01
A1: * | B1: * | D1: L | E1: 1
A2: * | D2: オペレーション実装仕様書 Operation Specification Implementation Sheet | E2: ModuleID : | F2: =IF(LogicCommon!C2="","",LogicCommon!C2) -> MS | G2: LogicID : | H2: =IF(LogicCommon!E2="","",LogicCommon!E2) -> MSBCL6080 | I2: Ope.ID : | J2: MfgActIF_Upd01 | K2: Pj.ID : | L2: =IF(LogicCommon!G2="","",LogicCommon!G2) -> MC | M2: Ope.Body : | N2: "mcframe.serverMAUD.MAUDL5010.MAUDL_Operation"
A3: * | D3: =IF(LogicCommon!A3="","",LogicCommon!A3) | E3: SubModuleID : | F3: =IF(LogicCommon!C3="","",LogicCommon!C3) -> MSBC | G3: LogicClass : | H3: =IF(LogicCommon!E3="","",LogicCommon!E3) -> MSBCL_MfgActRcptIFService | I3: Ope.Method : | J3: MfgActIF_Upd01 | K3: SuperClassPj.ID : | L3: =IF(LogicCommon!G3="","",LogicCommon!G3) | O3: Gene.Type : | P3: ALL
A4: * | E4: Version : | F4: 000000 | G4: LogicName : | H4: =IF(LogicCommon!E4="","",LogicCommon!E4) -> 製造実績受信ＩＦサービス | I4: Ope.Name : | J4: 登録・訂正 | K4: SuperLogicID : | L4: =IF(LogicCommon!G4="","",LogicCommon!G4) -> MS.MSUDL5010 | M4: ImplOpe.ID:
A5: * | E5: ACType :
A6: * | D6: 概要 : | E6: 製造実績の登録・訂正を行う。 | M6: ID | O6: ID | Q6: ID
A7: # | I7: U | K7: K | L7: o | M7: MARC.chk01 | N7: o | O7: MARU.upd01 | P7: o
A8: # | D8: ブロック名 Block Name | E8: 型 Type | G8: super/share | H8: 対象ブロック名 Target Block Name | L8: TargetName | M8: OPE.MS.MSBCL6050.MfgActReg_Chk01 | N8: TargetName | O8: OPE.MS.MSBCL6050.MfgActReg_Upd01 | P8: TargetName | T8: ブロック備考 Block Remarks
A9: # | D9: 項目名 Field Name | E9: 型 Type | F9: 桁 Digits | G9: フルネーム Full Name | H9: 日本語名 Japanese Name | I9: 上り項目 Request Message Field | J9: 下り項目 Response Message Field | R9: 条件および編集方法 Conditions and Editing Methods | T9: 項目備考 Field Remarks
A10: # | L10: 上り項目 Request Message Field | M10: 下り項目 Response Message Field | N10: 上り項目 Request Message Field | O10: 下り項目 Response Message Field | P10: 上り項目 Request Message Field | Q10: 下り項目 Response Message Field
A11: 10 | B11: * | D11: MfgActIF_Upd01_Ctrl | E11: R
A12: 10 | D12: if_upd_typ | E12: #MA.IF_UPD_TYP | G12: IF update type | H12: ＩＦ更新区分 | I12: E | J12: -
A13: 10 | D13: upd_cntr_chk_flg | E13: #MA.FLG | G13: Check for update counter | H13: 更新カウンタチェック | I13: E | J13: -
A15: 20 | B15: * | D15: MfgActIF_Upd01_Hdr | E15: L | L15: MfgActReg_Chk01_Hdr | M15: MfgActReg_Chk01_Hdr | N15: MfgActReg_Upd01_Hdr | O15: MfgActReg_Upd01_Hdr
A16: 20 | D16: data_crud_typ | E16: #MA.DATA_CRUD_TYP | G16: Data update type | H16: データ更新区分 | I16: E | J16: - | L16: - | M16: E | N16: E | O16: -
A17: 20 | D17: peg_no | E17: #MA.INT | G17: Pegging No. | H17: 紐付けＮＯ | I17: E | J17: E | L17: E | M17: E | N17: E | O17: E
A18: 20 | D18: err_flg | E18: #MA.FLG | G18: Error | H18: エラー | I18: - | J18: - | L18: - | M18: E | N18: - | O18: -
A19: 20 | D19: rtn_sts_typ | E19: #MA.RTN_STS_TYP | G19: Process result status type | H19: 処理結果状況区分 | I19: - | J19: E | L19: - | M19: E | N19: - | O19: E
A20: 20 | D20: mfg_sts_typ | E20: #MS.MFG_STS_TYP | G20: Mfg. status type | H20: 製造状況区分 | I20: E | J20: E | L20: E | M20: E | N20: E | O20: E
A21: 20 | D21: mfg_sts_typ_nm | E21: #MS.MFG_STS_TYP_NM | G21: Mfg. status name | H21: 製造状況区分名 | I21: - | J21: E | L21: - | M21: - | N21: - | O21: E
A22: 20 | D22: itm_cd | E22: #MA.ITM_CD | G22: Item cd. | H22: 品目ＣＤ | I22: - | J22: - | L22: - | M22: E | N22: E | O22: -
A23: 20 | D23: itm_sub1 | E23: #MA.ITM_SUB1 | G23: Branch No. 1 | H23: 枝番１ | I23: - | J23: - | L23: - | M23: E | N23: E | O23: -
A24: 20 | D24: itm_sub2 | E24: #MA.ITM_SUB2 | G24: Branch No. 2 | H24: 枝番２ | I24: - | J24: - | L24: - | M24: E | N24: E | O24: -
A25: 20 | D25: itm_sub3 | E25: #MA.ITM_SUB3 | G25: Branch No. 3 | H25: 枝番３ | I25: - | J25: - | L25: - | M25: E | N25: E | O25: -
A26: 20 | D26: inst_lot_no | E26: #MA.LOT_NO | G26: Lot No. (Order) | H26: ロットＮＯ（指図） | I26: - | J26: - | L26: - | M26: E | N26: E | O26: -
A27: 20 | D27: inst_sublot_no | E27: #MA.SUBLOT_NO | G27: Sublot No. (Order) | H27: サブロットＮＯ（指図） | I27: - | J27: - | L27: - | M27: E | N27: E | O27: -
... A102: 20 | D102: is_src_outsrc_srv_flg | E102: #MA.FLG | G102: Caller subcontractor mfg. result service | H102: 呼出元外注製造実績サービス | I102: E | J102: - | L102: - | M102: - | N102: E | O102: -
A103: 20 | D103: is_src_md_mfg_srv_flg | E103: #MA.FLG | I103: E | J103: - | L103: E | M103: E | N103: E | O103: -
A104: 20 | D104: all_inpt_cmpl_flg | E104: #MA.FLG | G104: All input completed | H104: 全投入完了 | I104: - | J104: - | L104: - | M104: - | N104: - | O104: -
A105: 20 | D105: lst_reg_flg | E105: #MA.FLG | G105: Bulk execution | H105: 一括実行 | I105: E | J105: - | L105: E | M105: - | N105: E | O105: -
A106: 20 | D106: bkf_tgt_cnt | E106: #MA.INT | G106: Number of BF | H106: バックフラッシュ対象件数 | I106: E | J106: E | L106: E | M106: E | N106: E | O106: E
A107: 20 | D107: bkf_success_cnt | E107: #MA.INT | G107: Number of backflush succeeded | H107: バックフラッシュ成功件数 | I107: E | J107: E | L107: E | M107: E | N107: E | O107: E
A108: 20 | D108: bkf_failure_cnt | E108: #MA.INT | G108: Number of backflush failed | H108: バックフラッシュ失敗件数 | I108: E | J108: E | L108: E | M108: E | N108: E | O108: E
A110: 30 | B110: * | D110: MfgActIF_Upd01_DtlOper | E110: L | L110: MfgActReg_Chk01_DtlOper | M110: MfgActReg_Chk01_DtlOper | N110: MfgActReg_Upd01_DtlOper | O110: MfgActReg_Upd01_DtlOper
A111: 30 | D111: data_crud_typ | E111: #MA.DATA_CRUD_TYP | G111: Data update type | H111: データ更新区分 | I111: E | J111: - | L111: - | M111: E | N111: E | O111: -
A112: 30 | D112: hdr_peg_no | E112: #MA.INT | G112: Header pegging No. | H112: ヘッダ紐付けＮＯ | I112: E | J112: E | L112: E | M112: E | N112: E | O112: E
A113: 30 | D113: peg_no | E113: #MA.INT | G113: Operation pegging No. | H113: 工程紐付けＮＯ | I113: E | J113: E | L113: E | M113: E | N113: E | O113: E
A114: 30 | D114: err_flg | E114: #MA.FLG | G114: Error | H114: エラー | I114: - | J114: - | L114: - | M114: E | N114: - | O114: -
A115: 30 | D115: oper_cd | E115: #MA.OPER_CD | G115: Operation cd. | H115: 工程ＣＤ | I115: - | J115: - | L115: - | M115: E | N115: E | O115: -
A116: 30 | D116: oper_unit_act_qty | E116: #MA.QTY | G116: Operation unit result qty. | H116: 工程単位実績数量 | I116: E | J116: - | L116: E | M116: E | N116: E | O116: -
...

Sheet MfgActIF_Del01
A1: * | B1: * | D1: L | E1: 1
A2: * | D2: オペレーション実装仕様書 Operation Specification Implementation Sheet | E2: ModuleID : | F2: =IF(LogicCommon!C2="","",LogicCommon!C2) -> MS | G2: LogicID : | H2: =IF(LogicCommon!E2="","",LogicCommon!E2) -> MSBCL6080 | I2: Ope.ID : | J2: MfgActIF_Del01 | K2: Pj.ID : | L2: =IF(LogicCommon!G2="","",LogicCommon!G2) -> MC | M2: Ope.Body : | N2: "mcframe.serverMAUD.MAUDL5010.MAUDL_Operation"
A3: * | D3: =IF(LogicCommon!A3="","",LogicCommon!A3) | E3: SubModuleID : | F3: =IF(LogicCommon!C3="","",LogicCommon!C3) -> MSBC | G3: LogicClass : | H3: =IF(LogicCommon!E3="","",LogicCommon!E3) -> MSBCL_MfgActRcptIFService | I3: Ope.Method : | J3: MfgActIF_Del01 | K3: SuperClassPj.ID : | L3: =IF(LogicCommon!G3="","",LogicCommon!G3) | O3: Gene.Type : | P3: ALL
A4: * | E4: Version : | F4: 000000 | G4: LogicName : | H4: =IF(LogicCommon!E4="","",LogicCommon!E4) -> 製造実績受信ＩＦサービス | I4: Ope.Name : | J4: 取消 | K4: SuperLogicID : | L4: =IF(LogicCommon!G4="","",LogicCommon!G4) -> MS.MSUDL5010 | M4: ImplOpe.ID:
A5: * | E5: ACType :
A6: * | D6: 概要 : | E6: 製造実績の取消を行う。 | M6: ID
A7: # | I7: U | K7: K | L7: o | M7: MARD.del01
A8: # | D8: ブロック名 Block Name | E8: 型 Type | G8: super/share | H8: 対象ブロック名 Target Block Name | L8: TargetName | M8: OPE.MS.MSBCL6050.MfgActReg_Del01 | P8: ブロック備考 Block Remarks
A9: # | D9: 項目名 Field Name | E9: 型 Type | F9: 桁 Digits | G9: フルネーム Full Name | H9: 日本語名 Japanese Name | I9: 上り項目 Request Message Field | J9: 下り項目 Response Message Field | N9: 条件および編集方法 Conditions and Editing Methods | P9: 項目備考 Field Remarks
A10: # | L10: 上り項目 Request Message Field | M10: 下り項目 Response Message Field
A11: 10 | B11: * | D11: MfgActIF_Del01_Ctrl | E11: R | L11: MfgActReg_Del01_Ctrl | M11: MfgActReg_Del01_Ctrl
A12: 10 | D12: if_upd_typ | E12: #MA.IF_UPD_TYP | G12: IF update type | H12: ＩＦ更新区分 | I12: E | J12: - | L12: - | M12: -
A13: 10 | D13: upd_cntr_chk_flg | E13: #MA.FLG | G13: Check for update counter | H13: 更新カウンタチェック | I13: E | J13: - | L13: E | M13: -
A14: 10 | D14: lst_del_flg | E14: #MA.FLG | G14: Bulk cancellation flg. | H14: 一括取消ＦＬＧ | I14: E | J14: - | L14: E | M14: -
A15: 10 | D15: is_src_batch_flg | E15: #MA.FLG | G15: Caller batch process | H15: 呼出元バッチ処理 | I15: E | J15: - | L15: E | M15: -
A16: 10 | D16: not_commit_flg | E16: #MA.FLG | G16: Do not commit | H16: コミットしない | I16: E | J16: - | L16: E | M16: -
A18: 20 | B18: * | D18: MfgActIF_Del01_Hdr | E18: L | L18: MfgActReg_Del01_Hdr | M18: MfgActReg_Del01_Hdr
A19: 20 | D19: peg_no | E19: #MA.INT | G19: Pegging No. | H19: 紐付けＮＯ | I19: E | J19: E | L19: E | M19: E
A20: 20 | D20: mfg_act_no | E20: #MA.MFG_ACT_NO | G20: Mfg. result No. | H20: 製造実績ＮＯ | I20: E | J20: - | L20: E | M20: -
A21: 20 | D21: mfg_inst_upd_cntr | E21: #MA.UPD_CNT | G21: Mfg. order update counter | H21: 製造指図更新カウンタ | I21: E | J21: - | L21: E | M21: -
A22: 20 | D22: mfg_inst_pr_upd_cntr | E22: #MA.UPD_CNT | G22: Production order progress update counter | H22: 製造指図進捗更新カウンタ | I22: E | J22: - | L22: E | M22: -
A23: 20 | D23: mfg_act_upd_cntr | E23: #MA.UPD_CNT | G23: Mfg. result update counter | H23: 製造実績更新カウンタ | I23: E | J23: - | L23: E | M23: -
A24: 20 | D24: err_flg | E24: #MA.FLG | G24: Error | H24: エラー | I24: - | J24: E | L24: - | M24: E
A25: 20 | D25: rtn_sts_typ | E25: #MA.RTN_STS_TYP | G25: Process result status type | H25: 処理結果状況区分 | I25: - | J25: E | L25: - | M25: E
A26: 20 | D26: upd_cntr_chk_flg | E26: #MA.FLG | G26: Check for update counter | H26: 更新カウンタチェック | I26: E | J26: - | L26: - | M26: -
A28: 30 | B28: * | D28: MfgActIF_Del01_DtlInpt | E28: L | L28: MfgActReg_Del01_DtlInpt | M28: MfgActReg_Del01_DtlInpt
A29: 30 | D29: inpt_act_no | E29: #MA.INPT_ACT_NO | G29: Input result No. | H29: 投入実績ＮＯ | I29: E | J29: - | L29: E | M29: -
A30: 30 | D30: can_ac_dt | E30: #MA.DT | G30: Cancellation recording date | H30: 取消計上日 | I30: E | J30: - | L30: E | M30: -
A32: 40 | B32: * | D32: MfgActIF_Del01_DtlYield | E32: L | L32: MfgActReg_Del01_DtlYield | M32: MfgActReg_Del01_DtlYield
A33: 40 | D33: yield_act_no | E33: #MA.YIELD_ACT_NO | G33: Output result No. | H33: 出来高実績ＮＯ | I33: E | J33: - | L33: E | M33: -
A34: 40 | D34: can_ac_dt | E34: #MA.DT | G34: Cancellation recording date | H34: 取消計上日 | I34: E | J34: - | L34: E | M34: -
A36: 50 | B36: * | D36: MfgActIF_Del01_DtlByProd | E36: L | L36: MfgActReg_Del01_DtlByProd | M36: MfgActReg_Del01_DtlByProd
A37: 50 | D37: yield_act_no | E37: #MA.YIELD_ACT_NO | G37: Output result No. | H37: 出来高実績ＮＯ | I37: E | J37: - | L37: E | M37: -
A38: 50 | D38: can_ac_dt | E38: #MA.DT | G38: Cancellation recording date | H38: 取消計上日 | I38: E | J38: - | L38: E | M38: -
D39: 詳細 :

Sheet MfgActIF_Upd02
A1: * | B1: * | D1: L | E1: 1
A2: * | D2: オペレーション実装仕様書 Operation Specification Implementation Sheet | E2: ModuleID : | F2: =IF(LogicCommon!C2="","",LogicCommon!C2) -> MS | G2: LogicID : | H2: =IF(LogicCommon!E2="","",LogicCommon!E2) -> MSBCL6080 | I2: Ope.ID : | J2: MfgActIF_Upd02 | K2: Pj.ID : | L2: =IF(LogicCommon!G2="","",LogicCommon!G2) -> MC | M2: Ope.Body : | N2: "mcframe.serverMAUD.MAUDL5010.MAUDL_Operation"
A3: * | D3: =IF(LogicCommon!A3="","",LogicCommon!A3) | E3: SubModuleID : | F3: =IF(LogicCommon!C3="","",LogicCommon!C3) -> MSBC | G3: LogicClass : | H3: =IF(LogicCommon!E3="","",LogicCommon!E3) -> MSBCL_MfgActRcptIFService | I3: Ope.Method : | J3: MfgActIF_Upd02 | K3: SuperClassPj.ID : | L3: =IF(LogicCommon!G3="","",LogicCommon!G3) | O3: Gene.Type : | P3: ALL
A4: * | E4: Version : | F4: 000000 | G4: LogicName : | H4: =IF(LogicCommon!E4="","",LogicCommon!E4) -> 製造実績受信ＩＦサービス | I4: Ope.Name : | J4: 工数実績登録・訂正 | K4: SuperLogicID : | L4: =IF(LogicCommon!G4="","",LogicCommon!G4) -> MS.MSUDL5010 | M4: ImplOpe.ID:
A5: * | E5: ACType :
A6: * | D6: 概要 : | E6: 工数実績の登録・訂正を行う。 | M6: ID | O6: ID | Q6: ID
A7: # | I7: U | K7: K | L7: o | M7: MARC.chk04 | N7: o | O7: MARU.upd03 | P7: o
A8: # | D8: ブロック名 Block Name | E8: 型 Type | G8: super/share | H8: 対象ブロック名 Target Block Name | L8: TargetName | M8: OPE.MS.MSBCL6050.MfgActReg_Chk04 | N8: TargetName | O8: OPE.MS.MSBCL6050.MfgActReg_Upd03 | P8: TargetName | T8: ブロック備考 Block Remarks
A9: # | D9: 項目名 Field Name | E9: 型 Type | F9: 桁 Digits | G9: フルネーム Full Name | H9: 日本語名 Japanese Name | I9: 上り項目 Request Message Field | J9: 下り項目 Response Message Field | R9: 条件および編集方法 Conditions and Editing Methods | T9: 項目備考 Field Remarks
A10: # | L10: 上り項目 Request Message Field | M10: 下り項目 Response Message Field | N10: 上り項目 Request Message Field | O10: 下り項目 Response Message Field | P10: 上り項目 Request Message Field | Q10: 下り項目 Response Message Field
A11: 10 | B11: * | D11: MfgActIF_Upd02_Ctrl | E11: R | L11: MfgActReg_Chk04_Ctrl | M11: MfgActReg_Chk04_Ctrl | N11: MfgActReg_Upd03_Ctrl | O11: MfgActReg_Upd03_Ctrl
A12: 10 | D12: if_upd_typ | E12: #MA.IF_UPD_TYP | G12: IF update type | H12: ＩＦ更新区分 | I12: E | J12: - | L12: - | M12: - | N12: - | O12: -
A13: 10 | D13: upd_cntr_chk_flg | E13: #MA.FLG | G13: Check for update counter | H13: 更新カウンタチェック | I13: E | J13: - | L13: E | M13: - | N13: - | O13: -
A14: 10 | D14: is_src_batch_flg | E14: #MA.FLG | G14: Caller batch process | H14: 呼出元バッチ処理 | I14: E | J14: - | L14: E | M14: - | N14: - | O14: -
A15: 10 | D15: not_commit_flg | E15: #MA.FLG | G15: Do not commit | H15: コミットしない | I15: E | J15: - | L15: - | M15: - | N15: E | O15: -
A17: 20 | B17: * | D17: MfgActIF_Upd02_Rslt | E17: L | L17: MfgActReg_Chk04_Rslt | M17: MfgActReg_Chk04_Rslt | N17: MfgActReg_Upd03_Rslt | O17: MfgActReg_Upd03_Rslt
A18: 20 | D18: peg_no | E18: #MA.INT | G18: Pegging No. | H18: 紐付けＮＯ | I18: E | J18: E | L18: E | M18: E | N18: E | O18: E
A19: 20 | D19: err_flg | E19: #MA.FLG | G19: Error flg. | H19: エラーＦＬＧ | I19: - | J19: E | L19: - | M19: E | N19: E | O19: E
A20: 20 | D20: data_crud_typ | E20: #MA.DATA_CRUD_TYP | G20: Data update type | H20: データ更新区分 | I20: E | J20: - | L20: E | M20: E | N20: E | O20: -
A21: 20 | D21: inst_wk_act_flg | E21: #MA.FLG | G21: Order direct man-hour result | H21: 指図工数実績 | I21: E | J21: - | L21: E | M21: E | N21: E | O21: -
A22: 20 | D22: mfg_inst_no | E22: #MA.MFG_INST_NO | G22: Mfg. order No. | H22: 製造指図ＮＯ | I22: E | J22: - | L22: E | M22: E | N22: E | O22: -
A23: 20 | D23: div_seq | E23: #MS.DIV_SEQ | G23: Split sequence number | H23: 分割連番 | I23: E | J23: - | L23: E | M23: E | N23: E | O23: -
A24: 20 | D24: disp_seq | E24: #MA.INT | G24: Display order | H24: 表示順 | I24: - | J24: - | L24: - | M24: - | N24: - | O24: -
A25: 20 | D25: oper_ptn | E25: #MA.OPER_PTN | G25: Operation pattern | H25: 工程パタン | I25: - | J25: - | L25: - | M25: - | N25: - | O25: -
A26: 20 | D26: oper_disp_seq | E26: #MA.INT | G26: Routing | H26: 工順 | I26: - | J26: - | L26: - | M26: - | N26: - | O26: -
A27: 20 | D27: oper_cd | E27: #MA.OPER_CD | G27: Operation cd. | H27: 工程ＣＤ | I27: E | J27: - | L27: E | M27: E | N27: E | O27: -
A28: 20 | D28: oper_nm | E28: #MA.OPER_NM | G28: Operation name | H28: 工程名 | I28: - | J28: - | L28: - | M28: E | N28: E | O28: -
A29: 20 | D29: oper_seq | E29: #MA.OPER_SEQ | G29: Operation sequence number | H29: 工程連番 | I29: - | J29: - | L29: - | M29: - | N29: - | O29: -
... A157: 20 | D157: ext_wk_act_no | E157: #MA.EXT_WK_ACT_NO | G157: External man-hour result No. | H157: 外部工数実績ＮＯ | I157: E | J157: - | L157: E | M157: E | N157: E | O157: -
D158: 詳細 :

Sheet MfgActIF_Del02
A1: * | B1: * | D1: L | E1: 1
A2: * | D2: オペレーション実装仕様書 Operation Specification Implementation Sheet | E2: ModuleID : | F2: =IF(LogicCommon!C2="","",LogicCommon!C2) -> MS | G2: LogicID : | H2: =IF(LogicCommon!E2="","",LogicCommon!E2) -> MSBCL6080 | I2: Ope.ID : | J2: MfgActIF_Del02 | K2: Pj.ID : | L2: =IF(LogicCommon!G2="","",LogicCommon!G2) -> MC | M2: Ope.Body : | N2: "mcframe.serverMAUD.MAUDL5010.MAUDL_Operation"
A3: * | D3: =IF(LogicCommon!A3="","",LogicCommon!A3) | E3: SubModuleID : | F3: =IF(LogicCommon!C3="","",LogicCommon!C3) -> MSBC | G3: LogicClass : | H3: =IF(LogicCommon!E3="","",LogicCommon!E3) -> MSBCL_MfgActRcptIFService | I3: Ope.Method : | J3: MfgActIF_Del02 | K3: SuperClassPj.ID : | L3: =IF(LogicCommon!G3="","",LogicCommon!G3) | O3: Gene.Type : | P3: ALL
A4: * | E4: Version : | F4: 000000 | G4: LogicName : | H4: =IF(LogicCommon!E4="","",LogicCommon!E4) -> 製造実績受信ＩＦサービス | I4: Ope.Name : | J4: 工数実績取消 | K4: SuperLogicID : | L4: =IF(LogicCommon!G4="","",LogicCommon!G4) -> MS.MSUDL5010 | M4: ImplOpe.ID:
A5: * | E5: ACType :
A6: * | D6: 概要 : | E6: 工数実績の取消を行う。 | M6: ID | O6: ID | Q6: ID
A7: # | I7: U | K7: K | L7: o | M7: MARC.chk05 | N7: o | O7: MARD.del02 | P7: o
A8: # | D8: ブロック名 Block Name | E8: 型 Type | G8: super/share | H8: 対象ブロック名 Target Block Name | L8: TargetName | M8: OPE.MS.MSBCL6050.MfgActReg_Chk05 | N8: TargetName | O8: OPE.MS.MSBCL6050.MfgActReg_Del02 | P8: TargetName | T8: ブロック備考 Block Remarks
A9: # | D9: 項目名 Field Name | E9: 型 Type | F9: 桁 Digits | G9: フルネーム Full Name | H9: 日本語名 Japanese Name | I9: 上り項目 Request Message Field | J9: 下り項目 Response Message Field | R9: 条件および編集方法 Conditions and Editing Methods | T9: 項目備考 Field Remarks
A10: # | L10: 上り項目 Request Message Field | M10: 下り項目 Response Message Field | N10: 上り項目 Request Message Field | O10: 下り項目 Response Message Field | P10: 上り項目 Request Message Field | Q10: 下り項目 Response Message Field
A11: 10 | B11: * | D11: MfgActIF_Del02_Ctrl | E11: R | L11: MfgActReg_Chk05_Ctrl | M11: MfgActReg_Chk05_Ctrl | N11: MfgActReg_Del02_Ctrl | O11: MfgActReg_Del02_Ctrl
A12: 10 | D12: if_upd_typ | E12: #MA.IF_UPD_TYP | G12: IF update type | H12: ＩＦ更新区分 | I12: E | J12: - | L12: - | M12: - | N12: - | O12: -
A13: 10 | D13: upd_cntr_chk_flg | E13: #MA.FLG | G13: Check for update counter | H13: 更新カウンタチェック | I13: E | J13: - | L13: E | M13: - | N13: - | O13: -
A14: 10 | D14: is_src_batch_flg | E14: #MA.FLG | G14: Caller batch process | H14: 呼出元バッチ処理 | I14: E | J14: - | L14: E | M14: - | N14: - | O14: -
A15: 10 | D15: not_commit_flg | E15: #MA.FLG | G15: Do not commit | H15: コミットしない | I15: E | J15: - | L15: - | M15: - | N15: E | O15: -
A17: 20 | B17: * | D17: MfgActIF_Del02_Rslt | E17: L | G17: $share$ | H17: MS.MSBCL6080.MfgActIF_Upd02.MfgActIF_Upd02_Rslt | L17: MfgActReg_Chk05_Rslt | M17: MfgActReg_Chk05_Rslt | N17: MfgActReg_Del02_Rslt | O17: MfgActReg_Del02_Rslt
A18: 20 | D18: peg_no | E18: #MA.INT | G18: Pegging No. | H18: 紐付けＮＯ | I18: E | J18: E | L18: E | M18: E | N18: E | O18: E
A19: 20 | D19: err_flg | E19: #MA.FLG | G19: Error flg. | H19: エラーＦＬＧ | I19: - | J19: E | L19: - | M19: E | N19: E | O19: E
A20: 20 | D20: data_crud_typ | E20: #MA.DATA_CRUD_TYP | G20: Data update type | H20: データ更新区分 | I20: E | J20: - | L20: E | M20: E | N20: E | O20: -
A21: 20 | D21: inst_wk_act_flg | E21: #MA.FLG | G21: Order direct man-hour result | H21: 指図工数実績 | I21: E | J21: - | L21: E | M21: E | N21: E | O21: -
A22: 20 | D22: mfg_inst_no | E22: #MA.MFG_INST_NO | G22: Mfg. order No. | H22: 製造指図ＮＯ | I22: E | J22: - | L22: E | M22: E | N22: E | O22: -
A23: 20 | D23: div_seq | E23: #MS.DIV_SEQ | G23: Split sequence number | H23: 分割連番 | I23: E | J23: - | L23: E | M23: E | N23: E | O23: -
A24: 20 | D24: disp_seq | E24: #MA.INT | G24: Display order | H24: 表示順 | I24: - | J24: - | L24: - | M24: - | N24: - | O24: -
A25: 20 | D25: oper_ptn | E25: #MA.OPER_PTN | G25: Operation pattern | H25: 工程パタン | I25: - | J25: - | L25: - | M25: - | N25: - | O25: -
A26: 20 | D26: oper_disp_seq | E26: #MA.INT | G26: Routing | H26: 工順 | I26: - | J26: - | L26: - | M26: - | N26: - | O26: -
A27: 20 | D27: oper_cd | E27: #MA.OPER_CD | G27: Operation cd. | H27: 工程ＣＤ | I27: - | J27: - | L27: - | M27: - | N27: - | O27: -
A28: 20 | D28: oper_nm | E28: #MA.OPER_NM | G28: Operation name | H28: 工程名 | I28: - | J28: - | L28: - | M28: - | N28: - | O28: -
A29: 20 | D29: oper_seq | E29: #MA.OPER_SEQ | G29: Operation sequence number | H29: 工程連番 | I29: - | J29: - | L29: - | M29: - | N29: - | O29: -
... A40: 20 | D40: act_wk_cost | E40: #MA.WK_COST_QTY | G40: Result man-hour | H40: 実績工数 | I40: - | J40: - | L40: - | M40: - | N40: - | O40: -
A41: 20 | D41: abort_flg | E41: #MA.FLG | G41: Cancel remaining | H41: 打切 | O41: -
A42: 20 | D42: rem_wk_cost | E42: #MA.WK_COST_QTY | G42: Remaining man-hour | H42: 残工数 | I42: - | J42: - | L42: - | M42: - | N42: - | O42: -
A43: 20 | D43: wk_cost_unit_nm | E43: #MA.WK_COST_UNIT_NM | G43: Work element unit name | H43: 工数管理単位名 | I43: - | J43: - | L43: - | M43: - | N43: - | O43: -
A44: 20 | D44: wk_cost_dec_place | E44: #MA.DEC_PLACE | G44: Number of decimal places | H44: 小数部有効桁数 | I44: - | J44: - | L44: - | M44: - | N44: - | O44: -
A45: 20 | D45: wk_cost_rnd_typ | E45: #MA.RND_TYP | G45: Rounding type | H45: 端数処理区分 | I45: - | J45: - | L45: - | M45: - | N45: - | O45: -
A46: 20 | D46: wk_day_cd | E46: #MA.WK_DAY_CD | G46: Work type cd. | H46: 勤務種類ＣＤ | I46: - | J46: - | L46: - | M46: - | N46: - | O46: -
A47: 20 | D47: wk_day_nm | E47: #MA.WK_DAY_NM | G47: Work type name | H47: 勤務種類名 | I47: - | J47: - | L47: - | M47: - | N47: - | O47: -
A48: 20 | D48: wk_rsn_cd | E48: #MA.WK_RSN_CD | G48: Man-hour reason cd. | H48: 工数理由ＣＤ | I48: - | J48: - | L48: - | M48: - | N48: - | O48: -
A49: 20 | D49: wk_rsn_nm | E49: #MA.WK_RSN_NM | G49: Man-hour reason name | H49: 工数理由名 | I49: - | J49: - | L49: - | M49: - | N49: - | O49: -
A50: 20 | D50: dpt_cd | E50: #MA.DPT_CD | G50: Dept. cd. | H50: 部門ＣＤ | I50: - | J50: - | L50: - | M50: - | N50: - | O50: -
A51: 20 | D51: dpt_nm | E51: #MA.DPT_NM | G51: Dept. name | H51: 部門名 | I51: - | J51: - | L51: - | M51: - | N51: - | O51: -
...

Sheet MfgActIF_Upd03
A1: * | B1: * | D1: L | E1: 1
A2: * | D2: オペレーション実装仕様書 Operation Specification Implementation Sheet | E2: ModuleID : | F2: =IF(LogicCommon!C2="","",LogicCommon!C2) -> MS | G2: LogicID : | H2: =IF(LogicCommon!E2="","",LogicCommon!E2) -> MSBCL6080 | I2: Ope.ID : | J2: MfgActIF_Upd03 | K2: Pj.ID : | L2: =IF(LogicCommon!G2="","",LogicCommon!G2) -> MC | M2: Ope.Body : | N2: "mcframe.serverMAUD.MAUDL5010.MAUDL_Operation"
A3: * | D3: =IF(LogicCommon!A3="","",LogicCommon!A3) | E3: SubModuleID : | F3: =IF(LogicCommon!C3="","",LogicCommon!C3) -> MSBC | G3: LogicClass : | H3: =IF(LogicCommon!E3="","",LogicCommon!E3) -> MSBCL_MfgActRcptIFService | I3: Ope.Method : | J3: MfgActIF_Upd03 | K3: SuperClassPj.ID : | L3: =IF(LogicCommon!G3="","",LogicCommon!G3) | O3: Gene.Type : | P3: ALL
A4: * | E4: Version : | F4: 000000 | G4: LogicName : | H4: =IF(LogicCommon!E4="","",LogicCommon!E4) -> 製造実績受信ＩＦサービス | I4: Ope.Name : | J4: 一括登録・訂正 | K4: SuperLogicID : | L4: =IF(LogicCommon!G4="","",LogicCommon!G4) -> MS.MSUDL5010 | M4: ImplOpe.ID:
A5: * | E5: ACType :
A6: * | D6: 概要 : | E6: 製造実績の一括登録・訂正処理 | M6: ID | O6: ID | Q6: ID
A7: # | I7: U | K7: K | L7: o | M7: MARU.upd02 | N7: o | P7: o
A8: # | D8: ブロック名 Block Name | E8: 型 Type | G8: super/share | H8: 対象ブロック名 Target Block Name | L8: TargetName | M8: OPE.MS.MSBCL6050.MfgActReg_Upd02 | N8: TargetName | P8: TargetName | T8: ブロック備考 Block Remarks
A9: # | D9: 項目名 Field Name | E9: 型 Type | F9: 桁 Digits | G9: フルネーム Full Name | H9: 日本語名 Japanese Name | I9: 上り項目 Request Message Field | J9: 下り項目 Response Message Field | R9: 条件および編集方法 Conditions and Editing Methods | T9: 項目備考 Field Remarks
A10: # | L10: 上り項目 Request Message Field | M10: 下り項目 Response Message Field | N10: 上り項目 Request Message Field | O10: 下り項目 Response Message Field | P10: 上り項目 Request Message Field | Q10: 下り項目 Response Message Field
A11: 10 | B11: * | D11: MfgActIF_Upd03_Ctrl | E11: R | L11: MfgActReg_Upd02_Ctrl | M11: MfgActReg_Upd02_Ctrl
A12: 10 | D12: if_upd_typ | E12: #MA.IF_UPD_TYP | G12: IF update type | H12: ＩＦ更新区分 | I12: E | J12: - | L12: - | M12: -
A13: 10 | D13: oper_unit_flg | E13: #MA.FLG | G13: Operation unit result | H13: 工程単位実績 | I13: E | J13: - | L13: E | M13: -
A14: 10 | D14: act_immed_prnt_flg | E14: #MA.FLG | G14: Record sheet immediate issue | H14: 記録書即時発行 | I14: E | J14: - | L14: E | M14: -
A15: 10 | D15: not_bkf_upd_flg | E15: #MA.FLG | G15: Not update BF | H15: ＢＦ更新しない | I15: E | J15: - | L15: E | M15: -
A16: 10 | D16: not_wk_cost_upd_calc_flg | E16: #MA.FLG | G16: Do not auto-calculate man-hour | H16: 自動工数計算しない | I16: E | J16: - | L16: E | M16: -
A17: 10 | D17: not_io_act_srv_exec_flg | E17: #MA.FLG | G17: GR/GI result service call not required | H17: 受払実績サービス呼び出し不要 | I17: E | J17: - | L17: E | M17: -
A18: 10 | D18: is_src_batch_flg | E18: #MA.FLG | G18: Caller batch process | H18: 呼出元バッチ処理 | I18: E | J18: - | L18: E | M18: -
A19: 10 | D19: upd_cntr_chk_flg | E19: #MA.FLG | G19: Check for update counter | H19: 更新カウンタチェック | I19: E | J19: - | L19: E | M19: -
A20: 10 | D20: not_commit_flg | E20: #MA.FLG | G20: Do not commit | H20: コミットしない | I20: E | J20: - | L20: E | M20: -
A22: 20 | B22: * | D22: MfgActIF_Upd03_Hdr1 | E22: L | L22: MfgActReg_Upd02_Hdr1 | M22: MfgActReg_Upd02_Hdr1
A23: 20 | D23: peg_no | E23: #MA.INT | G23: Pegging No. | H23: 紐付けＮＯ | I23: E | J23: E | L23: E | M23: E
A24: 20 | D24: mfg_sts_typ | E24: #MS.MFG_STS_TYP | G24: Mfg. status type | H24: 製造状況区分 | I24: E | J24: E | L24: E | M24: E
A25: 20 | D25: mfg_sts_typ_nm | E25: #MS.MFG_STS_TYP_NM | G25: Mfg. status name | H25: 製造状況区分名 | I25: - | J25: E | L25: - | M25: E
A26: 20 | D26: st_act_tm | E26: #MA.TM | G26: Actual start date | H26: 着手実績日 | I26: E | J26: - | L26: E | M26: -
A27: 20 | D27: st_ac_dt | E27: #MA.DT | G27: Start recording date | H27: 着手計上日 | I27: E | J27: - | L27: E | M27: -
A28: 20 | D28: end_act_tm | E28: #MA.TM | G28: Actual end date | H28: 終了実績日 | I28: E | J28: - | L28: E | M28: -
A29: 20 | D29: end_ac_dt | E29: #MA.DT | G29: End recording date | H29: 終了計上日 | I29: E | J29: - | L29: E | M29: -
A30: 20 | D30: base_unit_st_act_qty | E30: #MA.QTY | G30: Start qty. | H30: 着手数量 | I30: E | J30: - | L30: E | M30: -
A31: 20 | D31: rem_abort_flg | E31: #MA.FLG | G31: Cancel remaining qty. | H31: 残数打切 | I31: E | J31: - | L31: E | M31: -
A32: 20 | D32: act_usr_cd | E32: #MA.USR_CD | G32: Result management PIC cd. | H32: 実績責任者ＣＤ | I32: E | J32: - | L32: E | M32: -
A33: 20 | D33: act_dpt_cd | E33: #MA.DPT_CD | G33: Result dept. cd. | H33: 実績部門ＣＤ | I33: E | J33: - | L33: E | M33: -
A34: 20 | D34: mfg_act_rpt_rmrks | E34: #MS.MFG_ACT_RPT_RMRKS | G34: Mfg. record sheet remarks | H34: 製造記録書備考 | I34: E | J34: - | L34: E | M34: -
... A75: 20 | D75: if_auto_reg_flg | E75: #MA.FLG | G75: IF auto-create | H75: ＩＦ自動作成 | I75: E | J75: - | L75: E | M75: -
A77: 30 | B77: * | D77: MfgActIF_Upd03_Hdr2 | E77: L | G77: $share$ | H77: MS.MSBCL6050.MfgActReg_Upd02.MfgActReg_Upd02_Hdr1 | L77: MfgActReg_Upd02_Hdr2 | M77: MfgActReg_Upd02_Hdr2
A78: 30 | D78: peg_no | E78: #MA.INT | G78: Pegging No. | H78: 紐付けＮＯ | I78: E | J78: E | L78: E | M78: E
A79: 30 | D79: mfg_sts_typ | E79: #MS.MFG_STS_TYP | G79: Mfg. status type | H79: 製造状況区分 | I79: E | J79: E | L79: E | M79: E
A80: 30 | D80: mfg_sts_typ_nm | E80: #MS.MFG_STS_TYP_NM | G80: Mfg. status name | H80: 製造状況区分名 | I80: - | J80: E | L80: - | M80: E
A81: 30 | D81: st_act_tm | E81: #MA.TM | G81: Actual start date | H81: 着手実績日 | I81: E | J81: - | L81: E | M81: -
A82: 30 | D82: st_ac_dt | E82: #MA.DT | G82: Start recording date | H82: 着手計上日 | I82: E | J82: - | L82: E | M82: -
...

Sheet MfgActIF_Upd04
A1: * | B1: * | D1: L | E1: 1
A2: * | D2: オペレーション実装仕様書 Operation Specification Implementation Sheet | E2: ModuleID : | F2: =IF(LogicCommon!C2="","",LogicCommon!C2) -> MS | G2: LogicID : | H2: =IF(LogicCommon!E2="","",LogicCommon!E2) -> MSBCL6080 | I2: Ope.ID : | J2: MfgActIF_Upd04 | K2: Pj.ID : | L2: =IF(LogicCommon!G2="","",LogicCommon!G2) -> MC | M2: Ope.Body : | N2: "mcframe.serverMAUD.MAUDL5010.MAUDL_Operation"
A3: * | D3: =IF(LogicCommon!A3="","",LogicCommon!A3) | E3: SubModuleID : | F3: =IF(LogicCommon!C3="","",LogicCommon!C3) -> MSBC | G3: LogicClass : | H3: =IF(LogicCommon!E3="","",LogicCommon!E3) -> MSBCL_MfgActRcptIFService | I3: Ope.Method : | J3: MfgActIF_Upd04 | K3: SuperClassPj.ID : | L3: =IF(LogicCommon!G3="","",LogicCommon!G3) | O3: Gene.Type : | P3: ALL
A4: * | E4: Version : | F4: 000000 | G4: LogicName : | H4: =IF(LogicCommon!E4="","",LogicCommon!E4) -> 製造実績受信ＩＦサービス | I4: Ope.Name : | J4: 工程実績完了 | K4: SuperLogicID : | L4: =IF(LogicCommon!G4="","",LogicCommon!G4) -> MS.MSUDL5010 | M4: ImplOpe.ID:
A5: * | E5: ACType :
A6: * | D6: 概要 : | E6: 工程（製造）実績の完了処理を行う。 | M6: ID | O6: ID | Q6: ID
A7: # | I7: U | K7: K | L7: o | M7: MARU.upd04 | N7: o | P7: o
A8: # | D8: ブロック名 Block Name | E8: 型 Type | G8: super/share | H8: 対象ブロック名 Target Block Name | L8: TargetName | M8: OPE.MS.MSBCL6050.MfgActReg_Upd04 | N8: TargetName | P8: TargetName | T8: ブロック備考 Block Remarks
A9: # | D9: 項目名 Field Name | E9: 型 Type | F9: 桁 Digits | G9: フルネーム Full Name | H9: 日本語名 Japanese Name | I9: 上り項目 Request Message Field | J9: 下り項目 Response Message Field | R9: 条件および編集方法 Conditions and Editing Methods | T9: 項目備考 Field Remarks
A10: # | L10: 上り項目 Request Message Field | M10: 下り項目 Response Message Field | N10: 上り項目 Request Message Field | O10: 下り項目 Response Message Field | P10: 上り項目 Request Message Field | Q10: 下り項目 Response Message Field
A11: 10 | B11: * | D11: MfgActIF_Upd04_Ctrl | E11: R | L11: MfgActReg_Upd04_Ctrl | M11: MfgActReg_Upd04_Ctrl
A12: 10 | D12: is_src_batch_flg | E12: #MA.FLG | G12: Caller batch process | H12: 呼出元バッチ処理 | I12: E | J12: - | L12: E | M12: -
A13: 10 | D13: upd_cntr_chk_flg | E13: #MA.FLG | G13: Check for update counter | H13: 更新カウンタチェック | I13: E | J13: - | L13: E | M13: -
A14: 10 | D14: not_commit_flg | E14: #MA.FLG | G14: Do not commit | H14: コミットしない | I14: E | J14: - | L14: E | M14: -
A16: 20 | B16: * | D16: MfgActIF_Upd04_DtlOper | E16: L | L16: MfgActReg_Upd04_DtlOper | M16: MfgActReg_Upd04_DtlOper
A17: 20 | D17: peg_no | E17: #MA.INT | G17: Pegging No. | H17: 紐付けＮＯ | I17: E | J17: E | L17: E | M17: E
A18: 20 | D18: oper_act_no | E18: #MA.OPER_ACT_NO | G18: Operation result No. | H18: 工程実績ＮＯ | I18: E | J18: - | L18: E | M18: -
A19: 20 | D19: mfg_inst_no | E19: #MA.MFG_INST_NO | G19: Mfg. order No. | H19: 製造指図ＮＯ | I19: - | J19: - | L19: - | M19: -
A20: 20 | D20: rtn_sts_typ | E20: #MA.RTN_STS_TYP | G20: Process result status type | H20: 処理結果状況区分 | I20: - | J20: E | L20: - | M20: E
D21: 詳細 :

Sheet 来歴
A1: 変更来歴
A3: Rev. | H3: 修正番号 | O3: 変更内容 | AQ3: 変更箇所
A4: 1 | O4: 初版
A5: 1.1 | H5: MS7032#065 | O5: MfgActIF_Upd01_Hdrブロックにis_src_md_mfg_srv_flgを追加。 | AQ5: MfgActIF_Upd01
A6: 1.2 | H6: MS7032#174 | O6: MfgActIF_Upd01_DtlInptブロックにis_only_abort_flgを追加。 | AQ6: MfgActIF_Upd01
A7: 1.3 | O7: 英語の名称を追記 | AQ7: 全般
