Workbook

Sheet LogicCommon
A2: オペレーション実装仕様書 | B2: ModuleID : | C2: MS | D2: LogicID : | E2: MSBCL5010 | F2: Pj.ID : | G2: MC
B3: SubModuleID : | C3: MSBC | D3: LogicClass : | E3: MSBCL_OrdRegService | F3: SuperClassPj.ID :
D4: LogicName : | E4: オーダ登録サービス | F4: SuperLogicID : | G4: MS.MSUDL5010
A5: 概要 :
A6: 詳細 :

Sheet Ord_Upd01
A1: * | B1: * | D1: L | E1: 1
A2: * | D2: オペレーション実装仕様書 Operation Specification Implementation Sheet | E2: ModuleID : | F2: =IF(LogicCommon!C2="","",LogicCommon!C2) -> MS | G2: LogicID : | H2: =IF(LogicCommon!E2="","",LogicCommon!E2) -> MSBCL5010 | I2: Ope.ID : | J2: Ord_Upd01 | K2: Pj.ID : | L2: =IF(LogicCommon!G2="","",LogicCommon!G2) -> MC | M2: Ope.Body : | N2: "mcframe.serverMAUD.MAUDL5010.MAUDL_Operation"
A3: * | E3: SubModuleID : | F3: =IF(LogicCommon!C3="","",LogicCommon!C3) -> MSBC | G3: LogicClass : | H3: =IF(LogicCommon!E3="","",LogicCommon!E3) -> MSBCL_OrdRegService | I3: Ope.Method : | J3: Ord_Upd01 | K3: SuperClassPj.ID : | L3: =IF(LogicCommon!G3="","",LogicCommon!G3) | O3: Gene.Type : | P3: ALL
A4: * | E4: Version : | F4: 000000 | G4: LogicName : | H4: =IF(LogicCommon!E4="","",LogicCommon!E4) -> オーダ登録サービス | I4: Ope.Name : | J4: オーダ更新 | K4: SuperLogicID : | L4: =IF(LogicCommon!G4="","",LogicCommon!G4) -> MS.MSUDL5010 | M4: ImplOpe.ID:
A5: * | E5: ACType :
A6: * | D6: 概要 : | Q6: ID | S6: ID | U6: ID
A7: # | I7: U | K7: K | L7: K | M7: K | N7: K | O7: K | P7: o | R7: o | T7: o
A8: # | D8: ブロック名 Block Name | E8: 型 Type | G8: super/share | H8: 対象ブロック名 Target Block Name | K8: NULL_VAL | L8: CHK_NUM | M8: LIST_LOGIC | N8: LIST_IN | O8: LIST_IN_BASE | P8: TargetName | R8: TargetName | T8: TargetName | X8: ブロック備考 Block Remarks
A9: # | D9: 項目名 Field Name | E9: 型 Type | F9: 桁 Digits | G9: フルネーム Full Name | H9: 日本語名 Japanese Name | I9: 上り項目 Request Message Field | J9: 下り項目 Response Message Field | V9: 条件および編集方法 Conditions and Editing Methods | X9: 項目備考 Field Remarks
A10: # | P10: 上り項目 Request Message Field | Q10: 下り項目 Response Message Field | R10: 上り項目 Request Message Field | S10: 下り項目 Response Message Field | T10: 上り項目 Request Message Field | U10: 下り項目 Response Message Field
A11: 10 | B11: * | D11: Ord_Upd01_Dtl1 | E11: L
A12: 10 | D12: peg_no | E12: #MA.INT | G12: Pegging No. | H12: 紐付けＮＯ | I12: E | J12: -
A13: 10 | D13: mrp_typ | E13: #MS.MRP_TYP | G13: MRP type | H13: ＭＲＰタイプ | I13: E | J13: -
A14: 10 | D14: data_crud_typ | E14: #MA.DATA_CRUD_TYP | G14: Data update type | H14: データ更新区分 | I14: E | J14: -
A15: 10 | D15: a_itm_ord_sts_typ | E15: #MS.ITM_ORD_STS_TYP | G15: Order status type after update | H15: 更新後オーダ状況区分 | I15: - | J15: -
A16: 10 | D16: b_itm_ord_sts_typ | E16: #MS.ITM_ORD_STS_TYP | G16: Order status type before update | H16: 更新前オーダ状況区分 | I16: - | J16: -
A17: 10 | D17: ord | E17: R | F17: DBC:MS.MST_ITM_ORDER
A18: 10 | D18: ord.itm_ord_no#itm_ord_no | E18: RI | G18: Item order No. | H18: 品目オーダＮＯ | I18: E | J18: -
A19: 10 | D19: ord.itm_ord_typ# | E19: RI | G19: Order type | H19: オーダ区分 | I19: E | J19: -
A20: 10 | D20: ord.ord_gnrt_typ# | E20: RI | G20: Order generation type | H20: オーダ生成区分 | I20: E | J20: -
A21: 10 | D21: ord.itm_cd# | E21: RI | G21: Item cd. | H21: 品目ＣＤ | I21: E | J21: -
A22: 10 | D22: ord.itm_sub1# | E22: RI | G22: Branch No. 1 | H22: 枝番１ | I22: E | J22: -
A23: 10 | D23: ord.itm_sub2# | E23: RI | G23: Branch No. 2 | H23: 枝番２ | I23: E | J23: -
A24: 10 | D24: ord.itm_sub3# | E24: RI | G24: Branch No. 3 | H24: 枝番３ | I24: E | J24: -
A25: 10 | D25: ord.ver_no# | E25: RI | G25: Version No. | H25: 版ＮＯ | I25: E | J25: -
A26: 10 | D26: ord.strg_loc_cd# | E26: RI | G26: Storage location cd. | H26: 格納場所ＣＤ | I26: E | J26: - | K26: E
A27: 10 | D27: ord.mfg_loc_cd# | E27: RI | G27: Mfg. location cd. | H27: 製造場所ＣＤ | I27: E | J27: - | K27: E
A28: 10 | D28: ord.mst_mfg_loc_cd# | E28: RI | G28: Master mfg. location cd. | H28: マスタ製造場所ＣＤ | I28: E | J28: - | K28: E
A29: 10 | D29: ord.sppl_cd# | E29: RI | G29: Supplier cd. | H29: 発注先ＣＤ | I29: E | J29: - | K29: E
A30: 10 | D30: ord.maker_cd# | E30: RI | G30: Maker cd. | H30: メーカＣＤ | I30: E | J30: - | K30: E
A31: 10 | D31: ord.rqst_loc_cd# | E31: RI | G31: Requested location cd. | H31: 依頼先場所ＣＤ | I31: E | J31: - | K31: E
A32: 10 | D32: ord.rqst_wg_cd# | E32: RI | G32: Requested WG cd. | H32: 依頼先ワーキンググループＣＤ | I32: E | J32: -
A33: 10 | D33: ord.bom_ptn# | E33: RI | G33: BOM pattern | H33: 構成パタン | I33: E | J33: -
A34: 10 | D34: ord.oper_ptn# | E34: RI | G34: Operation pattern | H34: 工程パタン | I34: E | J34: - | M34: MA.MAUAL0010.ItmOper | N34: itm_cd;itm_sub1;itm_sub2;itm_sub3;mfg_loc_cd;master_dt;true | O34: itm_cd;itm_sub1;itm_sub2;itm_sub3;loc_cd;dt;mode_nullval_flg
A35: 10 | D35: ord.inst_qty# | E35: RI | G35: Order scheduled qty. | H35: 指図予定数量 | I35: E | J35: - | L35: positive
A36: 10 | D36: ord.yield_schd_qty# | E36: RI | G36: Output scheduled qty. | H36: 出来高予定数量 | I36: E | J36: - | L36: positive
A37: 10 | D37: ord.nmr_qty# | E37: RI | G37: Yield numerator | H37: 歩留分子 | I37: E | J37: -
A38: 10 | D38: ord.dnm_qty# | E38: RI | G38: Yield denominator | H38: 歩留分母 | I38: E | J38: -
A39: 10 | D39: ord.fxd_yield_qty# | E39: RI | G39: Constant yield qty. | H39: 固定歩留数量 | I39: E | J39: -
A40: 10 | D40: ord.itm_ord_sts_typ# | E40: RI | G40: Order status type | H40: オーダ状況区分 | I40: E | J40: -
...

Sheet Ord_Sprt01
A1: * | B1: * | D1: L | E1: 1
A2: * | D2: オペレーション実装仕様書 Operation Specification Implementation Sheet | E2: ModuleID : | F2: =IF(LogicCommon!C2="","",LogicCommon!C2) -> MS | G2: LogicID : | H2: =IF(LogicCommon!E2="","",LogicCommon!E2) -> MSBCL5010 | I2: Ope.ID : | J2: Ord_Sprt01 | K2: Pj.ID : | L2: =IF(LogicCommon!G2="","",LogicCommon!G2) -> MC | M2: Ope.Body : | N2: "mcframe.serverMAUD.MAUDL5010.MAUDL_Operation"
A3: * | E3: SubModuleID : | F3: =IF(LogicCommon!C3="","",LogicCommon!C3) -> MSBC | G3: LogicClass : | H3: =IF(LogicCommon!E3="","",LogicCommon!E3) -> MSBCL_OrdRegService | I3: Ope.Method : | J3: Ord_Sprt01 | K3: SuperClassPj.ID : | L3: =IF(LogicCommon!G3="","",LogicCommon!G3) | O3: Gene.Type : | P3: ALL
A4: * | E4: Version : | F4: 000000 | G4: LogicName : | H4: =IF(LogicCommon!E4="","",LogicCommon!E4) -> オーダ登録サービス | I4: Ope.Name : | J4: 工程オーダ展開 | K4: SuperLogicID : | L4: =IF(LogicCommon!G4="","",LogicCommon!G4) -> MS.MSUDL5010 | M4: ImplOpe.ID:
A5: * | E5: ACType :
A6: * | D6: 概要 : | M6: ID | O6: ID | Q6: ID
A7: # | I7: U | L7: o | N7: o | P7: o
A8: # | D8: ブロック名 Block Name | E8: 型 Type | G8: super/share | H8: 対象ブロック名 Target Block Name | L8: TargetName | N8: TargetName | P8: TargetName | T8: ブロック備考 Block Remarks
A9: # | D9: 項目名 Field Name | E9: 型 Type | F9: 桁 Digits | G9: フルネーム Full Name | H9: 日本語名 Japanese Name | I9: 上り項目 Request Message Field | J9: 下り項目 Response Message Field | R9: 条件および編集方法 Conditions and Editing Methods | T9: 項目備考 Field Remarks
A10: # | L10: 上り項目 Request Message Field | M10: 下り項目 Response Message Field | N10: 上り項目 Request Message Field | O10: 下り項目 Response Message Field | P10: 上り項目 Request Message Field | Q10: 下り項目 Response Message Field
A11: 10 | B11: * | D11: Ord_Sprt01_Dtl | E11: L
A12: 10 | D12: peg_no | E12: #MA.INT | G12: Pegging No. | H12: 紐付けＮＯ | I12: E | J12: -
A13: 10 | D13: itm_ord_no | E13: #MA.ITM_ORD_NO | G13: Item order No. | H13: 品目オーダＮＯ | I13: E | J13: -
A14: 10 | D14: itm_ord_typ | E14: #MS.ITM_ORD_TYP | G14: Item order type | H14: 品目オーダ区分 | I14: E
A15: 10 | D15: wg_cd | E15: #MA.WG_CD | G15: WG cd. | H15: ワーキンググループＣＤ | I15: E | J15: -
A16: 10 | D16: bom_ptn | E16: #MA.BOM_PTN | G16: BOM pattern | H16: 構成パタン | I16: E | J16: -
A17: 10 | D17: itm_cd | E17: #MA.ITM_CD | G17: Item cd. | H17: 品目ＣＤ | I17: E | J17: -
A18: 10 | D18: itm_sub1 | E18: #MA.ITM_SUB1 | G18: Branch No. 1 | H18: 枝番１ | I18: E | J18: -
A19: 10 | D19: itm_sub2 | E19: #MA.ITM_SUB2 | G19: Branch No. 2 | H19: 枝番２ | I19: E | J19: -
A20: 10 | D20: itm_sub3 | E20: #MA.ITM_SUB3 | G20: Branch No. 3 | H20: 枝番３ | I20: E | J20: -
A21: 10 | D21: inst_qty | E21: #MA.QTY | G21: Order scheduled qty. | H21: 指図予定数量 | I21: E | J21: -
A22: 10 | D22: mfg_loc_cd | E22: #MA.LOC_CD | G22: Mfg. location cd. | H22: 製造場所ＣＤ | I22: E | J22: -
A23: 10 | D23: oper_ptn | E23: #MA.OPER_PTN | G23: Operation pattern | H23: 工程パタン | I23: E | J23: -
A24: 10 | D24: sno1 | E24: #MA.SNO1 | G24: SEIBAN No. 1 | H24: 手配ＮＯ１ | I24: E | J24: -
A25: 10 | D25: sno2 | E25: #MA.SNO2 | G25: SEIBAN No. 2 | H25: 手配ＮＯ２ | I25: E | J25: -
A26: 10 | D26: sno3 | E26: #MA.SNO3 | G26: SEIBAN No. 3 | H26: 手配ＮＯ３ | I26: E | J26: -
... A38: 10 | D38: bkf_flg | E38: #MA.FLG | G38: Allow backflush | H38: バックフラッシュ許可 | I38: - | J38: -
A40: 20 | B40: * | D40: Ord_Sprt01_Rslt | E40: L
A41: 20 | D41: peg_no | E41: #MA.INT | G41: Pegging No. | H41: 紐付けＮＯ | I41: - | J41: E
A42: 20 | D42: st_schd_tm | E42: #MA.TM | G42: Scheduled operation start date and time | H42: 工程着手予定日時 | I42: - | J42: E
A43: 20 | D43: end_schd_tm | E43: #MA.TM | G43: Scheduled operation end date and time | H43: 工程終了予定日時 | I43: - | J43: E
A44: 20 | D44: oper_lt | E44: #MA.LT | G44: Operation LT | H44: 工程ＬＴ | I44: - | J44: E
A45: 20 | D45: mst_oper_lt | E45: #MA.LT | G45: Operation LT (Master) | H45: 工程ＬＴ（マスタ） | I45: - | J45: E
A46: 20 | D46: oper_lt_add_qty | E46: #MA.QTY | G46: Operation LT add base qty. | H46: 工程ＬＴ加算基準数量 | I46: - | J46: E
A47: 20 | D47: oper_offst_typ | E47: #MA.OFFST_TYP | G47: Operation offset type | H47: 工程オフセット区分 | I47: - | J47: E
A48: 20 | D48: oper_offst | E48: #MA.OFFST | G48: Operation offset | H48: 工程オフセット | I48: - | J48: E
A49: 20 | D49: mst_oper_offst | E49: #MA.OFFST | G49: Operation offset (Master) | H49: 工程オフセット（マスタ） | I49: - | J49: E
A50: 20 | D50: oper_offst_add_qty | E50: #MA.QTY | G50: Operation offset add base qty. | H50: 工程オフセット加算基準数量 | I50: - | J50: E
A51: 20 | D51: oper_ord_sts_typ | E51: #MS.OPER_ORD_STS_TYP | G51: Operation order status type | H51: 工程オーダ状況区分 | I51: - | J51: E
A52: 20 | D52: oper_schd_qty | E52: #MA.QTY | G52: Operation order scheduled qty. | H52: 工程指図予定数量 | I52: - | J52: E
...

Sheet Ord_Sprt02
A1: * | B1: * | D1: L | E1: 1
A2: * | D2: オペレーション実装仕様書 Operation Specification Implementation Sheet | E2: ModuleID : | F2: =IF(LogicCommon!C2="","",LogicCommon!C2) -> MS | G2: LogicID : | H2: =IF(LogicCommon!E2="","",LogicCommon!E2) -> MSBCL5010 | I2: Ope.ID : | J2: Ord_Sprt02 | K2: Pj.ID : | L2: =IF(LogicCommon!G2="","",LogicCommon!G2) -> MC | M2: Ope.Body : | N2: "mcframe.serverMAUD.MAUDL5010.MAUDL_Operation"
A3: * | E3: SubModuleID : | F3: =IF(LogicCommon!C3="","",LogicCommon!C3) -> MSBC | G3: LogicClass : | H3: =IF(LogicCommon!E3="","",LogicCommon!E3) -> MSBCL_OrdRegService | I3: Ope.Method : | J3: Ord_Sprt02 | K3: SuperClassPj.ID : | L3: =IF(LogicCommon!G3="","",LogicCommon!G3) | O3: Gene.Type : | P3: ALL
A4: * | E4: Version : | F4: 000000 | G4: LogicName : | H4: =IF(LogicCommon!E4="","",LogicCommon!E4) -> オーダ登録サービス | I4: Ope.Name : | J4: 構成展開 | K4: SuperLogicID : | L4: =IF(LogicCommon!G4="","",LogicCommon!G4) -> MS.MSUDL5010 | M4: ImplOpe.ID:
A5: * | E5: ACType :
A6: * | D6: 概要 : | M6: ID | O6: ID | Q6: ID
A7: # | I7: U | L7: o | N7: o | P7: o
A8: # | D8: ブロック名 Block Name | E8: 型 Type | G8: super/share | H8: 対象ブロック名 Target Block Name | L8: TargetName | N8: TargetName | P8: TargetName | T8: ブロック備考 Block Remarks
A9: # | D9: 項目名 Field Name | E9: 型 Type | F9: 桁 Digits | G9: フルネーム Full Name | H9: 日本語名 Japanese Name | I9: 上り項目 Request Message Field | J9: 下り項目 Response Message Field | R9: 条件および編集方法 Conditions and Editing Methods | T9: 項目備考 Field Remarks
A10: # | L10: 上り項目 Request Message Field | M10: 下り項目 Response Message Field | N10: 上り項目 Request Message Field | O10: 下り項目 Response Message Field | P10: 上り項目 Request Message Field | Q10: 下り項目 Response Message Field
A11: 10 | B11: * | D11: Ord_Sprt02_Cnd | E11: R
A12: 10 | D12: inst_exp_flg | E12: #MA.FLG | G12: Explode at order | H12: 指図時展開 | I12: E | J12: -
A13: 10 | D13: get_prov_upri_flg | E13: #MA.FLG | G13: Supply unit price acquisition | H13: 支給単価取得 | I13: E | J13: -
A15: 20 | B15: * | D15: Ord_Sprt02_Dtl | E15: L
A16: 20 | D16: peg_no | E16: #MA.INT | G16: Pegging No. | H16: 紐付けＮＯ | I16: E | J16: -
A17: 20 | D17: itm_ord_no | E17: #MA.ITM_ORD_NO | G17: Item order No. | H17: 品目オーダＮＯ | I17: E | J17: -
A18: 20 | D18: oper_ord_no | E18: #MA.OPER_ORD_NO | G18: Operation order No. | H18: 工程オーダＮＯ | I18: E | J18: -
A19: 20 | D19: itm_cd | E19: #MA.ITM_CD | G19: Item cd. | H19: 品目ＣＤ | I19: E | J19: -
A20: 20 | D20: itm_sub1 | E20: #MA.ITM_SUB1 | G20: Branch No. 1 | H20: 枝番１ | I20: E | J20: -
A21: 20 | D21: itm_sub2 | E21: #MA.ITM_SUB2 | G21: Branch No. 2 | H21: 枝番２ | I21: E | J21: -
A22: 20 | D22: itm_sub3 | E22: #MA.ITM_SUB3 | G22: Branch No. 3 | H22: 枝番３ | I22: E | J22: -
A23: 20 | D23: mfg_loc_cd | E23: #MA.LOC_CD | G23: Mfg. location cd. | H23: 製造場所ＣＤ | I23: E | J23: -
A24: 20 | D24: bom_ptn | E24: #MA.BOM_PTN | G24: BOM pattern | H24: 構成パタン | I24: E | J24: -
A25: 20 | D25: oper_cd | E25: #MA.OPER_CD | G25: Operation cd. | H25: 工程ＣＤ | I25: E | J25: -
A26: 20 | D26: oper_seq | E26: #MA.OPER_SEQ | G26: Operation sequence number | H26: 工程連番 | I26: E | J26: -
A27: 20 | D27: inst_qty | E27: #MA.QTY | G27: Order scheduled qty. | H27: 指図予定数量 | I27: E | J27: -
... A35: 20 | D35: cur_cd | E35: #MA.CUR_CD | G35: Currency cd. | H35: 通貨ＣＤ | I35: E | J35: -
A37: 30 | B37: * | D37: Ord_Sprt02_Rslt | E37: L
A38: 30 | D38: peg_no | E38: #MA.INT | G38: Pegging No. | H38: 紐付けＮＯ | I38: - | J38: E
A39: 30 | D39: bom_id | E39: #MA.INT | G39: BOM identification number | H39: ＢＯＭ識別ＩＤ | I39: - | J39: E
A40: 30 | D40: itm_seq | E40: #MA.INT | G40: Allow same child item sequence number | H40: 同一子品目連番 | I40: - | J40: E
A41: 30 | D41: itm_ord_no | E41: #MA.ITM_ORD_NO | G41: Item order No. | H41: 品目オーダＮＯ | I41: - | J41: E
A42: 30 | D42: oper_ord_no | E42: #MA.OPER_ORD_NO | G42: Operation order No. | H42: 工程オーダＮＯ | I42: - | J42: E
A43: 30 | D43: mst_wg_cd | E43: #MA.WG_CD | G43: Master WG cd. | H43: マスタワーキンググループＣＤ | I43: - | J43: E
A44: 30 | D44: oper_cd | E44: #MA.OPER_CD | G44: Operation cd. | H44: 工程ＣＤ | I44: - | J44: E
A45: 30 | D45: oper_seq | E45: #MA.OPER_SEQ | G45: Operation sequence number | H45: 工程連番 | I45: - | J45: E
A46: 30 | D46: loc_cd | E46: #MA.LOC_CD | G46: Input location cd. | H46: 投入場所ＣＤ | I46: - | J46: E
A47: 30 | D47: schd_in_dt | E47: #MA.DT | G47: Scheduled input date | H47: 投入予定日 | I47: - | J47: E
A48: 30 | D48: itm_cd | E48: #MA.ITM_CD | G48: Child item cd. | H48: 子品目ＣＤ | I48: - | J48: E
A49: 30 | D49: itm_sub1 | E49: #MA.ITM_SUB1 | G49: Child branch No. 1 | H49: 子枝番１ | I49: - | J49: E
...

Sheet Ord_Sprt03
A1: * | B1: * | D1: L | E1: 1
A2: * | D2: オペレーション実装仕様書 Operation Specification Implementation Sheet | E2: ModuleID : | F2: =IF(LogicCommon!C2="","",LogicCommon!C2) -> MS | G2: LogicID : | H2: =IF(LogicCommon!E2="","",LogicCommon!E2) -> MSBCL5010 | I2: Ope.ID : | J2: Ord_Sprt03 | K2: Pj.ID : | L2: =IF(LogicCommon!G2="","",LogicCommon!G2) -> MC | M2: Ope.Body : | N2: "mcframe.serverMAUD.MAUDL5010.MAUDL_Operation"
A3: * | E3: SubModuleID : | F3: =IF(LogicCommon!C3="","",LogicCommon!C3) -> MSBC | G3: LogicClass : | H3: =IF(LogicCommon!E3="","",LogicCommon!E3) -> MSBCL_OrdRegService | I3: Ope.Method : | J3: Ord_Sprt03 | K3: SuperClassPj.ID : | L3: =IF(LogicCommon!G3="","",LogicCommon!G3) | O3: Gene.Type : | P3: ALL
A4: * | E4: Version : | F4: 000000 | G4: LogicName : | H4: =IF(LogicCommon!E4="","",LogicCommon!E4) -> オーダ登録サービス | I4: Ope.Name : | J4: 予定日計算 | K4: SuperLogicID : | L4: =IF(LogicCommon!G4="","",LogicCommon!G4) -> MS.MSUDL5010 | M4: ImplOpe.ID:
A5: * | E5: ACType :
A6: * | D6: 概要 : | N6: ID | P6: ID | R6: ID
A7: # | I7: U | M7: o | O7: o | Q7: o
A8: # | D8: ブロック名 Block Name | E8: 型 Type | G8: super/share | H8: 対象ブロック名 Target Block Name | M8: TargetName | O8: TargetName | Q8: TargetName | U8: ブロック備考 Block Remarks
A9: # | D9: 項目名 Field Name | E9: 型 Type | F9: 桁 Digits | G9: フルネーム Full Name | H9: 日本語名 Japanese Name | I9: 上り項目 Request Message Field | J9: 下り項目 Response Message Field | S9: 条件および編集方法 Conditions and Editing Methods | U9: 項目備考 Field Remarks
A10: # | M10: 上り項目 Request Message Field | N10: 下り項目 Response Message Field | O10: 上り項目 Request Message Field | P10: 下り項目 Response Message Field | Q10: 上り項目 Request Message Field | R10: 下り項目 Response Message Field
A11: 10 | B11: * | D11: Ord_Sprt03_Dtl | E11: L
A12: 10 | D12: peg_no | E12: #MA.INT | G12: Pegging No. | H12: 紐付けＮＯ | I12: E | J12: -
A13: 10 | D13: itm_ord_typ | E13: #MS.ITM_ORD_TYP | G13: Order type | H13: オーダ区分 | I13: E | J13: -
A14: 10 | D14: po_schd_dt | E14: #MA.DT | G14: Scheduled PO date | H14: 発注予定日 | I14: E | J14: -
A15: 10 | D15: gi_schd_dt | E15: #MA.DT | G15: Scheduled GI date | H15: 出庫予定日 | I15: E | J15: -
A16: 10 | D16: mfg_st_schd_dt | E16: #MA.DT | G16: Scheduled mfg. start date | H16: 製造着手予定日 | I16: E | J16: -
A17: 10 | D17: mfg_end_schd_dt | E17: #MA.DT | G17: Scheduled mfg. end date | H17: 製造終了予定日 | I17: E | J17: -
A18: 10 | D18: strg_schd_dt | E18: #MA.DT | G18: Scheduled storage completion date | H18: 格納完了予定日 | I18: E | J18: -
A19: 10 | D19: accpt_schd_dt | E19: #MA.DT | G19: Scheduled acceptance date | H19: 検収予定日 | I19: E | J19: -
A20: 10 | D20: insp_st_schd_dt | E20: #MA.DT | G20: Scheduled inspection start date | H20: 検査着手予定日 | I20: E | J20: -
A21: 10 | D21: insp_end_schd_dt | E21: #MA.DT | G21: Scheduled inspection end date | H21: 検査終了予定日 | I21: E | J21: -
A22: 10 | D22: avl_schd_dt | E22: #MA.DT | G22: Available date | H22: 使用可能予定日 | I22: E | J22: -
A23: 10 | D23: master_dt | E23: #MA.DT | G23: Master application date | H23: マスタ適用日 | I23: E | J23: -
... A40: 10 | D40: dlv_cd | E40: #MA.BP_CD | G40: Delivery destination cd. | H40: 納品先ＣＤ | I40: E | J40: -
A42: 20 | B42: * | D42: Ord_Sprt03_Rslt | E42: L
A43: 20 | D43: peg_no | E43: #MA.INT | G43: Pegging No. | H43: 紐付けＮＯ | I43: - | J43: E
A44: 20 | D44: po_schd_dt | E44: #MA.DT | G44: Scheduled PO date | H44: 発注予定日 | I44: - | J44: E
A45: 20 | D45: purc_lt | E45: #MA.LT | G45: Purchase LT | H45: 購入ＬＴ | I45: - | J45: E
A46: 20 | D46: gi_schd_dt | E46: #MA.DT | G46: Scheduled GI date | H46: 出庫予定日 | I46: - | J46: E
A47: 20 | D47: mfg_st_schd_dt | E47: #MA.DT | G47: Scheduled mfg. start date | H47: 製造着手予定日 | I47: - | J47: E
A48: 20 | D48: mfg_lt | E48: #MA.LT | G48: Mfg. LT | H48: 製造ＬＴ | I48: - | J48: E
A49: 20 | D49: mfg_end_schd_dt | E49: #MA.DT | G49: Scheduled mfg. end date | H49: 製造終了予定日 | I49: - | J49: E
A50: 20 | D50: xfr_lt | E50: #MA.LT | G50: Movement LT | H50: 移動ＬＴ | I50: - | J50: E
A51: 20 | D51: strg_schd_dt | E51: #MA.DT | G51: Scheduled storage completion date | H51: 格納完了予定日 | I51: - | J51: E
A52: 20 | D52: accpt_insp_lt | E52: #MA.LT | G52: Acceptance LT | H52: 検収ＬＴ | I52: - | J52: E
A53: 20 | D53: accpt_schd_dt | E53: #MA.DT | G53: Scheduled acceptance date | H53: 検収予定日 | I53: - | J53: E
A54: 20 | D54: insp_offst | E54: #MA.LT | G54: Inspection offset | H54: 検査オフセット | I54: - | J54: E
... A59: 20 | D59: insp_flg | E59: #MA.FLG | G59: For inspection | H59: 検査対象 | I59: - | J59: E
D60: 詳細 :

Sheet Ord_Sprt04
A1: * | B1: * | D1: L | E1: 1
A2: * | D2: オペレーション実装仕様書 Operation Specification Implementation Sheet | E2: ModuleID : | F2: =IF(LogicCommon!C2="","",LogicCommon!C2) -> MS | G2: LogicID : | H2: =IF(LogicCommon!E2="","",LogicCommon!E2) -> MSBCL5010 | I2: Ope.ID : | J2: Ord_Sprt04 | K2: Pj.ID : | L2: =IF(LogicCommon!G2="","",LogicCommon!G2) -> MC | M2: Ope.Body : | N2: "mcframe.serverMAUD.MAUDL5010.MAUDL_Operation"
A3: * | E3: SubModuleID : | F3: =IF(LogicCommon!C3="","",LogicCommon!C3) -> MSBC | G3: LogicClass : | H3: =IF(LogicCommon!E3="","",LogicCommon!E3) -> MSBCL_OrdRegService | I3: Ope.Method : | J3: Ord_Sprt04 | K3: SuperClassPj.ID : | L3: =IF(LogicCommon!G3="","",LogicCommon!G3) | O3: Gene.Type : | P3: ALL
A4: * | E4: Version : | F4: 000000 | G4: LogicName : | H4: =IF(LogicCommon!E4="","",LogicCommon!E4) -> オーダ登録サービス | I4: Ope.Name : | J4: 品目オーダ補完 | K4: SuperLogicID : | L4: =IF(LogicCommon!G4="","",LogicCommon!G4) -> MS.MSUDL5010 | M4: ImplOpe.ID:
A5: * | E5: ACType :
A6: * | D6: 概要 : | M6: ID | O6: ID | Q6: ID
A7: # | I7: U | L7: o | N7: o | P7: o
A8: # | D8: ブロック名 Block Name | E8: 型 Type | G8: super/share | H8: 対象ブロック名 Target Block Name | L8: TargetName | N8: TargetName | P8: TargetName | T8: ブロック備考 Block Remarks
A9: # | D9: 項目名 Field Name | E9: 型 Type | F9: 桁 Digits | G9: フルネーム Full Name | H9: 日本語名 Japanese Name | I9: 上り項目 Request Message Field | J9: 下り項目 Response Message Field | R9: 条件および編集方法 Conditions and Editing Methods | T9: 項目備考 Field Remarks
A10: # | L10: 上り項目 Request Message Field | M10: 下り項目 Response Message Field | N10: 上り項目 Request Message Field | O10: 下り項目 Response Message Field | P10: 上り項目 Request Message Field | Q10: 下り項目 Response Message Field
A11: 10 | B11: * | D11: Ord_Sprt04_Dtl | E11: L | G11: $share$ | H11: MS.MSBCL5010.Ord_Upd01.Ord_Upd01_Dtl1
A12: 10 | D12: peg_no | E12: #MA.INT | G12: Pegging No. | H12: 紐付けＮＯ | I12: E | J12: E
A13: 10 | D13: mrp_typ | E13: #MS.MRP_TYP | G13: MRP type | H13: ＭＲＰタイプ | I13: - | J13: -
A14: 10 | D14: data_crud_typ | E14: #MA.DATA_CRUD_TYP | G14: Data update type | H14: データ更新区分 | I14: - | J14: -
A15: 10 | D15: a_itm_ord_sts_typ | E15: #MS.ITM_ORD_STS_TYP | G15: Order status type after update | H15: 更新後オーダ状況区分 | I15: - | J15: -
A16: 10 | D16: b_itm_ord_sts_typ | E16: #MS.ITM_ORD_STS_TYP | G16: Order status type before update | H16: 更新前オーダ状況区分 | I16: - | J16: -
A17: 10 | D17: ord | E17: R | F17: DBC:MS.MST_ITM_ORDER | I17: - | J17: -
A18: 10 | D18: ord.itm_ord_no# | E18: RI | G18: Item order No. | H18: 品目オーダＮＯ | I18: - | J18: -
A19: 10 | D19: ord.itm_ord_typ# | E19: RI | G19: Order type | H19: オーダ区分 | I19: E | J19: E
A20: 10 | D20: ord.ord_gnrt_typ# | E20: RI | G20: Order generation type | H20: オーダ生成区分 | I20: - | J20: -
A21: 10 | D21: ord.itm_cd# | E21: RI | G21: Item cd. | H21: 品目ＣＤ | I21: E | J21: E
A22: 10 | D22: ord.itm_sub1# | E22: RI | G22: Branch No. 1 | H22: 枝番１ | I22: E | J22: E
A23: 10 | D23: ord.itm_sub2# | E23: RI | G23: Branch No. 2 | H23: 枝番２ | I23: E | J23: E
A24: 10 | D24: ord.itm_sub3# | E24: RI | G24: Branch No. 3 | H24: 枝番３ | I24: E | J24: E
A25: 10 | D25: ord.ver_no# | E25: RI | G25: Version No. | H25: 版ＮＯ | I25: E | J25: E
A26: 10 | D26: ord.strg_loc_cd# | E26: RI | G26: Storage location cd. | H26: 格納場所ＣＤ | I26: E | J26: E
A27: 10 | D27: ord.mfg_loc_cd# | E27: RI | G27: Mfg. location cd. | H27: 製造場所ＣＤ | I27: E | J27: E
A28: 10 | D28: ord.mst_mfg_loc_cd# | E28: RI | G28: Master mfg. location cd. | H28: マスタ製造場所ＣＤ | I28: - | J28: E
A29: 10 | D29: ord.sppl_cd# | E29: RI | G29: Supplier cd. | H29: 発注先ＣＤ | I29: E | J29: E
... A135: 10 | D135: itm_typ_d_nm | E135: #MA.ITM_TYP_D_NM | G135: Item type details name | H135: 品目区分詳細名 | I135: - | J135: E
D136: 詳細 :

Sheet Ord_Chk01
A1: * | B1: * | D1: L | E1: 1
A2: * | D2: オペレーション実装仕様書 Operation Specification Implementation Sheet | E2: ModuleID : | F2: =IF(LogicCommon!C2="","",LogicCommon!C2) -> MS | G2: LogicID : | H2: =IF(LogicCommon!E2="","",LogicCommon!E2) -> MSBCL5010 | I2: Ope.ID : | J2: Ord_Chk01 | K2: Pj.ID : | L2: =IF(LogicCommon!G2="","",LogicCommon!G2) -> MC | M2: Ope.Body : | N2: MA.MAUDL5010.Checker
A3: * | E3: SubModuleID : | F3: =IF(LogicCommon!C3="","",LogicCommon!C3) -> MSBC | G3: LogicClass : | H3: =IF(LogicCommon!E3="","",LogicCommon!E3) -> MSBCL_OrdRegService | I3: Ope.Method : | J3: Ord_Chk01 | K3: SuperClassPj.ID : | L3: =IF(LogicCommon!G3="","",LogicCommon!G3) | O3: Gene.Type : | P3: ALL
A4: * | E4: Version : | F4: 000000 | G4: LogicName : | H4: =IF(LogicCommon!E4="","",LogicCommon!E4) -> オーダ登録サービス | I4: Ope.Name : | J4: オーダ更新チェック | K4: SuperLogicID : | L4: =IF(LogicCommon!G4="","",LogicCommon!G4) -> MS.MSUDL5010 | M4: ImplOpe.ID:
A5: * | E5: ACType :
A6: * | D6: 概要 : | V6: ID | X6: ID | Z6: ID
A7: # | I7: U | K7: K | L7: K | M7: K | N7: K | O7: K | P7: K | Q7: K | R7: K | S7: K | T7: K | U7: o | W7: o | Y7: o
A8: # | D8: ブロック名 Block Name | E8: 型 Type | G8: super/share | H8: 対象ブロック名 Target Block Name | K8: REQUIRED | L8: CHK_NUM | M8: SMALL_LARGE | N8: CONST | O8: NULL_VAL | P8: LIST_LOGIC | Q8: LIST_OUT | R8: LIST_OUT_BASE | S8: LIST_IN | T8: LIST_IN_BASE | U8: TargetName | W8: TargetName | Y8: TargetName | AC8: ブロック備考 Block Remarks
A9: # | D9: 項目名 Field Name | E9: 型 Type | F9: 桁 Digits | G9: フルネーム Full Name | H9: 日本語名 Japanese Name | I9: 上り項目 Request Message Field | J9: 下り項目 Response Message Field | AA9: 条件および編集方法 Conditions and Editing Methods | AC9: 項目備考 Field Remarks
A10: # | U10: 上り項目 Request Message Field | V10: 下り項目 Response Message Field | W10: 上り項目 Request Message Field | X10: 下り項目 Response Message Field | Y10: 上り項目 Request Message Field | Z10: 下り項目 Response Message Field
A11: 10 | B11: * | D11: Ord_Chk01_Dtl1 | E11: L | G11: $share$ | H11: MS.MSBCL5010.Ord_Upd01.Ord_Upd01_Dtl1
A12: 10 | D12: peg_no | E12: #MA.INT | G12: Pegging No. | H12: 紐付けＮＯ | I12: E | J12: E | K12: E
A13: 10 | D13: mrp_typ | E13: #MS.MRP_TYP | G13: MRP type | H13: ＭＲＰタイプ | I13: E | J13: - | K13: E | N13: MSC_MRP_TYP
A14: 10 | D14: data_crud_typ | E14: #MA.DATA_CRUD_TYP | G14: Data update type | H14: データ更新区分 | I14: E | J14: - | K14: E | N14: MSC_DATA_CRUD_TYP
A15: 10 | D15: a_itm_ord_sts_typ | E15: #MS.ITM_ORD_STS_TYP | G15: Order status type after update | H15: 更新後オーダ状況区分 | I15: - | J15: -
A16: 10 | D16: b_itm_ord_sts_typ | E16: #MS.ITM_ORD_STS_TYP | G16: Order status type before update | H16: 更新前オーダ状況区分 | I16: - | J16: -
A17: 10 | D17: oper_ord_pr_flg | E17: #MA.FLG | G17: Operation order generation | H17: 工程オーダ生成 | I17: E | J17: -
A18: 10 | D18: ord | E18: R | F18: DBC:MS.MST_ITM_ORDER
A19: 10 | D19: ord.itm_ord_no# | E19: RI | G19: Item order No. | H19: 品目オーダＮＯ | I19: E | J19: -
A20: 10 | D20: ord.itm_ord_typ# | E20: RI | G20: Order type | H20: オーダ区分 | I20: E | J20: - | N20: MSC_ITM_ORD_TYP
A21: 10 | D21: ord.ord_gnrt_typ# | E21: RI | G21: Order generation type | H21: オーダ生成区分 | I21: E | J21: - | N21: MSC_ORD_GNRT_TYP
A22: 10 | D22: ord.itm_cd# | E22: RI | G22: Item cd. | H22: 品目ＣＤ | I22: E | J22: -
A23: 10 | D23: ord.itm_sub1# | E23: RI | G23: Branch No. 1 | H23: 枝番１ | I23: E | J23: - | O23: E
A24: 10 | D24: ord.itm_sub2# | E24: RI | G24: Branch No. 2 | H24: 枝番２ | I24: E | J24: - | O24: E
A25: 10 | D25: ord.itm_sub3# | E25: RI | G25: Branch No. 3 | H25: 枝番３ | I25: E | J25: - | O25: E
A26: 10 | D26: ord.ver_no# | E26: RI | G26: Version No. | H26: 版ＮＯ | I26: E | J26: -
A27: 10 | D27: ord.strg_loc_cd# | E27: RI | G27: Storage location cd. | H27: 格納場所ＣＤ | I27: E | J27: - | O27: E
A28: 10 | D28: ord.mfg_loc_cd# | E28: RI | G28: Mfg. location cd. | H28: 製造場所ＣＤ | I28: E | J28: - | O28: E
A29: 10 | D29: ord.mst_mfg_loc_cd# | E29: RI | G29: Master mfg. location cd. | H29: マスタ製造場所ＣＤ | I29: E | J29: - | O29: E
A30: 10 | D30: ord.sppl_cd# | E30: RI | G30: Supplier cd. | H30: 発注先ＣＤ | I30: E | J30: - | O30: E
A31: 10 | D31: ord.maker_cd# | E31: RI | G31: Maker cd. | H31: メーカＣＤ | I31: E | J31: - | O31: E
A32: 10 | D32: ord.rqst_loc_cd# | E32: RI | G32: Requested location cd. | H32: 依頼先場所ＣＤ | I32: E | J32: - | O32: E
A33: 10 | D33: ord.rqst_wg_cd# | E33: RI | G33: Requested WG cd. | H33: 依頼先ＷＧ ＣＤ | I33: E | J33: -
A34: 10 | D34: ord.bom_ptn# | E34: RI | G34: BOM pattern | H34: 構成パタン | I34: E | J34: - | K34: E | O34: E
A35: 10 | D35: ord.oper_ptn# | E35: RI | G35: Operation pattern | H35: 工程パタン | I35: E | J35: -
A36: 10 | D36: ord.inst_qty# | E36: RI | G36: Order scheduled qty. | H36: 指図予定数量 | I36: E | J36: - | L36: positive
A37: 10 | D37: ord.yield_schd_qty# | E37: RI | G37: Output scheduled qty. | H37: 出来高予定数量 | I37: E | J37: - | L37: positive
A38: 10 | D38: ord.nmr_qty# | E38: RI | G38: Yield numerator | H38: 歩留分子 | I38: E | J38: - | L38: positive
A39: 10 | D39: ord.dnm_qty# | E39: RI | G39: Yield denominator | H39: 歩留分母 | I39: E | J39: - | L39: positive
A40: 10 | D40: ord.fxd_yield_qty# | E40: RI | G40: Constant yield qty. | H40: 固定歩留数量 | I40: E | J40: - | M40: 0:
...

Sheet Ord_Chk02
A1: * | B1: * | D1: L | E1: 1
A2: * | D2: オペレーション実装仕様書 Operation Specification Implementation Sheet | E2: ModuleID : | F2: =IF(LogicCommon!C2="","",LogicCommon!C2) -> MS | G2: LogicID : | H2: =IF(LogicCommon!E2="","",LogicCommon!E2) -> MSBCL5010 | I2: Ope.ID : | J2: Ord_Chk02 | K2: Pj.ID : | L2: =IF(LogicCommon!G2="","",LogicCommon!G2) -> MC | M2: Ope.Body : | N2: MA.MAUDL5010.Checker
A3: * | E3: SubModuleID : | F3: =IF(LogicCommon!C3="","",LogicCommon!C3) -> MSBC | G3: LogicClass : | H3: =IF(LogicCommon!E3="","",LogicCommon!E3) -> MSBCL_OrdRegService | I3: Ope.Method : | J3: Ord_Chk02 | K3: SuperClassPj.ID : | L3: =IF(LogicCommon!G3="","",LogicCommon!G3) | O3: Gene.Type : | P3: ALL
A4: * | E4: Version : | F4: 000000 | G4: LogicName : | H4: =IF(LogicCommon!E4="","",LogicCommon!E4) -> オーダ登録サービス | I4: Ope.Name : | J4: オーダ状況更新チェック | K4: SuperLogicID : | L4: =IF(LogicCommon!G4="","",LogicCommon!G4) -> MS.MSUDL5010 | M4: ImplOpe.ID:
A5: * | E5: ACType :
A6: * | D6: 概要 : | O6: ID | Q6: ID | S6: ID
A7: # | I7: U | K7: K | L7: K | M7: K | N7: o | P7: o | R7: o
A8: # | D8: ブロック名 Block Name | E8: 型 Type | G8: super/share | H8: 対象ブロック名 Target Block Name | K8: REQUIRED | L8: CONST | N8: TargetName | P8: TargetName | R8: TargetName | V8: ブロック備考 Block Remarks
A9: # | D9: 項目名 Field Name | E9: 型 Type | F9: 桁 Digits | G9: フルネーム Full Name | H9: 日本語名 Japanese Name | I9: 上り項目 Request Message Field | J9: 下り項目 Response Message Field | T9: 条件および編集方法 Conditions and Editing Methods | V9: 項目備考 Field Remarks
A10: # | N10: 上り項目 Request Message Field | O10: 下り項目 Response Message Field | P10: 上り項目 Request Message Field | Q10: 下り項目 Response Message Field | R10: 上り項目 Request Message Field | S10: 下り項目 Response Message Field
A11: 10 | B11: * | D11: Ord_Chk02_Dtl | E11: L | G11: $share$ | H11: MS.MSBCL5010.Ord_Upd01.Ord_Upd01_Dtl1
A12: 10 | D12: peg_no | E12: #MA.INT | G12: Pegging No. | H12: 紐付けＮＯ | I12: E | J12: E | K12: E
A13: 10 | D13: mrp_typ | E13: #MS.MRP_TYP | G13: MRP type | H13: ＭＲＰタイプ | I13: E | J13: -
A14: 10 | D14: data_crud_typ | E14: #MA.DATA_CRUD_TYP | G14: Data update type | H14: データ更新区分 | I14: E | J14: -
A15: 10 | D15: ord | E15: R | F15: DBC:MS.MST_ITM_ORDER
A16: 10 | D16: ord.itm_ord_no# | E16: RI | G16: Item order No. | H16: 品目オーダＮＯ | I16: E | J16: E | K16: E
A17: 10 | D17: ord.itm_ord_typ# | E17: RI | G17: Order type | H17: オーダ区分 | I17: - | J17: E
A18: 10 | D18: ord.itm_cd# | E18: RI | G18: Item cd. | H18: 品目ＣＤ | I18: - | J18: E
A19: 10 | D19: ord.itm_sub1# | E19: RI | G19: Branch No. 1 | H19: 枝番１ | I19: - | J19: E
A20: 10 | D20: ord.itm_sub2# | E20: RI | G20: Branch No. 2 | H20: 枝番２ | I20: - | J20: E
A21: 10 | D21: ord.itm_sub3# | E21: RI | G21: Branch No. 3 | H21: 枝番３ | I21: - | J21: E
A22: 10 | D22: ord.ver_no# | E22: RI | G22: Version No. | H22: 版ＮＯ | I22: - | J22: E
A23: 10 | D23: ord.strg_loc_cd# | E23: RI | G23: Storage location cd. | H23: 格納場所ＣＤ | I23: - | J23: E
A24: 10 | D24: ord.mfg_loc_cd# | E24: RI | G24: Mfg. location cd. | H24: 製造場所ＣＤ | I24: - | J24: E
A25: 10 | D25: ord.mst_mfg_loc_cd# | E25: RI | G25: Master mfg. location cd. | H25: マスタ製造場所ＣＤ | I25: - | J25: -
A26: 10 | D26: ord.sppl_cd# | E26: RI | G26: Supplier cd. | H26: 発注先ＣＤ | I26: - | J26: E
A27: 10 | D27: ord.maker_cd# | E27: RI | G27: Maker cd. | H27: メーカＣＤ | I27: - | J27: E
A28: 10 | D28: ord.rqst_loc_cd# | E28: RI | G28: Requested location cd. | H28: 依頼先場所ＣＤ | I28: - | J28: E
... A36: 10 | D36: ord.fxd_yield_qty# | E36: RI | G36: Constant yield qty. | H36: 固定歩留数量 | I36: - | J36: E
A37: 10 | D37: ord.itm_ord_sts_typ# | E37: RI | G37: Order status type | H37: オーダ状況区分 | I37: E | J37: E | K37: E | L37: MSC_ITM_ORD_STS_TYP
A38: 10 | D38: ord.po_schd_dt# | E38: RI | G38: Scheduled PO date | H38: 発注予定日 | I38: - | J38: E
A39: 10 | D39: ord.purc_lt# | E39: RI | G39: Purchase LT | H39: 購入ＬＴ | I39: - | J39: E
A40: 10 | D40: ord.mfg_st_schd_dt# | E40: RI | G40: Scheduled mfg. start date | H40: 製造着手予定日 | I40: - | J40: E
A41: 10 | D41: ord.mfg_end_schd_dt# | E41: RI | G41: Scheduled mfg. end date | H41: 製造終了予定日 | I41: - | J41: E
A42: 10 | D42: ord.mfg_lt# | E42: RI | G42: Mfg. LT | H42: 製造ＬＴ | I42: - | J42: E
A43: 10 | D43: ord.gi_schd_dt# | E43: RI | G43: Scheduled GI date | H43: 出庫予定日 | I43: - | J43: E
A44: 10 | D44: ord.strg_schd_dt# | E44: RI | G44: Scheduled storage completion date | H44: 格納完了予定日 | I44: - | J44: E
A45: 10 | D45: ord.xfr_lt# | E45: RI | G45: Movement LT | H45: 移動ＬＴ | I45: - | J45: E
A46: 10 | D46: ord.accpt_schd_dt# | E46: RI | G46: Scheduled acceptance date | H46: 検収予定日 | I46: - | J46: E
A47: 10 | D47: ord.accpt_insp_lt# | E47: RI | G47: Acceptance LT | H47: 検収ＬＴ | I47: - | J47: E
...

Sheet Ord_Upd02
A1: * | B1: * | D1: L | E1: 1
A2: * | D2: オペレーション実装仕様書 Operation Specification Implementation Sheet | E2: ModuleID : | F2: =IF(LogicCommon!C2="","",LogicCommon!C2) -> MS | G2: LogicID : | H2: =IF(LogicCommon!E2="","",LogicCommon!E2) -> MSBCL5010 | I2: Ope.ID : | J2: Ord_Upd02 | K2: Pj.ID : | L2: =IF(LogicCommon!G2="","",LogicCommon!G2) -> MC | M2: Ope.Body : | N2: "mcframe.serverMAUD.MAUDL5010.MAUDL_Operation"
A3: * | E3: SubModuleID : | F3: =IF(LogicCommon!C3="","",LogicCommon!C3) -> MSBC | G3: LogicClass : | H3: =IF(LogicCommon!E3="","",LogicCommon!E3) -> MSBCL_OrdRegService | I3: Ope.Method : | J3: Ord_Upd02 | K3: SuperClassPj.ID : | L3: =IF(LogicCommon!G3="","",LogicCommon!G3) | O3: Gene.Type : | P3: ALL
A4: * | E4: Version : | F4: 000000 | G4: LogicName : | H4: =IF(LogicCommon!E4="","",LogicCommon!E4) -> オーダ登録サービス | I4: Ope.Name : | J4: オーダ状況更新 | K4: SuperLogicID : | L4: =IF(LogicCommon!G4="","",LogicCommon!G4) -> MS.MSUDL5010 | M4: ImplOpe.ID:
A5: * | E5: ACType :
A6: * | D6: 概要 : | L6: ID | N6: ID | P6: ID
A7: # | I7: U | K7: o | M7: o | O7: o
A8: # | D8: ブロック名 Block Name | E8: 型 Type | G8: super/share | H8: 対象ブロック名 Target Block Name | K8: TargetName | M8: TargetName | O8: TargetName | S8: ブロック備考 Block Remarks
A9: # | D9: 項目名 Field Name | E9: 型 Type | F9: 桁 Digits | G9: フルネーム Full Name | H9: 日本語名 Japanese Name | I9: 上り項目 Request Message Field | J9: 下り項目 Response Message Field | Q9: 条件および編集方法 Conditions and Editing Methods | S9: 項目備考 Field Remarks
A10: # | K10: 上り項目 Request Message Field | L10: 下り項目 Response Message Field | M10: 上り項目 Request Message Field | N10: 下り項目 Response Message Field | O10: 上り項目 Request Message Field | P10: 下り項目 Response Message Field
A11: 10 | B11: * | D11: Ord_Upd02_Dtl | E11: L | G11: $share$ | H11: MS.MSBCL5010.Ord_Upd01.Ord_Upd01_Dtl1
A12: 10 | D12: peg_no | E12: #MA.INT | G12: Pegging No. | H12: 紐付けＮＯ | I12: E | J12: -
A13: 10 | D13: mrp_typ | E13: #MS.MRP_TYP | G13: MRP type | H13: ＭＲＰタイプ | I13: E | J13: -
A14: 10 | D14: data_crud_typ | E14: #MA.DATA_CRUD_TYP | G14: Data update type | H14: データ更新区分 | I14: E | J14: -
A15: 10 | D15: a_itm_ord_sts_typ | E15: #MS.ITM_ORD_STS_TYP | G15: Order status type after update | H15: 更新後オーダ状況区分 | I15: E | J15: E
A16: 10 | D16: b_itm_ord_sts_typ | E16: #MS.ITM_ORD_STS_TYP | G16: Order status type before update | H16: 更新前オーダ状況区分 | I16: E | J16: -
A17: 10 | D17: ord | E17: R | F17: DBC:MS.MST_ITM_ORDER
A18: 10 | D18: ord.itm_ord_no# | E18: RI | G18: Item order No. | H18: 品目オーダＮＯ | I18: E | J18: E
A19: 10 | D19: ord.itm_ord_typ# | E19: RI | G19: Order type | H19: オーダ区分 | I19: E | J19: -
A20: 10 | D20: ord.ord_gnrt_typ# | E20: RI | G20: Order generation type | H20: オーダ生成区分 | I20: E | J20: -
A21: 10 | D21: ord.itm_cd# | E21: RI | G21: Item cd. | H21: 品目ＣＤ | I21: E | J21: -
A22: 10 | D22: ord.itm_sub1# | E22: RI | G22: Branch No. 1 | H22: 枝番１ | I22: E | J22: -
A23: 10 | D23: ord.itm_sub2# | E23: RI | G23: Branch No. 2 | H23: 枝番２ | I23: E | J23: -
A24: 10 | D24: ord.itm_sub3# | E24: RI | G24: Branch No. 3 | H24: 枝番３ | I24: E | J24: -
A25: 10 | D25: ord.ver_no# | E25: RI | G25: Version No. | H25: 版ＮＯ | I25: E | J25: -
A26: 10 | D26: ord.strg_loc_cd# | E26: RI | G26: Storage location cd. | H26: 格納場所ＣＤ | I26: E | J26: -
A27: 10 | D27: ord.mfg_loc_cd# | E27: RI | G27: Mfg. location cd. | H27: 製造場所ＣＤ | I27: E | J27: -
A28: 10 | D28: ord.mst_mfg_loc_cd# | E28: RI | G28: Master mfg. location cd. | H28: マスタ製造場所ＣＤ | I28: E | J28: -
A29: 10 | D29: ord.sppl_cd# | E29: RI | G29: Supplier cd. | H29: 発注先ＣＤ | I29: E | J29: -
... A88: 10 | D88: ord.sub_char3# | E88: RI | G88: Spare 3 | H88: 予備３ | I88: - | J88: -
A89: 10 | D89: ord.inst_itm_ord_sts_typ# | E89: RI | G89: Item order at mfg. order status type | H89: 製造指図時品目オーダ状況区分 | I89: -
A90: 10 | D90: ord.for_scheduler_frozen_flg# | E90: RI | G90: Scheduler frozen target | H90: スケジューラ凍結対象 | I90: E
A91: 10 | D91: is_src_mfg_inst_flg | E91: #MA.FLG | G91: Caller mfg. order flg. | H91: 呼出元製造指図ＦＬＧ | I91: E
A92: 10 | D92: strg_lg_grp_cd | E92: #MA.LG_GRP_CD | G92: Storage location distribution group cd. | H92: 格納場所物流グループＣＤ | I92: E | J92: -
A93: 10 | D93: strg_sppl_cd | E93: #MA.BP_CD | G93: Storage location supplier cd. | H93: 格納場所発注先ＣＤ | I93: E | J93: -
A94: 10 | D94: rqst_to_lg_grp_cd | E94: #MA.LG_GRP_CD | G94: Requested location distribution group cd. | H94: 依頼先場所物流グループＣＤ | I94: E | J94: -
A95: 10 | D95: unit_cd | E95: #MA.UNIT_CD | G95: Base unit cd. | H95: 基準単位ＣＤ | I95: E | J95: -
A96: 10 | D96: oper_ord_pr_flg | E96: #MA.FLG | G96: Operation order generation | H96: 工程オーダ生成 | I96: - | J96: -
A97: 10 | D97: io_schd_pr_flg | E97: #MA.FLG | G97: Generate GR/GI schedule | H97: 受払予定生成 | I97: - | J97: -
A98: 10 | D98: rqst_lg_grp_cd | E98: #MA.LG_GRP_CD | G98: Requested location distribution group cd. | H98: 依頼先場所物流グループＣＤ | I98: - | J98: -
...

Sheet Ord_Upd03
A1: * | B1: * | D1: L | E1: 1
A2: * | D2: オペレーション実装仕様書 Operation Specification Implementation Sheet | E2: ModuleID : | F2: =IF(LogicCommon!C2="","",LogicCommon!C2) -> MS | G2: LogicID : | H2: =IF(LogicCommon!E2="","",LogicCommon!E2) -> MSBCL5010 | I2: Ope.ID : | J2: Ord_Upd03 | K2: Pj.ID : | L2: =IF(LogicCommon!G2="","",LogicCommon!G2) -> MC | M2: Ope.Body : | N2: "mcframe.serverMAUD.MAUDL5010.MAUDL_Operation"
A3: * | E3: SubModuleID : | F3: =IF(LogicCommon!C3="","",LogicCommon!C3) -> MSBC | G3: LogicClass : | H3: =IF(LogicCommon!E3="","",LogicCommon!E3) -> MSBCL_OrdRegService | I3: Ope.Method : | J3: Ord_Upd03 | K3: SuperClassPj.ID : | L3: =IF(LogicCommon!G3="","",LogicCommon!G3) | O3: Gene.Type : | P3: ALL
A4: * | E4: Version : | F4: 000000 | G4: LogicName : | H4: =IF(LogicCommon!E4="","",LogicCommon!E4) -> オーダ登録サービス | I4: Ope.Name : | J4: 工程オーダ更新 | K4: SuperLogicID : | L4: =IF(LogicCommon!G4="","",LogicCommon!G4) -> MS.MSUDL5010 | M4: ImplOpe.ID:
A5: * | E5: ACType :
A6: * | D6: 概要 : | L6: ID | N6: ID | P6: ID
A7: # | I7: U | K7: o | M7: o | O7: o
A8: # | D8: ブロック名 Block Name | E8: 型 Type | G8: super/share | H8: 対象ブロック名 Target Block Name | K8: TargetName | M8: TargetName | O8: TargetName | S8: ブロック備考 Block Remarks
A9: # | D9: 項目名 Field Name | E9: 型 Type | F9: 桁 Digits | G9: フルネーム Full Name | H9: 日本語名 Japanese Name | I9: 上り項目 Request Message Field | J9: 下り項目 Response Message Field | Q9: 条件および編集方法 Conditions and Editing Methods | S9: 項目備考 Field Remarks
A10: # | K10: 上り項目 Request Message Field | L10: 下り項目 Response Message Field | M10: 上り項目 Request Message Field | N10: 下り項目 Response Message Field | O10: 上り項目 Request Message Field | P10: 下り項目 Response Message Field
A11: 10 | B11: * | D11: Ord_Upd03_Dtl | E11: L
A12: 10 | D12: wk | E12: R | F12: DBC:MS.MSW_OPER_ORDER
A13: 10 | D13: wk.itm_ord_no# | E13: RI | G13: Item order No. | H13: 品目オーダＮＯ | I13: E | J13: -
A14: 10 | D14: wk.oper_cd# | E14: RI | G14: Operation cd. | H14: 工程ＣＤ | I14: E | J14: -
A15: 10 | D15: wk.oper_seq# | E15: RI | G15: Operation sequence number | H15: 工程連番 | I15: E | J15: -
A16: 10 | D16: wk.st_schd_tm# | E16: RI | G16: Scheduled operation start date and time | H16: 工程着手予定日時 | I16: E | J16: -
A17: 10 | D17: wk.end_schd_tm# | E17: RI | G17: Scheduled operation end date and time | H17: 工程終了予定日時 | I17: E | J17: -
A18: 10 | D18: wk.oper_ord_sts_typ# | E18: RI | G18: Operation order status type | H18: 工程オーダ状況区分 | I18: E | J18: -
A19: 10 | D19: wk.oper_schd_qty# | E19: RI | G19: Operation order qty. | H19: 工程指図数量 | I19: E | J19: -
D20: 詳細 :

Sheet Ord_Upd04
A1: * | B1: * | D1: L | E1: 1
A2: * | D2: オペレーション実装仕様書 Operation Specification Implementation Sheet | E2: ModuleID : | F2: =IF(LogicCommon!C2="","",LogicCommon!C2) -> MS | G2: LogicID : | H2: =IF(LogicCommon!E2="","",LogicCommon!E2) -> MSBCL5010 | I2: Ope.ID : | J2: Ord_Upd04 | K2: Pj.ID : | L2: =IF(LogicCommon!G2="","",LogicCommon!G2) -> MC | M2: Ope.Body : | N2: "mcframe.serverMAUD.MAUDL5010.MAUDL_Operation"
A3: * | E3: SubModuleID : | F3: =IF(LogicCommon!C3="","",LogicCommon!C3) -> MSBC | G3: LogicClass : | H3: =IF(LogicCommon!E3="","",LogicCommon!E3) -> MSBCL_OrdRegService | I3: Ope.Method : | J3: Ord_Upd04 | K3: SuperClassPj.ID : | L3: =IF(LogicCommon!G3="","",LogicCommon!G3) | O3: Gene.Type : | P3: ALL
A4: * | E4: Version : | F4: 000000 | G4: LogicName : | H4: =IF(LogicCommon!E4="","",LogicCommon!E4) -> オーダ登録サービス | I4: Ope.Name : | J4: 品目オーダ実績項目更新 | K4: SuperLogicID : | L4: =IF(LogicCommon!G4="","",LogicCommon!G4) -> MS.MSUDL5010 | M4: ImplOpe.ID:
A5: * | E5: ACType :
A6: * | D6: 概要 : | L6: ID | N6: ID | P6: ID
A7: # | I7: U | K7: o | M7: o | O7: o
A8: # | D8: ブロック名 Block Name | E8: 型 Type | G8: super/share | H8: 対象ブロック名 Target Block Name | K8: TargetName | M8: TargetName | O8: TargetName | S8: ブロック備考 Block Remarks
A9: # | D9: 項目名 Field Name | E9: 型 Type | F9: 桁 Digits | G9: フルネーム Full Name | H9: 日本語名 Japanese Name | I9: 上り項目 Request Message Field | J9: 下り項目 Response Message Field | Q9: 条件および編集方法 Conditions and Editing Methods | S9: 項目備考 Field Remarks
A10: # | K10: 上り項目 Request Message Field | L10: 下り項目 Response Message Field | M10: 上り項目 Request Message Field | N10: 下り項目 Response Message Field | O10: 上り項目 Request Message Field | P10: 下り項目 Response Message Field
A11: 10 | B11: * | D11: Ord_Upd04_Dtl | E11: L
A12: 10 | D12: itm_ord_no | E12: #MA.ITM_ORD_NO | G12: Item order No. | H12: 品目オーダＮＯ | I12: E | J12: -
A13: 10 | D13: itm_ord_typ | E13: #MS.ITM_ORD_TYP | G13: Order type | H13: オーダ区分 | I13: E | J13: -
A14: 10 | D14: abort_flg | E14: #MA.FLG | G14: Cancel remaining flg. | H14: 打切ＦＬＧ | I14: E | J14: -
D15: 詳細 :

Sheet Ord_Upd05
A1: * | B1: * | D1: L | E1: 1
A2: * | D2: オペレーション実装仕様書 Operation Specification Implementation Sheet | E2: ModuleID : | F2: =IF(LogicCommon!C2="","",LogicCommon!C2) -> MS | G2: LogicID : | H2: =IF(LogicCommon!E2="","",LogicCommon!E2) -> MSBCL5010 | I2: Ope.ID : | J2: Ord_Upd05 | K2: Pj.ID : | L2: =IF(LogicCommon!G2="","",LogicCommon!G2) -> MC | M2: Ope.Body : | N2: "mcframe.serverMAUD.MAUDL5010.MAUDL_Operation"
A3: * | E3: SubModuleID : | F3: =IF(LogicCommon!C3="","",LogicCommon!C3) -> MSBC | G3: LogicClass : | H3: =IF(LogicCommon!E3="","",LogicCommon!E3) -> MSBCL_OrdRegService | I3: Ope.Method : | J3: Ord_Upd05 | K3: SuperClassPj.ID : | L3: =IF(LogicCommon!G3="","",LogicCommon!G3) | O3: Gene.Type : | P3: ALL
A4: * | E4: Version : | F4: 000000 | G4: LogicName : | H4: =IF(LogicCommon!E4="","",LogicCommon!E4) -> オーダ登録サービス | I4: Ope.Name : | J4: 工程オーダ実績項目更新 | K4: SuperLogicID : | L4: =IF(LogicCommon!G4="","",LogicCommon!G4) -> MS.MSUDL5010 | M4: ImplOpe.ID:
A5: * | E5: ACType :
A6: * | D6: 概要 : | L6: ID | N6: ID | P6: ID
A7: # | I7: U | K7: o | M7: o | O7: o
A8: # | D8: ブロック名 Block Name | E8: 型 Type | G8: super/share | H8: 対象ブロック名 Target Block Name | K8: TargetName | M8: TargetName | O8: TargetName | S8: ブロック備考 Block Remarks
A9: # | D9: 項目名 Field Name | E9: 型 Type | F9: 桁 Digits | G9: フルネーム Full Name | H9: 日本語名 Japanese Name | I9: 上り項目 Request Message Field | J9: 下り項目 Response Message Field | Q9: 条件および編集方法 Conditions and Editing Methods | S9: 項目備考 Field Remarks
A10: # | K10: 上り項目 Request Message Field | L10: 下り項目 Response Message Field | M10: 上り項目 Request Message Field | N10: 下り項目 Response Message Field | O10: 上り項目 Request Message Field | P10: 下り項目 Response Message Field
A11: 10 | B11: * | D11: Ord_Upd05_Dtl | E11: L
A12: 10 | D12: itm_ord_no | E12: #MA.ITM_ORD_NO | G12: Item order No. | H12: 品目オーダＮＯ | I12: E | J12: -
D13: 詳細 :

Sheet Ord_Imp01
A1: * | B1: * | D1: L | E1: 1
A2: * | D2: オペレーション実装仕様書 Operation Specification Implementation Sheet | E2: ModuleID : | F2: =IF(LogicCommon!C2="","",LogicCommon!C2) -> MS | G2: LogicID : | H2: =IF(LogicCommon!E2="","",LogicCommon!E2) -> MSBCL5010 | I2: Ope.ID : | J2: Ord_Imp01 | K2: Pj.ID : | L2: =IF(LogicCommon!G2="","",LogicCommon!G2) -> MC | M2: Ope.Body : | N2: "mcframe.serverMAUD.MAUDL5010.MAUDL_Operation"
A3: * | E3: SubModuleID : | F3: =IF(LogicCommon!C3="","",LogicCommon!C3) -> MSBC | G3: LogicClass : | H3: =IF(LogicCommon!E3="","",LogicCommon!E3) -> MSBCL_OrdRegService | I3: Ope.Method : | J3: Ord_Imp01 | K3: SuperClassPj.ID : | L3: =IF(LogicCommon!G3="","",LogicCommon!G3) | O3: Gene.Type : | P3: ALL
A4: * | E4: Version : | F4: 000000 | G4: LogicName : | H4: =IF(LogicCommon!E4="","",LogicCommon!E4) -> オーダ登録サービス | I4: Ope.Name : | J4: オーダ取込 | K4: SuperLogicID : | L4: =IF(LogicCommon!G4="","",LogicCommon!G4) -> MS.MSUDL5010 | M4: ImplOpe.ID:
A5: * | E5: ACType :
A6: * | D6: 概要 : | L6: ID | N6: ID | P6: ID
A7: # | I7: U | K7: o | M7: o | O7: o
A8: # | D8: ブロック名 Block Name | E8: 型 Type | G8: super/share | H8: 対象ブロック名 Target Block Name | K8: TargetName | M8: TargetName | O8: TargetName | S8: ブロック備考 Block Remarks
A9: # | D9: 項目名 Field Name | E9: 型 Type | F9: 桁 Digits | G9: フルネーム Full Name | H9: 日本語名 Japanese Name | I9: 上り項目 Request Message Field | J9: 下り項目 Response Message Field | Q9: 条件および編集方法 Conditions and Editing Methods | S9: 項目備考 Field Remarks
A10: # | K10: 上り項目 Request Message Field | L10: 下り項目 Response Message Field | M10: 上り項目 Request Message Field | N10: 下り項目 Response Message Field | O10: 上り項目 Request Message Field | P10: 下り項目 Response Message Field
A11: 10 | B11: * | D11: Ord_Imp01_Dtl | E11: L
A12: 10 | D12: peg_no | E12: #MA.INT | G12: Pegging No. | H12: 紐付けＮＯ | I12: E | J12: E
A13: 10 | D13: data_crud_typ | E13: #MA.DATA_CRUD_TYP | G13: Data update type | H13: データ更新区分 | I13: E | J13: -
A14: 10 | D14: err_flg | E14: #MA.FLG | G14: Error | H14: エラー | I14: - | J14: E
A15: 10 | D15: mrp_typ | E15: #MS.MRP_TYP | G15: MRP type | H15: ＭＲＰタイプ | I15: E | J15: E
A16: 10 | D16: itm_ord_no | E16: #MA.ITM_ORD_NO | G16: Item order No. | H16: 品目オーダＮＯ | I16: - | J16: -
A17: 10 | D17: itm_ord_typ | E17: #MS.ITM_ORD_TYP | G17: Order type | H17: オーダ区分 | I17: E | J17: E
A18: 10 | D18: ord_gnrt_typ | E18: #MS.ORD_GNRT_TYP | G18: Order generation type | H18: オーダ生成区分 | I18: E | J18: E
A19: 10 | D19: itm_cd | E19: #MA.ITM_CD | G19: Item cd. | H19: 品目ＣＤ | I19: E | J19: E
A20: 10 | D20: itm_sub1 | E20: #MA.ITM_SUB1 | G20: Branch No. 1 | H20: 枝番１ | I20: E | J20: E
A21: 10 | D21: itm_sub2 | E21: #MA.ITM_SUB2 | G21: Branch No. 2 | H21: 枝番２ | I21: E | J21: E
A22: 10 | D22: itm_sub3 | E22: #MA.ITM_SUB3 | G22: Branch No. 3 | H22: 枝番３ | I22: E | J22: E
A23: 10 | D23: ver_no | E23: #MA.VER_NO | G23: Version No. | H23: 版ＮＯ | I23: E | J23: E
... A110: 10 | D110: itm_typ_d_nm | E110: #MA.ITM_TYP_D_NM | G110: Item type details name | H110: 品目区分詳細名 | I110: - | J110: E
D111: 詳細 :

Sheet Ord_Imp02
A1: * | B1: * | D1: L | E1: 1
A2: * | D2: オペレーション実装仕様書 Operation Specification Implementation Sheet | E2: ModuleID : | F2: =IF(LogicCommon!C2="","",LogicCommon!C2) -> MS | G2: LogicID : | H2: =IF(LogicCommon!E2="","",LogicCommon!E2) -> MSBCL5010 | I2: Ope.ID : | J2: Ord_Imp02 | K2: Pj.ID : | L2: =IF(LogicCommon!G2="","",LogicCommon!G2) -> MC | M2: Ope.Body : | N2: "mcframe.serverMAUD.MAUDL5010.MAUDL_Operation"
A3: * | E3: SubModuleID : | F3: =IF(LogicCommon!C3="","",LogicCommon!C3) -> MSBC | G3: LogicClass : | H3: =IF(LogicCommon!E3="","",LogicCommon!E3) -> MSBCL_OrdRegService | I3: Ope.Method : | J3: Ord_Imp02 | K3: SuperClassPj.ID : | L3: =IF(LogicCommon!G3="","",LogicCommon!G3) | O3: Gene.Type : | P3: ALL
A4: * | E4: Version : | F4: 000000 | G4: LogicName : | H4: =IF(LogicCommon!E4="","",LogicCommon!E4) -> オーダ登録サービス | I4: Ope.Name : | J4: 工程オーダ取込 | K4: SuperLogicID : | L4: =IF(LogicCommon!G4="","",LogicCommon!G4) -> MS.MSUDL5010 | M4: ImplOpe.ID:
A5: * | E5: ACType :
A6: * | D6: 概要 : | L6: ID | N6: ID | P6: ID
A7: # | I7: U | K7: o | M7: o | O7: o
A8: # | D8: ブロック名 Block Name | E8: 型 Type | G8: super/share | H8: 対象ブロック名 Target Block Name | K8: TargetName | M8: TargetName | O8: TargetName | S8: ブロック備考 Block Remarks
A9: # | D9: 項目名 Field Name | E9: 型 Type | F9: 桁 Digits | G9: フルネーム Full Name | H9: 日本語名 Japanese Name | I9: 上り項目 Request Message Field | J9: 下り項目 Response Message Field | Q9: 条件および編集方法 Conditions and Editing Methods | S9: 項目備考 Field Remarks
A10: # | K10: 上り項目 Request Message Field | L10: 下り項目 Response Message Field | M10: 上り項目 Request Message Field | N10: 下り項目 Response Message Field | O10: 上り項目 Request Message Field | P10: 下り項目 Response Message Field
A11: 10 | B11: * | D11: Ord_Imp02_Dtl | E11: L
A12: 10 | D12: peg_no | E12: #MA.INT | G12: Pegging No. | H12: 紐付けＮＯ | I12: E | J12: E
A13: 10 | D13: data_crud_typ | E13: #MA.DATA_CRUD_TYP | G13: Data update type | H13: データ更新区分 | I13: E | J13: E
A14: 10 | D14: err_flg | E14: #MA.FLG | G14: Error | H14: エラー | I14: - | J14: E
A15: 10 | D15: mrp_typ | E15: #MS.MRP_TYP | G15: MRP type | H15: ＭＲＰタイプ | I15: E | J15: E
A16: 10 | D16: itm_ord_no | E16: #MA.ITM_ORD_NO | G16: Item order No. | H16: 品目オーダＮＯ | I16: E | J16: E
A17: 10 | D17: itm_ord_typ | E17: #MS.ITM_ORD_TYP | G17: Order type | H17: オーダ区分 | I17: - | J17: E
A18: 10 | D18: ord_gnrt_typ | E18: #MS.ORD_GNRT_TYP | G18: Order generation type | H18: オーダ生成区分 | I18: - | J18: E
A19: 10 | D19: itm_cd | E19: #MA.ITM_CD | G19: Item cd. | H19: 品目ＣＤ | I19: E | J19: E
A20: 10 | D20: itm_sub1 | E20: #MA.ITM_SUB1 | G20: Branch No. 1 | H20: 枝番１ | I20: E | J20: E
A21: 10 | D21: itm_sub2 | E21: #MA.ITM_SUB2 | G21: Branch No. 2 | H21: 枝番２ | I21: E | J21: E
A22: 10 | D22: itm_sub3 | E22: #MA.ITM_SUB3 | G22: Branch No. 3 | H22: 枝番３ | I22: E | J22: E
A23: 10 | D23: ver_no | E23: #MA.VER_NO | G23: Version No. | H23: 版ＮＯ | I23: - | J23: E
... A106: 10 | D106: itm_typ_d_nm | E106: #MA.ITM_TYP_D_NM | G106: Item type details name | H106: 品目区分詳細名 | I106: - | J106: E
A107: 10 | D107: itm_order_upd_cntr | E107: #MA.UPD_CNT | I107: - | J107: E
A108: 10 | D108: oord | E108: R | F108: DBC:MS.MST_OPER_ORDER
A109: 10 | D109: oord.oper_ord_no# | E109: RI | G109: Operation order No. | H109: 工程オーダＮＯ | I109: - | J109: -
A110: 10 | D110: oord.oper_ord_sts_typ# | E110: RI | G110: Operation order status type | H110: 工程オーダ状況区分 | I110: E | J110: E
A111: 10 | D111: oord.oper_cd# | E111: RI | G111: Operation cd. | H111: 工程ＣＤ | I111: E | J111: E
A112: 10 | D112: oord.oper_seq# | E112: RI | G112: Operation sequence number | H112: 工程連番 | I112: E | J112: E
A113: 10 | D113: oord.loc_cd# | E113: RI | G113: Location cd. | H113: 場所ＣＤ | I113: E | J113: E
A114: 10 | D114: oord.disp_seq# | E114: RI | G114: Routing | H114: 工順 | I114: - | J114: -
A115: 10 | D115: oord.oper_schd_qty# | E115: RI | G115: Operation order scheduled qty. | H115: 工程指図予定数量 | I115: E | J115: E
A116: 10 | D116: oord.yield_oper_flg# | E116: RI | G116: Output recording operation | H116: 出来高計上工程 | I116: - | J116: -
A117: 10 | D117: oord.st_schd_tm# | E117: RI | G117: Scheduled operation start date and time | H117: 工程着手予定日時 | I117: E | J117: E
A118: 10 | D118: oord.inst_st_schd_tm# | E118: RI | G118: Scheduled operation start date and time (Order) | H118: 工程着手予定日時（指図） | I118: - | J118: -
A119: 10 | D119: oord.act_st_tm# | E119: RI | G119: Actual earliest operation start date and time | H119: 最早工程着手実績日時 | I119: - | J119: -
A120: 10 | D120: oord.end_schd_tm# | E120: RI | G120: Scheduled operation end date and time | H120: 工程終了予定日時 | I120: E | J120: E
... A130: 10 | D130: oord.sub_char3# | E130: RI | G130: Spare 3 | H130: 予備３ | I130: E | J130: E
D131: 詳細 :

Sheet 来歴
A1: 変更来歴
A3: Rev. | H3: 修正番号 | O3: 変更内容 | AQ3: 変更箇所
A4: 1 | O4: 初版
A5: 1.1 | H5: MS7031#405 | O5: Ord_Upd01_Dtl2ブロックに以下を追加 ・oord.scheduler_frozen_flg# Ord_Upd01_Dtl1ブロックに以下を追加 ・ord.for_scheduler_frozen_flg# | AQ5: Ord_Upd01
A6: 〃 | H6: 〃 | O6: Ord_Upd02_Dtlブロックに以下を追加 ・ord.for_scheduler_frozen_flg# | AQ6: Ord_Upd02
A7: 〃 | H7: 〃 | O7: Ord_Chk02_Dtlブロックに以下を追加 ・ord.for_scheduler_frozen_flg# | AQ7: Ord_Chk02
A8: 1.2 | O8: 英語の名称を追記 | AQ8: 全般
