Workbook

Sheet LogicCommon
A2: オペレーション実装仕様書 | B2: ModuleID : | C2: MB | D2: LogicID : | E2: MBBCL5020 | F2: Pj.ID : | G2: MC
B3: SubModuleID : | C3: MBBC | D3: LogicClass : | E3: MBBCL_AttachService | F3: SuperClassPj.ID :
D4: LogicName : | E4: 添付帳票登録サービス | F4: SuperLogicID : | G4: MB.MBUDL5010
A5: 概要 :
A6: 詳細 :

Sheet Attach_Chk01
A1: * | B1: * | D1: L | E1: 1
A2: * | D2: オペレーション実装仕様書 Operation Specification Implementation Sheet | E2: ModuleID : | F2: =IF(LogicCommon!C2="","",LogicCommon!C2) -> MB | G2: LogicID : | H2: =IF(LogicCommon!E2="","",LogicCommon!E2) -> MBBCL5020 | I2: Ope.ID : | J2: Attach_Chk01 | K2: Pj.ID : | L2: =IF(LogicCommon!G2="","",LogicCommon!G2) -> MC | M2: Ope.Body : | N2: MA.MAUDL5010.Checker
A3: * | D3: =IF(LogicCommon!A3="","",LogicCommon!A3) | E3: SubModuleID : | F3: =IF(LogicCommon!C3="","",LogicCommon!C3) -> MBBC | G3: LogicClass : | H3: =IF(LogicCommon!E3="","",LogicCommon!E3) -> MBBCL_AttachService | I3: Ope.Method : | J3: @ | K3: SuperClassPj.ID : | L3: =IF(LogicCommon!G3="","",LogicCommon!G3) | O3: Gene.Type : | P3: ALL
A4: * | E4: Version : | F4: 000000 | G4: LogicName : | H4: =IF(LogicCommon!E4="","",LogicCommon!E4) -> 添付帳票登録サービス | I4: Ope.Name : | J4: 登録・更新前チェック | K4: SuperLogicID : | L4: =IF(LogicCommon!G4="","",LogicCommon!G4) -> MB.MBUDL5010 | M4: ImplOpe.ID:
A5: * | E5: ACType :
A6: * | D6: 概要 : | E6: 添付ファイル情報登録・更新前チェック | AD6: ID | AF6: ID | AH6: ID
A7: # | I7: U | K7: K | L7: K | M7: K | N7: K | O7: K | P7: K | Q7: K | R7: K | S7: K | T7: K | U7: K | V7: K | W7: K | X7: K | Y7: K | Z7: K | AA7: K | AB7: K | AC7: o | AE7: o | AG7: o
A8: # | D8: ブロック名 Block Name | E8: 型 Type | G8: super/share | H8: 対象ブロック名 Target Block Name | K8: REQ_UPD_CNT_CHK | L8: REQUIRED | M8: CHK_NUM | N8: SMALL_LARGE | O8: CHK_DT | P8: BEFORE_AFTER | Q8: CHK_PTN | R8: DUPLICATE | S8: TOO_MANY_INPUTS | T8: AT_LEAST_ONE | U8: ONLY_ONE_INPUT | V8: LIST_LOGIC | W8: LIST_OUT | X8: LIST_OUT_BASE | Y8: LIST_IN | Z8: LIST_IN_BASE | AA8: CONST | AB8: NULL_VAL | AC8: TargetName | AE8: TargetName | AG8: TargetName | AK8: ブロック備考 Block Remarks
A9: # | D9: 項目名 Field Name | E9: 型 Type | F9: 桁 Digits | G9: フルネーム Full Name | H9: 日本語名 Japanese Name | I9: 上り項目 Request Message Field | J9: 下り項目 Response Message Field | AI9: 条件および編集方法 Conditions and Editing Methods | AK9: 項目備考 Field Remarks
A10: # | AC10: 上り項目 Request Message Field | AD10: 下り項目 Response Message Field | AE10: 上り項目 Request Message Field | AF10: 下り項目 Response Message Field | AG10: 上り項目 Request Message Field | AH10: 下り項目 Response Message Field
A11: 10 | B11: * | D11: Attach_Chk01_Dtl | E11: L
A12: 10 | D12: data_no | E12: #MA.IT_DAT_NO | G12: Report management No. | H12: 帳票管理ＮＯ | I12: E | J12: E
A13: 10 | D13: edition | E13: #MA.SLIP_REV | G13: Version | H13: 版 | I13: E | J13: E
A14: 10 | D14: biz_typ | E14: #MA.BIZ_TYP | G14: Business type | H14: 業務区分 | I14: E | J14: E | L14: E | AA14: MAC_BIZ_TYP
A15: 10 | D15: biz_key1 | E15: #MA.BIZ_KEY | G15: Business key 1 | H15: 業務キー１ | I15: E | J15: E | L15: E
A16: 10 | D16: biz_key2 | E16: #MA.BIZ_KEY | G16: Business key 2 | H16: 業務キー２ | I16: E | J16: E
A17: 10 | D17: biz_key3 | E17: #MA.BIZ_KEY | G17: Business key 3 | H17: 業務キー３ | I17: E | J17: E
A18: 10 | D18: biz_key4 | E18: #MA.BIZ_KEY | G18: Business key 4 | H18: 業務キー４ | I18: E | J18: E
A19: 10 | D19: biz_key5 | E19: #MA.BIZ_KEY | G19: Business key 5 | H19: 業務キー５ | I19: E | J19: E
A20: 10 | D20: biz_key6 | E20: #MA.BIZ_KEY | G20: Business key 6 | H20: 業務キー６ | I20: E | J20: E
A21: 10 | D21: biz_key7 | E21: #MA.BIZ_KEY | G21: Business key 7 | H21: 業務キー７ | I21: E | J21: E
A22: 10 | D22: biz_key8 | E22: #MA.BIZ_KEY | G22: Business key 8 | H22: 業務キー８ | I22: E | J22: E
A23: 10 | D23: biz_key9 | E23: #MA.BIZ_KEY | G23: Business key 9 | H23: 業務キー９ | I23: E | J23: E
A24: 10 | D24: biz_key10 | E24: #MA.BIZ_KEY | G24: Business key 10 | H24: 業務キー１０ | I24: E | J24: E
A25: 10 | D25: report_id | E25: #MA.REPORT_ID | G25: Report ID | H25: 帳票ＩＤ | I25: E | J25: E
A26: 10 | D26: dt | E26: #MA.DT | G26: Transaction date | H26: 取引年月日 | I26: E | J26: E | L26: E
A27: 10 | D27: bp_cd | E27: #MA.BP_CD | G27: BP cd. | H27: 取引先ＣＤ | I27: E | J27: E | V27: MA.MAUAL0010.Bp
A28: 10 | D28: cur_cd | E28: #MA.CUR_CD | G28: Transaction currency cd. | H28: 取引通貨ＣＤ | I28: E | J28: E | V28: MA.MAUAL0010.Cur
A29: 10 | D29: amt | E29: #MA.MONEY | G29: Transaction amount | H29: 取引金額 | I29: E | J29: E
A30: 10 | D30: rmrks1 | E30: #MA.ATTACHMENT_RMRKS | G30: Remarks 1 | H30: 備考１ | I30: E | J30: E
A31: 10 | D31: rmrks2 | E31: #MA.ATTACHMENT_RMRKS | G31: Remarks 2 | H31: 備考２ | I31: E | J31: E
A32: 10 | D32: rmrks3 | E32: #MA.ATTACHMENT_RMRKS | G32: Remarks 3 | H32: 備考３ | I32: E | J32: E
A33: 10 | D33: rmrks4 | E33: #MA.ATTACHMENT_RMRKS | G33: Remarks 4 | H33: 備考４ | I33: E | J33: E
A34: 10 | D34: rmrks5 | E34: #MA.ATTACHMENT_RMRKS | G34: Remarks 5 | H34: 備考５ | I34: E | J34: E
A35: 10 | D35: file_bin | E35: #MA.BIN | G35: Attachment source file | H35: 添付元ファイル | I35: E | J35: E
A36: 10 | D36: doc_id | E36: #MA.DOC_ID | G36: Document ID | H36: ドキュメントID | I36: E | J36: E
A37: 10 | D37: file_path | E37: #MA.FILE_PATH | G37: Storage location file path | H37: 保存先ファイルパス | I37: E | J37: E | R37: E
A38: 10 | D38: file_nm | E38: #MA.FILE_NM | G38: Storage location file name | H38: 保存先ファイル名 | I38: E | J38: E | R38: E
A39: 10 | D39: wg_cd | E39: #MA.DPT_CD | G39: WG cd. | H39: ワーキンググループＣＤ | I39: E | J39: E
A40: 10 | D40: sls_dpt_cd | E40: #MA.DPT_CD | G40: Sales dept. cd. | H40: 売上部門ＣＤ | I40: E | J40: E
...

Sheet Attach_Chk02
A1: * | B1: * | D1: L | E1: 1
A2: * | D2: オペレーション実装仕様書 Operation Specification Implementation Sheet | E2: ModuleID : | F2: =IF(LogicCommon!C2="","",LogicCommon!C2) -> MB | G2: LogicID : | H2: =IF(LogicCommon!E2="","",LogicCommon!E2) -> MBBCL5020 | I2: Ope.ID : | J2: Attach_Chk02 | K2: Pj.ID : | L2: =IF(LogicCommon!G2="","",LogicCommon!G2) -> MC | M2: Ope.Body : | N2: MA.MAUDL5010.Checker
A3: * | D3: =IF(LogicCommon!A3="","",LogicCommon!A3) | E3: SubModuleID : | F3: =IF(LogicCommon!C3="","",LogicCommon!C3) -> MBBC | G3: LogicClass : | H3: =IF(LogicCommon!E3="","",LogicCommon!E3) -> MBBCL_AttachService | I3: Ope.Method : | J3: @ | K3: SuperClassPj.ID : | L3: =IF(LogicCommon!G3="","",LogicCommon!G3) | O3: Gene.Type : | P3: ALL
A4: * | E4: Version : | F4: 000000 | G4: LogicName : | H4: =IF(LogicCommon!E4="","",LogicCommon!E4) -> 添付帳票登録サービス | I4: Ope.Name : | J4: 削除前チェック | K4: SuperLogicID : | L4: =IF(LogicCommon!G4="","",LogicCommon!G4) -> MB.MBUDL5010 | M4: ImplOpe.ID:
A5: * | E5: ACType :
A6: * | D6: 概要 : | E6: 添付ファイル情報削除前チェック | AD6: ID | AF6: ID | AH6: ID
A7: # | I7: U | K7: K | L7: K | M7: K | N7: K | O7: K | P7: K | Q7: K | R7: K | S7: K | T7: K | U7: K | V7: K | W7: K | X7: K | Y7: K | Z7: K | AA7: K | AB7: K | AC7: o | AE7: o | AG7: o
A8: # | D8: ブロック名 Block Name | E8: 型 Type | G8: super/share | H8: 対象ブロック名 Target Block Name | K8: REQ_UPD_CNT_CHK | L8: REQUIRED | M8: CHK_NUM | N8: SMALL_LARGE | O8: CHK_DT | P8: BEFORE_AFTER | Q8: CHK_PTN | R8: DUPLICATE | S8: TOO_MANY_INPUTS | T8: AT_LEAST_ONE | U8: ONLY_ONE_INPUT | V8: LIST_LOGIC | W8: LIST_OUT | X8: LIST_OUT_BASE | Y8: LIST_IN | Z8: LIST_IN_BASE | AA8: CONST | AB8: NULL_VAL | AC8: TargetName | AE8: TargetName | AG8: TargetName | AK8: ブロック備考 Block Remarks
A9: # | D9: 項目名 Field Name | E9: 型 Type | F9: 桁 Digits | G9: フルネーム Full Name | H9: 日本語名 Japanese Name | I9: 上り項目 Request Message Field | J9: 下り項目 Response Message Field | AI9: 条件および編集方法 Conditions and Editing Methods | AK9: 項目備考 Field Remarks
A10: # | AC10: 上り項目 Request Message Field | AD10: 下り項目 Response Message Field | AE10: 上り項目 Request Message Field | AF10: 下り項目 Response Message Field | AG10: 上り項目 Request Message Field | AH10: 下り項目 Response Message Field
A11: 10 | B11: * | D11: Attach_Chk02_Dtl | E11: L
A12: 10 | D12: biz_typ | E12: #MA.BIZ_TYP | G12: Business type | H12: 業務区分 | I12: E | J12: E | L12: E | AA12: MAC_BIZ_TYP
A13: 10 | D13: biz_key1 | E13: #MA.BIZ_KEY | G13: Business key 1 | H13: 業務キー１ | I13: E | J13: E | L13: E
A14: 10 | D14: biz_key2 | E14: #MA.BIZ_KEY | G14: Business key 2 | H14: 業務キー２ | I14: E | J14: E
A15: 10 | D15: biz_key3 | E15: #MA.BIZ_KEY | G15: Business key 3 | H15: 業務キー３ | I15: E | J15: E
A16: 10 | D16: biz_key4 | E16: #MA.BIZ_KEY | G16: Business key 4 | H16: 業務キー４ | I16: E | J16: E
A17: 10 | D17: biz_key5 | E17: #MA.BIZ_KEY | G17: Business key 5 | H17: 業務キー５ | I17: E | J17: E
A18: 10 | D18: biz_key6 | E18: #MA.BIZ_KEY | G18: Business key 6 | H18: 業務キー６ | I18: E | J18: E
A19: 10 | D19: biz_key7 | E19: #MA.BIZ_KEY | G19: Business key 7 | H19: 業務キー７ | I19: E | J19: E
A20: 10 | D20: biz_key8 | E20: #MA.BIZ_KEY | G20: Business key 8 | H20: 業務キー８ | I20: E | J20: E
A21: 10 | D21: biz_key9 | E21: #MA.BIZ_KEY | G21: Business key 9 | H21: 業務キー９ | I21: E | J21: E
A22: 10 | D22: biz_key10 | E22: #MA.BIZ_KEY | G22: Business key 10 | H22: 業務キー１０ | I22: E | J22: E
A23: 10 | D23: report_id | E23: #MA.REPORT_ID | G23: Report ID | H23: 帳票ＩＤ | I23: E | J23: E
A24: 10 | D24: err_flg | E24: #MA.FLG | G24: Error flg. | H24: エラーＦＬＧ | I24: - | J24: -
D25: 詳細 :

Sheet Attach_Upd01
A1: * | B1: * | D1: L | E1: 1
A2: * | D2: オペレーション実装仕様書 Operation Specification Implementation Sheet | E2: ModuleID : | F2: =IF(LogicCommon!C2="","",LogicCommon!C2) -> MB | G2: LogicID : | H2: =IF(LogicCommon!E2="","",LogicCommon!E2) -> MBBCL5020 | I2: Ope.ID : | J2: Attach_Upd01 | K2: Pj.ID : | L2: =IF(LogicCommon!G2="","",LogicCommon!G2) -> MC | M2: Ope.Body : | N2: "mcframe.serverMAUD.MAUDL5010.MAUDL_Operation"
A3: * | D3: =IF(LogicCommon!A3="","",LogicCommon!A3) | E3: SubModuleID : | F3: =IF(LogicCommon!C3="","",LogicCommon!C3) -> MBBC | G3: LogicClass : | H3: =IF(LogicCommon!E3="","",LogicCommon!E3) -> MBBCL_AttachService | I3: Ope.Method : | J3: @ | K3: SuperClassPj.ID : | L3: =IF(LogicCommon!G3="","",LogicCommon!G3) | O3: Gene.Type : | P3: ALL
A4: * | E4: Version : | F4: 000000 | G4: LogicName : | H4: =IF(LogicCommon!E4="","",LogicCommon!E4) -> 添付帳票登録サービス | I4: Ope.Name : | J4: 登録・更新 | K4: SuperLogicID : | L4: =IF(LogicCommon!G4="","",LogicCommon!G4) -> MB.MBUDL5010 | M4: ImplOpe.ID:
A5: * | E5: ACType :
A6: * | D6: 概要 : | E6: 添付ファイル情報を登録・更新する | M6: ID | O6: ID | Q6: ID
A7: # | I7: U | K7: K | L7: o | N7: o | P7: o
A8: # | D8: ブロック名 Block Name | E8: 型 Type | G8: super/share | H8: 対象ブロック名 Target Block Name | L8: TargetName | N8: TargetName | P8: TargetName | T8: ブロック備考 Block Remarks
A9: # | D9: 項目名 Field Name | E9: 型 Type | F9: 桁 Digits | G9: フルネーム Full Name | H9: 日本語名 Japanese Name | I9: 上り項目 Request Message Field | J9: 下り項目 Response Message Field | R9: 条件および編集方法 Conditions and Editing Methods | T9: 項目備考 Field Remarks
A10: # | L10: 上り項目 Request Message Field | M10: 下り項目 Response Message Field | N10: 上り項目 Request Message Field | O10: 下り項目 Response Message Field | P10: 上り項目 Request Message Field | Q10: 下り項目 Response Message Field
A11: 10 | B11: * | D11: Attach_Upd01_Dtl | E11: L | G11: $share$ | H11: MB.MBBCL5020.Attach_Chk01.Attach_Chk01_Dtl
A12: 10 | D12: data_no | E12: #MA.IT_DAT_NO | G12: Report management No. | H12: 帳票管理ＮＯ | I12: E | J12: -
A13: 10 | D13: edition | E13: #MA.SLIP_REV | G13: Version | H13: 版 | I13: E | J13: -
A14: 10 | D14: biz_typ | E14: #MA.BIZ_TYP | G14: Business type | H14: 業務区分 | I14: E | J14: -
A15: 10 | D15: biz_key1 | E15: #MA.BIZ_KEY | G15: Business key 1 | H15: 業務キー１ | I15: E | J15: -
A16: 10 | D16: biz_key2 | E16: #MA.BIZ_KEY | G16: Business key 2 | H16: 業務キー２ | I16: E | J16: -
A17: 10 | D17: biz_key3 | E17: #MA.BIZ_KEY | G17: Business key 3 | H17: 業務キー３ | I17: E | J17: -
A18: 10 | D18: biz_key4 | E18: #MA.BIZ_KEY | G18: Business key 4 | H18: 業務キー４ | I18: E | J18: -
A19: 10 | D19: biz_key5 | E19: #MA.BIZ_KEY | G19: Business key 5 | H19: 業務キー５ | I19: E | J19: -
A20: 10 | D20: biz_key6 | E20: #MA.BIZ_KEY | G20: Business key 6 | H20: 業務キー６ | I20: E | J20: -
A21: 10 | D21: biz_key7 | E21: #MA.BIZ_KEY | G21: Business key 7 | H21: 業務キー７ | I21: E | J21: -
A22: 10 | D22: biz_key8 | E22: #MA.BIZ_KEY | G22: Business key 8 | H22: 業務キー８ | I22: E | J22: -
A23: 10 | D23: biz_key9 | E23: #MA.BIZ_KEY | G23: Business key 9 | H23: 業務キー９ | I23: E | J23: -
... A73: 10 | D73: rtn_sts_typ | E73: #MA.RTN_STS_TYP | G73: Process result status type | H73: 処理結果状況区分 | I73: - | J73: E
L74: 上り項目 Request Message Field | M74: 下り項目 Response Message Field | N74: 上り項目 Request Message Field | O74: 下り項目 Response Message Field | P74: 上り項目 Request Message Field | Q74: 下り項目 Response Message Field
A75: 20 | B75: * | D75: Attach_Upd01_Hdr | E75: R | G75: $share$ | H75: MB.MBBCL5020.Attach_Chk01.Attach_Chk01_Hdr
A76: 20 | D76: upd_cntr_chk_flg | E76: #MA.FLG | G76: Check for update counter flg. | H76: 更新カウンタチェックＦＬＧ | I76: E | J76: -
A77: 20 | D77: del_flg | E77: #MA.FLG | G77: Cancel slip flg. | H77: 取消伝票ＦＬＧ | I77: E | J77: -
L78: 上り項目 Request Message Field | M78: 下り項目 Response Message Field | N78: 上り項目 Request Message Field | O78: 下り項目 Response Message Field | P78: 上り項目 Request Message Field | Q78: 下り項目 Response Message Field
A79: 30 | B79: * | D79: Attach_Upd01_Dtl2 | E79: L
A80: 30 | D80: biz_typ | E80: #MA.BIZ_TYP | G80: Business type | H80: 業務区分 | I80: E | J80: -
A81: 30 | D81: report_id | E81: #MA.REPORT_ID | G81: Report ID | H81: 帳票ＩＤ | I81: E | J81: -
A82: 30 | D82: biz_key1 | E82: #MA.BIZ_KEY | G82: Business key 1 | H82: 業務キー１ | I82: E | J82: -
A83: 30 | D83: biz_key2 | E83: #MA.BIZ_KEY | G83: Business key 2 | H83: 業務キー２ | I83: E | J83: -
A84: 30 | D84: biz_key3 | E84: #MA.BIZ_KEY | G84: Business key 3 | H84: 業務キー３ | I84: E | J84: -
A85: 30 | D85: biz_key4 | E85: #MA.BIZ_KEY | G85: Business key 4 | H85: 業務キー４ | I85: E | J85: -
A86: 30 | D86: biz_key5 | E86: #MA.BIZ_KEY | G86: Business key 5 | H86: 業務キー５ | I86: E | J86: -
A87: 30 | D87: biz_key6 | E87: #MA.BIZ_KEY | G87: Business key 6 | H87: 業務キー６ | I87: E | J87: -
A88: 30 | D88: biz_key7 | E88: #MA.BIZ_KEY | G88: Business key 7 | H88: 業務キー７ | I88: E | J88: -
A89: 30 | D89: biz_key8 | E89: #MA.BIZ_KEY | G89: Business key 8 | H89: 業務キー８ | I89: E | J89: -
...

Sheet Attach_Del01
A1: * | B1: * | D1: L | E1: 1
A2: * | D2: オペレーション実装仕様書 Operation Specification Implementation Sheet | E2: ModuleID : | F2: =IF(LogicCommon!C2="","",LogicCommon!C2) -> MB | G2: LogicID : | H2: =IF(LogicCommon!E2="","",LogicCommon!E2) -> MBBCL5020 | I2: Ope.ID : | J2: Attach_Del01 | K2: Pj.ID : | L2: =IF(LogicCommon!G2="","",LogicCommon!G2) -> MC | M2: Ope.Body : | N2: "mcframe.serverMAUD.MAUDL5010.MAUDL_Operation"
A3: * | D3: =IF(LogicCommon!A3="","",LogicCommon!A3) | E3: SubModuleID : | F3: =IF(LogicCommon!C3="","",LogicCommon!C3) -> MBBC | G3: LogicClass : | H3: =IF(LogicCommon!E3="","",LogicCommon!E3) -> MBBCL_AttachService | I3: Ope.Method : | J3: @ | K3: SuperClassPj.ID : | L3: =IF(LogicCommon!G3="","",LogicCommon!G3) | O3: Gene.Type : | P3: ALL
A4: * | E4: Version : | F4: 000000 | G4: LogicName : | H4: =IF(LogicCommon!E4="","",LogicCommon!E4) -> 添付帳票登録サービス | I4: Ope.Name : | J4: 削除 | K4: SuperLogicID : | L4: =IF(LogicCommon!G4="","",LogicCommon!G4) -> MB.MBUDL5010 | M4: ImplOpe.ID:
A5: * | E5: ACType :
A6: * | D6: 概要 : | E6: 添付ファイル情報を削除する | M6: ID | O6: ID | Q6: ID
A7: # | I7: U | K7: K | L7: o | N7: o | P7: o
A8: # | D8: ブロック名 Block Name | E8: 型 Type | G8: super/share | H8: 対象ブロック名 Target Block Name | L8: TargetName | N8: TargetName | P8: TargetName | T8: ブロック備考 Block Remarks
A9: # | D9: 項目名 Field Name | E9: 型 Type | F9: 桁 Digits | G9: フルネーム Full Name | H9: 日本語名 Japanese Name | I9: 上り項目 Request Message Field | J9: 下り項目 Response Message Field | R9: 条件および編集方法 Conditions and Editing Methods | T9: 項目備考 Field Remarks
A10: # | L10: 上り項目 Request Message Field | M10: 下り項目 Response Message Field | N10: 上り項目 Request Message Field | O10: 下り項目 Response Message Field | P10: 上り項目 Request Message Field | Q10: 下り項目 Response Message Field
A11: 10 | B11: * | D11: Attach_Del01_Dtl | E11: L | G11: $share$ | H11: MB.MBBCL5020.Attach_Chk02.Attach_Chk02_Dtl
A12: 10 | D12: biz_typ | E12: #MA.BIZ_TYP | G12: Business type | H12: 業務区分 | I12: E | J12: -
A13: 10 | D13: biz_key1 | E13: #MA.BIZ_KEY | G13: Business key 1 | H13: 業務キー１ | I13: E | J13: -
A14: 10 | D14: biz_key2 | E14: #MA.BIZ_KEY | G14: Business key 2 | H14: 業務キー２ | I14: E | J14: -
A15: 10 | D15: biz_key3 | E15: #MA.BIZ_KEY | G15: Business key 3 | H15: 業務キー３ | I15: E | J15: -
A16: 10 | D16: biz_key4 | E16: #MA.BIZ_KEY | G16: Business key 4 | H16: 業務キー４ | I16: E | J16: -
A17: 10 | D17: biz_key5 | E17: #MA.BIZ_KEY | G17: Business key 5 | H17: 業務キー５ | I17: E | J17: -
A18: 10 | D18: biz_key6 | E18: #MA.BIZ_KEY | G18: Business key 6 | H18: 業務キー６ | I18: E | J18: -
A19: 10 | D19: biz_key7 | E19: #MA.BIZ_KEY | G19: Business key 7 | H19: 業務キー７ | I19: E | J19: -
A20: 10 | D20: biz_key8 | E20: #MA.BIZ_KEY | G20: Business key 8 | H20: 業務キー８ | I20: E | J20: -
A21: 10 | D21: biz_key9 | E21: #MA.BIZ_KEY | G21: Business key 9 | H21: 業務キー９ | I21: E | J21: -
A22: 10 | D22: biz_key10 | E22: #MA.BIZ_KEY | G22: Business key 10 | H22: 業務キー１０ | I22: E | J22: -
A23: 10 | D23: report_id | E23: #MA.REPORT_ID | G23: Report ID | H23: 帳票ＩＤ | I23: E | J23: -
D24: 詳細 :

Sheet Attach_Copy01
A1: * | B1: * | D1: L | E1: 1
A2: * | D2: オペレーション実装仕様書 Operation Specification Implementation Sheet | E2: ModuleID : | F2: =IF(LogicCommon!C2="","",LogicCommon!C2) -> MB | G2: LogicID : | H2: =IF(LogicCommon!E2="","",LogicCommon!E2) -> MBBCL5020 | I2: Ope.ID : | J2: Attach_Copy01 | K2: Pj.ID : | L2: =IF(LogicCommon!G2="","",LogicCommon!G2) -> MC | M2: Ope.Body : | N2: "mcframe.serverMAUD.MAUDL5010.MAUDL_Operation"
A3: * | D3: =IF(LogicCommon!A3="","",LogicCommon!A3) | E3: SubModuleID : | F3: =IF(LogicCommon!C3="","",LogicCommon!C3) -> MBBC | G3: LogicClass : | H3: =IF(LogicCommon!E3="","",LogicCommon!E3) -> MBBCL_AttachService | I3: Ope.Method : | J3: @ | K3: SuperClassPj.ID : | L3: =IF(LogicCommon!G3="","",LogicCommon!G3) | O3: Gene.Type : | P3: ALL
A4: * | E4: Version : | F4: 000000 | G4: LogicName : | H4: =IF(LogicCommon!E4="","",LogicCommon!E4) -> 添付帳票登録サービス | I4: Ope.Name : | J4: ファイル保存 | K4: SuperLogicID : | L4: =IF(LogicCommon!G4="","",LogicCommon!G4) -> MB.MBUDL5010 | M4: ImplOpe.ID:
A5: * | E5: ACType :
A6: * | D6: 概要 : | E6: 添付ファイルを外部システムに保存する | M6: ID | O6: ID | Q6: ID
A7: # | I7: U | K7: K | L7: o | N7: o | P7: o
A8: # | D8: ブロック名 Block Name | E8: 型 Type | G8: super/share | H8: 対象ブロック名 Target Block Name | L8: TargetName | N8: TargetName | P8: TargetName | T8: ブロック備考 Block Remarks
A9: # | D9: 項目名 Field Name | E9: 型 Type | F9: 桁 Digits | G9: フルネーム Full Name | H9: 日本語名 Japanese Name | I9: 上り項目 Request Message Field | J9: 下り項目 Response Message Field | R9: 条件および編集方法 Conditions and Editing Methods | T9: 項目備考 Field Remarks
A10: # | L10: 上り項目 Request Message Field | M10: 下り項目 Response Message Field | N10: 上り項目 Request Message Field | O10: 下り項目 Response Message Field | P10: 上り項目 Request Message Field | Q10: 下り項目 Response Message Field
A11: 10 | B11: * | D11: Attach_Copy01_Hdr | E11: R
A12: 10 | D12: msg_queue_id | E12: #MA.MSG_QUEUE_ID | G12: Message queue ID | H12: メッセージキューＩＤ | I12: E | J12: -
A13: 10 | D13: retry_flg | E13: #MA.FLG | G13: Retry | H13: リトライ | I13: E | J13: -
D14: 詳細 :

Sheet 来歴
A1: 変更来歴
A3: Rev. | H3: 修正番号 | O3: 変更内容 | AQ3: 変更箇所
A4: 1 | O4: 初版
A5: 1.1 | H5: MB7032#007 | O5: 「Attach_Chk01_Dtl」ブロックにある以下の項目のREQUIREDを削除。 bp_cd、cur_cd、amt | AQ5: Attach_Chk01シート
A6: 1.2 | O6: 英語の名称を追記 | AQ6: 全般
