Workbook

Sheet LogicCommon
A2: ロジック共通定義 | B2: ModuleID : | C2: MA | D2: LogicID : | E2: MABGL0610 | F2: Pj.ID : | G2: MC
B3: SubModuleID : | C3: MABG | D3: LogicClass : | E3: MABGL_CostItmOutReg | F3: SuperClassPj.ID :
D4: LogicName : | E4: 原価対象外品目マスタ登録 | F4: SuperLogicID : | G4: MA.MAUDL5010
A5: 概要 :
A6: 詳細 :

Sheet CostItmOut_UpdChk01
A1: * | B1: * | D1: L | E1: 1
A2: * | D2: オペレーション実装仕様書 Operation Specification Implementation Sheet | E2: ModuleID : | F2: =IF(LogicCommon!C2="","",LogicCommon!C2) -> MA | G2: LogicID : | H2: =IF(LogicCommon!E2="","",LogicCommon!E2) -> MABGL0610 | I2: Ope.ID : | J2: CostItmOut_UpdChk01 | K2: Pj.ID : | L2: =IF(LogicCommon!G2="","",LogicCommon!G2) -> MC | M2: Ope.Body : | N2: =L4 & ".Checker" -> MA.MAUDL5010.Checker
A3: * | D3: =IF(LogicCommon!A3="","",LogicCommon!A3) | E3: SubModuleID : | F3: =IF(LogicCommon!C3="","",LogicCommon!C3) -> MABG | G3: LogicClass : | H3: =IF(LogicCommon!E3="","",LogicCommon!E3) -> MABGL_CostItmOutReg | I3: Ope.Method : | J3: @ | K3: SuperClassPj.ID : | L3: =IF(LogicCommon!G3="","",LogicCommon!G3) | M3: ReportID : | O3: Gene.Type : | P3: ALL
A4: * | E4: Version : | F4: 000000 | G4: LogicName : | H4: =IF(LogicCommon!E4="","",LogicCommon!E4) -> 原価対象外品目マスタ登録 | I4: Ope.Name : | J4: 登録前チェック | K4: SuperLogicID : | L4: =IF(LogicCommon!G4="","",LogicCommon!G4) -> MA.MAUDL5010
A5: * | E5: ACType :
A6: * | D6: 概要 : | E6: 原価対象外品目マスタを登録する前のチェックを行う | S6: ID
A7: # | I7: U | K7: K | L7: K | M7: K | N7: K | O7: K | R7: o
A8: # | D8: ブロック名 Block Name | E8: 型 Type | G8: super/share | H8: 対象ブロック名 Target Block Name | K8: REQUIRED | L8: LIST_LOGIC | M8: LIST_IN | N8: LIST_IN_BASE | O8: NULL_VAL | R8: TargetName | V8: ブロック備考 Block Remarks
A9: # | D9: 項目名 Field Name | E9: 型 Type | F9: 桁 Digits | G9: フルネーム Full Name | H9: 日本語名 Japanese Name | I9: 上り項目 Request Message Field | J9: 下り項目 Response Message Field | T9: 条件および編集方法 Conditions and Editing Methods | V9: 項目備考 Field Remarks
A10: # | R10: 上り項目 Request Message Field | S10: 下り項目 Response Message Field
A11: 10 | B11: * | D11: CostItmOut_UpdChk01_Dtl | E11: L | G11: $super$ | H11: DBC:MA.MAM_COST_ITM_OUT
A12: 10 | D12: itm_cd | E12: #MA.ITM_CD | G12: Item cd. | H12: 品目ＣＤ | I12: E | K12: E
A13: 10 | D13: itm_sub1 | E13: #MA.ITM_SUB1 | G13: Branch No. 1 | H13: 枝番１ | I13: E | K13: E | O13: E
A14: 10 | D14: itm_sub2 | E14: #MA.ITM_SUB2 | G14: Branch No. 2 | H14: 枝番２ | I14: E | K14: E | O14: E
A15: 10 | D15: itm_sub3 | E15: #MA.ITM_SUB3 | G15: Branch No. 3 | H15: 枝番３ | I15: E | K15: E | L15: MA.MAUAL0010.ItmSub3 | M15: MAC_ITM_IS_SRCH_TYP.NOT_ASSET3;itm_cd;itm_sub1;itm_sub2 | N15: itm_is_srch_typ;itm_cd;itm_sub1;itm_sub2 | O15: E
A16: 10 | D16: ym | E16: #MA.YM | G16: Application month | H16: 適用年月 | I16: E | K16: E
A17: 10 | D17: memo1 | E17: #MA.MST_MEMO1 | G17: Memo 1 | H17: メモ１ | I17: E
A18: 10 | D18: memo2 | E18: #MA.MST_MEMO2 | G18: Memo 2 | H18: メモ２ | I18: E
A19: 10 | D19: memo3 | E19: #MA.MST_MEMO3 | G19: Memo 3 | H19: メモ３ | I19: E
A20: 10 | D20: del_flg | E20: #MA.FLG | G20: Logical delete | H20: 論理削除 | I20: E
A21: 10 | D21: upd_cntr | E21: #MA.UPD_CNT | G21: Update counter | H21: 更新カウンタ | I21: E
D22: 詳細 :

Sheet CostItmOut_Upd01
A1: * | B1: * | D1: L | E1: 1
A2: * | D2: オペレーション実装仕様書 Operation Specification Implementation Sheet | E2: ModuleID : | F2: =IF(LogicCommon!C2="","",LogicCommon!C2) -> MA | G2: LogicID : | H2: =IF(LogicCommon!E2="","",LogicCommon!E2) -> MABGL0610 | I2: Ope.ID : | J2: CostItmOut_Upd01 | K2: Pj.ID : | L2: =IF(LogicCommon!G2="","",LogicCommon!G2) -> MC | M2: Ope.Body : | N2: "mcframe.serverMAUD.MAUDL6010.MAUDL_RLUpdater"
A3: * | D3: =IF(LogicCommon!A3="","",LogicCommon!A3) | E3: SubModuleID : | F3: =IF(LogicCommon!C3="","",LogicCommon!C3) -> MABG | G3: LogicClass : | H3: =IF(LogicCommon!E3="","",LogicCommon!E3) -> MABGL_CostItmOutReg | I3: Ope.Method : | J3: @ | K3: SuperClassPj.ID : | L3: =IF(LogicCommon!G3="","",LogicCommon!G3) | M3: ReportID : | O3: Gene.Type : | P3: ALL
A4: * | E4: Version : | F4: 000000 | G4: LogicName : | H4: =IF(LogicCommon!E4="","",LogicCommon!E4) -> 原価対象外品目マスタ登録 | I4: Ope.Name : | J4: 登録処理 | K4: SuperLogicID : | L4: =IF(LogicCommon!G4="","",LogicCommon!G4) -> MA.MAUDL5010
A5: * | E5: ACType :
A6: * | D6: 概要 : | E6: 原価対象外品目マスタを登録する | L6: ID | N6: ID
A7: # | I7: U | K7: o | L7: UPDATE.updMaster | M7: o | N7: MAIN.chkMaster
A8: # | D8: ブロック名 Block Name | E8: 型 Type | G8: super/share | H8: 対象ブロック名 Target Block Name | K8: TargetName | L8: DBC.MA.MAM_COST_ITM_OUT | M8: TargetName | N8: DBC.MA.MAM_COST_ITM_OUT | Q8: ブロック備考 Block Remarks
A9: # | D9: 項目名 Field Name | E9: 型 Type | F9: 桁 Digits | G9: フルネーム Full Name | H9: 日本語名 Japanese Name | I9: 上り項目 Request Message Field | J9: 下り項目 Response Message Field | O9: 条件および編集方法 Conditions and Editing Methods | Q9: 項目備考 Field Remarks
A10: # | K10: 上り項目 Request Message Field | L10: 下り項目 Response Message Field | M10: 上り項目 Request Message Field | N10: 下り項目 Response Message Field
A11: 10 | B11: * | D11: CostItmOut_Upd01_Dtl | E11: L | G11: $share$ | H11: MA.MABGL0610.CostItmOut_UpdChk01.CostItmOut_UpdChk01_Dtl | K11: L | M11: L
A12: 10 | D12: itm_cd | E12: #MA.ITM_CD | G12: Item cd. | H12: 品目ＣＤ | I12: E | K12: E | M12: E
A13: 10 | D13: itm_sub1 | E13: #MA.ITM_SUB1 | G13: Branch No. 1 | H13: 枝番１ | I13: E | K13: E | M13: E
A14: 10 | D14: itm_sub2 | E14: #MA.ITM_SUB2 | G14: Branch No. 2 | H14: 枝番２ | I14: E | K14: E | M14: E
A15: 10 | D15: itm_sub3 | E15: #MA.ITM_SUB3 | G15: Branch No. 3 | H15: 枝番３ | I15: E | K15: E | M15: E
A16: 10 | D16: ym | E16: #MA.YM | G16: Application month | H16: 適用年月 | I16: E | K16: E
A17: 10 | D17: memo1 | E17: #MA.MST_MEMO1 | G17: Memo 1 | H17: メモ１ | I17: E | K17: E
A18: 10 | D18: memo2 | E18: #MA.MST_MEMO2 | G18: Memo 2 | H18: メモ２ | I18: E | K18: E
A19: 10 | D19: memo3 | E19: #MA.MST_MEMO3 | G19: Memo 3 | H19: メモ３ | I19: E | K19: E
A20: 10 | D20: del_flg | E20: #MA.FLG | G20: Logical delete | H20: 論理削除 | I20: E | K20: E
A21: 10 | D21: upd_cntr | E21: #MA.UPD_CNT | G21: Update counter | H21: 更新カウンタ | I21: E | K21: E
D22: 詳細 :

Sheet CostItmOut_DelChk01
A1: * | B1: * | D1: L | E1: 1
A2: * | D2: オペレーション実装仕様書 Operation Specification Implementation Sheet | E2: ModuleID : | F2: =IF(LogicCommon!C2="","",LogicCommon!C2) -> MA | G2: LogicID : | H2: =IF(LogicCommon!E2="","",LogicCommon!E2) -> MABGL0610 | I2: Ope.ID : | J2: CostItmOut_DelChk01 | K2: Pj.ID : | L2: =IF(LogicCommon!G2="","",LogicCommon!G2) -> MC | M2: Ope.Body : | N2: =L4 & ".Checker" -> MA.MAUDL5010.Checker
A3: * | D3: =IF(LogicCommon!A3="","",LogicCommon!A3) | E3: SubModuleID : | F3: =IF(LogicCommon!C3="","",LogicCommon!C3) -> MABG | G3: LogicClass : | H3: =IF(LogicCommon!E3="","",LogicCommon!E3) -> MABGL_CostItmOutReg | I3: Ope.Method : | J3: @ | K3: SuperClassPj.ID : | L3: =IF(LogicCommon!G3="","",LogicCommon!G3) | M3: ReportID : | O3: Gene.Type : | P3: ALL
A4: * | E4: Version : | F4: 000000 | G4: LogicName : | H4: =IF(LogicCommon!E4="","",LogicCommon!E4) -> 原価対象外品目マスタ登録 | I4: Ope.Name : | J4: 削除前チェック | K4: SuperLogicID : | L4: =IF(LogicCommon!G4="","",LogicCommon!G4) -> MA.MAUDL5010
A5: * | E5: ACType :
A6: * | D6: 概要 : | E6: 原価対象外品目マスタを削除する前のチェックを行う | Q6: ID
A7: # | I7: U | K7: K | P7: o
A8: # | D8: ブロック名 Block Name | E8: 型 Type | G8: super/share | H8: 対象ブロック名 Target Block Name | K8: REQUIRED | P8: TargetName | T8: ブロック備考 Block Remarks
A9: # | D9: 項目名 Field Name | E9: 型 Type | F9: 桁 Digits | G9: フルネーム Full Name | H9: 日本語名 Japanese Name | I9: 上り項目 Request Message Field | J9: 下り項目 Response Message Field | R9: 条件および編集方法 Conditions and Editing Methods | T9: 項目備考 Field Remarks
A10: # | P10: 上り項目 Request Message Field | Q10: 下り項目 Response Message Field
A11: 10 | B11: * | D11: CostItmOut_DelChk01_Dtl | E11: L
A12: 10 | D12: itm_cd | E12: #MA.ITM_CD | G12: Item cd. | H12: 品目ＣＤ | I12: E | K12: E
A13: 10 | D13: itm_sub1 | E13: #MA.ITM_SUB1 | G13: Branch No. 1 | H13: 枝番１ | I13: E | K13: E
A14: 10 | D14: itm_sub2 | E14: #MA.ITM_SUB2 | G14: Branch No. 2 | H14: 枝番２ | I14: E | K14: E
A15: 10 | D15: itm_sub3 | E15: #MA.ITM_SUB3 | G15: Branch No. 3 | H15: 枝番３ | I15: E | K15: E
A16: 10 | D16: upd_cntr | E16: #MA.UPD_CNT | G16: Update counter | H16: 更新カウンタ | I16: E
D17: 詳細 :

Sheet CostItmOut_Del01
A1: * | B1: * | D1: L | E1: 1
A2: * | D2: オペレーション実装仕様書 Operation Specification Implementation Sheet | E2: ModuleID : | F2: =IF(LogicCommon!C2="","",LogicCommon!C2) -> MA | G2: LogicID : | H2: =IF(LogicCommon!E2="","",LogicCommon!E2) -> MABGL0610 | I2: Ope.ID : | J2: CostItmOut_Del01 | K2: Pj.ID : | L2: =IF(LogicCommon!G2="","",LogicCommon!G2) -> MC | M2: Ope.Body : | N2: "mcframe.serverMAUD.MAUDL6010.MAUDL_RLDeleter"
A3: * | D3: =IF(LogicCommon!A3="","",LogicCommon!A3) | E3: SubModuleID : | F3: =IF(LogicCommon!C3="","",LogicCommon!C3) -> MABG | G3: LogicClass : | H3: =IF(LogicCommon!E3="","",LogicCommon!E3) -> MABGL_CostItmOutReg | I3: Ope.Method : | J3: @ | K3: SuperClassPj.ID : | L3: =IF(LogicCommon!G3="","",LogicCommon!G3) | M3: ReportID : | O3: Gene.Type : | P3: ALL
A4: * | E4: Version : | F4: 000000 | G4: LogicName : | H4: =IF(LogicCommon!E4="","",LogicCommon!E4) -> 原価対象外品目マスタ登録 | I4: Ope.Name : | J4: 削除処理 | K4: SuperLogicID : | L4: =IF(LogicCommon!G4="","",LogicCommon!G4) -> MA.MAUDL5010
A5: * | E5: ACType :
A6: * | D6: 概要 : | E6: 原価対象外品目マスタを削除する | L6: ID
A7: # | I7: U | K7: o | L7: UPDATE.updMaster1
A8: # | D8: ブロック名 Block Name | E8: 型 Type | G8: super/share | H8: 対象ブロック名 Target Block Name | K8: TargetName | L8: DBC.MA.MAM_COST_ITM_OUT | O8: ブロック備考 Block Remarks
A9: # | D9: 項目名 Field Name | E9: 型 Type | F9: 桁 Digits | G9: フルネーム Full Name | H9: 日本語名 Japanese Name | I9: 上り項目 Request Message Field | J9: 下り項目 Response Message Field | M9: 条件および編集方法 Conditions and Editing Methods | O9: 項目備考 Field Remarks
A10: # | K10: 上り項目 Request Message Field | L10: 下り項目 Response Message Field
A11: 10 | B11: * | D11: CostItmOut_Del01_Dtl | E11: L | G11: $share$ | H11: MA.MABGL0610.CostItmOut_DelChk01.CostItmOut_DelChk01_Dtl | K11: L
A12: 10 | D12: itm_cd | E12: #MA.ITM_CD | G12: Item cd. | H12: 品目ＣＤ | I12: E | K12: E
A13: 10 | D13: itm_sub1 | E13: #MA.ITM_SUB1 | G13: Branch No. 1 | H13: 枝番１ | I13: E | K13: E
A14: 10 | D14: itm_sub2 | E14: #MA.ITM_SUB2 | G14: Branch No. 2 | H14: 枝番２ | I14: E | K14: E
A15: 10 | D15: itm_sub3 | E15: #MA.ITM_SUB3 | G15: Branch No. 3 | H15: 枝番３ | I15: E | K15: E
A16: 10 | D16: upd_cntr | E16: #MA.UPD_CNT | G16: Update counter | H16: 更新カウンタ | I16: E | K16: E
D17: 詳細 :

Sheet Srch01
A1: * | B1: * | D1: L | E1: 1
A2: * | D2: オペレーション実装仕様書 Operation Specification Implementation Sheet | E2: ModuleID : | F2: =IF(LogicCommon!C2="","",LogicCommon!C2) -> MA | G2: LogicID : | H2: =IF(LogicCommon!E2="","",LogicCommon!E2) -> MABGL0610 | I2: Ope.ID : | J2: Srch01 | K2: Pj.ID : | L2: =IF(LogicCommon!G2="","",LogicCommon!G2) -> MC | M2: Ope.Body : | N2: "mcframe.serverMAUD.MAUDL6010.MAUDL_RLSearcher"
A3: * | D3: =IF(LogicCommon!A3="","",LogicCommon!A3) | E3: SubModuleID : | F3: =IF(LogicCommon!C3="","",LogicCommon!C3) -> MABG | G3: LogicClass : | H3: =IF(LogicCommon!E3="","",LogicCommon!E3) -> MABGL_CostItmOutReg | I3: Ope.Method : | J3: @ | K3: SuperClassPj.ID : | L3: =IF(LogicCommon!G3="","",LogicCommon!G3) | M3: ReportID : | O3: Gene.Type : | P3: ALL
A4: * | E4: Version : | F4: 000000 | G4: LogicName : | H4: =IF(LogicCommon!E4="","",LogicCommon!E4) -> 原価対象外品目マスタ登録 | I4: Ope.Name : | J4: 検索 | K4: SuperLogicID : | L4: =IF(LogicCommon!G4="","",LogicCommon!G4) -> MA.MAUDL5010
A5: * | E5: ACType :
A6: * | D6: 概要 : | E6: 検索処理を行う | M6: ID
A7: # | I7: U | K7: K | L7: o | M7: SELECT.c0
A8: # | D8: ブロック名 Block Name | E8: 型 Type | G8: super/share | H8: 対象ブロック名 Target Block Name | K8: CONST | L8: TargetName | M8: DBC.MA.MAM_COST_ITM_OUT | P8: ブロック備考 Block Remarks
A9: # | D9: 項目名 Field Name | E9: 型 Type | F9: 桁 Digits | G9: フルネーム Full Name | H9: 日本語名 Japanese Name | I9: 上り項目 Request Message Field | J9: 下り項目 Response Message Field | N9: 条件および編集方法 Conditions and Editing Methods | P9: 項目備考 Field Remarks
A10: # | L10: 上り項目 Request Message Field | M10: 下り項目 Response Message Field
A11: 10 | B11: * | D11: Srch01_Cnd | E11: R | L11: R
A12: 10 | D12: ym_fr | E12: #MA.YM | G12: Applicable month FROM | H12: 適用年月ＦＲＯＭ | I12: E
A13: 10 | D13: ym_to | E13: #MA.YM | G13: Applicable month TO | H13: 適用年月ＴＯ | I13: E
A14: 10 | D14: itm_jnl_cd | E14: #MA.ITM_JNL_CD | G14: Item journal cd. | H14: 品目仕訳ＣＤ | I14: E
A15: 10 | D15: itm_jnl_nm | E15: #MA.ITM_JNL_NM | G15: Item journal name | H15: 品目仕訳名 | I15: E
A16: 10 | D16: ac_itm_grp_cd | E16: #MA.AC_ITM_GRP_CD | G16: Accounting item classification cd. | H16: 会計品目分類ＣＤ | I16: E
A17: 10 | D17: ac_itm_grp_nm | E17: #MA.AC_ITM_GRP_NM | G17: Accounting item classification name | H17: 会計品目分類名 | I17: E
A18: 10 | D18: itm_typ | E18: #MA.ITM_TYP | G18: Item type | H18: 品目区分 | I18: E
A19: 10 | D19: itm_typ_d_cd | E19: #MA.ITM_TYP_D_CD | G19: Item type details cd. | H19: 品目区分詳細ＣＤ | I19: E
A20: 10 | D20: itm_typ_d_nm | E20: #MA.ITM_TYP_D_NM | G20: Item type details name | H20: 品目区分詳細名 | I20: E
A21: 10 | D21: itm_cd | E21: #MA.ITM_CD | G21: Item cd. | H21: 品目ＣＤ | I21: E
A22: 10 | D22: itm_sub1 | E22: #MA.ITM_SUB1 | G22: Branch No. 1 | H22: 枝番１ | I22: E
A23: 10 | D23: itm_sub2 | E23: #MA.ITM_SUB2 | G23: Branch No. 2 | H23: 枝番２ | I23: E
... A50: 10 | D50: itm_grp_nm10 | E50: #MA.ITM_GRP_NM | G50: Item classification name 10 | H50: 品目分類名１０ | I50: E
A52: 20 | B52: * | D52: Srch01_Rslt1 | E52: L | M52: L
A53: 20 | D53: del_flg | E53: #MA.FLG | G53: Logical delete | H53: 論理削除 | J53: E | M53: E
A54: 20 | D54: itm_cd | E54: #MA.ITM_CD | G54: Item cd. | H54: 品目ＣＤ | J54: E | M54: E
A55: 20 | D55: itm_sub1 | E55: #MA.ITM_SUB1 | G55: Branch No. 1 | H55: 枝番１ | J55: E | M55: E
A56: 20 | D56: itm_sub2 | E56: #MA.ITM_SUB2 | G56: Branch No. 2 | H56: 枝番２ | J56: E | M56: E
A57: 20 | D57: itm_sub3 | E57: #MA.ITM_SUB3 | G57: Branch No. 3 | H57: 枝番３ | J57: E | M57: E
A58: 20 | D58: itm_nm | E58: #MA.ITM_NM | G58: Item name | H58: 品名 | J58: E | M58: E
A59: 20 | D59: itm_typ | E59: #MA.ITM_TYP | G59: Item type | H59: 品目区分 | J59: E | K59: MAC_ITM_TYP | M59: E
A60: 20 | D60: itm_typ_nm | E60: #MA.ITM_TYP_NM | G60: Item type name | H60: 品目区分名 | J60: E
A61: 20 | D61: itm_typ_d_cd | E61: #MA.ITM_TYP_D_CD | G61: Item type details cd. | H61: 品目区分詳細ＣＤ | J61: E | M61: E
A62: 20 | D62: itm_typ_d_nm | E62: #MA.ITM_TYP_D_NM | G62: Item type details name | H62: 品目区分詳細名 | J62: E | M62: E
A63: 20 | D63: ym | E63: #MA.YM | G63: Application month | H63: 適用年月 | J63: E | M63: E
A64: 20 | D64: memo1 | E64: #MA.MST_MEMO1 | G64: Memo 1 | H64: メモ１ | J64: E | M64: E
A65: 20 | D65: memo2 | E65: #MA.MST_MEMO2 | G65: Memo 2 | H65: メモ２ | J65: E | M65: E
A66: 20 | D66: memo3 | E66: #MA.MST_MEMO3 | G66: Memo 3 | H66: メモ３ | J66: E | M66: E
A67: 20 | D67: ins_usr_id | E67: #MA.FCM_USR_ID | G67: Entry user ID | H67: 登録ユーザＩＤ | J67: E | M67: E
...

Sheet Upd01
A1: * | B1: * | D1: L | E1: 1
A2: * | D2: オペレーション実装仕様書 Operation Specification Implementation Sheet | E2: ModuleID : | F2: =IF(LogicCommon!C2="","",LogicCommon!C2) -> MA | G2: LogicID : | H2: =IF(LogicCommon!E2="","",LogicCommon!E2) -> MABGL0610 | I2: Ope.ID : | J2: Upd01 | K2: Pj.ID : | L2: =IF(LogicCommon!G2="","",LogicCommon!G2) -> MC | M2: Ope.Body : | N2: "mcframe.serverMAUD.MAUDL6010.MAUDL_RLUpdater"
A3: * | D3: =IF(LogicCommon!A3="","",LogicCommon!A3) | E3: SubModuleID : | F3: =IF(LogicCommon!C3="","",LogicCommon!C3) -> MABG | G3: LogicClass : | H3: =IF(LogicCommon!E3="","",LogicCommon!E3) -> MABGL_CostItmOutReg | I3: Ope.Method : | J3: @ | K3: SuperClassPj.ID : | L3: =IF(LogicCommon!G3="","",LogicCommon!G3) | M3: ReportID : | O3: Gene.Type : | P3: ALL
A4: * | E4: Version : | F4: 000000 | G4: LogicName : | H4: =IF(LogicCommon!E4="","",LogicCommon!E4) -> 原価対象外品目マスタ登録 | I4: Ope.Name : | J4: 登録 | K4: SuperLogicID : | L4: =IF(LogicCommon!G4="","",LogicCommon!G4) -> MA.MAUDL5010
A5: * | E5: ACType :
A6: * | D6: 概要 : | E6: 登録処理を行う | L6: ID | N6: ID
A7: # | I7: U | K7: o | L7: CALL_OPE01.chk01 | M7: o | N7: CALL_OPE01.upd01
A8: # | D8: ブロック名 Block Name | E8: 型 Type | G8: super/share | H8: 対象ブロック名 Target Block Name | K8: TargetName | L8: OPE.MA.MABGL0610.CostItmOut_UpdChk01 | M8: TargetName | N8: OPE.MA.MABGL0610.CostItmOut_Upd01 | Q8: ブロック備考 Block Remarks
A9: # | D9: 項目名 Field Name | E9: 型 Type | F9: 桁 Digits | G9: フルネーム Full Name | H9: 日本語名 Japanese Name | I9: 上り項目 Request Message Field | J9: 下り項目 Response Message Field | O9: 条件および編集方法 Conditions and Editing Methods | Q9: 項目備考 Field Remarks
A10: # | K10: 上り項目 Request Message Field | L10: 下り項目 Response Message Field | M10: 上り項目 Request Message Field | N10: 下り項目 Response Message Field
A11: 10 | B11: * | D11: Upd01_Dtl1 | E11: L | G11: $share$ | H11: MA.MABGL0610.CostItmOut_Upd01.CostItmOut_Upd01_Dtl | K11: CostItmOut_UpdChk01_Dtl | M11: CostItmOut_Upd01_Dtl
A12: 10 | D12: itm_cd | E12: #MA.ITM_CD | G12: Item cd. | H12: 品目ＣＤ | I12: E | K12: E | M12: E
A13: 10 | D13: itm_sub1 | E13: #MA.ITM_SUB1 | G13: Branch No. 1 | H13: 枝番１ | I13: E | K13: E | M13: E
A14: 10 | D14: itm_sub2 | E14: #MA.ITM_SUB2 | G14: Branch No. 2 | H14: 枝番２ | I14: E | K14: E | M14: E
A15: 10 | D15: itm_sub3 | E15: #MA.ITM_SUB3 | G15: Branch No. 3 | H15: 枝番３ | I15: E | K15: E | M15: E
A16: 10 | D16: ym | E16: #MA.YM | G16: Application month | H16: 適用年月 | I16: E | K16: E | M16: E
A17: 10 | D17: memo1 | E17: #MA.MST_MEMO1 | G17: Memo 1 | H17: メモ１ | I17: E | K17: E | M17: E
A18: 10 | D18: memo2 | E18: #MA.MST_MEMO2 | G18: Memo 2 | H18: メモ２ | I18: E | K18: E | M18: E
A19: 10 | D19: memo3 | E19: #MA.MST_MEMO3 | G19: Memo 3 | H19: メモ３ | I19: E | K19: E | M19: E
A20: 10 | D20: del_flg | E20: #MA.FLG | G20: Logical delete | H20: 論理削除 | I20: E | K20: E | M20: E
A21: 10 | D21: upd_cntr | E21: #MA.UPD_CNT | G21: Update counter | H21: 更新カウンタ | I21: E | K21: E | M21: E
D22: 詳細 :

Sheet Del01
A1: * | B1: * | D1: L | E1: 1
A2: * | D2: オペレーション実装仕様書 Operation Specification Implementation Sheet | E2: ModuleID : | F2: =IF(LogicCommon!C2="","",LogicCommon!C2) -> MA | G2: LogicID : | H2: =IF(LogicCommon!E2="","",LogicCommon!E2) -> MABGL0610 | I2: Ope.ID : | J2: Del01 | K2: Pj.ID : | L2: =IF(LogicCommon!G2="","",LogicCommon!G2) -> MC | M2: Ope.Body : | N2: "mcframe.serverMAUD.MAUDL6010.MAUDL_RLDeleter"
A3: * | D3: =IF(LogicCommon!A3="","",LogicCommon!A3) | E3: SubModuleID : | F3: =IF(LogicCommon!C3="","",LogicCommon!C3) -> MABG | G3: LogicClass : | H3: =IF(LogicCommon!E3="","",LogicCommon!E3) -> MABGL_CostItmOutReg | I3: Ope.Method : | J3: @ | K3: SuperClassPj.ID : | L3: =IF(LogicCommon!G3="","",LogicCommon!G3) | M3: ReportID : | O3: Gene.Type : | P3: ALL
A4: * | E4: Version : | F4: 000000 | G4: LogicName : | H4: =IF(LogicCommon!E4="","",LogicCommon!E4) -> 原価対象外品目マスタ登録 | I4: Ope.Name : | J4: 削除 | K4: SuperLogicID : | L4: =IF(LogicCommon!G4="","",LogicCommon!G4) -> MA.MAUDL5010
A5: * | E5: ACType :
A6: * | D6: 概要 : | E6: 削除処理を行う | L6: ID | N6: ID
A7: # | I7: U | K7: o | L7: CALL_OPE01.chk01 | M7: o | N7: CALL_OPE01.del01
A8: # | D8: ブロック名 Block Name | E8: 型 Type | G8: super/share | H8: 対象ブロック名 Target Block Name | K8: TargetName | L8: OPE.MA.MABGL0610.CostItmOut_DelChk01 | M8: TargetName | N8: OPE.MA.MABGL0610.CostItmOut_Del01 | Q8: ブロック備考 Block Remarks
A9: # | D9: 項目名 Field Name | E9: 型 Type | F9: 桁 Digits | G9: フルネーム Full Name | H9: 日本語名 Japanese Name | I9: 上り項目 Request Message Field | J9: 下り項目 Response Message Field | O9: 条件および編集方法 Conditions and Editing Methods | Q9: 項目備考 Field Remarks
A10: # | K10: 上り項目 Request Message Field | L10: 下り項目 Response Message Field | M10: 上り項目 Request Message Field | N10: 下り項目 Response Message Field
A11: 10 | B11: * | D11: Del01_Dtl1 | E11: L | G11: $share$ | H11: MA.MABGL0610.CostItmOut_Del01.CostItmOut_Del01_Dtl | K11: CostItmOut_DelChk01_Dtl | M11: CostItmOut_Del01_Dtl
A12: 10 | D12: itm_cd | E12: #MA.ITM_CD | G12: Item cd. | H12: 品目ＣＤ | I12: E | K12: E | M12: E
A13: 10 | D13: itm_sub1 | E13: #MA.ITM_SUB1 | G13: Branch No. 1 | H13: 枝番１ | I13: E | K13: E | M13: E
A14: 10 | D14: itm_sub2 | E14: #MA.ITM_SUB2 | G14: Branch No. 2 | H14: 枝番２ | I14: E | K14: E | M14: E
A15: 10 | D15: itm_sub3 | E15: #MA.ITM_SUB3 | G15: Branch No. 3 | H15: 枝番３ | I15: E | K15: E | M15: E
A16: 10 | D16: upd_cntr | E16: #MA.UPD_CNT | G16: Update counter | H16: 更新カウンタ | I16: E | K16: E | M16: E
D17: 詳細 :

Sheet 来歴
A1: 変更来歴
A3: Rev. | H3: 修正番号 | O3: 変更内容 | AQ3: 変更箇所
A4: 1 | O4: 初版
A5: 1.1 | O5: 英語の名称を追記 | AQ5: 全般
