Workbook

Sheet LogicCommon
A2: ロジック共通定義 | B2: ModuleID : | C2: MA | D2: LogicID : | E2: MABGL0320 | F2: Pj.ID : | G2: MC
B3: SubModuleID : | C3: MABG | D3: LogicClass : | E3: MABGL_AlcOtherReg | F3: SuperClassPj.ID :
D4: LogicName : | E4: 任意基準値配賦マスタ登録 | F4: SuperLogicID : | G4: MA.MAUDL5010
A5: 概要 :
A6: 詳細 :

Sheet AlcOther_UpdChk01
A1: * | B1: * | D1: L | E1: 1
A2: * | D2: オペレーション実装仕様書 Operation Specification Implementation Sheet | E2: ModuleID : | F2: =IF(LogicCommon!C2="","",LogicCommon!C2) -> MA | G2: LogicID : | H2: =IF(LogicCommon!E2="","",LogicCommon!E2) -> MABGL0320 | I2: Ope.ID : | J2: AlcOther_UpdChk01 | K2: Pj.ID : | L2: =IF(LogicCommon!G2="","",LogicCommon!G2) -> MC | M2: Ope.Body : | N2: =L4 & ".Checker" -> MA.MAUDL5010.Checker
A3: * | D3: =IF(LogicCommon!A3="","",LogicCommon!A3) | E3: SubModuleID : | F3: =IF(LogicCommon!C3="","",LogicCommon!C3) -> MABG | G3: LogicClass : | H3: =IF(LogicCommon!E3="","",LogicCommon!E3) -> MABGL_AlcOtherReg | I3: Ope.Method : | J3: @ | K3: SuperClassPj.ID : | L3: =IF(LogicCommon!G3="","",LogicCommon!G3) | M3: ReportID : | O3: Gene.Type : | P3: ALL
A4: * | E4: Version : | F4: 000000 | G4: LogicName : | H4: =IF(LogicCommon!E4="","",LogicCommon!E4) -> 任意基準値配賦マスタ登録 | I4: Ope.Name : | J4: 登録前チェック | K4: SuperLogicID : | L4: =IF(LogicCommon!G4="","",LogicCommon!G4) -> MA.MAUDL5010
A5: * | E5: ACType :
A6: * | D6: 概要 : | E6: 任意基準値配賦マスタを登録する前のチェックを行う | Q6: ID | S6: ID
A7: # | I7: U | K7: K | L7: K | M7: K | N7: K | O7: K | P7: o | R7: o
A8: # | D8: ブロック名 Block Name | E8: 型 Type | G8: super/share | H8: 対象ブロック名 Target Block Name | K8: REQUIRED | L8: CONST | M8: LIST_LOGIC | N8: LIST_IN | O8: LIST_IN_BASE | P8: TargetName | R8: TargetName | V8: ブロック備考 Block Remarks
A9: # | D9: 項目名 Field Name | E9: 型 Type | F9: 桁 Digits | G9: フルネーム Full Name | H9: 日本語名 Japanese Name | I9: 上り項目 Request Message Field | J9: 下り項目 Response Message Field | T9: 条件および編集方法 Conditions and Editing Methods | V9: 項目備考 Field Remarks
A10: # | P10: 上り項目 Request Message Field | Q10: 下り項目 Response Message Field | R10: 上り項目 Request Message Field | S10: 下り項目 Response Message Field
A11: 10 | B11: * | D11: AlcOther_UpdChk01_Dtl | E11: L | G11: $super$ | H11: DBC:MA.MAM_ALC_OTHER | P11: L | R11: L
A12: 10 | D12: alc_ptn_cd | E12: #MA.ALC_PTN_CD | G12: Allocation pattern cd. | H12: 配賦パタンＣＤ | I12: E | K12: E | M12: MA.MAUAL0010.AlcRuleAlcPtnAsOtherVal | N12: term | O12: term
A13: 10 | D13: alc_val_typ | E13: #MA.ALC_VAL_TYP | G13: Allocation value type | H13: 配賦基準値区分 | I13: E | K13: E | L13: MAC_ALC_VAL_TYP
A14: 10 | D14: term | E14: #MA.YM | G14: Term | H14: 期 | I14: E | K14: E | M14: MA.MAUAL0010.Term
A15: 10 | D15: minus_flg | E15: #MA.FLG | G15: Minus | H15: マイナス | I15: E | K15: E
A16: 10 | D16: memo1 | E16: #MA.MST_MEMO1 | G16: Memo 1 | H16: メモ１ | I16: E
A17: 10 | D17: memo2 | E17: #MA.MST_MEMO2 | G17: Memo 2 | H17: メモ２ | I17: E
A18: 10 | D18: memo3 | E18: #MA.MST_MEMO3 | G18: Memo 3 | H18: メモ３ | I18: E
A19: 10 | D19: del_flg | E19: #MA.FLG | G19: Logical delete | H19: 論理削除 | I19: E
A20: 10 | D20: upd_cntr | E20: #MA.UPD_CNT | G20: Update counter | H20: 更新カウンタ | I20: E
D21: 詳細 :

Sheet AlcOther_Upd01
A1: * | B1: * | D1: L | E1: 1
A2: * | D2: オペレーション実装仕様書 Operation Specification Implementation Sheet | E2: ModuleID : | F2: =IF(LogicCommon!C2="","",LogicCommon!C2) -> MA | G2: LogicID : | H2: =IF(LogicCommon!E2="","",LogicCommon!E2) -> MABGL0320 | I2: Ope.ID : | J2: AlcOther_Upd01 | K2: Pj.ID : | L2: =IF(LogicCommon!G2="","",LogicCommon!G2) -> MC | M2: Ope.Body : | N2: "mcframe.serverMAUD.MAUDL6010.MAUDL_RLUpdater"
A3: * | D3: =IF(LogicCommon!A3="","",LogicCommon!A3) | E3: SubModuleID : | F3: =IF(LogicCommon!C3="","",LogicCommon!C3) -> MABG | G3: LogicClass : | H3: =IF(LogicCommon!E3="","",LogicCommon!E3) -> MABGL_AlcOtherReg | I3: Ope.Method : | J3: @ | K3: SuperClassPj.ID : | L3: =IF(LogicCommon!G3="","",LogicCommon!G3) | M3: ReportID : | O3: Gene.Type : | P3: ALL
A4: * | E4: Version : | F4: 000000 | G4: LogicName : | H4: =IF(LogicCommon!E4="","",LogicCommon!E4) -> 任意基準値配賦マスタ登録 | I4: Ope.Name : | J4: 登録処理 | K4: SuperLogicID : | L4: =IF(LogicCommon!G4="","",LogicCommon!G4) -> MA.MAUDL5010
A5: * | E5: ACType :
A6: * | D6: 概要 : | E6: 任意基準値配賦マスタを登録する | L6: ID | N6: ID | P6: ID | R6: ID
A7: # | I7: U | K7: o | L7: UPDATE.updMaster | M7: o | N7: MAIN.chkMaster | O7: o | Q7: o
A8: # | D8: ブロック名 Block Name | E8: 型 Type | G8: super/share | H8: 対象ブロック名 Target Block Name | K8: TargetName | L8: DBC.MA.MAM_ALC_OTHER | M8: TargetName | N8: DBC.MA.MAM_ALC_OTHER | O8: TargetName | Q8: TargetName | U8: ブロック備考 Block Remarks
A9: # | D9: 項目名 Field Name | E9: 型 Type | F9: 桁 Digits | G9: フルネーム Full Name | H9: 日本語名 Japanese Name | I9: 上り項目 Request Message Field | J9: 下り項目 Response Message Field | S9: 条件および編集方法 Conditions and Editing Methods | U9: 項目備考 Field Remarks
A10: # | K10: 上り項目 Request Message Field | L10: 下り項目 Response Message Field | M10: 上り項目 Request Message Field | N10: 下り項目 Response Message Field | O10: 上り項目 Request Message Field | P10: 下り項目 Response Message Field | Q10: 上り項目 Request Message Field | R10: 下り項目 Response Message Field
A11: 10 | B11: * | D11: AlcOther_Upd01_Dtl | E11: L | G11: $share$ | H11: MA.MABGL0320.AlcOther_UpdChk01.AlcOther_UpdChk01_Dtl | K11: L | M11: L
A12: 10 | D12: alc_ptn_cd | E12: #MA.ALC_PTN_CD | G12: Allocation pattern cd. | H12: 配賦パタンＣＤ | I12: E | K12: E | M12: E
A13: 10 | D13: alc_val_typ | E13: #MA.ALC_VAL_TYP | G13: Allocation value type | H13: 配賦基準値区分 | I13: E | K13: E | M13: E
A14: 10 | D14: term | E14: #MA.YM | G14: Term | H14: 期 | I14: E | K14: E | M14: E
A15: 10 | D15: minus_flg | E15: #MA.FLG | G15: Minus | H15: マイナス | I15: E | K15: E
A16: 10 | D16: memo1 | E16: #MA.MST_MEMO1 | G16: Memo 1 | H16: メモ１ | I16: E | K16: E
A17: 10 | D17: memo2 | E17: #MA.MST_MEMO2 | G17: Memo 2 | H17: メモ２ | I17: E | K17: E
A18: 10 | D18: memo3 | E18: #MA.MST_MEMO3 | G18: Memo 3 | H18: メモ３ | I18: E | K18: E
A19: 10 | D19: del_flg | E19: #MA.FLG | G19: Logical delete | H19: 論理削除 | I19: E | K19: E
A20: 10 | D20: upd_cntr | E20: #MA.UPD_CNT | G20: Update counter | H20: 更新カウンタ | I20: E | K20: E
D21: 詳細 :

Sheet AlcOther_DelChk01
A1: * | B1: * | D1: L | E1: 1
A2: * | D2: オペレーション実装仕様書 Operation Specification Implementation Sheet | E2: ModuleID : | F2: =IF(LogicCommon!C2="","",LogicCommon!C2) -> MA | G2: LogicID : | H2: =IF(LogicCommon!E2="","",LogicCommon!E2) -> MABGL0320 | I2: Ope.ID : | J2: AlcOther_DelChk01 | K2: Pj.ID : | L2: =IF(LogicCommon!G2="","",LogicCommon!G2) -> MC | M2: Ope.Body : | N2: =L4 & ".Checker" -> MA.MAUDL5010.Checker
A3: * | D3: =IF(LogicCommon!A3="","",LogicCommon!A3) | E3: SubModuleID : | F3: =IF(LogicCommon!C3="","",LogicCommon!C3) -> MABG | G3: LogicClass : | H3: =IF(LogicCommon!E3="","",LogicCommon!E3) -> MABGL_AlcOtherReg | I3: Ope.Method : | J3: @ | K3: SuperClassPj.ID : | L3: =IF(LogicCommon!G3="","",LogicCommon!G3) | M3: ReportID : | O3: Gene.Type : | P3: ALL
A4: * | E4: Version : | F4: 000000 | G4: LogicName : | H4: =IF(LogicCommon!E4="","",LogicCommon!E4) -> 任意基準値配賦マスタ登録 | I4: Ope.Name : | J4: 削除前チェック | K4: SuperLogicID : | L4: =IF(LogicCommon!G4="","",LogicCommon!G4) -> MA.MAUDL5010
A5: * | E5: ACType :
A6: * | D6: 概要 : | E6: 任意基準値配賦マスタを削除する前のチェックを行う | Q6: ID
A7: # | I7: U | K7: K | P7: o
A8: # | D8: ブロック名 Block Name | E8: 型 Type | G8: super/share | H8: 対象ブロック名 Target Block Name | K8: REQUIRED | P8: TargetName | T8: ブロック備考 Block Remarks
A9: # | D9: 項目名 Field Name | E9: 型 Type | F9: 桁 Digits | G9: フルネーム Full Name | H9: 日本語名 Japanese Name | I9: 上り項目 Request Message Field | J9: 下り項目 Response Message Field | R9: 条件および編集方法 Conditions and Editing Methods | T9: 項目備考 Field Remarks
A10: # | P10: 上り項目 Request Message Field | Q10: 下り項目 Response Message Field
A11: 10 | B11: * | D11: AlcOther_DelChk01_Dtl | E11: L
A12: 10 | D12: alc_ptn_cd | E12: #MA.ALC_PTN_CD | G12: Allocation pattern cd. | H12: 配賦パタンＣＤ | I12: E | K12: E
A13: 10 | D13: alc_val_typ | E13: #MA.ALC_VAL_TYP | G13: Allocation value type | H13: 配賦基準値区分 | I13: E | K13: E
A14: 10 | D14: term | E14: #MA.YM | G14: Term | H14: 期 | I14: E | K14: E
A15: 10 | D15: upd_cntr | E15: #MA.UPD_CNT | G15: Update counter | H15: 更新カウンタ | I15: E
D16: 詳細 :

Sheet AlcOther_Del01
A1: * | B1: * | D1: L | E1: 1
A2: * | D2: オペレーション実装仕様書 Operation Specification Implementation Sheet | E2: ModuleID : | F2: =IF(LogicCommon!C2="","",LogicCommon!C2) -> MA | G2: LogicID : | H2: =IF(LogicCommon!E2="","",LogicCommon!E2) -> MABGL0320 | I2: Ope.ID : | J2: AlcOther_Del01 | K2: Pj.ID : | L2: =IF(LogicCommon!G2="","",LogicCommon!G2) -> MC | M2: Ope.Body : | N2: "mcframe.serverMAUD.MAUDL6010.MAUDL_RLDeleter"
A3: * | D3: =IF(LogicCommon!A3="","",LogicCommon!A3) | E3: SubModuleID : | F3: =IF(LogicCommon!C3="","",LogicCommon!C3) -> MABG | G3: LogicClass : | H3: =IF(LogicCommon!E3="","",LogicCommon!E3) -> MABGL_AlcOtherReg | I3: Ope.Method : | J3: @ | K3: SuperClassPj.ID : | L3: =IF(LogicCommon!G3="","",LogicCommon!G3) | M3: ReportID : | O3: Gene.Type : | P3: ALL
A4: * | E4: Version : | F4: 000000 | G4: LogicName : | H4: =IF(LogicCommon!E4="","",LogicCommon!E4) -> 任意基準値配賦マスタ登録 | I4: Ope.Name : | J4: 削除処理 | K4: SuperLogicID : | L4: =IF(LogicCommon!G4="","",LogicCommon!G4) -> MA.MAUDL5010
A5: * | E5: ACType :
A6: * | D6: 概要 : | E6: 任意基準値配賦マスタを削除する | L6: ID | N6: ID
A7: # | I7: U | K7: o | L7: UPDATE.updMaster1 | M7: o
A8: # | D8: ブロック名 Block Name | E8: 型 Type | G8: super/share | H8: 対象ブロック名 Target Block Name | K8: TargetName | L8: DBC.MA.MAM_ALC_OTHER | M8: TargetName | Q8: ブロック備考 Block Remarks
A9: # | D9: 項目名 Field Name | E9: 型 Type | F9: 桁 Digits | G9: フルネーム Full Name | H9: 日本語名 Japanese Name | I9: 上り項目 Request Message Field | J9: 下り項目 Response Message Field | O9: 条件および編集方法 Conditions and Editing Methods | Q9: 項目備考 Field Remarks
A10: # | K10: 上り項目 Request Message Field | L10: 下り項目 Response Message Field | M10: 上り項目 Request Message Field | N10: 下り項目 Response Message Field
A11: 10 | B11: * | D11: AlcOther_Del01_Dtl | E11: L | G11: $share$ | H11: MA.MABGL0320.AlcOther_DelChk01.AlcOther_DelChk01_Dtl | K11: L
A12: 10 | D12: alc_ptn_cd | E12: #MA.ALC_PTN_CD | G12: Allocation pattern cd. | H12: 配賦パタンＣＤ | I12: E | K12: E
A13: 10 | D13: alc_val_typ | E13: #MA.ALC_VAL_TYP | G13: Allocation value type | H13: 配賦基準値区分 | I13: E | K13: E
A14: 10 | D14: term | E14: #MA.YM | G14: Term | H14: 期 | I14: E | K14: E
A15: 10 | D15: upd_cntr | E15: #MA.UPD_CNT | G15: Update counter | H15: 更新カウンタ | I15: E | K15: E
D16: 詳細 :

Sheet Srch01
A1: * | B1: * | D1: L | E1: 1
A2: * | D2: オペレーション実装仕様書 Operation Specification Implementation Sheet | E2: ModuleID : | F2: =IF(LogicCommon!C2="","",LogicCommon!C2) -> MA | G2: LogicID : | H2: =IF(LogicCommon!E2="","",LogicCommon!E2) -> MABGL0320 | I2: Ope.ID : | J2: Srch01 | K2: Pj.ID : | L2: =IF(LogicCommon!G2="","",LogicCommon!G2) -> MC | M2: Ope.Body : | N2: "mcframe.serverMAUD.MAUDL6010.MAUDL_RLSearcher"
A3: * | D3: =IF(LogicCommon!A3="","",LogicCommon!A3) | E3: SubModuleID : | F3: =IF(LogicCommon!C3="","",LogicCommon!C3) -> MABG | G3: LogicClass : | H3: =IF(LogicCommon!E3="","",LogicCommon!E3) -> MABGL_AlcOtherReg | I3: Ope.Method : | J3: @ | K3: SuperClassPj.ID : | L3: =IF(LogicCommon!G3="","",LogicCommon!G3) | M3: ReportID : | O3: Gene.Type : | P3: ALL
A4: * | E4: Version : | F4: 000000 | G4: LogicName : | H4: =IF(LogicCommon!E4="","",LogicCommon!E4) -> 任意基準値配賦マスタ登録 | I4: Ope.Name : | J4: 検索 | K4: SuperLogicID : | L4: =IF(LogicCommon!G4="","",LogicCommon!G4) -> MA.MAUDL5010
A5: * | E5: ACType :
A6: * | D6: 概要 : | E6: 検索処理を行う | M6: ID | O6: ID
A7: # | I7: U | K7: K | L7: o | M7: SELECT.c0 | N7: o
A8: # | D8: ブロック名 Block Name | E8: 型 Type | G8: super/share | H8: 対象ブロック名 Target Block Name | K8: CONST | L8: TargetName | M8: DBC.MA.MAM_ALC_OTHER | N8: TargetName | R8: ブロック備考 Block Remarks
A9: # | D9: 項目名 Field Name | E9: 型 Type | F9: 桁 Digits | G9: フルネーム Full Name | H9: 日本語名 Japanese Name | I9: 上り項目 Request Message Field | J9: 下り項目 Response Message Field | P9: 条件および編集方法 Conditions and Editing Methods | R9: 項目備考 Field Remarks
A10: # | L10: 上り項目 Request Message Field | M10: 下り項目 Response Message Field | N10: 上り項目 Request Message Field | O10: 下り項目 Response Message Field
A11: 10 | B11: * | D11: Srch01_Cnd | E11: R | L11: R
A12: 10 | D12: term_fr | E12: #MA.YM | G12: Term FROM | H12: 期ＦＲＯＭ | I12: E
A13: 10 | D13: term_fr_nm | E13: #MA.TERM_NM | G13: Term FROM name | H13: 期ＦＲＯＭ名称 | I13: E
A14: 10 | D14: term_to | E14: #MA.YM | G14: Item category cd. | H14: 品群ＣＤ | I14: E
A15: 10 | D15: term_to_nm | E15: #MA.TERM_NM | G15: Term TO name | H15: 期ＴＯ名称 | I15: E
A16: 10 | D16: alc_ptn_cd | E16: #MA.ALC_PTN_CD | G16: Allocation pattern cd. | H16: 配賦パタンＣＤ | I16: E
A17: 10 | D17: alc_ptn_nm | E17: #MA.ALC_PTN_NM | G17: Allocation pattern name | H17: 配賦パタン名 | I17: E
A18: 10 | D18: alc_val_typ | E18: #MA.ALC_VAL_TYP | G18: Allocation value type | H18: 配賦基準値区分 | I18: E
A19: 10 | D19: off_del_flg | E19: #MA.FLG | G19: Logical delete flg. (Off) | H19: 論理削除ＦＬＧ（オフ） | I19: E
A20: 10 | D20: on_del_flg | E20: #MA.FLG | G20: Logical delete flg. (On) | H20: 論理削除ＦＬＧ（オン） | I20: E
A21: 10 | D21: memo1 | E21: #MA.MST_MEMO1 | G21: Memo 1 | H21: メモ１ | I21: E
A22: 10 | D22: memo2 | E22: #MA.MST_MEMO2 | G22: Memo 2 | H22: メモ２ | I22: E
A23: 10 | D23: memo3 | E23: #MA.MST_MEMO3 | G23: Memo 3 | H23: メモ３ | I23: E
A25: 20 | B25: * | D25: Srch01_Rslt1 | E25: L | M25: L
A26: 20 | D26: del_flg | E26: #MA.FLG | G26: Logical delete | H26: 論理削除 | J26: E | M26: E
A27: 20 | D27: term | E27: #MA.YM | G27: Term | H27: 期 | J27: E | M27: E
A28: 20 | D28: term_nm | E28: #MA.TERM_NM | G28: Term name | H28: 期名称 | J28: E | M28: E
A29: 20 | D29: alc_ptn_cd | E29: #MA.ALC_PTN_CD | G29: Allocation pattern cd. | H29: 配賦パタンＣＤ | J29: E | M29: E
A30: 20 | D30: alc_ptn_nm | E30: #MA.ALC_PTN_NM | G30: Allocation pattern name | H30: 配賦パタン名 | J30: E | M30: E
A31: 20 | D31: alc_val_typ | E31: #MA.ALC_VAL_TYP | G31: Allocation value type | H31: 配賦基準値区分 | J31: E | K31: MAC_ALC_VAL_TYP | M31: E
A32: 20 | D32: alc_val_typ_nm | E32: #MA.ALC_VAL_TYP_NM | G32: Allocation value type name | H32: 配賦基準値区分名 | J32: E
A33: 20 | D33: minus_flg | E33: #MA.FLG | G33: Minus | H33: マイナス | J33: E | M33: E
A34: 20 | D34: memo1 | E34: #MA.MST_MEMO1 | G34: Memo 1 | H34: メモ１ | J34: E | M34: E
A35: 20 | D35: memo2 | E35: #MA.MST_MEMO2 | G35: Memo 2 | H35: メモ２ | J35: E | M35: E
A36: 20 | D36: memo3 | E36: #MA.MST_MEMO3 | G36: Memo 3 | H36: メモ３ | J36: E | M36: E
A37: 20 | D37: ins_usr_id | E37: #MA.FCM_USR_ID | G37: Entry user ID | H37: 登録ユーザＩＤ | J37: E | M37: E
A38: 20 | D38: ins_usr_nm | E38: #MA.FCM_USR_NM | G38: Entry user name | H38: 登録ユーザ名 | J38: E | M38: E
A39: 20 | D39: ins_ts | E39: #MA.SYS_TS | G39: Entry date and time | H39: 登録日時 | J39: E | M39: E
A40: 20 | D40: ins_func_id | E40: #MA.FUNC_ID | G40: Entry function ID | H40: 登録機能ＩＤ | J40: E | M40: E
A41: 20 | D41: ins_func_nm | E41: #MA.FUNC_NM | G41: Entry function name | H41: 登録機能名 | J41: E
...

Sheet Upd01
A1: * | B1: * | D1: L | E1: 1
A2: * | D2: オペレーション実装仕様書 Operation Specification Implementation Sheet | E2: ModuleID : | F2: =IF(LogicCommon!C2="","",LogicCommon!C2) -> MA | G2: LogicID : | H2: =IF(LogicCommon!E2="","",LogicCommon!E2) -> MABGL0320 | I2: Ope.ID : | J2: Upd01 | K2: Pj.ID : | L2: =IF(LogicCommon!G2="","",LogicCommon!G2) -> MC | M2: Ope.Body : | N2: "mcframe.serverMAUD.MAUDL6010.MAUDL_RLUpdater"
A3: * | D3: =IF(LogicCommon!A3="","",LogicCommon!A3) | E3: SubModuleID : | F3: =IF(LogicCommon!C3="","",LogicCommon!C3) -> MABG | G3: LogicClass : | H3: =IF(LogicCommon!E3="","",LogicCommon!E3) -> MABGL_AlcOtherReg | I3: Ope.Method : | J3: @ | K3: SuperClassPj.ID : | L3: =IF(LogicCommon!G3="","",LogicCommon!G3) | M3: ReportID : | O3: Gene.Type : | P3: ALL
A4: * | E4: Version : | F4: 000000 | G4: LogicName : | H4: =IF(LogicCommon!E4="","",LogicCommon!E4) -> 任意基準値配賦マスタ登録 | I4: Ope.Name : | J4: 登録 | K4: SuperLogicID : | L4: =IF(LogicCommon!G4="","",LogicCommon!G4) -> MA.MAUDL5010
A5: * | E5: ACType :
A6: * | D6: 概要 : | E6: 登録処理を行う | L6: ID | N6: ID | P6: ID | R6: ID
A7: # | I7: U | K7: o | L7: CALL_OPE01.chk01 | M7: o | N7: CALL_OPE01.upd01 | O7: o | Q7: o
A8: # | D8: ブロック名 Block Name | E8: 型 Type | G8: super/share | H8: 対象ブロック名 Target Block Name | K8: TargetName | L8: OPE.MA.MABGL0320.AlcOther_UpdChk01 | M8: TargetName | N8: OPE.MA.MABGL0320.AlcOther_Upd01 | O8: TargetName | Q8: TargetName | U8: ブロック備考 Block Remarks
A9: # | D9: 項目名 Field Name | E9: 型 Type | F9: 桁 Digits | G9: フルネーム Full Name | H9: 日本語名 Japanese Name | I9: 上り項目 Request Message Field | J9: 下り項目 Response Message Field | S9: 条件および編集方法 Conditions and Editing Methods | U9: 項目備考 Field Remarks
A10: # | K10: 上り項目 Request Message Field | L10: 下り項目 Response Message Field | M10: 上り項目 Request Message Field | N10: 下り項目 Response Message Field | O10: 上り項目 Request Message Field | P10: 下り項目 Response Message Field | Q10: 上り項目 Request Message Field | R10: 下り項目 Response Message Field
A11: 10 | B11: * | D11: Upd01_Dtl1 | E11: L | G11: $share$ | H11: MA.MABGL0320.AlcOther_Upd01.AlcOther_Upd01_Dtl | K11: AlcOther_UpdChk01_Dtl | M11: AlcOther_Upd01_Dtl
A12: 10 | D12: alc_ptn_cd | E12: #MA.ALC_PTN_CD | G12: Allocation pattern cd. | H12: 配賦パタンＣＤ | I12: E | K12: E | M12: E
A13: 10 | D13: alc_val_typ | E13: #MA.ALC_VAL_TYP | G13: Allocation value type | H13: 配賦基準値区分 | I13: E | K13: E | M13: E
A14: 10 | D14: term | E14: #MA.YM | G14: Term | H14: 期 | I14: E | K14: E | M14: E
A15: 10 | D15: minus_flg | E15: #MA.FLG | G15: Minus | H15: マイナス | I15: E | K15: E | M15: E
A16: 10 | D16: memo1 | E16: #MA.MST_MEMO1 | G16: Memo 1 | H16: メモ１ | I16: E | K16: E | M16: E
A17: 10 | D17: memo2 | E17: #MA.MST_MEMO2 | G17: Memo 2 | H17: メモ２ | I17: E | K17: E | M17: E
A18: 10 | D18: memo3 | E18: #MA.MST_MEMO3 | G18: Memo 3 | H18: メモ３ | I18: E | K18: E | M18: E
A19: 10 | D19: del_flg | E19: #MA.FLG | G19: Logical delete | H19: 論理削除 | I19: E | K19: E | M19: E
A20: 10 | D20: upd_cntr | E20: #MA.UPD_CNT | G20: Update counter | H20: 更新カウンタ | I20: E | K20: E | M20: E
D21: 詳細 :

Sheet Del01
A1: * | B1: * | D1: L | E1: 1
A2: * | D2: オペレーション実装仕様書 Operation Specification Implementation Sheet | E2: ModuleID : | F2: =IF(LogicCommon!C2="","",LogicCommon!C2) -> MA | G2: LogicID : | H2: =IF(LogicCommon!E2="","",LogicCommon!E2) -> MABGL0320 | I2: Ope.ID : | J2: Del01 | K2: Pj.ID : | L2: =IF(LogicCommon!G2="","",LogicCommon!G2) -> MC | M2: Ope.Body : | N2: "mcframe.serverMAUD.MAUDL6010.MAUDL_RLDeleter"
A3: * | D3: =IF(LogicCommon!A3="","",LogicCommon!A3) | E3: SubModuleID : | F3: =IF(LogicCommon!C3="","",LogicCommon!C3) -> MABG | G3: LogicClass : | H3: =IF(LogicCommon!E3="","",LogicCommon!E3) -> MABGL_AlcOtherReg | I3: Ope.Method : | J3: @ | K3: SuperClassPj.ID : | L3: =IF(LogicCommon!G3="","",LogicCommon!G3) | M3: ReportID : | O3: Gene.Type : | P3: ALL
A4: * | E4: Version : | F4: 000000 | G4: LogicName : | H4: =IF(LogicCommon!E4="","",LogicCommon!E4) -> 任意基準値配賦マスタ登録 | I4: Ope.Name : | J4: 削除 | K4: SuperLogicID : | L4: =IF(LogicCommon!G4="","",LogicCommon!G4) -> MA.MAUDL5010
A5: * | E5: ACType :
A6: * | D6: 概要 : | E6: 削除処理を行う | L6: ID | N6: ID
A7: # | I7: U | K7: o | L7: CALL_OPE01.chk01 | M7: o | N7: CALL_OPE01.del01
A8: # | D8: ブロック名 Block Name | E8: 型 Type | G8: super/share | H8: 対象ブロック名 Target Block Name | K8: TargetName | L8: OPE.MA.MABGL0320.AlcOther_DelChk01 | M8: TargetName | N8: OPE.MA.MABGL0320.AlcOther_Del01 | Q8: ブロック備考 Block Remarks
A9: # | D9: 項目名 Field Name | E9: 型 Type | F9: 桁 Digits | G9: フルネーム Full Name | H9: 日本語名 Japanese Name | I9: 上り項目 Request Message Field | J9: 下り項目 Response Message Field | O9: 条件および編集方法 Conditions and Editing Methods | Q9: 項目備考 Field Remarks
A10: # | K10: 上り項目 Request Message Field | L10: 下り項目 Response Message Field | M10: 上り項目 Request Message Field | N10: 下り項目 Response Message Field
A11: 10 | B11: * | D11: Del01_Dtl1 | E11: L | G11: $share$ | H11: MA.MABGL0320.AlcOther_Del01.AlcOther_Del01_Dtl | K11: AlcOther_DelChk01_Dtl | M11: AlcOther_Del01_Dtl
A12: 10 | D12: alc_ptn_cd | E12: #MA.ALC_PTN_CD | G12: Allocation pattern cd. | H12: 配賦パタンＣＤ | I12: E | K12: E | M12: E
A13: 10 | D13: alc_val_typ | E13: #MA.ALC_VAL_TYP | G13: Allocation value type | H13: 配賦基準値区分 | I13: E | K13: E | M13: E
A14: 10 | D14: term | E14: #MA.YM | G14: Term | H14: 期 | I14: E | K14: E | M14: E
A15: 10 | D15: upd_cntr | E15: #MA.UPD_CNT | G15: Update counter | H15: 更新カウンタ | I15: E | K15: E | M15: E
D16: 詳細 :

Sheet 来歴
A1: 変更来歴
A3: Rev. | H3: 修正番号 | O3: 変更内容 | AQ3: 変更箇所
A4: 1 | O4: 初版
A5: 1.1 | O5: 英語の名称を追記 | AQ5: 全般
