Workbook

Sheet LogicCommon
A2: ロジック共通定義 | B2: ModuleID : | C2: MA | D2: LogicID : | E2: MABGL0420 | F2: Pj.ID : | G2: MC
B3: SubModuleID : | C3: MABG | D3: LogicClass : | E3: MABGL_RptConfReg | F3: SuperClassPj.ID :
D4: LogicName : | E4: 原価レポート構成マスタ登録 | F4: SuperLogicID : | G4: MA.MAUDL5010
A5: 概要 :
A6: 詳細 :

Sheet RptConf_UpdChk01
A1: * | B1: * | D1: L | E1: 1
A2: * | D2: オペレーション実装仕様書 Operation Specification Implementation Sheet | E2: ModuleID : | F2: =IF(LogicCommon!C2="","",LogicCommon!C2) -> MA | G2: LogicID : | H2: =IF(LogicCommon!E2="","",LogicCommon!E2) -> MABGL0420 | I2: Ope.ID : | J2: RptConf_UpdChk01 | K2: Pj.ID : | L2: =IF(LogicCommon!G2="","",LogicCommon!G2) -> MC | M2: Ope.Body : | N2: =L4 & ".Checker" -> MA.MAUDL5010.Checker
A3: * | D3: =IF(LogicCommon!A3="","",LogicCommon!A3) | E3: SubModuleID : | F3: =IF(LogicCommon!C3="","",LogicCommon!C3) -> MABG | G3: LogicClass : | H3: =IF(LogicCommon!E3="","",LogicCommon!E3) -> MABGL_RptConfReg | I3: Ope.Method : | J3: @ | K3: SuperClassPj.ID : | L3: =IF(LogicCommon!G3="","",LogicCommon!G3) | M3: ReportID : | O3: Gene.Type : | P3: ALL
A4: * | E4: Version : | F4: 000000 | G4: LogicName : | H4: =IF(LogicCommon!E4="","",LogicCommon!E4) -> 原価レポート構成マスタ登録 | I4: Ope.Name : | J4: 登録前チェック | K4: SuperLogicID : | L4: =IF(LogicCommon!G4="","",LogicCommon!G4) -> MA.MAUDL5010
A5: * | E5: ACType :
A6: * | D6: 概要 : | E6: 原価レポート構成マスタを登録する前のチェックを行う | R6: ID
A7: # | I7: U | K7: K | L7: K | M7: K | N7: K | O7: K | P7: K | Q7: o
A8: # | D8: ブロック名 Block Name | E8: 型 Type | G8: super/share | H8: 対象ブロック名 Target Block Name | K8: REQUIRED | L8: CHK_NUM | M8: CONST | N8: LIST_LOGIC | O8: LIST_OUT | P8: LIST_OUT_BASE | Q8: TargetName | U8: ブロック備考 Block Remarks
A9: # | D9: 項目名 Field Name | E9: 型 Type | F9: 桁 Digits | G9: フルネーム Full Name | H9: 日本語名 Japanese Name | I9: 上り項目 Request Message Field | J9: 下り項目 Response Message Field | S9: 条件および編集方法 Conditions and Editing Methods | U9: 項目備考 Field Remarks
A10: # | Q10: 上り項目 Request Message Field | R10: 下り項目 Response Message Field
A11: 10 | B11: * | D11: RptConf_UpdChk01_Dtl | E11: L | G11: $super$ | H11: DBC:MA.MAM_RPT_CONF
A12: 10 | D12: rpt_ptn_cd | E12: #MA.RPT_PTN_CD | G12: Report pattern cd. | H12: レポートパタンＣＤ | I12: E | K12: E | N12: MA.MAUAL0010.RptPtn
A13: 10 | D13: rpt_row_cd | E13: #MA.RPT_ROW_CD | G13: Report row cd. | H13: レポート行ＣＤ | I13: E | K13: E
A14: 10 | D14: rpt_pre_word | E14: #MA.RPT_PRE_WORD | G14: Prefix | H14: 接頭語 | I14: E
A15: 10 | D15: rpt_row_nm | E15: #MA.RPT_ROW_NM | G15: Standard Report row name | H15: 標準レポート行名 | I15: E | K15: E
A16: 10 | D16: rpt_seq | E16: #MA.INT3 | G16: Display order | H16: 表示順 | I16: E | K16: E
A17: 10 | D17: sml_flg | E17: #MA.FLG | G17: Aggregation row | H17: 集計行 | I17: E
A18: 10 | D18: hdn_flg | E18: #MA.FLG | G18: Hide | H18: 非表示 | I18: E
A19: 10 | D19: rpt_tgt_typ | E19: #MA.RPT_TGT_TYP | G19: Report type | H19: レポート対象区分 | I19: E | M19: MAC_RPT_TGT_TYP
A20: 10 | D20: cost_io_typ | E20: #MA.COST_IO_TYP | G20: Cost GR/GI type | H20: 原価入出庫区分 | I20: E | M20: MAC_COST_IO_TYP
A21: 10 | D21: asst_typ | E21: #MA.ASST_TYP | G21: Asset type | H21: 資産区分 | I21: E | M21: MAC_ASST_TYP
A22: 10 | D22: std_flg | E22: #MA.FLG | G22: Standard | H22: 標準 | I22: E
A23: 10 | D23: qty_unit_typ | E23: #MA.QTY_UNIT_TYP | G23: Quantity unit type | H23: 数量単位区分 | I23: E | M23: MAC_QTY_UNIT_TYP
A24: 10 | D24: alc_ac_grp_cd1 | E24: #MA.ALC_AC_GRP_CD | G24: Allocation account group cd. 1 | H24: 配賦科目グループＣＤ１ | I24: E | N24: MA.MAUAL0010.AlcAcGrp1 | O24: alc_ac_grp_nm1 | P24: alc_ac_grp_nm
A25: 10 | D25: alc_ac_grp_cd2 | E25: #MA.ALC_AC_GRP_CD | G25: Allocation account group cd. 2 | H25: 配賦科目グループＣＤ２ | I25: E | N25: MA.MAUAL0010.AlcAcGrp2 | O25: alc_ac_grp_nm2 | P25: alc_ac_grp_nm
A26: 10 | D26: alc_ac_grp_cd3 | E26: #MA.ALC_AC_GRP_CD | G26: Allocation account group cd. 3 | H26: 配賦科目グループＣＤ３ | I26: E | N26: MA.MAUAL0010.AlcAcGrp3 | O26: alc_ac_grp_nm3 | P26: alc_ac_grp_nm
A27: 10 | D27: alc_ac_cd | E27: #MA.ALC_AC_CD | G27: Allocation account cd. | H27: 配賦科目ＣＤ | I27: E | N27: MA.MAUAL0010.AlcAc
A28: 10 | D28: ac_slip_typ | E28: #MA.AC_SLIP_TYP | G28: Accounting slip type | H28: 会計伝票区分 | I28: E | M28: MAC_AC_SLIP_TYP
A29: 10 | D29: ac_rsn_cd | E29: #MA.AC_RSN_CD | G29: Accounting reason cd. | H29: 会計理由ＣＤ | I29: E | N29: MA.MAUAL0010.AcRsn
A30: 10 | D30: itm_jnl_cd | E30: #MA.ITM_JNL_CD | G30: Item journal cd. | H30: 品目仕訳ＣＤ | I30: E | N30: MA.MAUAL0010.ItmJnl
A31: 10 | D31: itm_grp_cd1 | E31: #MA.ITM_GRP_CD | G31: Item classification cd. 1 | H31: 品目分類ＣＤ１ | I31: E | N31: MA.MAUAL0010.ItmGrp1 | O31: itm_grp_nm1 | P31: itm_grp_nm
A32: 10 | D32: itm_grp_cd2 | E32: #MA.ITM_GRP_CD | G32: Item classification cd. 2 | H32: 品目分類ＣＤ２ | I32: E | N32: MA.MAUAL0010.ItmGrp2 | O32: itm_grp_nm2 | P32: itm_grp_nm
A33: 10 | D33: itm_grp_cd3 | E33: #MA.ITM_GRP_CD | G33: Item classification cd. 3 | H33: 品目分類ＣＤ３ | I33: E | N33: MA.MAUAL0010.ItmGrp3 | O33: itm_grp_nm3 | P33: itm_grp_nm
A34: 10 | D34: itm_grp_cd4 | E34: #MA.ITM_GRP_CD | G34: Item classification cd. 4 | H34: 品目分類ＣＤ４ | I34: E | N34: MA.MAUAL0010.ItmGrp4 | O34: itm_grp_nm4 | P34: itm_grp_nm
A35: 10 | D35: itm_grp_cd5 | E35: #MA.ITM_GRP_CD | G35: Item classification cd. 5 | H35: 品目分類ＣＤ５ | I35: E | N35: MA.MAUAL0010.ItmGrp5 | O35: itm_grp_nm5 | P35: itm_grp_nm
A36: 10 | D36: itm_grp_cd6 | E36: #MA.ITM_GRP_CD | G36: Item classification cd. 6 | H36: 品目分類ＣＤ６ | I36: E | N36: MA.MAUAL0010.ItmGrp6 | O36: itm_grp_nm6 | P36: itm_grp_nm
A37: 10 | D37: itm_grp_cd7 | E37: #MA.ITM_GRP_CD | G37: Item classification cd. 7 | H37: 品目分類ＣＤ７ | I37: E | N37: MA.MAUAL0010.ItmGrp7 | O37: itm_grp_nm7 | P37: itm_grp_nm
A38: 10 | D38: itm_grp_cd8 | E38: #MA.ITM_GRP_CD | G38: Item classification cd. 8 | H38: 品目分類ＣＤ８ | I38: E | N38: MA.MAUAL0010.ItmGrp8 | O38: itm_grp_nm8 | P38: itm_grp_nm
A39: 10 | D39: itm_grp_cd9 | E39: #MA.ITM_GRP_CD | G39: Item classification cd. 9 | H39: 品目分類ＣＤ９ | I39: E | N39: MA.MAUAL0010.ItmGrp9 | O39: itm_grp_nm9 | P39: itm_grp_nm
A40: 10 | D40: itm_grp_cd10 | E40: #MA.ITM_GRP_CD | G40: Item classification cd. 10 | H40: 品目分類ＣＤ１０ | I40: E | N40: MA.MAUAL0010.ItmGrp10 | O40: itm_grp_nm10 | P40: itm_grp_nm
...

Sheet RptConf_Upd01
A1: * | B1: * | D1: L | E1: 1
A2: * | D2: オペレーション実装仕様書 Operation Specification Implementation Sheet | E2: ModuleID : | F2: =IF(LogicCommon!C2="","",LogicCommon!C2) -> MA | G2: LogicID : | H2: =IF(LogicCommon!E2="","",LogicCommon!E2) -> MABGL0420 | I2: Ope.ID : | J2: RptConf_Upd01 | K2: Pj.ID : | L2: =IF(LogicCommon!G2="","",LogicCommon!G2) -> MC | M2: Ope.Body : | N2: "mcframe.serverMAUD.MAUDL6020.MAUDL_LCLRLUpdater"
A3: * | D3: =IF(LogicCommon!A3="","",LogicCommon!A3) | E3: SubModuleID : | F3: =IF(LogicCommon!C3="","",LogicCommon!C3) -> MABG | G3: LogicClass : | H3: =IF(LogicCommon!E3="","",LogicCommon!E3) -> MABGL_RptConfReg | I3: Ope.Method : | J3: @ | K3: SuperClassPj.ID : | L3: =IF(LogicCommon!G3="","",LogicCommon!G3) | M3: ReportID : | O3: Gene.Type : | P3: ALL
A4: * | E4: Version : | F4: 000000 | G4: LogicName : | H4: =IF(LogicCommon!E4="","",LogicCommon!E4) -> 原価レポート構成マスタ登録 | I4: Ope.Name : | J4: 登録処理 | K4: SuperLogicID : | L4: =IF(LogicCommon!G4="","",LogicCommon!G4) -> MA.MAUDL5010
A5: * | E5: ACType :
A6: * | D6: 概要 : | E6: 原価レポート構成マスタを登録する | L6: ID | N6: ID | P6: ID | R6: ID
A7: # | I7: U | K7: o | L7: UPDATE.updMaster | M7: o | N7: MAIN.chkMaster | O7: o | Q7: o
A8: # | D8: ブロック名 Block Name | E8: 型 Type | G8: super/share | H8: 対象ブロック名 Target Block Name | K8: TargetName | L8: DBC.MA.MAM_RPT_CONF | M8: TargetName | N8: DBC.MA.MAM_RPT_CONF | O8: TargetName | Q8: TargetName | U8: ブロック備考 Block Remarks
A9: # | D9: 項目名 Field Name | E9: 型 Type | F9: 桁 Digits | G9: フルネーム Full Name | H9: 日本語名 Japanese Name | I9: 上り項目 Request Message Field | J9: 下り項目 Response Message Field | S9: 条件および編集方法 Conditions and Editing Methods | U9: 項目備考 Field Remarks
A10: # | K10: 上り項目 Request Message Field | L10: 下り項目 Response Message Field | M10: 上り項目 Request Message Field | N10: 下り項目 Response Message Field | O10: 上り項目 Request Message Field | P10: 下り項目 Response Message Field | Q10: 上り項目 Request Message Field | R10: 下り項目 Response Message Field
A11: 10 | B11: * | D11: RptConf_Upd01_Dtl | E11: L | G11: $share$ | H11: MA.MABGL0420.RptConf_UpdChk01.RptConf_UpdChk01_Dtl | K11: L | M11: L
A12: 10 | D12: rpt_ptn_cd | E12: #MA.RPT_PTN_CD | G12: Report pattern cd. | H12: レポートパタンＣＤ | I12: E | K12: E | M12: E
A13: 10 | D13: rpt_row_cd | E13: #MA.RPT_ROW_CD | G13: Report row cd. | H13: レポート行ＣＤ | I13: E | K13: E | M13: E
A14: 10 | D14: rpt_pre_word | E14: #MA.RPT_PRE_WORD | G14: Prefix | H14: 接頭語 | I14: E | K14: E
A15: 10 | D15: rpt_row_nm | E15: #MA.RPT_ROW_NM | G15: Standard Report row name | H15: 標準レポート行名 | I15: E | K15: E
A16: 10 | D16: rpt_seq | E16: #MA.INT3 | G16: Display order | H16: 表示順 | I16: E | K16: E
A17: 10 | D17: sml_flg | E17: #MA.FLG | G17: Aggregation row | H17: 集計行 | I17: E | K17: E
A18: 10 | D18: hdn_flg | E18: #MA.FLG | G18: Hide | H18: 非表示 | I18: E | K18: E
A19: 10 | D19: rpt_tgt_typ | E19: #MA.RPT_TGT_TYP | G19: Report type | H19: レポート対象区分 | I19: E | K19: E
A20: 10 | D20: cost_io_typ | E20: #MA.COST_IO_TYP | G20: Cost GR/GI type | H20: 原価入出庫区分 | I20: E | K20: E
A21: 10 | D21: asst_typ | E21: #MA.ASST_TYP | G21: Asset type | H21: 資産区分 | I21: E | K21: E
A22: 10 | D22: std_flg | E22: #MA.FLG | G22: Standard | H22: 標準 | I22: E | K22: E
A23: 10 | D23: qty_unit_typ | E23: #MA.QTY_UNIT_TYP | G23: Quantity unit type | H23: 数量単位区分 | I23: E | K23: E
A24: 10 | D24: alc_ac_grp_cd1 | E24: #MA.ALC_AC_GRP_CD | G24: Allocation account group cd. 1 | H24: 配賦科目グループＣＤ１ | I24: E | K24: E
A25: 10 | D25: alc_ac_grp_cd2 | E25: #MA.ALC_AC_GRP_CD | G25: Allocation account group cd. 2 | H25: 配賦科目グループＣＤ２ | I25: E | K25: E
... A56: 10 | D56: upd_cntr | E56: #MA.UPD_CNT | G56: Update counter | H56: 更新カウンタ | I56: E | K56: E
D57: 詳細 :

Sheet RptConfLcl_UpdChk01
A1: * | B1: * | D1: L | E1: 1
A2: * | D2: オペレーション実装仕様書 Operation Specification Implementation Sheet | E2: ModuleID : | F2: MA | G2: LogicID : | H2: =IF(LogicCommon!E2="","",LogicCommon!E2) -> MABGL0420 | I2: Ope.ID : | J2: RptConfLcl_UpdChk01 | K2: Pj.ID : | L2: MC | M2: Ope.Body : | N2: =L4 & ".Checker" -> MA.MAUDL5010.Checker
A3: * | E3: SubModuleID : | F3: MABG | G3: LogicClass : | H3: =IF(LogicCommon!E3="","",LogicCommon!E3) -> MABGL_RptConfReg | I3: Ope.Method : | J3: @ | K3: SuperClassPj.ID : | M3: ReportID : | O3: Gene.Type : | P3: ALL
A4: * | E4: Version : | F4: 000000 | G4: LogicName : | H4: =IF(LogicCommon!E4="","",LogicCommon!E4) -> 原価レポート構成マスタ登録 | I4: Ope.Name : | J4: 登録前チェック(ロケール別情報) | K4: SuperLogicID : | L4: =IF(LogicCommon!G4="","",LogicCommon!G4) -> MA.MAUDL5010
A5: * | E5: ACType :
A6: * | D6: 概要 : | E6: 原価レポート構成マスタ(ロケール別情報)を登録する前のチェックを行う | Q6: ID
A7: # | I7: U | K7: K | P7: o | Q7: EXISTS.chk01
A8: # | D8: ブロック名 Block Name | E8: 型 Type | G8: super/share | H8: 対象ブロック名 Target Block Name | K8: REQUIRED | P8: TargetName | Q8: DBC.MA.MAM_RPT_CONF | T8: ブロック備考 Block Remarks
A9: # | D9: 項目名 Field Name | E9: 型 Type | F9: 桁 Digits | G9: フルネーム Full Name | H9: 日本語名 Japanese Name | I9: 上り項目 Request Message Field | J9: 下り項目 Response Message Field | R9: 条件および編集方法 Conditions and Editing Methods | T9: 項目備考 Field Remarks
A10: # | P10: 上り項目 Request Message Field | Q10: 下り項目 Response Message Field
A11: 10 | B11: * | D11: RptConfLcl_UpdChk01_Dtl | E11: L | G11: $super$ | H11: DBC:MA.MAM_RPT_CONF_LCL | P11: L
A12: 10 | D12: rpt_ptn_cd | E12: #MA.RPT_PTN_CD | G12: Report pattern cd. | H12: レポートパタンＣＤ | I12: E | K12: E | P12: E
A13: 10 | D13: rpt_row_cd | E13: #MA.RPT_ROW_CD | G13: Report row cd. | H13: レポート行ＣＤ | I13: E | K13: E | P13: E
A14: 10 | D14: lcl_cd | E14: #MA.LCL_CD | G14: Locale cd. | H14: ロケールＣＤ | I14: E | K14: E
A15: 10 | D15: rpt_row_nm | E15: #MA.RPT_ROW_NM | G15: Report row name | H15: レポート行名 | I15: E | K15: E
A16: 10 | D16: memo1 | E16: #MA.MST_MEMO1 | G16: Memo 1 | H16: メモ１ | I16: E
A17: 10 | D17: memo2 | E17: #MA.MST_MEMO2 | G17: Memo 2 | H17: メモ２ | I17: E
A18: 10 | D18: memo3 | E18: #MA.MST_MEMO3 | G18: Memo 3 | H18: メモ３ | I18: E
A19: 10 | D19: upd_cntr | E19: #MA.UPD_CNT | G19: Update counter | H19: 更新カウンタ | I19: E
D20: 詳細 :

Sheet RptConfLcl_Upd01
A1: * | B1: * | D1: L | E1: 1
A2: * | D2: オペレーション実装仕様書 Operation Specification Implementation Sheet | E2: ModuleID : | F2: MA | G2: LogicID : | H2: =IF(LogicCommon!E2="","",LogicCommon!E2) -> MABGL0420 | I2: Ope.ID : | J2: RptConfLcl_Upd01 | K2: Pj.ID : | L2: MC | M2: Ope.Body : | N2: "mcframe.serverMAUD.MAUDL6020.MAUDL_LCLRLUpdater"
A3: * | E3: SubModuleID : | F3: MABG | G3: LogicClass : | H3: =IF(LogicCommon!E3="","",LogicCommon!E3) -> MABGL_RptConfReg | I3: Ope.Method : | J3: @ | K3: SuperClassPj.ID : | M3: ReportID : | O3: Gene.Type : | P3: ALL
A4: * | E4: Version : | F4: 000000 | G4: LogicName : | H4: =IF(LogicCommon!E4="","",LogicCommon!E4) -> 原価レポート構成マスタ登録 | I4: Ope.Name : | J4: 登録処理(ロケール別情報) | K4: SuperLogicID : | L4: =IF(LogicCommon!G4="","",LogicCommon!G4) -> MA.MAUDL5010
A5: * | E5: ACType :
A6: * | D6: 概要 : | E6: 原価レポート構成マスタ(ロケール別情報)を登録する | L6: ID | N6: ID | P6: ID | R6: ID
A7: # | I7: U | K7: o | L7: UPDATE.updMaster | M7: o | N7: MAIN.chkMaster | O7: o | Q7: o
A8: # | D8: ブロック名 Block Name | E8: 型 Type | G8: super/share | H8: 対象ブロック名 Target Block Name | K8: TargetName | L8: DBC.MA.MAM_RPT_CONF_LCL | M8: TargetName | N8: DBC.MA.MAM_RPT_CONF_LCL | O8: TargetName | Q8: TargetName | U8: ブロック備考 Block Remarks
A9: # | D9: 項目名 Field Name | E9: 型 Type | F9: 桁 Digits | G9: フルネーム Full Name | H9: 日本語名 Japanese Name | I9: 上り項目 Request Message Field | J9: 下り項目 Response Message Field | S9: 条件および編集方法 Conditions and Editing Methods | U9: 項目備考 Field Remarks
A10: # | K10: 上り項目 Request Message Field | L10: 下り項目 Response Message Field | M10: 上り項目 Request Message Field | N10: 下り項目 Response Message Field | O10: 上り項目 Request Message Field | P10: 下り項目 Response Message Field | Q10: 上り項目 Request Message Field | R10: 下り項目 Response Message Field
A11: 10 | B11: * | D11: RptConfLcl_Upd01_Dtl | E11: L | G11: $share$ | H11: MA.MABGL0420.RptConfLcl_UpdChk01.RptConfLcl_UpdChk01_Dtl | K11: L | M11: L
A12: 10 | D12: rpt_ptn_cd | E12: #MA.RPT_PTN_CD | G12: Report pattern cd. | H12: レポートパタンＣＤ | I12: E | K12: E | M12: E
A13: 10 | D13: rpt_row_cd | E13: #MA.RPT_ROW_CD | G13: Report row cd. | H13: レポート行ＣＤ | I13: E | K13: E | M13: E
A14: 10 | D14: lcl_cd | E14: #MA.LCL_CD | G14: Locale cd. | H14: ロケールＣＤ | I14: E | K14: E | M14: E
A15: 10 | D15: rpt_row_nm | E15: #MA.RPT_ROW_NM | G15: Report row name | H15: レポート行名 | I15: E | K15: E
A16: 10 | D16: memo1 | E16: #MA.MST_MEMO1 | G16: Memo 1 | H16: メモ１ | I16: E | K16: E
A17: 10 | D17: memo2 | E17: #MA.MST_MEMO2 | G17: Memo 2 | H17: メモ２ | I17: E | K17: E
A18: 10 | D18: memo3 | E18: #MA.MST_MEMO3 | G18: Memo 3 | H18: メモ３ | I18: E | K18: E
A19: 10 | D19: upd_cntr | E19: #MA.UPD_CNT | G19: Update counter | H19: 更新カウンタ | I19: E | K19: E
D20: 詳細 :

Sheet RptConf_DelChk01
A1: * | B1: * | D1: L | E1: 1
A2: * | D2: オペレーション実装仕様書 Operation Specification Implementation Sheet | E2: ModuleID : | F2: =IF(LogicCommon!C2="","",LogicCommon!C2) -> MA | G2: LogicID : | H2: =IF(LogicCommon!E2="","",LogicCommon!E2) -> MABGL0420 | I2: Ope.ID : | J2: RptConf_DelChk01 | K2: Pj.ID : | L2: =IF(LogicCommon!G2="","",LogicCommon!G2) -> MC | M2: Ope.Body : | N2: =L4 & ".Checker" -> MA.MAUDL5010.Checker
A3: * | D3: =IF(LogicCommon!A3="","",LogicCommon!A3) | E3: SubModuleID : | F3: =IF(LogicCommon!C3="","",LogicCommon!C3) -> MABG | G3: LogicClass : | H3: =IF(LogicCommon!E3="","",LogicCommon!E3) -> MABGL_RptConfReg | I3: Ope.Method : | J3: @ | K3: SuperClassPj.ID : | L3: =IF(LogicCommon!G3="","",LogicCommon!G3) | M3: ReportID : | O3: Gene.Type : | P3: ALL
A4: * | E4: Version : | F4: 000000 | G4: LogicName : | H4: =IF(LogicCommon!E4="","",LogicCommon!E4) -> 原価レポート構成マスタ登録 | I4: Ope.Name : | J4: 削除前チェック | K4: SuperLogicID : | L4: =IF(LogicCommon!G4="","",LogicCommon!G4) -> MA.MAUDL5010
A5: * | E5: ACType :
A6: * | D6: 概要 : | E6: 原価レポート構成マスタ、原価レポート構成マスタ(ロケール別情報)を削除する前のチェックを行う | Q6: ID
A7: # | I7: U | K7: K | P7: o
A8: # | D8: ブロック名 Block Name | E8: 型 Type | G8: super/share | H8: 対象ブロック名 Target Block Name | K8: REQUIRED | P8: TargetName | T8: ブロック備考 Block Remarks
A9: # | D9: 項目名 Field Name | E9: 型 Type | F9: 桁 Digits | G9: フルネーム Full Name | H9: 日本語名 Japanese Name | I9: 上り項目 Request Message Field | J9: 下り項目 Response Message Field | R9: 条件および編集方法 Conditions and Editing Methods | T9: 項目備考 Field Remarks
A10: # | P10: 上り項目 Request Message Field | Q10: 下り項目 Response Message Field
A11: 10 | B11: * | D11: RptConf_DelChk01_Dtl | E11: L | G11: $super$ | H11: DBC:MA.MAM_RPT_CONF
A12: 10 | D12: rpt_ptn_cd | E12: #MA.RPT_PTN_CD | G12: Report pattern cd. | H12: レポートパタンＣＤ | I12: E | K12: E
A13: 10 | D13: rpt_row_cd | E13: #MA.RPT_ROW_CD | G13: Report row cd. | H13: レポート行ＣＤ | I13: E | K13: E
A14: 10 | D14: upd_cntr | E14: #MA.UPD_CNT | G14: Update counter | H14: 更新カウンタ | I14: E
D15: 詳細 :

Sheet RptConf_Del01
A1: * | B1: * | D1: L | E1: 1
A2: * | D2: オペレーション実装仕様書 Operation Specification Implementation Sheet | E2: ModuleID : | F2: =IF(LogicCommon!C2="","",LogicCommon!C2) -> MA | G2: LogicID : | H2: =IF(LogicCommon!E2="","",LogicCommon!E2) -> MABGL0420 | I2: Ope.ID : | J2: RptConf_Del01 | K2: Pj.ID : | L2: =IF(LogicCommon!G2="","",LogicCommon!G2) -> MC | M2: Ope.Body : | N2: "mcframe.serverMAUD.MAUDL6020.MAUDL_LCLRLDeleter"
A3: * | D3: =IF(LogicCommon!A3="","",LogicCommon!A3) | E3: SubModuleID : | F3: =IF(LogicCommon!C3="","",LogicCommon!C3) -> MABG | G3: LogicClass : | H3: =IF(LogicCommon!E3="","",LogicCommon!E3) -> MABGL_RptConfReg | I3: Ope.Method : | J3: @ | K3: SuperClassPj.ID : | L3: =IF(LogicCommon!G3="","",LogicCommon!G3) | M3: ReportID : | O3: Gene.Type : | P3: ALL
A4: * | E4: Version : | F4: 000000 | G4: LogicName : | H4: =IF(LogicCommon!E4="","",LogicCommon!E4) -> 原価レポート構成マスタ登録 | I4: Ope.Name : | J4: 削除処理 | K4: SuperLogicID : | L4: =IF(LogicCommon!G4="","",LogicCommon!G4) -> MA.MAUDL5010
A5: * | E5: ACType :
A6: * | D6: 概要 : | E6: 原価レポート構成マスタ、原価レポート構成マスタ(ロケール別情報)を削除する | L6: ID | N6: ID
A7: # | I7: U | K7: o | L7: UPDATE.updMaster1 | M7: o | N7: UPDATE.updMaster2
A8: # | D8: ブロック名 Block Name | E8: 型 Type | G8: super/share | H8: 対象ブロック名 Target Block Name | K8: TargetName | L8: DBC.MA.MAM_RPT_CONF | M8: TargetName | N8: DBC.MA.MAM_RPT_CONF_LCL | Q8: ブロック備考 Block Remarks
A9: # | D9: 項目名 Field Name | E9: 型 Type | F9: 桁 Digits | G9: フルネーム Full Name | H9: 日本語名 Japanese Name | I9: 上り項目 Request Message Field | J9: 下り項目 Response Message Field | O9: 条件および編集方法 Conditions and Editing Methods | Q9: 項目備考 Field Remarks
A10: # | K10: 上り項目 Request Message Field | L10: 下り項目 Response Message Field | M10: 上り項目 Request Message Field | N10: 下り項目 Response Message Field
A11: 10 | B11: * | D11: RptConf_Del01_Dtl | E11: L | G11: $share$ | H11: MA.MABGL0420.RptConf_DelChk01.RptConf_DelChk01_Dtl | K11: L | M11: L
A12: 10 | D12: rpt_ptn_cd | E12: #MA.RPT_PTN_CD | G12: Report pattern cd. | H12: レポートパタンＣＤ | I12: E | K12: E | M12: E
A13: 10 | D13: rpt_row_cd | E13: #MA.RPT_ROW_CD | G13: Report row cd. | H13: レポート行ＣＤ | I13: E | K13: E | M13: E
A14: 10 | D14: upd_cntr | E14: #MA.UPD_CNT | G14: Update counter | H14: 更新カウンタ | I14: E | K14: E
D15: 詳細 :

Sheet Srch01
A1: * | B1: * | D1: L | E1: 1
A2: * | D2: オペレーション実装仕様書 Operation Specification Implementation Sheet | E2: ModuleID : | F2: =IF(LogicCommon!C2="","",LogicCommon!C2) -> MA | G2: LogicID : | H2: =IF(LogicCommon!E2="","",LogicCommon!E2) -> MABGL0420 | I2: Ope.ID : | J2: Srch01 | K2: Pj.ID : | L2: =IF(LogicCommon!G2="","",LogicCommon!G2) -> MC | M2: Ope.Body : | N2: "mcframe.serverMAUD.MAUDL6020.MAUDL_LCLRLSearcher"
A3: * | D3: =IF(LogicCommon!A3="","",LogicCommon!A3) | E3: SubModuleID : | F3: =IF(LogicCommon!C3="","",LogicCommon!C3) -> MABG | G3: LogicClass : | H3: =IF(LogicCommon!E3="","",LogicCommon!E3) -> MABGL_RptConfReg | I3: Ope.Method : | J3: @ | K3: SuperClassPj.ID : | L3: =IF(LogicCommon!G3="","",LogicCommon!G3) | M3: ReportID : | O3: Gene.Type : | P3: ALL
A4: * | E4: Version : | F4: 000000 | G4: LogicName : | H4: =IF(LogicCommon!E4="","",LogicCommon!E4) -> 原価レポート構成マスタ登録 | I4: Ope.Name : | J4: 検索 | K4: SuperLogicID : | L4: =IF(LogicCommon!G4="","",LogicCommon!G4) -> MA.MAUDL5010
A5: * | E5: ACType :
A6: * | D6: 概要 : | E6: 検索処理を行う | M6: ID | O6: ID
A7: # | I7: U | K7: K | L7: o | M7: SELECT.c0 | N7: o | O7: SELECT_LCL.c1
A8: # | D8: ブロック名 Block Name | E8: 型 Type | G8: super/share | H8: 対象ブロック名 Target Block Name | K8: CONST | L8: TargetName | M8: DBC.MA.MAM_RPT_CONF | N8: TargetName | O8: DBC.MA.MAM_RPT_CONF_LCL | R8: ブロック備考 Block Remarks
A9: # | D9: 項目名 Field Name | E9: 型 Type | F9: 桁 Digits | G9: フルネーム Full Name | H9: 日本語名 Japanese Name | I9: 上り項目 Request Message Field | J9: 下り項目 Response Message Field | P9: 条件および編集方法 Conditions and Editing Methods | R9: 項目備考 Field Remarks
A10: # | L10: 上り項目 Request Message Field | M10: 下り項目 Response Message Field | N10: 上り項目 Request Message Field | O10: 下り項目 Response Message Field
A11: 10 | B11: * | D11: Srch01_Cnd | E11: R | L11: R
A12: 10 | D12: rpt_ptn_cd | E12: #MA.RPT_PTN_CD | G12: Report pattern cd. | H12: レポートパタンＣＤ | I12: E
A14: 20 | B14: * | D14: Srch01_Rslt1 | E14: L | M14: L
A15: 20 | D15: del_flg | E15: #MA.FLG | G15: Logical delete | H15: 論理削除 | J15: E | M15: E
A16: 20 | D16: rpt_ptn_cd | E16: #MA.RPT_PTN_CD | G16: Report pattern cd. | H16: レポートパタンＣＤ | J16: E | M16: E
A17: 20 | D17: rpt_ptn_nm | E17: #MA.RPT_PTN_NM | G17: Report pattern name | H17: レポートパタン名 | J17: E | M17: E
A18: 20 | D18: rpt_row_cd | E18: #MA.RPT_ROW_CD | G18: Report row cd. | H18: レポート行ＣＤ | J18: E | M18: E
A19: 20 | D19: rpt_pre_word | E19: #MA.RPT_PRE_WORD | G19: Prefix | H19: 接頭語 | J19: E | M19: E
A20: 20 | D20: rpt_row_nm_lcl | E20: #MA.RPT_ROW_NM | G20: Report row name | H20: レポート行名 | J20: E | M20: rpt_row_nm
A21: 20 | D21: rpt_row_nm | E21: #MA.RPT_ROW_NM | G21: Standard Report row name | H21: 標準レポート行名 | J21: E | M21: base_rpt_row_nm
A22: 20 | D22: rpt_seq | E22: #MA.INT3 | G22: Display order | H22: 表示順 | J22: E | M22: E
A23: 20 | D23: sml_flg | E23: #MA.FLG | G23: Aggregation row | H23: 集計行 | J23: E | M23: E
A24: 20 | D24: hdn_flg | E24: #MA.FLG | G24: Hide | H24: 非表示 | J24: E | M24: E
A25: 20 | D25: rpt_tgt_typ | E25: #MA.RPT_TGT_TYP | G25: Report type | H25: レポート対象区分 | J25: E | K25: MAC_RPT_TGT_TYP | M25: E
A26: 20 | D26: rpt_tgt_typ_nm | E26: #MA.RPT_TGT_TYP_NM | G26: Report type name | H26: レポート対象区分名 | J26: E
A27: 20 | D27: cost_io_typ | E27: #MA.COST_IO_TYP | G27: Cost GR/GI type | H27: 原価入出庫区分 | J27: E | K27: MAC_COST_IO_TYP | M27: E
A28: 20 | D28: cost_io_typ_nm | E28: #MA.COST_IO_TYP_NM | G28: Cost GR/GI type name | H28: 原価入出庫区分名 | J28: E
A29: 20 | D29: asst_typ | E29: #MA.ASST_TYP | G29: Asset type | H29: 資産区分 | J29: E | K29: MAC_ASST_TYP | M29: E
A30: 20 | D30: asst_typ_nm | E30: #MA.ASST_TYP_NM | G30: Asset type name | H30: 資産区分名 | J30: E
A31: 20 | D31: std_flg | E31: #MA.FLG | G31: Standard | H31: 標準 | J31: E | M31: E
A32: 20 | D32: qty_unit_typ | E32: #MA.QTY_UNIT_TYP | G32: Quantity unit type | H32: 数量単位区分 | J32: E | K32: MAC_QTY_UNIT_TYP | M32: E
A33: 20 | D33: qty_unit_typ_nm | E33: #MA.QTY_UNIT_TYP_NM | G33: Quantity unit type name | H33: 数量単位区分名 | J33: E
A34: 20 | D34: alc_ac_grp_cd1 | E34: #MA.ALC_AC_GRP_CD | G34: Allocation account group cd. 1 | H34: 配賦科目グループＣＤ１ | J34: E | M34: E
A35: 20 | D35: alc_ac_grp_nm1 | E35: #MA.ALC_AC_GRP_NM | G35: Allocation account group name 1 | H35: 配賦科目グループ名１ | J35: E | M35: E
A36: 20 | D36: alc_ac_grp_cd2 | E36: #MA.ALC_AC_GRP_CD | G36: Allocation account group cd. 2 | H36: 配賦科目グループＣＤ２ | J36: E | M36: E
A37: 20 | D37: alc_ac_grp_nm2 | E37: #MA.ALC_AC_GRP_NM | G37: Allocation account group name 2 | H37: 配賦科目グループ名２ | J37: E | M37: E
A38: 20 | D38: alc_ac_grp_cd3 | E38: #MA.ALC_AC_GRP_CD | G38: Allocation account group cd. 3 | H38: 配賦科目グループＣＤ３ | J38: E | M38: E
A39: 20 | D39: alc_ac_grp_nm3 | E39: #MA.ALC_AC_GRP_NM | G39: Allocation account group name 3 | H39: 配賦科目グループ名３ | J39: E | M39: E
A40: 20 | D40: alc_ac_cd | E40: #MA.ALC_AC_CD | G40: Allocation account cd. | H40: 配賦科目ＣＤ | J40: E | M40: E
A41: 20 | D41: alc_ac_nm | E41: #MA.ALC_AC_NM | G41: Allocation account name | H41: 配賦科目名 | J41: E | M41: E
...

Sheet Upd01
A1: * | B1: * | D1: L | E1: 1
A2: * | D2: オペレーション実装仕様書 Operation Specification Implementation Sheet | E2: ModuleID : | F2: =IF(LogicCommon!C2="","",LogicCommon!C2) -> MA | G2: LogicID : | H2: =IF(LogicCommon!E2="","",LogicCommon!E2) -> MABGL0420 | I2: Ope.ID : | J2: Upd01 | K2: Pj.ID : | L2: =IF(LogicCommon!G2="","",LogicCommon!G2) -> MC | M2: Ope.Body : | N2: "mcframe.serverMAUD.MAUDL6020.MAUDL_LCLRLUpdater"
A3: * | D3: =IF(LogicCommon!A3="","",LogicCommon!A3) | E3: SubModuleID : | F3: =IF(LogicCommon!C3="","",LogicCommon!C3) -> MABG | G3: LogicClass : | H3: =IF(LogicCommon!E3="","",LogicCommon!E3) -> MABGL_RptConfReg | I3: Ope.Method : | J3: @ | K3: SuperClassPj.ID : | L3: =IF(LogicCommon!G3="","",LogicCommon!G3) | M3: ReportID : | O3: Gene.Type : | P3: ALL
A4: * | E4: Version : | F4: 000000 | G4: LogicName : | H4: =IF(LogicCommon!E4="","",LogicCommon!E4) -> 原価レポート構成マスタ登録 | I4: Ope.Name : | J4: 登録 | K4: SuperLogicID : | L4: =IF(LogicCommon!G4="","",LogicCommon!G4) -> MA.MAUDL5010
A5: * | E5: ACType :
A6: * | D6: 概要 : | E6: 登録処理を行う | L6: ID | N6: ID | P6: ID | R6: ID
A7: # | I7: U | K7: o | L7: CALL_OPE01.chk01 | M7: o | N7: CALL_OPE01.upd01 | O7: o | P7: CALL_OPE02.chk02 | Q7: o | R7: CALL_OPE02.upd02
A8: # | D8: ブロック名 Block Name | E8: 型 Type | G8: super/share | H8: 対象ブロック名 Target Block Name | K8: TargetName | L8: OPE.MA.MABGL0420.RptConf_UpdChk01 | M8: TargetName | N8: OPE.MA.MABGL0420.RptConf_Upd01 | O8: TargetName | P8: OPE.MA.MABGL0420.RptConfLcl_UpdChk01 | Q8: TargetName | R8: OPE.MA.MABGL0420.RptConfLcl_Upd01 | U8: ブロック備考 Block Remarks
A9: # | D9: 項目名 Field Name | E9: 型 Type | F9: 桁 Digits | G9: フルネーム Full Name | H9: 日本語名 Japanese Name | I9: 上り項目 Request Message Field | J9: 下り項目 Response Message Field | S9: 条件および編集方法 Conditions and Editing Methods | U9: 項目備考 Field Remarks
A10: # | K10: 上り項目 Request Message Field | L10: 下り項目 Response Message Field | M10: 上り項目 Request Message Field | N10: 下り項目 Response Message Field | O10: 上り項目 Request Message Field | P10: 下り項目 Response Message Field | Q10: 上り項目 Request Message Field | R10: 下り項目 Response Message Field
A11: 10 | B11: * | D11: Upd01_Dtl1 | E11: L | G11: $share$ | H11: MA.MABGL0420.RptConf_Upd01.RptConf_Upd01_Dtl | K11: RptConf_UpdChk01_Dtl | M11: RptConf_Upd01_Dtl
A12: 10 | D12: rpt_ptn_cd | E12: #MA.RPT_PTN_CD | G12: Report pattern cd. | H12: レポートパタンＣＤ | I12: E | K12: E | M12: E
A13: 10 | D13: rpt_row_cd | E13: #MA.RPT_ROW_CD | G13: Report row cd. | H13: レポート行ＣＤ | I13: E | K13: E | M13: E
A14: 10 | D14: rpt_pre_word | E14: #MA.RPT_PRE_WORD | G14: Prefix | H14: 接頭語 | I14: E | K14: E | M14: E
A15: 10 | D15: rpt_row_nm | E15: #MA.RPT_ROW_NM | G15: Standard Report row name | H15: 標準レポート行名 | I15: E | K15: E | M15: E
A16: 10 | D16: rpt_seq | E16: #MA.INT3 | G16: Display order | H16: 表示順 | I16: E | K16: E | M16: E
A17: 10 | D17: sml_flg | E17: #MA.FLG | G17: Aggregation row | H17: 集計行 | I17: E | K17: E | M17: E
A18: 10 | D18: hdn_flg | E18: #MA.FLG | G18: Hide | H18: 非表示 | I18: E | K18: E | M18: E
A19: 10 | D19: rpt_tgt_typ | E19: #MA.RPT_TGT_TYP | G19: Report type | H19: レポート対象区分 | I19: E | K19: E | M19: E
A20: 10 | D20: cost_io_typ | E20: #MA.COST_IO_TYP | G20: Cost GR/GI type | H20: 原価入出庫区分 | I20: E | K20: E | M20: E
A21: 10 | D21: asst_typ | E21: #MA.ASST_TYP | G21: Asset type | H21: 資産区分 | I21: E | K21: E | M21: E
A22: 10 | D22: std_flg | E22: #MA.FLG | G22: Standard | H22: 標準 | I22: E | K22: E | M22: E
A23: 10 | D23: qty_unit_typ | E23: #MA.QTY_UNIT_TYP | G23: Quantity unit type | H23: 数量単位区分 | I23: E | K23: E | M23: E
... A56: 10 | D56: upd_cntr | E56: #MA.UPD_CNT | G56: Update counter | H56: 更新カウンタ | I56: E | K56: E | M56: E
A58: 20 | B58: * | D58: Upd01_Dtl2 | E58: L | G58: $share$ | H58: MA.MABGL0420.RptConfLcl_Upd01.RptConfLcl_Upd01_Dtl | O58: RptConfLcl_UpdChk01_Dtl | Q58: RptConfLcl_Upd01_Dtl
A59: 20 | D59: rpt_ptn_cd | E59: #MA.RPT_PTN_CD | G59: Report pattern cd. | H59: レポートパタンＣＤ | I59: E | O59: E | Q59: E
A60: 20 | D60: rpt_row_cd | E60: #MA.RPT_ROW_CD | G60: Report row cd. | H60: レポート行ＣＤ | I60: E | O60: E | Q60: E
A61: 20 | D61: lcl_cd | E61: #MA.LCL_CD | G61: Locale cd. | H61: ロケールＣＤ | I61: E | O61: E | Q61: E
A62: 20 | D62: rpt_row_nm | E62: #MA.RPT_ROW_NM | G62: Report row name | H62: レポート行名 | I62: E | O62: E | Q62: E
A63: 20 | D63: memo1 | E63: #MA.MST_MEMO1 | G63: Memo 1 | H63: メモ１ | I63: E | O63: E | Q63: E
A64: 20 | D64: memo2 | E64: #MA.MST_MEMO2 | G64: Memo 2 | H64: メモ２ | I64: E | O64: E | Q64: E
A65: 20 | D65: memo3 | E65: #MA.MST_MEMO3 | G65: Memo 3 | H65: メモ３ | I65: E | O65: E | Q65: E
A66: 20 | D66: upd_cntr | E66: #MA.UPD_CNT | G66: Update counter | H66: 更新カウンタ | I66: E | O66: E | Q66: E
D67: 詳細 :

Sheet Del01
A1: * | B1: * | D1: L | E1: 1
A2: * | D2: オペレーション実装仕様書 Operation Specification Implementation Sheet | E2: ModuleID : | F2: =IF(LogicCommon!C2="","",LogicCommon!C2) -> MA | G2: LogicID : | H2: =IF(LogicCommon!E2="","",LogicCommon!E2) -> MABGL0420 | I2: Ope.ID : | J2: Del01 | K2: Pj.ID : | L2: =IF(LogicCommon!G2="","",LogicCommon!G2) -> MC | M2: Ope.Body : | N2: "mcframe.serverMAUD.MAUDL6020.MAUDL_LCLRLDeleter"
A3: * | D3: =IF(LogicCommon!A3="","",LogicCommon!A3) | E3: SubModuleID : | F3: =IF(LogicCommon!C3="","",LogicCommon!C3) -> MABG | G3: LogicClass : | H3: =IF(LogicCommon!E3="","",LogicCommon!E3) -> MABGL_RptConfReg | I3: Ope.Method : | J3: @ | K3: SuperClassPj.ID : | L3: =IF(LogicCommon!G3="","",LogicCommon!G3) | M3: ReportID : | O3: Gene.Type : | P3: ALL
A4: * | E4: Version : | F4: 000000 | G4: LogicName : | H4: =IF(LogicCommon!E4="","",LogicCommon!E4) -> 原価レポート構成マスタ登録 | I4: Ope.Name : | J4: 削除 | K4: SuperLogicID : | L4: =IF(LogicCommon!G4="","",LogicCommon!G4) -> MA.MAUDL5010
A5: * | E5: ACType :
A6: * | D6: 概要 : | E6: 削除処理を行う | L6: ID | N6: ID
A7: # | I7: U | K7: o | L7: CALL_OPE01.chk01 | M7: o | N7: CALL_OPE01.del01
A8: # | D8: ブロック名 Block Name | E8: 型 Type | G8: super/share | H8: 対象ブロック名 Target Block Name | K8: TargetName | L8: OPE.MA.MABGL0420.RptConf_DelChk01 | M8: TargetName | N8: OPE.MA.MABGL0420.RptConf_Del01 | Q8: ブロック備考 Block Remarks
A9: # | D9: 項目名 Field Name | E9: 型 Type | F9: 桁 Digits | G9: フルネーム Full Name | H9: 日本語名 Japanese Name | I9: 上り項目 Request Message Field | J9: 下り項目 Response Message Field | O9: 条件および編集方法 Conditions and Editing Methods | Q9: 項目備考 Field Remarks
A10: # | K10: 上り項目 Request Message Field | L10: 下り項目 Response Message Field | M10: 上り項目 Request Message Field | N10: 下り項目 Response Message Field
A11: 10 | B11: * | D11: Del01_Dtl1 | E11: L | G11: $share$ | H11: MA.MABGL0420.RptConf_Del01.RptConf_Del01_Dtl | K11: RptConf_DelChk01_Dtl | M11: RptConf_Del01_Dtl
A12: 10 | D12: rpt_ptn_cd | E12: #MA.RPT_PTN_CD | G12: Report pattern cd. | H12: レポートパタンＣＤ | I12: E | K12: E | M12: E
A13: 10 | D13: rpt_row_cd | E13: #MA.RPT_ROW_CD | G13: Report row cd. | H13: レポート行ＣＤ | I13: E | K13: E | M13: E
A14: 10 | D14: upd_cntr | E14: #MA.UPD_CNT | G14: Update counter | H14: 更新カウンタ | I14: E | K14: E | M14: E
D15: 詳細 :

Sheet 来歴
A1: 変更来歴
A3: Rev. | H3: 修正番号 | O3: 変更内容 | AQ3: 変更箇所
A4: 1 | O4: 初版
A5: 1.1 | O5: 英語の名称を追記 | AQ5: 全般
