Workbook

Sheet LogicCommon
A2: ロジック共通定義 | B2: ModuleID : | C2: MA | D2: LogicID : | E2: MABGL0070 | F2: Pj.ID : | G2: MC
B3: SubModuleID : | C3: MABG | D3: LogicClass : | E3: MABGL_GrpWgReg | F3: SuperClassPj.ID :
D4: LogicName : | E4: 計算グループＷＧマスタ登録 | F4: SuperLogicID : | G4: MA.MAUDL5010
A5: 概要 :
A6: 詳細 :

Sheet GrpWg_UpdChk01
A1: * | B1: * | D1: L | E1: 1
A2: * | D2: オペレーション実装仕様書 Operation Specification Implementation Sheet | E2: ModuleID : | F2: =IF(LogicCommon!C2="","",LogicCommon!C2) -> MA | G2: LogicID : | H2: =IF(LogicCommon!E2="","",LogicCommon!E2) -> MABGL0070 | I2: Ope.ID : | J2: GrpWg_UpdChk01 | K2: Pj.ID : | L2: =IF(LogicCommon!G2="","",LogicCommon!G2) -> MC | M2: Ope.Body : | N2: =L4 & ".Checker" -> MA.MAUDL5010.Checker
A3: * | D3: =IF(LogicCommon!A3="","",LogicCommon!A3) | E3: SubModuleID : | F3: =IF(LogicCommon!C3="","",LogicCommon!C3) -> MABG | G3: LogicClass : | H3: =IF(LogicCommon!E3="","",LogicCommon!E3) -> MABGL_GrpWgReg | I3: Ope.Method : | J3: @ | K3: SuperClassPj.ID : | L3: =IF(LogicCommon!G3="","",LogicCommon!G3) | M3: ReportID : | O3: Gene.Type : | P3: ALL
A4: * | E4: Version : | F4: 000000 | G4: LogicName : | H4: =IF(LogicCommon!E4="","",LogicCommon!E4) -> 計算グループＷＧマスタ登録 | I4: Ope.Name : | J4: 登録前チェック | K4: SuperLogicID : | L4: =IF(LogicCommon!G4="","",LogicCommon!G4) -> MA.MAUDL5010
A5: * | E5: ACType :
A6: * | D6: 概要 : | E6: 計算グループＷＧマスタを登録する前のチェックを行う | Q6: ID | S6: ID
A7: # | I7: U | K7: K | L7: K | M7: K | P7: o | R7: o
A8: # | D8: ブロック名 Block Name | E8: 型 Type | G8: super/share | H8: 対象ブロック名 Target Block Name | K8: REQUIRED | L8: LIST_LOGIC | M8: SMALL_LARGE | P8: TargetName | R8: TargetName | V8: ブロック備考 Block Remarks
A9: # | D9: 項目名 Field Name | E9: 型 Type | F9: 桁 Digits | G9: フルネーム Full Name | H9: 日本語名 Japanese Name | I9: 上り項目 Request Message Field | J9: 下り項目 Response Message Field | T9: 条件および編集方法 Conditions and Editing Methods | V9: 項目備考 Field Remarks
A10: # | P10: 上り項目 Request Message Field | Q10: 下り項目 Response Message Field | R10: 上り項目 Request Message Field | S10: 下り項目 Response Message Field
A11: 10 | B11: * | D11: GrpWg_UpdChk01_Dtl | E11: L | G11: $super$ | H11: DBC:MA.MAM_GRP_WG | P11: L | R11: L
A12: 10 | D12: calc_grp_cd | E12: #MA.CALC_GRP_CD | G12: Calculation group cd. | H12: 計算グループＣＤ | I12: E | K12: E | L12: MA.MAUAL0010.CalcGrp
A13: 10 | D13: wg_cd | E13: #MA.WG_CD | G13: WG cd. | H13: ワーキンググループＣＤ | I13: E | K13: E | L13: MA.MAUAL0010.CostWg
A14: 10 | D14: wg_prio | E14: #MA.INT2 | G14: Priority | H14: 優先順位 | I14: E | M14: 0:99
A15: 10 | D15: memo1 | E15: #MA.MST_MEMO1 | G15: Memo 1 | H15: メモ１ | I15: E
A16: 10 | D16: memo2 | E16: #MA.MST_MEMO2 | G16: Memo 2 | H16: メモ２ | I16: E
A17: 10 | D17: memo3 | E17: #MA.MST_MEMO3 | G17: Memo 3 | H17: メモ３ | I17: E
A18: 10 | D18: del_flg | E18: #MA.FLG | G18: Logical delete | H18: 論理削除 | I18: E
A19: 10 | D19: upd_cntr | E19: #MA.UPD_CNT | G19: Update counter | H19: 更新カウンタ | I19: E
D20: 詳細 :

Sheet GrpWg_Upd01
A1: * | B1: * | D1: L | E1: 1
A2: * | D2: オペレーション実装仕様書 Operation Specification Implementation Sheet | E2: ModuleID : | F2: =IF(LogicCommon!C2="","",LogicCommon!C2) -> MA | G2: LogicID : | H2: =IF(LogicCommon!E2="","",LogicCommon!E2) -> MABGL0070 | I2: Ope.ID : | J2: GrpWg_Upd01 | K2: Pj.ID : | L2: =IF(LogicCommon!G2="","",LogicCommon!G2) -> MC | M2: Ope.Body : | N2: "mcframe.serverMAUD.MAUDL6010.MAUDL_RLUpdater"
A3: * | D3: =IF(LogicCommon!A3="","",LogicCommon!A3) | E3: SubModuleID : | F3: =IF(LogicCommon!C3="","",LogicCommon!C3) -> MABG | G3: LogicClass : | H3: =IF(LogicCommon!E3="","",LogicCommon!E3) -> MABGL_GrpWgReg | I3: Ope.Method : | J3: @ | K3: SuperClassPj.ID : | L3: =IF(LogicCommon!G3="","",LogicCommon!G3) | M3: ReportID : | O3: Gene.Type : | P3: ALL
A4: * | E4: Version : | F4: 000000 | G4: LogicName : | H4: =IF(LogicCommon!E4="","",LogicCommon!E4) -> 計算グループＷＧマスタ登録 | I4: Ope.Name : | J4: 登録処理 | K4: SuperLogicID : | L4: =IF(LogicCommon!G4="","",LogicCommon!G4) -> MA.MAUDL5010
A5: * | E5: ACType :
A6: * | D6: 概要 : | E6: 計算グループＷＧマスタを登録する | L6: ID | N6: ID | P6: ID | R6: ID
A7: # | I7: U | K7: o | L7: UPDATE.updMaster | M7: o | N7: MAIN.chkMaster | O7: o | Q7: o
A8: # | D8: ブロック名 Block Name | E8: 型 Type | G8: super/share | H8: 対象ブロック名 Target Block Name | K8: TargetName | L8: DBC.MA.MAM_GRP_WG | M8: TargetName | N8: DBC.MA.MAM_GRP_WG | O8: TargetName | Q8: TargetName | U8: ブロック備考 Block Remarks
A9: # | D9: 項目名 Field Name | E9: 型 Type | F9: 桁 Digits | G9: フルネーム Full Name | H9: 日本語名 Japanese Name | I9: 上り項目 Request Message Field | J9: 下り項目 Response Message Field | S9: 条件および編集方法 Conditions and Editing Methods | U9: 項目備考 Field Remarks
A10: # | K10: 上り項目 Request Message Field | L10: 下り項目 Response Message Field | M10: 上り項目 Request Message Field | N10: 下り項目 Response Message Field | O10: 上り項目 Request Message Field | P10: 下り項目 Response Message Field | Q10: 上り項目 Request Message Field | R10: 下り項目 Response Message Field
A11: 10 | B11: * | D11: GrpWg_Upd01_Dtl | E11: L | G11: $share$ | H11: MA.MABGL0070.GrpWg_UpdChk01.GrpWg_UpdChk01_Dtl | K11: L | M11: L
A12: 10 | D12: calc_grp_cd | E12: #MA.CALC_GRP_CD | G12: Calculation group cd. | H12: 計算グループＣＤ | I12: E | K12: E | M12: E
A13: 10 | D13: wg_cd | E13: #MA.WG_CD | G13: WG cd. | H13: ワーキンググループＣＤ | I13: E | K13: E | M13: E
A14: 10 | D14: wg_prio | E14: #MA.INT2 | G14: Priority | H14: 優先順位 | I14: E | K14: E
A15: 10 | D15: memo1 | E15: #MA.MST_MEMO1 | G15: Memo 1 | H15: メモ１ | I15: E | K15: E
A16: 10 | D16: memo2 | E16: #MA.MST_MEMO2 | G16: Memo 2 | H16: メモ２ | I16: E | K16: E
A17: 10 | D17: memo3 | E17: #MA.MST_MEMO3 | G17: Memo 3 | H17: メモ３ | I17: E | K17: E
A18: 10 | D18: del_flg | E18: #MA.FLG | G18: Logical delete | H18: 論理削除 | I18: E | K18: E
A19: 10 | D19: upd_cntr | E19: #MA.UPD_CNT | G19: Update counter | H19: 更新カウンタ | I19: E | K19: E
D20: 詳細 :

Sheet GrpWg_DelChk01
A1: * | B1: * | D1: L | E1: 1
A2: * | D2: オペレーション実装仕様書 Operation Specification Implementation Sheet | E2: ModuleID : | F2: =IF(LogicCommon!C2="","",LogicCommon!C2) -> MA | G2: LogicID : | H2: =IF(LogicCommon!E2="","",LogicCommon!E2) -> MABGL0070 | I2: Ope.ID : | J2: GrpWg_DelChk01 | K2: Pj.ID : | L2: =IF(LogicCommon!G2="","",LogicCommon!G2) -> MC | M2: Ope.Body : | N2: =L4 & ".Checker" -> MA.MAUDL5010.Checker
A3: * | D3: =IF(LogicCommon!A3="","",LogicCommon!A3) | E3: SubModuleID : | F3: =IF(LogicCommon!C3="","",LogicCommon!C3) -> MABG | G3: LogicClass : | H3: =IF(LogicCommon!E3="","",LogicCommon!E3) -> MABGL_GrpWgReg | I3: Ope.Method : | J3: @ | K3: SuperClassPj.ID : | L3: =IF(LogicCommon!G3="","",LogicCommon!G3) | M3: ReportID : | O3: Gene.Type : | P3: ALL
A4: * | E4: Version : | F4: 000000 | G4: LogicName : | H4: =IF(LogicCommon!E4="","",LogicCommon!E4) -> 計算グループＷＧマスタ登録 | I4: Ope.Name : | J4: 削除前チェック | K4: SuperLogicID : | L4: =IF(LogicCommon!G4="","",LogicCommon!G4) -> MA.MAUDL5010
A5: * | E5: ACType :
A6: * | D6: 概要 : | E6: 計算グループＷＧマスタを削除する前のチェックを行う | Q6: ID
A7: # | I7: U | K7: K | P7: o
A8: # | D8: ブロック名 Block Name | E8: 型 Type | G8: super/share | H8: 対象ブロック名 Target Block Name | K8: REQUIRED | P8: TargetName | T8: ブロック備考 Block Remarks
A9: # | D9: 項目名 Field Name | E9: 型 Type | F9: 桁 Digits | G9: フルネーム Full Name | H9: 日本語名 Japanese Name | I9: 上り項目 Request Message Field | J9: 下り項目 Response Message Field | R9: 条件および編集方法 Conditions and Editing Methods | T9: 項目備考 Field Remarks
A10: # | P10: 上り項目 Request Message Field | Q10: 下り項目 Response Message Field
A11: 10 | B11: * | D11: GrpWg_DelChk01_Dtl | E11: L
A12: 10 | D12: calc_grp_cd | E12: #MA.CALC_GRP_CD | G12: Calculation group cd. | H12: 計算グループＣＤ | I12: E | K12: E
A13: 10 | D13: wg_cd | E13: #MA.WG_CD | G13: WG cd. | H13: ワーキンググループＣＤ | I13: E | K13: E
A14: 10 | D14: upd_cntr | E14: #MA.UPD_CNT | G14: Update counter | H14: 更新カウンタ | I14: E
D15: 詳細 :

Sheet GrpWg_Del01
A1: * | B1: * | D1: L | E1: 1
A2: * | D2: オペレーション実装仕様書 Operation Specification Implementation Sheet | E2: ModuleID : | F2: =IF(LogicCommon!C2="","",LogicCommon!C2) -> MA | G2: LogicID : | H2: =IF(LogicCommon!E2="","",LogicCommon!E2) -> MABGL0070 | I2: Ope.ID : | J2: GrpWg_Del01 | K2: Pj.ID : | L2: =IF(LogicCommon!G2="","",LogicCommon!G2) -> MC | M2: Ope.Body : | N2: "mcframe.serverMAUD.MAUDL6010.MAUDL_RLDeleter"
A3: * | D3: =IF(LogicCommon!A3="","",LogicCommon!A3) | E3: SubModuleID : | F3: =IF(LogicCommon!C3="","",LogicCommon!C3) -> MABG | G3: LogicClass : | H3: =IF(LogicCommon!E3="","",LogicCommon!E3) -> MABGL_GrpWgReg | I3: Ope.Method : | J3: @ | K3: SuperClassPj.ID : | L3: =IF(LogicCommon!G3="","",LogicCommon!G3) | M3: ReportID : | O3: Gene.Type : | P3: ALL
A4: * | E4: Version : | F4: 000000 | G4: LogicName : | H4: =IF(LogicCommon!E4="","",LogicCommon!E4) -> 計算グループＷＧマスタ登録 | I4: Ope.Name : | J4: 削除処理 | K4: SuperLogicID : | L4: =IF(LogicCommon!G4="","",LogicCommon!G4) -> MA.MAUDL5010
A5: * | E5: ACType :
A6: * | D6: 概要 : | E6: 計算グループＷＧマスタを削除する | L6: ID | N6: ID
A7: # | I7: U | K7: o | L7: UPDATE.updMaster1 | M7: o
A8: # | D8: ブロック名 Block Name | E8: 型 Type | G8: super/share | H8: 対象ブロック名 Target Block Name | K8: TargetName | L8: DBC.MA.MAM_GRP_WG | M8: TargetName | Q8: ブロック備考 Block Remarks
A9: # | D9: 項目名 Field Name | E9: 型 Type | F9: 桁 Digits | G9: フルネーム Full Name | H9: 日本語名 Japanese Name | I9: 上り項目 Request Message Field | J9: 下り項目 Response Message Field | O9: 条件および編集方法 Conditions and Editing Methods | Q9: 項目備考 Field Remarks
A10: # | K10: 上り項目 Request Message Field | L10: 下り項目 Response Message Field | M10: 上り項目 Request Message Field | N10: 下り項目 Response Message Field
A11: 10 | B11: * | D11: GrpWg_Del01_Dtl | E11: L | G11: $share$ | H11: MA.MABGL0070.GrpWg_DelChk01.GrpWg_DelChk01_Dtl | K11: L
A12: 10 | D12: calc_grp_cd | E12: #MA.CALC_GRP_CD | G12: Calculation group cd. | H12: 計算グループＣＤ | I12: E | K12: E
A13: 10 | D13: wg_cd | E13: #MA.WG_CD | G13: WG cd. | H13: ワーキンググループＣＤ | I13: E | K13: E
A14: 10 | D14: upd_cntr | E14: #MA.UPD_CNT | G14: Update counter | H14: 更新カウンタ | I14: E | K14: E
D15: 詳細 :

Sheet Srch01
A1: * | B1: * | D1: L | E1: 1
A2: * | D2: オペレーション実装仕様書 Operation Specification Implementation Sheet | E2: ModuleID : | F2: =IF(LogicCommon!C2="","",LogicCommon!C2) -> MA | G2: LogicID : | H2: =IF(LogicCommon!E2="","",LogicCommon!E2) -> MABGL0070 | I2: Ope.ID : | J2: Srch01 | K2: Pj.ID : | L2: =IF(LogicCommon!G2="","",LogicCommon!G2) -> MC | M2: Ope.Body : | N2: "mcframe.serverMAUD.MAUDL6010.MAUDL_RLSearcher"
A3: * | D3: =IF(LogicCommon!A3="","",LogicCommon!A3) | E3: SubModuleID : | F3: =IF(LogicCommon!C3="","",LogicCommon!C3) -> MABG | G3: LogicClass : | H3: =IF(LogicCommon!E3="","",LogicCommon!E3) -> MABGL_GrpWgReg | I3: Ope.Method : | J3: @ | K3: SuperClassPj.ID : | L3: =IF(LogicCommon!G3="","",LogicCommon!G3) | M3: ReportID : | O3: Gene.Type : | P3: ALL
A4: * | E4: Version : | F4: 000000 | G4: LogicName : | H4: =IF(LogicCommon!E4="","",LogicCommon!E4) -> 計算グループＷＧマスタ登録 | I4: Ope.Name : | J4: 検索 | K4: SuperLogicID : | L4: =IF(LogicCommon!G4="","",LogicCommon!G4) -> MA.MAUDL5010
A5: * | E5: ACType :
A6: * | D6: 概要 : | E6: 検索処理を行う | M6: ID | O6: ID
A7: # | I7: U | K7: K | L7: o | M7: SELECT.c0 | N7: o
A8: # | D8: ブロック名 Block Name | E8: 型 Type | G8: super/share | H8: 対象ブロック名 Target Block Name | K8: CONST | L8: TargetName | M8: DBC.MA.MAM_GRP_WG | N8: TargetName | R8: ブロック備考 Block Remarks
A9: # | D9: 項目名 Field Name | E9: 型 Type | F9: 桁 Digits | G9: フルネーム Full Name | H9: 日本語名 Japanese Name | I9: 上り項目 Request Message Field | J9: 下り項目 Response Message Field | P9: 条件および編集方法 Conditions and Editing Methods | R9: 項目備考 Field Remarks
A10: # | L10: 上り項目 Request Message Field | M10: 下り項目 Response Message Field | N10: 上り項目 Request Message Field | O10: 下り項目 Response Message Field
A11: 10 | B11: * | D11: Srch01_Cnd | E11: R | L11: R
A12: 10 | D12: calc_grp_cd | E12: #MA.CALC_GRP_CD | G12: Calculation group cd. | H12: 計算グループＣＤ | I12: E
A13: 10 | D13: calc_grp_nm | E13: #MA.CALC_GRP_NM | G13: Calculation group name | H13: 計算グループ名 | I13: E
A14: 10 | D14: wg_cd | E14: #MA.WG_CD | G14: WG cd. | H14: ワーキンググループＣＤ | I14: E
A15: 10 | D15: wg_nm | E15: #MA.WG_NM | G15: WG name | H15: ワーキンググループ名 | I15: E
A16: 10 | D16: off_del_flg | E16: #MA.FLG | G16: Logical delete flg. (Off) | H16: 論理削除ＦＬＧ（オフ） | I16: E
A17: 10 | D17: on_del_flg | E17: #MA.FLG | G17: Logical delete flg. (On) | H17: 論理削除ＦＬＧ（オン） | I17: E
A18: 10 | D18: memo1 | E18: #MA.MST_MEMO1 | G18: Memo 1 | H18: メモ１ | I18: E
A19: 10 | D19: memo2 | E19: #MA.MST_MEMO2 | G19: Memo 2 | H19: メモ２ | I19: E
A20: 10 | D20: memo3 | E20: #MA.MST_MEMO3 | G20: Memo 3 | H20: メモ３ | I20: E
A22: 20 | B22: * | D22: Srch01_Rslt1 | E22: L | M22: L
A23: 20 | D23: del_flg | E23: #MA.FLG | G23: Logical delete | H23: 論理削除 | J23: E | M23: E
A24: 20 | D24: calc_grp_cd | E24: #MA.CALC_GRP_CD | G24: Calculation group cd. | H24: 計算グループＣＤ | J24: E | M24: E
A25: 20 | D25: calc_grp_nm | E25: #MA.CALC_GRP_NM | G25: Calculation group name | H25: 計算グループ名 | J25: E | M25: E
A26: 20 | D26: wg_cd | E26: #MA.WG_CD | G26: WG cd. | H26: ワーキンググループＣＤ | J26: E | M26: E
A27: 20 | D27: wg_nm | E27: #MA.WG_NM | G27: WG name | H27: ワーキンググループ名 | J27: E | M27: E
A28: 20 | D28: wg_prio | E28: #MA.INT2 | G28: Priority | H28: 優先順位 | J28: E | M28: E
A29: 20 | D29: memo1 | E29: #MA.MST_MEMO1 | G29: Memo 1 | H29: メモ１ | J29: E | M29: E
A30: 20 | D30: memo2 | E30: #MA.MST_MEMO2 | G30: Memo 2 | H30: メモ２ | J30: E | M30: E
A31: 20 | D31: memo3 | E31: #MA.MST_MEMO3 | G31: Memo 3 | H31: メモ３ | J31: E | M31: E
A32: 20 | D32: ins_usr_id | E32: #MA.FCM_USR_ID | G32: Entry user ID | H32: 登録ユーザＩＤ | J32: E | M32: E
A33: 20 | D33: ins_usr_nm | E33: #MA.FCM_USR_NM | G33: Entry user name | H33: 登録ユーザ名 | J33: E | M33: E
A34: 20 | D34: ins_ts | E34: #MA.SYS_TS | G34: Entry date and time | H34: 登録日時 | J34: E | M34: E
A35: 20 | D35: ins_func_id | E35: #MA.FUNC_ID | G35: Entry function ID | H35: 登録機能ＩＤ | J35: E | M35: E
A36: 20 | D36: ins_func_nm | E36: #MA.FUNC_NM | G36: Entry function name | H36: 登録機能名 | J36: E
A37: 20 | D37: upd_cntr | E37: #MA.UPD_CNT | G37: Update counter | H37: 更新カウンタ | J37: E | M37: E
A38: 20 | D38: upd_usr_id | E38: #MA.FCM_USR_ID | G38: Update user ID | H38: 更新ユーザＩＤ | J38: E | M38: E
A39: 20 | D39: upd_usr_nm | E39: #MA.FCM_USR_NM | G39: Update user name | H39: 更新ユーザ名 | J39: E | M39: E
A40: 20 | D40: upd_ts | E40: #MA.SYS_TS | G40: Update date and time | H40: 更新日時 | J40: E | M40: E
A41: 20 | D41: upd_func_id | E41: #MA.FUNC_ID | G41: Update function ID | H41: 更新機能ＩＤ | J41: E | M41: E
...

Sheet Upd01
A1: * | B1: * | D1: L | E1: 1
A2: * | D2: オペレーション実装仕様書 Operation Specification Implementation Sheet | E2: ModuleID : | F2: =IF(LogicCommon!C2="","",LogicCommon!C2) -> MA | G2: LogicID : | H2: =IF(LogicCommon!E2="","",LogicCommon!E2) -> MABGL0070 | I2: Ope.ID : | J2: Upd01 | K2: Pj.ID : | L2: =IF(LogicCommon!G2="","",LogicCommon!G2) -> MC | M2: Ope.Body : | N2: "mcframe.serverMAUD.MAUDL6010.MAUDL_RLUpdater"
A3: * | D3: =IF(LogicCommon!A3="","",LogicCommon!A3) | E3: SubModuleID : | F3: =IF(LogicCommon!C3="","",LogicCommon!C3) -> MABG | G3: LogicClass : | H3: =IF(LogicCommon!E3="","",LogicCommon!E3) -> MABGL_GrpWgReg | I3: Ope.Method : | J3: @ | K3: SuperClassPj.ID : | L3: =IF(LogicCommon!G3="","",LogicCommon!G3) | M3: ReportID : | O3: Gene.Type : | P3: ALL
A4: * | E4: Version : | F4: 000000 | G4: LogicName : | H4: =IF(LogicCommon!E4="","",LogicCommon!E4) -> 計算グループＷＧマスタ登録 | I4: Ope.Name : | J4: 登録 | K4: SuperLogicID : | L4: =IF(LogicCommon!G4="","",LogicCommon!G4) -> MA.MAUDL5010
A5: * | E5: ACType :
A6: * | D6: 概要 : | E6: 登録処理を行う | L6: ID | N6: ID | P6: ID | R6: ID
A7: # | I7: U | K7: o | L7: CALL_OPE01.chk01 | M7: o | N7: CALL_OPE01.upd01 | O7: o | Q7: o
A8: # | D8: ブロック名 Block Name | E8: 型 Type | G8: super/share | H8: 対象ブロック名 Target Block Name | K8: TargetName | L8: OPE.MA.MABGL0070.GrpWg_UpdChk01 | M8: TargetName | N8: OPE.MA.MABGL0070.GrpWg_Upd01 | O8: TargetName | Q8: TargetName | U8: ブロック備考 Block Remarks
A9: # | D9: 項目名 Field Name | E9: 型 Type | F9: 桁 Digits | G9: フルネーム Full Name | H9: 日本語名 Japanese Name | I9: 上り項目 Request Message Field | J9: 下り項目 Response Message Field | S9: 条件および編集方法 Conditions and Editing Methods | U9: 項目備考 Field Remarks
A10: # | K10: 上り項目 Request Message Field | L10: 下り項目 Response Message Field | M10: 上り項目 Request Message Field | N10: 下り項目 Response Message Field | O10: 上り項目 Request Message Field | P10: 下り項目 Response Message Field | Q10: 上り項目 Request Message Field | R10: 下り項目 Response Message Field
A11: 10 | B11: * | D11: Upd01_Dtl1 | E11: L | G11: $share$ | H11: MA.MABGL0070.GrpWg_Upd01.GrpWg_Upd01_Dtl | K11: GrpWg_UpdChk01_Dtl | M11: GrpWg_Upd01_Dtl
A12: 10 | D12: calc_grp_cd | E12: #MA.CALC_GRP_CD | G12: Calculation group cd. | H12: 計算グループＣＤ | I12: E | K12: E | M12: E
A13: 10 | D13: wg_cd | E13: #MA.WG_CD | G13: WG cd. | H13: ワーキンググループＣＤ | I13: E | K13: E | M13: E
A14: 10 | D14: wg_prio | E14: #MA.INT2 | G14: Priority | H14: 優先順位 | I14: E | K14: E | M14: E
A15: 10 | D15: memo1 | E15: #MA.MST_MEMO1 | G15: Memo 1 | H15: メモ１ | I15: E | K15: E | M15: E
A16: 10 | D16: memo2 | E16: #MA.MST_MEMO2 | G16: Memo 2 | H16: メモ２ | I16: E | K16: E | M16: E
A17: 10 | D17: memo3 | E17: #MA.MST_MEMO3 | G17: Memo 3 | H17: メモ３ | I17: E | K17: E | M17: E
A18: 10 | D18: del_flg | E18: #MA.FLG | G18: Logical delete | H18: 論理削除 | I18: E | K18: E | M18: E
A19: 10 | D19: upd_cntr | E19: #MA.UPD_CNT | G19: Update counter | H19: 更新カウンタ | I19: E | K19: E | M19: E
D20: 詳細 :

Sheet Del01
A1: * | B1: * | D1: L | E1: 1
A2: * | D2: オペレーション実装仕様書 Operation Specification Implementation Sheet | E2: ModuleID : | F2: =IF(LogicCommon!C2="","",LogicCommon!C2) -> MA | G2: LogicID : | H2: =IF(LogicCommon!E2="","",LogicCommon!E2) -> MABGL0070 | I2: Ope.ID : | J2: Del01 | K2: Pj.ID : | L2: =IF(LogicCommon!G2="","",LogicCommon!G2) -> MC | M2: Ope.Body : | N2: "mcframe.serverMAUD.MAUDL6010.MAUDL_RLDeleter"
A3: * | D3: =IF(LogicCommon!A3="","",LogicCommon!A3) | E3: SubModuleID : | F3: =IF(LogicCommon!C3="","",LogicCommon!C3) -> MABG | G3: LogicClass : | H3: =IF(LogicCommon!E3="","",LogicCommon!E3) -> MABGL_GrpWgReg | I3: Ope.Method : | J3: @ | K3: SuperClassPj.ID : | L3: =IF(LogicCommon!G3="","",LogicCommon!G3) | M3: ReportID : | O3: Gene.Type : | P3: ALL
A4: * | E4: Version : | F4: 000000 | G4: LogicName : | H4: =IF(LogicCommon!E4="","",LogicCommon!E4) -> 計算グループＷＧマスタ登録 | I4: Ope.Name : | J4: 削除 | K4: SuperLogicID : | L4: =IF(LogicCommon!G4="","",LogicCommon!G4) -> MA.MAUDL5010
A5: * | E5: ACType :
A6: * | D6: 概要 : | E6: 削除処理を行う | L6: ID | N6: ID
A7: # | I7: U | K7: o | L7: CALL_OPE01.chk01 | M7: o | N7: CALL_OPE01.del01
A8: # | D8: ブロック名 Block Name | E8: 型 Type | G8: super/share | H8: 対象ブロック名 Target Block Name | K8: TargetName | L8: OPE.MA.MABGL0070.GrpWg_DelChk01 | M8: TargetName | N8: OPE.MA.MABGL0070.GrpWg_Del01 | Q8: ブロック備考 Block Remarks
A9: # | D9: 項目名 Field Name | E9: 型 Type | F9: 桁 Digits | G9: フルネーム Full Name | H9: 日本語名 Japanese Name | I9: 上り項目 Request Message Field | J9: 下り項目 Response Message Field | O9: 条件および編集方法 Conditions and Editing Methods | Q9: 項目備考 Field Remarks
A10: # | K10: 上り項目 Request Message Field | L10: 下り項目 Response Message Field | M10: 上り項目 Request Message Field | N10: 下り項目 Response Message Field
A11: 10 | B11: * | D11: Del01_Dtl1 | E11: L | G11: $share$ | H11: MA.MABGL0070.GrpWg_Del01.GrpWg_Del01_Dtl | K11: GrpWg_DelChk01_Dtl | M11: GrpWg_Del01_Dtl
A12: 10 | D12: calc_grp_cd | E12: #MA.CALC_GRP_CD | G12: Calculation group cd. | H12: 計算グループＣＤ | I12: E | K12: E | M12: E
A13: 10 | D13: wg_cd | E13: #MA.WG_CD | G13: WG cd. | H13: ワーキンググループＣＤ | I13: E | K13: E | M13: E
A14: 10 | D14: upd_cntr | E14: #MA.UPD_CNT | G14: Update counter | H14: 更新カウンタ | I14: E | K14: E | M14: E
D15: 詳細 :

Sheet 来歴
A1: 変更来歴
A3: Rev. | H3: 修正番号 | O3: 変更内容 | AQ3: 変更箇所
A4: 1 | O4: 初版
A5: 1.1 | O5: 英語の名称を追記 | AQ5: 全般
