Workbook

Sheet LogicCommon
A2: ロジック共通定義 | B2: ModuleID : | C2: MA | D2: LogicID : | E2: MABGL0010 | F2: Pj.ID : | G2: MC
B3: SubModuleID : | C3: MABG | D3: LogicClass : | E3: MABGL_CoParmReg | F3: SuperClassPj.ID :
D4: LogicName : | E4: 原価会社パラメータマスタ登録 | F4: SuperLogicID : | G4: MA.MAUDL5010
A5: 概要 :
A6: 詳細 :

Sheet CoParm_UpdChk01
A1: * | B1: * | D1: L | E1: 1
A2: * | D2: オペレーション実装仕様書 Operation Specification Implementation Sheet | E2: ModuleID : | F2: =IF(LogicCommon!C2="","",LogicCommon!C2) -> MA | G2: LogicID : | H2: =IF(LogicCommon!E2="","",LogicCommon!E2) -> MABGL0010 | I2: Ope.ID : | J2: CoParm_UpdChk01 | K2: Pj.ID : | L2: =IF(LogicCommon!G2="","",LogicCommon!G2) -> MC | M2: Ope.Body : | N2: =L4 & ".Checker" -> MA.MAUDL5010.Checker
A3: * | D3: =IF(LogicCommon!A3="","",LogicCommon!A3) | E3: SubModuleID : | F3: =IF(LogicCommon!C3="","",LogicCommon!C3) -> MABG | G3: LogicClass : | H3: =IF(LogicCommon!E3="","",LogicCommon!E3) -> MABGL_CoParmReg | I3: Ope.Method : | J3: @ | K3: SuperClassPj.ID : | L3: =IF(LogicCommon!G3="","",LogicCommon!G3) | M3: ReportID : | O3: Gene.Type : | P3: ALL
A4: * | E4: Version : | F4: 000000 | G4: LogicName : | H4: =IF(LogicCommon!E4="","",LogicCommon!E4) -> 原価会社パラメータマスタ登録 | I4: Ope.Name : | J4: 登録前チェック | K4: SuperLogicID : | L4: =IF(LogicCommon!G4="","",LogicCommon!G4) -> MA.MAUDL5010
A5: * | E5: ACType :
A6: * | D6: 概要 : | E6: 原価会社パラメータマスタを登録する前のチェックを行う | T6: ID
A7: # | I7: U | K7: K | L7: K | M7: K | N7: K | O7: K | P7: K | Q7: K | R7: K | S7: o
A8: # | D8: ブロック名 Block Name | E8: 型 Type | G8: super/share | H8: 対象ブロック名 Target Block Name | K8: REQUIRED | L8: CONST | M8: LIST_LOGIC | N8: LIST_OUT | O8: LIST_OUT_BASE | P8: LIST_IN | Q8: LIST_IN_BASE | R8: SMALL_LARGE | S8: TargetName | W8: ブロック備考 Block Remarks
A9: # | D9: 項目名 Field Name | E9: 型 Type | F9: 桁 Digits | G9: フルネーム Full Name | H9: 日本語名 Japanese Name | I9: 上り項目 Request Message Field | J9: 下り項目 Response Message Field | U9: 条件および編集方法 Conditions and Editing Methods | W9: 項目備考 Field Remarks
A10: # | S10: 上り項目 Request Message Field | T10: 下り項目 Response Message Field
A11: 10 | B11: * | D11: CoParm_UpdChk01_Dtl | E11: L | G11: $super$ | H11: DBC:MA.MAM_CO_PARM
A12: 10 | D12: co_cd | E12: #MA.CO_CD | G12: Company cd. | H12: 会社ＣＤ | I12: E | K12: E
A13: 10 | D13: std_rnd_typ | E13: #MA.RND_TYP | G13: Rounding type (Standard) | H13: 標準端数処理区分 | I13: E | K13: E | L13: MAC_RND_TYP
A14: 10 | D14: std_dec_place | E14: #MA.DEC_PLACE | G14: Standard number of decimal places | H14: 標準小数部有効桁数 | I14: E | K14: E | R14: 0:8
A15: 10 | D15: amt_rnd_typ | E15: #MA.RND_TYP | G15: Rounding type (Amount) | H15: 金額端数処理区分 | I15: E | K15: E | L15: MAC_RND_TYP
A16: 10 | D16: amt_dec_place | E16: #MA.DEC_PLACE | G16: Amount number of decimal places | H16: 金額小数部有効桁数 | I16: E | K16: E | R16: 0:8
A17: 10 | D17: ave_rnd_typ | E17: #MA.RND_TYP | G17: Rounding type (Unit price) | H17: 単価端数処理区分 | I17: E | K17: E | L17: MAC_RND_TYP
A18: 10 | D18: ave_dec_place | E18: #MA.DEC_PLACE | G18: Unit price number of decimal places | H18: 単価小数部有効桁数 | I18: E | K18: E | R18: 0:8
A19: 10 | D19: adj_typ | E19: #MA.ADJ_TYP | G19: Fraction adjustment type | H19: 端数調整区分 | I19: E | K19: E | L19: MAC_ADJ_TYP
A20: 10 | D20: mrgn_expns_cd | E20: #MA.EXPNS_CD | G20: Adjustment cost element cd. | H20: 調整費目ＣＤ | I20: E | K20: E | M20: MA.MAUAL0010.Expns | P20: MAC_EXPNS_TYP.PROD | Q20: expns_typ
A21: 10 | D21: purc_expns_cd | E21: #MA.EXPNS_CD | G21: Purchase cost element item cd. | H21: 購買費目ＣＤ | I21: E | M21: MA.MAUAL0010.Expns | P21: MAC_EXPNS_TYP.PROD | Q21: expns_typ
A22: 10 | D22: out_expns_cd | E22: #MA.EXPNS_CD | G22: Subcontract cost element cd. | H22: 外注費目ＣＤ | I22: E | M22: MA.MAUAL0010.Expns | P22: MAC_EXPNS_TYP.PROD | Q22: expns_typ
A23: 10 | D23: inpt_expns_cd | E23: #MA.EXPNS_CD | G23: Input cost element cd. | H23: 投入費目ＣＤ | I23: E | M23: MA.MAUAL0010.Expns | P23: MAC_EXPNS_TYP.PROD | Q23: expns_typ
A24: 10 | D24: ss_expns_cd | E24: #MA.EXPNS_CD | G24: Self supply cost element cd. | H24: 自給費目ＣＤ | I24: E | M24: MA.MAUAL0010.Expns | P24: MAC_EXPNS_TYP.PROD | Q24: expns_typ
A25: 10 | D25: prov_expns_cd | E25: #MA.EXPNS_CD | G25: Cost element cd. for gain or loss of chargeable item | H25: 有償差額費目ＣＤ | I25: E | M25: MA.MAUAL0010.Expns | P25: MAC_EXPNS_TYP.SPPL | Q25: expns_typ
A26: 10 | D26: pre_alc_max_lvl | E26: #MA.PRE_ALC_MAX_LVL | G26: Departmental alloc. max. hierarchy | H26: 一次配賦最大階層 | I26: E | R26: 0:999
A27: 10 | D27: pre_alc_max_rec | E27: #MA.PRE_ALC_MAX_REC | G27: Departmental alloc. max. number of records | H27: 一次配賦最大レコード数 | I27: E | R27: 0:999999999
A28: 10 | D28: diff_use_typ | E28: #MA.DIFF_USE_TYP | G28: Variance use type | H28: 差異使用区分 | I28: E | L28: MAC_DIFF_USE_TYP
A29: 10 | D29: lot_use_typ | E29: #MA.PS_USE_TYP | G29: Lot No. use type for production/sales | H29: ロットＮＯ生販使用区分 | I29: E | L29: MAC_PS_USE_TYP
A30: 10 | D30: sublot_use_typ | E30: #MA.PS_USE_TYP | G30: Sublot No. use type for production/sales | H30: サブロットＮＯ生販使用区分 | I30: E | L30: MAC_PS_USE_TYP
A31: 10 | D31: sno1_use_typ | E31: #MA.PS_USE_TYP | G31: SEIBAN No. 1 production/sales use type | H31: 手配ＮＯ１生販使用区分 | I31: E | L31: MAC_PS_USE_TYP
A32: 10 | D32: sno2_use_typ | E32: #MA.PS_USE_TYP | G32: SEIBAN No. 2 production/sales use type | H32: 手配ＮＯ２生販使用区分 | I32: E | L32: MAC_PS_USE_TYP
A33: 10 | D33: sno3_use_typ | E33: #MA.PS_USE_TYP | G33: SEIBAN No. 3 production/sales use type | H33: 手配ＮＯ３生販使用区分 | I33: E | L33: MAC_PS_USE_TYP
A34: 10 | D34: sno4_use_typ | E34: #MA.PS_USE_TYP | G34: SEIBAN No. 4 production/sales use type | H34: 手配ＮＯ４生販使用区分 | I34: E | L34: MAC_PS_USE_TYP
A35: 10 | D35: def_calc_ctg_cd | E35: #MA.CALC_CTG_CD | G35: Default calculation category | H35: デフォルト計算カテゴリ | I35: E | M35: MA.MAUAL0010.CalcCtg
A36: 10 | D36: fix_dpt_cd | E36: #MA.COST_DPT_CD | G36: Constant management dept. cd. | H36: 固定管理部門ＣＤ | I36: E | M36: MA.MAUAL0010.CostDpt | P36: true | Q36: ignore_ym_flg
A37: 10 | D37: trd_ratio_flg | E37: #MA.FLG | G37: Use standard unit cost at transfer ratio setting | H37: 振替比率設定時に標準単価を使用する | I37: E
A38: 10 | D38: stop_slip_flg | E38: #MA.FLG | G38: Take in canceled slip | H38: 取り消した伝票を取り込む | I38: E
A39: 10 | D39: non_prod_flg | E39: #MA.FLG | G39: Do not import production data | H39: 生産データを取り込まない | I39: E
A40: 10 | D40: oper_sum_flg | E40: #MA.FLG | G40: Import operation cd. as operation result No. | H40: 工程ＣＤを工程実績ＮＯとして取り込む | I40: E
...

Sheet CoParm_Upd01
A1: * | B1: * | D1: L | E1: 1
A2: * | D2: オペレーション実装仕様書 Operation Specification Implementation Sheet | E2: ModuleID : | F2: =IF(LogicCommon!C2="","",LogicCommon!C2) -> MA | G2: LogicID : | H2: =IF(LogicCommon!E2="","",LogicCommon!E2) -> MABGL0010 | I2: Ope.ID : | J2: CoParm_Upd01 | K2: Pj.ID : | L2: =IF(LogicCommon!G2="","",LogicCommon!G2) -> MC | M2: Ope.Body : | N2: "mcframe.serverMAUD.MAUDL6010.MAUDL_RLUpdater"
A3: * | D3: =IF(LogicCommon!A3="","",LogicCommon!A3) | E3: SubModuleID : | F3: =IF(LogicCommon!C3="","",LogicCommon!C3) -> MABG | G3: LogicClass : | H3: =IF(LogicCommon!E3="","",LogicCommon!E3) -> MABGL_CoParmReg | I3: Ope.Method : | J3: @ | K3: SuperClassPj.ID : | L3: =IF(LogicCommon!G3="","",LogicCommon!G3) | M3: ReportID : | O3: Gene.Type : | P3: ALL
A4: * | E4: Version : | F4: 000000 | G4: LogicName : | H4: =IF(LogicCommon!E4="","",LogicCommon!E4) -> 原価会社パラメータマスタ登録 | I4: Ope.Name : | J4: 登録処理 | K4: SuperLogicID : | L4: =IF(LogicCommon!G4="","",LogicCommon!G4) -> MA.MAUDL5010
A5: * | E5: ACType :
A6: * | D6: 概要 : | E6: 原価会社パラメータマスタを登録する | L6: ID | N6: ID | P6: ID | R6: ID
A7: # | I7: U | K7: o | L7: UPDATE.updMaster | M7: o | N7: MAIN.chkMaster | O7: o | Q7: o
A8: # | D8: ブロック名 Block Name | E8: 型 Type | G8: super/share | H8: 対象ブロック名 Target Block Name | K8: TargetName | L8: DBC.MA.MAM_CO_PARM | M8: TargetName | N8: DBC.MA.MAM_CO_PARM | O8: TargetName | Q8: TargetName | U8: ブロック備考 Block Remarks
A9: # | D9: 項目名 Field Name | E9: 型 Type | F9: 桁 Digits | G9: フルネーム Full Name | H9: 日本語名 Japanese Name | I9: 上り項目 Request Message Field | J9: 下り項目 Response Message Field | S9: 条件および編集方法 Conditions and Editing Methods | U9: 項目備考 Field Remarks
A10: # | K10: 上り項目 Request Message Field | L10: 下り項目 Response Message Field | M10: 上り項目 Request Message Field | N10: 下り項目 Response Message Field | O10: 上り項目 Request Message Field | P10: 下り項目 Response Message Field | Q10: 上り項目 Request Message Field | R10: 下り項目 Response Message Field
A11: 10 | B11: * | D11: CoParm_Upd01_Dtl | E11: L | G11: $share$ | H11: MA.MABGL0010.CoParm_UpdChk01.CoParm_UpdChk01_Dtl | K11: L | M11: L
A12: 10 | D12: co_cd | E12: #MA.CO_CD | G12: Company cd. | H12: 会社ＣＤ | I12: E | K12: E | M12: E
A13: 10 | D13: std_rnd_typ | E13: #MA.RND_TYP | G13: Rounding type (Standard) | H13: 標準端数処理区分 | I13: E | K13: E
A14: 10 | D14: std_dec_place | E14: #MA.DEC_PLACE | G14: Standard number of decimal places | H14: 標準小数部有効桁数 | I14: E | K14: E
A15: 10 | D15: amt_rnd_typ | E15: #MA.RND_TYP | G15: Rounding type (Amount) | H15: 金額端数処理区分 | I15: E | K15: E
A16: 10 | D16: amt_dec_place | E16: #MA.DEC_PLACE | G16: Amount number of decimal places | H16: 金額小数部有効桁数 | I16: E | K16: E
A17: 10 | D17: ave_rnd_typ | E17: #MA.RND_TYP | G17: Rounding type (Unit price) | H17: 単価端数処理区分 | I17: E | K17: E
A18: 10 | D18: ave_dec_place | E18: #MA.DEC_PLACE | G18: Unit price number of decimal places | H18: 単価小数部有効桁数 | I18: E | K18: E
A19: 10 | D19: adj_typ | E19: #MA.ADJ_TYP | G19: Fraction adjustment type | H19: 端数調整区分 | I19: E | K19: E
A20: 10 | D20: mrgn_expns_cd | E20: #MA.EXPNS_CD | G20: Adjustment cost element cd. | H20: 調整費目ＣＤ | I20: E | K20: E
A21: 10 | D21: purc_expns_cd | E21: #MA.EXPNS_CD | G21: Purchase cost element item cd. | H21: 購買費目ＣＤ | I21: E | K21: E
A22: 10 | D22: out_expns_cd | E22: #MA.EXPNS_CD | G22: Subcontract cost element cd. | H22: 外注費目ＣＤ | I22: E | K22: E
A23: 10 | D23: inpt_expns_cd | E23: #MA.EXPNS_CD | G23: Input cost element cd. | H23: 投入費目ＣＤ | I23: E | K23: E
A24: 10 | D24: ss_expns_cd | E24: #MA.EXPNS_CD | G24: Self supply cost element cd. | H24: 自給費目ＣＤ | I24: E | K24: E
... A64: 10 | D64: upd_cntr | E64: #MA.UPD_CNT | G64: Update counter | H64: 更新カウンタ | I64: E | K64: E
D65: 詳細 :

Sheet CoParm_DelChk01
A1: * | B1: * | D1: L | E1: 1
A2: * | D2: オペレーション実装仕様書 Operation Specification Implementation Sheet | E2: ModuleID : | F2: =IF(LogicCommon!C2="","",LogicCommon!C2) -> MA | G2: LogicID : | H2: =IF(LogicCommon!E2="","",LogicCommon!E2) -> MABGL0010 | I2: Ope.ID : | J2: CoParm_DelChk01 | K2: Pj.ID : | L2: =IF(LogicCommon!G2="","",LogicCommon!G2) -> MC | M2: Ope.Body : | N2: =L4 & ".Checker" -> MA.MAUDL5010.Checker
A3: * | D3: =IF(LogicCommon!A3="","",LogicCommon!A3) | E3: SubModuleID : | F3: =IF(LogicCommon!C3="","",LogicCommon!C3) -> MABG | G3: LogicClass : | H3: =IF(LogicCommon!E3="","",LogicCommon!E3) -> MABGL_CoParmReg | I3: Ope.Method : | J3: @ | K3: SuperClassPj.ID : | L3: =IF(LogicCommon!G3="","",LogicCommon!G3) | M3: ReportID : | O3: Gene.Type : | P3: ALL
A4: * | E4: Version : | F4: 000000 | G4: LogicName : | H4: =IF(LogicCommon!E4="","",LogicCommon!E4) -> 原価会社パラメータマスタ登録 | I4: Ope.Name : | J4: 削除前チェック | K4: SuperLogicID : | L4: =IF(LogicCommon!G4="","",LogicCommon!G4) -> MA.MAUDL5010
A5: * | E5: ACType :
A6: * | D6: 概要 : | E6: 原価会社パラメータマスタを削除する前のチェックを行う | Q6: ID
A7: # | I7: U | K7: K | P7: o
A8: # | D8: ブロック名 Block Name | E8: 型 Type | G8: super/share | H8: 対象ブロック名 Target Block Name | K8: REQUIRED | P8: TargetName | T8: ブロック備考 Block Remarks
A9: # | D9: 項目名 Field Name | E9: 型 Type | F9: 桁 Digits | G9: フルネーム Full Name | H9: 日本語名 Japanese Name | I9: 上り項目 Request Message Field | J9: 下り項目 Response Message Field | R9: 条件および編集方法 Conditions and Editing Methods | T9: 項目備考 Field Remarks
A10: # | P10: 上り項目 Request Message Field | Q10: 下り項目 Response Message Field
A11: 10 | B11: * | D11: CoParm_DelChk01_Dtl | E11: L
A12: 10 | D12: co_cd | E12: #MA.CO_CD | G12: Company cd. | H12: 会社ＣＤ | I12: E | K12: E
A13: 10 | D13: upd_cntr | E13: #MA.UPD_CNT | G13: Update counter | H13: 更新カウンタ | I13: E
D14: 詳細 :

Sheet CoParm_Del01
A1: * | B1: * | D1: L | E1: 1
A2: * | D2: オペレーション実装仕様書 Operation Specification Implementation Sheet | E2: ModuleID : | F2: =IF(LogicCommon!C2="","",LogicCommon!C2) -> MA | G2: LogicID : | H2: =IF(LogicCommon!E2="","",LogicCommon!E2) -> MABGL0010 | I2: Ope.ID : | J2: CoParm_Del01 | K2: Pj.ID : | L2: =IF(LogicCommon!G2="","",LogicCommon!G2) -> MC | M2: Ope.Body : | N2: "mcframe.serverMAUD.MAUDL6010.MAUDL_RLDeleter"
A3: * | D3: =IF(LogicCommon!A3="","",LogicCommon!A3) | E3: SubModuleID : | F3: =IF(LogicCommon!C3="","",LogicCommon!C3) -> MABG | G3: LogicClass : | H3: =IF(LogicCommon!E3="","",LogicCommon!E3) -> MABGL_CoParmReg | I3: Ope.Method : | J3: @ | K3: SuperClassPj.ID : | L3: =IF(LogicCommon!G3="","",LogicCommon!G3) | M3: ReportID : | O3: Gene.Type : | P3: ALL
A4: * | E4: Version : | F4: 000000 | G4: LogicName : | H4: =IF(LogicCommon!E4="","",LogicCommon!E4) -> 原価会社パラメータマスタ登録 | I4: Ope.Name : | J4: 削除処理 | K4: SuperLogicID : | L4: =IF(LogicCommon!G4="","",LogicCommon!G4) -> MA.MAUDL5010
A5: * | E5: ACType :
A6: * | D6: 概要 : | E6: 原価会社パラメータマスタを削除する | L6: ID | N6: ID
A7: # | I7: U | K7: o | L7: UPDATE.updMaster1 | M7: o
A8: # | D8: ブロック名 Block Name | E8: 型 Type | G8: super/share | H8: 対象ブロック名 Target Block Name | K8: TargetName | L8: DBC.MA.MAM_CO_PARM | M8: TargetName | Q8: ブロック備考 Block Remarks
A9: # | D9: 項目名 Field Name | E9: 型 Type | F9: 桁 Digits | G9: フルネーム Full Name | H9: 日本語名 Japanese Name | I9: 上り項目 Request Message Field | J9: 下り項目 Response Message Field | O9: 条件および編集方法 Conditions and Editing Methods | Q9: 項目備考 Field Remarks
A10: # | K10: 上り項目 Request Message Field | L10: 下り項目 Response Message Field | M10: 上り項目 Request Message Field | N10: 下り項目 Response Message Field
A11: 10 | B11: * | D11: CoParm_Del01_Dtl | E11: L | G11: $share$ | H11: MA.MABGL0010.CoParm_DelChk01.CoParm_DelChk01_Dtl | K11: L
A12: 10 | D12: co_cd | E12: #MA.CO_CD | G12: Company cd. | H12: 会社ＣＤ | I12: E | K12: E
A13: 10 | D13: upd_cntr | E13: #MA.UPD_CNT | G13: Update counter | H13: 更新カウンタ | I13: E | K13: E
D14: 詳細 :

Sheet Srch01
A1: * | B1: * | D1: L | E1: 1
A2: * | D2: オペレーション実装仕様書 Operation Specification Implementation Sheet | E2: ModuleID : | F2: =IF(LogicCommon!C2="","",LogicCommon!C2) -> MA | G2: LogicID : | H2: =IF(LogicCommon!E2="","",LogicCommon!E2) -> MABGL0010 | I2: Ope.ID : | J2: Srch01 | K2: Pj.ID : | L2: =IF(LogicCommon!G2="","",LogicCommon!G2) -> MC | M2: Ope.Body : | N2: "mcframe.serverMAUD.MAUDL6010.MAUDL_RLSearcher"
A3: * | D3: =IF(LogicCommon!A3="","",LogicCommon!A3) | E3: SubModuleID : | F3: =IF(LogicCommon!C3="","",LogicCommon!C3) -> MABG | G3: LogicClass : | H3: =IF(LogicCommon!E3="","",LogicCommon!E3) -> MABGL_CoParmReg | I3: Ope.Method : | J3: @ | K3: SuperClassPj.ID : | L3: =IF(LogicCommon!G3="","",LogicCommon!G3) | M3: ReportID : | O3: Gene.Type : | P3: ALL
A4: * | E4: Version : | F4: 000000 | G4: LogicName : | H4: =IF(LogicCommon!E4="","",LogicCommon!E4) -> 原価会社パラメータマスタ登録 | I4: Ope.Name : | J4: 検索 | K4: SuperLogicID : | L4: =IF(LogicCommon!G4="","",LogicCommon!G4) -> MA.MAUDL5010
A5: * | E5: ACType :
A6: * | D6: 概要 : | E6: 検索処理を行う | M6: ID | O6: ID | Q6: ID
A7: # | I7: U | K7: K | L7: o | M7: SELECT.c0 | N7: o | P7: o
A8: # | D8: ブロック名 Block Name | E8: 型 Type | G8: super/share | H8: 対象ブロック名 Target Block Name | K8: CONST | L8: TargetName | M8: DBC.MA.MAM_CO_PARM | N8: TargetName | P8: TargetName | T8: ブロック備考 Block Remarks
A9: # | D9: 項目名 Field Name | E9: 型 Type | F9: 桁 Digits | G9: フルネーム Full Name | H9: 日本語名 Japanese Name | I9: 上り項目 Request Message Field | J9: 下り項目 Response Message Field | R9: 条件および編集方法 Conditions and Editing Methods | T9: 項目備考 Field Remarks
A10: # | L10: 上り項目 Request Message Field | M10: 下り項目 Response Message Field | N10: 上り項目 Request Message Field | O10: 下り項目 Response Message Field | P10: 上り項目 Request Message Field | Q10: 下り項目 Response Message Field
A11: 10 | B11: * | D11: Srch01_Cnd | E11: R | L11: R
A12: 10 | D12: co_cd | E12: #MA.CO_CD | G12: Company cd. | H12: 会社ＣＤ | I12: E
A13: 10 | D13: co_nm | E13: #MA.CO_NM | G13: Company name | H13: 会社名 | I13: E
A14: 10 | D14: this_term | E14: #MA.YM | G14: Term (Correspond to cost login info. change) | H14: 期（原価ログイン情報変更対応） | I14: E
A16: 20 | B16: * | D16: Srch01_Rslt1 | E16: L | M16: L
A17: 20 | D17: co_cd | E17: #MA.CO_CD | G17: Company cd. | H17: 会社ＣＤ
A18: 20 | D18: std_rnd_typ | E18: #MA.RND_TYP | G18: Rounding type (Standard) | H18: 標準端数処理区分 | J18: E | K18: MAC_RND_TYP | M18: E
A19: 20 | D19: std_rnd_typ_nm | E19: #MA.RND_TYP_NM | G19: Rounding type name (Standard) | H19: 標準端数処理区分名 | J19: E
A20: 20 | D20: std_dec_place | E20: #MA.DEC_PLACE | G20: Standard number of decimal places | H20: 標準小数部有効桁数 | J20: E | M20: E
A21: 20 | D21: amt_rnd_typ | E21: #MA.RND_TYP | G21: Rounding type (Amount) | H21: 金額端数処理区分 | J21: E | K21: MAC_RND_TYP | M21: E
A22: 20 | D22: amt_rnd_typ_nm | E22: #MA.RND_TYP_NM | G22: Rounding type name (Amount) | H22: 金額端数処理区分名 | J22: E
A23: 20 | D23: amt_dec_place | E23: #MA.DEC_PLACE | G23: Amount number of decimal places | H23: 金額小数部有効桁数 | J23: E | M23: E
A24: 20 | D24: ave_rnd_typ | E24: #MA.RND_TYP | G24: Rounding type (Unit price) | H24: 単価端数処理区分 | J24: E | K24: MAC_RND_TYP | M24: E
A25: 20 | D25: ave_rnd_typ_nm | E25: #MA.RND_TYP_NM | G25: Rounding type name (Unit price) | H25: 単価端数処理区分名 | J25: E
A26: 20 | D26: ave_dec_place | E26: #MA.DEC_PLACE | G26: Unit price number of decimal places | H26: 単価小数部有効桁数 | J26: E | M26: E
A27: 20 | D27: adj_typ | E27: #MA.ADJ_TYP | G27: Fraction adjustment type | H27: 端数調整区分 | J27: E | K27: MAC_ADJ_TYP | M27: E
A28: 20 | D28: adj_typ_nm | E28: #MA.ADJ_TYP_NM | G28: Fraction adjustment type name | H28: 端数調整区分名 | J28: E
A29: 20 | D29: mrgn_expns_cd | E29: #MA.EXPNS_CD | G29: Adjustment cost element cd. | H29: 調整費目ＣＤ | J29: E | M29: E
A30: 20 | D30: mrgn_expns_nm | E30: #MA.EXPNS_NM | G30: Adjustment cost element name | H30: 調整費目名 | J30: E | M30: E
A31: 20 | D31: purc_expns_cd | E31: #MA.EXPNS_CD | G31: Purchase cost element item cd. | H31: 購買費目ＣＤ | J31: E | M31: E
A32: 20 | D32: purc_expns_nm | E32: #MA.EXPNS_NM | G32: Purchase cost element name | H32: 購買費目名 | J32: E | M32: E
A33: 20 | D33: out_expns_cd | E33: #MA.EXPNS_CD | G33: Subcontract cost element cd. | H33: 外注費目ＣＤ | J33: E | M33: E
A34: 20 | D34: out_expns_nm | E34: #MA.EXPNS_NM | G34: Subcontract cost element name | H34: 外注費目名 | J34: E | M34: E
A35: 20 | D35: inpt_expns_cd | E35: #MA.EXPNS_CD | G35: Input cost element cd. | H35: 投入費目ＣＤ | J35: E | M35: E
A36: 20 | D36: inpt_expns_nm | E36: #MA.EXPNS_NM | G36: Input cost element name | H36: 投入費目名 | J36: E | M36: E
A37: 20 | D37: ss_expns_cd | E37: #MA.EXPNS_CD | G37: Self supply cost element cd. | H37: 自給費目ＣＤ | J37: E | M37: E
A38: 20 | D38: ss_expns_nm | E38: #MA.EXPNS_NM | G38: Self supply cost element name | H38: 自給費目名 | J38: E | M38: E
A39: 20 | D39: prov_expns_cd | E39: #MA.EXPNS_CD | G39: Cost element cd. for gain or loss of chargeable item | H39: 有償差額費目ＣＤ | J39: E | M39: E
A40: 20 | D40: prov_expns_nm | E40: #MA.EXPNS_NM | G40: Gain or loss of chargeable supply cost element name | H40: 有償差額費目名 | J40: E | M40: E
... A42: 20 | D42: pre_alc_max_rec | E42: #MA.PRE_ALC_MAX_REC | G42: Departmental alloc. max. number of records | H42: 一次配賦最大レコード数 | J42: E | M42: E
...

Sheet Upd01
A1: * | B1: * | D1: L | E1: 1
A2: * | D2: オペレーション実装仕様書 Operation Specification Implementation Sheet | E2: ModuleID : | F2: =IF(LogicCommon!C2="","",LogicCommon!C2) -> MA | G2: LogicID : | H2: =IF(LogicCommon!E2="","",LogicCommon!E2) -> MABGL0010 | I2: Ope.ID : | J2: Upd01 | K2: Pj.ID : | L2: =IF(LogicCommon!G2="","",LogicCommon!G2) -> MC | M2: Ope.Body : | N2: "mcframe.serverMAUD.MAUDL6010.MAUDL_RLUpdater"
A3: * | D3: =IF(LogicCommon!A3="","",LogicCommon!A3) | E3: SubModuleID : | F3: =IF(LogicCommon!C3="","",LogicCommon!C3) -> MABG | G3: LogicClass : | H3: =IF(LogicCommon!E3="","",LogicCommon!E3) -> MABGL_CoParmReg | I3: Ope.Method : | J3: @ | K3: SuperClassPj.ID : | L3: =IF(LogicCommon!G3="","",LogicCommon!G3) | M3: ReportID : | O3: Gene.Type : | P3: ALL
A4: * | E4: Version : | F4: 000000 | G4: LogicName : | H4: =IF(LogicCommon!E4="","",LogicCommon!E4) -> 原価会社パラメータマスタ登録 | I4: Ope.Name : | J4: 登録 | K4: SuperLogicID : | L4: =IF(LogicCommon!G4="","",LogicCommon!G4) -> MA.MAUDL5010
A5: * | E5: ACType :
A6: * | D6: 概要 : | E6: 登録処理を行う | L6: ID | N6: ID | P6: ID
A7: # | I7: U | K7: o | L7: CALL_OPE01.chk01 | M7: o | N7: CALL_OPE01.upd01 | O7: o
A8: # | D8: ブロック名 Block Name | E8: 型 Type | G8: super/share | H8: 対象ブロック名 Target Block Name | K8: TargetName | L8: OPE.MA.MABGL0010.CoParm_UpdChk01 | M8: TargetName | N8: OPE.MA.MABGL0010.CoParm_Upd01 | O8: TargetName | S8: ブロック備考 Block Remarks
A9: # | D9: 項目名 Field Name | E9: 型 Type | F9: 桁 Digits | G9: フルネーム Full Name | H9: 日本語名 Japanese Name | I9: 上り項目 Request Message Field | J9: 下り項目 Response Message Field | Q9: 条件および編集方法 Conditions and Editing Methods | S9: 項目備考 Field Remarks
A10: # | K10: 上り項目 Request Message Field | L10: 下り項目 Response Message Field | M10: 上り項目 Request Message Field | N10: 下り項目 Response Message Field | O10: 上り項目 Request Message Field | P10: 下り項目 Response Message Field
A11: 10 | B11: * | D11: Upd01_Dtl1 | E11: L | G11: $share$ | H11: MA.MABGL0010.CoParm_Upd01.CoParm_Upd01_Dtl | K11: CoParm_UpdChk01_Dtl | M11: CoParm_Upd01_Dtl
A12: 10 | D12: co_cd | E12: #MA.CO_CD | G12: Company cd. | H12: 会社ＣＤ | I12: E | K12: E | M12: E
A13: 10 | D13: std_rnd_typ | E13: #MA.RND_TYP | G13: Rounding type (Standard) | H13: 標準端数処理区分 | I13: E | K13: E | M13: E
A14: 10 | D14: std_dec_place | E14: #MA.DEC_PLACE | G14: Standard number of decimal places | H14: 標準小数部有効桁数 | I14: E | K14: E | M14: E
A15: 10 | D15: amt_rnd_typ | E15: #MA.RND_TYP | G15: Rounding type (Amount) | H15: 金額端数処理区分 | I15: E | K15: E | M15: E
A16: 10 | D16: amt_dec_place | E16: #MA.DEC_PLACE | G16: Amount number of decimal places | H16: 金額小数部有効桁数 | I16: E | K16: E | M16: E
A17: 10 | D17: ave_rnd_typ | E17: #MA.RND_TYP | G17: Rounding type (Unit price) | H17: 単価端数処理区分 | I17: E | K17: E | M17: E
A18: 10 | D18: ave_dec_place | E18: #MA.DEC_PLACE | G18: Unit price number of decimal places | H18: 単価小数部有効桁数 | I18: E | K18: E | M18: E
A19: 10 | D19: adj_typ | E19: #MA.ADJ_TYP | G19: Fraction adjustment type | H19: 端数調整区分 | I19: E | K19: E | M19: E
A20: 10 | D20: mrgn_expns_cd | E20: #MA.EXPNS_CD | G20: Adjustment cost element cd. | H20: 調整費目ＣＤ | I20: E | K20: E | M20: E
A21: 10 | D21: purc_expns_cd | E21: #MA.EXPNS_CD | G21: Purchase cost element item cd. | H21: 購買費目ＣＤ | I21: E | K21: E | M21: E
A22: 10 | D22: out_expns_cd | E22: #MA.EXPNS_CD | G22: Subcontract cost element cd. | H22: 外注費目ＣＤ | I22: E | K22: E | M22: E
A23: 10 | D23: inpt_expns_cd | E23: #MA.EXPNS_CD | G23: Input cost element cd. | H23: 投入費目ＣＤ | I23: E | K23: E | M23: E
... A64: 10 | D64: upd_cntr | E64: #MA.UPD_CNT | G64: Update counter | H64: 更新カウンタ | I64: E | K64: E | M64: E
D65: 詳細 :

Sheet Del01
A1: * | B1: * | D1: L | E1: 1
A2: * | D2: オペレーション実装仕様書 Operation Specification Implementation Sheet | E2: ModuleID : | F2: =IF(LogicCommon!C2="","",LogicCommon!C2) -> MA | G2: LogicID : | H2: =IF(LogicCommon!E2="","",LogicCommon!E2) -> MABGL0010 | I2: Ope.ID : | J2: Del01 | K2: Pj.ID : | L2: =IF(LogicCommon!G2="","",LogicCommon!G2) -> MC | M2: Ope.Body : | N2: "mcframe.serverMAUD.MAUDL6010.MAUDL_RLDeleter"
A3: * | D3: =IF(LogicCommon!A3="","",LogicCommon!A3) | E3: SubModuleID : | F3: =IF(LogicCommon!C3="","",LogicCommon!C3) -> MABG | G3: LogicClass : | H3: =IF(LogicCommon!E3="","",LogicCommon!E3) -> MABGL_CoParmReg | I3: Ope.Method : | J3: @ | K3: SuperClassPj.ID : | L3: =IF(LogicCommon!G3="","",LogicCommon!G3) | M3: ReportID : | O3: Gene.Type : | P3: ALL
A4: * | E4: Version : | F4: 000000 | G4: LogicName : | H4: =IF(LogicCommon!E4="","",LogicCommon!E4) -> 原価会社パラメータマスタ登録 | I4: Ope.Name : | J4: 削除 | K4: SuperLogicID : | L4: =IF(LogicCommon!G4="","",LogicCommon!G4) -> MA.MAUDL5010
A5: * | E5: ACType :
A6: * | D6: 概要 : | E6: 削除処理を行う | L6: ID | N6: ID
A7: # | I7: U | K7: o | L7: CALL_OPE01.chk01 | M7: o | N7: CALL_OPE01.del01
A8: # | D8: ブロック名 Block Name | E8: 型 Type | G8: super/share | H8: 対象ブロック名 Target Block Name | K8: TargetName | L8: OPE.MA.MABGL0010.CoParm_DelChk01 | M8: TargetName | N8: OPE.MA.MABGL0010.CoParm_Del01 | Q8: ブロック備考 Block Remarks
A9: # | D9: 項目名 Field Name | E9: 型 Type | F9: 桁 Digits | G9: フルネーム Full Name | H9: 日本語名 Japanese Name | I9: 上り項目 Request Message Field | J9: 下り項目 Response Message Field | O9: 条件および編集方法 Conditions and Editing Methods | Q9: 項目備考 Field Remarks
A10: # | K10: 上り項目 Request Message Field | L10: 下り項目 Response Message Field | M10: 上り項目 Request Message Field | N10: 下り項目 Response Message Field
A11: 10 | B11: * | D11: Del01_Dtl1 | E11: L | G11: $share$ | H11: MA.MABGL0010.CoParm_Del01.CoParm_Del01_Dtl | K11: CoParm_DelChk01_Dtl | M11: CoParm_Del01_Dtl
A12: 10 | D12: co_cd | E12: #MA.CO_CD | G12: Company cd. | H12: 会社ＣＤ | I12: E | K12: E | M12: E
A13: 10 | D13: upd_cntr | E13: #MA.UPD_CNT | G13: Update counter | H13: 更新カウンタ | I13: E | K13: E | M13: E
D14: 詳細 :

Sheet 来歴
A1: 変更来歴
A3: Rev. | H3: 修正番号 | O3: 変更内容 | AQ3: 変更箇所
A4: 1 | O4: 初版
A5: 1.1 | O5: 英語の名称を追記 | AQ5: 全般
