Workbook

Sheet LogicCommon
A2: ロジック共通定義 | B2: ModuleID : | C2: MA | D2: LogicID : | E2: MABGL0100 | F2: Pj.ID : | G2: MC
B3: SubModuleID : | C3: MABG | D3: LogicClass : | E3: MABGL_CalcPtnReg | F3: SuperClassPj.ID :
D4: LogicName : | E4: 計算パタンマスタ登録 | F4: SuperLogicID : | G4: MA.MAUDL5010
A5: 概要 :
A6: 詳細 :

Sheet CalcPtn_UpdChk01
A1: * | B1: * | D1: L | E1: 1
A2: * | D2: オペレーション実装仕様書 Operation Specification Implementation Sheet | E2: ModuleID : | F2: =IF(LogicCommon!C2="","",LogicCommon!C2) -> MA | G2: LogicID : | H2: =IF(LogicCommon!E2="","",LogicCommon!E2) -> MABGL0100 | I2: Ope.ID : | J2: CalcPtn_UpdChk01 | K2: Pj.ID : | L2: =IF(LogicCommon!G2="","",LogicCommon!G2) -> MC | M2: Ope.Body : | N2: =L4 & ".Checker" -> MA.MAUDL5010.Checker
A3: * | D3: =IF(LogicCommon!A3="","",LogicCommon!A3) | E3: SubModuleID : | F3: =IF(LogicCommon!C3="","",LogicCommon!C3) -> MABG | G3: LogicClass : | H3: =IF(LogicCommon!E3="","",LogicCommon!E3) -> MABGL_CalcPtnReg | I3: Ope.Method : | J3: @ | K3: SuperClassPj.ID : | L3: =IF(LogicCommon!G3="","",LogicCommon!G3) | M3: ReportID : | O3: Gene.Type : | P3: ALL
A4: * | E4: Version : | F4: 000000 | G4: LogicName : | H4: =IF(LogicCommon!E4="","",LogicCommon!E4) -> 計算パタンマスタ登録 | I4: Ope.Name : | J4: 登録前チェック | K4: SuperLogicID : | L4: =IF(LogicCommon!G4="","",LogicCommon!G4) -> MA.MAUDL5010
A5: * | E5: ACType :
A6: * | D6: 概要 : | E6: 計算パタンマスタを登録する前のチェックを行う | S6: ID
A7: # | I7: U | K7: K | L7: K | M7: K | N7: K | O7: K | P7: K | R7: o
A8: # | D8: ブロック名 Block Name | E8: 型 Type | G8: super/share | H8: 対象ブロック名 Target Block Name | K8: REQUIRED | L8: CONST | M8: LIST_LOGIC | N8: SMALL_LARGE | O8: LIST_IN | P8: LIST_IN_BASE | R8: TargetName | V8: ブロック備考 Block Remarks
A9: # | D9: 項目名 Field Name | E9: 型 Type | F9: 桁 Digits | G9: フルネーム Full Name | H9: 日本語名 Japanese Name | I9: 上り項目 Request Message Field | J9: 下り項目 Response Message Field | T9: 条件および編集方法 Conditions and Editing Methods | V9: 項目備考 Field Remarks
A10: # | R10: 上り項目 Request Message Field | S10: 下り項目 Response Message Field
A11: 10 | B11: * | D11: CalcPtn_UpdChk01_Dtl | E11: L | G11: $super$ | H11: DBC:MA.MAM_CALC_PTN
A12: 10 | D12: calc_ptn_cd | E12: #MA.CALC_PTN_CD | G12: Calculation pattern cd. | H12: 計算パタンＣＤ | I12: E | K12: E
A13: 10 | D13: calc_ptn_nm | E13: #MA.CALC_PTN_NM | G13: Calculation pattern name | H13: 計算パタン名 | I13: E | K13: E
A14: 10 | D14: mfg_purc_typ | E14: #MA.MFG_PURC_TYP | G14: Mfg. purchase type | H14: 製造購買区分 | I14: E | K14: E | L14: MAC_MFG_PURC_TYP
A15: 10 | D15: eval_typ | E15: #MA.EVAL_TYP | G15: Amount evaluation type | H15: 金額評価区分 | I15: E | L15: MAC_EVAL_TYP
A16: 10 | D16: dpt_typ | E16: #MA.UNIT_CALC_TYP | G16: Dept. calculation type | H16: 部門計算区分 | I16: E | L16: MAC_UNIT_CALC_TYP
A17: 10 | D17: lot_typ | E17: #MA.UNIT_CALC_TYP | G17: Lot No. calculation type | H17: ロットＮＯ計算区分 | I17: E | L17: MAC_UNIT_CALC_TYP
A18: 10 | D18: sublot_typ | E18: #MA.UNIT_CALC_TYP | G18: Sublot No. calculation type | H18: サブロットＮＯ計算区分 | I18: E | L18: MAC_UNIT_CALC_TYP
A19: 10 | D19: sno1_typ | E19: #MA.UNIT_CALC_TYP | G19: SEIBAN No. 1 calculation type | H19: 手配ＮＯ１計算区分 | I19: E | L19: MAC_UNIT_CALC_TYP
A20: 10 | D20: sno2_typ | E20: #MA.UNIT_CALC_TYP | G20: SEIBAN No. 2 calculation type | H20: 手配ＮＯ２計算区分 | I20: E | L20: MAC_UNIT_CALC_TYP
A21: 10 | D21: sno3_typ | E21: #MA.UNIT_CALC_TYP | G21: SEIBAN No. 3 calculation type | H21: 手配ＮＯ３計算区分 | I21: E | L21: MAC_UNIT_CALC_TYP
A22: 10 | D22: sno4_typ | E22: #MA.UNIT_CALC_TYP | G22: SEIBAN No. 4 calculation type | H22: 手配ＮＯ４計算区分 | I22: E | L22: MAC_UNIT_CALC_TYP
A23: 10 | D23: lot_act_typ | E23: #MA.ACT_SET_TYP | G23: Lot No. result type | H23: ロットＮＯ実績区分 | I23: E | L23: MAC_ACT_SET_TYP
A24: 10 | D24: sublot_act_typ | E24: #MA.ACT_SET_TYP | G24: Sublot No. result type | H24: サブロットＮＯ実績区分 | I24: E | L24: MAC_ACT_SET_TYP
A25: 10 | D25: sno1_act_typ | E25: #MA.ACT_SET_TYP | G25: SEIBAN No. 1 result type | H25: 手配ＮＯ１実績区分 | I25: E | L25: MAC_ACT_SET_TYP
A26: 10 | D26: sno2_act_typ | E26: #MA.ACT_SET_TYP | G26: SEIBAN No. 2 result type | H26: 手配ＮＯ２実績区分 | I26: E | L26: MAC_ACT_SET_TYP
... A46: 10 | D46: std_rnd_typ | E46: #MA.RND_TYP | G46: Rounding type (Standard) | H46: 標準端数処理区分 | I46: E | L46: MAC_RND_TYP
A47: 10 | D47: std_dec_place | E47: #MA.DEC_PLACE | G47: Standard number of decimal places | H47: 標準小数部有効桁数 | I47: E | N47: 0:8
A48: 10 | D48: ave_rnd_typ | E48: #MA.RND_TYP | G48: Rounding type (Unit price) | H48: 単価端数処理区分 | I48: E | L48: MAC_RND_TYP
A49: 10 | D49: ave_dec_place | E49: #MA.DEC_PLACE | G49: Unit price number of decimal places | H49: 単価小数部有効桁数 | I49: E | N49: 0:8
A50: 10 | D50: adj_typ | E50: #MA.ADJ_TYP | G50: Fraction adjustment type | H50: 端数調整区分 | I50: E | L50: MAC_ADJ_TYP
A51: 10 | D51: wip_typ | E51: #MA.WIP_TYP | G51: WIP type | H51: 仕掛区分 | I51: E | L51: MAC_WIP_TYP
A52: 10 | D52: bd_agg_typ | E52: #MA.BD_AGG_TYP | G52: Breakdown aggregated type | H52: 内訳集計区分 | I52: E | L52: MAC_BD_AGG_TYP
A53: 10 | D53: mrgn_expns_cd | E53: #MA.EXPNS_CD | G53: Adjustment cost element cd. | H53: 調整費目ＣＤ | I53: E | M53: MA.MAUAL0010.Expns | O53: MAC_EXPNS_TYP.PROD | P53: expns_typ
A54: 10 | D54: purc_expns_cd | E54: #MA.EXPNS_CD | G54: Purchase cost element item cd. | H54: 購買費目ＣＤ | I54: E | M54: MA.MAUAL0010.Expns | O54: MAC_EXPNS_TYP.PROD | P54: expns_typ
A55: 10 | D55: out_expns_cd | E55: #MA.EXPNS_CD | G55: Subcontract cost element cd. | H55: 外注費目ＣＤ | I55: E | M55: MA.MAUAL0010.Expns | O55: MAC_EXPNS_TYP.PROD | P55: expns_typ
A56: 10 | D56: inpt_expns_cd | E56: #MA.EXPNS_CD | G56: Input cost element cd. | H56: 投入費目ＣＤ | I56: E | M56: MA.MAUAL0010.Expns | O56: MAC_EXPNS_TYP.PROD | P56: expns_typ
A57: 10 | D57: ss_expns_cd | E57: #MA.EXPNS_CD | G57: Self supply cost element cd. | H57: 自給費目ＣＤ | I57: E | M57: MA.MAUAL0010.Expns | O57: MAC_EXPNS_TYP.PROD | P57: expns_typ
A58: 10 | D58: prov_expns_cd | E58: #MA.EXPNS_CD | G58: Cost element cd. for gain or loss of chargeable item | H58: 有償差額費目ＣＤ | I58: E | M58: MA.MAUAL0010.Expns | O58: MAC_EXPNS_TYP.SPPL | P58: expns_typ
A59: 10 | D59: exp_alloc_typ | E59: #MA.EXP_ALLOC_TYP | G59: Explosion allocation type | H59: 展開割付区分 | I59: E | L59: MAC_EXP_ALLOC_TYP
...

Sheet CalcPtn_Upd01
A1: * | B1: * | D1: L | E1: 1
A2: * | D2: オペレーション実装仕様書 Operation Specification Implementation Sheet | E2: ModuleID : | F2: =IF(LogicCommon!C2="","",LogicCommon!C2) -> MA | G2: LogicID : | H2: =IF(LogicCommon!E2="","",LogicCommon!E2) -> MABGL0100 | I2: Ope.ID : | J2: CalcPtn_Upd01 | K2: Pj.ID : | L2: =IF(LogicCommon!G2="","",LogicCommon!G2) -> MC | M2: Ope.Body : | N2: "mcframe.serverMAUD.MAUDL6020.MAUDL_LCLRLUpdater"
A3: * | D3: =IF(LogicCommon!A3="","",LogicCommon!A3) | E3: SubModuleID : | F3: =IF(LogicCommon!C3="","",LogicCommon!C3) -> MABG | G3: LogicClass : | H3: =IF(LogicCommon!E3="","",LogicCommon!E3) -> MABGL_CalcPtnReg | I3: Ope.Method : | J3: @ | K3: SuperClassPj.ID : | L3: =IF(LogicCommon!G3="","",LogicCommon!G3) | M3: ReportID : | O3: Gene.Type : | P3: ALL
A4: * | E4: Version : | F4: 000000 | G4: LogicName : | H4: =IF(LogicCommon!E4="","",LogicCommon!E4) -> 計算パタンマスタ登録 | I4: Ope.Name : | J4: 登録処理 | K4: SuperLogicID : | L4: =IF(LogicCommon!G4="","",LogicCommon!G4) -> MA.MAUDL5010
A5: * | E5: ACType :
A6: * | D6: 概要 : | E6: 計算パタンマスタを登録する | L6: ID | N6: ID | P6: ID | R6: ID
A7: # | I7: U | K7: o | L7: UPDATE.updMaster | M7: o | N7: MAIN.chkMaster | O7: o | Q7: o
A8: # | D8: ブロック名 Block Name | E8: 型 Type | G8: super/share | H8: 対象ブロック名 Target Block Name | K8: TargetName | L8: DBC.MA.MAM_CALC_PTN | M8: TargetName | N8: DBC.MA.MAM_CALC_PTN | O8: TargetName | Q8: TargetName | U8: ブロック備考 Block Remarks
A9: # | D9: 項目名 Field Name | E9: 型 Type | F9: 桁 Digits | G9: フルネーム Full Name | H9: 日本語名 Japanese Name | I9: 上り項目 Request Message Field | J9: 下り項目 Response Message Field | S9: 条件および編集方法 Conditions and Editing Methods | U9: 項目備考 Field Remarks
A10: # | K10: 上り項目 Request Message Field | L10: 下り項目 Response Message Field | M10: 上り項目 Request Message Field | N10: 下り項目 Response Message Field | O10: 上り項目 Request Message Field | P10: 下り項目 Response Message Field | Q10: 上り項目 Request Message Field | R10: 下り項目 Response Message Field
A11: 10 | B11: * | D11: CalcPtn_Upd01_Dtl | E11: L | G11: $share$ | H11: MA.MABGL0100.CalcPtn_UpdChk01.CalcPtn_UpdChk01_Dtl | K11: L | M11: L
A12: 10 | D12: calc_ptn_cd | E12: #MA.CALC_PTN_CD | G12: Calculation pattern cd. | H12: 計算パタンＣＤ | I12: E | K12: E | M12: E
A13: 10 | D13: calc_ptn_nm | E13: #MA.CALC_PTN_NM | G13: Calculation pattern name | H13: 計算パタン名 | I13: E | K13: E
A14: 10 | D14: mfg_purc_typ | E14: #MA.MFG_PURC_TYP | G14: Mfg. purchase type | H14: 製造購買区分 | I14: E | K14: E
A15: 10 | D15: eval_typ | E15: #MA.EVAL_TYP | G15: Amount evaluation type | H15: 金額評価区分 | I15: E | K15: E
A16: 10 | D16: dpt_typ | E16: #MA.UNIT_CALC_TYP | G16: Dept. calculation type | H16: 部門計算区分 | I16: E | K16: E
A17: 10 | D17: lot_typ | E17: #MA.UNIT_CALC_TYP | G17: Lot No. calculation type | H17: ロットＮＯ計算区分 | I17: E | K17: E
A18: 10 | D18: sublot_typ | E18: #MA.UNIT_CALC_TYP | G18: Sublot No. calculation type | H18: サブロットＮＯ計算区分 | I18: E | K18: E
A19: 10 | D19: sno1_typ | E19: #MA.UNIT_CALC_TYP | G19: SEIBAN No. 1 calculation type | H19: 手配ＮＯ１計算区分 | I19: E | K19: E
A20: 10 | D20: sno2_typ | E20: #MA.UNIT_CALC_TYP | G20: SEIBAN No. 2 calculation type | H20: 手配ＮＯ２計算区分 | I20: E | K20: E
A21: 10 | D21: sno3_typ | E21: #MA.UNIT_CALC_TYP | G21: SEIBAN No. 3 calculation type | H21: 手配ＮＯ３計算区分 | I21: E | K21: E
A22: 10 | D22: sno4_typ | E22: #MA.UNIT_CALC_TYP | G22: SEIBAN No. 4 calculation type | H22: 手配ＮＯ４計算区分 | I22: E | K22: E
A23: 10 | D23: lot_act_typ | E23: #MA.ACT_SET_TYP | G23: Lot No. result type | H23: ロットＮＯ実績区分 | I23: E | K23: E
A24: 10 | D24: sublot_act_typ | E24: #MA.ACT_SET_TYP | G24: Sublot No. result type | H24: サブロットＮＯ実績区分 | I24: E | K24: E
... A64: 10 | D64: upd_cntr | E64: #MA.UPD_CNT | G64: Update counter | H64: 更新カウンタ | I64: E | K64: E
D65: 詳細 :

Sheet CalcPtnLcl_UpdChk01
A1: * | B1: * | D1: L | E1: 1
A2: * | D2: オペレーション実装仕様書 Operation Specification Implementation Sheet | E2: ModuleID : | F2: =IF(LogicCommon!C2="","",LogicCommon!C2) -> MA | G2: LogicID : | H2: =IF(LogicCommon!E2="","",LogicCommon!E2) -> MABGL0100 | I2: Ope.ID : | J2: CalcPtnLcl_UpdChk01 | K2: Pj.ID : | L2: =IF(LogicCommon!G2="","",LogicCommon!G2) -> MC | M2: Ope.Body : | N2: =L4 & ".Checker" -> MA.MAUDL5010.Checker
A3: * | D3: =IF(LogicCommon!A3="","",LogicCommon!A3) | E3: SubModuleID : | F3: =IF(LogicCommon!C3="","",LogicCommon!C3) -> MABG | G3: LogicClass : | H3: =IF(LogicCommon!E3="","",LogicCommon!E3) -> MABGL_CalcPtnReg | I3: Ope.Method : | J3: @ | K3: SuperClassPj.ID : | L3: =IF(LogicCommon!G3="","",LogicCommon!G3) | M3: ReportID : | O3: Gene.Type : | P3: ALL
A4: * | E4: Version : | F4: 000000 | G4: LogicName : | H4: =IF(LogicCommon!E4="","",LogicCommon!E4) -> 計算パタンマスタ登録 | I4: Ope.Name : | J4: 登録前チェック(ロケール別情報) | K4: SuperLogicID : | L4: =IF(LogicCommon!G4="","",LogicCommon!G4) -> MA.MAUDL5010
A5: * | E5: ACType :
A6: * | D6: 概要 : | E6: 計算パタンマスタ(ロケール別情報)を登録する前のチェックを行う | Q6: ID
A7: # | I7: U | K7: K | P7: o | Q7: EXISTS.chk01
A8: # | D8: ブロック名 Block Name | E8: 型 Type | G8: super/share | H8: 対象ブロック名 Target Block Name | K8: REQUIRED | P8: TargetName | Q8: DBC.MA.MAM_CALC_PTN | T8: ブロック備考 Block Remarks
A9: # | D9: 項目名 Field Name | E9: 型 Type | F9: 桁 Digits | G9: フルネーム Full Name | H9: 日本語名 Japanese Name | I9: 上り項目 Request Message Field | J9: 下り項目 Response Message Field | R9: 条件および編集方法 Conditions and Editing Methods | T9: 項目備考 Field Remarks
A10: # | P10: 上り項目 Request Message Field | Q10: 下り項目 Response Message Field
A11: 10 | B11: * | D11: CalcPtnLcl_UpdChk01_Dtl | E11: L | G11: $super$ | H11: DBC:MA.MAM_CALC_PTN_LCL | P11: L
A12: 10 | D12: calc_ptn_cd | E12: #MA.CALC_PTN_CD | G12: Calculation pattern cd. | H12: 計算パタンＣＤ | I12: E | K12: E | P12: E
A13: 10 | D13: lcl_cd | E13: #MA.LCL_CD | G13: Locale cd. | H13: ロケールＣＤ | I13: E | K13: E
A14: 10 | D14: calc_ptn_nm | E14: #MA.CALC_PTN_NM | G14: Calculation pattern name | H14: 計算パタン名 | I14: E | K14: E
A15: 10 | D15: memo1 | E15: #MA.MST_MEMO1 | G15: Memo 1 | H15: メモ１ | I15: E
A16: 10 | D16: memo2 | E16: #MA.MST_MEMO2 | G16: Memo 2 | H16: メモ２ | I16: E
A17: 10 | D17: memo3 | E17: #MA.MST_MEMO3 | G17: Memo 3 | H17: メモ３ | I17: E
A18: 10 | D18: upd_cntr | E18: #MA.UPD_CNT | G18: Update counter | H18: 更新カウンタ | I18: E
D19: 詳細 :

Sheet CalcPtnLcl_Upd01
A1: * | B1: * | D1: L | E1: 1
A2: * | D2: オペレーション実装仕様書 Operation Specification Implementation Sheet | E2: ModuleID : | F2: =IF(LogicCommon!C2="","",LogicCommon!C2) -> MA | G2: LogicID : | H2: =IF(LogicCommon!E2="","",LogicCommon!E2) -> MABGL0100 | I2: Ope.ID : | J2: CalcPtnLcl_Upd01 | K2: Pj.ID : | L2: =IF(LogicCommon!G2="","",LogicCommon!G2) -> MC | M2: Ope.Body : | N2: "mcframe.serverMAUD.MAUDL6020.MAUDL_LCLRLUpdater"
A3: * | D3: =IF(LogicCommon!A3="","",LogicCommon!A3) | E3: SubModuleID : | F3: =IF(LogicCommon!C3="","",LogicCommon!C3) -> MABG | G3: LogicClass : | H3: =IF(LogicCommon!E3="","",LogicCommon!E3) -> MABGL_CalcPtnReg | I3: Ope.Method : | J3: @ | K3: SuperClassPj.ID : | L3: =IF(LogicCommon!G3="","",LogicCommon!G3) | M3: ReportID : | O3: Gene.Type : | P3: ALL
A4: * | E4: Version : | F4: 000000 | G4: LogicName : | H4: =IF(LogicCommon!E4="","",LogicCommon!E4) -> 計算パタンマスタ登録 | I4: Ope.Name : | J4: 登録処理(ロケール別情報) | K4: SuperLogicID : | L4: =IF(LogicCommon!G4="","",LogicCommon!G4) -> MA.MAUDL5010
A5: * | E5: ACType :
A6: * | D6: 概要 : | E6: 計算パタンマスタ(ロケール別情報)を登録する | L6: ID | N6: ID | P6: ID | R6: ID
A7: # | I7: U | K7: o | L7: UPDATE.updMaster | M7: o | N7: MAIN.chkMaster | O7: o | Q7: o
A8: # | D8: ブロック名 Block Name | E8: 型 Type | G8: super/share | H8: 対象ブロック名 Target Block Name | K8: TargetName | L8: DBC.MA.MAM_CALC_PTN_LCL | M8: TargetName | N8: DBC.MA.MAM_CALC_PTN_LCL | O8: TargetName | Q8: TargetName | U8: ブロック備考 Block Remarks
A9: # | D9: 項目名 Field Name | E9: 型 Type | F9: 桁 Digits | G9: フルネーム Full Name | H9: 日本語名 Japanese Name | I9: 上り項目 Request Message Field | J9: 下り項目 Response Message Field | S9: 条件および編集方法 Conditions and Editing Methods | U9: 項目備考 Field Remarks
A10: # | K10: 上り項目 Request Message Field | L10: 下り項目 Response Message Field | M10: 上り項目 Request Message Field | N10: 下り項目 Response Message Field | O10: 上り項目 Request Message Field | P10: 下り項目 Response Message Field | Q10: 上り項目 Request Message Field | R10: 下り項目 Response Message Field
A11: 10 | B11: * | D11: CalcPtnLcl_Upd01_Dtl | E11: L | G11: $share$ | H11: MA.MABGL0100.CalcPtnLcl_UpdChk01.CalcPtnLcl_UpdChk01_Dtl | K11: L | M11: L
A12: 10 | D12: calc_ptn_cd | E12: #MA.CALC_PTN_CD | G12: Calculation pattern cd. | H12: 計算パタンＣＤ | I12: E | K12: E | M12: E
A13: 10 | D13: lcl_cd | E13: #MA.LCL_CD | G13: Locale cd. | H13: ロケールＣＤ | I13: E | K13: E | M13: E
A14: 10 | D14: calc_ptn_nm | E14: #MA.CALC_PTN_NM | G14: Calculation pattern name | H14: 計算パタン名 | I14: E | K14: E
A15: 10 | D15: memo1 | E15: #MA.MST_MEMO1 | G15: Memo 1 | H15: メモ１ | I15: E | K15: E
A16: 10 | D16: memo2 | E16: #MA.MST_MEMO2 | G16: Memo 2 | H16: メモ２ | I16: E | K16: E
A17: 10 | D17: memo3 | E17: #MA.MST_MEMO3 | G17: Memo 3 | H17: メモ３ | I17: E | K17: E
A18: 10 | D18: upd_cntr | E18: #MA.UPD_CNT | G18: Update counter | H18: 更新カウンタ | I18: E | K18: E
D19: 詳細 :

Sheet CalcPtn_DelChk01
A1: * | B1: * | D1: L | E1: 1
A2: * | D2: オペレーション実装仕様書 Operation Specification Implementation Sheet | E2: ModuleID : | F2: =IF(LogicCommon!C2="","",LogicCommon!C2) -> MA | G2: LogicID : | H2: =IF(LogicCommon!E2="","",LogicCommon!E2) -> MABGL0100 | I2: Ope.ID : | J2: CalcPtn_DelChk01 | K2: Pj.ID : | L2: =IF(LogicCommon!G2="","",LogicCommon!G2) -> MC | M2: Ope.Body : | N2: =L4 & ".Checker" -> MA.MAUDL5010.Checker
A3: * | D3: =IF(LogicCommon!A3="","",LogicCommon!A3) | E3: SubModuleID : | F3: =IF(LogicCommon!C3="","",LogicCommon!C3) -> MABG | G3: LogicClass : | H3: =IF(LogicCommon!E3="","",LogicCommon!E3) -> MABGL_CalcPtnReg | I3: Ope.Method : | J3: @ | K3: SuperClassPj.ID : | L3: =IF(LogicCommon!G3="","",LogicCommon!G3) | M3: ReportID : | O3: Gene.Type : | P3: ALL
A4: * | E4: Version : | F4: 000000 | G4: LogicName : | H4: =IF(LogicCommon!E4="","",LogicCommon!E4) -> 計算パタンマスタ登録 | I4: Ope.Name : | J4: 削除前チェック | K4: SuperLogicID : | L4: =IF(LogicCommon!G4="","",LogicCommon!G4) -> MA.MAUDL5010
A5: * | E5: ACType :
A6: * | D6: 概要 : | E6: 計算パタンマスタ、計算パタンマスタ(ロケール別情報)を削除する前のチェックを行う | Q6: ID
A7: # | I7: U | K7: K | P7: o
A8: # | D8: ブロック名 Block Name | E8: 型 Type | G8: super/share | H8: 対象ブロック名 Target Block Name | K8: REQUIRED | P8: TargetName | T8: ブロック備考 Block Remarks
A9: # | D9: 項目名 Field Name | E9: 型 Type | F9: 桁 Digits | G9: フルネーム Full Name | H9: 日本語名 Japanese Name | I9: 上り項目 Request Message Field | J9: 下り項目 Response Message Field | R9: 条件および編集方法 Conditions and Editing Methods | T9: 項目備考 Field Remarks
A10: # | P10: 上り項目 Request Message Field | Q10: 下り項目 Response Message Field
A11: 10 | B11: * | D11: CalcPtn_DelChk01_Dtl | E11: L
A12: 10 | D12: calc_ptn_cd | E12: #MA.CALC_PTN_CD | G12: Calculation pattern cd. | H12: 計算パタンＣＤ | I12: E | K12: E
A13: 10 | D13: upd_cntr | E13: #MA.UPD_CNT | G13: Update counter | H13: 更新カウンタ | I13: E
D14: 詳細 :

Sheet CalcPtn_Del01
A1: * | B1: * | D1: L | E1: 1
A2: * | D2: オペレーション実装仕様書 Operation Specification Implementation Sheet | E2: ModuleID : | F2: =IF(LogicCommon!C2="","",LogicCommon!C2) -> MA | G2: LogicID : | H2: =IF(LogicCommon!E2="","",LogicCommon!E2) -> MABGL0100 | I2: Ope.ID : | J2: CalcPtn_Del01 | K2: Pj.ID : | L2: =IF(LogicCommon!G2="","",LogicCommon!G2) -> MC | M2: Ope.Body : | N2: "mcframe.serverMAUD.MAUDL6020.MAUDL_LCLRLDeleter"
A3: * | D3: =IF(LogicCommon!A3="","",LogicCommon!A3) | E3: SubModuleID : | F3: =IF(LogicCommon!C3="","",LogicCommon!C3) -> MABG | G3: LogicClass : | H3: =IF(LogicCommon!E3="","",LogicCommon!E3) -> MABGL_CalcPtnReg | I3: Ope.Method : | J3: @ | K3: SuperClassPj.ID : | L3: =IF(LogicCommon!G3="","",LogicCommon!G3) | M3: ReportID : | O3: Gene.Type : | P3: ALL
A4: * | E4: Version : | F4: 000000 | G4: LogicName : | H4: =IF(LogicCommon!E4="","",LogicCommon!E4) -> 計算パタンマスタ登録 | I4: Ope.Name : | J4: 削除処理 | K4: SuperLogicID : | L4: =IF(LogicCommon!G4="","",LogicCommon!G4) -> MA.MAUDL5010
A5: * | E5: ACType :
A6: * | D6: 概要 : | E6: 計算パタンマスタ、計算パタンマスタ(ロケール別情報)を削除する | L6: ID | N6: ID
A7: # | I7: U | K7: o | L7: UPDATE.updMaster1 | M7: o | N7: UPDATE.updMaster2
A8: # | D8: ブロック名 Block Name | E8: 型 Type | G8: super/share | H8: 対象ブロック名 Target Block Name | K8: TargetName | L8: DBC.MA.MAM_CALC_PTN | M8: TargetName | N8: DBC.MA.MAM_CALC_PTN_LCL | Q8: ブロック備考 Block Remarks
A9: # | D9: 項目名 Field Name | E9: 型 Type | F9: 桁 Digits | G9: フルネーム Full Name | H9: 日本語名 Japanese Name | I9: 上り項目 Request Message Field | J9: 下り項目 Response Message Field | O9: 条件および編集方法 Conditions and Editing Methods | Q9: 項目備考 Field Remarks
A10: # | K10: 上り項目 Request Message Field | L10: 下り項目 Response Message Field | M10: 上り項目 Request Message Field | N10: 下り項目 Response Message Field
A11: 10 | B11: * | D11: CalcPtn_Del01_Dtl | E11: L | G11: $share$ | H11: MA.MABGL0100.CalcPtn_DelChk01.CalcPtn_DelChk01_Dtl | K11: L | M11: L
A12: 10 | D12: calc_ptn_cd | E12: #MA.CALC_PTN_CD | G12: Calculation pattern cd. | H12: 計算パタンＣＤ | I12: E | K12: E | M12: E
A13: 10 | D13: upd_cntr | E13: #MA.UPD_CNT | G13: Update counter | H13: 更新カウンタ | I13: E | K13: E
D14: 詳細 :

Sheet Srch01
A1: * | B1: * | D1: L | E1: 1
A2: * | D2: オペレーション実装仕様書 Operation Specification Implementation Sheet | E2: ModuleID : | F2: =IF(LogicCommon!C2="","",LogicCommon!C2) -> MA | G2: LogicID : | H2: =IF(LogicCommon!E2="","",LogicCommon!E2) -> MABGL0100 | I2: Ope.ID : | J2: Srch01 | K2: Pj.ID : | L2: =IF(LogicCommon!G2="","",LogicCommon!G2) -> MC | M2: Ope.Body : | N2: "mcframe.serverMAUD.MAUDL6020.MAUDL_LCLRLSearcher"
A3: * | D3: =IF(LogicCommon!A3="","",LogicCommon!A3) | E3: SubModuleID : | F3: =IF(LogicCommon!C3="","",LogicCommon!C3) -> MABG | G3: LogicClass : | H3: =IF(LogicCommon!E3="","",LogicCommon!E3) -> MABGL_CalcPtnReg | I3: Ope.Method : | J3: @ | K3: SuperClassPj.ID : | L3: =IF(LogicCommon!G3="","",LogicCommon!G3) | M3: ReportID : | O3: Gene.Type : | P3: ALL
A4: * | E4: Version : | F4: 000000 | G4: LogicName : | H4: =IF(LogicCommon!E4="","",LogicCommon!E4) -> 計算パタンマスタ登録 | I4: Ope.Name : | J4: 検索 | K4: SuperLogicID : | L4: =IF(LogicCommon!G4="","",LogicCommon!G4) -> MA.MAUDL5010
A5: * | E5: ACType :
A6: * | D6: 概要 : | E6: 検索処理を行う | L6: ID | M6: ID | N6: ID | O6: ID
A7: # | I7: U | K7: K | L7: o | M7: SELECT.c0 | N7: o | O7: SELECT_LCL.c1
A8: # | D8: ブロック名 Block Name | E8: 型 Type | G8: super/share | H8: 対象ブロック名 Target Block Name | K8: CONST | L8: TargetName | M8: DBC.MA.MAM_CALC_PTN | N8: TargetName | O8: DBC.MA.MAM_CALC_PTN_LCL | R8: ブロック備考 Block Remarks
A9: # | D9: 項目名 Field Name | E9: 型 Type | F9: 桁 Digits | G9: フルネーム Full Name | H9: 日本語名 Japanese Name | I9: 上り項目 Request Message Field | J9: 下り項目 Response Message Field | P9: 条件および編集方法 Conditions and Editing Methods | R9: 項目備考 Field Remarks
A10: # | L10: 上り項目 Request Message Field | M10: 下り項目 Response Message Field | N10: 上り項目 Request Message Field | O10: 下り項目 Response Message Field
A11: 10 | B11: * | D11: Srch01_Cnd | E11: R | L11: R
A12: 10 | D12: calc_ptn_cd | E12: #MA.CALC_PTN_CD | G12: Calculation pattern cd. | H12: 計算パタンＣＤ | I12: E | L12: E
A13: 10 | D13: calc_ptn_nm_lcl | E13: #MA.CALC_PTN_NM | G13: Calculation pattern name | H13: 計算パタン名 | I13: E | L13: E
A14: 10 | D14: off_del_flg | E14: #MA.FLG | G14: Logical delete flg. (Off) | H14: 論理削除ＦＬＧ（オフ） | I14: E
A15: 10 | D15: on_del_flg | E15: #MA.FLG | G15: Logical delete flg. (On) | H15: 論理削除ＦＬＧ（オン） | I15: E
A16: 10 | D16: memo1 | E16: #MA.MST_MEMO1 | G16: Memo 1 | H16: メモ１ | I16: E | L16: E
A17: 10 | D17: memo2 | E17: #MA.MST_MEMO2 | G17: Memo 2 | H17: メモ２ | I17: E | L17: E
A18: 10 | D18: memo3 | E18: #MA.MST_MEMO3 | G18: Memo 3 | H18: メモ３ | I18: E | L18: E
A20: 20 | B20: * | D20: Srch01_Rslt1 | E20: L | M20: L
A21: 20 | D21: del_flg | E21: #MA.FLG | G21: Logical delete | H21: 論理削除 | J21: E | M21: E
A22: 20 | D22: calc_ptn_cd | E22: #MA.CALC_PTN_CD | G22: Calculation pattern cd. | H22: 計算パタンＣＤ | J22: E | M22: E
A23: 20 | D23: calc_ptn_nm_lcl | E23: #MA.CALC_PTN_NM | G23: Calculation pattern name | H23: 計算パタン名 | J23: E | M23: calc_ptn_nm
A24: 20 | D24: calc_ptn_nm | E24: #MA.CALC_PTN_NM | G24: Standard calculation pattern name | H24: 標準計算パタン名 | J24: E | M24: base_calc_ptn_nm
A25: 20 | D25: mfg_purc_typ | E25: #MA.MFG_PURC_TYP | G25: Mfg. purchase type | H25: 製造購買区分 | J25: E | K25: MAC_MFG_PURC_TYP | M25: E
A26: 20 | D26: mfg_purc_typ_nm | E26: #MA.MFG_PURC_TYP_NM | G26: Mfg. purchase type name | H26: 製造購買区分名 | J26: E
A27: 20 | D27: eval_typ | E27: #MA.EVAL_TYP | G27: Amount evaluation type | H27: 金額評価区分 | J27: E | K27: MAC_EVAL_TYP | M27: E
A28: 20 | D28: eval_typ_nm | E28: #MA.EVAL_TYP_NM | G28: Amount evaluation type name | H28: 金額評価区分名 | J28: E
A29: 20 | D29: dpt_typ | E29: #MA.UNIT_CALC_TYP | G29: Dept. calculation type | H29: 部門計算区分 | J29: E | K29: MAC_UNIT_CALC_TYP | M29: E
A30: 20 | D30: dpt_typ_nm | E30: #MA.UNIT_CALC_TYP_NM | G30: Dept. calculation type name | H30: 部門計算区分名 | J30: E
A31: 20 | D31: lot_typ | E31: #MA.UNIT_CALC_TYP | G31: Lot No. calculation type | H31: ロットＮＯ計算区分 | J31: E | K31: MAC_UNIT_CALC_TYP | M31: E
A32: 20 | D32: lot_typ_nm | E32: #MA.UNIT_CALC_TYP_NM | G32: Lot No. calculation type name | H32: ロットＮＯ計算区分名 | J32: E
A33: 20 | D33: sublot_typ | E33: #MA.UNIT_CALC_TYP | G33: Sublot No. calculation type | H33: サブロットＮＯ計算区分 | J33: E | K33: MAC_UNIT_CALC_TYP | M33: E
A34: 20 | D34: sublot_typ_nm | E34: #MA.UNIT_CALC_TYP_NM | G34: Sublot No. calculation type name | H34: サブロットＮＯ計算区分名 | J34: E
A35: 20 | D35: sno1_typ | E35: #MA.UNIT_CALC_TYP | G35: SEIBAN No. 1 calculation type | H35: 手配ＮＯ１計算区分 | J35: E | K35: MAC_UNIT_CALC_TYP | M35: E
A36: 20 | D36: sno1_typ_nm | E36: #MA.UNIT_CALC_TYP_NM | G36: SEIBAN No. 1 calculation type name | H36: 手配ＮＯ１計算区分名 | J36: E
A37: 20 | D37: sno2_typ | E37: #MA.UNIT_CALC_TYP | G37: SEIBAN No. 2 calculation type | H37: 手配ＮＯ２計算区分 | J37: E | K37: MAC_UNIT_CALC_TYP | M37: E
A38: 20 | D38: sno2_typ_nm | E38: #MA.UNIT_CALC_TYP_NM | G38: SEIBAN No. 2 calculation type name | H38: 手配ＮＯ２計算区分名 | J38: E
A39: 20 | D39: sno3_typ | E39: #MA.UNIT_CALC_TYP | G39: SEIBAN No. 3 calculation type | H39: 手配ＮＯ３計算区分 | J39: E | K39: MAC_UNIT_CALC_TYP | M39: E
A40: 20 | D40: sno3_typ_nm | E40: #MA.UNIT_CALC_TYP_NM | G40: SEIBAN No. 3 calculation type name | H40: 手配ＮＯ３計算区分名 | J40: E
A41: 20 | D41: sno4_typ | E41: #MA.UNIT_CALC_TYP | G41: SEIBAN No. 4 calculation type | H41: 手配ＮＯ４計算区分 | J41: E | K41: MAC_UNIT_CALC_TYP | M41: E
...

Sheet Upd01
A1: * | B1: * | D1: L | E1: 1
A2: * | D2: オペレーション実装仕様書 Operation Specification Implementation Sheet | E2: ModuleID : | F2: =IF(LogicCommon!C2="","",LogicCommon!C2) -> MA | G2: LogicID : | H2: =IF(LogicCommon!E2="","",LogicCommon!E2) -> MABGL0100 | I2: Ope.ID : | J2: Upd01 | K2: Pj.ID : | L2: =IF(LogicCommon!G2="","",LogicCommon!G2) -> MC | M2: Ope.Body : | N2: "mcframe.serverMAUD.MAUDL6020.MAUDL_LCLRLUpdater"
A3: * | D3: =IF(LogicCommon!A3="","",LogicCommon!A3) | E3: SubModuleID : | F3: =IF(LogicCommon!C3="","",LogicCommon!C3) -> MABG | G3: LogicClass : | H3: =IF(LogicCommon!E3="","",LogicCommon!E3) -> MABGL_CalcPtnReg | I3: Ope.Method : | J3: @ | K3: SuperClassPj.ID : | L3: =IF(LogicCommon!G3="","",LogicCommon!G3) | M3: ReportID : | O3: Gene.Type : | P3: ALL
A4: * | E4: Version : | F4: 000000 | G4: LogicName : | H4: =IF(LogicCommon!E4="","",LogicCommon!E4) -> 計算パタンマスタ登録 | I4: Ope.Name : | J4: 登録 | K4: SuperLogicID : | L4: =IF(LogicCommon!G4="","",LogicCommon!G4) -> MA.MAUDL5010
A5: * | E5: ACType :
A6: * | D6: 概要 : | E6: 登録処理を行う | L6: ID | N6: ID | P6: ID | R6: ID
A7: # | I7: U | K7: o | L7: CALL_OPE01.chk01 | M7: o | N7: CALL_OPE01.upd01 | O7: o | P7: CALL_OPE02.chk02 | Q7: o | R7: CALL_OPE02.upd02
A8: # | D8: ブロック名 Block Name | E8: 型 Type | G8: super/share | H8: 対象ブロック名 Target Block Name | K8: TargetName | L8: OPE.MA.MABGL0100.CalcPtn_UpdChk01 | M8: TargetName | N8: OPE.MA.MABGL0100.CalcPtn_Upd01 | O8: TargetName | P8: OPE.MA.MABGL0100.CalcPtnLcl_UpdChk01 | Q8: TargetName | R8: OPE.MA.MABGL0100.CalcPtnLcl_Upd01 | U8: ブロック備考 Block Remarks
A9: # | D9: 項目名 Field Name | E9: 型 Type | F9: 桁 Digits | G9: フルネーム Full Name | H9: 日本語名 Japanese Name | I9: 上り項目 Request Message Field | J9: 下り項目 Response Message Field | S9: 条件および編集方法 Conditions and Editing Methods | U9: 項目備考 Field Remarks
A10: # | K10: 上り項目 Request Message Field | L10: 下り項目 Response Message Field | M10: 上り項目 Request Message Field | N10: 下り項目 Response Message Field | O10: 上り項目 Request Message Field | P10: 下り項目 Response Message Field | Q10: 上り項目 Request Message Field | R10: 下り項目 Response Message Field
A11: 10 | B11: * | D11: Upd01_Dtl1 | E11: L | G11: $share$ | H11: MA.MABGL0100.CalcPtn_Upd01.CalcPtn_Upd01_Dtl | K11: CalcPtn_UpdChk01_Dtl | M11: CalcPtn_Upd01_Dtl
A12: 10 | D12: calc_ptn_cd | E12: #MA.CALC_PTN_CD | G12: Calculation pattern cd. | H12: 計算パタンＣＤ | I12: E | K12: E | M12: E
A13: 10 | D13: calc_ptn_nm | E13: #MA.CALC_PTN_NM | G13: Calculation pattern name | H13: 計算パタン名 | I13: E | K13: E | M13: E
A14: 10 | D14: mfg_purc_typ | E14: #MA.MFG_PURC_TYP | G14: Mfg. purchase type | H14: 製造購買区分 | I14: E | K14: E | M14: E
A15: 10 | D15: eval_typ | E15: #MA.EVAL_TYP | G15: Amount evaluation type | H15: 金額評価区分 | I15: E | K15: E | M15: E
A16: 10 | D16: dpt_typ | E16: #MA.UNIT_CALC_TYP | G16: Dept. calculation type | H16: 部門計算区分 | I16: E | K16: E | M16: E
A17: 10 | D17: lot_typ | E17: #MA.UNIT_CALC_TYP | G17: Lot No. calculation type | H17: ロットＮＯ計算区分 | I17: E | K17: E | M17: E
A18: 10 | D18: sublot_typ | E18: #MA.UNIT_CALC_TYP | G18: Sublot No. calculation type | H18: サブロットＮＯ計算区分 | I18: E | K18: E | M18: E
A19: 10 | D19: sno1_typ | E19: #MA.UNIT_CALC_TYP | G19: SEIBAN No. 1 calculation type | H19: 手配ＮＯ１計算区分 | I19: E | K19: E | M19: E
A20: 10 | D20: sno2_typ | E20: #MA.UNIT_CALC_TYP | G20: SEIBAN No. 2 calculation type | H20: 手配ＮＯ２計算区分 | I20: E | K20: E | M20: E
A21: 10 | D21: sno3_typ | E21: #MA.UNIT_CALC_TYP | G21: SEIBAN No. 3 calculation type | H21: 手配ＮＯ３計算区分 | I21: E | K21: E | M21: E
A22: 10 | D22: sno4_typ | E22: #MA.UNIT_CALC_TYP | G22: SEIBAN No. 4 calculation type | H22: 手配ＮＯ４計算区分 | I22: E | K22: E | M22: E
A23: 10 | D23: lot_act_typ | E23: #MA.ACT_SET_TYP | G23: Lot No. result type | H23: ロットＮＯ実績区分 | I23: E | K23: E | M23: E
... A64: 10 | D64: upd_cntr | E64: #MA.UPD_CNT | G64: Update counter | H64: 更新カウンタ | I64: E | K64: E | M64: E
A66: 20 | B66: * | D66: Upd01_Dtl2 | E66: L | G66: $share$ | H66: MA.MABGL0100.CalcPtnLcl_Upd01.CalcPtnLcl_Upd01_Dtl | O66: CalcPtnLcl_UpdChk01_Dtl | Q66: CalcPtnLcl_Upd01_Dtl
A67: 20 | D67: calc_ptn_cd | E67: #MA.CALC_PTN_CD | G67: Calculation pattern cd. | H67: 計算パタンＣＤ | I67: E | O67: E | Q67: E
A68: 20 | D68: lcl_cd | E68: #MA.LCL_CD | G68: Locale cd. | H68: ロケールＣＤ | I68: E | O68: E | Q68: E
A69: 20 | D69: calc_ptn_nm | E69: #MA.CALC_PTN_NM | G69: Calculation pattern name | H69: 計算パタン名 | I69: E | O69: E | Q69: E
A70: 20 | D70: memo1 | E70: #MA.MST_MEMO1 | G70: Memo 1 | H70: メモ１ | I70: E | O70: E | Q70: E
A71: 20 | D71: memo2 | E71: #MA.MST_MEMO2 | G71: Memo 2 | H71: メモ２ | I71: E | O71: E | Q71: E
A72: 20 | D72: memo3 | E72: #MA.MST_MEMO3 | G72: Memo 3 | H72: メモ３ | I72: E | O72: E | Q72: E
A73: 20 | D73: upd_cntr | E73: #MA.UPD_CNT | G73: Update counter | H73: 更新カウンタ | I73: E | O73: E | Q73: E
D74: 詳細 :

Sheet Del01
A1: * | B1: * | D1: L | E1: 1
A2: * | D2: オペレーション実装仕様書 Operation Specification Implementation Sheet | E2: ModuleID : | F2: =IF(LogicCommon!C2="","",LogicCommon!C2) -> MA | G2: LogicID : | H2: =IF(LogicCommon!E2="","",LogicCommon!E2) -> MABGL0100 | I2: Ope.ID : | J2: Del01 | K2: Pj.ID : | L2: =IF(LogicCommon!G2="","",LogicCommon!G2) -> MC | M2: Ope.Body : | N2: "mcframe.serverMAUD.MAUDL6020.MAUDL_LCLRLDeleter"
A3: * | D3: =IF(LogicCommon!A3="","",LogicCommon!A3) | E3: SubModuleID : | F3: =IF(LogicCommon!C3="","",LogicCommon!C3) -> MABG | G3: LogicClass : | H3: =IF(LogicCommon!E3="","",LogicCommon!E3) -> MABGL_CalcPtnReg | I3: Ope.Method : | J3: @ | K3: SuperClassPj.ID : | L3: =IF(LogicCommon!G3="","",LogicCommon!G3) | M3: ReportID : | O3: Gene.Type : | P3: ALL
A4: * | E4: Version : | F4: 000000 | G4: LogicName : | H4: =IF(LogicCommon!E4="","",LogicCommon!E4) -> 計算パタンマスタ登録 | I4: Ope.Name : | J4: 削除 | K4: SuperLogicID : | L4: =IF(LogicCommon!G4="","",LogicCommon!G4) -> MA.MAUDL5010
A5: * | E5: ACType :
A6: * | D6: 概要 : | E6: 削除処理を行う | L6: ID | N6: ID
A7: # | I7: U | K7: o | L7: CALL_OPE01.chk01 | M7: o | N7: CALL_OPE01.del01
A8: # | D8: ブロック名 Block Name | E8: 型 Type | G8: super/share | H8: 対象ブロック名 Target Block Name | K8: TargetName | L8: OPE.MA.MABGL0100.CalcPtn_DelChk01 | M8: TargetName | N8: OPE.MA.MABGL0100.CalcPtn_Del01 | Q8: ブロック備考 Block Remarks
A9: # | D9: 項目名 Field Name | E9: 型 Type | F9: 桁 Digits | G9: フルネーム Full Name | H9: 日本語名 Japanese Name | I9: 上り項目 Request Message Field | J9: 下り項目 Response Message Field | O9: 条件および編集方法 Conditions and Editing Methods | Q9: 項目備考 Field Remarks
A10: # | K10: 上り項目 Request Message Field | L10: 下り項目 Response Message Field | M10: 上り項目 Request Message Field | N10: 下り項目 Response Message Field
A11: 10 | B11: * | D11: Del01_Dtl1 | E11: L | G11: $share$ | H11: MA.MABGL0100.CalcPtn_Del01.CalcPtn_Del01_Dtl | K11: CalcPtn_DelChk01_Dtl | M11: CalcPtn_Del01_Dtl
A12: 10 | D12: calc_ptn_cd | E12: #MA.CALC_PTN_CD | G12: Calculation pattern cd. | H12: 計算パタンＣＤ | I12: E | K12: E | M12: E
A13: 10 | D13: upd_cntr | E13: #MA.UPD_CNT | G13: Update counter | H13: 更新カウンタ | I13: E | K13: E | M13: E
D14: 詳細 :

Sheet 来歴
A1: 変更来歴
A3: Rev. | H3: 修正番号 | O3: 変更内容 | AQ3: 変更箇所
A4: 1 | O4: 初版
A5: 1.1 | O5: 英語の名称を追記 | AQ5: 全般
