Workbook

Sheet LogicCommon
A2: ロジック共通定義 | B2: ModuleID : | C2: MA | D2: LogicID : | E2: MABGL0110 | G2: MC
B3: SubModuleID : | C3: MABG | D3: LogicClass : | E3: MABGL_GrpPtn
D4: LogicName : | E4: 計算グループパタンマスタ | G4: MA.MAUDL5010
A5: 概要 :
A6: 詳細 :

Sheet GrpPtn_UpdChk01
A1: * | B1: * | D1: L | E1: 1
A2: * | D2: オペレーション実装仕様書 Operation Specification Implementation Sheet | E2: ModuleID : | F2: =IF(LogicCommon!C2="","",LogicCommon!C2) -> MA | G2: LogicID : | H2: =IF(LogicCommon!E2="","",LogicCommon!E2) -> MABGL0110 | I2: Ope.ID : | J2: GrpPtn_UpdChk01 | K2: Pj.ID : | L2: =IF(LogicCommon!G2="","",LogicCommon!G2) -> MC | M2: Ope.Body : | N2: =L4 & ".Checker" -> MA.MAUDL5010.Checker
A3: * | D3: =IF(LogicCommon!A3="","",LogicCommon!A3) | E3: SubModuleID : | F3: =IF(LogicCommon!C3="","",LogicCommon!C3) -> MABG | G3: LogicClass : | H3: =IF(LogicCommon!E3="","",LogicCommon!E3) -> MABGL_GrpPtn | I3: Ope.Method : | J3: @ | K3: SuperClassPj.ID : | L3: =IF(LogicCommon!G3="","",LogicCommon!G3) | M3: ReportID : | O3: Gene.Type : | P3: ALL
A4: * | E4: Version : | F4: 000000 | G4: LogicName : | H4: =IF(LogicCommon!E4="","",LogicCommon!E4) -> 計算グループパタンマスタ | I4: Ope.Name : | J4: 登録前チェック | K4: SuperLogicID : | L4: =IF(LogicCommon!G4="","",LogicCommon!G4) -> MA.MAUDL5010
A5: * | E5: ACType :
A6: * | D6: 概要 : | E6: 計算グループパタンマスタを登録する前のチェックを行う | S6: ID
A7: # | I7: U | K7: K | L7: K | M7: K | N7: K | O7: K | P7: K | R7: o
A8: # | D8: ブロック名 Block Name | E8: 型 Type | G8: super/share | H8: 対象ブロック名 Target Block Name | K8: REQUIRED | L8: CONST | M8: SMALL_LARGE | N8: LIST_LOGIC | O8: LIST_IN | P8: LIST_IN_BASE | R8: TargetName | V8: ブロック備考 Block Remarks
A9: # | D9: 項目名 Field Name | E9: 型 Type | F9: 桁 Digits | G9: フルネーム Full Name | H9: 日本語名 Japanese Name | I9: 上り項目 Request Message Field | J9: 下り項目 Response Message Field | T9: 条件および編集方法 Conditions and Editing Methods | V9: 項目備考 Field Remarks
A10: # | R10: 上り項目 Request Message Field | S10: 下り項目 Response Message Field
A11: 10 | B11: * | D11: GrpPtn_UpdChk01_Dtl | E11: L | G11: $super$ | H11: DBC:MA.MAM_GRP_PTN
A12: 10 | D12: calc_ptn_cd | E12: #MA.CALC_PTN_CD | G12: Calculation pattern cd. | H12: 計算パタンＣＤ | I12: E | K12: E | N12: MA.MAUAL0010.CalcPtn
A13: 10 | D13: calc_grp_cd | E13: #MA.CALC_GRP_CD | G13: Calculation group cd. | H13: 計算グループＣＤ | I13: E | K13: E | N13: MA.MAUAL0010.CalcGrp
A14: 10 | D14: mfg_purc_typ | E14: #MA.MFG_PURC_TYP | G14: Mfg. purchase type | H14: 製造購買区分 | I14: E | L14: MAC_MFG_PURC_TYP
A15: 10 | D15: eval_typ | E15: #MA.EVAL_TYP | G15: Amount evaluation type | H15: 金額評価区分 | I15: E | L15: MAC_EVAL_TYP
A16: 10 | D16: dpt_typ | E16: #MA.UNIT_CALC_TYP | G16: Dept. calculation type | H16: 部門計算区分 | I16: E | L16: MAC_UNIT_CALC_TYP
A17: 10 | D17: lot_typ | E17: #MA.UNIT_CALC_TYP | G17: Lot No. calculation type | H17: ロットＮＯ計算区分 | I17: E | L17: MAC_UNIT_CALC_TYP
A18: 10 | D18: sublot_typ | E18: #MA.UNIT_CALC_TYP | G18: Sublot No. calculation type | H18: サブロットＮＯ計算区分 | I18: E | L18: MAC_UNIT_CALC_TYP
A19: 10 | D19: sno1_typ | E19: #MA.UNIT_CALC_TYP | G19: SEIBAN No. 1 calculation type | H19: 手配ＮＯ１計算区分 | I19: E | L19: MAC_UNIT_CALC_TYP
A20: 10 | D20: sno2_typ | E20: #MA.UNIT_CALC_TYP | G20: SEIBAN No. 2 calculation type | H20: 手配ＮＯ２計算区分 | I20: E | L20: MAC_UNIT_CALC_TYP
A21: 10 | D21: sno3_typ | E21: #MA.UNIT_CALC_TYP | G21: SEIBAN No. 3 calculation type | H21: 手配ＮＯ３計算区分 | I21: E | L21: MAC_UNIT_CALC_TYP
A22: 10 | D22: sno4_typ | E22: #MA.UNIT_CALC_TYP | G22: SEIBAN No. 4 calculation type | H22: 手配ＮＯ４計算区分 | I22: E | L22: MAC_UNIT_CALC_TYP
A23: 10 | D23: lot_exp_typ | E23: #MA.EXP_SET_TYP | G23: Lot No. explosion type | H23: ロットＮＯ展開区分 | I23: E | L23: MAC_EXP_SET_TYP
A24: 10 | D24: sublot_exp_typ | E24: #MA.EXP_SET_TYP | G24: Sublot No. explosion type | H24: サブロットＮＯ展開区分 | I24: E | L24: MAC_EXP_SET_TYP
A25: 10 | D25: sno1_exp_typ | E25: #MA.EXP_SET_TYP | G25: SEIBAN No. 1 explosion type | H25: 手配ＮＯ１展開区分 | I25: E | L25: MAC_EXP_SET_TYP
... A29: 10 | D29: std_rnd_typ | E29: #MA.RND_TYP | G29: Rounding type (Standard) | H29: 標準端数処理区分 | I29: E | L29: MAC_RND_TYP
A30: 10 | D30: std_dec_place | E30: #MA.DEC_PLACE | G30: Standard number of decimal places | H30: 標準小数部有効桁数 | I30: E | M30: 0:8
A31: 10 | D31: ave_rnd_typ | E31: #MA.RND_TYP | G31: Rounding type (Unit price) | H31: 単価端数処理区分 | I31: E | L31: MAC_RND_TYP
A32: 10 | D32: ave_dec_place | E32: #MA.DEC_PLACE | G32: Unit price number of decimal places | H32: 単価小数部有効桁数 | I32: E | M32: 0:8
A33: 10 | D33: adj_typ | E33: #MA.ADJ_TYP | G33: Fraction adjustment type | H33: 端数調整区分 | I33: E | L33: MAC_ADJ_TYP
A34: 10 | D34: wip_typ | E34: #MA.WIP_TYP | G34: WIP type | H34: 仕掛区分 | I34: E | L34: MAC_WIP_TYP
A35: 10 | D35: bd_agg_typ | E35: #MA.BD_AGG_TYP | G35: Breakdown aggregated type | H35: 内訳集計区分 | I35: E | L35: MAC_BD_AGG_TYP
A36: 10 | D36: mrgn_expns_cd | E36: #MA.EXPNS_CD | G36: Adjustment cost element cd. | H36: 調整費目ＣＤ | I36: E | N36: MA.MAUAL0010.Expns | O36: MAC_EXPNS_TYP.PROD | P36: expns_typ
A37: 10 | D37: purc_expns_cd | E37: #MA.EXPNS_CD | G37: Purchase cost element item cd. | H37: 購買費目ＣＤ | I37: E | N37: MA.MAUAL0010.Expns | O37: MAC_EXPNS_TYP.PROD | P37: expns_typ
A38: 10 | D38: out_expns_cd | E38: #MA.EXPNS_CD | G38: Subcontract cost element cd. | H38: 外注費目ＣＤ | I38: E | N38: MA.MAUAL0010.Expns | O38: MAC_EXPNS_TYP.PROD | P38: expns_typ
A39: 10 | D39: inpt_expns_cd | E39: #MA.EXPNS_CD | G39: Input cost element cd. | H39: 投入費目ＣＤ | I39: E | N39: MA.MAUAL0010.Expns | O39: MAC_EXPNS_TYP.PROD | P39: expns_typ
A40: 10 | D40: ss_expns_cd | E40: #MA.EXPNS_CD | G40: Self supply cost element cd. | H40: 自給費目ＣＤ | I40: E | N40: MA.MAUAL0010.Expns | O40: MAC_EXPNS_TYP.PROD | P40: expns_typ
A41: 10 | D41: prov_expns_cd | E41: #MA.EXPNS_CD | G41: Cost element cd. for gain or loss of chargeable item | H41: 有償差額費目ＣＤ | I41: E | N41: MA.MAUAL0010.Expns | O41: MAC_EXPNS_TYP.SPPL | P41: expns_typ
A42: 10 | D42: exp_alloc_typ | E42: #MA.EXP_ALLOC_TYP | G42: Explosion allocation type | H42: 展開割付区分 | I42: E | L42: MAC_EXP_ALLOC_TYP
A43: 10 | D43: memo1 | E43: #MA.MST_MEMO1 | G43: Memo 1 | H43: メモ１ | I43: E
...

Sheet GrpPtn_Upd01
A1: * | B1: * | D1: L | E1: 1
A2: * | D2: オペレーション実装仕様書 Operation Specification Implementation Sheet | E2: ModuleID : | F2: =IF(LogicCommon!C2="","",LogicCommon!C2) -> MA | G2: LogicID : | H2: =IF(LogicCommon!E2="","",LogicCommon!E2) -> MABGL0110 | I2: Ope.ID : | J2: GrpPtn_Upd01 | K2: Pj.ID : | L2: =IF(LogicCommon!G2="","",LogicCommon!G2) -> MC | M2: Ope.Body : | N2: "mcframe.serverMAUD.MAUDL6010.MAUDL_RLUpdater"
A3: * | D3: =IF(LogicCommon!A3="","",LogicCommon!A3) | E3: SubModuleID : | F3: =IF(LogicCommon!C3="","",LogicCommon!C3) -> MABG | G3: LogicClass : | H3: =IF(LogicCommon!E3="","",LogicCommon!E3) -> MABGL_GrpPtn | I3: Ope.Method : | J3: @ | K3: SuperClassPj.ID : | L3: =IF(LogicCommon!G3="","",LogicCommon!G3) | M3: ReportID : | O3: Gene.Type : | P3: ALL
A4: * | E4: Version : | F4: 000000 | G4: LogicName : | H4: =IF(LogicCommon!E4="","",LogicCommon!E4) -> 計算グループパタンマスタ | I4: Ope.Name : | J4: 登録処理 | K4: SuperLogicID : | L4: =IF(LogicCommon!G4="","",LogicCommon!G4) -> MA.MAUDL5010
A5: * | E5: ACType :
A6: * | D6: 概要 : | E6: 計算グループパタンマスタを登録する | L6: ID | N6: ID | P6: ID | R6: ID
A7: # | I7: U | K7: o | L7: UPDATE.updMaster | M7: o | N7: MAIN.chkMaster | O7: o | Q7: o
A8: # | D8: ブロック名 Block Name | E8: 型 Type | G8: super/share | H8: 対象ブロック名 Target Block Name | K8: TargetName | L8: DBC.MA.MAM_GRP_PTN | M8: TargetName | N8: DBC.MA.MAM_GRP_PTN | O8: TargetName | Q8: TargetName | U8: ブロック備考 Block Remarks
A9: # | D9: 項目名 Field Name | E9: 型 Type | F9: 桁 Digits | G9: フルネーム Full Name | H9: 日本語名 Japanese Name | I9: 上り項目 Request Message Field | J9: 下り項目 Response Message Field | S9: 条件および編集方法 Conditions and Editing Methods | U9: 項目備考 Field Remarks
A10: # | K10: 上り項目 Request Message Field | L10: 下り項目 Response Message Field | M10: 上り項目 Request Message Field | N10: 下り項目 Response Message Field | O10: 上り項目 Request Message Field | P10: 下り項目 Response Message Field | Q10: 上り項目 Request Message Field | R10: 下り項目 Response Message Field
A11: 10 | B11: * | D11: GrpPtn_Upd01_Dtl | E11: L | G11: $share$ | H11: MA.MABGL0110.GrpPtn_UpdChk01.GrpPtn_UpdChk01_Dtl | K11: L | M11: L
A12: 10 | D12: calc_ptn_cd | E12: #MA.CALC_PTN_CD | G12: Calculation pattern cd. | H12: 計算パタンＣＤ | I12: E | K12: E | M12: E
A13: 10 | D13: calc_grp_cd | E13: #MA.CALC_GRP_CD | G13: Calculation group cd. | H13: 計算グループＣＤ | I13: E | K13: E | M13: E
A14: 10 | D14: mfg_purc_typ | E14: #MA.MFG_PURC_TYP | G14: Mfg. purchase type | H14: 製造購買区分 | I14: E | K14: E
A15: 10 | D15: eval_typ | E15: #MA.EVAL_TYP | G15: Amount evaluation type | H15: 金額評価区分 | I15: E | K15: E
A16: 10 | D16: dpt_typ | E16: #MA.UNIT_CALC_TYP | G16: Dept. calculation type | H16: 部門計算区分 | I16: E | K16: E
A17: 10 | D17: lot_typ | E17: #MA.UNIT_CALC_TYP | G17: Lot No. calculation type | H17: ロットＮＯ計算区分 | I17: E | K17: E
A18: 10 | D18: sublot_typ | E18: #MA.UNIT_CALC_TYP | G18: Sublot No. calculation type | H18: サブロットＮＯ計算区分 | I18: E | K18: E
A19: 10 | D19: sno1_typ | E19: #MA.UNIT_CALC_TYP | G19: SEIBAN No. 1 calculation type | H19: 手配ＮＯ１計算区分 | I19: E | K19: E
A20: 10 | D20: sno2_typ | E20: #MA.UNIT_CALC_TYP | G20: SEIBAN No. 2 calculation type | H20: 手配ＮＯ２計算区分 | I20: E | K20: E
A21: 10 | D21: sno3_typ | E21: #MA.UNIT_CALC_TYP | G21: SEIBAN No. 3 calculation type | H21: 手配ＮＯ３計算区分 | I21: E | K21: E
A22: 10 | D22: sno4_typ | E22: #MA.UNIT_CALC_TYP | G22: SEIBAN No. 4 calculation type | H22: 手配ＮＯ４計算区分 | I22: E | K22: E
A23: 10 | D23: lot_exp_typ | E23: #MA.UNIT_CALC_TYP | G23: Lot No. explosion type | H23: ロットＮＯ展開区分 | I23: E | K23: E
A24: 10 | D24: sublot_exp_typ | E24: #MA.EXP_SET_TYP | G24: Sublot No. explosion type | H24: サブロットＮＯ展開区分 | I24: E | K24: E
A25: 10 | D25: sno1_exp_typ | E25: #MA.EXP_SET_TYP | G25: SEIBAN No. 1 explosion type | H25: 手配ＮＯ１展開区分 | I25: E | K25: E
... A47: 10 | D47: upd_cntr | E47: #MA.UPD_CNT | G47: Update counter | H47: 更新カウンタ | I47: E | K47: E
D48: 詳細 :

Sheet GrpPtn_DelChk01
A1: * | B1: * | D1: L | E1: 1
A2: * | D2: オペレーション実装仕様書 Operation Specification Implementation Sheet | E2: ModuleID : | F2: =IF(LogicCommon!C2="","",LogicCommon!C2) -> MA | G2: LogicID : | H2: =IF(LogicCommon!E2="","",LogicCommon!E2) -> MABGL0110 | I2: Ope.ID : | J2: GrpPtn_DelChk01 | K2: Pj.ID : | L2: =IF(LogicCommon!G2="","",LogicCommon!G2) -> MC | M2: Ope.Body : | N2: =L4 & ".Checker" -> MA.MAUDL5010.Checker
A3: * | D3: =IF(LogicCommon!A3="","",LogicCommon!A3) | E3: SubModuleID : | F3: =IF(LogicCommon!C3="","",LogicCommon!C3) -> MABG | G3: LogicClass : | H3: =IF(LogicCommon!E3="","",LogicCommon!E3) -> MABGL_GrpPtn | I3: Ope.Method : | J3: @ | K3: SuperClassPj.ID : | L3: =IF(LogicCommon!G3="","",LogicCommon!G3) | M3: ReportID : | O3: Gene.Type : | P3: ALL
A4: * | E4: Version : | F4: 000000 | G4: LogicName : | H4: =IF(LogicCommon!E4="","",LogicCommon!E4) -> 計算グループパタンマスタ | I4: Ope.Name : | J4: 削除前チェック | K4: SuperLogicID : | L4: =IF(LogicCommon!G4="","",LogicCommon!G4) -> MA.MAUDL5010
A5: * | E5: ACType :
A6: * | D6: 概要 : | E6: 計算グループパタンマスタを削除する前のチェックを行う | Q6: ID
A7: # | I7: U | K7: K | P7: o
A8: # | D8: ブロック名 Block Name | E8: 型 Type | G8: super/share | H8: 対象ブロック名 Target Block Name | K8: REQUIRED | P8: TargetName | T8: ブロック備考 Block Remarks
A9: # | D9: 項目名 Field Name | E9: 型 Type | F9: 桁 Digits | G9: フルネーム Full Name | H9: 日本語名 Japanese Name | I9: 上り項目 Request Message Field | J9: 下り項目 Response Message Field | R9: 条件および編集方法 Conditions and Editing Methods | T9: 項目備考 Field Remarks
A10: # | P10: 上り項目 Request Message Field | Q10: 下り項目 Response Message Field
A11: 10 | B11: * | D11: GrpPtn_DelChk01_Dtl | E11: L
A12: 10 | D12: calc_ptn_cd | E12: #MA.CALC_PTN_CD | G12: Calculation pattern cd. | H12: 計算パタンＣＤ | I12: E | K12: E
A13: 10 | D13: calc_grp_cd | E13: #MA.CALC_GRP_CD | G13: Calculation group cd. | H13: 計算グループＣＤ | I13: E | K13: E
A14: 10 | D14: upd_cntr | E14: #MA.UPD_CNT | G14: Update counter | H14: 更新カウンタ | I14: E | K14: E
D15: 詳細 :

Sheet GrpPtn_Del01
A1: * | B1: * | D1: L | E1: 1
A2: * | D2: オペレーション実装仕様書 Operation Specification Implementation Sheet | E2: ModuleID : | F2: =IF(LogicCommon!C2="","",LogicCommon!C2) -> MA | G2: LogicID : | H2: =IF(LogicCommon!E2="","",LogicCommon!E2) -> MABGL0110 | I2: Ope.ID : | J2: GrpPtn_Del01 | K2: Pj.ID : | L2: =IF(LogicCommon!G2="","",LogicCommon!G2) -> MC | M2: Ope.Body : | N2: "mcframe.serverMAUD.MAUDL6010.MAUDL_RLDeleter"
A3: * | D3: =IF(LogicCommon!A3="","",LogicCommon!A3) | E3: SubModuleID : | F3: =IF(LogicCommon!C3="","",LogicCommon!C3) -> MABG | G3: LogicClass : | H3: =IF(LogicCommon!E3="","",LogicCommon!E3) -> MABGL_GrpPtn | I3: Ope.Method : | J3: @ | K3: SuperClassPj.ID : | L3: =IF(LogicCommon!G3="","",LogicCommon!G3) | M3: ReportID : | O3: Gene.Type : | P3: ALL
A4: * | E4: Version : | F4: 000000 | G4: LogicName : | H4: =IF(LogicCommon!E4="","",LogicCommon!E4) -> 計算グループパタンマスタ | I4: Ope.Name : | J4: 削除処理 | K4: SuperLogicID : | L4: =IF(LogicCommon!G4="","",LogicCommon!G4) -> MA.MAUDL5010
A5: * | E5: ACType :
A6: * | D6: 概要 : | E6: 計算グループパタンマスタを削除する | L6: ID | N6: ID
A7: # | I7: U | K7: o | L7: UPDATE.updMaster1 | M7: o
A8: # | D8: ブロック名 Block Name | E8: 型 Type | G8: super/share | H8: 対象ブロック名 Target Block Name | K8: TargetName | L8: DBC.MA.MAM_GRP_PTN | M8: TargetName | Q8: ブロック備考 Block Remarks
A9: # | D9: 項目名 Field Name | E9: 型 Type | F9: 桁 Digits | G9: フルネーム Full Name | H9: 日本語名 Japanese Name | I9: 上り項目 Request Message Field | J9: 下り項目 Response Message Field | O9: 条件および編集方法 Conditions and Editing Methods | Q9: 項目備考 Field Remarks
A10: # | K10: 上り項目 Request Message Field | L10: 下り項目 Response Message Field | M10: 上り項目 Request Message Field | N10: 下り項目 Response Message Field
A11: 10 | B11: * | D11: GrpPtn_Del01_Dtl | E11: L | G11: $share$ | H11: MA.MABGL0110.GrpPtn_DelChk01.GrpPtn_DelChk01_Dtl | K11: L
A12: 10 | D12: calc_ptn_cd | E12: #MA.CALC_PTN_CD | G12: Calculation pattern cd. | H12: 計算パタンＣＤ | I12: E | K12: E
A13: 10 | D13: calc_grp_cd | E13: #MA.CALC_GRP_CD | G13: Calculation group cd. | H13: 計算グループＣＤ | I13: E | K13: E
A14: 10 | D14: upd_cntr | E14: #MA.UPD_CNT | G14: Update counter | H14: 更新カウンタ | I14: E | K14: E
D15: 詳細 :

Sheet Srch01
A1: * | B1: * | D1: L | E1: 1
A2: * | D2: オペレーション実装仕様書 Operation Specification Implementation Sheet | E2: ModuleID : | F2: =IF(LogicCommon!C2="","",LogicCommon!C2) -> MA | G2: LogicID : | H2: =IF(LogicCommon!E2="","",LogicCommon!E2) -> MABGL0110 | I2: Ope.ID : | J2: Srch01 | K2: Pj.ID : | L2: =IF(LogicCommon!G2="","",LogicCommon!G2) -> MC | M2: Ope.Body : | N2: "mcframe.serverMAUD.MAUDL6010.MAUDL_RLSearcher"
A3: * | D3: =IF(LogicCommon!A3="","",LogicCommon!A3) | E3: SubModuleID : | F3: =IF(LogicCommon!C3="","",LogicCommon!C3) -> MABG | G3: LogicClass : | H3: =IF(LogicCommon!E3="","",LogicCommon!E3) -> MABGL_GrpPtn | I3: Ope.Method : | J3: @ | K3: SuperClassPj.ID : | L3: =IF(LogicCommon!G3="","",LogicCommon!G3) | M3: ReportID : | O3: Gene.Type : | P3: ALL
A4: * | E4: Version : | F4: 000000 | G4: LogicName : | H4: =IF(LogicCommon!E4="","",LogicCommon!E4) -> 計算グループパタンマスタ | I4: Ope.Name : | J4: 検索 | K4: SuperLogicID : | L4: =IF(LogicCommon!G4="","",LogicCommon!G4) -> MA.MAUDL5010
A5: * | E5: ACType :
A6: * | D6: 概要 : | E6: 検索処理を行う | M6: ID | O6: ID
A7: # | I7: U | K7: K | L7: o | M7: SELECT.c0 | N7: o
A8: # | D8: ブロック名 Block Name | E8: 型 Type | G8: super/share | H8: 対象ブロック名 Target Block Name | K8: CONST | L8: TargetName | M8: DBC.MA.MAM_GRP_PTN | N8: TargetName | R8: ブロック備考 Block Remarks
A9: # | D9: 項目名 Field Name | E9: 型 Type | F9: 桁 Digits | G9: フルネーム Full Name | H9: 日本語名 Japanese Name | I9: 上り項目 Request Message Field | J9: 下り項目 Response Message Field | P9: 条件および編集方法 Conditions and Editing Methods | R9: 項目備考 Field Remarks
A10: # | L10: 上り項目 Request Message Field | M10: 下り項目 Response Message Field | N10: 上り項目 Request Message Field | O10: 下り項目 Response Message Field
A11: 10 | B11: * | D11: Srch01_Cnd | E11: R | L11: R
A12: 10 | D12: calc_ptn_cd | E12: #MA.CALC_PTN_CD | G12: Calculation pattern cd. | H12: 計算パタンＣＤ | I12: E
A13: 10 | D13: calc_ptn_nm | E13: #MA.CALC_PTN_NM | G13: Calculation pattern name | H13: 計算パタン名 | I13: E
A14: 10 | D14: calc_grp_cd | E14: #MA.CALC_GRP_CD | G14: Calculation group cd. | H14: 計算グループＣＤ | I14: E
A15: 10 | D15: calc_grp_nm | E15: #MA.CALC_GRP_NM | G15: Calculation group name | H15: 計算グループ名 | I15: E
A16: 10 | D16: off_del_flg | E16: #MA.FLG | G16: Logical delete flg. (Off) | H16: 論理削除ＦＬＧ（オフ） | I16: E
A17: 10 | D17: on_del_flg | E17: #MA.FLG | G17: Logical delete flg. (On) | H17: 論理削除ＦＬＧ（オン） | I17: E
A18: 10 | D18: memo1 | E18: #MA.MST_MEMO1 | G18: Memo 1 | H18: メモ１ | I18: E
A19: 10 | D19: memo2 | E19: #MA.MST_MEMO2 | G19: Memo 2 | H19: メモ２ | I19: E
A20: 10 | D20: memo3 | E20: #MA.MST_MEMO3 | G20: Memo 3 | H20: メモ３ | I20: E
A22: 20 | B22: * | D22: Srch01_Rslt1 | E22: L | M22: L
A23: 20 | D23: del_flg | E23: #MA.FLG | G23: Logical delete | H23: 論理削除 | J23: E | M23: E
A24: 20 | D24: calc_ptn_cd | E24: #MA.CALC_PTN_CD | G24: Calculation pattern cd. | H24: 計算パタンＣＤ | J24: E | M24: E
A25: 20 | D25: calc_ptn_nm | E25: #MA.CALC_PTN_NM | G25: Calculation pattern name | H25: 計算パタン名 | J25: E | M25: E
A26: 20 | D26: calc_grp_cd | E26: #MA.CALC_GRP_CD | G26: Calculation group cd. | H26: 計算グループＣＤ | J26: E | M26: E
A27: 20 | D27: calc_grp_nm | E27: #MA.CALC_GRP_NM | G27: Calculation group name | H27: 計算グループ名 | J27: E | M27: E
A28: 20 | D28: mfg_purc_typ | E28: #MA.MFG_PURC_TYP | G28: Mfg. purchase type | H28: 製造購買区分 | J28: E | K28: MAC_MFG_PURC_TYP | M28: E
A29: 20 | D29: mfg_purc_typ_nm | E29: #MA.MFG_PURC_TYP_NM | G29: Mfg. purchase type name | H29: 製造購買区分名 | J29: E
A30: 20 | D30: eval_typ | E30: #MA.EVAL_TYP | G30: Amount evaluation type | H30: 金額評価区分 | J30: E | K30: MAC_EVAL_TYP | M30: E
A31: 20 | D31: eval_typ_nm | E31: #MA.EVAL_TYP_NM | G31: Amount evaluation type name | H31: 金額評価区分名 | J31: E
A32: 20 | D32: dpt_typ | E32: #MA.UNIT_CALC_TYP | G32: Dept. calculation type | H32: 部門計算区分 | J32: E | K32: MAC_UNIT_CALC_TYP | M32: E
A33: 20 | D33: dpt_typ_nm | E33: #MA.UNIT_CALC_TYP_NM | G33: Dept. calculation type name | H33: 部門計算区分名 | J33: E
A34: 20 | D34: lot_typ | E34: #MA.UNIT_CALC_TYP | G34: Lot No. calculation type | H34: ロットＮＯ計算区分 | J34: E | K34: MAC_UNIT_CALC_TYP | M34: E
A35: 20 | D35: lot_typ_nm | E35: #MA.UNIT_CALC_TYP_NM | G35: Lot No. calculation type name | H35: ロットＮＯ計算区分名 | J35: E
A36: 20 | D36: sublot_typ | E36: #MA.UNIT_CALC_TYP | G36: Sublot No. calculation type | H36: サブロットＮＯ計算区分 | J36: E | K36: MAC_UNIT_CALC_TYP | M36: E
A37: 20 | D37: sublot_typ_nm | E37: #MA.UNIT_CALC_TYP_NM | G37: Sublot No. calculation type name | H37: サブロットＮＯ計算区分名 | J37: E
A38: 20 | D38: sno1_typ | E38: #MA.UNIT_CALC_TYP | G38: SEIBAN No. 1 calculation type | H38: 手配ＮＯ１計算区分 | J38: E | K38: MAC_UNIT_CALC_TYP | M38: E
A39: 20 | D39: sno1_typ_nm | E39: #MA.UNIT_CALC_TYP_NM | G39: SEIBAN No. 1 calculation type name | H39: 手配ＮＯ１計算区分名 | J39: E
A40: 20 | D40: sno2_typ | E40: #MA.UNIT_CALC_TYP | G40: SEIBAN No. 2 calculation type | H40: 手配ＮＯ２計算区分 | J40: E | K40: MAC_UNIT_CALC_TYP | M40: E
A41: 20 | D41: sno2_typ_nm | E41: #MA.UNIT_CALC_TYP_NM | G41: SEIBAN No. 2 calculation type name | H41: 手配ＮＯ２計算区分名 | J41: E
...

Sheet Upd01
A1: * | B1: * | D1: L | E1: 1
A2: * | D2: オペレーション実装仕様書 Operation Specification Implementation Sheet | E2: ModuleID : | F2: =IF(LogicCommon!C2="","",LogicCommon!C2) -> MA | G2: LogicID : | H2: =IF(LogicCommon!E2="","",LogicCommon!E2) -> MABGL0110 | I2: Ope.ID : | J2: Upd01 | K2: Pj.ID : | L2: =IF(LogicCommon!G2="","",LogicCommon!G2) -> MC | M2: Ope.Body : | N2: "mcframe.serverMAUD.MAUDL6010.MAUDL_RLUpdater"
A3: * | D3: =IF(LogicCommon!A3="","",LogicCommon!A3) | E3: SubModuleID : | F3: =IF(LogicCommon!C3="","",LogicCommon!C3) -> MABG | G3: LogicClass : | H3: =IF(LogicCommon!E3="","",LogicCommon!E3) -> MABGL_GrpPtn | I3: Ope.Method : | J3: @ | K3: SuperClassPj.ID : | L3: =IF(LogicCommon!G3="","",LogicCommon!G3) | M3: ReportID : | O3: Gene.Type : | P3: ALL
A4: * | E4: Version : | F4: 000000 | G4: LogicName : | H4: =IF(LogicCommon!E4="","",LogicCommon!E4) -> 計算グループパタンマスタ | I4: Ope.Name : | J4: 登録 | K4: SuperLogicID : | L4: =IF(LogicCommon!G4="","",LogicCommon!G4) -> MA.MAUDL5010
A5: * | E5: ACType :
A6: * | D6: 概要 : | E6: 登録処理を行う | L6: ID | N6: ID | P6: ID | R6: ID
A7: # | I7: U | K7: o | L7: CALL_OPE01.chk01 | M7: o | N7: CALL_OPE01.upd01 | O7: o | Q7: o
A8: # | D8: ブロック名 Block Name | E8: 型 Type | G8: super/share | H8: 対象ブロック名 Target Block Name | K8: TargetName | L8: OPE.MA.MABGL0110.GrpPtn_UpdChk01 | M8: TargetName | N8: OPE.MA.MABGL0110.GrpPtn_Upd01 | O8: TargetName | Q8: TargetName | U8: ブロック備考 Block Remarks
A9: # | D9: 項目名 Field Name | E9: 型 Type | F9: 桁 Digits | G9: フルネーム Full Name | H9: 日本語名 Japanese Name | I9: 上り項目 Request Message Field | J9: 下り項目 Response Message Field | S9: 条件および編集方法 Conditions and Editing Methods | U9: 項目備考 Field Remarks
A10: # | K10: 上り項目 Request Message Field | L10: 下り項目 Response Message Field | M10: 上り項目 Request Message Field | N10: 下り項目 Response Message Field | O10: 上り項目 Request Message Field | P10: 下り項目 Response Message Field | Q10: 上り項目 Request Message Field | R10: 下り項目 Response Message Field
A11: 10 | B11: * | D11: Upd01_Dtl1 | E11: L | G11: $share$ | H11: MA.MABGL0110.GrpPtn_Upd01.GrpPtn_Upd01_Dtl | K11: GrpPtn_UpdChk01_Dtl | M11: GrpPtn_Upd01_Dtl
A12: 10 | D12: calc_ptn_cd | E12: #MA.CALC_PTN_CD | G12: Calculation pattern cd. | H12: 計算パタンＣＤ | I12: E | K12: E | M12: E
A13: 10 | D13: calc_grp_cd | E13: #MA.CALC_GRP_CD | G13: Calculation group cd. | H13: 計算グループＣＤ | I13: E | K13: E | M13: E
A14: 10 | D14: mfg_purc_typ | E14: #MA.MFG_PURC_TYP | G14: Mfg. purchase type | H14: 製造購買区分 | I14: E | K14: E | M14: E
A15: 10 | D15: eval_typ | E15: #MA.EVAL_TYP | G15: Amount evaluation type | H15: 金額評価区分 | I15: E | K15: E | M15: E
A16: 10 | D16: dpt_typ | E16: #MA.UNIT_CALC_TYP | G16: Dept. calculation type | H16: 部門計算区分 | I16: E | K16: E | M16: E
A17: 10 | D17: lot_typ | E17: #MA.UNIT_CALC_TYP | G17: Lot No. calculation type | H17: ロットＮＯ計算区分 | I17: E | K17: E | M17: E
A18: 10 | D18: sublot_typ | E18: #MA.UNIT_CALC_TYP | G18: Sublot No. calculation type | H18: サブロットＮＯ計算区分 | I18: E | K18: E | M18: E
A19: 10 | D19: sno1_typ | E19: #MA.UNIT_CALC_TYP | G19: SEIBAN No. 1 calculation type | H19: 手配ＮＯ１計算区分 | I19: E | K19: E | M19: E
A20: 10 | D20: sno2_typ | E20: #MA.UNIT_CALC_TYP | G20: SEIBAN No. 2 calculation type | H20: 手配ＮＯ２計算区分 | I20: E | K20: E | M20: E
A21: 10 | D21: sno3_typ | E21: #MA.UNIT_CALC_TYP | G21: SEIBAN No. 3 calculation type | H21: 手配ＮＯ３計算区分 | I21: E | K21: E | M21: E
A22: 10 | D22: sno4_typ | E22: #MA.UNIT_CALC_TYP | G22: SEIBAN No. 4 calculation type | H22: 手配ＮＯ４計算区分 | I22: E | K22: E | M22: E
A23: 10 | D23: lot_exp_typ | E23: #MA.EXP_SET_TYP | G23: Lot No. explosion type | H23: ロットＮＯ展開区分 | I23: E | K23: E | M23: E
... A47: 10 | D47: upd_cntr | E47: #MA.UPD_CNT | G47: Update counter | H47: 更新カウンタ | I47: E | K47: E | M47: E
D48: 詳細 :

Sheet Del01
A1: * | B1: * | D1: L | E1: 1
A2: * | D2: オペレーション実装仕様書 Operation Specification Implementation Sheet | E2: ModuleID : | F2: =IF(LogicCommon!C2="","",LogicCommon!C2) -> MA | G2: LogicID : | H2: =IF(LogicCommon!E2="","",LogicCommon!E2) -> MABGL0110 | I2: Ope.ID : | J2: Del01 | K2: Pj.ID : | L2: =IF(LogicCommon!G2="","",LogicCommon!G2) -> MC | M2: Ope.Body : | N2: "mcframe.serverMAUD.MAUDL6010.MAUDL_RLDeleter"
A3: * | D3: =IF(LogicCommon!A3="","",LogicCommon!A3) | E3: SubModuleID : | F3: =IF(LogicCommon!C3="","",LogicCommon!C3) -> MABG | G3: LogicClass : | H3: =IF(LogicCommon!E3="","",LogicCommon!E3) -> MABGL_GrpPtn | I3: Ope.Method : | J3: @ | K3: SuperClassPj.ID : | L3: =IF(LogicCommon!G3="","",LogicCommon!G3) | M3: ReportID : | O3: Gene.Type : | P3: ALL
A4: * | E4: Version : | F4: 000000 | G4: LogicName : | H4: =IF(LogicCommon!E4="","",LogicCommon!E4) -> 計算グループパタンマスタ | I4: Ope.Name : | J4: 削除 | K4: SuperLogicID : | L4: =IF(LogicCommon!G4="","",LogicCommon!G4) -> MA.MAUDL5010
A5: * | E5: ACType :
A6: * | D6: 概要 : | E6: 削除処理を行う | L6: ID | N6: ID
A7: # | I7: U | K7: o | L7: CALL_OPE01.chk01 | M7: o | N7: CALL_OPE01.del01
A8: # | D8: ブロック名 Block Name | E8: 型 Type | G8: super/share | H8: 対象ブロック名 Target Block Name | K8: TargetName | L8: OPE.MA.MABGL0110.GrpPtn_DelChk01 | M8: TargetName | N8: OPE.MA.MABGL0110.GrpPtn_Del01 | Q8: ブロック備考 Block Remarks
A9: # | D9: 項目名 Field Name | E9: 型 Type | F9: 桁 Digits | G9: フルネーム Full Name | H9: 日本語名 Japanese Name | I9: 上り項目 Request Message Field | J9: 下り項目 Response Message Field | O9: 条件および編集方法 Conditions and Editing Methods | Q9: 項目備考 Field Remarks
A10: # | K10: 上り項目 Request Message Field | L10: 下り項目 Response Message Field | M10: 上り項目 Request Message Field | N10: 下り項目 Response Message Field
A11: 10 | B11: * | D11: Del01_Dtl1 | E11: L | G11: $share$ | H11: MA.MABGL0110.GrpPtn_Del01.GrpPtn_Del01_Dtl | K11: GrpPtn_DelChk01_Dtl | M11: GrpPtn_Del01_Dtl
A12: 10 | D12: calc_ptn_cd | E12: #MA.CALC_PTN_CD | G12: Calculation pattern cd. | H12: 計算パタンＣＤ | I12: E | K12: E | M12: E
A13: 10 | D13: calc_grp_cd | E13: #MA.CALC_GRP_CD | G13: Calculation group cd. | H13: 計算グループＣＤ | I13: E | K13: E | M13: E
A14: 10 | D14: upd_cntr | E14: #MA.UPD_CNT | G14: Update counter | H14: 更新カウンタ | I14: E | K14: E | M14: E
D15: 詳細 :

Sheet 来歴
A1: 変更来歴
A3: Rev. | H3: 修正番号 | O3: 変更内容 | AQ3: 変更箇所
A4: 1 | O4: 初版
A5: 1.1 | O5: 英語の名称を追記 | AQ5: 全般
