Workbook

Sheet LogicCommon
A2: オペレーション実装仕様書 | B2: ModuleID : | C2: MS | D2: LogicID : | E2: MSBGL5100 | F2: Pj.ID : | G2: MC
B3: SubModuleID : | C3: MSBG | D3: LogicClass : | E3: MSBGL_ArDtlApplService | F3: SuperClassPj.ID :
D4: LogicName : | E4: 売掛明細消込サービス | F4: SuperLogicID : | G4: MS.MSUDL5010
A5: 概要 : | B5: 売掛明細の消込処理、自動消込処理、不要明細消込処理を行う
A6: 詳細 :

Sheet ArDtlAppl_Chk01
A1: * | B1: * | D1: L | E1: 1
A2: * | D2: オペレーション実装仕様書 Operation Specification Implementation Sheet | E2: ModuleID : | F2: =IF(LogicCommon!C2="","",LogicCommon!C2) -> MS | G2: LogicID : | H2: =IF(LogicCommon!E2="","",LogicCommon!E2) -> MSBGL5100 | I2: Ope.ID : | J2: ArDtlAppl_Chk01 | K2: Pj.ID : | L2: =IF(LogicCommon!G2="","",LogicCommon!G2) -> MC | M2: Ope.Body : | N2: MA.MAUDL5010.Checker
A3: * | D3: =IF(LogicCommon!A3="","",LogicCommon!A3) | E3: SubModuleID : | F3: =IF(LogicCommon!C3="","",LogicCommon!C3) -> MSBG | G3: LogicClass : | H3: =IF(LogicCommon!E3="","",LogicCommon!E3) -> MSBGL_ArDtlApplService | I3: Ope.Method : | J3: @ | K3: SuperClassPj.ID : | L3: =IF(LogicCommon!G3="","",LogicCommon!G3) | O3: Gene.Type : | P3: ALL
A4: * | E4: Version : | F4: 000000 | G4: LogicName : | H4: =IF(LogicCommon!E4="","",LogicCommon!E4) -> 売掛明細消込サービス | I4: Ope.Name : | J4: 消込前チェック | K4: SuperLogicID : | L4: =IF(LogicCommon!G4="","",LogicCommon!G4) -> MS.MSUDL5010 | M4: ImplOpe.ID:
A5: * | E5: ACType :
A6: * | D6: 概要 : | E6: 消込処理用のチェックを行う | M6: ID | O6: ID | Q6: ID
A7: # | I7: U | K7: K | L7: o | N7: o | P7: o
A8: # | D8: ブロック名 Block Name | E8: 型 Type | G8: super/share | H8: 対象ブロック名 Target Block Name | L8: TargetName | N8: TargetName | P8: TargetName | T8: ブロック備考 Block Remarks
A9: # | D9: 項目名 Field Name | E9: 型 Type | F9: 桁 Digits | G9: フルネーム Full Name | H9: 日本語名 Japanese Name | I9: 上り項目 Request Message Field | J9: 下り項目 Response Message Field | R9: 条件および編集方法 Conditions and Editing Methods | T9: 項目備考 Field Remarks
A10: # | L10: 上り項目 Request Message Field | M10: 下り項目 Response Message Field | N10: 上り項目 Request Message Field | O10: 下り項目 Response Message Field | P10: 上り項目 Request Message Field | Q10: 下り項目 Response Message Field
A11: 10 | B11: * | D11: ArDtlAppl_Chk01_Dtl | E11: L
A12: 10 | D12: rcv_act_d_no | E12: #MA.RCV_ACT_D_NO | G12: Payment received result details No. | H12: 入金実績明細ＮＯ | I12: E | J12: E
A13: 10 | D13: rcv_act_d_seq | E13: #MA.SLIP_SEQ | G13: Payment received result details sequence number | H13: 入金実績明細連番 | I13: E | J13: E
A14: 10 | D14: bill_d_no | E14: #MA.BILL_D_NO | G14: Billing details No. | H14: 請求明細ＮＯ | I14: E | J14: E
A15: 10 | D15: parent_bill_d_no | E15: #MA.BILL_D_NO | G15: Parent billing details No. | H15: 親請求明細ＮＯ | I15: E | J15: E
A16: 10 | D16: bill_mng_no | E16: #MA.BILL_MNG_NO | G16: Billing management No. | H16: 請求管理ＮＯ | I16: E | J16: E
A17: 10 | D17: appl_amt | E17: #MA.MONEY | G17: Reconciled amount | H17: 消込額 | I17: E | J17: E
A18: 10 | D18: rcv_act_no | E18: #MA.RCV_ACT_NO | G18: Payment received result No. | H18: 入金実績ＮＯ | I18: E | J18: E
A19: 10 | D19: rcv_act_seq | E19: #MA.SLIP_SEQ | G19: Payment received result sequence number | H19: 入金実績連番 | I19: E | J19: E
A20: 10 | D20: ar_appl_flg | E20: #MA.FLG | G20: AR reconciliation | H20: 売掛消込 | I20: E | J20: E
A21: 10 | D21: un_dtl_appl_flg | E21: #MA.FLG | G21: Unnecessary details payment | H21: 不要明細消込 | I21: E | J21: E
A22: 10 | D22: no_upd_ar_bal_flg | E22: #MA.FLG | I22: - | J22: -
A23: 10 | D23: rcv_act_ac_ym | E23: #MA.YM | G23: Recording month | H23: 計上年月 | I23: - | J23: -
A24: 10 | D24: ac_ym | E24: #MA.YM | G24: Recording month | H24: 計上年月 | I24: - | J24: -
A25: 10 | D25: acst_cd | E25: #MA.BP_CD | G25: AR customer cd. | H25: 売掛先ＣＤ | I25: - | J25: -
A26: 10 | D26: iv_no | E26: #MA.IV_NO | G26: Invoice No. | H26: インボイスＮＯ | I26: - | J26: -
A27: 10 | D27: wrk_no | E27: #MA.WRK_NO | G27: Sales project No. | H27: 案件ＮＯ | I27: - | J27: -
A28: 10 | D28: ar_typ | E28: #MA.AR_TYP | G28: AR type | H28: 債権区分 | I28: - | J28: -
A29: 10 | D29: trd_cur_cd | E29: #MA.CUR_CD | G29: Transaction currency cd. | H29: 取引通貨ＣＤ | I29: - | J29: -
A30: 10 | D30: ac_dt | E30: #MA.DT | G30: Recording date | H30: 計上日 | I30: - | J30: -
A31: 10 | D31: org_appl_amt | E31: #MA.MONEY | G31: Original reconcile amount | H31: 元消込額 | I31: - | J31: -
A32: 10 | D32: not_appl_bal | E32: #MA.MONEY | G32: Reconciled balance | H32: 消込残高 | I32: - | J32: -
A33: 10 | D33: ar_dpt_cd | E33: #MA.DPT_CD | G33: AR dept. cd. | H33: 債権部門ＣＤ | I33: - | J33: -
A34: 10 | D34: xrate | E34: #MA.MONEY | G34: Exchange rate | H34: 為替レート | I34: - | J34: -
... A39: 10 | D39: par_pre_rcv_act_d_no | E39: #MA.RCV_ACT_D_NO | G39: Old parent payment received result details No. | H39: 旧親入金実績明細ＮＯ | I39: - | J39: -

Sheet ArDtlAppl_Upd01
A1: * | B1: * | D1: L | E1: 1
A2: * | D2: オペレーション実装仕様書 Operation Specification Implementation Sheet | E2: ModuleID : | F2: =IF(LogicCommon!C2="","",LogicCommon!C2) -> MS | G2: LogicID : | H2: =IF(LogicCommon!E2="","",LogicCommon!E2) -> MSBGL5100 | I2: Ope.ID : | J2: ArDtlAppl_Upd01 | K2: Pj.ID : | L2: =IF(LogicCommon!G2="","",LogicCommon!G2) -> MC | M2: Ope.Body : | N2: "mcframe.serverMAUD.MAUDL5010.MAUDL_Operation"
A3: * | D3: =IF(LogicCommon!A3="","",LogicCommon!A3) | E3: SubModuleID : | F3: =IF(LogicCommon!C3="","",LogicCommon!C3) -> MSBG | G3: LogicClass : | H3: =IF(LogicCommon!E3="","",LogicCommon!E3) -> MSBGL_ArDtlApplService | I3: Ope.Method : | J3: @ | K3: SuperClassPj.ID : | L3: =IF(LogicCommon!G3="","",LogicCommon!G3) | O3: Gene.Type : | P3: ALL
A4: * | E4: Version : | F4: 000000 | G4: LogicName : | H4: =IF(LogicCommon!E4="","",LogicCommon!E4) -> 売掛明細消込サービス | I4: Ope.Name : | J4: 消込 | K4: SuperLogicID : | L4: =IF(LogicCommon!G4="","",LogicCommon!G4) -> MS.MSUDL5010 | M4: ImplOpe.ID:
A5: * | E5: ACType :
A6: * | D6: 概要 : | E6: 売掛明細消込処理を行う | M6: ID | O6: ID | Q6: ID
A7: # | I7: U | K7: K | L7: o | N7: o | P7: o
A8: # | D8: ブロック名 Block Name | E8: 型 Type | G8: super/share | H8: 対象ブロック名 Target Block Name | L8: TargetName | N8: TargetName | P8: TargetName | T8: ブロック備考 Block Remarks
A9: # | D9: 項目名 Field Name | E9: 型 Type | F9: 桁 Digits | G9: フルネーム Full Name | H9: 日本語名 Japanese Name | I9: 上り項目 Request Message Field | J9: 下り項目 Response Message Field | R9: 条件および編集方法 Conditions and Editing Methods | T9: 項目備考 Field Remarks
A10: # | L10: 上り項目 Request Message Field | M10: 下り項目 Response Message Field | N10: 上り項目 Request Message Field | O10: 下り項目 Response Message Field | P10: 上り項目 Request Message Field | Q10: 下り項目 Response Message Field
A11: 10 | B11: * | D11: ArDtlAppl_Upd01_Dtl | E11: L | G11: $share$ | H11: MS.MSBGL5100.ArDtlAppl_Chk01.ArDtlAppl_Chk01_Dtl
A12: 10 | D12: rcv_act_d_no | E12: #MA.RCV_ACT_D_NO | G12: Payment received result details No. | H12: 入金実績明細ＮＯ | I12: E
A13: 10 | D13: rcv_act_d_seq | E13: #MA.SLIP_SEQ | G13: Payment received result details sequence number | H13: 入金実績明細連番 | I13: E
A14: 10 | D14: bill_d_no | E14: #MA.BILL_D_NO | G14: Billing details No. | H14: 請求明細ＮＯ | I14: E
A15: 10 | D15: parent_bill_d_no | E15: #MA.BILL_D_NO | G15: Parent billing details No. | H15: 親請求明細ＮＯ | I15: E
A16: 10 | D16: bill_mng_no | E16: #MA.BILL_MNG_NO | G16: Billing management No. | H16: 請求管理ＮＯ | I16: E
A17: 10 | D17: appl_amt | E17: #MA.MONEY | G17: Reconciled amount | H17: 消込額 | I17: E
A18: 10 | D18: rcv_act_no | E18: #MA.RCV_ACT_NO | G18: Payment received result No. | H18: 入金実績ＮＯ | I18: E
A19: 10 | D19: rcv_act_seq | E19: #MA.SLIP_SEQ | G19: Payment received result sequence number | H19: 入金実績連番 | I19: E
A20: 10 | D20: ar_appl_flg | E20: #MA.FLG | G20: AR reconciliation | H20: 売掛消込 | I20: E
A21: 10 | D21: un_dtl_appl_flg | E21: #MA.FLG | G21: Unnecessary details payment | H21: 不要明細消込 | I21: E
A22: 10 | D22: no_upd_ar_bal_flg | E22: #MA.FLG | I22: E
A23: 10 | D23: rcv_act_ac_ym | E23: #MA.YM | G23: Recording month | H23: 計上年月 | I23: -
A24: 10 | D24: ac_ym | E24: #MA.YM | G24: Recording month | H24: 計上年月 | I24: -
A25: 10 | D25: acst_cd | E25: #MA.BP_CD | G25: AR customer cd. | H25: 売掛先ＣＤ | I25: -
A26: 10 | D26: iv_no | E26: #MA.IV_NO | G26: Invoice No. | H26: インボイスＮＯ | I26: -
A27: 10 | D27: wrk_no | E27: #MA.WRK_NO | G27: Sales project No. | H27: 案件ＮＯ | I27: -
A28: 10 | D28: ar_typ | E28: #MA.AR_TYP | G28: AR type | H28: 債権区分 | I28: -
A29: 10 | D29: trd_cur_cd | E29: #MA.CUR_CD | G29: Transaction currency cd. | H29: 取引通貨ＣＤ | I29: -
A30: 10 | D30: ac_dt | E30: #MA.DT | G30: Recording date | H30: 計上日 | I30: -
A31: 10 | D31: org_appl_amt | E31: #MA.MONEY | G31: Original reconcile amount | H31: 元消込額 | I31: -
A32: 10 | D32: not_appl_bal | E32: #MA.MONEY | G32: Reconciled balance | H32: 消込残高 | I32: -
A33: 10 | D33: ar_dpt_cd | E33: #MA.DPT_CD | G33: AR dept. cd. | H33: 債権部門ＣＤ | I33: -
A34: 10 | D34: par_slip_sts_typ | E34: #MA.SLIP_STS_TYP | G34: Parent slip status type | H34: 親伝票状況区分 | I34: -
... A36: 10 | D36: par_rcv_act_d_seq | E36: #MA.SLIP_SEQ | G36: Parent payment received result details sequence number | H36: 親入金実績明細連番 | I36: -
A38: 20 | B38: * | D38: ArDtlAppl_Upd01_BillDApplBal | E38: L
A39: 20 | D39: ac_ym | E39: #MA.YM | G39: Recording month | H39: 計上年月 | I39: -
A40: 20 | D40: bill_d_no | E40: #MA.BILL_D_NO | G40: Billing details No. | H40: 請求明細ＮＯ | I40: -
A41: 20 | D41: parent_bill_d_no | E41: #MA.BILL_D_NO | G41: Parent billing details No. | H41: 親請求明細ＮＯ | I41: -
A42: 20 | D42: last_appl_dt | E42: #MA.DT | G42: Last reconciled date | H42: 最終消込日 | I42: -
...

Sheet ArDtlAppl_Upd02
A1: * | B1: * | D1: L | E1: 1
A2: * | D2: オペレーション実装仕様書 Operation Specification Implementation Sheet | E2: ModuleID : | F2: =IF(LogicCommon!C2="","",LogicCommon!C2) -> MS | G2: LogicID : | H2: =IF(LogicCommon!E2="","",LogicCommon!E2) -> MSBGL5100 | I2: Ope.ID : | J2: ArDtlAppl_Upd02 | K2: Pj.ID : | L2: =IF(LogicCommon!G2="","",LogicCommon!G2) -> MC | M2: Ope.Body : | N2: "mcframe.serverMAUD.MAUDL5010.MAUDL_Operation"
A3: * | D3: =IF(LogicCommon!A3="","",LogicCommon!A3) | E3: SubModuleID : | F3: =IF(LogicCommon!C3="","",LogicCommon!C3) -> MSBG | G3: LogicClass : | H3: =IF(LogicCommon!E3="","",LogicCommon!E3) -> MSBGL_ArDtlApplService | I3: Ope.Method : | J3: @ | K3: SuperClassPj.ID : | L3: =IF(LogicCommon!G3="","",LogicCommon!G3) | O3: Gene.Type : | P3: ALL
A4: * | E4: Version : | F4: 000000 | G4: LogicName : | H4: =IF(LogicCommon!E4="","",LogicCommon!E4) -> 売掛明細消込サービス | I4: Ope.Name : | J4: 自動消込 | K4: SuperLogicID : | L4: =IF(LogicCommon!G4="","",LogicCommon!G4) -> MS.MSUDL5010 | M4: ImplOpe.ID:
A5: * | E5: ACType :
A6: * | D6: 概要 : | E6: 売掛明細の自動消込処理を行う | M6: ID | O6: ID | Q6: ID
A7: # | I7: U | K7: K | L7: o | N7: o | P7: o
A8: # | D8: ブロック名 Block Name | E8: 型 Type | G8: super/share | H8: 対象ブロック名 Target Block Name | L8: TargetName | N8: TargetName | P8: TargetName | T8: ブロック備考 Block Remarks
A9: # | D9: 項目名 Field Name | E9: 型 Type | F9: 桁 Digits | G9: フルネーム Full Name | H9: 日本語名 Japanese Name | I9: 上り項目 Request Message Field | J9: 下り項目 Response Message Field | R9: 条件および編集方法 Conditions and Editing Methods | T9: 項目備考 Field Remarks
A10: # | L10: 上り項目 Request Message Field | M10: 下り項目 Response Message Field | N10: 上り項目 Request Message Field | O10: 下り項目 Response Message Field | P10: 上り項目 Request Message Field | Q10: 下り項目 Response Message Field
A11: 10 | B11: * | D11: ArDtlAppl_Upd02_Dtl | E11: L
A12: 10 | D12: rcv_act_d_no | E12: #MA.RCV_ACT_D_NO | G12: Payment received result details No. | H12: 入金実績明細ＮＯ | I12: E
A13: 10 | D13: rcv_act_d_seq | E13: #MA.SLIP_SEQ | G13: Payment received result details sequence number | H13: 入金実績明細連番 | I13: E
A14: 10 | D14: appl_tgt_amt | E14: #MA.MONEY | G14: Reconciled target amount | H14: 消込対象額 | I14: E

Sheet ArDtlAppl_Upd03
A1: * | B1: * | D1: L | E1: 1
A2: * | D2: オペレーション実装仕様書 Operation Specification Implementation Sheet | E2: ModuleID : | F2: =IF(LogicCommon!C2="","",LogicCommon!C2) -> MS | G2: LogicID : | H2: =IF(LogicCommon!E2="","",LogicCommon!E2) -> MSBGL5100 | I2: Ope.ID : | J2: ArDtlAppl_Upd03 | K2: Pj.ID : | L2: =IF(LogicCommon!G2="","",LogicCommon!G2) -> MC | M2: Ope.Body : | N2: "mcframe.serverMAUD.MAUDL5010.MAUDL_Operation"
A3: * | D3: =IF(LogicCommon!A3="","",LogicCommon!A3) | E3: SubModuleID : | F3: =IF(LogicCommon!C3="","",LogicCommon!C3) -> MSBG | G3: LogicClass : | H3: =IF(LogicCommon!E3="","",LogicCommon!E3) -> MSBGL_ArDtlApplService | I3: Ope.Method : | J3: @ | K3: SuperClassPj.ID : | L3: =IF(LogicCommon!G3="","",LogicCommon!G3) | O3: Gene.Type : | P3: ALL
A4: * | E4: Version : | F4: 000000 | G4: LogicName : | H4: =IF(LogicCommon!E4="","",LogicCommon!E4) -> 売掛明細消込サービス | I4: Ope.Name : | J4: 不要明細消込 | K4: SuperLogicID : | L4: =IF(LogicCommon!G4="","",LogicCommon!G4) -> MS.MSUDL5010 | M4: ImplOpe.ID:
A5: * | E5: ACType :
A6: * | D6: 概要 : | E6: 売掛明細の自動消込処理を行う | M6: ID | O6: ID | Q6: ID
A7: # | I7: U | K7: K | L7: o | N7: o | P7: o
A8: # | D8: ブロック名 Block Name | E8: 型 Type | G8: super/share | H8: 対象ブロック名 Target Block Name | L8: TargetName | N8: TargetName | P8: TargetName | T8: ブロック備考 Block Remarks
A9: # | D9: 項目名 Field Name | E9: 型 Type | F9: 桁 Digits | G9: フルネーム Full Name | H9: 日本語名 Japanese Name | I9: 上り項目 Request Message Field | J9: 下り項目 Response Message Field | R9: 条件および編集方法 Conditions and Editing Methods | T9: 項目備考 Field Remarks
A10: # | L10: 上り項目 Request Message Field | M10: 下り項目 Response Message Field | N10: 上り項目 Request Message Field | O10: 下り項目 Response Message Field | P10: 上り項目 Request Message Field | Q10: 下り項目 Response Message Field

Sheet 来歴
A1: 変更来歴
A3: Rev. | H3: 修正番号 | O3: 変更内容 | AQ3: 変更箇所
A4: 1 | O4: 初版
A5: 1.1 | O5: 英語の名称を追記 | AQ5: 全般
