Workbook

Sheet LogicCommon
A2: ロジック共通定義 | B2: ModuleID : | C2: MS | D2: LogicID : | E2: MSBGL0080 | F2: Pj.ID : | G2: MC
B3: SubModuleID : | C3: MSBG | D3: LogicClass : | E3: MSBGL_RcvSchdAdjstReg | F3: SuperClassPj.ID :
D4: LogicName : | E4: 入金予定調整登録 | F4: SuperLogicID : | G4: MS.MSUDL5010
A5: 概要 :
A6: 詳細 :

Sheet Srch01
A1: * | B1: * | D1: L | E1: 1
A2: * | D2: オペレーション実装仕様書 Operation Specification Implementation Sheet | E2: ModuleID : | F2: =IF(LogicCommon!C2="","",LogicCommon!C2) -> MS | G2: LogicID : | H2: =IF(LogicCommon!E2="","",LogicCommon!E2) -> MSBGL0080 | I2: Ope.ID : | J2: Srch01 | K2: Pj.ID : | L2: =IF(LogicCommon!G2="","",LogicCommon!G2) -> MC | M2: Ope.Body : | N2: "mcframe.serverMAUD.MAUDL5010.MAUDL_Searcher"
A3: * | E3: SubModuleID : | F3: =IF(LogicCommon!C3="","",LogicCommon!C3) -> MSBG | G3: LogicClass : | H3: =IF(LogicCommon!E3="","",LogicCommon!E3) -> MSBGL_RcvSchdAdjstReg | I3: Ope.Method : | J3: Srch01 | K3: SuperClassPj.ID : | L3: =IF(LogicCommon!G3="","",LogicCommon!G3) | O3: Gene.Type : | P3: ALL
A4: * | E4: Version : | F4: 000000 | G4: LogicName : | H4: =IF(LogicCommon!E4="","",LogicCommon!E4) -> 入金予定調整登録 | I4: Ope.Name : | J4: 検索 | K4: SuperLogicID : | L4: =IF(LogicCommon!G4="","",LogicCommon!G4) -> MS.MSUDL5010 | M4: ImplOpe.ID:
A5: * | E5: ACType :
A6: * | D6: 概要 : | E6: 請求ヘッダ、入金予定、入金予定消込実績を検索する。 | M6: ID | O6: ID
A7: # | I7: U | K7: K | L7: o | N7: o
A8: # | D8: ブロック名 Block Name | E8: 型 Type | G8: super/share | H8: 対象ブロック名 Target Block Name | K8: CONST | L8: TargetName | N8: TargetName | R8: ブロック備考 Block Remarks
A9: # | D9: 項目名 Field Name | E9: 型 Type | F9: 桁 Digits | G9: フルネーム Full Name | H9: 日本語名 Japanese Name | I9: 上り項目 Request Message Field | J9: 下り項目 Response Message Field | P9: 条件および編集方法 Conditions and Editing Methods | R9: 項目備考 Field Remarks
A10: # | L10: 上り項目 Request Message Field | M10: 下り項目 Response Message Field | N10: 上り項目 Request Message Field | O10: 下り項目 Response Message Field
A11: 10 | B11: * | D11: Srch01_Cnd | E11: R
A12: 10 | D12: bill_no | E12: #MA.BILL_NO | G12: Invoice No. | H12: 請求書ＮＯ | I12: E | J12: -
L13: 上り項目 Request Message Field | M13: 下り項目 Response Message Field | N13: 上り項目 Request Message Field | O13: 下り項目 Response Message Field
A14: 20 | B14: * | D14: Srch01_Hdr | E14: R
A15: 20 | D15: bill_ym | E15: #MA.YM | G15: Billing month | H15: 請求年月 | I15: - | J15: E
A16: 20 | D16: bill_cl_day | E16: #MA.CL_DAY | G16: Closing date | H16: 締日 | I16: - | J16: E
A17: 20 | D17: iv_no | E17: #MA.IV_NO | G17: Invoice No. | H17: インボイスＮＯ | I17: - | J17: E
A18: 20 | D18: prnt_flg | E18: #MA.FLG | G18: Issued | H18: 発行済 | I18: - | J18: E
A19: 20 | D19: bfw_bal_disp_flg | E19: #MA.FLG | G19: Display payment receipt schedule in invoice details | H19: 請求書明細入金予定表示 | I19: - | J19: E
A20: 20 | D20: bill_dpt_cd | E20: #MA.DPT_CD | G20: Billing dept. cd. | H20: 請求部門ＣＤ | I20: - | J20: E
A21: 20 | D21: bill_dpt_nm | E21: #MA.DPT_NM | G21: Billing dept. name | H21: 請求部門名 | I21: - | J21: E
A22: 20 | D22: wg_cd | E22: #MA.WG_CD | G22: WG cd. | H22: ワーキンググループＣＤ | I22: - | J22: E
A23: 20 | D23: wg_nm | E23: #MA.WG_NM | G23: WG name | H23: ワーキンググループ名 | I23: - | J23: E
A24: 20 | D24: bcst_cd | E24: #MA.BP_CD | G24: Billing customer cd. | H24: 請求先ＣＤ | I24: - | J24: E
A25: 20 | D25: bcst_nm | E25: #MA.BP_NM | G25: Billing customer name | H25: 請求先名 | I25: - | J25: E
A26: 20 | D26: trd_cur_cd | E26: #MA.CUR_CD | G26: Currency cd. | H26: 通貨ＣＤ | I26: - | J26: E
... A53: 20 | D53: upd_cntr | E53: #MA.UPD_CNT | G53: Update counter | H53: 更新カウンタ | I53: - | J53: E
L54: 上り項目 Request Message Field | M54: 下り項目 Response Message Field | N54: 上り項目 Request Message Field | O54: 下り項目 Response Message Field
A55: 30 | B55: * | D55: Srch01_Dtl1 | E55: L
A56: 30 | D56: rcv_schd_dt | E56: #MA.DT | G56: Scheduled payment receipt date | H56: 入金予定日 | I56: - | J56: E
A57: 30 | D57: rcv_cd | E57: #MA.STTL_CD | G57: Payment received method cd. | H57: 入金方法ＣＤ | I57: - | J57: E
A58: 30 | D58: rcv_nm | E58: #MA.STTL_NM | G58: Payment received method name | H58: 入金方法名 | I58: - | J58: E
A59: 30 | D59: rcv_typ | E59: #MA.AR_STTL_TYP | G59: Payment received type | H59: 入金区分 | I59: - | J59: E
A60: 30 | D60: rcv_schd_amt | E60: #MA.MONEY | G60: Amount of payment receipt schedule | H60: 入金予定額 | I60: - | J60: E
A61: 30 | D61: rcv_schd_no | E61: #MA.RCV_SCHD_NO | G61: Payment receipt schedule No. | H61: 入金予定ＮＯ | I61: - | J61: E
A62: 30 | D62: sub_char1 | E62: #MS.RCV_SCHD_SUB_CHAR1 | G62: Spare 1 | H62: 予備１ | I62: - | J62: E
A63: 30 | D63: sub_char2 | E63: #MS.RCV_SCHD_SUB_CHAR2 | G63: Spare 2 | H63: 予備２ | I63: - | J63: E
A64: 30 | D64: sub_char3 | E64: #MS.RCV_SCHD_SUB_CHAR3 | G64: Spare 3 | H64: 予備３ | I64: - | J64: E
A65: 30 | D65: ins_usr_id | E65: #MA.FCM_USR_ID | G65: Entry user ID | H65: 登録ユーザＩＤ | I65: - | J65: E
A66: 30 | D66: ins_usr_nm | E66: #MA.FCM_USR_NM | G66: Entry user name | H66: 登録ユーザ名 | I66: - | J66: E
...

Sheet Chk01
A1: * | B1: * | D1: L | E1: 1
A2: * | D2: オペレーション実装仕様書 Operation Specification Implementation Sheet | E2: ModuleID : | F2: =IF(LogicCommon!C2="","",LogicCommon!C2) -> MS | G2: LogicID : | H2: =IF(LogicCommon!E2="","",LogicCommon!E2) -> MSBGL0080 | I2: Ope.ID : | J2: Chk01 | K2: Pj.ID : | L2: =IF(LogicCommon!G2="","",LogicCommon!G2) -> MC | M2: Ope.Body : | N2: MA.MAUDL5010.Checker
A3: * | E3: SubModuleID : | F3: =IF(LogicCommon!C3="","",LogicCommon!C3) -> MSBG | G3: LogicClass : | H3: =IF(LogicCommon!E3="","",LogicCommon!E3) -> MSBGL_RcvSchdAdjstReg | I3: Ope.Method : | J3: Chk01 | K3: SuperClassPj.ID : | L3: =IF(LogicCommon!G3="","",LogicCommon!G3) | O3: Gene.Type : | P3: ALL
A4: * | E4: Version : | F4: 000000 | G4: LogicName : | H4: =IF(LogicCommon!E4="","",LogicCommon!E4) -> 入金予定調整登録 | I4: Ope.Name : | J4: 登録前チェック | K4: SuperLogicID : | L4: =IF(LogicCommon!G4="","",LogicCommon!G4) -> MS.MSUDL5010 | M4: ImplOpe.ID:
A5: * | E5: ACType :
A6: * | D6: 概要 : | E6: 登録済みの入金予定調整を更新する前に、チェックを実行する。 | AD6: ID | AF6: ID
A7: # | I7: U | K7: K | L7: K | M7: K | N7: K | O7: K | P7: K | Q7: K | R7: K | S7: K | T7: K | U7: K | V7: K | W7: K | X7: K | Y7: K | Z7: K | AA7: K | AB7: K | AC7: o | AE7: o
A8: # | D8: ブロック名 Block Name | E8: 型 Type | G8: super/share | H8: 対象ブロック名 Target Block Name | K8: REQ_UPD_CNT_CHK | L8: REQUIRED | M8: CHK_NUM | N8: SMALL_LARGE | O8: CHK_DT | P8: BEFORE_AFTER | Q8: CHK_PTN | R8: DUPLICATE | S8: TOO_MANY_INPUTS | T8: AT_LEAST_ONE | U8: ONLY_ONE_INPUT | V8: LIST_LOGIC | W8: LIST_OUT | X8: LIST_OUT_BASE | Y8: LIST_IN | Z8: LIST_IN_BASE | AA8: CONST | AB8: NULL_VAL | AC8: TargetName | AE8: TargetName | AI8: ブロック備考 Block Remarks
A9: # | D9: 項目名 Field Name | E9: 型 Type | F9: 桁 Digits | G9: フルネーム Full Name | H9: 日本語名 Japanese Name | I9: 上り項目 Request Message Field | J9: 下り項目 Response Message Field | AG9: 条件および編集方法 Conditions and Editing Methods | AI9: 項目備考 Field Remarks
A10: # | AC10: 上り項目 Request Message Field | AD10: 下り項目 Response Message Field | AE10: 上り項目 Request Message Field | AF10: 下り項目 Response Message Field
A11: 10 | B11: * | D11: Chk01_Hdr | E11: R
A12: 10 | D12: rcv_schd_adjst_flg | E12: #MA.FLG | G12: Payment receipt schedule adjusted | H12: 入金予定調整済 | I12: - | J12: E
A13: 10 | D13: bill_mng_no | E13: #MA.BILL_MNG_NO | G13: Billing management No. | H13: 請求管理ＮＯ | I13: E | J13: - | K13: E
A14: 10 | D14: trd_cur_cd | E14: #MA.CUR_CD | G14: Currency cd. | H14: 通貨ＣＤ | I14: - | J14: -
A15: 10 | D15: bill_dpt_cd | E15: #MA.DPT_CD | G15: Billing dept. cd. | H15: 請求部門ＣＤ | I15: E | J15: -
A16: 10 | D16: amt_dec_place | E16: #MA.DEC_PLACE | G16: Amount number of decimal places | H16: 金額小数部有効桁数 | I16: E | J16: -
A17: 10 | D17: iv_no | E17: #MA.IV_NO | G17: Invoice No. | H17: インボイスＮＯ | I17: - | J17: -
A18: 10 | D18: upd_cntr | E18: #MA.UPD_CNT | G18: Update counter | H18: 更新カウンタ | I18: E | J18: -
A19: 10 | D19: err_flg | E19: #MA.FLG | G19: Error | H19: エラー | I19: - | J19: E
A20: 10 | D20: peg_no | E20: #MA.INT | G20: Pegging No. | H20: 紐付けＮＯ | I20: E | J20: E
AC21: 上り項目 Request Message Field | AD21: 下り項目 Response Message Field | AE21: 上り項目 Request Message Field | AF21: 下り項目 Response Message Field
A22: 20 | B22: * | D22: Chk01_Dtl2 | E22: L
A23: 20 | D23: rcv_schd_dt | E23: #MA.DT | G23: Scheduled payment receipt date | H23: 入金予定日 | I23: E | J23: E | L23: E
A24: 20 | D24: rcv_cd | E24: #MA.STTL_CD | G24: Payment received method cd. | H24: 入金方法ＣＤ | I24: - | J24: E | L24: E | V24: MA.MAUAL0010.ArSttlNotRcvSchd | W24: rcv_nm;rcv_typ | X24: sttl_nm;ar_sttl_typ
A25: 20 | D25: rcv_nm | E25: #MA.STTL_NM | G25: Payment received method name | H25: 入金方法名 | I25: - | J25: -
A26: 20 | D26: rcv_typ | E26: #MA.AR_STTL_TYP | G26: Payment received type | H26: 入金区分 | I26: E | J26: E | AA26: MAC_AR_STTL_TYP
A27: 20 | D27: rcv_schd_amt | E27: #MA.MONEY | G27: Amount of payment receipt schedule | H27: 入金予定額 | I27: E | J27: E | L27: E | M27: notZero
A28: 20 | D28: rcv_schd_no | E28: #MA.RCV_SCHD_NO | G28: Payment receipt schedule No. | H28: 入金予定ＮＯ | I28: E | J28: E
A29: 20 | D29: sub_char1 | E29: #MS.RCV_SCHD_SUB_CHAR1 | G29: Spare 1 | H29: 予備１ | I29: E | J29: E
A30: 20 | D30: sub_char2 | E30: #MS.RCV_SCHD_SUB_CHAR2 | G30: Spare 2 | H30: 予備２ | I30: E | J30: E
A31: 20 | D31: sub_char3 | E31: #MS.RCV_SCHD_SUB_CHAR3 | G31: Spare 3 | H31: 予備３ | I31: E | J31: E
A32: 20 | D32: err_flg | E32: #MA.FLG | G32: Error | H32: エラー | I32: - | J32: E
A33: 20 | D33: peg_no | E33: #MA.INT | G33: Pegging No. | H33: 紐付けＮＯ | I33: E | J33: E
D34: 詳細 :

Sheet Upd01
A1: * | B1: * | D1: L | E1: 1
A2: * | D2: オペレーション実装仕様書 Operation Specification Implementation Sheet | E2: ModuleID : | F2: =IF(LogicCommon!C2="","",LogicCommon!C2) -> MS | G2: LogicID : | H2: =IF(LogicCommon!E2="","",LogicCommon!E2) -> MSBGL0080 | I2: Ope.ID : | J2: Upd01 | K2: Pj.ID : | L2: =IF(LogicCommon!G2="","",LogicCommon!G2) -> MC | M2: Ope.Body : | N2: "mcframe.serverMAUD.MAUDL5010.MAUDL_Operation"
A3: * | E3: SubModuleID : | F3: =IF(LogicCommon!C3="","",LogicCommon!C3) -> MSBG | G3: LogicClass : | H3: =IF(LogicCommon!E3="","",LogicCommon!E3) -> MSBGL_RcvSchdAdjstReg | I3: Ope.Method : | J3: Upd01 | K3: SuperClassPj.ID : | L3: =IF(LogicCommon!G3="","",LogicCommon!G3) | O3: Gene.Type : | P3: ALL
A4: * | E4: Version : | F4: 000000 | G4: LogicName : | H4: =IF(LogicCommon!E4="","",LogicCommon!E4) -> 入金予定調整登録 | I4: Ope.Name : | J4: 更新 | K4: SuperLogicID : | L4: =IF(LogicCommon!G4="","",LogicCommon!G4) -> MS.MSUDL5010 | M4: ImplOpe.ID:
A5: * | E5: ACType :
A6: * | D6: 概要 : | E6: 登録済みの入金予定調整を更新する。 | L6: ID | N6: ID | P6: ID | R6: ID
A7: # | I7: U | K7: o | M7: o | O7: o | Q7: o
A8: # | D8: ブロック名 Block Name | E8: 型 Type | G8: super/share | H8: 対象ブロック名 Target Block Name | K8: TargetName | M8: TargetName | O8: TargetName | Q8: TargetName | U8: ブロック備考 Block Remarks
A9: # | D9: 項目名 Field Name | E9: 型 Type | F9: 桁 Digits | G9: フルネーム Full Name | H9: 日本語名 Japanese Name | I9: 上り項目 Request Message Field | J9: 下り項目 Response Message Field | S9: 条件および編集方法 Conditions and Editing Methods | U9: 項目備考 Field Remarks
A10: # | K10: 上り項目 Request Message Field | L10: 下り項目 Response Message Field | M10: 上り項目 Request Message Field | N10: 下り項目 Response Message Field | O10: 上り項目 Request Message Field | P10: 下り項目 Response Message Field | Q10: 上り項目 Request Message Field | R10: 下り項目 Response Message Field
A11: 10 | B11: * | D11: Upd01_Hdr | E11: R | G11: $share$ | H11: MS.MSBGL0080.Chk01.Chk01_Hdr
A12: 10 | D12: rcv_schd_adjst_flg | E12: #MA.FLG | G12: Payment receipt schedule adjusted | H12: 入金予定調整済 | I12: E | J12: -
A13: 10 | D13: bill_mng_no | E13: #MA.BILL_MNG_NO | G13: Billing management No. | H13: 請求管理ＮＯ | I13: E | J13: -
A14: 10 | D14: trd_cur_cd | E14: #MA.CUR_CD | G14: Currency cd. | H14: 通貨ＣＤ | I14: E | J14: -
A15: 10 | D15: bill_dpt_cd | E15: #MA.DPT_CD | G15: Billing dept. cd. | H15: 請求部門ＣＤ | I15: E | J15: -
A16: 10 | D16: amt_dec_place | E16: #MA.DEC_PLACE | G16: Amount number of decimal places | H16: 金額小数部有効桁数 | I16: E | J16: -
A17: 10 | D17: iv_no | E17: #MA.IV_NO | G17: Invoice No. | H17: インボイスＮＯ | I17: E | J17: -
A18: 10 | D18: upd_cntr | E18: #MA.UPD_CNT | G18: Update counter | H18: 更新カウンタ | I18: E | J18: -
A19: 10 | D19: err_flg | E19: #MA.FLG | G19: Error | H19: エラー | I19: - | J19: -
A20: 10 | D20: peg_no | E20: #MA.INT | G20: Pegging No. | H20: 紐付けＮＯ | I20: - | J20: -
A22: 20 | B22: * | D22: Upd01_Dtl2 | E22: L | G22: $share$ | H22: MS.MSBGL0080.Chk01.Chk01_Dtl2
A23: 20 | D23: rcv_schd_dt | E23: #MA.DT | G23: Scheduled payment receipt date | H23: 入金予定日 | I23: E | J23: -
A24: 20 | D24: rcv_cd | E24: #MA.STTL_CD | G24: Payment received method cd. | H24: 入金方法ＣＤ | I24: E | J24: -
A25: 20 | D25: rcv_nm | E25: #MA.STTL_NM | G25: Payment received method name | H25: 入金方法名 | I25: - | J25: -
A26: 20 | D26: rcv_typ | E26: #MA.AR_STTL_TYP | G26: Payment received type | H26: 入金区分 | I26: E | J26: -
A27: 20 | D27: rcv_schd_amt | E27: #MA.MONEY | G27: Amount of payment receipt schedule | H27: 入金予定額 | I27: E | J27: -
A28: 20 | D28: rcv_schd_no | E28: #MA.RCV_SCHD_NO | G28: Payment receipt schedule No. | H28: 入金予定ＮＯ | I28: E | J28: -
A29: 20 | D29: sub_char1 | E29: #MS.RCV_SCHD_SUB_CHAR1 | G29: Spare 1 | H29: 予備１ | I29: E | J29: -
A30: 20 | D30: sub_char2 | E30: #MS.RCV_SCHD_SUB_CHAR2 | G30: Spare 2 | H30: 予備２ | I30: E | J30: -
A31: 20 | D31: sub_char3 | E31: #MS.RCV_SCHD_SUB_CHAR3 | G31: Spare 3 | H31: 予備３ | I31: E | J31: -
A32: 20 | D32: err_flg | E32: #MA.FLG | G32: Error | H32: エラー | I32: - | J32: -
A33: 20 | D33: peg_no | E33: #MA.INT | G33: Pegging No. | H33: 紐付けＮＯ | I33: - | J33: -
D34: 詳細 :

Sheet 来歴
A1: 変更来歴
A3: Rev. | H3: 修正番号 | O3: 変更内容 | AQ3: 変更箇所
A4: 1 | O4: 初版
A5: 1.1 | O5: 英語の名称を追記 | AQ5: 全般
