Workbook

Sheet LogicCommon
A2: オペレーション実装仕様書 | B2: ModuleID : | C2: MS | D2: LogicID : | E2: MSBGL0010 | F2: Pj.ID : | G2: MC
B3: SubModuleID : | C3: MSBG | D3: LogicClass : | E3: MSBGL_BillCl | F3: SuperClassPj.ID :
D4: LogicName : | E4: 請求締処理 | F4: SuperLogicID : | G4: MS.MSUDL5010
A5: 概要 :
A6: 詳細 :

Sheet Srch02
A1: * | B1: * | D1: L | E1: 1
A2: * | D2: オペレーション実装仕様書 Operation Specification Implementation Sheet | E2: ModuleID : | F2: =IF(LogicCommon!C2="","",LogicCommon!C2) -> MS | G2: LogicID : | H2: =IF(LogicCommon!E2="","",LogicCommon!E2) -> MSBGL0010 | I2: Ope.ID : | J2: Srch02 | K2: Pj.ID : | L2: =IF(LogicCommon!G2="","",LogicCommon!G2) -> MC | M2: Ope.Body : | N2: "mcframe.serverMAUD.MAUDL5010.MAUDL_Searcher"
A3: * | D3: =IF(LogicCommon!A3="","",LogicCommon!A3) | E3: SubModuleID : | F3: =IF(LogicCommon!C3="","",LogicCommon!C3) -> MSBG | G3: LogicClass : | H3: =IF(LogicCommon!E3="","",LogicCommon!E3) -> MSBGL_BillCl | I3: Ope.Method : | J3: Srch02 | K3: SuperClassPj.ID : | L3: =IF(LogicCommon!G3="","",LogicCommon!G3) | O3: Gene.Type : | P3: ALL
A4: * | E4: Version : | F4: 000000 | G4: LogicName : | H4: =IF(LogicCommon!E4="","",LogicCommon!E4) -> 請求締処理 | I4: Ope.Name : | J4: 請求締解除対象検索 | K4: SuperLogicID : | L4: =IF(LogicCommon!G4="","",LogicCommon!G4) -> MS.MSUDL5010 | M4: ImplOpe.ID:
A5: * | E5: ACType :
A6: * | D6: 概要 : | E6: 請求締解除の対象となる請求締済の請求情報を検索する。 | M6: ID | O6: ID | Q6: ID
A7: # | I7: U | K7: K | L7: o | N7: o | P7: o
A8: # | D8: ブロック名 Block Name | E8: 型 Type | G8: super/share | H8: 対象ブロック名 Target Block Name | K8: CONST | L8: TargetName | N8: TargetName | P8: TargetName | T8: ブロック備考 Block Remarks
A9: # | D9: 項目名 Field Name | E9: 型 Type | F9: 桁 Digits | G9: フルネーム Full Name | H9: 日本語名 Japanese Name | I9: 上り項目 Request Message Field | J9: 下り項目 Response Message Field | R9: 条件および編集方法 Conditions and Editing Methods | T9: 項目備考 Field Remarks
A10: # | L10: 上り項目 Request Message Field | M10: 下り項目 Response Message Field | N10: 上り項目 Request Message Field | O10: 下り項目 Response Message Field | P10: 上り項目 Request Message Field | Q10: 下り項目 Response Message Field
A11: 10 | B11: * | D11: Srch02_Cnd | E11: R
A12: 10 | D12: bill_ym | E12: #MA.YM | G12: Billing month | H12: 請求年月 | I12: E | J12: -
A13: 10 | D13: bill_cl_day | E13: #MA.CL_DAY | G13: Billing closing day | H13: 請求締日 | I13: E | J13: -
A14: 10 | D14: bcst_cd | E14: #MA.BP_CD | G14: Billing customer cd. | H14: 請求先ＣＤ | I14: E | J14: -
A15: 10 | D15: bcst_nm | E15: #MA.BP_NM | G15: Billing customer name | H15: 請求先名 | I15: E | J15: -
A16: 10 | D16: on_edi_flg | E16: #MA.FLG | G16: for EDI | H16: ＥＤＩ対象.対象 | I16: E | J16: -
A17: 10 | D17: off_edi_flg | E17: #MA.FLG | G17: Not for EDI | H17: ＥＤＩ対象.対象外 | I17: E | J17: -
A18: 10 | D18: bill_dpt_cd | E18: #MA.DPT_CD | G18: Billing dept. cd. | H18: 請求部門ＣＤ | I18: E | J18: -
A19: 10 | D19: bill_dpt_nm | E19: #MA.DPT_NM | G19: Billing dept. name | H19: 請求部門名 | I19: E | J19: -
A20: 10 | D20: wg_cd | E20: #MA.WG_CD | G20: WG cd. | H20: ワーキンググーループＣＤ | I20: E | J20: -
A21: 10 | D21: wg_nm | E21: #MA.WG_NM | G21: WG name | H21: ワーキンググーループ名 | I21: E | J21: -
A22: 10 | D22: trd_cur_cd | E22: #MA.CUR_CD | G22: Currency cd. | H22: 通貨ＣＤ | I22: E | J22: -
A23: 10 | D23: trd_cur_nm | E23: #MA.CUR_NM | G23: Currency name | H23: 通貨名 | I23: E | J23: -
... A32: 10 | D32: today | E32: #MA.DT | G32: Operation date | H32: 運用日付 | I32: - | J32: -
A34: 20 | B34: * | D34: Srch02_Hdr | E34: L
A35: 20 | D35: bill_no | E35: #MA.BILL_NO | G35: Invoice No. | H35: 請求書ＮＯ | I35: - | J35: E
A36: 20 | D36: bill_dpt_cd | E36: #MA.DPT_CD | G36: Billing dept. cd. | H36: 請求部門ＣＤ | I36: - | J36: E
A37: 20 | D37: bill_dpt_nm | E37: #MA.DPT_NM | G37: Billing dept. name | H37: 請求部門名 | I37: - | J37: E
A38: 20 | D38: wg_cd | E38: #MA.WG_CD | G38: WG cd. | H38: ワーキンググーループＣＤ | I38: - | J38: E
A39: 20 | D39: wg_nm | E39: #MA.WG_NM | G39: WG name | H39: ワーキンググーループ名 | I39: - | J39: E
A40: 20 | D40: bcst_cd | E40: #MA.BP_CD | G40: Billing customer cd. | H40: 請求先ＣＤ | I40: - | J40: E
A41: 20 | D41: bcst_nm | E41: #MA.BP_NM | G41: Billing customer name | H41: 請求先名 | I41: - | J41: E
A42: 20 | D42: edi_flg | E42: #MA.FLG | G42: For EDI | H42: ＥＤＩ対象 | I42: - | J42: E
A43: 20 | D43: iv_no | E43: #MA.IV_NO | G43: Invoice No. | H43: インボイスＮＯ | I43: - | J43: E
A44: 20 | D44: bill_ym | E44: #MA.YM | G44: Billing month | H44: 請求年月 | I44: - | J44: E
A45: 20 | D45: bill_cl_day | E45: #MA.CL_DAY | G45: Closing date | H45: 締日 | I45: - | J45: E
A46: 20 | D46: rcv_schd_dt | E46: #MA.DT | G46: Scheduled payment receipt date | H46: 入金予定日 | I46: - | J46: E
... A55: 20 | D55: last_bill_cl_day | E55: #MA.CL_DAY | G55: Last closing date | H55: 前回締日 | I55: - | J55: E
A56: 20 | D56: bill_cl_typ | E56: #MA.BILL_CL_TYP | G56: Billing closing type | H56: 請求締処理区分 | I56: - | J56: E | K56: MAC_BILL_CL_TYP
A57: 20 | D57: bill_cl_typ_nm | E57: #MA.BILL_CL_TYP_NM | G57: Billing closing type name | H57: 請求締処理区分名 | I57: - | J57: E
...

Sheet Srch01
A1: * | B1: * | D1: L | E1: 1
A2: * | D2: オペレーション実装仕様書 Operation Specification Implementation Sheet | E2: ModuleID : | F2: =IF(LogicCommon!C2="","",LogicCommon!C2) -> MS | G2: LogicID : | H2: =IF(LogicCommon!E2="","",LogicCommon!E2) -> MSBGL0010 | I2: Ope.ID : | J2: Srch01 | K2: Pj.ID : | L2: =IF(LogicCommon!G2="","",LogicCommon!G2) -> MC | M2: Ope.Body : | N2: "mcframe.serverMAUD.MAUDL5010.MAUDL_Searcher"
A3: * | D3: =IF(LogicCommon!A3="","",LogicCommon!A3) | E3: SubModuleID : | F3: =IF(LogicCommon!C3="","",LogicCommon!C3) -> MSBG | G3: LogicClass : | H3: =IF(LogicCommon!E3="","",LogicCommon!E3) -> MSBGL_BillCl | I3: Ope.Method : | J3: Srch01 | K3: SuperClassPj.ID : | L3: =IF(LogicCommon!G3="","",LogicCommon!G3) | O3: Gene.Type : | P3: ALL
A4: * | E4: Version : | F4: 000000 | G4: LogicName : | H4: =IF(LogicCommon!E4="","",LogicCommon!E4) -> 請求締処理 | I4: Ope.Name : | J4: 請求締対象検索 | K4: SuperLogicID : | L4: =IF(LogicCommon!G4="","",LogicCommon!G4) -> MS.MSUDL5010 | M4: ImplOpe.ID:
A5: * | E5: ACType :
A6: * | D6: 概要 : | E6: 請求締処理の対象となる未請求の請求情報を検索する。 | M6: ID | O6: ID | Q6: ID
A7: # | I7: U | K7: K | L7: o | N7: o | P7: o
A8: # | D8: ブロック名 Block Name | E8: 型 Type | G8: super/share | H8: 対象ブロック名 Target Block Name | K8: CONST | L8: TargetName | N8: TargetName | P8: TargetName | T8: ブロック備考 Block Remarks
A9: # | D9: 項目名 Field Name | E9: 型 Type | F9: 桁 Digits | G9: フルネーム Full Name | H9: 日本語名 Japanese Name | I9: 上り項目 Request Message Field | J9: 下り項目 Response Message Field | R9: 条件および編集方法 Conditions and Editing Methods | T9: 項目備考 Field Remarks
A10: # | L10: 上り項目 Request Message Field | M10: 下り項目 Response Message Field | N10: 上り項目 Request Message Field | O10: 下り項目 Response Message Field | P10: 上り項目 Request Message Field | Q10: 下り項目 Response Message Field
A11: 10 | B11: * | D11: Srch01_Cnd | E11: R | G11: $share$ | H11: MS.MSBGL0010.Srch02.Srch02_Cnd
A12: 10 | D12: bill_ym | E12: #MA.YM | G12: Billing month | H12: 請求年月 | I12: E | J12: -
A13: 10 | D13: bill_cl_day | E13: #MA.CL_DAY | G13: Billing closing day | H13: 請求締日 | I13: E | J13: -
A14: 10 | D14: bcst_cd | E14: #MA.BP_CD | G14: Billing customer cd. | H14: 請求先ＣＤ | I14: E | J14: -
A15: 10 | D15: bcst_nm | E15: #MA.BP_NM | G15: Billing customer name | H15: 請求先名 | I15: E | J15: -
A16: 10 | D16: on_edi_flg | E16: #MA.FLG | G16: for EDI | H16: ＥＤＩ対象.対象 | I16: E | J16: -
A17: 10 | D17: off_edi_flg | E17: #MA.FLG | G17: Not for EDI | H17: ＥＤＩ対象.対象外 | I17: E | J17: -
A18: 10 | D18: bill_dpt_cd | E18: #MA.DPT_CD | G18: Billing dept. cd. | H18: 請求部門ＣＤ | I18: E | J18: -
A19: 10 | D19: bill_dpt_nm | E19: #MA.DPT_NM | G19: Billing dept. name | H19: 請求部門名 | I19: E | J19: -
A20: 10 | D20: wg_cd | E20: #MA.WG_CD | G20: WG cd. | H20: ワーキンググーループＣＤ | I20: E | J20: -
A21: 10 | D21: wg_nm | E21: #MA.WG_NM | G21: WG name | H21: ワーキンググーループ名 | I21: E | J21: -
A22: 10 | D22: trd_cur_cd | E22: #MA.CUR_CD | G22: Currency cd. | H22: 通貨ＣＤ | I22: E | J22: -
A23: 10 | D23: trd_cur_nm | E23: #MA.CUR_NM | G23: Currency name | H23: 通貨名 | I23: E | J23: -
... A30: 10 | D30: today | E30: #MA.DT | G30: Operation date | H30: 運用日付 | I30: - | J30: -
A32: 20 | B32: * | D32: Srch01_Hdr | E32: L | G32: $share$ | H32: MS.MSBGL0010.Srch02.Srch02_Hdr
A33: 20 | D33: bill_no | E33: #MA.BILL_NO | G33: Invoice No. | H33: 請求書ＮＯ | I33: - | J33: E
A34: 20 | D34: bill_dpt_cd | E34: #MA.DPT_CD | G34: Billing dept. cd. | H34: 請求部門ＣＤ | I34: - | J34: E
A35: 20 | D35: bill_dpt_nm | E35: #MA.DPT_NM | G35: Billing dept. name | H35: 請求部門名 | I35: - | J35: E
A36: 20 | D36: wg_cd | E36: #MA.WG_CD | G36: WG cd. | H36: ワーキンググーループＣＤ | I36: - | J36: E
A37: 20 | D37: wg_nm | E37: #MA.WG_NM | G37: WG name | H37: ワーキンググーループ名 | I37: - | J37: E
A38: 20 | D38: bcst_cd | E38: #MA.BP_CD | G38: Billing customer cd. | H38: 請求先ＣＤ | I38: - | J38: E
A39: 20 | D39: bcst_nm | E39: #MA.BP_NM | G39: Billing customer name | H39: 請求先名 | I39: - | J39: E
A40: 20 | D40: edi_flg | E40: #MA.FLG | G40: For EDI | H40: ＥＤＩ対象 | I40: - | J40: E
A41: 20 | D41: iv_no | E41: #MA.IV_NO | G41: Invoice No. | H41: インボイスＮＯ | I41: - | J41: E
A42: 20 | D42: bill_ym | E42: #MA.YM | G42: Billing month | H42: 請求年月 | I42: - | J42: E
A43: 20 | D43: bill_cl_day | E43: #MA.CL_DAY | G43: Closing date | H43: 締日 | I43: - | J43: E
A44: 20 | D44: trd_cur_cd | E44: #MA.CUR_CD | G44: Transaction currency cd. | H44: 取引通貨ＣＤ | I44: - | J44: E
... A52: 20 | D52: last_bill_cl_day | E52: #MA.CL_DAY | G52: Last closing date | H52: 前回締日 | I52: - | J52: E
A53: 20 | D53: bill_cl_typ | E53: #MA.BILL_CL_TYP | G53: Billing closing type | H53: 請求締処理区分 | I53: - | J53: E | K53: MAC_BILL_CL_TYP
A54: 20 | D54: bill_cl_typ_nm | E54: #MA.BILL_CL_TYP_NM | G54: Billing closing type name | H54: 請求締処理区分名 | I54: - | J54: E
...

Sheet Chk01
A1: * | B1: * | D1: L | E1: 1
A2: * | D2: オペレーション実装仕様書 Operation Specification Implementation Sheet | E2: ModuleID : | F2: =IF(LogicCommon!C2="","",LogicCommon!C2) -> MS | G2: LogicID : | H2: =IF(LogicCommon!E2="","",LogicCommon!E2) -> MSBGL0010 | I2: Ope.ID : | J2: Chk01 | K2: Pj.ID : | L2: =IF(LogicCommon!G2="","",LogicCommon!G2) -> MC | M2: Ope.Body : | N2: MA.MAUDL5010.Checker
A3: * | D3: =IF(LogicCommon!A3="","",LogicCommon!A3) | E3: SubModuleID : | F3: =IF(LogicCommon!C3="","",LogicCommon!C3) -> MSBG | G3: LogicClass : | H3: =IF(LogicCommon!E3="","",LogicCommon!E3) -> MSBGL_BillCl | I3: Ope.Method : | J3: Chk01 | K3: SuperClassPj.ID : | L3: =IF(LogicCommon!G3="","",LogicCommon!G3) | O3: Gene.Type : | P3: ALL
A4: * | E4: Version : | F4: 000000 | G4: LogicName : | H4: =IF(LogicCommon!E4="","",LogicCommon!E4) -> 請求締処理 | I4: Ope.Name : | J4: 登録・訂正前チェック | K4: SuperLogicID : | L4: =IF(LogicCommon!G4="","",LogicCommon!G4) -> MS.MSUDL5010 | M4: ImplOpe.ID:
A5: * | E5: ACType :
A6: * | D6: 概要 : | E6: 締処理時の各種チェックを行う。 | S6: ID | U6: ID | W6: ID
A7: # | I7: U | K7: K | L7: K | M7: K | N7: K | O7: K | P7: K | Q7: K | R7: o | T7: o | V7: o
A8: # | D8: ブロック名 Block Name | E8: 型 Type | G8: super/share | H8: 対象ブロック名 Target Block Name | K8: REQ_UPD_CNT_CHK | L8: REQUIRED | M8: LIST_LOGIC | N8: LIST_OUT | O8: LIST_OUT_BASE | P8: LIST_IN | Q8: LIST_IN_BASE | R8: TargetName | T8: TargetName | V8: TargetName | Z8: ブロック備考 Block Remarks
A9: # | D9: 項目名 Field Name | E9: 型 Type | F9: 桁 Digits | G9: フルネーム Full Name | H9: 日本語名 Japanese Name | I9: 上り項目 Request Message Field | J9: 下り項目 Response Message Field | X9: 条件および編集方法 Conditions and Editing Methods | Z9: 項目備考 Field Remarks
A10: # | R10: 上り項目 Request Message Field | S10: 下り項目 Response Message Field | T10: 上り項目 Request Message Field | U10: 下り項目 Response Message Field | V10: 上り項目 Request Message Field | W10: 下り項目 Response Message Field
A11: 10 | B11: * | D11: Chk01_Hdr | E11: L
A12: 10 | D12: peg_no | E12: #MA.INT | G12: Pegging No. | H12: 紐付けＮＯ | I12: E | J12: E
A13: 10 | D13: err_flg | E13: #MA.FLG | G13: Error | H13: エラー | I13: - | J13: -
A14: 10 | D14: rtn_sts_typ | E14: #MA.RTN_STS_TYP | G14: Process result status type | H14: 処理結果状況区分 | I14: - | J14: E
A15: 10 | D15: bcst_cd | E15: #MA.BP_CD | G15: Billing customer cd. | H15: 請求先ＣＤ | I15: E | J15: E | M15: MA.MAUAL0010.Bp | P15: MAC_BP_IS_SRCH_TYP.BCST | Q15: bp_is_srch_typ
A16: 10 | D16: bill_dpt_cd | E16: #MA.DPT_CD | G16: Billing dept. cd. | H16: 請求部門ＣＤ | I16: E | J16: E | M16: MA.MAUAL0010.Dpt | P16: bill_cl_dt;MAC_DPT_IS_SRCH_TYP.BCST;bcst_cd | Q16: dt;dpt_is_srch_typ;bcst_cd
A17: 10 | D17: iv_no | E17: #MA.IV_NO | G17: Invoice No. | H17: インボイスＮＯ | I17: E | J17: E
A18: 10 | D18: trd_cur_cd | E18: #MA.CUR_CD | G18: Transaction currency cd. | H18: 取引通貨ＣＤ | I18: E | J18: E | M18: MA.MAUAL0010.Cur
A19: 10 | D19: bill_xrate | E19: #MA.MONEY | G19: Billing exchange rate | H19: 請求為替レート | I19: E | J19: E
A20: 10 | D20: wrk_no | E20: #MA.WRK_NO | G20: Sales project No. | H20: 案件ＮＯ | I20: E | J20: E
A21: 10 | D21: bill_cl_dt | E21: #MA.DT | G21: Billing date | H21: 請求年月日 | I21: - | J21: -
A22: 10 | D22: inpt_bill_ym | E22: #MA.YM | G22: Input billing month | H22: 入力請求年月 | I22: E | J22: E | L22: E
A23: 10 | D23: inpt_rcv_schd_dt | E23: #MA.DT | G23: Input scheduled payment receipt date | H23: 入力入金予定日 | I23: E | J23: E
A24: 10 | D24: inpt_bill_cl_day | E24: #MA.CL_DAY | G24: Input billing closing date | H24: 入力請求締日 | I24: E | J24: E
A25: 10 | D25: bill_d_sel_flg | E25: #MA.FLG | G25: Select billing details | H25: 請求明細選択 | I25: E | J25: E
A26: 10 | D26: bill_no | E26: #MA.BILL_NO | G26: Invoice No. | H26: 請求書ＮＯ | I26: - | J26: -
A27: 10 | D27: bill_cl_typ | E27: #MA.BILL_CL_TYP | G27: Billing closing type | H27: 請求締処理区分 | I27: E | J27: E
A28: 10 | D28: upd_cntr | E28: #MA.UPD_CNT | G28: Update counter | H28: 更新カウンタ | I28: E | J28: E | K28: E
A29: 10 | D29: bill_mng_no | E29: #MA.BILL_MNG_NO | G29: Billing management No. | H29: 請求管理ＮＯ | I29: E | J29: E | K29: E
A30: 10 | D30: rec_id | E30: #MA.INT | G30: Record ID | H30: レコードＩＤ | I30: E | J30: E
A32: 20 | B32: * | D32: Chk01_Dtl | E32: L
A33: 20 | D33: bill_d_no | E33: #MA.BILL_NO | G33: Billing details No. | H33: 請求明細ＮＯ | I33: E | J33: E
A34: 20 | D34: bill_mtd_typ | E34: #MS.BILL_MTD_TYP | G34: Billing method type | H34: 請求方式区分 | I34: E | J34: E
A35: 20 | D35: amt | E35: #MA.MONEY | G35: Amount | H35: 金額 | I35: E | J35: E
A36: 20 | D36: tax_amt | E36: #MA.MONEY | G36: Tax amount | H36: 税額 | I36: E | J36: E
A37: 20 | D37: bill_prnt_tgt_flg | E37: #MA.FLG | G37: Invoice output | H37: 請求書出力 | I37: E | J37: E
A38: 20 | D38: rec_id | E38: #MA.INT | G38: Record ID | H38: レコードＩＤ | I38: E | J38: E
A39: 20 | D39: rcv_act_d_no | E39: #MA.RCV_ACT_D_NO | G39: Payment received result details No. | H39: 入金実績明細ＮＯ | I39: E | J39: E
A40: 20 | D40: rcv_act_d_seq | E40: #MA.SLIP_SEQ | G40: Payment received result details sequence number | H40: 入金実績明細連番 | I40: E | J40: E
A41: 20 | D41: rcv_act_upd_cntr | E41: #MA.UPD_CNT | G41: Payment received result update counter | H41: 入金実績更新カウンタ | I41: E | J41: E
...

Sheet Upd01
A1: * | B1: * | D1: L | E1: 1
A2: * | D2: オペレーション実装仕様書 Operation Specification Implementation Sheet | E2: ModuleID : | F2: =IF(LogicCommon!C2="","",LogicCommon!C2) -> MS | G2: LogicID : | H2: =IF(LogicCommon!E2="","",LogicCommon!E2) -> MSBGL0010 | I2: Ope.ID : | J2: Upd01 | K2: Pj.ID : | L2: =IF(LogicCommon!G2="","",LogicCommon!G2) -> MC | M2: Ope.Body : | N2: "mcframe.serverMAUD.MAUDL5010.MAUDL_Operation"
A3: * | D3: =IF(LogicCommon!A3="","",LogicCommon!A3) | E3: SubModuleID : | F3: =IF(LogicCommon!C3="","",LogicCommon!C3) -> MSBG | G3: LogicClass : | H3: =IF(LogicCommon!E3="","",LogicCommon!E3) -> MSBGL_BillCl | I3: Ope.Method : | J3: Upd01 | K3: SuperClassPj.ID : | L3: =IF(LogicCommon!G3="","",LogicCommon!G3) | O3: Gene.Type : | P3: ALL
A4: * | E4: Version : | F4: 000000 | G4: LogicName : | H4: =IF(LogicCommon!E4="","",LogicCommon!E4) -> 請求締処理 | I4: Ope.Name : | J4: 登録・訂正 | K4: SuperLogicID : | L4: =IF(LogicCommon!G4="","",LogicCommon!G4) -> MS.MSUDL5010 | M4: ImplOpe.ID:
A5: * | E5: ACType :
A6: * | D6: 概要 : | E6: 締処理対象の請求情報をワークテーブルに登録し、請求締サービスを実行する。 | M6: ID | O6: ID | Q6: ID
A7: # | I7: U | K7: K | L7: o | N7: o | P7: o
A8: # | D8: ブロック名 Block Name | E8: 型 Type | G8: super/share | H8: 対象ブロック名 Target Block Name | L8: TargetName | N8: TargetName | P8: TargetName | T8: ブロック備考 Block Remarks
A9: # | D9: 項目名 Field Name | E9: 型 Type | F9: 桁 Digits | G9: フルネーム Full Name | H9: 日本語名 Japanese Name | I9: 上り項目 Request Message Field | J9: 下り項目 Response Message Field | R9: 条件および編集方法 Conditions and Editing Methods | T9: 項目備考 Field Remarks
A10: # | L10: 上り項目 Request Message Field | M10: 下り項目 Response Message Field | N10: 上り項目 Request Message Field | O10: 下り項目 Response Message Field | P10: 上り項目 Request Message Field | Q10: 下り項目 Response Message Field
A11: 10 | B11: * | D11: Upd01_Hdr | E11: L | G11: $share$ | H11: MS.MSBGL0010.Chk01.Chk01_Hdr
A12: 10 | D12: peg_no | E12: #MA.INT | G12: Pegging No. | H12: 紐付けＮＯ | I12: - | J12: -
A13: 10 | D13: err_flg | E13: #MA.FLG | G13: Error | H13: エラー | I13: - | J13: -
A14: 10 | D14: rtn_sts_typ | E14: #MA.RTN_STS_TYP | G14: Process result status type | H14: 処理結果状況区分 | I14: - | J14: E
A15: 10 | D15: bcst_cd | E15: #MA.BP_CD | G15: Billing customer cd. | H15: 請求先ＣＤ | I15: E | J15: -
A16: 10 | D16: bill_dpt_cd | E16: #MA.DPT_CD | G16: Billing dept. cd. | H16: 請求部門ＣＤ | I16: E | J16: -
A17: 10 | D17: iv_no | E17: #MA.IV_NO | G17: Invoice No. | H17: インボイスＮＯ | I17: E | J17: -
A18: 10 | D18: trd_cur_cd | E18: #MA.CUR_CD | G18: Transaction currency cd. | H18: 取引通貨ＣＤ | I18: E | J18: -
A19: 10 | D19: bill_xrate | E19: #MA.MONEY | G19: Billing exchange rate | H19: 請求為替レート | I19: E | J19: -
A20: 10 | D20: wrk_no | E20: #MA.WRK_NO | G20: Sales project No. | H20: 案件ＮＯ | I20: E | J20: -
A21: 10 | D21: inpt_bill_ym | E21: #MA.YM | G21: Input billing month | H21: 入力請求年月 | I21: E | J21: -
A22: 10 | D22: inpt_rcv_schd_dt | E22: #MA.DT | G22: Input scheduled payment receipt date | H22: 入力入金予定日 | I22: E | J22: E
A23: 10 | D23: inpt_bill_cl_day | E23: #MA.CL_DAY | G23: Input billing closing date | H23: 入力請求締日 | I23: E | J23: -
... A29: 10 | D29: rec_id | E29: #MA.INT | G29: Record ID | H29: レコードＩＤ | I29: E | J29: -
A31: 20 | B31: * | D31: Upd01_Dtl | E31: L | G31: $share$ | H31: MS.MSBGL0010.Chk01.Chk01_Dtl
A32: 20 | D32: bill_d_no | E32: #MA.BILL_NO | G32: Billing details No. | H32: 請求明細ＮＯ | I32: E | J32: -
A33: 20 | D33: bill_mtd_typ | E33: #MS.BILL_MTD_TYP | G33: Billing method type | H33: 請求方式区分 | I33: E | J33: -
A34: 20 | D34: amt | E34: #MA.MONEY | G34: Amount | H34: 金額 | I34: E | J34: -
A35: 20 | D35: tax_amt | E35: #MA.MONEY | G35: Tax amount | H35: 税額 | I35: E | J35: -
A36: 20 | D36: bill_prnt_tgt_flg | E36: #MA.FLG | G36: Invoice output | H36: 請求書出力 | I36: E | J36: -
A37: 20 | D37: rec_id | E37: #MA.INT | G37: Record ID | H37: レコードＩＤ | I37: E | J37: -
A38: 20 | D38: rcv_act_d_no | E38: #MA.RCV_ACT_D_NO | G38: Payment received result details No. | H38: 入金実績明細ＮＯ | I38: E | J38: -
A39: 20 | D39: rcv_act_d_seq | E39: #MA.SLIP_SEQ | G39: Payment received result details sequence number | H39: 入金実績明細連番 | I39: E | J39: -
A40: 20 | D40: rcv_act_upd_cntr | E40: #MA.UPD_CNT | G40: Payment received result update counter | H40: 入金実績更新カウンタ | I40: E | J40: -
A42: 30 | B42: * | D42: Upd01_Cnd | E42: R
A43: 30 | D43: indiv_prnt_flg | E43: #MA.FLG | G43: Individual issue | H43: 個別発行 | I43: E | J43: -
D44: 詳細 :

Sheet Chk02
A1: * | B1: * | D1: L | E1: 1
A2: * | D2: オペレーション実装仕様書 Operation Specification Implementation Sheet | E2: ModuleID : | F2: =IF(LogicCommon!C2="","",LogicCommon!C2) -> MS | G2: LogicID : | H2: =IF(LogicCommon!E2="","",LogicCommon!E2) -> MSBGL0010 | I2: Ope.ID : | J2: Chk02 | K2: Pj.ID : | L2: =IF(LogicCommon!G2="","",LogicCommon!G2) -> MC | M2: Ope.Body : | N2: MA.MAUDL5010.Checker
A3: * | D3: =IF(LogicCommon!A3="","",LogicCommon!A3) | E3: SubModuleID : | F3: =IF(LogicCommon!C3="","",LogicCommon!C3) -> MSBG | G3: LogicClass : | H3: =IF(LogicCommon!E3="","",LogicCommon!E3) -> MSBGL_BillCl | I3: Ope.Method : | J3: Chk02 | K3: SuperClassPj.ID : | L3: =IF(LogicCommon!G3="","",LogicCommon!G3) | O3: Gene.Type : | P3: ALL
A4: * | E4: Version : | F4: 000000 | G4: LogicName : | H4: =IF(LogicCommon!E4="","",LogicCommon!E4) -> 請求締処理 | I4: Ope.Name : | J4: 取消前チェック | K4: SuperLogicID : | L4: =IF(LogicCommon!G4="","",LogicCommon!G4) -> MS.MSUDL5010 | M4: ImplOpe.ID:
A5: * | E5: ACType :
A6: * | D6: 概要 : | E6: 締解除時の各種チェックを行う。 | R6: ID | T6: ID | V6: ID
A7: # | I7: U | K7: K | L7: K | M7: K | N7: K | O7: K | P7: K | Q7: o | S7: o | U7: o
A8: # | D8: ブロック名 Block Name | E8: 型 Type | G8: super/share | H8: 対象ブロック名 Target Block Name | K8: REQ_UPD_CNT_CHK | L8: LIST_LOGIC | M8: LIST_OUT | N8: LIST_OUT_BASE | O8: LIST_IN | P8: LIST_IN_BASE | Q8: TargetName | S8: TargetName | U8: TargetName | Y8: ブロック備考 Block Remarks
A9: # | D9: 項目名 Field Name | E9: 型 Type | F9: 桁 Digits | G9: フルネーム Full Name | H9: 日本語名 Japanese Name | I9: 上り項目 Request Message Field | J9: 下り項目 Response Message Field | W9: 条件および編集方法 Conditions and Editing Methods | Y9: 項目備考 Field Remarks
A10: # | Q10: 上り項目 Request Message Field | R10: 下り項目 Response Message Field | S10: 上り項目 Request Message Field | T10: 下り項目 Response Message Field | U10: 上り項目 Request Message Field | V10: 下り項目 Response Message Field
A11: 10 | B11: * | D11: Chk02_Hdr | E11: L
A12: 10 | D12: peg_no | E12: #MA.INT | G12: Pegging No. | H12: 紐付けＮＯ | I12: E | J12: E
A13: 10 | D13: err_flg | E13: #MA.FLG | G13: Error | H13: エラー | I13: - | J13: -
A14: 10 | D14: bill_mng_no | E14: #MA.BILL_MNG_NO | G14: Billing management No. | H14: 請求管理ＮＯ | I14: E | J14: E | K14: E
A15: 10 | D15: upd_cntr | E15: #MA.UPD_CNT | G15: Update counter | H15: 更新カウンタ | I15: E | J15: E | K15: E
A16: 10 | D16: bill_dpt_cd | E16: #MA.DPT_CD | G16: Billing dept. cd. | H16: 請求部門ＣＤ | I16: - | J16: -
A17: 10 | D17: rtn_sts_typ | E17: #MA.RTN_STS_TYP | G17: Process result status type | H17: 処理結果状況区分 | I17: - | J17: E
D18: 詳細 :

Sheet Del01
A1: * | B1: * | D1: L | E1: 1
A2: * | D2: オペレーション実装仕様書 Operation Specification Implementation Sheet | E2: ModuleID : | F2: =IF(LogicCommon!C2="","",LogicCommon!C2) -> MS | G2: LogicID : | H2: =IF(LogicCommon!E2="","",LogicCommon!E2) -> MSBGL0010 | I2: Ope.ID : | J2: Del01 | K2: Pj.ID : | L2: =IF(LogicCommon!G2="","",LogicCommon!G2) -> MC | M2: Ope.Body : | N2: "mcframe.serverMAUD.MAUDL5010.MAUDL_Operation"
A3: * | D3: =IF(LogicCommon!A3="","",LogicCommon!A3) | E3: SubModuleID : | F3: =IF(LogicCommon!C3="","",LogicCommon!C3) -> MSBG | G3: LogicClass : | H3: =IF(LogicCommon!E3="","",LogicCommon!E3) -> MSBGL_BillCl | I3: Ope.Method : | J3: Del01 | K3: SuperClassPj.ID : | L3: =IF(LogicCommon!G3="","",LogicCommon!G3) | O3: Gene.Type : | P3: ALL
A4: * | E4: Version : | F4: 000000 | G4: LogicName : | H4: =IF(LogicCommon!E4="","",LogicCommon!E4) -> 請求締処理 | I4: Ope.Name : | J4: 取消前 | K4: SuperLogicID : | L4: =IF(LogicCommon!G4="","",LogicCommon!G4) -> MS.MSUDL5010 | M4: ImplOpe.ID:
A5: * | E5: ACType :
A6: * | D6: 概要 : | E6: 請求締サービスを実行する。 | M6: ID | O6: ID | Q6: ID
A7: # | I7: U | K7: K | L7: o | N7: o | P7: o
A8: # | D8: ブロック名 Block Name | E8: 型 Type | G8: super/share | H8: 対象ブロック名 Target Block Name | L8: TargetName | N8: TargetName | P8: TargetName | T8: ブロック備考 Block Remarks
A9: # | D9: 項目名 Field Name | E9: 型 Type | F9: 桁 Digits | G9: フルネーム Full Name | H9: 日本語名 Japanese Name | I9: 上り項目 Request Message Field | J9: 下り項目 Response Message Field | R9: 条件および編集方法 Conditions and Editing Methods | T9: 項目備考 Field Remarks
A10: # | L10: 上り項目 Request Message Field | M10: 下り項目 Response Message Field | N10: 上り項目 Request Message Field | O10: 下り項目 Response Message Field | P10: 上り項目 Request Message Field | Q10: 下り項目 Response Message Field
A11: 10 | B11: * | D11: Del01_Hdr | E11: L | G11: $share$ | H11: MS.MSBGL0010.Chk02.Chk02_Hdr
A12: 10 | D12: peg_no | E12: #MA.INT | G12: Pegging No. | H12: 紐付けＮＯ | I12: - | J12: -
A13: 10 | D13: err_flg | E13: #MA.FLG | G13: Error | H13: エラー | I13: - | J13: -
A14: 10 | D14: bill_mng_no | E14: #MA.BILL_MNG_NO | G14: Billing management No. | H14: 請求管理ＮＯ | I14: E | J14: -
A15: 10 | D15: upd_cntr | E15: #MA.UPD_CNT | G15: Update counter | H15: 更新カウンタ | I15: E | J15: -
A16: 10 | D16: rtn_sts_typ | E16: #MA.RTN_STS_TYP | G16: Process result status type | H16: 処理結果状況区分 | I16: - | J16: E
D17: 詳細 :

Sheet 来歴
A1: 変更来歴
A3: Rev. | H3: 修正番号 | O3: 変更内容 | AQ3: 変更箇所
A4: 1 | O4: 初版
A5: 1.1 | O5: 英語の名称を追記 | AQ5: 全般
