Workbook

Sheet LogicCommon
A2: ロジック共通定義 | B2: ModuleID : | C2: MB | D2: LogicID : | E2: MBBAL5030 | F2: Pj.ID : | G2: MC
B3: SubModuleID : | C3: MBBA | D3: LogicClass : | E3: MBBAL_AprvRegService | F3: SuperClassPj.ID :
D4: LogicName : | E4: 承認一覧登録サービス | F4: SuperLogicID : | G4: MB.MBUDL5010
A5: 概要 :
A6: 詳細 :

Sheet Aprv_Srch01
A1: * | B1: * | D1: L | E1: 1
A2: * | D2: オペレーション実装仕様書 Operation Specification Implementation Sheet | E2: ModuleID : | F2: =IF(LogicCommon!C2="","",LogicCommon!C2) -> MB | G2: LogicID : | H2: =IF(LogicCommon!E2="","",LogicCommon!E2) -> MBBAL5030 | I2: Ope.ID : | J2: Aprv_Srch01 | K2: Pj.ID : | L2: =IF(LogicCommon!G2="","",LogicCommon!G2) -> MC | M2: Ope.Body : | N2: "mcframe.serverMAUD.MAUDL5010.MAUDL_Searcher"
A3: * | E3: SubModuleID : | F3: =IF(LogicCommon!C3="","",LogicCommon!C3) -> MBBA | G3: LogicClass : | H3: =IF(LogicCommon!E3="","",LogicCommon!E3) -> MBBAL_AprvRegService | I3: Ope.Method : | J3: Aprv_Srch01 | K3: SuperClassPj.ID : | L3: =IF(LogicCommon!G3="","",LogicCommon!G3) | M3: ReportID : | O3: Gene.Type : | P3: ALL
A4: * | E4: Version : | F4: 000000 | G4: LogicName : | H4: =IF(LogicCommon!E4="","",LogicCommon!E4) -> 承認一覧登録サービス | I4: Ope.Name : | J4: 検索 | K4: SuperLogicID : | L4: =IF(LogicCommon!G4="","",LogicCommon!G4) -> MB.MBUDL5010
A5: * | E5: ACType :
A6: * | D6: 概要 : | E6: 承認情報を検索する。 | N6: ID
A7: # | I7: U | K7: K | M7: o
A8: # | D8: ブロック名 Block Name | E8: 型 Type | G8: super/share | H8: 対象ブロック名 Target Block Name | K8: CONST | M8: TargetName | Q8: ブロック備考 Block Remarks
A9: # | D9: 項目名 Field Name | E9: 型 Type | F9: 桁 Digits | G9: フルネーム Full Name | H9: 日本語名 Japanese Name | I9: 上り項目 Request Message Field | J9: 下り項目 Response Message Field | O9: 条件および編集方法 Conditions and Editing Methods | Q9: 項目備考 Field Remarks
A10: # | M10: 上り項目 Request Message Field | N10: 下り項目 Response Message Field
A11: 10 | B11: * | D11: Aprv_Srch01_Cnd1 | E11: R
A12: 10 | D12: aprv_func_typ | E12: #MA.APRV_FUNC_TYP | G12: Approval function type | H12: 承認機能区分 | I12: E | J12: -
A13: 10 | D13: aprv_no | E13: #MA.APRV_NO | G13: Approval No. | H13: 承認ＮＯ | I13: E | J13: -
A14: 10 | D14: aprv_src_no1 | E14: #MA.APRV_SRC_NO | G14: Approval creating source No. 1 | H14: 承認作成元ＮＯ１ | I14: E | J14: -
A15: 10 | D15: aprv_src_no2 | E15: #MA.APRV_SRC_NO | G15: Approval creating source No. 2 | H15: 承認作成元ＮＯ２ | I15: E | J15: -
A16: 10 | D16: aprv_d_sts_typ | E16: #MA.APRV_D_STS_TYP | G16: Approval details status type | H16: 承認明細状況区分 | I16: E | J16: -
A17: 10 | D17: ins_dt_fr | E17: #MA.DT | G17: Entry date FROM | H17: 登録日ＦＲＯＭ | I17: E | J17: -
A18: 10 | D18: ins_dt_to | E18: #MA.DT | G18: Entry date TO | H18: 登録日ＴＯ | I18: E | J18: -
A19: 10 | D19: aprv_d_tm_fr | E19: #MA.TM | G19: Approval date and time FROM | H19: 承認日時ＦＲＯＭ | I19: E | J19: -
A20: 10 | D20: aprv_d_tm_to | E20: #MA.TM | G20: Approval date and time TO | H20: 承認日時ＴＯ | I20: E | J20: -
A21: 10 | D21: ins_biz_usr_cd | E21: #MA.USR_CD | G21: Entry/business PIC cd. | H21: 登録／業務担当者ＣＤ | I21: E | J21: -
A22: 10 | D22: ins_biz_usr_nm | E22: #MA.USR_NM | G22: Entry/business PIC name | H22: 登録／業務担当者名 | I22: E | J22: -
A23: 10 | D23: aprv_usr_cd | E23: #MA.USR_CD | G23: Approver cd. | H23: 承認担当者ＣＤ | I23: E | J23: -
... A29: 10 | D29: usr_dtl_flg_str | E29: #MA.FLG_STR | G29: Including PIC details | H29: 担当者詳細含む | I29: - | J29: -
M30: 上り項目 Request Message Field | N30: 下り項目 Response Message Field
A31: 20 | B31: * | D31: Aprv_Srch01_Dtl1 | E31: L
A32: 20 | D32: aprv_no | E32: #MA.APRV_NO | G32: Approval No. | H32: 承認ＮＯ | I32: - | J32: E
A33: 20 | D33: aprv_no_seq | E33: #MA.APRV_NO_SEQ | G33: Approval sequence number | H33: 承認ＮＯ連番 | I33: - | J33: E
A34: 20 | D34: next_opr_flg | E34: #MA.FLG | G34: Next completed process | H34: 次処理済 | I34: - | J34: E
A35: 20 | D35: ins_dt | E35: #MA.DT | G35: Entry date | H35: 登録日 | I35: - | J35: E
A36: 20 | D36: biz_usr_cd | E36: #MA.USR_CD | G36: Business PIC cd. | H36: 業務担当者ＣＤ | I36: - | J36: E
A37: 20 | D37: biz_usr_nm | E37: #MA.USR_NM | G37: Business PIC name | H37: 業務担当者名 | I37: - | J37: E
A38: 20 | D38: src_ins_usr_cd | E38: #MA.USR_CD | G38: Entry PIC cd. | H38: 登録担当者ＣＤ | I38: - | J38: E
A39: 20 | D39: src_ins_usr_nm | E39: #MA.USR_NM | G39: Entry PIC name | H39: 登録担当者名 | I39: - | J39: E
A40: 20 | D40: aprv_sts_typ | E40: #MA.APRV_STS_TYP | G40: Approval status type | H40: 承認状況区分 | I40: - | J40: E | K40: MAC_APRV_STS_TYP
A41: 20 | D41: aprv_sts_typ_nm | E41: #MA.APRV_STS_TYP_NM | G41: Approval status type name | H41: 承認状況区分名 | I41: - | J41: E
A42: 20 | D42: aprv_func_typ | E42: #MA.APRV_FUNC_TYP | G42: Approval function type | H42: 承認機能区分 | I42: - | J42: E | K42: MAC_APRV_FUNC_TYP
A43: 20 | D43: aprv_func_typ_nm | E43: #MA.APRV_FUNC_TYP_NM | G43: Approval function type name | H43: 承認機能区分名 | I43: - | J43: E
A44: 20 | D44: src_itm_cd | E44: #MA.ITM_CD | G44: Approval creating source item cd. | H44: 承認作成元品目ＣＤ | I44: - | J44: E
A45: 20 | D45: src_itm_sub1 | E45: #MA.ITM_SUB1 | G45: Approval creating source branch No. 1 | H45: 承認作成元枝番１ | I45: - | J45: E
...

Sheet Aprv_Srch02
A1: * | B1: * | D1: L | E1: 1
A2: * | D2: オペレーション実装仕様書 Operation Specification Implementation Sheet | E2: ModuleID : | F2: =IF(LogicCommon!C2="","",LogicCommon!C2) -> MB | G2: LogicID : | H2: =IF(LogicCommon!E2="","",LogicCommon!E2) -> MBBAL5030 | I2: Ope.ID : | J2: Aprv_Srch02 | K2: Pj.ID : | L2: =IF(LogicCommon!G2="","",LogicCommon!G2) -> MC | M2: Ope.Body : | N2: "mcframe.serverMAUD.MAUDL5010.MAUDL_Searcher"
A3: * | E3: SubModuleID : | F3: =IF(LogicCommon!C3="","",LogicCommon!C3) -> MBBA | G3: LogicClass : | H3: =IF(LogicCommon!E3="","",LogicCommon!E3) -> MBBAL_AprvRegService | I3: Ope.Method : | J3: Aprv_Srch02 | K3: SuperClassPj.ID : | L3: =IF(LogicCommon!G3="","",LogicCommon!G3) | M3: ReportID : | O3: Gene.Type : | P3: ALL
A4: * | E4: Version : | F4: 000000 | G4: LogicName : | H4: =IF(LogicCommon!E4="","",LogicCommon!E4) -> 承認一覧登録サービス | I4: Ope.Name : | J4: 検索 | K4: SuperLogicID : | L4: =IF(LogicCommon!G4="","",LogicCommon!G4) -> MB.MBUDL5010
A5: * | E5: ACType :
A6: * | D6: 概要 : | E6: 承認状況を検索する。 | L6: ID
A7: # | I7: U | K7: o | L7: AP.so01
A8: # | D8: ブロック名 Block Name | E8: 型 Type | G8: super/share | H8: 対象ブロック名 Target Block Name | K8: TargetName | L8: OPE.MB.MBBAL0010.Srch01 | O8: ブロック備考 Block Remarks
A9: # | D9: 項目名 Field Name | E9: 型 Type | F9: 桁 Digits | G9: フルネーム Full Name | H9: 日本語名 Japanese Name | I9: 上り項目 Request Message Field | J9: 下り項目 Response Message Field | M9: 条件および編集方法 Conditions and Editing Methods | O9: 項目備考 Field Remarks
A10: # | K10: 上り項目 Request Message Field | L10: 下り項目 Response Message Field
A11: 10 | B11: * | D11: Aprv_Srch02_Cnd1 | E11: R | K11: Srch01_Cnd1
A12: 10 | D12: aprv_func_typ | E12: #MA.APRV_FUNC_TYP | G12: Approval function type | H12: 承認機能区分 | I12: E | J12: - | K12: E
A13: 10 | D13: aprv_no | E13: #MA.APRV_NO | G13: Approval No. | H13: 承認ＮＯ | I13: E | J13: - | K13: E
A14: 10 | D14: aprv_src_no1 | E14: #MA.APRV_SRC_NO | G14: Approval creating source No. 1 | H14: 承認作成元ＮＯ１ | I14: E | J14: - | K14: E
A15: 10 | D15: aprv_src_no2 | E15: #MA.APRV_SRC_NO | G15: Approval creating source No. 2 | H15: 承認作成元ＮＯ２ | I15: E | J15: - | K15: E
A16: 10 | D16: aprv_sts_typ | E16: #MA.APRV_STS_TYP | G16: Approval status type | H16: 承認状況区分 | I16: E | J16: - | K16: E
A17: 10 | D17: ins_dt_fr | E17: #MA.DT | G17: Entry date FROM | H17: 登録日ＦＲＯＭ | I17: E | J17: - | K17: E
A18: 10 | D18: ins_dt_to | E18: #MA.DT | G18: Entry date TO | H18: 登録日ＴＯ | I18: E | J18: - | K18: E
A19: 10 | D19: ins_biz_usr_cd | E19: #MA.USR_CD | G19: Entry/business PIC cd. | H19: 登録／業務担当者ＣＤ | I19: E | J19: - | K19: E
A20: 10 | D20: ins_biz_usr_nm | E20: #MA.USR_NM | G20: Entry/business PIC name | H20: 登録／業務担当者名 | I20: E | J20: - | K20: E
A21: 10 | D21: usr_dtl_flg | E21: #MA.FLG | G21: Including PIC details | H21: 担当者詳細含む | I21: E | J21: - | K21: E
K22: 上り項目 Request Message Field | L22: 下り項目 Response Message Field
A23: 20 | B23: * | D23: Aprv_Srch02_Hdr1 | E23: L | L23: Srch01_Hdr1
A24: 20 | D24: aprv_no | E24: #MA.APRV_NO | G24: Approval No. | H24: 承認ＮＯ | I24: - | J24: E | L24: E
A25: 20 | D25: aprv_no_seq | E25: #MA.APRV_NO_SEQ | G25: Approval sequence number | H25: 承認ＮＯ連番 | I25: - | J25: E | L25: E
A26: 20 | D26: aprv_sts_typ | E26: #MA.APRV_STS_TYP | G26: Approval status type | H26: 承認状況区分 | I26: - | J26: E | L26: E
A27: 20 | D27: aprv_sts_typ_nm | E27: #MA.APRV_STS_TYP_NM | G27: Approval status type name | H27: 承認状況区分名 | I27: - | J27: E | L27: E
A28: 20 | D28: last_aprv_usr_cd | E28: #MA.USR_CD | G28: Final approver cd. | H28: 最終承認者ＣＤ | I28: - | J28: E | L28: E
A29: 20 | D29: last_aprv_usr_nm | E29: #MA.USR_NM | G29: Final approver name | H29: 最終承認者名 | I29: - | J29: E | L29: E
A30: 20 | D30: last_aprv_tm | E30: #MA.TM | G30: Final approver date and time | H30: 最終承認日時 | I30: - | J30: E | L30: E
A31: 20 | D31: ins_dt | E31: #MA.DT | G31: Entry date | H31: 登録日 | I31: - | J31: E | L31: E
A32: 20 | D32: biz_usr_cd | E32: #MA.USR_CD | G32: Business PIC cd. | H32: 業務担当者ＣＤ | I32: - | J32: E | L32: E
A33: 20 | D33: biz_usr_nm | E33: #MA.USR_NM | G33: Business PIC name | H33: 業務担当者名 | I33: - | J33: E | L33: E
A34: 20 | D34: src_ins_usr_cd | E34: #MA.USR_CD | G34: Entry PIC cd. | H34: 登録担当者ＣＤ | I34: - | J34: E | L34: E
A35: 20 | D35: src_ins_usr_nm | E35: #MA.USR_NM | G35: Entry PIC name | H35: 登録担当者名 | I35: - | J35: E | L35: E
... A71: 20 | D71: upd_srv_req_no | E71: #MA.SRV_REQ_NO | G71: Update request No. (Header) | H71: 更新リクエストＮＯ（ヘッダ） | I71: - | J71: E | L71: E
K72: 上り項目 Request Message Field | L72: 下り項目 Response Message Field
A73: 30 | B73: * | D73: Aprv_Srch02_Dtl1 | E73: L | L73: Srch01_Dtl1
A74: 30 | D74: hdr | E74: R | F74: MB.MBBAL5030.Aprv_Srch02.Aprv_Srch02_Hdr1
A75: 30 | D75: hdr.aprv_no# | E75: RI | G75: Approval No. | H75: 承認ＮＯ | I75: - | J75: E | L75: E
...

Sheet Aprv_Chk01
A1: * | B1: * | D1: L | E1: 1
A2: * | D2: オペレーション実装仕様書 Operation Specification Implementation Sheet | E2: ModuleID : | F2: =IF(LogicCommon!C2="","",LogicCommon!C2) -> MB | G2: LogicID : | H2: =IF(LogicCommon!E2="","",LogicCommon!E2) -> MBBAL5030 | I2: Ope.ID : | J2: Aprv_Chk01 | K2: Pj.ID : | L2: =IF(LogicCommon!G2="","",LogicCommon!G2) -> MC | M2: Ope.Body : | N2: MA.MAUDL5010.Checker
A3: * | E3: SubModuleID : | F3: =IF(LogicCommon!C3="","",LogicCommon!C3) -> MBBA | G3: LogicClass : | H3: =IF(LogicCommon!E3="","",LogicCommon!E3) -> MBBAL_AprvRegService | I3: Ope.Method : | J3: Aprv_Chk01 | K3: SuperClassPj.ID : | L3: =IF(LogicCommon!G3="","",LogicCommon!G3) | M3: ReportID : | O3: Gene.Type : | P3: ALL
A4: * | E4: Version : | F4: 000000 | G4: LogicName : | H4: =IF(LogicCommon!E4="","",LogicCommon!E4) -> 承認一覧登録サービス | I4: Ope.Name : | J4: 承認または却下前チェック | K4: SuperLogicID : | L4: =IF(LogicCommon!G4="","",LogicCommon!G4) -> MB.MBUDL5010
A5: * | E5: ACType :
A6: * | D6: 概要 : | E6: 承認または却下する際のチェックを行う。 | P6: ID
A7: # | I7: U | K7: K | L7: K | M7: K | O7: o
A8: # | D8: ブロック名 Block Name | E8: 型 Type | G8: super/share | H8: 対象ブロック名 Target Block Name | K8: REQUIRED | L8: CONST | M8: DUPLICATE | O8: TargetName | S8: ブロック備考 Block Remarks
A9: # | D9: 項目名 Field Name | E9: 型 Type | F9: 桁 Digits | G9: フルネーム Full Name | H9: 日本語名 Japanese Name | I9: 上り項目 Request Message Field | J9: 下り項目 Response Message Field | Q9: 条件および編集方法 Conditions and Editing Methods | S9: 項目備考 Field Remarks
A10: # | O10: 上り項目 Request Message Field | P10: 下り項目 Response Message Field
A11: 10 | B11: * | D11: Aprv_Chk01_Rslt1 | E11: L
A12: 10 | D12: aprv_no | E12: #MA.APRV_NO | G12: Approval No. | H12: 承認ＮＯ | I12: E | J12: E | K12: E | M12: APRV_D
A13: 10 | D13: aprv_no_seq | E13: #MA.APRV_NO_SEQ | G13: Approval sequence number | H13: 承認ＮＯ連番 | I13: E | J13: E | K13: E | M13: APRV_D
A14: 10 | D14: aprv_role_cd | E14: #MA.APRV_ROLE_CD | G14: Approval role cd. | H14: 承認役割ＣＤ | I14: E | J14: E | K14: E | M14: APRV_D
A15: 10 | D15: aprv_usr_cd | E15: #MA.USR_CD | G15: Main PIC cd. | H15: 主担当者ＣＤ | I15: E | J15: E | K15: E | M15: APRV_D
A16: 10 | D16: aprv_d_sts_typ | E16: #MA.APRV_D_STS_TYP | G16: Approval details status type | H16: 承認明細状況区分 | I16: E | J16: E
A17: 10 | D17: act_usr_cd | E17: #MA.USR_CD | G17: Approval executor cd. | H17: 承認実行者ＣＤ | I17: - | J17: E
A18: 10 | D18: aprv_d_rmrks | E18: #MA.APRV_D_RMRKS | G18: Approval details remarks | H18: 承認明細備考 | I18: E | J18: E
A19: 10 | D19: sub_char1 | E19: #MA.APRV_D_SUB_CHAR1 | G19: Approval details spare 1 | H19: 承認明細予備１ | I19: E | J19: E
A20: 10 | D20: sub_char2 | E20: #MA.APRV_D_SUB_CHAR2 | G20: Approval details spare 2 | H20: 承認明細予備２ | I20: E | J20: E
A21: 10 | D21: sub_char3 | E21: #MA.APRV_D_SUB_CHAR3 | G21: Approval details spare 3 | H21: 承認明細予備３ | I21: E | J21: E
A22: 10 | D22: upd_cntr | E22: #MA.UPD_CNT | G22: Update counter | H22: 更新カウンタ | I22: E | J22: E
A23: 10 | D23: upd_cntr_chk_flg | E23: #MA.FLG | G23: Check for update counter flg. | H23: 更新カウンタチェックＦＬＧ | I23: E | J23: E
A24: 10 | D24: peg_no | E24: #MA.INT | G24: Pegging No. | H24: 紐付けＮＯ | I24: E | J24: E
A25: 10 | D25: err_flg | E25: #MA.FLG | G25: Error flg. | H25: エラーＦＬＧ | I25: - | J25: E
D26: 詳細 :

Sheet Aprv_Upd01
A1: * | B1: * | D1: L | E1: 1
A2: * | D2: オペレーション実装仕様書 Operation Specification Implementation Sheet | E2: ModuleID : | F2: =IF(LogicCommon!C2="","",LogicCommon!C2) -> MB | G2: LogicID : | H2: =IF(LogicCommon!E2="","",LogicCommon!E2) -> MBBAL5030 | I2: Ope.ID : | J2: Aprv_Upd01 | K2: Pj.ID : | L2: =IF(LogicCommon!G2="","",LogicCommon!G2) -> MC | M2: Ope.Body :
A3: * | E3: SubModuleID : | F3: =IF(LogicCommon!C3="","",LogicCommon!C3) -> MBBA | G3: LogicClass : | H3: =IF(LogicCommon!E3="","",LogicCommon!E3) -> MBBAL_AprvRegService | I3: Ope.Method : | J3: Aprv_Upd01 | K3: SuperClassPj.ID : | L3: =IF(LogicCommon!G3="","",LogicCommon!G3) | M3: ReportID : | O3: Gene.Type : | P3: ALL
A4: * | E4: Version : | F4: 000000 | G4: LogicName : | H4: =IF(LogicCommon!E4="","",LogicCommon!E4) -> 承認一覧登録サービス | I4: Ope.Name : | J4: 承認または却下 | K4: SuperLogicID : | L4: =IF(LogicCommon!G4="","",LogicCommon!G4) -> MB.MBUDL5010
A5: * | E5: ACType :
A6: * | D6: 概要 : | E6: 承認または却下する。 | L6: ID
A7: # | I7: U | K7: o
A8: # | D8: ブロック名 Block Name | E8: 型 Type | G8: super/share | H8: 対象ブロック名 Target Block Name | K8: TargetName | O8: ブロック備考 Block Remarks
A9: # | D9: 項目名 Field Name | E9: 型 Type | F9: 桁 Digits | G9: フルネーム Full Name | H9: 日本語名 Japanese Name | I9: 上り項目 Request Message Field | J9: 下り項目 Response Message Field | M9: 条件および編集方法 Conditions and Editing Methods | O9: 項目備考 Field Remarks
A10: # | K10: 上り項目 Request Message Field | L10: 下り項目 Response Message Field
A11: 10 | B11: * | D11: Aprv_Upd01_Dtl1 | E11: L | G11: $share$ | H11: MB.MBBAL5030.Aprv_Chk01.Aprv_Chk01_Rslt1
A12: 10 | D12: aprv_no | E12: #MA.APRV_NO | G12: Approval No. | H12: 承認ＮＯ | I12: E | J12: -
A13: 10 | D13: aprv_no_seq | E13: #MA.APRV_NO_SEQ | G13: Approval sequence number | H13: 承認ＮＯ連番 | I13: E | J13: -
A14: 10 | D14: aprv_role_cd | E14: #MA.APRV_ROLE_CD | G14: Approval role cd. | H14: 承認役割ＣＤ | I14: E | J14: -
A15: 10 | D15: aprv_usr_cd | E15: #MA.USR_CD | G15: Main PIC cd. | H15: 主担当者ＣＤ | I15: E | J15: -
A16: 10 | D16: aprv_d_sts_typ | E16: #MA.APRV_D_STS_TYP | G16: Approval details status type | H16: 承認明細状況区分 | I16: E | J16: -
A17: 10 | D17: act_usr_cd | E17: #MA.USR_CD | G17: Approval executor cd. | H17: 承認実行者ＣＤ | I17: E | J17: -
A18: 10 | D18: aprv_d_rmrks | E18: #MA.APRV_D_RMRKS | G18: Approval details remarks | H18: 承認明細備考 | I18: E | J18: -
A19: 10 | D19: sub_char1 | E19: #MA.APRV_D_SUB_CHAR1 | G19: Approval details spare 1 | H19: 承認明細予備１ | I19: E | J19: -
A20: 10 | D20: sub_char2 | E20: #MA.APRV_D_SUB_CHAR2 | G20: Approval details spare 2 | H20: 承認明細予備２ | I20: E | J20: -
A21: 10 | D21: sub_char3 | E21: #MA.APRV_D_SUB_CHAR3 | G21: Approval details spare 3 | H21: 承認明細予備３ | I21: E | J21: -
A22: 10 | D22: upd_cntr | E22: #MA.UPD_CNT | G22: Update counter | H22: 更新カウンタ | I22: E | J22: -
A23: 10 | D23: upd_cntr_chk_flg | E23: #MA.FLG | G23: Check for update counter flg. | H23: 更新カウンタチェックＦＬＧ | I23: E | J23: -
... A25: 10 | D25: err_flg | E25: #MA.FLG | G25: Error flg. | H25: エラーＦＬＧ | I25: - | J25: E
D26: 詳細 :

Sheet Aprv_Chk02
A1: * | B1: * | D1: L | E1: 1
A2: * | D2: オペレーション実装仕様書 Operation Specification Implementation Sheet | E2: ModuleID : | F2: =IF(LogicCommon!C2="","",LogicCommon!C2) -> MB | G2: LogicID : | H2: =IF(LogicCommon!E2="","",LogicCommon!E2) -> MBBAL5030 | I2: Ope.ID : | J2: Aprv_Chk02 | K2: Pj.ID : | L2: =IF(LogicCommon!G2="","",LogicCommon!G2) -> MC | M2: Ope.Body : | N2: MA.MAUDL5010.Checker
A3: * | E3: SubModuleID : | F3: =IF(LogicCommon!C3="","",LogicCommon!C3) -> MBBA | G3: LogicClass : | H3: =IF(LogicCommon!E3="","",LogicCommon!E3) -> MBBAL_AprvRegService | I3: Ope.Method : | J3: Aprv_Chk02 | K3: SuperClassPj.ID : | L3: =IF(LogicCommon!G3="","",LogicCommon!G3) | M3: ReportID : | O3: Gene.Type : | P3: ALL
A4: * | E4: Version : | F4: 000000 | G4: LogicName : | H4: =IF(LogicCommon!E4="","",LogicCommon!E4) -> 承認一覧登録サービス | I4: Ope.Name : | J4: 取消前チェック | K4: SuperLogicID : | L4: =IF(LogicCommon!G4="","",LogicCommon!G4) -> MB.MBUDL5010
A5: * | E5: ACType :
A6: * | D6: 概要 : | E6: 承認または却下を取り消す際のチェックを行う。 | O6: ID
A7: # | I7: U | K7: K | L7: K | N7: o
A8: # | D8: ブロック名 Block Name | E8: 型 Type | G8: super/share | H8: 対象ブロック名 Target Block Name | K8: REQUIRED | L8: DUPLICATE | N8: TargetName | R8: ブロック備考 Block Remarks
A9: # | D9: 項目名 Field Name | E9: 型 Type | F9: 桁 Digits | G9: フルネーム Full Name | H9: 日本語名 Japanese Name | I9: 上り項目 Request Message Field | J9: 下り項目 Response Message Field | P9: 条件および編集方法 Conditions and Editing Methods | R9: 項目備考 Field Remarks
A10: # | N10: 上り項目 Request Message Field | O10: 下り項目 Response Message Field
A11: 10 | B11: * | D11: Aprv_Chk02_Rslt1 | E11: L | G11: $share$ | H11: MB.MBBAL5030.Aprv_Chk01.Aprv_Chk01_Rslt1
A12: 10 | D12: aprv_no | E12: #MA.APRV_NO | G12: Approval No. | H12: 承認ＮＯ | I12: E | J12: E | K12: E | L12: APRV_D
A13: 10 | D13: aprv_no_seq | E13: #MA.APRV_NO_SEQ | G13: Approval sequence number | H13: 承認ＮＯ連番 | I13: E | J13: E | K13: E | L13: APRV_D
A14: 10 | D14: aprv_role_cd | E14: #MA.APRV_ROLE_CD | G14: Approval role cd. | H14: 承認役割ＣＤ | I14: E | J14: E | K14: E | L14: APRV_D
A15: 10 | D15: aprv_usr_cd | E15: #MA.USR_CD | G15: Main PIC cd. | H15: 主担当者ＣＤ | I15: E | J15: E | K15: E | L15: APRV_D
A16: 10 | D16: aprv_d_sts_typ | E16: #MA.APRV_D_STS_TYP | G16: Approval details status type | H16: 承認明細状況区分 | I16: - | J16: E
A17: 10 | D17: act_usr_cd | E17: #MA.USR_CD | G17: Approval executor cd. | H17: 承認実行者ＣＤ | I17: - | J17: -
A18: 10 | D18: aprv_d_rmrks | E18: #MA.APRV_D_RMRKS | G18: Approval details remarks | H18: 承認明細備考 | I18: E | J18: E
A19: 10 | D19: sub_char1 | E19: #MA.APRV_D_SUB_CHAR1 | G19: Approval details spare 1 | H19: 承認明細予備１ | I19: E | J19: E
A20: 10 | D20: sub_char2 | E20: #MA.APRV_D_SUB_CHAR2 | G20: Approval details spare 2 | H20: 承認明細予備２ | I20: E | J20: E
A21: 10 | D21: sub_char3 | E21: #MA.APRV_D_SUB_CHAR3 | G21: Approval details spare 3 | H21: 承認明細予備３ | I21: E | J21: E
A22: 10 | D22: upd_cntr | E22: #MA.UPD_CNT | G22: Update counter | H22: 更新カウンタ | I22: E | J22: E
A23: 10 | D23: upd_cntr_chk_flg | E23: #MA.FLG | G23: Check for update counter flg. | H23: 更新カウンタチェックＦＬＧ | I23: E | J23: E
A24: 10 | D24: peg_no | E24: #MA.INT | G24: Pegging No. | H24: 紐付けＮＯ | I24: E | J24: E
A25: 10 | D25: err_flg | E25: #MA.FLG | G25: Error flg. | H25: エラーＦＬＧ | I25: - | J25: E
D26: 詳細 :

Sheet Aprv_Upd02
A1: * | B1: * | D1: L | E1: 1
A2: * | D2: オペレーション実装仕様書 Operation Specification Implementation Sheet | E2: ModuleID : | F2: =IF(LogicCommon!C2="","",LogicCommon!C2) -> MB | G2: LogicID : | H2: =IF(LogicCommon!E2="","",LogicCommon!E2) -> MBBAL5030 | I2: Ope.ID : | J2: Aprv_Upd02 | K2: Pj.ID : | L2: =IF(LogicCommon!G2="","",LogicCommon!G2) -> MC | M2: Ope.Body :
A3: * | E3: SubModuleID : | F3: =IF(LogicCommon!C3="","",LogicCommon!C3) -> MBBA | G3: LogicClass : | H3: =IF(LogicCommon!E3="","",LogicCommon!E3) -> MBBAL_AprvRegService | I3: Ope.Method : | J3: Aprv_Upd02 | K3: SuperClassPj.ID : | L3: =IF(LogicCommon!G3="","",LogicCommon!G3) | M3: ReportID : | O3: Gene.Type : | P3: ALL
A4: * | E4: Version : | F4: 000000 | G4: LogicName : | H4: =IF(LogicCommon!E4="","",LogicCommon!E4) -> 承認一覧登録サービス | I4: Ope.Name : | J4: 取消 | K4: SuperLogicID : | L4: =IF(LogicCommon!G4="","",LogicCommon!G4) -> MB.MBUDL5010
A5: * | E5: ACType :
A6: * | D6: 概要 : | E6: 承認または却下を取り消す。 | L6: ID
A7: # | I7: U | K7: o
A8: # | D8: ブロック名 Block Name | E8: 型 Type | G8: super/share | H8: 対象ブロック名 Target Block Name | K8: TargetName | O8: ブロック備考 Block Remarks
A9: # | D9: 項目名 Field Name | E9: 型 Type | F9: 桁 Digits | G9: フルネーム Full Name | H9: 日本語名 Japanese Name | I9: 上り項目 Request Message Field | J9: 下り項目 Response Message Field | M9: 条件および編集方法 Conditions and Editing Methods | O9: 項目備考 Field Remarks
A10: # | K10: 上り項目 Request Message Field | L10: 下り項目 Response Message Field
A11: 10 | B11: * | D11: Aprv_Upd02_Dtl1 | E11: L | G11: $share$ | H11: MB.MBBAL5030.Aprv_Chk01.Aprv_Chk01_Rslt1
A12: 10 | D12: aprv_no | E12: #MA.APRV_NO | G12: Approval No. | H12: 承認ＮＯ | I12: E | J12: -
A13: 10 | D13: aprv_no_seq | E13: #MA.APRV_NO_SEQ | G13: Approval sequence number | H13: 承認ＮＯ連番 | I13: E | J13: -
A14: 10 | D14: aprv_role_cd | E14: #MA.APRV_ROLE_CD | G14: Approval role cd. | H14: 承認役割ＣＤ | I14: E | J14: -
A15: 10 | D15: aprv_usr_cd | E15: #MA.USR_CD | G15: Main PIC cd. | H15: 主担当者ＣＤ | I15: E | J15: -
A16: 10 | D16: aprv_d_sts_typ | E16: #MA.APRV_D_STS_TYP | G16: Approval details status type | H16: 承認明細状況区分 | I16: E | J16: -
A17: 10 | D17: act_usr_cd | E17: #MA.USR_CD | G17: Approval executor cd. | H17: 承認実行者ＣＤ | I17: - | J17: -
A18: 10 | D18: aprv_d_rmrks | E18: #MA.APRV_D_RMRKS | G18: Approval details remarks | H18: 承認明細備考 | I18: E | J18: -
A19: 10 | D19: sub_char1 | E19: #MA.APRV_D_SUB_CHAR1 | G19: Approval details spare 1 | H19: 承認明細予備１ | I19: E | J19: -
A20: 10 | D20: sub_char2 | E20: #MA.APRV_D_SUB_CHAR2 | G20: Approval details spare 2 | H20: 承認明細予備２ | I20: E | J20: -
A21: 10 | D21: sub_char3 | E21: #MA.APRV_D_SUB_CHAR3 | G21: Approval details spare 3 | H21: 承認明細予備３ | I21: E | J21: -
A22: 10 | D22: upd_cntr | E22: #MA.UPD_CNT | G22: Update counter | H22: 更新カウンタ | I22: E | J22: -
A23: 10 | D23: upd_cntr_chk_flg | E23: #MA.FLG | G23: Check for update counter flg. | H23: 更新カウンタチェックＦＬＧ | I23: E | J23: -
... A25: 10 | D25: err_flg | E25: #MA.FLG | G25: Error flg. | H25: エラーＦＬＧ | I25: - | J25: E
D26: 詳細 :

Sheet Aprv_Chk03
A1: * | B1: * | D1: L | E1: 1
A2: * | D2: オペレーション実装仕様書 Operation Specification Implementation Sheet | E2: ModuleID : | F2: =IF(LogicCommon!C2="","",LogicCommon!C2) -> MB | G2: LogicID : | H2: =IF(LogicCommon!E2="","",LogicCommon!E2) -> MBBAL5030 | I2: Ope.ID : | J2: Aprv_Chk03 | K2: Pj.ID : | L2: =IF(LogicCommon!G2="","",LogicCommon!G2) -> MC | M2: Ope.Body : | N2: MA.MAUDL5010.Checker
A3: * | E3: SubModuleID : | F3: =IF(LogicCommon!C3="","",LogicCommon!C3) -> MBBA | G3: LogicClass : | H3: =IF(LogicCommon!E3="","",LogicCommon!E3) -> MBBAL_AprvRegService | I3: Ope.Method : | J3: Aprv_Chk03 | K3: SuperClassPj.ID : | L3: =IF(LogicCommon!G3="","",LogicCommon!G3) | M3: ReportID : | O3: Gene.Type : | P3: ALL
A4: * | E4: Version : | F4: 000000 | G4: LogicName : | H4: =IF(LogicCommon!E4="","",LogicCommon!E4) -> 承認一覧登録サービス | I4: Ope.Name : | J4: 更新前チェック | K4: SuperLogicID : | L4: =IF(LogicCommon!G4="","",LogicCommon!G4) -> MB.MBUDL5010
A5: * | E5: ACType :
A6: * | D6: 概要 : | E6: 承認情報を更新する際のチェックを行う。 | O6: ID
A7: # | I7: U | K7: K | L7: K | N7: o
A8: # | D8: ブロック名 Block Name | E8: 型 Type | G8: super/share | H8: 対象ブロック名 Target Block Name | K8: REQUIRED | L8: DUPLICATE | N8: TargetName | R8: ブロック備考 Block Remarks
A9: # | D9: 項目名 Field Name | E9: 型 Type | F9: 桁 Digits | G9: フルネーム Full Name | H9: 日本語名 Japanese Name | I9: 上り項目 Request Message Field | J9: 下り項目 Response Message Field | P9: 条件および編集方法 Conditions and Editing Methods | R9: 項目備考 Field Remarks
A10: # | N10: 上り項目 Request Message Field | O10: 下り項目 Response Message Field
A11: 10 | B11: * | D11: Aprv_Chk03_Rslt1 | E11: L | G11: $share$ | H11: MB.MBBAL5030.Aprv_Chk01.Aprv_Chk01_Rslt1
A12: 10 | D12: aprv_no | E12: #MA.APRV_NO | G12: Approval No. | H12: 承認ＮＯ | I12: E | J12: E | K12: E | L12: APRV_D
A13: 10 | D13: aprv_no_seq | E13: #MA.APRV_NO_SEQ | G13: Approval sequence number | H13: 承認ＮＯ連番 | I13: E | J13: E | K13: E | L13: APRV_D
A14: 10 | D14: aprv_role_cd | E14: #MA.APRV_ROLE_CD | G14: Approval role cd. | H14: 承認役割ＣＤ | I14: E | J14: E | K14: E | L14: APRV_D
A15: 10 | D15: aprv_usr_cd | E15: #MA.USR_CD | G15: Main PIC cd. | H15: 主担当者ＣＤ | I15: E | J15: E | K15: E | L15: APRV_D
A16: 10 | D16: aprv_d_sts_typ | E16: #MA.APRV_D_STS_TYP | G16: Approval details status type | H16: 承認明細状況区分 | I16: - | J16: -
A17: 10 | D17: act_usr_cd | E17: #MA.USR_CD | G17: Approval executor cd. | H17: 承認実行者ＣＤ | I17: - | J17: -
A18: 10 | D18: aprv_d_rmrks | E18: #MA.APRV_D_RMRKS | G18: Approval details remarks | H18: 承認明細備考 | I18: E | J18: E
A19: 10 | D19: sub_char1 | E19: #MA.APRV_D_SUB_CHAR1 | G19: Approval details spare 1 | H19: 承認明細予備１ | I19: E | J19: E
A20: 10 | D20: sub_char2 | E20: #MA.APRV_D_SUB_CHAR2 | G20: Approval details spare 2 | H20: 承認明細予備２ | I20: E | J20: E
A21: 10 | D21: sub_char3 | E21: #MA.APRV_D_SUB_CHAR3 | G21: Approval details spare 3 | H21: 承認明細予備３ | I21: E | J21: E
A22: 10 | D22: upd_cntr | E22: #MA.UPD_CNT | G22: Update counter | H22: 更新カウンタ | I22: E | J22: E
A23: 10 | D23: upd_cntr_chk_flg | E23: #MA.FLG | G23: Check for update counter flg. | H23: 更新カウンタチェックＦＬＧ | I23: E | J23: E
A24: 10 | D24: peg_no | E24: #MA.INT | G24: Pegging No. | H24: 紐付けＮＯ | I24: E | J24: E
A25: 10 | D25: err_flg | E25: #MA.FLG | G25: Error flg. | H25: エラーＦＬＧ | I25: - | J25: E
D26: 詳細 :

Sheet Aprv_Upd03
A1: * | B1: * | D1: L | E1: 1
A2: * | D2: オペレーション実装仕様書 Operation Specification Implementation Sheet | E2: ModuleID : | F2: =IF(LogicCommon!C2="","",LogicCommon!C2) -> MB | G2: LogicID : | H2: =IF(LogicCommon!E2="","",LogicCommon!E2) -> MBBAL5030 | I2: Ope.ID : | J2: Aprv_Upd03 | K2: Pj.ID : | L2: =IF(LogicCommon!G2="","",LogicCommon!G2) -> MC | M2: Ope.Body :
A3: * | E3: SubModuleID : | F3: =IF(LogicCommon!C3="","",LogicCommon!C3) -> MBBA | G3: LogicClass : | H3: =IF(LogicCommon!E3="","",LogicCommon!E3) -> MBBAL_AprvRegService | I3: Ope.Method : | J3: Aprv_Upd03 | K3: SuperClassPj.ID : | L3: =IF(LogicCommon!G3="","",LogicCommon!G3) | M3: ReportID : | O3: Gene.Type : | P3: ALL
A4: * | E4: Version : | F4: 000000 | G4: LogicName : | H4: =IF(LogicCommon!E4="","",LogicCommon!E4) -> 承認一覧登録サービス | I4: Ope.Name : | J4: 更新 | K4: SuperLogicID : | L4: =IF(LogicCommon!G4="","",LogicCommon!G4) -> MB.MBUDL5010
A5: * | E5: ACType :
A6: * | D6: 概要 : | E6: 承認情報を更新する。 | L6: ID
A7: # | I7: U | K7: o
A8: # | D8: ブロック名 Block Name | E8: 型 Type | G8: super/share | H8: 対象ブロック名 Target Block Name | K8: TargetName | O8: ブロック備考 Block Remarks
A9: # | D9: 項目名 Field Name | E9: 型 Type | F9: 桁 Digits | G9: フルネーム Full Name | H9: 日本語名 Japanese Name | I9: 上り項目 Request Message Field | J9: 下り項目 Response Message Field | M9: 条件および編集方法 Conditions and Editing Methods | O9: 項目備考 Field Remarks
A10: # | K10: 上り項目 Request Message Field | L10: 下り項目 Response Message Field
A11: 10 | B11: * | D11: Aprv_Upd03_Dtl1 | E11: L | G11: $share$ | H11: MB.MBBAL5030.Aprv_Chk01.Aprv_Chk01_Rslt1
A12: 10 | D12: aprv_no | E12: #MA.APRV_NO | G12: Approval No. | H12: 承認ＮＯ | I12: E | J12: -
A13: 10 | D13: aprv_no_seq | E13: #MA.APRV_NO_SEQ | G13: Approval sequence number | H13: 承認ＮＯ連番 | I13: E | J13: -
A14: 10 | D14: aprv_role_cd | E14: #MA.APRV_ROLE_CD | G14: Approval role cd. | H14: 承認役割ＣＤ | I14: E | J14: -
A15: 10 | D15: aprv_usr_cd | E15: #MA.USR_CD | G15: Main PIC cd. | H15: 主担当者ＣＤ | I15: E | J15: -
A16: 10 | D16: aprv_d_sts_typ | E16: #MA.APRV_D_STS_TYP | G16: Approval details status type | H16: 承認明細状況区分 | I16: - | J16: -
A17: 10 | D17: act_usr_cd | E17: #MA.USR_CD | G17: Approval executor cd. | H17: 承認実行者ＣＤ | I17: - | J17: -
A18: 10 | D18: aprv_d_rmrks | E18: #MA.APRV_D_RMRKS | G18: Approval details remarks | H18: 承認明細備考 | I18: E | J18: -
A19: 10 | D19: sub_char1 | E19: #MA.APRV_D_SUB_CHAR1 | G19: Approval details spare 1 | H19: 承認明細予備１ | I19: E | J19: -
A20: 10 | D20: sub_char2 | E20: #MA.APRV_D_SUB_CHAR2 | G20: Approval details spare 2 | H20: 承認明細予備２ | I20: E | J20: -
A21: 10 | D21: sub_char3 | E21: #MA.APRV_D_SUB_CHAR3 | G21: Approval details spare 3 | H21: 承認明細予備３ | I21: E | J21: -
A22: 10 | D22: upd_cntr | E22: #MA.UPD_CNT | G22: Update counter | H22: 更新カウンタ | I22: E | J22: -
A23: 10 | D23: upd_cntr_chk_flg | E23: #MA.FLG | G23: Check for update counter flg. | H23: 更新カウンタチェックＦＬＧ | I23: E | J23: -
... A25: 10 | D25: err_flg | E25: #MA.FLG | G25: Error flg. | H25: エラーＦＬＧ | I25: - | J25: E
D26: 詳細 :

Sheet 来歴
A1: 変更来歴
A3: Rev. | H3: 修正番号 | O3: 変更内容 | AQ3: 変更箇所
A4: 1 | O4: 初版
A5: 1.1 | O5: 英語の名称を追記 | AQ5: 全般
