Workbook

Sheet LogicCommon
A2: オペレーション実装仕様書 | B2: ModuleID : | C2: MS | D2: LogicID : | E2: MSBBL6010 | F2: Pj.ID : | G2: MC
B3: SubModuleID : | C3: MSBB | D3: LogicClass : | E3: MSBBL_SlsActService | F3: SuperClassPj.ID :
D4: LogicName : | E4: 売上実績サービス | F4: SuperLogicID : | G4: MS.MSBBL9010
A5: 概要 :
A6: 詳細 :

Sheet SlsAct_Upd01
A1: * | B1: * | D1: L | E1: 1
A2: * | D2: オペレーション実装仕様書 Operation Specification Implementation Sheet | E2: ModuleID : | F2: =IF(LogicCommon!C2="","",LogicCommon!C2) -> MS | G2: LogicID : | H2: =IF(LogicCommon!E2="","",LogicCommon!E2) -> MSBBL6010 | I2: Ope.ID : | J2: SlsAct_Upd01 | K2: Pj.ID : | L2: =IF(LogicCommon!G2="","",LogicCommon!G2) -> MC | M2: Ope.Body : | N2: "mcframe.serverMAUD.MAUDL5010.MAUDL_Operation"
A3: * | D3: =IF(LogicCommon!A3="","",LogicCommon!A3) | E3: SubModuleID : | F3: =IF(LogicCommon!C3="","",LogicCommon!C3) -> MSBB | G3: LogicClass : | H3: =IF(LogicCommon!E3="","",LogicCommon!E3) -> MSBBL_SlsActService | I3: Ope.Method : | J3: =J2 -> SlsAct_Upd01 | K3: SuperClassPj.ID : | L3: =IF(LogicCommon!G3="","",LogicCommon!G3) | O3: Gene.Type : | P3: ALL
A4: * | E4: Version : | F4: 000000 | G4: LogicName : | H4: =IF(LogicCommon!E4="","",LogicCommon!E4) -> 売上実績サービス | I4: Ope.Name : | J4: 登録 | K4: SuperLogicID : | L4: =IF(LogicCommon!G4="","",LogicCommon!G4) -> MS.MSBBL9010 | M4: ImplOpe.ID:
A5: * | E5: ACType :
A6: * | D6: 概要 : | E6: 売上実績を登録する | M6: ID | O6: ID | Q6: ID
A7: # | I7: U | K7: K | L7: o | N7: o | P7: o
A8: # | D8: ブロック名 Block Name | E8: 型 Type | G8: super/share | H8: 対象ブロック名 Target Block Name | L8: TargetName | N8: TargetName | P8: TargetName | T8: ブロック備考 Block Remarks
A9: # | D9: 項目名 Field Name | E9: 型 Type | F9: 桁 Digits | G9: フルネーム Full Name | H9: 日本語名 Japanese Name | I9: 上り項目 Request Message Field | J9: 下り項目 Response Message Field | R9: 条件および編集方法 Conditions and Editing Methods | T9: 項目備考 Field Remarks
A10: # | L10: 上り項目 Request Message Field | M10: 下り項目 Response Message Field | N10: 上り項目 Request Message Field | O10: 下り項目 Response Message Field | P10: 上り項目 Request Message Field | Q10: 下り項目 Response Message Field
A11: 10 | B11: * | D11: SlsAct_Upd01_Hdr | E11: L
A12: 10 | D12: hdr_peg_no | E12: #MA.INT | G12: Header pegging No. | H12: ヘッダ紐付けＮＯ | I12: E
A13: 10 | D13: data_crud_typ | E13: #MA.DATA_CRUD_TYP | G13: Data update type | H13: データ更新区分 | I13: E
A14: 10 | D14: sls_act_no | E14: #MA.SLS_ACT_NO | G14: Sales result No. | H14: 売上実績ＮＯ | I14: E
A15: 10 | D15: sls_act_seq | E15: #MA.SLIP_SEQ | G15: Sales result sequence number | H15: 売上実績連番 | I15: E
A16: 10 | D16: sls_act_rev | E16: #MA.SLIP_REV | G16: Sales result rev. number | H16: 売上実績改訂番号 | I16: E
A17: 10 | D17: trd_cd | E17: #MA.TRD_CD | G17: Transaction cd. | H17: 取引ＣＤ | I17: E
A18: 10 | D18: trd_ptn_typ | E18: #MA.TRD_PTN_TYP | G18: Transaction pattern type | H18: 取引パタン区分 | I18: E
A19: 10 | D19: ac_dt | E19: #MA.DT | G19: Recording date | H19: 計上日 | I19: E
A20: 10 | D20: can_ac_dt | E20: #MA.DT | G20: Cancellation recording date | H20: 取消計上日 | I20: E
A21: 10 | D21: sls_usr_cd | E21: #MA.USR_CD | G21: Sales PIC cd. | H21: 売上担当者ＣＤ | I21: E
A22: 10 | D22: sls_dpt_cd | E22: #MA.DPT_CD | G22: Sales dept. cd. | H22: 売上部門ＣＤ | I22: E
A23: 10 | D23: wg_cd | E23: #MA.WG_CD | G23: WG cd. | H23: ワーキンググループＣＤ | I23: E
... A45: 10 | D45: iv_no | E45: #MA.IV_NO | G45: Invoice No. | H45: インボイスＮＯ | I45: E
A46: 10 | D46: iv_rev | E46: #MA.SLIP_REV | G46: Invoice rev. number | H46: インボイス改訂番号
A47: 10 | D47: ref_iv_no | E47: #MA.IV_NO | G47: Corresponding I/V No. | H47: 対応インボイスＮＯ | I47: E
A48: 10 | D48: rcpt_iv_mng_no | E48: #MA.RCPT_IV_MNG_NO | G48: Purchase invoice management No. | H48: 受領インボイス管理ＮＯ | I48: E
A49: 10 | D49: rcpt_iv_no | E49: #MA.IV_NO | G49: Purchase invoice No. | H49: 受領インボイスＮＯ | I49: E
A50: 10 | D50: num_flg | E50: #MA.FLG | G50: Auto | H50: 自動 | I50: E
A51: 10 | D51: iv_dt | E51: #MA.DT | G51: Invoice date | H51: インボイス日付 | I51: E
A52: 10 | D52: pl_skip_flg | E52: #MA.FLG | G52: Omit packing list | H52: パッキングリスト省略 | I52: E
A53: 10 | D53: iv_immed_prnt_flg | E53: #MA.FLG | G53: Invoice immediate issue | H53: インボイス即時発行 | I53: E
A54: 10 | D54: iv_rmrks | E54: #MS.IV_RMRKS | G54: Invoice remarks | H54: インボイス備考 | I54: E
A55: 10 | D55: case_mrk1 | E55: #MS.CASE_MRK | G55: Case mark 1 | H55: ケースマーク１ | I55: E
A56: 10 | D56: case_mrk2 | E56: #MS.CASE_MRK | G56: Case mark 2 | H56: ケースマーク２ | I56: E
A57: 10 | D57: case_mrk3 | E57: #MS.CASE_MRK | G57: Case mark 3 | H57: ケースマーク３ | I57: E
A58: 10 | D58: case_mrk4 | E58: #MS.CASE_MRK | G58: Case mark 4 | H58: ケースマーク４ | I58: E
... A117: 10 | D117: ship_act_sync_flg | E117: #MA.FLG | G117: Shipping result simultaneously recording | H117: 出荷実績同時計上 | I117: E
A118: 10 | D118: new_hdr_peg_no | E118: #MA.INT | G118: New header pegging No. | H118: 新ヘッダ紐付けＮＯ
A119: 10 | D119: hdr_dlv_cd | E119: #MA.BP_CD | G119: Header delivery destination cd. | H119: ヘッダ納品先ＣＤ
...

Sheet SlsAct_Upd02
A1: * | B1: * | D1: L | E1: 1
A2: * | D2: オペレーション実装仕様書 Operation Specification Implementation Sheet | E2: ModuleID : | F2: =IF(LogicCommon!C2="","",LogicCommon!C2) -> MS | G2: LogicID : | H2: =IF(LogicCommon!E2="","",LogicCommon!E2) -> MSBBL6010 | I2: Ope.ID : | J2: SlsAct_Upd02 | K2: Pj.ID : | L2: =IF(LogicCommon!G2="","",LogicCommon!G2) -> MC | M2: Ope.Body : | N2: "mcframe.serverMAUD.MAUDL5010.MAUDL_Operation"
A3: * | D3: =IF(LogicCommon!A3="","",LogicCommon!A3) | E3: SubModuleID : | F3: =IF(LogicCommon!C3="","",LogicCommon!C3) -> MSBB | G3: LogicClass : | H3: =IF(LogicCommon!E3="","",LogicCommon!E3) -> MSBBL_SlsActService | I3: Ope.Method : | J3: =J2 -> SlsAct_Upd02 | K3: SuperClassPj.ID : | L3: =IF(LogicCommon!G3="","",LogicCommon!G3) | O3: Gene.Type : | P3: ALL
A4: * | E4: Version : | F4: 000000 | G4: LogicName : | H4: =IF(LogicCommon!E4="","",LogicCommon!E4) -> 売上実績サービス | I4: Ope.Name : | J4: 登録（出荷実績呼出用） | K4: SuperLogicID : | L4: =IF(LogicCommon!G4="","",LogicCommon!G4) -> MS.MSBBL9010 | M4: ImplOpe.ID:
A5: * | E5: ACType :
A6: * | D6: 概要 : | E6: 売上実績を登録する（出荷実績サービスより呼び出す） | M6: ID | O6: ID | Q6: ID
A7: # | I7: U | K7: K | L7: o | N7: o | P7: o
A8: # | D8: ブロック名 Block Name | E8: 型 Type | G8: super/share | H8: 対象ブロック名 Target Block Name | L8: TargetName | N8: TargetName | P8: TargetName | T8: ブロック備考 Block Remarks
A9: # | D9: 項目名 Field Name | E9: 型 Type | F9: 桁 Digits | G9: フルネーム Full Name | H9: 日本語名 Japanese Name | I9: 上り項目 Request Message Field | J9: 下り項目 Response Message Field | R9: 条件および編集方法 Conditions and Editing Methods | T9: 項目備考 Field Remarks
A10: # | L10: 上り項目 Request Message Field | M10: 下り項目 Response Message Field | N10: 上り項目 Request Message Field | O10: 下り項目 Response Message Field | P10: 上り項目 Request Message Field | Q10: 下り項目 Response Message Field
A11: 10 | B11: * | D11: SlsAct_Upd02_Cnd | E11: L
A12: 10 | D12: dlv_slip_no | E12: #MA.DLV_SLIP_NO | G12: Delivery note No. | H12: 納品書ＮＯ | I12: E
A13: 10 | D13: iv_no | E13: #MA.IV_NO | G13: Invoice No. | H13: インボイスＮＯ | I13: E
A14: 10 | D14: data_crud_typ | E14: #MA.DATA_CRUD_TYP | G14: Data update type | H14: データ更新区分 | I14: E
A15: 10 | D15: dlv_slip_seq | E15: #MA.SLIP_SEQ | G15: Delivery note sequence number | H15: 納品書連番
A16: 10 | D16: via_dlv_typ | E16: #MA.VIA_DLV_TYP | G16: Receiving point stopover type | H16: 配送先経由区分
A17: 10 | D17: split_flg | E17: #MA.FLG | G17: Split exists | H17: 分割有
A18: 10 | D18: can_ac_dt | E18: #MA.DT | G18: Cancellation recording date | H18: 取消計上日 | I18: E
A19: 10 | D19: ship_dt | E19: #MA.DT | G19: Shipping date | H19: 出荷日 | I19: E
A20: 10 | D20: ac_dt | E20: #MA.DT | G20: Recording date | H20: 計上日 | I20: E
A21: 10 | D21: use_iv_ship_act_map | E21: #MA.FLG | G21: Use invoice shipping result map | H21: インボイス出荷実績マップ使用 | I21: E
A23: 20 | B23: * | D23: SlsAct_Upd02_IvL | E23: L
A24: 20 | D24: trd_cd | E24: #MA.TRD_CD | G24: Transaction cd. | H24: 取引ＣＤ
A25: 20 | D25: trd_ptn_typ | E25: #MA.TRD_PTN_TYP | G25: Transaction pattern type | H25: 取引パタン区分
A26: 20 | D26: ac_dt | E26: #MA.DT | G26: Recording date | H26: 計上日
A27: 20 | D27: sls_dpt_cd | E27: #MA.DPT_CD | G27: Sales dept. cd. | H27: 売上部門ＣＤ
A28: 20 | D28: wg_cd | E28: #MA.WG_CD | G28: WG cd. | H28: ワーキンググループＣＤ
A29: 20 | D29: sls_usr_cd | E29: #MA.USR_CD | G29: Sales PIC cd. | H29: 売上担当者ＣＤ
A30: 20 | D30: eta_dt | E30: #MA.DT | G30: Estimated date of unloading | H30: 船卸予定日
A31: 20 | D31: cst_cd | E31: #MA.BP_CD | G31: Customer cd. | H31: 得意先ＣＤ
A32: 20 | D32: iv_no | E32: #MA.IV_NO | G32: Invoice No. | H32: インボイスＮＯ
A33: 20 | D33: rcpt_iv_mng_no | E33: #MA.RCPT_IV_MNG_NO | G33: Purchase invoice management No. | H33: 受領インボイス管理ＮＯ
A34: 20 | D34: rcpt_iv_no | E34: #MA.IV_NO | G34: Purchase invoice No. | H34: 受領インボイスＮＯ
A35: 20 | D35: tterm_cd1 | E35: #MA.TTERM_CD | G35: Transaction terms cd. 1 | H35: 取引条件ＣＤ１
... A137: 20 | D137: sls_dt | E137: #MA.DT | G137: Sales date | H137: 売上日
A139: 30 | B139: * | D139: SlsAct_Upd02_IoL | E139: L
A140: 30 | D140: ship_act_d_no | E140: #MA.SHIP_ACT_D_NO | G140: Shipping result details No. | H140: 出荷実績明細ＮＯ
A141: 30 | D141: iv_ship_act_d_no | E141: #MA.IV_SHIP_ACT_D_NO | G141: Shipping invoice result details No. | H141: インボイス出荷実績明細ＮＯ
A142: 30 | D142: sno1 | E142: #MA.SNO1 | G142: SEIBAN No. 1 | H142: 手配ＮＯ１
A143: 30 | D143: sno2 | E143: #MA.SNO2 | G143: SEIBAN No. 2 | H143: 手配ＮＯ２
...

Sheet SlsAct_Upd03
A1: * | B1: * | D1: L | E1: 1
A2: * | D2: オペレーション実装仕様書 Operation Specification Implementation Sheet | E2: ModuleID : | F2: =IF(LogicCommon!C2="","",LogicCommon!C2) -> MS | G2: LogicID : | H2: =IF(LogicCommon!E2="","",LogicCommon!E2) -> MSBBL6010 | I2: Ope.ID : | J2: SlsAct_Upd03 | K2: Pj.ID : | L2: =IF(LogicCommon!G2="","",LogicCommon!G2) -> MC | M2: Ope.Body : | N2: "mcframe.serverMAUD.MAUDL5010.MAUDL_Operation"
A3: * | D3: =IF(LogicCommon!A3="","",LogicCommon!A3) | E3: SubModuleID : | F3: =IF(LogicCommon!C3="","",LogicCommon!C3) -> MSBB | G3: LogicClass : | H3: =IF(LogicCommon!E3="","",LogicCommon!E3) -> MSBBL_SlsActService | I3: Ope.Method : | J3: =J2 -> SlsAct_Upd03 | K3: SuperClassPj.ID : | L3: =IF(LogicCommon!G3="","",LogicCommon!G3) | O3: Gene.Type : | P3: ALL
A4: * | E4: Version : | F4: 000000 | G4: LogicName : | H4: =IF(LogicCommon!E4="","",LogicCommon!E4) -> 売上実績サービス | I4: Ope.Name : | J4: 登録（承認用） | K4: SuperLogicID : | L4: =IF(LogicCommon!G4="","",LogicCommon!G4) -> MS.MSBBL9010 | M4: ImplOpe.ID:
A5: * | E5: ACType :
A6: * | D6: 概要 : | E6: 売上値引で承認/承認取消された場合に、売上実績を承認/承認取消として更新する | M6: ID | O6: ID | Q6: ID
A7: # | I7: U | K7: K | L7: o | N7: o | P7: o
A8: # | D8: ブロック名 Block Name | E8: 型 Type | G8: super/share | H8: 対象ブロック名 Target Block Name | L8: TargetName | N8: TargetName | P8: TargetName | T8: ブロック備考 Block Remarks
A9: # | D9: 項目名 Field Name | E9: 型 Type | F9: 桁 Digits | G9: フルネーム Full Name | H9: 日本語名 Japanese Name | I9: 上り項目 Request Message Field | J9: 下り項目 Response Message Field | R9: 条件および編集方法 Conditions and Editing Methods | T9: 項目備考 Field Remarks
A10: # | L10: 上り項目 Request Message Field | M10: 下り項目 Response Message Field | N10: 上り項目 Request Message Field | O10: 下り項目 Response Message Field | P10: 上り項目 Request Message Field | Q10: 下り項目 Response Message Field
A11: 10 | B11: * | D11: SlsAct_Upd03_Aprv | E11: L
A12: 10 | D12: sls_act_no | E12: #MA.SLS_ACT_NO | G12: Sales result No. | H12: 売上実績ＮＯ | I12: E
A13: 10 | D13: aprv_sts_typ | E13: #MA.APRV_STS_TYP | G13: Approval status type | H13: 承認状況区分 | I13: E

Sheet SlsAct_Upd04
A1: * | B1: * | D1: L | E1: 1
A2: * | D2: オペレーション実装仕様書 Operation Specification Implementation Sheet | E2: ModuleID : | F2: =IF(LogicCommon!C2="","",LogicCommon!C2) -> MS | G2: LogicID : | H2: =IF(LogicCommon!E2="","",LogicCommon!E2) -> MSBBL6010 | I2: Ope.ID : | J2: SlsAct_Upd04 | K2: Pj.ID : | L2: =IF(LogicCommon!G2="","",LogicCommon!G2) -> MC | M2: Ope.Body : | N2: "mcframe.serverMAUD.MAUDL5010.MAUDL_Operation"
A3: * | D3: =IF(LogicCommon!A3="","",LogicCommon!A3) | E3: SubModuleID : | F3: =IF(LogicCommon!C3="","",LogicCommon!C3) -> MSBB | G3: LogicClass : | H3: =IF(LogicCommon!E3="","",LogicCommon!E3) -> MSBBL_SlsActService | I3: Ope.Method : | J3: =J2 -> SlsAct_Upd04 | K3: SuperClassPj.ID : | L3: =IF(LogicCommon!G3="","",LogicCommon!G3) | O3: Gene.Type : | P3: ALL
A4: * | E4: Version : | F4: 000000 | G4: LogicName : | H4: =IF(LogicCommon!E4="","",LogicCommon!E4) -> 売上実績サービス | I4: Ope.Name : | J4: 請求繰越回数更新 | K4: SuperLogicID : | L4: =IF(LogicCommon!G4="","",LogicCommon!G4) -> MS.MSBBL9010 | M4: ImplOpe.ID:
A5: * | E5: ACType :
A6: * | D6: 概要 : | E6: 請求繰越回数を更新する | M6: ID | O6: ID | Q6: ID
A7: # | I7: U | K7: K | L7: o | N7: o | P7: o
A8: # | D8: ブロック名 Block Name | E8: 型 Type | G8: super/share | H8: 対象ブロック名 Target Block Name | L8: TargetName | N8: TargetName | P8: TargetName | T8: ブロック備考 Block Remarks
A9: # | D9: 項目名 Field Name | E9: 型 Type | F9: 桁 Digits | G9: フルネーム Full Name | H9: 日本語名 Japanese Name | I9: 上り項目 Request Message Field | J9: 下り項目 Response Message Field | R9: 条件および編集方法 Conditions and Editing Methods | T9: 項目備考 Field Remarks
A10: # | L10: 上り項目 Request Message Field | M10: 下り項目 Response Message Field | N10: 上り項目 Request Message Field | O10: 下り項目 Response Message Field | P10: 上り項目 Request Message Field | Q10: 下り項目 Response Message Field
A11: 10 | B11: * | D11: SlsAct_Upd04_Dtl | E11: L
A12: 10 | D12: sls_act_d_no | E12: #MA.SLS_ACT_D_NO | G12: Sales result details No. | H12: 売上実績明細ＮＯ | I12: E
A13: 10 | D13: sls_act_d_seq | E13: #MA.SLIP_SEQ | G13: Sales result details sequence number | H13: 売上実績明細連番 | I13: E
A14: 10 | D14: bill_crryovr_times | E14: #MA.CRRYOVR_TIMES | G14: Billing carry-over count | H14: 請求繰越回数 | I14: E

Sheet 来歴
A1: 変更来歴
A3: Rev. | H3: 修正番号 | O3: 変更内容 | AQ3: 変更箇所
A4: 1 | O4: 初版
A5: 1.1 | H5: MS7031#166 | O5: SlsAct_Upd01_Rslt_Dtlブロックに以下の項目を追加 ・sls_act_no ・sls_act_seq ・sls_act_rev ・dlv_slip_no ・iv_no | AQ5: SlsAct_Upd01シート
A6: 1.2 | O6: 英語の名称を追記 | AQ6: 全般
