Workbook

Sheet LogicCommon
A2: オペレーション実装仕様書 | B2: ModuleID : | C2: MS | D2: LogicID : | E2: MSLAL6220 | F2: Pj.ID : | G2: MC
B3: SubModuleID : | C3: MSLA | D3: LogicClass : | E3: MSLAL_MfgActRecvIfService | F3: SuperClassPj.ID :
D4: LogicName : | E4: 製造実績受信ＩＦサービス | F4: SuperLogicID : | G4: MS.MSUDL5010
A5: 概要 : | B5: ＭＥＳなど外部システムから製造実績（工程・投入・工数・出来高）を取り込むための処理を提供する。
A6: 詳細 :

Sheet MfgActRecvIf_Upd01
A1: * | B1: * | D1: L | E1: 1
A2: * | D2: オペレーション実装仕様書 Operation Specification Implementation Sheet | E2: ModuleID : | F2: =IF(LogicCommon!C2="","",LogicCommon!C2) -> MS | G2: LogicID : | H2: =IF(LogicCommon!E2="","",LogicCommon!E2) -> MSLAL6220 | I2: Ope.ID : | J2: MfgActRecvIf_Upd01 | K2: Pj.ID : | L2: =IF(LogicCommon!G2="","",LogicCommon!G2) -> MC | M2: Ope.Body : | N2: "mcframe.serverMAUD.MAUDL5010.MAUDL_Operation"
A3: * | D3: =IF(LogicCommon!A3="","",LogicCommon!A3) | E3: SubModuleID : | F3: =IF(LogicCommon!C3="","",LogicCommon!C3) -> MSLA | G3: LogicClass : | H3: =IF(LogicCommon!E3="","",LogicCommon!E3) -> MSLAL_MfgActRecvIfService | I3: Ope.Method : | J3: @ | K3: SuperClassPj.ID : | L3: =IF(LogicCommon!G3="","",LogicCommon!G3) | O3: Gene.Type : | P3: ALL
A4: * | E4: Version : | F4: 000000 | G4: LogicName : | H4: =IF(LogicCommon!E4="","",LogicCommon!E4) -> 製造実績受信ＩＦサービス | I4: Ope.Name : | J4: 製造実績取込１ | K4: SuperLogicID : | L4: =IF(LogicCommon!G4="","",LogicCommon!G4) -> MS.MSUDL5010 | M4: ImplOpe.ID: | N4: PF.PFUDL0040.Upd01
A5: * | E5: ACType :
A6: * | D6: 概要 : | E6: 製造実績（工程・投入・工数・出来高）受信ＩＦ取込を行う。（ＥＳＢのリアルタイム取込から呼び出される） | M6: ID | O6: ID | Q6: ID
A7: # | I7: U | K7: K | L7: o | N7: o | P7: o
A8: # | D8: ブロック名 Block Name | E8: 型 Type | G8: super/share | H8: 対象ブロック名 Target Block Name | L8: TargetName | N8: TargetName | P8: TargetName | T8: ブロック備考 Block Remarks
A9: # | D9: 項目名 Field Name | E9: 型 Type | F9: 桁 Digits | G9: フルネーム Full Name | H9: 日本語名 Japanese Name | I9: 上り項目 Request Message Field | J9: 下り項目 Response Message Field | R9: 条件および編集方法 Conditions and Editing Methods | T9: 項目備考 Field Remarks
A10: # | L10: 上り項目 Request Message Field | M10: 下り項目 Response Message Field | N10: 上り項目 Request Message Field | O10: 下り項目 Response Message Field | P10: 上り項目 Request Message Field | Q10: 下り項目 Response Message Field
A11: 10 | B11: * | D11: MfgActRecvIf_Upd01_Dtl | E11: L | G11: $share$ | H11: PF.PFUDL0040.Upd01.Upd01_Dtl
A12: 10 | D12: data_no | E12: #MA.IF_DATA_NO | G12: Data No. | H12: データＮＯ | I12: E | J12: -
A13: 10 | D13: ext_data_no | E13: #MA.IF_EXT_DATA_NO | G13: External system data No. | H13: 外部システムデータＮＯ | I13: E | J13: -
A14: 10 | D14: ext_sys_cd | E14: #MA.EXT_SYS_CD | G14: External system cd. | H14: 外部システムＣＤ | I14: E | J14: -
A15: 10 | D15: if_proc_typ | E15: #MA.IF_PROC_TYP | G15: IF process type | H15: ＩＦ処理区分 | I15: E | J15: -
D16: 詳細 :

Sheet MfgActRecvIf_Upd02
A1: * | B1: * | D1: L | E1: 1
A2: * | D2: オペレーション実装仕様書 Operation Specification Implementation Sheet | E2: ModuleID : | F2: =IF(LogicCommon!C2="","",LogicCommon!C2) -> MS | G2: LogicID : | H2: =IF(LogicCommon!E2="","",LogicCommon!E2) -> MSLAL6220 | I2: Ope.ID : | J2: MfgActRecvIf_Upd02 | K2: Pj.ID : | L2: =IF(LogicCommon!G2="","",LogicCommon!G2) -> MC | M2: Ope.Body : | N2: "mcframe.serverMAUD.MAUDL5010.MAUDL_Operation"
A3: * | D3: =IF(LogicCommon!A3="","",LogicCommon!A3) | E3: SubModuleID : | F3: =IF(LogicCommon!C3="","",LogicCommon!C3) -> MSLA | G3: LogicClass : | H3: =IF(LogicCommon!E3="","",LogicCommon!E3) -> MSLAL_MfgActRecvIfService | I3: Ope.Method : | J3: @ | K3: SuperClassPj.ID : | L3: =IF(LogicCommon!G3="","",LogicCommon!G3) | O3: Gene.Type : | P3: ALL
A4: * | E4: Version : | F4: 000000 | G4: LogicName : | H4: =IF(LogicCommon!E4="","",LogicCommon!E4) -> 製造実績受信ＩＦサービス | I4: Ope.Name : | J4: 製造実績取込２ | K4: SuperLogicID : | L4: =IF(LogicCommon!G4="","",LogicCommon!G4) -> MS.MSUDL5010 | M4: ImplOpe.ID: | N4: MB.MBBEL5010.Upd01
A5: * | E5: ACType :
A6: * | D6: 概要 : | E6: 製造実績（工程・投入・工数・出来高）受信ＩＦ取込を行う。（ＩＦデータ確認、および製造実績受信ＩＦ取込バッチから呼び出される） | M6: ID | O6: ID | Q6: ID
A7: # | I7: U | K7: K | L7: o | N7: o | P7: o
A8: # | D8: ブロック名 Block Name | E8: 型 Type | G8: super/share | H8: 対象ブロック名 Target Block Name | L8: TargetName | N8: TargetName | P8: TargetName | T8: ブロック備考 Block Remarks
A9: # | D9: 項目名 Field Name | E9: 型 Type | F9: 桁 Digits | G9: フルネーム Full Name | H9: 日本語名 Japanese Name | I9: 上り項目 Request Message Field | J9: 下り項目 Response Message Field | R9: 条件および編集方法 Conditions and Editing Methods | T9: 項目備考 Field Remarks
A10: # | L10: 上り項目 Request Message Field | M10: 下り項目 Response Message Field | N10: 上り項目 Request Message Field | O10: 下り項目 Response Message Field | P10: 上り項目 Request Message Field | Q10: 下り項目 Response Message Field
A11: 10 | B11: * | D11: MfgActRecvIf_Upd02_Dtl | E11: L | G11: $share$ | H11: MB.MBBEL5010.Upd01.IfDataImp_Upd01_Dtl
A12: 10 | D12: data_lno | E12: #MA.IF_DATA_LNO | G12: Data row No. | H12: データ行ＮＯ | I12: E | J12: -
A13: 10 | D13: data_no | E13: #MA.IF_DATA_NO | G13: Data No. | H13: データＮＯ | I13: E | J13: -
A14: 10 | D14: ext_data_no | E14: #MA.IF_EXT_DATA_NO | G14: External system data No. | H14: 外部システムデータＮＯ | I14: E | J14: -
A15: 10 | D15: ext_sys_cd | E15: #MA.EXT_SYS_CD | G15: External system cd. | H15: 外部システムＣＤ | I15: E | J15: -
A16: 10 | D16: if_proc_typ | E16: #MA.IF_PROC_TYP | G16: IF process type | H16: ＩＦ処理区分 | I16: E | J16: -
L17: 上り項目 Request Message Field | M17: 下り項目 Response Message Field | N17: 上り項目 Request Message Field | O17: 下り項目 Response Message Field | P17: 上り項目 Request Message Field | Q17: 下り項目 Response Message Field
A18: 20 | B18: * | D18: MfgActRecvIf_Upd02_Cnd | E18: R | G18: $share$ | H18: MB.MBBEL5010.Upd01.IfDataImp_Upd01_Cnd
A19: 20 | D19: exe_unit_lump_flg | E19: #MA.FLG | G19: Process unit aggregation | H19: 処理単位まとめ | I19: E | J19: -
A20: 20 | D20: if_upd_typ | E20: #MA.IF_UPD_TYP | G20: IF update type | H20: ＩＦ更新区分 | I20: E | J20: -
A21: 20 | D21: src_actlumprecv_flg | E21: #MA.FLG | G21: Caller results import batch | H21: 呼出元実績一括受信バッチ | I21: E | J21: -
A22: 20 | D22: not_bkf_upd_flg | E22: #MA.FLG | G22: Not update BF | H22: ＢＦ更新しない | I22: E | J22: -
L23: 上り項目 Request Message Field | M23: 下り項目 Response Message Field | N23: 上り項目 Request Message Field | O23: 下り項目 Response Message Field | P23: 上り項目 Request Message Field | Q23: 下り項目 Response Message Field
A24: 30 | B24: * | D24: MfgActRecvIf_Upd02_Rslt | E24: R | G24: $share$ | H24: MB.MBBEL5010.Upd01.IfDataImp_Upd01_Rslt
A25: 30 | D25: total_num | E25: N | G25: Number of processed target | H25: 処理対象件数 | I25: - | J25: R
A26: 30 | D26: ok_num | E26: N | G26: Number of entries | H26: 登録件数 | I26: - | J26: R
A27: 30 | D27: err_num | E27: N | G27: Error count | H27: エラー件数 | I27: - | J27: R
A28: 30 | D28: skip_num | E28: N | G28: Skip count | H28: スキップ件数 | I28: - | J28: R
L29: 上り項目 Request Message Field | M29: 下り項目 Response Message Field | N29: 上り項目 Request Message Field | O29: 下り項目 Response Message Field | P29: 上り項目 Request Message Field | Q29: 下り項目 Response Message Field
A30: 40 | B30: * | D30: MfgActRecvIf_Upd02_ActLst | E30: L
A31: 40 | D31: err_flg | E31: #MA.FLG | G31: Error flg. | H31: エラーフラグ | I31: - | J31: -
A32: 40 | D32: if_proc_typ | E32: #MA.IF_PROC_TYP | G32: IF process type | H32: ＩＦ処理区分 | I32: - | J32: -
A33: 40 | D33: data_lno | E33: #MA.IF_DATA_LNO | G33: Data row No. | H33: データ行ＮＯ | I33: - | J33: -
A34: 40 | D34: data_no | E34: #MA.IF_DATA_NO | G34: Data No. | H34: データＮＯ | I34: - | J34: -
A35: 40 | D35: exe_sts_typ | E35: #MA.EXE_STS_TYP | G35: PG execution status type | H35: ＰＧ実行状況区分 | I35: - | J35: -
A36: 40 | D36: data_crud_typ | E36: #MA.DATA_CRUD_TYP | G36: Data update type | H36: データ更新区分 | I36: - | J36: -
A37: 40 | D37: ext_sys_cd | E37: #MA.EXT_SYS_CD | G37: External system cd. | H37: 外部システムＣＤ | I37: - | J37: -
A38: 40 | D38: ext_data_no | E38: #MA.IF_EXT_DATA_NO | G38: External system data No. | H38: 外部システムデータＮＯ | I38: - | J38: -
A39: 40 | D39: ext_data_lno | E39: #MA.IF_EXT_DATA_LNO | G39: External system data row No. | H39: 外部システムデータ行ＮＯ | I39: - | J39: -
A40: 40 | D40: data_make_dt | E40: #MA.TM | G40: Creation date and time of source record | H40: 送信元レコード作成日時 | I40: - | J40: -
...

Sheet MfgActRecvIf_Upd03
A1: * | B1: * | D1: L | E1: 1
A2: * | D2: オペレーション実装仕様書 Operation Specification Implementation Sheet | E2: ModuleID : | F2: =IF(LogicCommon!C2="","",LogicCommon!C2) -> MS | G2: LogicID : | H2: =IF(LogicCommon!E2="","",LogicCommon!E2) -> MSLAL6220 | I2: Ope.ID : | J2: MfgActRecvIf_Upd03 | K2: Pj.ID : | L2: =IF(LogicCommon!G2="","",LogicCommon!G2) -> MC | M2: Ope.Body : | N2: "mcframe.serverMAUD.MAUDL5010.MAUDL_Operation"
A3: * | D3: =IF(LogicCommon!A3="","",LogicCommon!A3) | E3: SubModuleID : | F3: =IF(LogicCommon!C3="","",LogicCommon!C3) -> MSLA | G3: LogicClass : | H3: =IF(LogicCommon!E3="","",LogicCommon!E3) -> MSLAL_MfgActRecvIfService | I3: Ope.Method : | J3: @ | K3: SuperClassPj.ID : | L3: =IF(LogicCommon!G3="","",LogicCommon!G3) | O3: Gene.Type : | P3: ALL
A4: * | E4: Version : | F4: 000000 | G4: LogicName : | H4: =IF(LogicCommon!E4="","",LogicCommon!E4) -> 製造実績受信ＩＦサービス | I4: Ope.Name : | J4: 製造実績取込３ | K4: SuperLogicID : | L4: =IF(LogicCommon!G4="","",LogicCommon!G4) -> MS.MSUDL5010 | M4: ImplOpe.ID:
A5: * | E5: ACType :
A6: * | D6: 概要 : | E6: 製造実績（工程・投入・工数・出来高）受信ＩＦ取込を行う。（マルチスレッド実行用） | M6: ID | O6: ID | Q6: ID
A7: # | I7: U | K7: K | L7: o | N7: o | P7: o
A8: # | D8: ブロック名 Block Name | E8: 型 Type | G8: super/share | H8: 対象ブロック名 Target Block Name | L8: TargetName | N8: TargetName | P8: TargetName | T8: ブロック備考 Block Remarks
A9: # | D9: 項目名 Field Name | E9: 型 Type | F9: 桁 Digits | G9: フルネーム Full Name | H9: 日本語名 Japanese Name | I9: 上り項目 Request Message Field | J9: 下り項目 Response Message Field | R9: 条件および編集方法 Conditions and Editing Methods | T9: 項目備考 Field Remarks
A10: # | L10: 上り項目 Request Message Field | M10: 下り項目 Response Message Field | N10: 上り項目 Request Message Field | O10: 下り項目 Response Message Field | P10: 上り項目 Request Message Field | Q10: 下り項目 Response Message Field
A11: 10 | B11: * | D11: MfgActRecvIf_Upd03_ActLst | E11: L | G11: $share$ | H11: MS.MSLAL6220.MfgActRecvIf_Upd02.MfgActRecvIf_Upd02_ActLst
A12: 10 | D12: err_flg | E12: #MA.FLG | G12: Error flg. | H12: エラーフラグ | I12: E | J12: -
A13: 10 | D13: if_proc_typ | E13: #MA.IF_PROC_TYP | G13: IF process type | H13: ＩＦ処理区分 | I13: E | J13: -
A14: 10 | D14: data_lno | E14: #MA.IF_DATA_LNO | G14: Data row No. | H14: データ行ＮＯ | I14: E | J14: -
A15: 10 | D15: data_no | E15: #MA.IF_DATA_NO | G15: Data No. | H15: データＮＯ | I15: E | J15: -
A16: 10 | D16: exe_sts_typ | E16: #MA.EXE_STS_TYP | G16: PG execution status type | H16: ＰＧ実行状況区分 | I16: E | J16: -
A17: 10 | D17: data_crud_typ | E17: #MA.DATA_CRUD_TYP | G17: Data update type | H17: データ更新区分 | I17: E | J17: -
A18: 10 | D18: ext_sys_cd | E18: #MA.EXT_SYS_CD | G18: External system cd. | H18: 外部システムＣＤ | I18: E | J18: -
A19: 10 | D19: ext_data_no | E19: #MA.IF_EXT_DATA_NO | G19: External system data No. | H19: 外部システムデータＮＯ | I19: E | J19: -
A20: 10 | D20: ext_data_lno | E20: #MA.IF_EXT_DATA_LNO | G20: External system data row No. | H20: 外部システムデータ行ＮＯ | I20: E | J20: -
A21: 10 | D21: data_make_dt | E21: #MA.TM | G21: Creation date and time of source record | H21: 送信元レコード作成日時 | I21: E | J21: -
A22: 10 | D22: imp_flg | E22: #MA.FLG | G22: To import | H22: 取込対象 | I22: E | J22: -
A23: 10 | D23: recv_dt | E23: #MA.DT | G23: Receiving date | H23: 受信日 | I23: E | J23: -
... A200: 10 | D200: wg_cd | E200: #MA.WG_CD | G200: WG cd. | H200: ワーキンググループＣＤ | I200: E | J200: -
L201: 上り項目 Request Message Field | M201: 下り項目 Response Message Field | N201: 上り項目 Request Message Field | O201: 下り項目 Response Message Field | P201: 上り項目 Request Message Field | Q201: 下り項目 Response Message Field
A202: 20 | B202: * | D202: MfgActRecvIf_Upd03_Cnd | E202: R | G202: $share$ | H202: MB.MBBEL5010.Upd01.IfDataImp_Upd01_Cnd
A203: 20 | D203: exe_unit_lump_flg | E203: #MA.FLG | G203: Process unit aggregation | H203: 処理単位まとめ | I203: - | J203: -
A204: 20 | D204: if_upd_typ | E204: #MA.IF_UPD_TYP | G204: IF update type | H204: ＩＦ更新区分 | I204: E | J204: -
A205: 20 | D205: src_actlumprecv_flg | E205: #MA.FLG | G205: Caller results import batch | H205: 呼出元実績一括受信バッチ | I205: E | J205: -
A206: 20 | D206: not_bkf_upd_flg | E206: #MA.FLG | G206: Not update BF | H206: ＢＦ更新しない | I206: E | J206: -
L207: 上り項目 Request Message Field | M207: 下り項目 Response Message Field | N207: 上り項目 Request Message Field | O207: 下り項目 Response Message Field | P207: 上り項目 Request Message Field | Q207: 下り項目 Response Message Field
A208: 30 | B208: * | D208: MfgActRecvIf_Upd03_Rslt | E208: R | G208: $share$ | H208: MB.MBBEL5010.Upd01.IfDataImp_Upd01_Rslt
A209: 30 | D209: total_num | E209: N | G209: Number of processed target | H209: 処理対象件数 | I209: - | J209: R
A210: 30 | D210: ok_num | E210: N | G210: Number of entries | H210: 登録件数 | I210: - | J210: R
A211: 30 | D211: err_num | E211: N | G211: Error count | H211: エラー件数 | I211: - | J211: R
A212: 30 | D212: skip_num | E212: N | G212: Skip count | H212: スキップ件数 | I212: - | J212: R
D213: 詳細 :

Sheet MfgActRecvIf_Upd04
A1: * | B1: * | D1: L | E1: 1
A2: * | D2: オペレーション実装仕様書 Operation Specification Implementation Sheet | E2: ModuleID : | F2: =IF(LogicCommon!C2="","",LogicCommon!C2) -> MS | G2: LogicID : | H2: =IF(LogicCommon!E2="","",LogicCommon!E2) -> MSLAL6220 | I2: Ope.ID : | J2: MfgActRecvIf_Upd04 | K2: Pj.ID : | L2: =IF(LogicCommon!G2="","",LogicCommon!G2) -> MC | M2: Ope.Body : | N2: "mcframe.serverMAUD.MAUDL5010.MAUDL_Operation"
A3: * | D3: =IF(LogicCommon!A3="","",LogicCommon!A3) | E3: SubModuleID : | F3: =IF(LogicCommon!C3="","",LogicCommon!C3) -> MSLA | G3: LogicClass : | H3: =IF(LogicCommon!E3="","",LogicCommon!E3) -> MSLAL_MfgActRecvIfService | I3: Ope.Method : | J3: @ | K3: SuperClassPj.ID : | L3: =IF(LogicCommon!G3="","",LogicCommon!G3) | O3: Gene.Type : | P3: ALL
A4: * | E4: Version : | F4: 000000 | G4: LogicName : | H4: =IF(LogicCommon!E4="","",LogicCommon!E4) -> 製造実績受信ＩＦサービス | I4: Ope.Name : | J4: 製造実績取込４ | K4: SuperLogicID : | L4: =IF(LogicCommon!G4="","",LogicCommon!G4) -> MS.MSUDL5010 | M4: ImplOpe.ID:
A5: * | E5: ACType :
A6: * | D6: 概要 : | E6: 製造実績（工程・投入・工数・出来高）受信ＩＦ取込を行う。（製造実績受信ＩＦサービスを呼び出す本処理） | M6: ID | O6: ID | Q6: ID
A7: # | I7: U | K7: K | L7: o | N7: o | P7: o
A8: # | D8: ブロック名 Block Name | E8: 型 Type | G8: super/share | H8: 対象ブロック名 Target Block Name | L8: TargetName | N8: TargetName | P8: TargetName | T8: ブロック備考 Block Remarks
A9: # | D9: 項目名 Field Name | E9: 型 Type | F9: 桁 Digits | G9: フルネーム Full Name | H9: 日本語名 Japanese Name | I9: 上り項目 Request Message Field | J9: 下り項目 Response Message Field | R9: 条件および編集方法 Conditions and Editing Methods | T9: 項目備考 Field Remarks
A10: # | L10: 上り項目 Request Message Field | M10: 下り項目 Response Message Field | N10: 上り項目 Request Message Field | O10: 下り項目 Response Message Field | P10: 上り項目 Request Message Field | Q10: 下り項目 Response Message Field
A11: 10 | B11: * | D11: MfgActRecvIf_Upd04_ActLst | E11: L | G11: $share$ | H11: MS.MSLAL6220.MfgActRecvIf_Upd02.MfgActRecvIf_Upd02_ActLst
A12: 10 | D12: err_flg | E12: #MA.FLG | G12: Error flg. | H12: エラーフラグ | I12: E | J12: E
A13: 10 | D13: if_proc_typ | E13: #MA.IF_PROC_TYP | G13: IF process type | H13: ＩＦ処理区分 | I13: E | J13: E
A14: 10 | D14: data_lno | E14: #MA.IF_DATA_LNO | G14: Data row No. | H14: データ行ＮＯ | I14: E | J14: E
A15: 10 | D15: data_no | E15: #MA.IF_DATA_NO | G15: Data No. | H15: データＮＯ | I15: E | J15: E
A16: 10 | D16: exe_sts_typ | E16: #MA.EXE_STS_TYP | G16: PG execution status type | H16: ＰＧ実行状況区分 | I16: E | J16: E
A17: 10 | D17: data_crud_typ | E17: #MA.DATA_CRUD_TYP | G17: Data update type | H17: データ更新区分 | I17: E | J17: E
A18: 10 | D18: ext_sys_cd | E18: #MA.EXT_SYS_CD | G18: External system cd. | H18: 外部システムＣＤ | I18: E | J18: E
A19: 10 | D19: ext_data_no | E19: #MA.IF_EXT_DATA_NO | G19: External system data No. | H19: 外部システムデータＮＯ | I19: E | J19: E
A20: 10 | D20: ext_data_lno | E20: #MA.IF_EXT_DATA_LNO | G20: External system data row No. | H20: 外部システムデータ行ＮＯ | I20: E | J20: E
A21: 10 | D21: data_make_dt | E21: #MA.TM | G21: Creation date and time of source record | H21: 送信元レコード作成日時 | I21: E | J21: -
A22: 10 | D22: imp_flg | E22: #MA.FLG | G22: To import | H22: 取込対象 | I22: E | J22: -
A23: 10 | D23: recv_dt | E23: #MA.DT | G23: Receiving date | H23: 受信日 | I23: E | J23: -
... A200: 10 | D200: wg_cd | E200: #MA.WG_CD | G200: WG cd. | H200: ワーキンググループＣＤ | I200: E | J200: -
L201: 上り項目 Request Message Field | M201: 下り項目 Response Message Field | N201: 上り項目 Request Message Field | O201: 下り項目 Response Message Field | P201: 上り項目 Request Message Field | Q201: 下り項目 Response Message Field
A202: 20 | B202: * | D202: MfgActRecvIf_Upd04_Cnd | E202: R | G202: $share$ | H202: MB.MBBEL5010.Upd01.IfDataImp_Upd01_Cnd
A203: 20 | D203: exe_unit_lump_flg | E203: #MA.FLG | G203: Process unit aggregation | H203: 処理単位まとめ | I203: - | J203: -
A204: 20 | D204: if_upd_typ | E204: #MA.IF_UPD_TYP | G204: IF update type | H204: ＩＦ更新区分 | I204: E | J204: -
A205: 20 | D205: src_actlumprecv_flg | E205: #MA.FLG | G205: Caller results import batch | H205: 呼出元実績一括受信バッチ | I205: E | J205: -
A206: 20 | D206: not_bkf_upd_flg | E206: #MA.FLG | G206: Not update BF | H206: ＢＦ更新しない | I206: E | J206: -
D207: 詳細 :

Sheet MfgActRecvIf_Chk01
A1: * | B1: * | D1: L | E1: 1
A2: * | D2: オペレーション実装仕様書 Operation Specification Implementation Sheet | E2: ModuleID : | F2: =IF(LogicCommon!C2="","",LogicCommon!C2) -> MS | G2: LogicID : | H2: =IF(LogicCommon!E2="","",LogicCommon!E2) -> MSLAL6220 | I2: Ope.ID : | J2: MfgActRecvIf_Chk01 | K2: Pj.ID : | L2: =IF(LogicCommon!G2="","",LogicCommon!G2) -> MC | M2: Ope.Body : | N2: MA.MAUDL5010.Checker
A3: * | D3: =IF(LogicCommon!A3="","",LogicCommon!A3) | E3: SubModuleID : | F3: =IF(LogicCommon!C3="","",LogicCommon!C3) -> MSLA | G3: LogicClass : | H3: =IF(LogicCommon!E3="","",LogicCommon!E3) -> MSLAL_MfgActRecvIfService | I3: Ope.Method : | J3: @ | K3: SuperClassPj.ID : | L3: =IF(LogicCommon!G3="","",LogicCommon!G3) | O3: Gene.Type : | P3: ALL
A4: * | E4: Version : | F4: 000000 | G4: LogicName : | H4: =IF(LogicCommon!E4="","",LogicCommon!E4) -> 製造実績受信ＩＦサービス | I4: Ope.Name : | J4: 取込前チェック | K4: SuperLogicID : | L4: =IF(LogicCommon!G4="","",LogicCommon!G4) -> MS.MSUDL5010 | M4: ImplOpe.ID:
A5: * | E5: ACType :
A6: * | D6: 概要 : | E6: 製造実績（工程・投入・工数・出来高）受信ＩＦ取込を行う前のチェック処理 | M6: ID | O6: ID | Q6: ID | AD6: ID | AF6: ID
A7: # | I7: U | K7: K | L7: K | M7: K | N7: K | O7: K | P7: K | Q7: K | R7: K | S7: K | T7: K | U7: K | V7: K | W7: K | X7: K | Y7: K | Z7: K | AA7: K | AB7: K | AC7: o | AE7: o
A8: # | D8: ブロック名 Block Name | E8: 型 Type | G8: super/share | H8: 対象ブロック名 Target Block Name | K8: REQ_UPD_CNT_CHK | L8: REQUIRED | M8: CHK_NUM | N8: SMALL_LARGE | O8: CHK_DT | P8: BEFORE_AFTER | Q8: CHK_PTN | R8: DUPLICATE | S8: TOO_MANY_INPUTS | T8: AT_LEAST_ONE | U8: ONLY_ONE_INPUT | V8: LIST_LOGIC | W8: LIST_OUT | X8: LIST_OUT_BASE | Y8: LIST_IN | Z8: LIST_IN_BASE | AA8: CONST | AB8: NULL_VAL | AC8: TargetName | AE8: TargetName | AI8: ブロック備考 Block Remarks
A9: # | D9: 項目名 Field Name | E9: 型 Type | F9: 桁 Digits | G9: フルネーム Full Name | H9: 日本語名 Japanese Name | I9: 上り項目 Request Message Field | J9: 下り項目 Response Message Field | AG9: 条件および編集方法 Conditions and Editing Methods | AI9: 項目備考 Field Remarks
A10: #
A11: 10 | B11: * | D11: MfgActRecvIf_Chk01_ActLst | E11: L | G11: $share$ | H11: MS.MSLAL6220.MfgActRecvIf_Upd02.MfgActRecvIf_Upd02_ActLst | AC11: 上り項目 | AD11: 下り項目 | AE11: 上り項目 | AF11: 下り項目
A12: 10 | D12: err_flg | E12: #MA.FLG | G12: Error flg. | H12: エラーフラグ | I12: E | J12: E
A13: 10 | D13: if_proc_typ | E13: #MA.IF_PROC_TYP | G13: IF process type | H13: ＩＦ処理区分 | I13: E | J13: E
A14: 10 | D14: data_lno | E14: #MA.IF_DATA_LNO | G14: Data row No. | H14: データ行ＮＯ | I14: E | J14: E
A15: 10 | D15: data_no | E15: #MA.IF_DATA_NO | G15: Data No. | H15: データＮＯ | I15: E | J15: E
A16: 10 | D16: exe_sts_typ | E16: #MA.EXE_STS_TYP | G16: PG execution status type | H16: ＰＧ実行状況区分 | I16: E | J16: E
A17: 10 | D17: data_crud_typ | E17: #MA.DATA_CRUD_TYP | G17: Data update type | H17: データ更新区分 | I17: E | J17: E | L17: E | AA17: MAC_DATA_CRUD_TYP
A18: 10 | D18: ext_sys_cd | E18: #MA.EXT_SYS_CD | G18: External system cd. | H18: 外部システムＣＤ | I18: E | J18: E
A19: 10 | D19: ext_data_no | E19: #MA.IF_EXT_DATA_NO | G19: External system data No. | H19: 外部システムデータＮＯ | I19: E | J19: E
A20: 10 | D20: ext_data_lno | E20: #MA.IF_EXT_DATA_LNO | G20: External system data row No. | H20: 外部システムデータ行ＮＯ | I20: E | J20: E
A21: 10 | D21: data_make_dt | E21: #MA.TM | G21: Creation date and time of source record | H21: 送信元レコード作成日時 | I21: E | J21: E
A22: 10 | D22: imp_flg | E22: #MA.FLG | G22: To import | H22: 取込対象 | I22: E | J22: E
A23: 10 | D23: recv_dt | E23: #MA.DT | G23: Receiving date | H23: 受信日 | I23: E | J23: E
A24: 10 | D24: oper_inst_no | E24: #MA.OPER_INST_NO | G24: Operation order No. | H24: 工程指図ＮＯ | I24: E | J24: E
A25: 10 | D25: mfg_inst_no | E25: #MA.MFG_INST_NO | G25: Mfg. order No. | H25: 製造指図ＮＯ | I25: E | J25: E
A26: 10 | D26: oper_act_no | E26: #MA.OPER_ACT_NO | G26: Operation result No. | H26: 工程実績ＮＯ | I26: E | J26: E
A27: 10 | D27: mfg_act_no | E27: #MA.MFG_ACT_NO | G27: Mfg. result No. | H27: 製造実績ＮＯ | I27: E | J27: E
A28: 10 | D28: mfg_inst_rev | E28: #MA.SLIP_REV | G28: Mfg. order rev. number | H28: 製造指図改訂番号 | I28: E | J28: E
A29: 10 | D29: div_seq | E29: #MS.DIV_SEQ | G29: Split sequence number | H29: 分割連番 | I29: E | J29: E
A30: 10 | D30: oper_cd | E30: #MA.OPER_CD | G30: Operation cd. | H30: 工程ＣＤ | I30: E | J30: E
A31: 10 | D31: oper_seq | E31: #MA.OPER_SEQ | G31: Operation sequence number | H31: 工程連番 | I31: E | J31: E | N31: 1:
A32: 10 | D32: ext_oper_act_no | E32: #MA.EXT_OPER_ACT_NO | G32: External operation result No. | H32: 外部工程実績ＮＯ | I32: E | J32: E
A33: 10 | D33: intr_rmrks | E33: #MS.OPER_ACT_INTR_RMRKS | G33: Operation internal remarks | H33: 工程内部備考 | I33: E | J33: E
A34: 10 | D34: act_rpt_rmrks | E34: #MS.OPER_ACT_RPT_RMRKS | G34: Operation record sheet remarks | H34: 工程記録書備考 | I34: E | J34: E
A35: 10 | D35: act_intr_rmrks | E35: #MS.INPT_ACT_INTR_RMRKS | G35: Input internal remarks | H35: 投入内部備考 | I35: E | J35: E
A36: 10 | D36: inpt_act_rpt_rmrks | E36: #MS.INPT_ACT_RPT_RMRKS | G36: Input record sheet remarks | H36: 投入記録書備考 | I36: E | J36: E
A37: 10 | D37: act_trd_rmrks | E37: #MA.TRD_RMRKS | G37: Input transaction remarks | H37: 投入取引備考 | I37: E | J37: E
A38: 10 | D38: wk_intr_rmrks | E38: #MS.WK_ACT_INTR_RMRKS | G38: Man-hour internal remarks | H38: 工数内部備考 | I38: E | J38: E
A39: 10 | D39: mfg_act_intr_rmrks | E39: #MS.MFG_ACT_INTR_RMRKS | G39: Mfg. internal remarks | H39: 製造内部備考 | I39: E | J39: E
A40: 10 | D40: mfg_act_rpt_rmrks | E40: #MS.MFG_ACT_RPT_RMRKS | G40: Mfg. record sheet remarks | H40: 製造記録書備考 | I40: E | J40: E
...

Sheet MfgActRecvIf_Chk02
A1: * | B1: * | D1: L | E1: 1
A2: * | D2: オペレーション実装仕様書 Operation Specification Implementation Sheet | E2: ModuleID : | F2: =IF(LogicCommon!C2="","",LogicCommon!C2) -> MS | G2: LogicID : | H2: =IF(LogicCommon!E2="","",LogicCommon!E2) -> MSLAL6220 | I2: Ope.ID : | J2: MfgActRecvIf_Chk02 | K2: Pj.ID : | L2: =IF(LogicCommon!G2="","",LogicCommon!G2) -> MC | M2: Ope.Body : | N2: MA.MAUDL5010.Checker
A3: * | D3: =IF(LogicCommon!A3="","",LogicCommon!A3) | E3: SubModuleID : | F3: =IF(LogicCommon!C3="","",LogicCommon!C3) -> MSLA | G3: LogicClass : | H3: =IF(LogicCommon!E3="","",LogicCommon!E3) -> MSLAL_MfgActRecvIfService | I3: Ope.Method : | J3: @ | K3: SuperClassPj.ID : | L3: =IF(LogicCommon!G3="","",LogicCommon!G3) | O3: Gene.Type : | P3: ALL
A4: * | E4: Version : | F4: 000000 | G4: LogicName : | H4: =IF(LogicCommon!E4="","",LogicCommon!E4) -> 製造実績受信ＩＦサービス | I4: Ope.Name : | J4: 計画外実績登録チェック | K4: SuperLogicID : | L4: =IF(LogicCommon!G4="","",LogicCommon!G4) -> MS.MSUDL5010 | M4: ImplOpe.ID:
A5: * | E5: ACType :
A6: * | D6: 概要 : | E6: 計画外実績登録チェック | M6: ID | O6: ID | Q6: ID | AD6: ID | AF6: ID
A7: # | I7: U | K7: K | L7: K | M7: K | N7: K | O7: K | P7: K | Q7: K | R7: K | S7: K | T7: K | U7: K | V7: K | W7: K | X7: K | Y7: K | Z7: K | AA7: K | AB7: K | AC7: o | AE7: o
A8: # | D8: ブロック名 Block Name | E8: 型 Type | G8: super/share | H8: 対象ブロック名 Target Block Name | K8: REQ_UPD_CNT_CHK | L8: REQUIRED | M8: CHK_NUM | N8: SMALL_LARGE | O8: CHK_DT | P8: BEFORE_AFTER | Q8: CHK_PTN | R8: DUPLICATE | S8: TOO_MANY_INPUTS | T8: AT_LEAST_ONE | U8: ONLY_ONE_INPUT | V8: LIST_LOGIC | W8: LIST_OUT | X8: LIST_OUT_BASE | Y8: LIST_IN | Z8: LIST_IN_BASE | AA8: CONST | AB8: NULL_VAL | AC8: TargetName | AE8: TargetName | AI8: ブロック備考 Block Remarks
A9: # | D9: 項目名 Field Name | E9: 型 Type | F9: 桁 Digits | G9: フルネーム Full Name | H9: 日本語名 Japanese Name | I9: 上り項目 Request Message Field | J9: 下り項目 Response Message Field | AG9: 条件および編集方法 Conditions and Editing Methods | AI9: 項目備考 Field Remarks
A10: #
A11: 10 | B11: * | D11: MfgActRecvIf_Chk02_ActLst | E11: L | AC11: 上り項目 | AD11: 下り項目 | AE11: 上り項目 | AF11: 下り項目
A12: 10 | D12: err_flg | E12: #MA.FLG | G12: Error flg. | H12: エラーフラグ | I12: E | J12: E
A13: 10 | D13: data_lno | E13: #MA.IF_DATA_LNO | G13: Data row No. | H13: データ行ＮＯ | I13: E | J13: -
A14: 10 | D14: data_no | E14: #MA.IF_DATA_NO | G14: Data No. | H14: データＮＯ | I14: E | J14: -
A15: 10 | D15: data_crud_typ | E15: #MA.DATA_CRUD_TYP | G15: Data update type | H15: データ更新区分 | I15: E | J15: - | L15: E | AA15: MAC_DATA_CRUD_TYP
A16: 10 | D16: ext_sys_cd | E16: #MA.EXT_SYS_CD | G16: External system cd. | H16: 外部システムＣＤ | I16: E | J16: -
A17: 10 | D17: recv_dt | E17: #MA.DT | G17: Receiving date | H17: 受信日 | I17: E | J17: -
A18: 10 | D18: unschd_act_flg | E18: #MA.FLG | G18: Unplanned result | H18: 計画外実績 | I18: E | J18: -
A19: 10 | D19: yield_schd_no | E19: #MA.YIELD_INST_NO | G19: Output schedule No. | H19: 出来高予定ＮＯ | I19: E | J19: -
A20: 10 | D20: oper_inst_no | E20: #MA.OPER_INST_NO | G20: Operation order No. | H20: 工程指図ＮＯ | I20: E | J20: -
A21: 10 | D21: mfg_inst_no | E21: #MA.MFG_INST_NO | G21: Mfg. order No. | H21: 製造指図ＮＯ | I21: E | J21: -
A22: 10 | D22: mfg_inst_rev | E22: #MA.SLIP_REV | G22: Mfg. order rev. number | H22: 製造指図改訂番号 | I22: E | J22: -
A23: 10 | D23: mfg_loc_cd | E23: #MA.LOC_CD | G23: Mfg. location cd. | H23: 製造場所ＣＤ | I23: E | J23: - | L23: E | V23: MA.MAUAL0010.Loc | W23: wg_cd;sppl_cd;site_cd | X23: wg_cd;sppl_cd;site_cd | Y23: act_tm;mfg_itm_cd;mfg_itm_sub1;mfg_itm_sub2;mfg_itm_sub3 | Z23: master_dt;itm_cd;itm_sub1;itm_sub2;itm_sub3
A24: 10 | D24: mfg_str_ln_cd | E24: #MA.STR_LN_CD | G24: Mfg. rack/line cd. | H24: 製造棚・ラインＣＤ | I24: E | J24: - | V24: MA.MAUAL0010.StrLn | Y24: mfg_loc_cd;true | Z24: loc_cd;mode_nullval_flg
A25: 10 | D25: bom_ptn | E25: #MA.BOM_PTN | G25: BOM pattern | H25: 構成パタン | I25: E | J25: - | L25: E | V25: MS.MSUAL0040.ItmDtlBomPtn | Y25: act_tm;mfg_itm_cd;mfg_itm_sub1;mfg_itm_sub2;mfg_itm_sub3;wg_cd;mfg_loc_cd;MAC_STR.NULL_VAL;MAC_STR.NULL_VAL;MAC_STR.NULL_VAL | Z25: dt;itm_cd;itm_sub1;itm_sub2;itm_sub3;wg_cd;mfg_loc_cd;sppl_cd;maker_cd;rqst_loc_cd
A26: 10 | D26: mfg_itm_cd | E26: #MA.ITM_CD | G26: Mfg. item cd. | H26: 製造品目ＣＤ | I26: E | J26: - | L26: E
A27: 10 | D27: mfg_itm_sub1 | E27: #MA.ITM_SUB1 | G27: Mfg. item branch No. 1 | H27: 製造品目枝番１ | I27: E | J27: - | L27: E | AB27: E
A28: 10 | D28: mfg_itm_sub2 | E28: #MA.ITM_SUB2 | G28: Mfg. item branch No. 2 | H28: 製造品目枝番２ | I28: E | J28: - | L28: E | AB28: E
A29: 10 | D29: mfg_itm_sub3 | E29: #MA.ITM_SUB3 | G29: Mfg. item branch No. 3 | H29: 製造品目枝番３ | I29: E | J29: - | L29: E | V29: MA.MAUAL0010.ItmSub3 | W29: lot_mng_typ;lot_no_typ;lot_no_ptn_cd;sublot_mng_typ;sublot_no_typ;sublot_no_ptn_cd;sno1_mng_typ;sno2_mng_typ;sno3_mng_typ;sno4_mng_typ | X29: lot_mng_typ;lot_no_typ;lot_no_ptn_cd;sublot_mng_typ;sublot_no_typ;sublot_no_ptn_cd;sno1_mng_typ;sno2_mng_typ;sno3_mng_typ;sno4_mng_typ | Y29: mfg_itm_cd;mfg_itm_sub1;mfg_itm_sub2 | Z29: itm_cd;itm_sub1;itm_sub2 | AB29: E
A30: 10 | D30: trd_unit_qty | E30: #MA.QTY | G30: Transaction unit qty. | H30: 取引単位数量 | I30: E | J30: - | L30: E | M30: positive
A31: 10 | D31: trd_unit_cd | E31: #MA.UNIT_CD | G31: Transaction unit cd. | H31: 取引単位ＣＤ | I31: E | J31: - | L31: E | V31: MA.MAUAL0010.ItmUnit | Y31: mfg_itm_cd;mfg_itm_sub1;mfg_itm_sub2;mfg_itm_sub3 | Z31: itm_cd;itm_sub1;itm_sub2;itm_sub3
A32: 10 | D32: oper_ptn | E32: #MA.OPER_PTN | G32: Operation pattern | H32: 工程パタン | I32: E | J32: - | V32: MA.MAUAL0010.ItmOper | Y32: mfg_itm_cd;mfg_itm_sub1;mfg_itm_sub2;mfg_itm_sub3;mfg_loc_cd;act_tm;true | Z32: itm_cd;itm_sub1;itm_sub2;itm_sub3;loc_cd;dt;mode_nullval_flg | AB32: E
A33: 10 | D33: yield_typ | E33: #MA.YIELD_TYP | G33: Output type | H33: 出来高区分 | I33: E | J33: - | AA33: MAC_YIELD_TYP
A34: 10 | D34: yield_rate | E34: #MA.RATE | G34: Output progress | H34: 出来高進捗度 | I34: E | J34: -
A35: 10 | D35: lot_no | E35: #MA.LOT_NO | G35: Lot No. | H35: ロットＮＯ | I35: E | J35: - | AB35: E
A36: 10 | D36: sublot_no | E36: #MA.SUBLOT_NO | G36: Sublot No. | H36: サブロットＮＯ | I36: E | J36: - | AB36: E
A37: 10 | D37: sno1 | E37: #MA.SNO1 | G37: SEIBAN No. 1 | H37: 手配ＮＯ１ | I37: E | J37: - | AB37: E
A38: 10 | D38: sno2 | E38: #MA.SNO2 | G38: SEIBAN No. 2 | H38: 手配ＮＯ２ | I38: E | J38: - | AB38: E
A39: 10 | D39: sno3 | E39: #MA.SNO3 | G39: SEIBAN No. 3 | H39: 手配ＮＯ３ | I39: E | J39: - | AB39: E
A40: 10 | D40: sno4 | E40: #MA.SNO4 | G40: SEIBAN No. 4 | H40: 手配ＮＯ４ | I40: E | J40: - | AB40: E
...

Sheet 来歴
A1: 変更来歴
A3: Rev. | H3: 修正番号 | O3: 変更内容 | AQ3: 変更箇所
A4: 1 | O4: 初版
A5: 1.1 | O5: 英語の名称を追記 | AQ5: 全般
