Workbook

Sheet LogicCommon
A2: オペレーション実装仕様書 | B2: ModuleID : | C2: MS | D2: LogicID : | E2: MSLAL6020 | F2: Pj.ID : | G2: MC
B3: SubModuleID : | C3: MSLA | D3: LogicClass : | E3: MSLAL_ShipActRecvIfService | F3: SuperClassPj.ID :
D4: LogicName : | E4: 出荷実績受信ＩＦサービス | F4: SuperLogicID : | G4: MS.MSUDL5010
A5: 概要 : | B5: ＷＭＳで出荷実績を取り込むための処理を提供する
A6: 詳細 :

Sheet ShipActRecvIf_Upd01
A1: * | B1: * | D1: L | E1: 1
A2: * | D2: オペレーション実装仕様書 Operation Specification Implementation Sheet | E2: ModuleID : | F2: =IF(LogicCommon!C2="","",LogicCommon!C2) -> MS | G2: LogicID : | H2: =IF(LogicCommon!E2="","",LogicCommon!E2) -> MSLAL6020 | I2: Ope.ID : | J2: ShipActRecvIf_Upd01 | K2: Pj.ID : | L2: =IF(LogicCommon!G2="","",LogicCommon!G2) -> MC | M2: Ope.Body : | N2: "mcframe.serverMAUD.MAUDL5010.MAUDL_Operation"
A3: * | D3: =IF(LogicCommon!A3="","",LogicCommon!A3) | E3: SubModuleID : | F3: =IF(LogicCommon!C3="","",LogicCommon!C3) -> MSLA | G3: LogicClass : | H3: =IF(LogicCommon!E3="","",LogicCommon!E3) -> MSLAL_ShipActRecvIfService | I3: Ope.Method : | J3: @ | K3: SuperClassPj.ID : | L3: =IF(LogicCommon!G3="","",LogicCommon!G3) | O3: Gene.Type : | P3: ALL
A4: * | E4: Version : | F4: 000000 | G4: LogicName : | H4: =IF(LogicCommon!E4="","",LogicCommon!E4) -> 出荷実績受信ＩＦサービス | I4: Ope.Name : | J4: 出荷実績取込１ | K4: SuperLogicID : | L4: =IF(LogicCommon!G4="","",LogicCommon!G4) -> MS.MSUDL5010 | M4: ImplOpe.ID: | N4: PF.PFUDL0040.Upd01
A5: * | E5: ACType :
A6: * | D6: 概要 : | E6: 出荷実績受信ＩＦ取込を行う。（ＥＳＢのリアルタイム取込から呼び出される） | M6: ID | O6: ID | Q6: ID
A7: # | I7: U | K7: K | L7: o | N7: o | P7: o
A8: # | D8: ブロック名 Block Name | E8: 型 Type | G8: super/share | H8: 対象ブロック名 Target Block Name | L8: TargetName | N8: TargetName | P8: TargetName | T8: ブロック備考 Block Remarks
A9: # | D9: 項目名 Field Name | E9: 型 Type | F9: 桁 Digits | G9: フルネーム Full Name | H9: 日本語名 Japanese Name | I9: 上り項目 Request Message Field | J9: 下り項目 Response Message Field | R9: 条件および編集方法 Conditions and Editing Methods | T9: 項目備考 Field Remarks
A10: # | L10: 上り項目 Request Message Field | M10: 下り項目 Response Message Field | N10: 上り項目 Request Message Field | O10: 下り項目 Response Message Field | P10: 上り項目 Request Message Field | Q10: 下り項目 Response Message Field
A11: 10 | B11: * | D11: ShipActRecvIf_Upd01_Dtl | E11: L | G11: $share$ | H11: PF.PFUDL0040.Upd01.Upd01_Dtl
A12: 10 | D12: data_no | E12: #MA.IF_DATA_NO | G12: Data No. | H12: データＮＯ | I12: E | J12: -
A13: 10 | D13: ext_data_no | E13: #MA.IF_EXT_DATA_NO | G13: External system data No. | H13: 外部システムデータＮＯ | I13: E | J13: -
A14: 10 | D14: ext_sys_cd | E14: #MA.EXT_SYS_CD | G14: External system cd. | H14: 外部システムＣＤ | I14: E | J14: -
D15: 詳細 :

Sheet ShipActRecvIf_Upd02
A1: * | B1: * | D1: L | E1: 1
A2: * | D2: オペレーション実装仕様書 Operation Specification Implementation Sheet | E2: ModuleID : | F2: =IF(LogicCommon!C2="","",LogicCommon!C2) -> MS | G2: LogicID : | H2: =IF(LogicCommon!E2="","",LogicCommon!E2) -> MSLAL6020 | I2: Ope.ID : | J2: ShipActRecvIf_Upd02 | K2: Pj.ID : | L2: =IF(LogicCommon!G2="","",LogicCommon!G2) -> MC | M2: Ope.Body : | N2: "mcframe.serverMAUD.MAUDL5010.MAUDL_Operation"
A3: * | D3: =IF(LogicCommon!A3="","",LogicCommon!A3) | E3: SubModuleID : | F3: =IF(LogicCommon!C3="","",LogicCommon!C3) -> MSLA | G3: LogicClass : | H3: =IF(LogicCommon!E3="","",LogicCommon!E3) -> MSLAL_ShipActRecvIfService | I3: Ope.Method : | J3: @ | K3: SuperClassPj.ID : | L3: =IF(LogicCommon!G3="","",LogicCommon!G3) | O3: Gene.Type : | P3: ALL
A4: * | E4: Version : | F4: 000000 | G4: LogicName : | H4: =IF(LogicCommon!E4="","",LogicCommon!E4) -> 出荷実績受信ＩＦサービス | I4: Ope.Name : | J4: 出荷実績取込２ | K4: SuperLogicID : | L4: =IF(LogicCommon!G4="","",LogicCommon!G4) -> MS.MSUDL5010 | M4: ImplOpe.ID: | N4: MB.MBBEL5010.Upd01
A5: * | E5: ACType :
A6: * | D6: 概要 : | E6: 出荷実績受信ＩＦ取込を行う。（ＩＦデータ確認、および出荷実績受信ＩＦ取込バッチから呼び出される） | M6: ID | O6: ID | Q6: ID
A7: # | I7: U | K7: K | L7: o | N7: o | P7: o
A8: # | D8: ブロック名 Block Name | E8: 型 Type | G8: super/share | H8: 対象ブロック名 Target Block Name | L8: TargetName | N8: TargetName | P8: TargetName | T8: ブロック備考 Block Remarks
A9: # | D9: 項目名 Field Name | E9: 型 Type | F9: 桁 Digits | G9: フルネーム Full Name | H9: 日本語名 Japanese Name | I9: 上り項目 Request Message Field | J9: 下り項目 Response Message Field | R9: 条件および編集方法 Conditions and Editing Methods | T9: 項目備考 Field Remarks
A10: # | L10: 上り項目 Request Message Field | M10: 下り項目 Response Message Field | N10: 上り項目 Request Message Field | O10: 下り項目 Response Message Field | P10: 上り項目 Request Message Field | Q10: 下り項目 Response Message Field
A11: 10 | B11: * | D11: ShipActRecvIf_Upd01_Dtl | E11: L | G11: $share$ | H11: MB.MBBEL5010.Upd01.IfDataImp_Upd01_Dtl
A12: 10 | D12: data_lno | E12: #MA.IF_DATA_LNO | G12: Data row No. | H12: データ行ＮＯ | I12: E | J12: -
A13: 10 | D13: data_no | E13: #MA.IF_DATA_NO | G13: Data No. | H13: データＮＯ | I13: E | J13: -
A14: 10 | D14: ext_data_no | E14: #MA.IF_EXT_DATA_NO | G14: External system data No. | H14: 外部システムデータＮＯ | I14: E | J14: -
A15: 10 | D15: ext_sys_cd | E15: #MA.EXT_SYS_CD | G15: External system cd. | H15: 外部システムＣＤ | I15: E | J15: -
L16: 上り項目 Request Message Field | M16: 下り項目 Response Message Field | N16: 上り項目 Request Message Field | O16: 下り項目 Response Message Field | P16: 上り項目 Request Message Field | Q16: 下り項目 Response Message Field
A17: 20 | B17: * | D17: ShipActRecvIf_Upd02_Cnd | E17: R | G17: $share$ | H17: MB.MBBEL5010.Upd01.IfDataImp_Upd01_Cnd
A18: 20 | D18: exe_unit_lump_flg | E18: #MA.FLG | G18: Process unit aggregation | H18: 処理単位まとめ | I18: E | J18: -
A19: 20 | D19: if_upd_typ | E19: #MA.IF_UPD_TYP | G19: IF update type | H19: ＩＦ更新区分 | I19: E | J19: -
A20: 20 | D20: src_actlumprecv_flg | E20: #MA.FLG | G20: Caller results import batch | H20: 呼出元実績一括受信バッチ | I20: E | J20: -
L21: 上り項目 Request Message Field | M21: 下り項目 Response Message Field | N21: 上り項目 Request Message Field | O21: 下り項目 Response Message Field | P21: 上り項目 Request Message Field | Q21: 下り項目 Response Message Field
A22: 30 | B22: * | D22: ShipActRecvIf_Upd02_Rslt | E22: R | G22: $share$ | H22: MB.MBBEL5010.Upd01.IfDataImp_Upd01_Rslt
A23: 30 | D23: total_num | E23: N | G23: Number of processed target | H23: 処理対象件数 | I23: - | J23: E
A24: 30 | D24: ok_num | E24: N | G24: Number of entries | H24: 登録件数 | I24: - | J24: E
A25: 30 | D25: err_num | E25: N | G25: Error count | H25: エラー件数 | I25: - | J25: E
A26: 30 | D26: skip_num | E26: N | G26: Skip count | H26: スキップ件数 | I26: - | J26: E
D27: 詳細 :

Sheet ShipActRecvIf_Upd03
A1: * | B1: * | D1: L | E1: 1
A2: * | D2: オペレーション実装仕様書 Operation Specification Implementation Sheet | E2: ModuleID : | F2: =IF(LogicCommon!C2="","",LogicCommon!C2) -> MS | G2: LogicID : | H2: =IF(LogicCommon!E2="","",LogicCommon!E2) -> MSLAL6020 | I2: Ope.ID : | J2: ShipActRecvIf_Upd03 | K2: Pj.ID : | L2: =IF(LogicCommon!G2="","",LogicCommon!G2) -> MC | M2: Ope.Body : | N2: "mcframe.serverMAUD.MAUDL5010.MAUDL_Operation"
A3: * | D3: =IF(LogicCommon!A3="","",LogicCommon!A3) | E3: SubModuleID : | F3: =IF(LogicCommon!C3="","",LogicCommon!C3) -> MSLA | G3: LogicClass : | H3: =IF(LogicCommon!E3="","",LogicCommon!E3) -> MSLAL_ShipActRecvIfService | I3: Ope.Method : | J3: @ | K3: SuperClassPj.ID : | L3: =IF(LogicCommon!G3="","",LogicCommon!G3) | O3: Gene.Type : | P3: ALL
A4: * | E4: Version : | F4: 000000 | G4: LogicName : | H4: =IF(LogicCommon!E4="","",LogicCommon!E4) -> 出荷実績受信ＩＦサービス | I4: Ope.Name : | J4: 出荷実績取込３ | K4: SuperLogicID : | L4: =IF(LogicCommon!G4="","",LogicCommon!G4) -> MS.MSUDL5010 | M4: ImplOpe.ID:
A5: * | E5: ACType :
A6: * | D6: 概要 : | E6: 出荷実績受信ＩＦ取込を行う。（マルチスレッド実行用） | M6: ID | O6: ID | Q6: ID
A7: # | I7: U | K7: K | L7: o | N7: o | P7: o
A8: # | D8: ブロック名 Block Name | E8: 型 Type | G8: super/share | H8: 対象ブロック名 Target Block Name | L8: TargetName | N8: TargetName | P8: TargetName | T8: ブロック備考 Block Remarks
A9: # | D9: 項目名 Field Name | E9: 型 Type | F9: 桁 Digits | G9: フルネーム Full Name | H9: 日本語名 Japanese Name | I9: 上り項目 Request Message Field | J9: 下り項目 Response Message Field | R9: 条件および編集方法 Conditions and Editing Methods | T9: 項目備考 Field Remarks
A10: # | L10: 上り項目 Request Message Field | M10: 下り項目 Response Message Field | N10: 上り項目 Request Message Field | O10: 下り項目 Response Message Field | P10: 上り項目 Request Message Field | Q10: 下り項目 Response Message Field
A11: 10 | B11: * | D11: ShipActRecvIf_Upd03_Dtl | E11: L
A12: 10 | D12: sa | E12: R | F12: DBC:MS.MST_SHIP_ACT_RECV_IF
A13: 10 | D13: sa.data_lno# | E13: RI | G13: Data row No. | H13: データ行ＮＯ | I13: E | J13: -
A14: 10 | D14: sa.data_no# | E14: RI | G14: Data No. | H14: データＮＯ | I14: E | J14: -
A15: 10 | D15: sa.ext_sys_cd# | E15: RI | G15: External system cd. | H15: 外部システムＣＤ | I15: E | J15: -
A16: 10 | D16: sa.ext_data_no# | E16: RI | G16: External system data No. | H16: 外部システムデータＮＯ | I16: E | J16: -
A17: 10 | D17: sa.ext_data_lno# | E17: RI | G17: External system data row No. | H17: 外部システムデータ行ＮＯ | I17: E | J17: -
A18: 10 | D18: sa.data_make_dt# | E18: RI | G18: Creation date and time of source record | H18: 送信元レコード作成日時 | I18: E | J18: -
A19: 10 | D19: sa.ship_fr_lg_grp_cd# | E19: RI | G19: Shipping point distribution group cd. | H19: 出荷元物流グループＣＤ | I19: E | J19: -
A20: 10 | D20: sa.ship_inst_no# | E20: RI | G20: Shipping order No. | H20: 出荷指図ＮＯ | I20: E | J20: -
L21: 上り項目 Request Message Field | M21: 下り項目 Response Message Field | N21: 上り項目 Request Message Field | O21: 下り項目 Response Message Field | P21: 上り項目 Request Message Field | Q21: 下り項目 Response Message Field
A22: 20 | B22: * | D22: ShipActRecvIf_Upd03_Cnd | E22: R | G22: $share$ | H22: MS.MSLAL6020.ShipActRecvIf_Upd02.ShipActRecvIf_Upd02_Cnd
A23: 20 | D23: exe_unit_lump_flg | E23: #MA.FLG | G23: Process unit aggregation | H23: 処理単位まとめ | I23: - | J23: -
A24: 20 | D24: if_upd_typ | E24: #MA.IF_UPD_TYP | G24: IF update type | H24: ＩＦ更新区分 | I24: E | J24: -
A25: 20 | D25: src_actlumprecv_flg | E25: #MA.FLG | G25: Caller results import batch | H25: 呼出元実績一括受信バッチ | I25: E | J25: -
L26: 上り項目 Request Message Field | M26: 下り項目 Response Message Field | N26: 上り項目 Request Message Field | O26: 下り項目 Response Message Field | P26: 上り項目 Request Message Field | Q26: 下り項目 Response Message Field
A27: 30 | B27: * | D27: ShipActRecvIf_Upd03_Rslt | E27: R | G27: $share$ | H27: MS.MSLAL6020.ShipActRecvIf_Upd02.ShipActRecvIf_Upd02_Rslt
A28: 30 | D28: total_num | E28: N | G28: Number of processed target | H28: 処理対象件数 | I28: - | J28: E
A29: 30 | D29: ok_num | E29: N | G29: Number of entries | H29: 登録件数 | I29: - | J29: E
A30: 30 | D30: err_num | E30: N | G30: Error count | H30: エラー件数 | I30: - | J30: E
A31: 30 | D31: skip_num | E31: N | G31: Skip count | H31: スキップ件数 | I31: - | J31: E
D32: 詳細 :

Sheet ShipActRecvIf_Upd04
A1: * | B1: * | D1: L | E1: 1
A2: * | D2: オペレーション実装仕様書 Operation Specification Implementation Sheet | E2: ModuleID : | F2: =IF(LogicCommon!C2="","",LogicCommon!C2) -> MS | G2: LogicID : | H2: =IF(LogicCommon!E2="","",LogicCommon!E2) -> MSLAL6020 | I2: Ope.ID : | J2: ShipActRecvIf_Upd04 | K2: Pj.ID : | L2: =IF(LogicCommon!G2="","",LogicCommon!G2) -> MC | M2: Ope.Body : | N2: "mcframe.serverMAUD.MAUDL5010.MAUDL_Operation"
A3: * | D3: =IF(LogicCommon!A3="","",LogicCommon!A3) | E3: SubModuleID : | F3: =IF(LogicCommon!C3="","",LogicCommon!C3) -> MSLA | G3: LogicClass : | H3: =IF(LogicCommon!E3="","",LogicCommon!E3) -> MSLAL_ShipActRecvIfService | I3: Ope.Method : | J3: @ | K3: SuperClassPj.ID : | L3: =IF(LogicCommon!G3="","",LogicCommon!G3) | O3: Gene.Type : | P3: ALL
A4: * | E4: Version : | F4: 000000 | G4: LogicName : | H4: =IF(LogicCommon!E4="","",LogicCommon!E4) -> 出荷実績受信ＩＦサービス | I4: Ope.Name : | J4: 出荷実績取込４ | K4: SuperLogicID : | L4: =IF(LogicCommon!G4="","",LogicCommon!G4) -> MS.MSUDL5010 | M4: ImplOpe.ID:
A5: * | E5: ACType :
A6: * | D6: 概要 : | E6: 出荷実績受信ＩＦ取込を行う。（出荷実績受信ＩＦサービスを呼び出す本処理） | M6: ID | O6: ID | Q6: ID
A7: # | I7: U | K7: K | L7: o | N7: o | P7: o
A8: # | D8: ブロック名 Block Name | E8: 型 Type | G8: super/share | H8: 対象ブロック名 Target Block Name | L8: TargetName | N8: TargetName | P8: TargetName | T8: ブロック備考 Block Remarks
A9: # | D9: 項目名 Field Name | E9: 型 Type | F9: 桁 Digits | G9: フルネーム Full Name | H9: 日本語名 Japanese Name | I9: 上り項目 Request Message Field | J9: 下り項目 Response Message Field | R9: 条件および編集方法 Conditions and Editing Methods | T9: 項目備考 Field Remarks
A10: # | L10: 上り項目 Request Message Field | M10: 下り項目 Response Message Field | N10: 上り項目 Request Message Field | O10: 下り項目 Response Message Field | P10: 上り項目 Request Message Field | Q10: 下り項目 Response Message Field
A11: 10 | B11: * | D11: ShipActRecvIf_Upd04_Dtl | E11: L
A12: 10 | D12: sa | E12: R | F12: DBC:MS.MST_SHIP_ACT_RECV_IF
A13: 10 | D13: sa.data_lno# | E13: RI | G13: Data row No. | H13: データ行ＮＯ | I13: E | J13: E
A14: 10 | D14: sa.data_no# | E14: RI | G14: Data No. | H14: データＮＯ | I14: E | J14: E
A15: 10 | D15: sa.ext_data_no# | E15: RI | G15: External system data No. | H15: 外部システムデータＮＯ | I15: E | J15: -
A16: 10 | D16: sa.ext_data_lno# | E16: RI | G16: External system data row No. | H16: 外部システムデータ行ＮＯ | I16: E | J16: -
A17: 10 | D17: sa.exe_sts_typ# | E17: RI | G17: PG execution status type | H17: ＰＧ実行状況区分 | I17: - | J17: E
A18: 10 | D18: sa.ship_fr_lg_grp_cd# | E18: RI | G18: Shipping point distribution group cd. | H18: 出荷元物流グループＣＤ | I18: E | J18: -
A19: 10 | D19: sa.ship_inst_no# | E19: RI | G19: Shipping order No. | H19: 出荷指図ＮＯ | I19: E | J19: -
A20: 10 | D20: uplnd_flg | E20: #MA.FLG | G20: Unplanned | H20: 計画外 | I20: - | J20: -
A21: 10 | D21: hdr_dtl_peg_no | E21: #MA.INT | G21: Header details pegging No. | H21: ヘッダ明細紐付けＮＯ | I21: - | J21: -
L22: 上り項目 Request Message Field | M22: 下り項目 Response Message Field | N22: 上り項目 Request Message Field | O22: 下り項目 Response Message Field | P22: 上り項目 Request Message Field | Q22: 下り項目 Response Message Field
A23: 20 | B23: * | D23: ShipActRecvIf_Upd04_Cnd | E23: R | G23: $share$ | H23: MS.MSLAL6020.ShipActRecvIf_Upd02.ShipActRecvIf_Upd02_Cnd
A24: 20 | D24: exe_unit_lump_flg | E24: #MA.FLG | G24: Process unit aggregation | H24: 処理単位まとめ | I24: - | J24: -
A25: 20 | D25: if_upd_typ | E25: #MA.IF_UPD_TYP | G25: IF update type | H25: ＩＦ更新区分 | I25: E | J25: -
A26: 20 | D26: src_actlumprecv_flg | E26: #MA.FLG | G26: Caller results import batch | H26: 呼出元実績一括受信バッチ | I26: E | J26: -
D27: 詳細 :

Sheet ShipActRecvIf_Chk01
A1: * | B1: * | D1: L | E1: 1
A2: * | D2: オペレーション実装仕様書 Operation Specification Implementation Sheet | E2: ModuleID : | F2: =IF(LogicCommon!C2="","",LogicCommon!C2) -> MS | G2: LogicID : | H2: =IF(LogicCommon!E2="","",LogicCommon!E2) -> MSLAL6020 | I2: Ope.ID : | J2: ShipActRecvIf_Chk01 | K2: Pj.ID : | L2: =IF(LogicCommon!G2="","",LogicCommon!G2) -> MC | M2: Ope.Body : | N2: MA.MAUDL5010.Checker
A3: * | D3: =IF(LogicCommon!A3="","",LogicCommon!A3) | E3: SubModuleID : | F3: =IF(LogicCommon!C3="","",LogicCommon!C3) -> MSLA | G3: LogicClass : | H3: =IF(LogicCommon!E3="","",LogicCommon!E3) -> MSLAL_ShipActRecvIfService | I3: Ope.Method : | J3: @ | K3: SuperClassPj.ID : | L3: =IF(LogicCommon!G3="","",LogicCommon!G3) | O3: Gene.Type : | P3: ALL
A4: * | E4: Version : | F4: 000000 | G4: LogicName : | H4: =IF(LogicCommon!E4="","",LogicCommon!E4) -> 出荷実績受信ＩＦサービス | I4: Ope.Name : | J4: 取込前チェック | K4: SuperLogicID : | L4: =IF(LogicCommon!G4="","",LogicCommon!G4) -> MS.MSUDL5010 | M4: ImplOpe.ID:
A5: * | E5: ACType :
A6: * | D6: 概要 : | E6: 出荷実績受信ＩＦ取込を行う前のチェック処理 | M6: ID | O6: ID | Q6: ID | AD6: ID | AF6: ID
A7: # | I7: U | K7: K | L7: K | M7: K | N7: K | O7: K | P7: K | Q7: K | R7: K | S7: K | T7: K | U7: K | V7: K | W7: K | X7: K | Y7: K | Z7: K | AA7: K | AB7: K | AC7: o | AE7: o
A8: # | D8: ブロック名 Block Name | E8: 型 Type | G8: super/share | H8: 対象ブロック名 Target Block Name | K8: REQ_UPD_CNT_CHK | L8: REQUIRED | M8: CHK_NUM | N8: SMALL_LARGE | O8: CHK_DT | P8: BEFORE_AFTER | Q8: CHK_PTN | R8: DUPLICATE | S8: TOO_MANY_INPUTS | T8: AT_LEAST_ONE | U8: ONLY_ONE_INPUT | V8: LIST_LOGIC | W8: LIST_OUT | X8: LIST_OUT_BASE | Y8: LIST_IN | Z8: LIST_IN_BASE | AA8: CONST | AB8: NULL_VAL | AC8: TargetName | AE8: TargetName | AI8: ブロック備考 Block Remarks
A9: # | D9: 項目名 Field Name | E9: 型 Type | F9: 桁 Digits | G9: フルネーム Full Name | H9: 日本語名 Japanese Name | I9: 上り項目 Request Message Field | J9: 下り項目 Response Message Field | AG9: 条件および編集方法 Conditions and Editing Methods | AI9: 項目備考 Field Remarks
A10: #
A11: 10 | B11: * | D11: ShipActRecvIf_Chk01_Dtl | E11: L | AC11: 上り項目 | AD11: 下り項目 | AE11: 上り項目 | AF11: 下り項目
A12: 10 | D12: sa | E12: R | F12: DBC:MS.MST_SHIP_ACT_RECV_IF
A13: 10 | D13: sa.data_lno# | E13: RI | G13: Data row No. | H13: データ行ＮＯ | I13: E | J13: E
A14: 10 | D14: sa.data_no# | E14: RI | G14: Data No. | H14: データＮＯ | I14: E | J14: -
A15: 10 | D15: sa.data_crud_typ# | E15: RI | G15: Data update type | H15: データ更新区分 | I15: E | J15: -
A16: 10 | D16: sa.ext_sys_cd# | E16: RI | G16: External system cd. | H16: 外部システムＣＤ | I16: E | J16: -
A17: 10 | D17: sa.exe_sts_typ# | E17: RI | G17: PG execution status type | H17: ＰＧ実行状況区分 | I17: E | J17: -
A18: 10 | D18: sa.ext_data_no# | E18: RI | G18: External system data No. | H18: 外部システムデータＮＯ | I18: E | J18: -
A19: 10 | D19: sa.ext_data_lno# | E19: RI | G19: External system data row No. | H19: 外部システムデータ行ＮＯ | I19: E | J19: -
A20: 10 | D20: sa.data_make_dt# | E20: RI | G20: Creation date and time of source record | H20: 送信元レコード作成日時 | I20: E | J20: -
A21: 10 | D21: sa.imp_flg# | E21: RI | G21: To import | H21: 取込対象 | I21: E | J21: -
A22: 10 | D22: sa.ship_inst_no# | E22: RI | G22: Shipping order No. | H22: 出荷指図ＮＯ | I22: E | J22: -
A23: 10 | D23: sa.ship_fr_lg_grp_cd# | E23: RI | G23: Shipping point distribution group cd. | H23: 出荷元物流グループＣＤ | I23: E | J23: - | L23: E
A24: 10 | D24: sa.site_co_cd# | E24: RI | G24: Warehousing business cd. | H24: 倉庫事業者ＣＤ | I24: E | J24: -
A25: 10 | D25: sa.trd_cd# | E25: RI | G25: Transaction cd. | H25: 取引ＣＤ | I25: E | J25: - | V25: MA.MAUAL0010.Trd | W25: mst_trd_ptn_typ | X25: trd_ptn_typ
A26: 10 | D26: sa.trd_ptn_typ# | E26: RI | G26: Transaction pattern type | H26: 取引パタン区分 | I26: E | J26: -
A27: 10 | D27: sa.ship_tm# | E27: RI | G27: Shipping date and time | H27: 出荷日時 | I27: E | J27: -
A28: 10 | D28: sa.dlv_tm# | E28: RI | G28: Delivery date and time | H28: 納品日時 | I28: E | J28: -
A29: 10 | D29: sa.cst_cd# | E29: RI | G29: Customer cd. | H29: 得意先ＣＤ | I29: E | J29: -
A30: 10 | D30: sa.ship_to_id_typ# | E30: RI | G30: Receiving point identification type | H30: 送付先識別区分 | I30: E | J30: -
A31: 10 | D31: sa.ship_to_id_cd# | E31: RI | G31: Receiving point identification cd. | H31: 送付先識別ＣＤ | I31: E | J31: - | V31: MS.MSUAL0060.ShipToId | W31: ship_to_sundry_flg;mst_ship_to_id_nm | X31: ship_to_sundry_flg;ship_to_id_nm | Y31: ship_to_id_typ;ship_tm | Z31: ship_to_id_typ;base_dt
A32: 10 | D32: sa.ship_to_id_nm# | E32: RI | G32: Receiving point Identification name | H32: 送付先識別名 | I32: E | J32: -
A33: 10 | D33: sa.ship_to_zip_cd# | E33: RI | G33: Receiving point zip code | H33: 送付先郵便番号 | I33: E | J33: -
A34: 10 | D34: sa.ship_to_addr1# | E34: RI | G34: Receiving point address 1 | H34: 送付先住所１ | I34: E | J34: -
A35: 10 | D35: sa.ship_to_addr2# | E35: RI | G35: Receiving point address 2 | H35: 送付先住所２ | I35: E | J35: -
A36: 10 | D36: sa.ship_to_addr3# | E36: RI | G36: Receiving point address 3 | H36: 送付先住所３ | I36: E | J36: -
A37: 10 | D37: sa.ship_to_addr4# | E37: RI | G37: Receiving point address 4 | H37: 送付先住所４ | I37: E | J37: -
A38: 10 | D38: sa.ship_to_cntct_dpt# | E38: RI | G38: Receiving point dept. | H38: 送付先部署 | I38: E | J38: -
A39: 10 | D39: sa.ship_to_cntct_psn# | E39: RI | G39: Receiving point PIC | H39: 送付先担当者 | I39: E | J39: -
A40: 10 | D40: sa.ship_to_tel# | E40: RI | G40: Receiving point TEL | H40: 送付先ＴＥＬ | I40: E | J40: -
...

Sheet 来歴
A1: 変更来歴
A3: Rev. | H3: 修正番号 | O3: 変更内容 | AQ3: 変更箇所
A4: 1 | O4: 初版
A5: 1.1 | O5: 英語の名称を追記 | AQ5: 全般
