Workbook

Sheet LogicCommon
A2: オペレーション実装仕様書 | B2: ModuleID : | C2: MS | D2: LogicID : | E2: MSLAL5120 | F2: Pj.ID : | G2: MC
B3: SubModuleID : | C3: MSLA | D3: LogicClass : | E3: MSLAL_SloRecvIfService | F3: SuperClassPj.ID :
D4: LogicName : | E4: 受注受信ＩＦサービス | F4: SuperLogicID : | G4: MS.MSUDL5010
A5: 概要 : | B5: ＥＤＩで受注を取り込むための処理を提供する
A6: 詳細 :

Sheet SloRecvIf_Upd01
A1: * | B1: * | D1: L | E1: 1
A2: * | D2: オペレーション実装仕様書 Operation Specification Implementation Sheet | E2: ModuleID : | F2: =IF(LogicCommon!C2="","",LogicCommon!C2) -> MS | G2: LogicID : | H2: =IF(LogicCommon!E2="","",LogicCommon!E2) -> MSLAL5120 | I2: Ope.ID : | J2: SloRecvIf_Upd01 | K2: Pj.ID : | L2: =IF(LogicCommon!G2="","",LogicCommon!G2) -> MC | M2: Ope.Body : | N2: "mcframe.serverMAUD.MAUDL5010.MAUDL_Operation"
A3: * | D3: =IF(LogicCommon!A3="","",LogicCommon!A3) | E3: SubModuleID : | F3: =IF(LogicCommon!C3="","",LogicCommon!C3) -> MSLA | G3: LogicClass : | H3: =IF(LogicCommon!E3="","",LogicCommon!E3) -> MSLAL_SloRecvIfService | I3: Ope.Method : | J3: @ | K3: SuperClassPj.ID : | L3: =IF(LogicCommon!G3="","",LogicCommon!G3) | O3: Gene.Type : | P3: ALL
A4: * | E4: Version : | F4: 000000 | G4: LogicName : | H4: =IF(LogicCommon!E4="","",LogicCommon!E4) -> 受注受信ＩＦサービス | I4: Ope.Name : | J4: 受注取込１ | K4: SuperLogicID : | L4: =IF(LogicCommon!G4="","",LogicCommon!G4) -> MS.MSUDL5010 | M4: ImplOpe.ID: | N4: PF.PFUDL0040.Upd01
A5: * | E5: ACType :
A6: * | D6: 概要 : | E6: 受注受信ＩＦ取込を行う。（ＥＳＢのリアルタイム取込から呼び出される） | M6: ID | O6: ID | Q6: ID
A7: # | I7: U | K7: K | L7: o | N7: o | P7: o
A8: # | D8: ブロック名 Block Name | E8: 型 Type | G8: super/share | H8: 対象ブロック名 Target Block Name | L8: TargetName | N8: TargetName | P8: TargetName | T8: ブロック備考 Block Remarks
A9: # | D9: 項目名 Field Name | E9: 型 Type | F9: 桁 Digits | G9: フルネーム Full Name | H9: 日本語名 Japanese Name | I9: 上り項目 Request Message Field | J9: 下り項目 Response Message Field | R9: 条件および編集方法 Conditions and Editing Methods | T9: 項目備考 Field Remarks
A10: # | L10: 上り項目 Request Message Field | M10: 下り項目 Response Message Field | N10: 上り項目 Request Message Field | O10: 下り項目 Response Message Field | P10: 上り項目 Request Message Field | Q10: 下り項目 Response Message Field
A11: 10 | B11: * | D11: SloRecvIf_Upd01_Dtl | E11: L | G11: $share$ | H11: PF.PFUDL0040.Upd01.Upd01_Dtl
A12: 10 | D12: data_no | E12: #MA.IF_DATA_NO | G12: Data No. | H12: データＮＯ | I12: E | J12: -
A13: 10 | D13: ext_data_no | E13: #MA.IF_EXT_DATA_NO | G13: External system data No. | H13: 外部システムデータＮＯ | I13: E | J13: -
A14: 10 | D14: ext_sys_cd | E14: #MA.EXT_SYS_CD | G14: External system cd. | H14: 外部システムＣＤ | I14: E | J14: -
A15: 10 | D15: bp_cd | E15: #MA.BP_CD | G15: BP cd. | H15: 取引先ＣＤ | I15: E | J15: -
D16: 詳細 :

Sheet SloRecvIf_Upd02
A1: * | B1: * | D1: L | E1: 1
A2: * | D2: オペレーション実装仕様書 Operation Specification Implementation Sheet | E2: ModuleID : | F2: =IF(LogicCommon!C2="","",LogicCommon!C2) -> MS | G2: LogicID : | H2: =IF(LogicCommon!E2="","",LogicCommon!E2) -> MSLAL5120 | I2: Ope.ID : | J2: SloRecvIf_Upd02 | K2: Pj.ID : | L2: =IF(LogicCommon!G2="","",LogicCommon!G2) -> MC | M2: Ope.Body : | N2: "mcframe.serverMAUD.MAUDL5010.MAUDL_Operation"
A3: * | D3: =IF(LogicCommon!A3="","",LogicCommon!A3) | E3: SubModuleID : | F3: =IF(LogicCommon!C3="","",LogicCommon!C3) -> MSLA | G3: LogicClass : | H3: =IF(LogicCommon!E3="","",LogicCommon!E3) -> MSLAL_SloRecvIfService | I3: Ope.Method : | J3: @ | K3: SuperClassPj.ID : | L3: =IF(LogicCommon!G3="","",LogicCommon!G3) | O3: Gene.Type : | P3: ALL
A4: * | E4: Version : | F4: 000000 | G4: LogicName : | H4: =IF(LogicCommon!E4="","",LogicCommon!E4) -> 受注受信ＩＦサービス | I4: Ope.Name : | J4: 受注取込２ | K4: SuperLogicID : | L4: =IF(LogicCommon!G4="","",LogicCommon!G4) -> MS.MSUDL5010 | M4: ImplOpe.ID: | N4: MB.MBBEL5010.Upd01
A5: * | E5: ACType :
A6: * | D6: 概要 : | E6: 受注受信ＩＦ取込を行う。（ＩＦデータ確認、および受注受信ＩＦ取込バッチから呼び出される） | M6: ID | O6: ID | Q6: ID
A7: # | I7: U | K7: K | L7: o | N7: o | P7: o
A8: # | D8: ブロック名 Block Name | E8: 型 Type | G8: super/share | H8: 対象ブロック名 Target Block Name | L8: TargetName | N8: TargetName | P8: TargetName | T8: ブロック備考 Block Remarks
A9: # | D9: 項目名 Field Name | E9: 型 Type | F9: 桁 Digits | G9: フルネーム Full Name | H9: 日本語名 Japanese Name | I9: 上り項目 Request Message Field | J9: 下り項目 Response Message Field | R9: 条件および編集方法 Conditions and Editing Methods | T9: 項目備考 Field Remarks
A10: # | L10: 上り項目 Request Message Field | M10: 下り項目 Response Message Field | N10: 上り項目 Request Message Field | O10: 下り項目 Response Message Field | P10: 上り項目 Request Message Field | Q10: 下り項目 Response Message Field
A11: 10 | B11: * | D11: SloRecvIf_Upd01_Dtl | E11: L | G11: $share$ | H11: MB.MBBEL5010.Upd01.IfDataImp_Upd01_Dtl
A12: 10 | D12: data_no | E12: #MA.IF_DATA_NO | G12: Data No. | H12: データＮＯ | I12: E | J12: -
A13: 10 | D13: ext_data_no | E13: #MA.IF_EXT_DATA_NO | G13: External system data No. | H13: 外部システムデータＮＯ | I13: E | J13: -
A14: 10 | D14: ext_sys_cd | E14: #MA.EXT_SYS_CD | G14: External system cd. | H14: 外部システムＣＤ | I14: E | J14: -
A15: 10 | D15: bp_cd | E15: #MA.BP_CD | G15: BP cd. | H15: 取引先ＣＤ | I15: E | J15: -
L16: 上り項目 Request Message Field | M16: 下り項目 Response Message Field | N16: 上り項目 Request Message Field | O16: 下り項目 Response Message Field | P16: 上り項目 Request Message Field | Q16: 下り項目 Response Message Field
A17: 20 | B17: * | D17: SloRecvIf_Upd02_Cnd | E17: R | G17: $share$ | H17: MB.MBBEL5010.Upd01.IfDataImp_Upd01_Cnd
A18: 20 | D18: exe_unit_lump_flg | E18: #MA.FLG | G18: Process unit aggregation | H18: 処理単位まとめ | I18: E | J18: -
A19: 20 | D19: if_upd_typ | E19: #MA.IF_UPD_TYP | G19: IF update type | H19: ＩＦ更新区分 | I19: E | J19: -
A20: 20 | D20: src_actlumprecv_flg | E20: #MA.FLG | G20: Caller results import batch | H20: 呼出元実績一括受信バッチ | I20: E | J20: -
L21: 上り項目 Request Message Field | M21: 下り項目 Response Message Field | N21: 上り項目 Request Message Field | O21: 下り項目 Response Message Field | P21: 上り項目 Request Message Field | Q21: 下り項目 Response Message Field
A22: 30 | B22: * | D22: SloRecvIf_Upd02_Rslt | E22: R | G22: $share$ | H22: MB.MBBEL5010.Upd01.IfDataImp_Upd01_Rslt
A23: 30 | D23: total_num | E23: N | G23: Number of processed target | H23: 処理対象件数 | I23: - | J23: E
A24: 30 | D24: ok_num | E24: N | G24: Number of entries | H24: 登録件数 | I24: - | J24: E
A25: 30 | D25: err_num | E25: N | G25: Error count | H25: エラー件数 | I25: - | J25: E
A26: 30 | D26: skip_num | E26: N | G26: Skip count | H26: スキップ件数 | I26: - | J26: E
D27: 詳細 :

Sheet SloRecvIf_Upd03
A1: * | B1: * | D1: L | E1: 1
A2: * | D2: オペレーション実装仕様書 Operation Specification Implementation Sheet | E2: ModuleID : | F2: =IF(LogicCommon!C2="","",LogicCommon!C2) -> MS | G2: LogicID : | H2: =IF(LogicCommon!E2="","",LogicCommon!E2) -> MSLAL5120 | I2: Ope.ID : | J2: SloRecvIf_Upd03 | K2: Pj.ID : | L2: =IF(LogicCommon!G2="","",LogicCommon!G2) -> MC | M2: Ope.Body : | N2: "mcframe.serverMAUD.MAUDL5010.MAUDL_Operation"
A3: * | D3: =IF(LogicCommon!A3="","",LogicCommon!A3) | E3: SubModuleID : | F3: =IF(LogicCommon!C3="","",LogicCommon!C3) -> MSLA | G3: LogicClass : | H3: =IF(LogicCommon!E3="","",LogicCommon!E3) -> MSLAL_SloRecvIfService | I3: Ope.Method : | J3: @ | K3: SuperClassPj.ID : | L3: =IF(LogicCommon!G3="","",LogicCommon!G3) | O3: Gene.Type : | P3: ALL
A4: * | E4: Version : | F4: 000000 | G4: LogicName : | H4: =IF(LogicCommon!E4="","",LogicCommon!E4) -> 受注受信ＩＦサービス | I4: Ope.Name : | J4: 受注取込３ | K4: SuperLogicID : | L4: =IF(LogicCommon!G4="","",LogicCommon!G4) -> MS.MSUDL5010 | M4: ImplOpe.ID:
A5: * | E5: ACType :
A6: * | D6: 概要 : | E6: 受注受信ＩＦ取込を行う。（マルチスレッド実行用） | M6: ID | O6: ID | Q6: ID
A7: # | I7: U | K7: K | L7: o | N7: o | P7: o
A8: # | D8: ブロック名 Block Name | E8: 型 Type | G8: super/share | H8: 対象ブロック名 Target Block Name | L8: TargetName | N8: TargetName | P8: TargetName | T8: ブロック備考 Block Remarks
A9: # | D9: 項目名 Field Name | E9: 型 Type | F9: 桁 Digits | G9: フルネーム Full Name | H9: 日本語名 Japanese Name | I9: 上り項目 Request Message Field | J9: 下り項目 Response Message Field | R9: 条件および編集方法 Conditions and Editing Methods | T9: 項目備考 Field Remarks
A10: # | L10: 上り項目 Request Message Field | M10: 下り項目 Response Message Field | N10: 上り項目 Request Message Field | O10: 下り項目 Response Message Field | P10: 上り項目 Request Message Field | Q10: 下り項目 Response Message Field
A11: 10 | B11: * | D11: SloRecvIf_Upd03_Dtl | E11: L
A12: 10 | D12: slo | E12: R | F12: DBC:MS.MST_SLO_RECV_IF
A13: 10 | D13: slo.data_lno# | E13: RI | G13: Data row No. | H13: データ行ＮＯ | I13: E | J13: -
A14: 10 | D14: slo.data_no# | E14: RI | G14: Data No. | H14: データＮＯ | I14: E | J14: -
A15: 10 | D15: slo.ext_data_no# | E15: RI | G15: External system data No. | H15: 外部システムデータＮＯ | I15: E | J15: -
A16: 10 | D16: slo.ext_data_lno# | E16: RI | G16: External system data row No. | H16: 外部システムデータ行ＮＯ | I16: E | J16: -
A17: 10 | D17: slo.cst_po_no# | E17: RI | G17: Customer order No. | H17: 得意先注文ＮＯ | I17: E | J17: -
A18: 10 | D18: slo.cst_po_rev# | E18: RI | G18: Customer order rev. number | H18: 得意先注文改訂番号 | I18: E | J18: -
A19: 10 | D19: slo.cst_cd# | E19: RI | G19: Customer cd. | H19: 得意先ＣＤ | I19: E | J19: -
L20: 上り項目 Request Message Field | M20: 下り項目 Response Message Field | N20: 上り項目 Request Message Field | O20: 下り項目 Response Message Field | P20: 上り項目 Request Message Field | Q20: 下り項目 Response Message Field
A21: 20 | B21: * | D21: SloRecvIf_Upd03_Rslt | E21: R
A22: 20 | D22: total_num | E22: N | G22: Number of processed target | H22: 処理対象件数 | I22: - | J22: E
A23: 20 | D23: ok_num | E23: N | G23: Number of entries | H23: 登録件数 | I23: - | J23: E
A24: 20 | D24: err_num | E24: N | G24: Error count | H24: エラー件数 | I24: - | J24: E
A25: 20 | D25: skip_num | E25: N | G25: Skip count | H25: スキップ件数 | I25: - | J25: E
D26: 詳細 :

Sheet SloRecvIf_Upd04
A1: * | B1: * | D1: L | E1: 1
A2: * | D2: オペレーション実装仕様書 Operation Specification Implementation Sheet | E2: ModuleID : | F2: =IF(LogicCommon!C2="","",LogicCommon!C2) -> MS | G2: LogicID : | H2: =IF(LogicCommon!E2="","",LogicCommon!E2) -> MSLAL5120 | I2: Ope.ID : | J2: SloRecvIf_Upd04 | K2: Pj.ID : | L2: =IF(LogicCommon!G2="","",LogicCommon!G2) -> MC | M2: Ope.Body : | N2: "mcframe.serverMAUD.MAUDL5010.MAUDL_Operation"
A3: * | D3: =IF(LogicCommon!A3="","",LogicCommon!A3) | E3: SubModuleID : | F3: =IF(LogicCommon!C3="","",LogicCommon!C3) -> MSLA | G3: LogicClass : | H3: =IF(LogicCommon!E3="","",LogicCommon!E3) -> MSLAL_SloRecvIfService | I3: Ope.Method : | J3: @ | K3: SuperClassPj.ID : | L3: =IF(LogicCommon!G3="","",LogicCommon!G3) | O3: Gene.Type : | P3: ALL
A4: * | E4: Version : | F4: 000000 | G4: LogicName : | H4: =IF(LogicCommon!E4="","",LogicCommon!E4) -> 受注受信ＩＦサービス | I4: Ope.Name : | J4: 受注取込４ | K4: SuperLogicID : | L4: =IF(LogicCommon!G4="","",LogicCommon!G4) -> MS.MSUDL5010 | M4: ImplOpe.ID:
A5: * | E5: ACType :
A6: * | D6: 概要 : | E6: 受注受信ＩＦ取込を行う。（受注登録サービスを呼び出す本処理） | M6: ID | O6: ID | Q6: ID
A7: # | I7: U | K7: K | L7: o | N7: o | P7: o
A8: # | D8: ブロック名 Block Name | E8: 型 Type | G8: super/share | H8: 対象ブロック名 Target Block Name | L8: TargetName | N8: TargetName | P8: TargetName | T8: ブロック備考 Block Remarks
A9: # | D9: 項目名 Field Name | E9: 型 Type | F9: 桁 Digits | G9: フルネーム Full Name | H9: 日本語名 Japanese Name | I9: 上り項目 Request Message Field | J9: 下り項目 Response Message Field | R9: 条件および編集方法 Conditions and Editing Methods | T9: 項目備考 Field Remarks
A10: # | L10: 上り項目 Request Message Field | M10: 下り項目 Response Message Field | N10: 上り項目 Request Message Field | O10: 下り項目 Response Message Field | P10: 上り項目 Request Message Field | Q10: 下り項目 Response Message Field
A11: 10 | B11: * | D11: SloRecvIf_Upd04_Dtl | E11: L
A12: 10 | D12: slo | E12: R | F12: DBC:MS.MST_SLO_RECV_IF
A13: 10 | D13: slo.data_lno# | E13: RI | G13: Data row No. | H13: データ行ＮＯ | I13: E | J13: E
A14: 10 | D14: slo.data_no# | E14: RI | G14: Data No. | H14: データＮＯ | I14: E | J14: E
A15: 10 | D15: slo.ext_data_no# | E15: RI | G15: External system data No. | H15: 外部システムデータＮＯ | I15: E | J15: -
A16: 10 | D16: slo.ext_data_lno# | E16: RI | G16: External system data row No. | H16: 外部システムデータ行ＮＯ | I16: E | J16: -
A17: 10 | D17: slo.exe_sts_typ# | E17: RI | G17: PG execution status type | H17: ＰＧ実行状況区分 | I17: - | J17: E
A18: 10 | D18: slo.cst_po_no# | E18: RI | G18: Customer order No. | H18: 得意先注文ＮＯ | I18: E | J18: -
A19: 10 | D19: slo.cst_po_rev# | E19: RI | G19: Customer order rev. number | H19: 得意先注文改訂番号 | I19: E | J19: -
A20: 10 | D20: slo.cst_cd# | E20: RI | G20: Customer cd. | H20: 得意先ＣＤ | I20: E | J20: -
A21: 10 | D21: slo.sls_usr_cd# | E21: RI | G21: Sales PIC cd. | H21: 売上担当者ＣＤ | I21: - | J21: -
A22: 10 | D22: slo.log_sub_key1# | E22: RI | G22: Log sub key 1 | H22: ログサブキー１ | I22: - | J22: -
A23: 10 | D23: slo.log_sub_key2# | E23: RI | G23: Log sub key 2 | H23: ログサブキー２ | I23: - | J23: -
A24: 10 | D24: wg_cd | E24: #MA.WG_CD | G24: WG cd. | H24: ワーキンググループＣＤ | I24: - | J24: -
D25: 詳細 :

Sheet SloRecvIf_Chk01
A1: * | B1: * | D1: L | E1: 1
A2: * | D2: オペレーション実装仕様書 Operation Specification Implementation Sheet | E2: ModuleID : | F2: =IF(LogicCommon!C2="","",LogicCommon!C2) -> MS | G2: LogicID : | H2: =IF(LogicCommon!E2="","",LogicCommon!E2) -> MSLAL5120 | I2: Ope.ID : | J2: SloRecvIf_Chk01 | K2: Pj.ID : | L2: =IF(LogicCommon!G2="","",LogicCommon!G2) -> MC | M2: Ope.Body : | N2: MA.MAUDL5010.Checker
A3: * | D3: =IF(LogicCommon!A3="","",LogicCommon!A3) | E3: SubModuleID : | F3: =IF(LogicCommon!C3="","",LogicCommon!C3) -> MSLA | G3: LogicClass : | H3: =IF(LogicCommon!E3="","",LogicCommon!E3) -> MSLAL_SloRecvIfService | I3: Ope.Method : | J3: @ | K3: SuperClassPj.ID : | L3: =IF(LogicCommon!G3="","",LogicCommon!G3) | O3: Gene.Type : | P3: ALL
A4: * | E4: Version : | F4: 000000 | G4: LogicName : | H4: =IF(LogicCommon!E4="","",LogicCommon!E4) -> 受注受信ＩＦサービス | I4: Ope.Name : | J4: 取込前チェック | K4: SuperLogicID : | L4: =IF(LogicCommon!G4="","",LogicCommon!G4) -> MS.MSUDL5010 | M4: ImplOpe.ID:
A5: * | E5: ACType :
A6: * | D6: 概要 : | E6: 受注受信ＩＦ取込を行う前のチェック処理 | M6: ID | O6: ID | Q6: ID | AD6: ID | AF6: ID
A7: # | I7: U | K7: K | L7: K | M7: K | N7: K | O7: K | P7: K | Q7: K | R7: K | S7: K | T7: K | U7: K | V7: K | W7: K | X7: K | Y7: K | Z7: K | AA7: K | AB7: K | AC7: o | AE7: o
A8: # | D8: ブロック名 Block Name | E8: 型 Type | G8: super/share | H8: 対象ブロック名 Target Block Name | K8: REQ_UPD_CNT_CHK | L8: REQUIRED | M8: CHK_NUM | N8: SMALL_LARGE | O8: CHK_DT | P8: BEFORE_AFTER | Q8: CHK_PTN | R8: DUPLICATE | S8: TOO_MANY_INPUTS | T8: AT_LEAST_ONE | U8: ONLY_ONE_INPUT | V8: LIST_LOGIC | W8: LIST_OUT | X8: LIST_OUT_BASE | Y8: LIST_IN | Z8: LIST_IN_BASE | AA8: CONST | AB8: NULL_VAL | AC8: TargetName | AE8: TargetName | AI8: ブロック備考 Block Remarks
A9: # | D9: 項目名 Field Name | E9: 型 Type | F9: 桁 Digits | G9: フルネーム Full Name | H9: 日本語名 Japanese Name | I9: 上り項目 Request Message Field | J9: 下り項目 Response Message Field | AG9: 条件および編集方法 Conditions and Editing Methods | AI9: 項目備考 Field Remarks
A10: #
A11: 10 | B11: * | D11: SloRecvIf_Chk01_Dtl | E11: L | AC11: 上り項目 | AD11: 下り項目 | AE11: 上り項目 | AF11: 下り項目
A12: 10 | D12: slo | E12: R | F12: DBC:MS.MST_SLO_RECV_IF
A13: 10 | D13: slo.data_lno# | E13: RI | G13: Data row No. | H13: データ行ＮＯ | I13: E | J13: E
A14: 10 | D14: slo.data_no# | E14: RI | G14: Data No. | H14: データＮＯ | I14: E | J14: -
A15: 10 | D15: slo.data_crud_typ# | E15: RI | G15: Data update type | H15: データ更新区分 | I15: E | J15: - | AA15: MAC_DATA_CRUD_TYP
A16: 10 | D16: slo.ext_sys_cd# | E16: RI | G16: External system cd. | H16: 外部システムＣＤ | I16: E | J16: -
A17: 10 | D17: slo.exe_sts_typ# | E17: RI | G17: PG execution status type | H17: ＰＧ実行状況区分 | I17: E | J17: -
A18: 10 | D18: slo.ext_data_no# | E18: RI | G18: External system data No. | H18: 外部システムデータＮＯ | I18: E | J18: -
A19: 10 | D19: slo.ext_data_lno# | E19: RI | G19: External system data row No. | H19: 外部システムデータ行ＮＯ | I19: E | J19: -
A20: 10 | D20: slo.data_make_dt# | E20: RI | G20: Creation date and time of source record | H20: 送信元レコード作成日時 | I20: E | J20: -
A21: 10 | D21: slo.imp_flg# | E21: RI | G21: To import | H21: 取込対象 | I21: E | J21: -
A22: 10 | D22: slo.recv_dt# | E22: RI | G22: Receiving date | H22: 受信日 | I22: E | J22: -
A23: 10 | D23: slo.cst_po_no# | E23: RI | G23: Customer order No. | H23: 得意先注文ＮＯ | I23: E | J23: - | L23: E
A24: 10 | D24: slo.cst_po_rev# | E24: RI | G24: Customer order rev. number | H24: 得意先注文改訂番号 | I24: E | J24: -
A25: 10 | D25: slo.cst_po_d_no# | E25: RI | G25: Customer order details No. | H25: 得意先注文明細ＮＯ | I25: E | J25: -
A26: 10 | D26: slo.cst_cd# | E26: RI | G26: Customer cd. | H26: 得意先ＣＤ | I26: E | J26: - | L26: E | V26: MA.MAUAL0010.Bp | W26: cst_iv_flg;sls_basis_typ;cst_trd_cur_cd;cst_upri_dec_place;cst_amt_dec_place;sls_amt_rnd_typ;sls_tax_rnd_typ;cst_ar_dpt_cd;cst_bill_crryovr_times;ship_schd_split_typ;sls_upri_req_typ;cst_sls_usr_cd;cst_sls_dpt_cd;ar_dpt_typ;cst_tterm_cd1;cst_tterm_cd2;cst_tterm_cd3 | X26: cst_iv_flg;sls_basis_typ;cur_cd;upri_dec_place;amt_dec_place;sls_amt_rnd_typ;sls_tax_rnd_typ;ar_dpt_cd;bill_crryovr_times;ship_schd_split_typ;sls_upri_req_typ;cst_usr_cd;cst_dpt_cd;ar_dpt_typ;cst_tterm_cd1;cst_tterm_cd2;cst_tterm_cd3 | Y26: MAC_BP_IS_SRCH_TYP.CST_NOT_SUNDRY;slo_dt | Z26: bp_is_srch_typ;dt
A27: 10 | D27: slo.dest_cd1# | E27: RI | G27: Distribution channel cd. 1 | H27: 仕向先ＣＤ１ | I27: E | J27: -
A28: 10 | D28: slo.dest_cd2# | E28: RI | G28: Distribution channel cd. 2 | H28: 仕向先ＣＤ２ | I28: E | J28: -
A29: 10 | D29: slo.dest_cd3# | E29: RI | G29: Distribution channel cd. 3 | H29: 仕向先ＣＤ３ | I29: E | J29: -
A30: 10 | D30: slo.po_dt# | E30: RI | G30: PO date | H30: 注文日 | I30: E | J30: -
A31: 10 | D31: slo.purc_id_typ# | E31: RI | G31: Purchase identification type | H31: 購買識別区分 | I31: E | J31: -
A32: 10 | D32: slo.sls_cststk_flg# | E32: RI | G32: Sales keeping customer inventory | H32: 預り売上 | I32: E | J32: -
A33: 10 | D33: slo.slo_typ# | E33: RI | G33: Sales order type | H33: 受注区分 | I33: E | J33: -
A34: 10 | D34: slo.trd_cur_cd# | E34: RI | G34: Transaction currency cd. | H34: 取引通貨ＣＤ | I34: E | J34: - | V34: MA.MAUAL0010.Cur | W34: upri_dec_place;amt_dec_place | X34: upri_dec_place;amt_dec_place
A35: 10 | D35: slo.sls_dpt_cd# | E35: RI | G35: Sales dept. cd. | H35: 売上部門ＣＤ | I35: E | J35: - | V35: MA.MAUAL0010.Dpt | W35: dpt_wg_cd | X35: wg_cd | Y35: slo_dt;MAC_DPT_IS_SRCH_TYP.SLS;sls_usr_cd | Z35: dt;dpt_is_srch_typ;usr_cd
A36: 10 | D36: slo.sls_usr_cd# | E36: RI | G36: Sales PIC cd. | H36: 売上担当者ＣＤ | I36: E | J36: -
A37: 10 | D37: slo.dlv_cd# | E37: RI | G37: Delivery destination cd. | H37: 納品先ＣＤ | I37: E | J37: - | V37: MA.MAUAL0010.Bp | W37: mst_dlv_nm;dlv_sundry_flg;pri_prnt_flg;mst_dlv_zip_cd;mst_dlv_addr1;mst_dlv_addr2;mst_dlv_addr3;mst_dlv_addr4;mst_dlv_cntry_cd;mst_dlv_tel;mst_dlv_fax;mst_dlv_cntct_dpt;mst_dlv_cntct_psn;dlv_lg_grp_cd;tdlv_req_flg;prnt_lcl_cd | X37: bp_nm;dlv_sundry_flg;pri_prnt_flg;zip_cd;addr1;addr2;addr3;addr4;cntry_cd;tel;fax;dlv_cntct_dpt;dlv_cntct_psn;lg_grp_cd;tdlv_req_flg;prnt_lcl_cd | Y37: MAC_BP_IS_SRCH_TYP.DLV;slo_dt | Z37: bp_is_srch_typ;dt
A38: 10 | D38: slo.dlv_nm# | E38: RI | G38: Delivery destination name | H38: 納品先名 | I38: E | J38: -
A39: 10 | D39: slo.dlv_cntct_dpt# | E39: RI | G39: Delivery destination dept. | H39: 納品先部署 | I39: E | J39: -
A40: 10 | D40: slo.dlv_cntct_psn# | E40: RI | G40: Delivery destination PIC | H40: 納品先担当者 | I40: E | J40: -
...

Sheet 来歴
A1: 変更来歴
A3: Rev. | H3: 修正番号 | O3: 変更内容 | AQ3: 変更箇所
A4: 1 | O4: 初版
A5: 1.1 | H5: MS7031#003 | O5: SloRecvIf_Chk01_Dtlブロック ・以下、3つの項目を追加 cst_tterm_cd1、cst_tterm_cd2、cst_tterm_cd3 ・slo.cst_cd#のLIST_OUTとLIST_OUT_BASEにcst_tterm_cd1;cst_tterm_cd2;cst_tterm_cd3を追加 | AQ5: SloRecvIf_Chk01
A6: 1.2 | H6: MS7031#404 | O6: SloRecvIf_Chk01_Dtlブロック、SloRecvIf_Chk01_Slo_Upd01_Dtlブロックに以下の項目を追加 not_lg_mix_flg、not_lot_mix_flg、not_sublot_mix_flg SloRecvIf_Chk01_Dtlブロックに以下の項目を追加 lot_mng_typ SloRecvIf_Chk01_Dtlブロックにあるslo.itm_sub3#のLIST_OUT、LIST_OUT_BASEに以下の項目を追加 lot_mng_typ | AQ6: SloRecvIf_Chk01
A7: 1.3 | O7: 英語の名称を追記 | AQ7: 全般
