Workbook

Sheet LogicCommon
A2: オペレーション実装仕様書 | B2: ModuleID : | C2: MS | D2: LogicID : | E2: MSLAL5030 | F2: Pj.ID : | G2: MC
B3: SubModuleID : | C3: MSLA | D3: LogicClass : | E3: MSLAL_PoPrmsRecvIfService | F3: SuperClassPj.ID :
D4: LogicName : | E4: 発注納期回答受信ＩＦサービス | F4: SuperLogicID : | G4: MS.MSUDL5010
A5: 概要 :
A6: 詳細 :

Sheet PoPrmsRecvIf_Chk01
A1: * | B1: * | D1: L | E1: 1
A2: * | D2: オペレーション実装仕様書 Operation Specification Implementation Sheet | E2: ModuleID : | F2: =IF(LogicCommon!C2="","",LogicCommon!C2) -> MS | G2: LogicID : | H2: =IF(LogicCommon!E2="","",LogicCommon!E2) -> MSLAL5030 | I2: Ope.ID : | J2: PoPrmsRecvIf_Chk01 | K2: Pj.ID : | L2: =IF(LogicCommon!G2="","",LogicCommon!G2) -> MC | M2: Ope.Body : | N2: MA.MAUDL5010.Checker
A3: * | D3: =IF(LogicCommon!A3="","",LogicCommon!A3) | E3: SubModuleID : | F3: =IF(LogicCommon!C3="","",LogicCommon!C3) -> MSLA | G3: LogicClass : | H3: =IF(LogicCommon!E3="","",LogicCommon!E3) -> MSLAL_PoPrmsRecvIfService | I3: Ope.Method : | J3: @ | K3: SuperClassPj.ID : | L3: =IF(LogicCommon!G3="","",LogicCommon!G3) | O3: Gene.Type : | P3: ALL
A4: * | E4: Version : | F4: 000000 | G4: LogicName : | H4: =IF(LogicCommon!E4="","",LogicCommon!E4) -> 発注納期回答受信ＩＦサービス | I4: Ope.Name : | J4: 取込前チェック | K4: SuperLogicID : | L4: =IF(LogicCommon!G4="","",LogicCommon!G4) -> MS.MSUDL5010 | M4: ImplOpe.ID:
A5: * | E5: ACType :
A6: * | D6: 概要 : | E6: 納期回答受信ＩＦ取込を行う前のチェック処理 | M6: ID | O6: ID | Q6: ID | AD6: ID | AF6: ID | AH6: ID
A7: # | I7: U | K7: K | L7: K | M7: K | N7: K | O7: K | P7: K | Q7: K | R7: K | S7: K | T7: K | U7: K | V7: K | W7: K | X7: K | Y7: K | Z7: K | AA7: K | AB7: K | AC7: o | AE7: o | AG7: o
A8: # | D8: ブロック名 Block Name | E8: 型 Type | G8: super/share | H8: 対象ブロック名 Target Block Name | K8: REQ_UPD_CNT_CHK | L8: REQUIRED | M8: CHK_NUM | N8: SMALL_LARGE | O8: CHK_DT | P8: BEFORE_AFTER | Q8: CHK_PTN | R8: DUPLICATE | S8: TOO_MANY_INPUTS | T8: AT_LEAST_ONE | U8: ONLY_ONE_INPUT | V8: LIST_LOGIC | W8: LIST_OUT | X8: LIST_OUT_BASE | Y8: LIST_IN | Z8: LIST_IN_BASE | AA8: CONST | AB8: NULL_VAL | AC8: TargetName | AE8: TargetName | AG8: TargetName | AK8: ブロック備考 Block Remarks
A9: # | D9: 項目名 Field Name | E9: 型 Type | F9: 桁 Digits | G9: フルネーム Full Name | H9: 日本語名 Japanese Name | I9: 上り項目 Request Message Field | J9: 下り項目 Response Message Field | AI9: 条件および編集方法 Conditions and Editing Methods | AK9: 項目備考 Field Remarks
A10: #
A11: 10 | B11: * | D11: PoPrmsRecvIf_Chk01_Dtl | E11: L | AC11: 上り項目 | AD11: 下り項目 | AE11: 上り項目 | AF11: 下り項目 | AG11: 上り項目 | AH11: 下り項目
A12: 10 | D12: prms | E12: R | F12: DBC:MS.MST_PRMS_RECV_IF
A13: 10 | D13: prms.data_lno# | E13: RI | G13: Data row No. | H13: データ行ＮＯ | I13: E | J13: E | L13: E
A14: 10 | D14: prms.data_no# | E14: RI | G14: Data No. | H14: データＮＯ | I14: E | J14: E | L14: E
A15: 10 | D15: prms.ext_data_no# | E15: RI | G15: External system data No. | H15: 外部システムデータＮＯ | I15: E | J15: E | L15: E
A16: 10 | D16: prms.ext_data_lno# | E16: RI | G16: External system data row No. | H16: 外部システムデータ行ＮＯ | I16: E | J16: E | L16: E
A17: 10 | D17: prms.data_crud_typ# | E17: RI | G17: Data update type | H17: データ更新区分 | I17: E | J17: E | L17: E | AA17: MAC_DATA_CRUD_TYP
A18: 10 | D18: prms.exe_sts_typ# | E18: RI | G18: PG execution status type | H18: ＰＧ実行状況区分 | I18: E | J18: E | AA18: MAC_EXE_STS_TYP
A19: 10 | D19: prms.po_no# | E19: RI | G19: PO No. | H19: 発注ＮＯ | I19: E | J19: E | L19: E
A20: 10 | D20: prms.po_rev# | E20: RI | G20: PO rev. number | H20: 発注改訂番号 | I20: E | J20: E
A21: 10 | D21: prms.po_d_no# | E21: RI | G21: PO details No. | H21: 発注明細ＮＯ | I21: E | J21: E | L21: E
A22: 10 | D22: prms.sppl_cd# | E22: RI | G22: Supplier cd. | H22: 発注先ＣＤ | I22: E | J22: E | L22: E | V22: MA.MAUAL0010.Bp | W22: prms_recv_flg;sppl_cal_cd;subcon_flg | X22: prms_recv_flg;sppl_cal_cd;subcon_flg | Y22: MAC_BP_IS_SRCH_TYP.SPPL | Z22: bp_is_srch_typ
A23: 10 | D23: prms.itm_cd# | E23: RI | G23: Item cd. | H23: 品目ＣＤ | I23: E | J23: E
A24: 10 | D24: prms.itm_sub1# | E24: RI | G24: Branch No. 1 | H24: 枝番１ | I24: E | J24: E | AB24: E
A25: 10 | D25: prms.itm_sub2# | E25: RI | G25: Branch No. 2 | H25: 枝番２ | I25: E | J25: E | AB25: E
A26: 10 | D26: prms.itm_sub3# | E26: RI | G26: Branch No. 3 | H26: 枝番３ | I26: E | J26: E | AB26: E
A27: 10 | D27: prms.trd_unit_cd# | E27: RI | G27: Transaction unit cd. | H27: 取引単位ＣＤ | I27: E | J27: E | L27: E
A28: 10 | D28: prms.trd_unit_qty# | E28: RI | G28: Transaction unit qty. | H28: 取引単位数量 | I28: E | J28: E | L28: E | M28: positive
A29: 10 | D29: prms.prms_dlv_tm# | E29: RI | G29: Replied delivery date and time | H29: 回答納入日時 | I29: E | J29: E | L29: E
A30: 10 | D30: prms.prms_rmrks# | E30: RI | G30: Order promising remarks | H30: 納期回答備考 | I30: - | J30: -
A31: 10 | D31: prms.dlv_inst_rev# | E31: RI | G31: Delivery order rev. number | H31: 納入指示改訂番号 | I31: E | J31: E
A32: 10 | D32: prms.dlv_inst_no# | E32: RI | G32: Delivery order No. | H32: 納入指示ＮＯ | I32: E | J32: E
A33: 10 | D33: prms.dlv_inst_d_no# | E33: RI | G33: Delivery order details No. | H33: 納入指示明細ＮＯ | I33: E | J33: E
A34: 10 | D34: prms.sub_char1# | E34: RI | G34: Spare CHAR column 1 | H34: 予備ＣＨＡＲ項目１ | I34: E | J34: E
A35: 10 | D35: prms.sub_char2# | E35: RI | G35: Spare CHAR column 2 | H35: 予備ＣＨＡＲ項目２ | I35: E | J35: E
A36: 10 | D36: prms.sub_char3# | E36: RI | G36: Spare CHAR column 3 | H36: 予備ＣＨＡＲ項目３ | I36: E | J36: E
A37: 10 | D37: prms.sub_char4# | E37: RI | G37: Spare CHAR column 4 | H37: 予備ＣＨＡＲ項目４ | I37: E | J37: E
A38: 10 | D38: prms.sub_char5# | E38: RI | G38: Spare CHAR column 5 | H38: 予備ＣＨＡＲ項目５ | I38: E | J38: E
A39: 10 | D39: prms.sub_char6# | E39: RI | G39: Spare CHAR column 6 | H39: 予備ＣＨＡＲ項目６ | I39: E | J39: E
A40: 10 | D40: prms.sub_char7# | E40: RI | G40: Spare CHAR column 7 | H40: 予備ＣＨＡＲ項目７ | I40: E | J40: E
...

Sheet PoPrmsRecvIf_Upd01
A1: * | B1: * | D1: L | E1: 1
A2: * | D2: オペレーション実装仕様書 Operation Specification Implementation Sheet | E2: ModuleID : | F2: =IF(LogicCommon!C2="","",LogicCommon!C2) -> MS | G2: LogicID : | H2: =IF(LogicCommon!E2="","",LogicCommon!E2) -> MSLAL5030 | I2: Ope.ID : | J2: PoPrmsRecvIf_Upd01 | K2: Pj.ID : | L2: =IF(LogicCommon!G2="","",LogicCommon!G2) -> MC | M2: Ope.Body : | N2: "mcframe.serverMAUD.MAUDL5010.MAUDL_Operation"
A3: * | D3: =IF(LogicCommon!A3="","",LogicCommon!A3) | E3: SubModuleID : | F3: =IF(LogicCommon!C3="","",LogicCommon!C3) -> MSLA | G3: LogicClass : | H3: =IF(LogicCommon!E3="","",LogicCommon!E3) -> MSLAL_PoPrmsRecvIfService | I3: Ope.Method : | J3: @ | K3: SuperClassPj.ID : | L3: =IF(LogicCommon!G3="","",LogicCommon!G3) | O3: Gene.Type : | P3: ALL
A4: * | E4: Version : | F4: 000000 | G4: LogicName : | H4: =IF(LogicCommon!E4="","",LogicCommon!E4) -> 発注納期回答受信ＩＦサービス | I4: Ope.Name : | J4: 納期回答受信ＩＦ取込１ | K4: SuperLogicID : | L4: =IF(LogicCommon!G4="","",LogicCommon!G4) -> MS.MSUDL5010 | M4: ImplOpe.ID: | N4: PF.PFUDL0040.Upd01
A5: * | E5: ACType :
A6: * | D6: 概要 : | E6: 納期回答受信ＩＦ取込を行う。（ＥＳＢのリアルタイム取込から呼び出される） | M6: ID | O6: ID | Q6: ID
A7: # | I7: U | K7: K | L7: o | N7: o | P7: o
A8: # | D8: ブロック名 Block Name | E8: 型 Type | G8: super/share | H8: 対象ブロック名 Target Block Name | L8: TargetName | N8: TargetName | P8: TargetName | T8: ブロック備考 Block Remarks
A9: # | D9: 項目名 Field Name | E9: 型 Type | F9: 桁 Digits | G9: フルネーム Full Name | H9: 日本語名 Japanese Name | I9: 上り項目 Request Message Field | J9: 下り項目 Response Message Field | R9: 条件および編集方法 Conditions and Editing Methods | T9: 項目備考 Field Remarks
A10: # | L10: 上り項目 Request Message Field | M10: 下り項目 Response Message Field | N10: 上り項目 Request Message Field | O10: 下り項目 Response Message Field | P10: 上り項目 Request Message Field | Q10: 下り項目 Response Message Field
A11: 10 | B11: * | D11: PoPrmsRecvIf_Upd01_Dtl | E11: L | G11: $share$ | H11: PF.PFUDL0040.Upd01.Upd01_Dtl
A12: 10 | D12: data_no | E12: #MA.IF_DATA_NO | G12: Data No. | H12: データＮＯ | I12: E | J12: -
A13: 10 | D13: ext_data_no | E13: #MA.IF_EXT_DATA_NO | G13: External system data No. | H13: 外部システムデータＮＯ | I13: E | J13: -
A14: 10 | D14: ext_sys_cd | E14: #MA.EXT_SYS_CD | G14: External system cd. | H14: 外部システムＣＤ | I14: E | J14: -
A15: 10 | D15: bp_cd | E15: #MA.BP_CD | G15: Supplier cd. | H15: 発注先ＣＤ | I15: E | J15: -
D16: 詳細 :

Sheet PoPrmsRecvIf_Upd02
A1: * | B1: * | D1: L | E1: 1
A2: * | D2: オペレーション実装仕様書 Operation Specification Implementation Sheet | E2: ModuleID : | F2: =IF(LogicCommon!C2="","",LogicCommon!C2) -> MS | G2: LogicID : | H2: =IF(LogicCommon!E2="","",LogicCommon!E2) -> MSLAL5030 | I2: Ope.ID : | J2: PoPrmsRecvIf_Upd02 | K2: Pj.ID : | L2: =IF(LogicCommon!G2="","",LogicCommon!G2) -> MC | M2: Ope.Body : | N2: "mcframe.serverMAUD.MAUDL5010.MAUDL_Operation"
A3: * | D3: =IF(LogicCommon!A3="","",LogicCommon!A3) | E3: SubModuleID : | F3: =IF(LogicCommon!C3="","",LogicCommon!C3) -> MSLA | G3: LogicClass : | H3: =IF(LogicCommon!E3="","",LogicCommon!E3) -> MSLAL_PoPrmsRecvIfService | I3: Ope.Method : | J3: @ | K3: SuperClassPj.ID : | L3: =IF(LogicCommon!G3="","",LogicCommon!G3) | O3: Gene.Type : | P3: ALL
A4: * | E4: Version : | F4: 000000 | G4: LogicName : | H4: =IF(LogicCommon!E4="","",LogicCommon!E4) -> 発注納期回答受信ＩＦサービス | I4: Ope.Name : | J4: 納期回答受信ＩＦ取込２ | K4: SuperLogicID : | L4: =IF(LogicCommon!G4="","",LogicCommon!G4) -> MS.MSUDL5010 | M4: ImplOpe.ID: | N4: MB.MBBEL5010.Upd01
A5: * | E5: ACType :
A6: * | D6: 概要 : | E6: 納期回答受信ＩＦ取込を行う。（ＩＦデータ確認、および納期回答受信ＩＦ取込バッチから呼び出される） | M6: ID | O6: ID | Q6: ID
A7: # | I7: U | K7: K | L7: o | N7: o | P7: o
A8: # | D8: ブロック名 Block Name | E8: 型 Type | G8: super/share | H8: 対象ブロック名 Target Block Name | L8: TargetName | N8: TargetName | P8: TargetName | T8: ブロック備考 Block Remarks
A9: # | D9: 項目名 Field Name | E9: 型 Type | F9: 桁 Digits | G9: フルネーム Full Name | H9: 日本語名 Japanese Name | I9: 上り項目 Request Message Field | J9: 下り項目 Response Message Field | R9: 条件および編集方法 Conditions and Editing Methods | T9: 項目備考 Field Remarks
A10: # | L10: 上り項目 Request Message Field | M10: 下り項目 Response Message Field | N10: 上り項目 Request Message Field | O10: 下り項目 Response Message Field | P10: 上り項目 Request Message Field | Q10: 下り項目 Response Message Field
A11: 10 | B11: * | D11: PoPrmsRecvIf_Upd02_Dtl | E11: L | G11: $share$ | H11: MB.MBBEL5010.Upd01.IfDataImp_Upd01_Dtl
A12: 10 | D12: data_no | E12: #MA.IF_DATA_NO | G12: Data No. | H12: データＮＯ | I12: E | J12: -
A13: 10 | D13: ext_data_no | E13: #MA.IF_EXT_DATA_NO | G13: External system data No. | H13: 外部システムデータＮＯ | I13: E | J13: -
A14: 10 | D14: ext_sys_cd | E14: #MA.EXT_SYS_CD | G14: External system cd. | H14: 外部システムＣＤ | I14: E | J14: -
A15: 10 | D15: bp_cd | E15: #MA.BP_CD | G15: Supplier cd. | H15: 発注先ＣＤ | I15: E | J15: -
L16: 上り項目 Request Message Field | M16: 下り項目 Response Message Field | N16: 上り項目 Request Message Field | O16: 下り項目 Response Message Field | P16: 上り項目 Request Message Field | Q16: 下り項目 Response Message Field
A17: 20 | B17: * | D17: PoPrmsRecvIf_Upd02_Cnd | E17: R | G17: $share$ | H17: MB.MBBEL5010.Upd01.IfDataImp_Upd01_Cnd
A18: 20 | D18: exe_unit_lump_flg | E18: #MA.FLG | G18: Process unit aggregation | H18: 処理単位まとめ | I18: E | J18: -
A19: 20 | D19: if_upd_typ | E19: #MA.IF_UPD_TYP | G19: IF update type | H19: ＩＦ更新区分 | I19: E | J19: -
A20: 20 | D20: src_actlumprecv_flg | E20: #MA.FLG | G20: Caller results import batch | H20: 呼出元実績一括受信バッチ | I20: E | J20: -
L21: 上り項目 Request Message Field | M21: 下り項目 Response Message Field | N21: 上り項目 Request Message Field | O21: 下り項目 Response Message Field | P21: 上り項目 Request Message Field | Q21: 下り項目 Response Message Field
A22: 30 | B22: * | D22: PoPrmsRecvIf_Upd02_Rslt | E22: R | G22: $share$ | H22: MB.MBBEL5010.Upd01.IfDataImp_Upd01_Rslt
A23: 30 | D23: total_num | E23: N | G23: Number of processed target | H23: 処理対象件数 | I23: - | J23: E
A24: 30 | D24: ok_num | E24: N | G24: Number of entries | H24: 登録件数 | I24: - | J24: E
A25: 30 | D25: err_num | E25: N | G25: Error count | H25: エラー件数 | I25: - | J25: E
A26: 30 | D26: skip_num | E26: N | G26: Skip count | H26: スキップ件数 | I26: - | J26: E
D27: 詳細 :

Sheet PoPrmsRecvIf_Upd03
A1: * | B1: * | D1: L | E1: 1
A2: * | D2: オペレーション実装仕様書 Operation Specification Implementation Sheet | E2: ModuleID : | F2: =IF(LogicCommon!C2="","",LogicCommon!C2) -> MS | G2: LogicID : | H2: =IF(LogicCommon!E2="","",LogicCommon!E2) -> MSLAL5030 | I2: Ope.ID : | J2: PoPrmsRecvIf_Upd03 | K2: Pj.ID : | L2: =IF(LogicCommon!G2="","",LogicCommon!G2) -> MC | M2: Ope.Body : | N2: "mcframe.serverMAUD.MAUDL5010.MAUDL_Operation"
A3: * | D3: =IF(LogicCommon!A3="","",LogicCommon!A3) | E3: SubModuleID : | F3: =IF(LogicCommon!C3="","",LogicCommon!C3) -> MSLA | G3: LogicClass : | H3: =IF(LogicCommon!E3="","",LogicCommon!E3) -> MSLAL_PoPrmsRecvIfService | I3: Ope.Method : | J3: @ | K3: SuperClassPj.ID : | L3: =IF(LogicCommon!G3="","",LogicCommon!G3) | O3: Gene.Type : | P3: ALL
A4: * | E4: Version : | F4: 000000 | G4: LogicName : | H4: =IF(LogicCommon!E4="","",LogicCommon!E4) -> 発注納期回答受信ＩＦサービス | I4: Ope.Name : | J4: 納期回答受信ＩＦ取込３ | K4: SuperLogicID : | L4: =IF(LogicCommon!G4="","",LogicCommon!G4) -> MS.MSUDL5010 | M4: ImplOpe.ID:
A5: * | E5: ACType :
A6: * | D6: 概要 : | E6: 納期回答受信ＩＦ取込を行う。（マルチスレッド実行用） | M6: ID | O6: ID | Q6: ID
A7: # | I7: U | K7: K | L7: o | N7: o | P7: o
A8: # | D8: ブロック名 Block Name | E8: 型 Type | G8: super/share | H8: 対象ブロック名 Target Block Name | L8: TargetName | N8: TargetName | P8: TargetName | T8: ブロック備考 Block Remarks
A9: # | D9: 項目名 Field Name | E9: 型 Type | F9: 桁 Digits | G9: フルネーム Full Name | H9: 日本語名 Japanese Name | I9: 上り項目 Request Message Field | J9: 下り項目 Response Message Field | R9: 条件および編集方法 Conditions and Editing Methods | T9: 項目備考 Field Remarks
A10: # | L10: 上り項目 Request Message Field | M10: 下り項目 Response Message Field | N10: 上り項目 Request Message Field | O10: 下り項目 Response Message Field | P10: 上り項目 Request Message Field | Q10: 下り項目 Response Message Field
A11: 10 | B11: * | D11: PoPrmsRecvIf_Upd03_Dtl | E11: L
A12: 10 | D12: prms | E12: R | F12: DBC:MS.MST_PRMS_RECV_IF
A13: 10 | D13: prms.data_lno# | E13: RI | G13: Data row No. | H13: データ行ＮＯ | I13: E | J13: -
A14: 10 | D14: prms.data_no# | E14: RI | G14: Data No. | H14: データＮＯ | I14: E | J14: -
A15: 10 | D15: prms.ext_data_no# | E15: RI | G15: External system data No. | H15: 外部システムデータＮＯ | I15: E | J15: -
A16: 10 | D16: prms.ext_data_lno# | E16: RI | G16: External system data row No. | H16: 外部システムデータ行ＮＯ | I16: E | J16: -
A17: 10 | D17: prms.po_no# | E17: RI | G17: PO No. | H17: 発注ＮＯ | I17: E | J17: -
A18: 10 | D18: prms.po_d_no# | E18: RI | G18: PO details No. | H18: 発注明細ＮＯ | I18: E | J18: -
L19: 上り項目 Request Message Field | M19: 下り項目 Response Message Field | N19: 上り項目 Request Message Field | O19: 下り項目 Response Message Field | P19: 上り項目 Request Message Field | Q19: 下り項目 Response Message Field
A20: 20 | B20: * | D20: PoPrmsRecvIf_Upd03_Rslt | E20: R
A21: 20 | D21: total_num | E21: N | G21: Number of processed target | H21: 処理対象件数 | I21: - | J21: E
A22: 20 | D22: ok_num | E22: N | G22: Number of entries | H22: 登録件数 | I22: - | J22: E
A23: 20 | D23: err_num | E23: N | G23: Error count | H23: エラー件数 | I23: - | J23: E
A24: 20 | D24: skip_num | E24: N | G24: Skip count | H24: スキップ件数 | I24: - | J24: E
D25: 詳細 :

Sheet PoPrmsRecvIf_Upd04
A1: * | B1: * | D1: L | E1: 1
A2: * | D2: オペレーション実装仕様書 Operation Specification Implementation Sheet | E2: ModuleID : | F2: =IF(LogicCommon!C2="","",LogicCommon!C2) -> MS | G2: LogicID : | H2: =IF(LogicCommon!E2="","",LogicCommon!E2) -> MSLAL5030 | I2: Ope.ID : | J2: PoPrmsRecvIf_Upd04 | K2: Pj.ID : | L2: =IF(LogicCommon!G2="","",LogicCommon!G2) -> MC | M2: Ope.Body : | N2: "mcframe.serverMAUD.MAUDL5010.MAUDL_Operation"
A3: * | D3: =IF(LogicCommon!A3="","",LogicCommon!A3) | E3: SubModuleID : | F3: =IF(LogicCommon!C3="","",LogicCommon!C3) -> MSLA | G3: LogicClass : | H3: =IF(LogicCommon!E3="","",LogicCommon!E3) -> MSLAL_PoPrmsRecvIfService | I3: Ope.Method : | J3: @ | K3: SuperClassPj.ID : | L3: =IF(LogicCommon!G3="","",LogicCommon!G3) | O3: Gene.Type : | P3: ALL
A4: * | E4: Version : | F4: 000000 | G4: LogicName : | H4: =IF(LogicCommon!E4="","",LogicCommon!E4) -> 発注納期回答受信ＩＦサービス | I4: Ope.Name : | J4: 納期回答受信ＩＦ取込４ | K4: SuperLogicID : | L4: =IF(LogicCommon!G4="","",LogicCommon!G4) -> MS.MSUDL5010 | M4: ImplOpe.ID:
A5: * | E5: ACType :
A6: * | D6: 概要 : | E6: 納期回答受信ＩＦ取込を行う。 | M6: ID | O6: ID | Q6: ID
A7: # | I7: U | K7: K | L7: o | N7: o | P7: o
A8: # | D8: ブロック名 Block Name | E8: 型 Type | G8: super/share | H8: 対象ブロック名 Target Block Name | L8: TargetName | N8: TargetName | P8: TargetName | T8: ブロック備考 Block Remarks
A9: # | D9: 項目名 Field Name | E9: 型 Type | F9: 桁 Digits | G9: フルネーム Full Name | H9: 日本語名 Japanese Name | I9: 上り項目 Request Message Field | J9: 下り項目 Response Message Field | R9: 条件および編集方法 Conditions and Editing Methods | T9: 項目備考 Field Remarks
A10: # | L10: 上り項目 Request Message Field | M10: 下り項目 Response Message Field | N10: 上り項目 Request Message Field | O10: 下り項目 Response Message Field | P10: 上り項目 Request Message Field | Q10: 下り項目 Response Message Field
A11: 10 | B11: * | D11: PoPrmsRecvIf_Upd04_Dtl | E11: L | G11: $share$ | H11: MS.MSLAL5030.PoPrmsRecvIf_Chk01.PoPrmsRecvIf_Chk01_Dtl
A12: 10 | D12: prms | E12: R | F12: DBC:MS.MST_PRMS_RECV_IF
A13: 10 | D13: prms.data_lno# | E13: RI | G13: Data row No. | H13: データ行ＮＯ | I13: E | J13: E
A14: 10 | D14: prms.data_no# | E14: RI | G14: Data No. | H14: データＮＯ | I14: E | J14: -
A15: 10 | D15: prms.ext_data_no# | E15: RI | G15: External system data No. | H15: 外部システムデータＮＯ | I15: E | J15: -
A16: 10 | D16: prms.ext_data_lno# | E16: RI | G16: External system data row No. | H16: 外部システムデータ行ＮＯ | I16: E | J16: -
A17: 10 | D17: prms.data_crud_typ# | E17: RI | G17: Data update type | H17: データ更新区分 | I17: E | J17: -
A18: 10 | D18: prms.exe_sts_typ# | E18: RI | G18: PG execution status type | H18: ＰＧ実行状況区分 | I18: E | J18: E
A19: 10 | D19: prms.po_no# | E19: RI | G19: PO No. | H19: 発注ＮＯ | I19: E | J19: -
A20: 10 | D20: prms.po_rev# | E20: RI | G20: PO rev. number | H20: 発注改訂番号 | I20: E | J20: -
A21: 10 | D21: prms.po_d_no# | E21: RI | G21: PO details No. | H21: 発注明細ＮＯ | I21: E | J21: -
A22: 10 | D22: prms.sppl_cd# | E22: RI | G22: Supplier cd. | H22: 発注先ＣＤ | I22: E | J22: E
A23: 10 | D23: prms.itm_cd# | E23: RI | G23: Item cd. | H23: 品目ＣＤ | I23: E | J23: -
A24: 10 | D24: prms.itm_sub1# | E24: RI | G24: Branch No. 1 | H24: 枝番１ | I24: E | J24: -
... A77: 10 | D77: purc_usr_cd | E77: #MA.USR_CD | G77: Purchasing PIC cd. | H77: 購買担当者ＣＤ | I77: - | J77: E
D78: 詳細 :

Sheet 来歴
A1: 変更来歴
A3: Rev. | H3: 修正番号 | O3: 変更内容 | AQ3: 変更箇所
A4: 1 | O4: 初版
A5: 1.1 | O5: 英語の名称を追記 | AQ5: 全般
