Workbook

Sheet LogicCommon
A2: ロジック共通定義 | B2: ModuleID : | C2: MB | D2: LogicID : | E2: MBBEL0050 | F2: Pj.ID : | G2: MC
B3: SubModuleID : | C3: MBBE | D3: LogicClass : | E3: MBBEL_BizDatDLHstSrch | F3: SuperClassPj.ID :
D4: LogicName : | E4: 業務データダウンロード履歴一覧 | F4: SuperLogicID : | G4: MB.MBUDL5010
A5: 概要 :
A6: 詳細 :

Sheet Srch01
A1: * | B1: * | D1: L | E1: 1
A2: * | D2: オペレーション実装仕様書 Operation Specification Implementation Sheet | E2: ModuleID : | F2: =IF(LogicCommon!C2="","",LogicCommon!C2) -> MB | G2: LogicID : | H2: =IF(LogicCommon!E2="","",LogicCommon!E2) -> MBBEL0050 | I2: Ope.ID : | J2: Srch01 | K2: Pj.ID : | L2: =IF(LogicCommon!G2="","",LogicCommon!G2) -> MC | M2: Ope.Body : | N2: "mcframe.serverMAUD.MAUDL5010.MAUDL_Searcher"
A3: * | E3: SubModuleID : | F3: =IF(LogicCommon!C3="","",LogicCommon!C3) -> MBBE | G3: LogicClass : | H3: =IF(LogicCommon!E3="","",LogicCommon!E3) -> MBBEL_BizDatDLHstSrch | I3: Ope.Method : | J3: @ | K3: SuperClassPj.ID : | M3: ReportID : | O3: Gene.Type : | P3: ALL
A4: * | E4: Version : | F4: 000000 | G4: LogicName : | H4: =IF(LogicCommon!E4="","",LogicCommon!E4) -> 業務データダウンロード履歴一覧 | I4: Ope.Name : | J4: 検索 | K4: SuperLogicID : | L4: =IF(LogicCommon!G4="","",LogicCommon!G4) -> MB.MBUDL5010
A5: * | E5: ACType :
A6: * | D6: 概要 : | E6: 業務データダウンロード履歴を検索する | M6: ID | O6: ID | Q6: ID
A7: # | I7: U | K7: K | L7: o | N7: o | P7: o
A8: # | D8: ブロック名 Block Name | E8: 型 Type | G8: super/share | H8: 対象ブロック名 Target Block Name | K8: CONST | L8: TargetName | T8: ブロック備考 Block Remarks
A9: # | D9: 項目名 Field Name | E9: 型 Type | F9: 桁 Digits | G9: フルネーム Full Name | H9: 日本語名 Japanese Name | I9: 上り項目 Request Message Field | J9: 下り項目 Response Message Field | R9: 条件および編集方法 Conditions and Editing Methods | T9: 項目備考 Field Remarks
A10: # | L10: 上り項目 Request Message Field | M10: 下り項目 Response Message Field | N10: 上り項目 Request Message Field | O10: 下り項目 Response Message Field | P10: 上り項目 Request Message Field | Q10: 下り項目 Response Message Field
A11: 10 | B11: * | D11: Srch01_Cnd | E11: R
A12: 10 | D12: running_flg | E12: #MA.FLG | G12: Executing | H12: 実行中 | I12: E | J12: -
A13: 10 | D13: success_flg | E13: #MA.FLG | G13: End | H13: 終了 | I13: E | J13: -
A14: 10 | D14: download_flg | E14: #MA.FLG | G14: Downloaded | H14: ダウンロード済み | I14: E | J14: -
A15: 10 | D15: error_flg | E15: #MA.FLG | G15: Error | H15: エラー | I15: E | J15: -
A16: 10 | D16: excel_flg | E16: #MA.FLG | G16: Excel | H16: Excel | I16: E | J16: -
A17: 10 | D17: csv_flg | E17: #MA.FLG | G17: CSV | H17: CSV | I17: E | J17: -
A18: 10 | D18: report_flg | E18: #MA.FLG | G18: Output report | H18: 帳票出力 | I18: E | J18: -
A19: 10 | D19: screen_flg | E19: #MA.FLG | G19: Display screen | H19: 画面表示 | I19: E | J19: -
A20: 10 | D20: proc_st_tm_fr | E20: #MA.TM | G20: Process start date and time FROM | H20: 処理開始日時ＦＲＯＭ | I20: E | J20: -
A21: 10 | D21: proc_st_tm_to | E21: #MA.TM | G21: Process start date and time TO | H21: 処理開始日時ＴＯ | I21: E | J21: -
A22: 10 | D22: proc_end_tm_fr | E22: #MA.TM | G22: Process end date FROM | H22: 処理終了日時ＦＲＯＭ | I22: E | J22: -
A23: 10 | D23: proc_end_tm_to | E23: #MA.TM | G23: Process end date TO | H23: 処理終了日時ＴＯ | I23: E | J23: -
... A36: 10 | D36: biz_dat_dl_cond | E36: #MA.BIZ_DAT_DL_COND | G36: Business data download search criteria | H36: 業務データダウンロード検索条件 | I36: E | J36: -
L37: 上り項目 Request Message Field | M37: 下り項目 Response Message Field | N37: 上り項目 Request Message Field | O37: 下り項目 Response Message Field | P37: 上り項目 Request Message Field | Q37: 下り項目 Response Message Field
A38: 20 | B38: * | D38: Srch01_Rslt | E38: L
A39: 20 | D39: biz_dat_dl_hst_no | E39: #MA.BIZ_DAT_DL_HST_NO | G39: Business data download execution history No. | H39: 業務データダウンロード実行履歴ＮＯ | I39: - | J39: E
A40: 20 | D40: biz_dat_file_typ | E40: #MA.BIZ_DAT_FILE_TYP | G40: File classification type | H40: ファイル種類区分 | I40: - | J40: E | K40: MAC_BIZ_DAT_FILE_TYP
A41: 20 | D41: biz_dat_file_typ_nm | E41: #MA.BIZ_DAT_FILE_TYP_NM | G41: File classification type name | H41: ファイル種類区分名 | I41: - | J41: E
A42: 20 | D42: biz_dat_dl_sts_typ | E42: #MA.BIZ_DAT_DL_STS_TYP | G42: Business data download execution status type | H42: 業務データダウンロード実行状況区分 | I42: - | J42: E | K42: MAC_BIZ_DAT_DL_STS_TYP
A43: 20 | D43: biz_dat_dl_sts_typ_nm | E43: #MA.BIZ_DAT_DL_STS_TYP_NM | G43: Business data download execution status type name | H43: 業務データダウンロード実行状況区分名 | I43: - | J43: E
A44: 20 | D44: proc_st_tm | E44: #MA.TM | G44: Process start date and time | H44: 処理開始日時 | I44: - | J44: E
A45: 20 | D45: proc_end_tm | E45: #MA.TM | G45: Process end date | H45: 処理終了日時 | I45: - | J45: E
A46: 20 | D46: biz_dat_id | E46: #MA.BIZ_DAT_ID | G46: Business data ID | H46: 業務データＩＤ | I46: - | J46: E
A47: 20 | D47: biz_dat_nm | E47: #MA.BIZ_DAT_NM | G47: Business data name | H47: 業務データ名 | I47: - | J47: E
A48: 20 | D48: biz_dat_dl_cond | E48: #MA.BIZ_DAT_DL_COND | G48: Business data download search criteria | H48: 業務データダウンロード検索条件 | I48: - | J48: E
A49: 20 | D49: usr_cd | E49: #MA.USR_CD | G49: PIC cd. | H49: 担当者ＣＤ | I49: - | J49: E
A50: 20 | D50: usr_nm | E50: #MA.USR_NM | G50: PIC name | H50: 担当者名 | I50: - | J50: E
A51: 20 | D51: file_bin | E51: #MA.BIN | G51: File | H51: ファイル | I51: - | J51: E
A52: 20 | D52: file_size | E52: #MA.FILE_SIZE | G52: File capacity [KB] | H52: ファイル容量［KB］ | I52: - | J52: E
...

Sheet Upd01
A1: * | B1: * | D1: L | E1: 1
A2: * | D2: オペレーション実装仕様書 Operation Specification Implementation Sheet | E2: ModuleID : | F2: =IF(LogicCommon!C2="","",LogicCommon!C2) -> MB | G2: LogicID : | H2: =IF(LogicCommon!E2="","",LogicCommon!E2) -> MBBEL0050 | I2: Ope.ID : | J2: Upd01 | K2: Pj.ID : | L2: =IF(LogicCommon!G2="","",LogicCommon!G2) -> MC | M2: Ope.Body : | N2: "mcframe.serverMAUD.MAUDL5010.MAUDL_Operation"
A3: * | E3: SubModuleID : | F3: =IF(LogicCommon!C3="","",LogicCommon!C3) -> MBBE | G3: LogicClass : | H3: =IF(LogicCommon!E3="","",LogicCommon!E3) -> MBBEL_BizDatDLHstSrch | I3: Ope.Method : | J3: @ | K3: SuperClassPj.ID : | M3: ReportID : | O3: Gene.Type : | P3: ALL
A4: * | E4: Version : | F4: 000000 | G4: LogicName : | H4: =IF(LogicCommon!E4="","",LogicCommon!E4) -> 業務データダウンロード履歴一覧 | I4: Ope.Name : | J4: ダウンロード | K4: SuperLogicID : | L4: =IF(LogicCommon!G4="","",LogicCommon!G4) -> MB.MBUDL5010
A5: * | E5: ACType :
A6: * | D6: 概要 : | E6: 業務データダウンロード履歴を更新する | M6: ID | O6: ID | Q6: ID
A7: # | I7: U | K7: K | L7: o | N7: o | P7: o
A8: # | D8: ブロック名 Block Name | E8: 型 Type | G8: super/share | H8: 対象ブロック名 Target Block Name | K8: CONST | L8: TargetName | T8: ブロック備考 Block Remarks
A9: # | D9: 項目名 Field Name | E9: 型 Type | F9: 桁 Digits | G9: フルネーム Full Name | H9: 日本語名 Japanese Name | I9: 上り項目 Request Message Field | J9: 下り項目 Response Message Field | R9: 条件および編集方法 Conditions and Editing Methods | T9: 項目備考 Field Remarks
A10: # | L10: 上り項目 Request Message Field | M10: 下り項目 Response Message Field | N10: 上り項目 Request Message Field | O10: 下り項目 Response Message Field | P10: 上り項目 Request Message Field | Q10: 下り項目 Response Message Field
A11: 10 | B11: * | D11: Upd01_Dtl | E11: R
A12: 10 | D12: biz_dat_dl_hst_no | E12: #MA.BIZ_DAT_DL_HST_NO | G12: Business data download execution history No. | H12: 業務データダウンロード実行履歴ＮＯ | I12: E | J12: -
A13: 10 | D13: dl_file_path | E13: #MA.FILE_PATH | G13: Output destination | H13: 出力先 | I13: E | J13: -
D14: 詳細 :

Sheet Chk01
A1: * | B1: * | D1: L | E1: 1
A2: * | D2: オペレーション実装仕様書 Operation Specification Implementation Sheet | E2: ModuleID : | F2: =IF(LogicCommon!C2="","",LogicCommon!C2) -> MB | G2: LogicID : | H2: =IF(LogicCommon!E2="","",LogicCommon!E2) -> MBBEL0050 | I2: Ope.ID : | J2: Chk01 | K2: Pj.ID : | L2: =IF(LogicCommon!G2="","",LogicCommon!G2) -> MC | M2: Ope.Body : | N2: MA.MAUDL5010.Checker
A3: * | E3: SubModuleID : | F3: =IF(LogicCommon!C3="","",LogicCommon!C3) -> MBBE | G3: LogicClass : | H3: =IF(LogicCommon!E3="","",LogicCommon!E3) -> MBBEL_BizDatDLHstSrch | I3: Ope.Method : | J3: @ | K3: SuperClassPj.ID : | M3: ReportID : | O3: Gene.Type : | P3: ALL
A4: * | E4: Version : | F4: 000000 | G4: LogicName : | H4: =IF(LogicCommon!E4="","",LogicCommon!E4) -> 業務データダウンロード履歴一覧 | I4: Ope.Name : | J4: ダウンロード前チェック | K4: SuperLogicID : | L4: =IF(LogicCommon!G4="","",LogicCommon!G4) -> MB.MBUDL5010
A5: * | E5: ACType :
A6: * | D6: 概要 : | E6: 削除前チェック処理をする | M6: ID | O6: ID | Q6: ID
A7: # | I7: U | K7: K | L7: o | N7: o | P7: o
A8: # | D8: ブロック名 Block Name | E8: 型 Type | G8: super/share | H8: 対象ブロック名 Target Block Name | K8: REQUIRED | L8: TargetName | T8: ブロック備考 Block Remarks
A9: # | D9: 項目名 Field Name | E9: 型 Type | F9: 桁 Digits | G9: フルネーム Full Name | H9: 日本語名 Japanese Name | I9: 上り項目 Request Message Field | J9: 下り項目 Response Message Field | R9: 条件および編集方法 Conditions and Editing Methods | T9: 項目備考 Field Remarks
A10: # | L10: 上り項目 Request Message Field | M10: 下り項目 Response Message Field | N10: 上り項目 Request Message Field | O10: 下り項目 Response Message Field | P10: 上り項目 Request Message Field | Q10: 下り項目 Response Message Field
A11: 10 | B11: * | D11: Chk01_Dtl | E11: L
A12: 10 | D12: peg_no | E12: #MA.INT | G12: Pegging No. | H12: 紐付けＮＯ | I12: E | J12: E
A13: 10 | D13: err_flg | E13: #MA.FLG | G13: Error | H13: エラー | I13: - | J13: E
A14: 10 | D14: rtn_sts_typ | E14: #MA.RTN_STS_TYP | G14: Process result status type | H14: 処理結果状況区分 | I14: - | J14: E
A15: 10 | D15: biz_dat_dl_hst_no | E15: #MA.BIZ_DAT_DL_HST_NO | G15: Business data download execution history No. | H15: 業務データダウンロード実行履歴ＮＯ | I15: E | J15: E | K15: E
A16: 10 | D16: upd_cntr | E16: #MA.UPD_CNT | G16: Update counter | H16: 更新カウンタ | I16: E | J16: E
D17: 詳細 :

Sheet Del01
A1: * | B1: * | D1: L | E1: 1
A2: * | D2: オペレーション実装仕様書 Operation Specification Implementation Sheet | E2: ModuleID : | F2: =IF(LogicCommon!C2="","",LogicCommon!C2) -> MB | G2: LogicID : | H2: =IF(LogicCommon!E2="","",LogicCommon!E2) -> MBBEL0050 | I2: Ope.ID : | J2: Del01 | K2: Pj.ID : | L2: =IF(LogicCommon!G2="","",LogicCommon!G2) -> MC | M2: Ope.Body : | N2: "mcframe.serverMAUD.MAUDL5010.MAUDL_Operation"
A3: * | E3: SubModuleID : | F3: =IF(LogicCommon!C3="","",LogicCommon!C3) -> MBBE | G3: LogicClass : | H3: =IF(LogicCommon!E3="","",LogicCommon!E3) -> MBBEL_BizDatDLHstSrch | I3: Ope.Method : | J3: @ | K3: SuperClassPj.ID : | M3: ReportID : | O3: Gene.Type : | P3: ALL
A4: * | E4: Version : | F4: 000000 | G4: LogicName : | H4: =IF(LogicCommon!E4="","",LogicCommon!E4) -> 業務データダウンロード履歴一覧 | I4: Ope.Name : | J4: 削除 | K4: SuperLogicID : | L4: =IF(LogicCommon!G4="","",LogicCommon!G4) -> MB.MBUDL5010
A5: * | E5: ACType :
A6: * | D6: 概要 : | E6: 業務データダウンロード履歴を削除する | M6: ID | O6: ID | Q6: ID
A7: # | I7: U | K7: K | L7: o | N7: o | P7: o
A8: # | D8: ブロック名 Block Name | E8: 型 Type | G8: super/share | H8: 対象ブロック名 Target Block Name | K8: CONST | L8: TargetName | T8: ブロック備考 Block Remarks
A9: # | D9: 項目名 Field Name | E9: 型 Type | F9: 桁 Digits | G9: フルネーム Full Name | H9: 日本語名 Japanese Name | I9: 上り項目 Request Message Field | J9: 下り項目 Response Message Field | R9: 条件および編集方法 Conditions and Editing Methods | T9: 項目備考 Field Remarks
A10: # | L10: 上り項目 Request Message Field | M10: 下り項目 Response Message Field | N10: 上り項目 Request Message Field | O10: 下り項目 Response Message Field | P10: 上り項目 Request Message Field | Q10: 下り項目 Response Message Field
A11: 10 | B11: * | D11: Del01_Dtl | E11: L | G11: $share$ | H11: MB.MBBEL0050.Chk01.Chk01_Dtl
A12: 10 | D12: peg_no | E12: #MA.INT | G12: Pegging No. | H12: 紐付けＮＯ | I12: - | J12: -
A13: 10 | D13: err_flg | E13: #MA.FLG | G13: Error | H13: エラー | I13: - | J13: -
A14: 10 | D14: rtn_sts_typ | E14: #MA.RTN_STS_TYP | G14: Process result status type | H14: 処理結果状況区分 | I14: - | J14: E
A15: 10 | D15: biz_dat_dl_hst_no | E15: #MA.BIZ_DAT_DL_HST_NO | G15: Business data download execution history No. | H15: 業務データダウンロード実行履歴ＮＯ | I15: E | J15: -
A16: 10 | D16: upd_cntr | E16: #MA.UPD_CNT | G16: Update counter | H16: 更新カウンタ | I16: E | J16: -
D17: 詳細 :

Sheet 来歴
A1: 変更来歴
A3: Rev. | H3: 修正番号 | O3: 変更内容 | AQ3: 変更箇所
A4: 1 | O4: 初版
A5: 1.1 | H5: MB7032#016 | O5: ・「Srch01_Cnd」ブロックの以下の項目を追加 excel_flg、csv_flg、report_flg、screen_flg ・「Srch01_Rslt」ブロックの以下の項目を追加 biz_dat_file_typ、biz_dat_file_typ_nm | AQ5: Srch01
A6: 1.2 | O6: 英語の名称を追記 | AQ6: 全般
