Workbook

Sheet LogicCommon
A2: オペレーション実装仕様書 | B2: ModuleID : | C2: MS | D2: LogicID : | E2: MSBHL0090 | F2: Pj.ID : | G2: MC
B3: SubModuleID : | C3: MSBH | D3: LogicClass : | E3: MSBHL_PayActReg | F3: SuperClassPj.ID :
D4: LogicName : | E4: 支払実績登録 | F4: SuperLogicID : | G4: MS.MSUDL5010
A5: 概要 :
A6: 詳細 :

Sheet Srch01
A1: * | B1: * | D1: L | E1: 1
A2: * | D2: オペレーション実装仕様書 Operation Specification Implementation Sheet | E2: ModuleID : | F2: =IF(LogicCommon!C2="","",LogicCommon!C2) -> MS | G2: LogicID : | H2: =IF(LogicCommon!E2="","",LogicCommon!E2) -> MSBHL0090 | I2: Ope.ID : | J2: Srch01 | K2: Pj.ID : | L2: MC | M2: Ope.Body : | N2: "mcframe.serverMAUD.MAUDL5010.MAUDL_Searcher"
A3: * | D3: =IF(LogicCommon!A3="","",LogicCommon!A3) | E3: SubModuleID : | F3: =IF(LogicCommon!C3="","",LogicCommon!C3) -> MSBH | G3: LogicClass : | H3: =IF(LogicCommon!E3="","",LogicCommon!E3) -> MSBHL_PayActReg | I3: Ope.Method : | J3: =J2 -> Srch01 | K3: SuperClassPj.ID : | O3: Gene.Type : | P3: ALL
A4: * | E4: Version : | F4: 000000 | G4: LogicName : | H4: =IF(LogicCommon!E4="","",LogicCommon!E4) -> 支払実績登録 | I4: Ope.Name : | J4: 支払実績検索 | K4: SuperLogicID : | L4: =IF(LogicCommon!G4="","",LogicCommon!G4) -> MS.MSUDL5010 | M4: ImplOpe.ID:
A5: * | E5: ACType :
A6: * | D6: 概要 : | E6: 支払実績を検索する。 | M6: ID | O6: ID | Q6: ID
A7: # | I7: U | K7: K | L7: o | N7: o | P7: o
A8: # | D8: ブロック名 Block Name | E8: 型 Type | G8: super/share | H8: 対象ブロック名 Target Block Name | K8: CONST | L8: TargetName | N8: TargetName | P8: TargetName | T8: ブロック備考 Block Remarks
A9: # | D9: 項目名 Field Name | E9: 型 Type | F9: 桁 Digits | G9: フルネーム Full Name | H9: 日本語名 Japanese Name | I9: 上り項目 Request Message Field | J9: 下り項目 Response Message Field | R9: 条件および編集方法 Conditions and Editing Methods | T9: 項目備考 Field Remarks
A10: # | L10: 上り項目 Request Message Field | M10: 下り項目 Response Message Field | N10: 上り項目 Request Message Field | O10: 下り項目 Response Message Field | P10: 上り項目 Request Message Field | Q10: 下り項目 Response Message Field
A11: 10 | B11: * | D11: Srch01_Cnd | E11: R
A12: 10 | D12: pay_act_no | E12: #MA.PAY_ACT_NO | G12: Payment result No. | H12: 支払実績ＮＯ | I12: E | J12: -
A13: 10 | D13: pay_act_rev | E13: #MA.SLIP_REV | G13: Payment result revision number | H13: 支払実績改訂番号 | I13: E | J13: -
A14: 10 | D14: latest_flg | E14: #MA.FLG | G14: Latest | H14: 最新 | I14: E | J14: -
A16: 20 | B16: * | D16: Srch01_Hdr | E16: R
A17: 20 | D17: pay_act_no | E17: #MA.PAY_ACT_NO | G17: Payment result No. | H17: 支払実績ＮＯ | I17: - | J17: E
A18: 20 | D18: pay_act_seq | E18: #MA.SLIP_SEQ | G18: Payment result sequence No. | H18: 支払実績連番 | I18: - | J18: E
A19: 20 | D19: pay_act_rev | E19: #MA.SLIP_REV | G19: Payment result revision number | H19: 支払実績改訂番号 | I19: - | J19: E
A20: 20 | D20: latest_flg | E20: #MA.FLG | G20: Latest | H20: 最新 | I20: - | J20: E
A21: 20 | D21: slip_sts_typ | E21: #MA.SLIP_STS_TYP | G21: Slip status type | H21: 伝票状況区分 | I21: - | J21: -
A22: 20 | D22: ac_ym | E22: #MA.YM | G22: Recording month | H22: 計上年月 | I22: - | J22: E
A23: 20 | D23: pay_act_dt | E23: #MA.DT | G23: Actual payment date | H23: 支払実績日 | I23: - | J23: E
A24: 20 | D24: ac_dt | E24: #MA.DT | G24: Recording date | H24: 計上日 | I24: - | J24: E
A25: 20 | D25: pay_basis_dt | E25: #MA.DT | G25: Payment base date | H25: 支払起算日 | I25: - | J25: E
A26: 20 | D26: pay_usr_cd | E26: #MA.USR_CD | G26: Payment PIC cd. | H26: 支払担当者ＣＤ | I26: - | J26: E
A27: 20 | D27: pay_usr_nm | E27: #MA.USR_NM | G27: Payment PIC name | H27: 支払担当者名 | I27: - | J27: E
A28: 20 | D28: pay_dpt_cd | E28: #MA.DPT_CD | G28: Payment dept. cd. | H28: 支払部門ＣＤ | I28: - | J28: E
... A31: 20 | D31: wg_nm | E31: #MA.WG_NM | G31: WG name | H31: ワーキンググループ名 | I31: - | J31: E
I32: - | J32: E
A33: 20 | D33: ins_usr_id | E33: #MA.FCM_USR_ID | G33: Entry user ID | H33: 登録ユーザＩＤ | I33: - | J33: E
A34: 20 | D34: ins_usr_nm | E34: #MA.FCM_USR_NM | G34: Entry user name | H34: 登録ユーザ名 | I34: - | J34: E
A35: 20 | D35: ins_func_id | E35: #MA.FUNC_ID | G35: Entry function ID | H35: 登録機能ＩＤ | I35: - | J35: E
A36: 20 | D36: ins_func_nm | E36: #MA.FUNC_NM | G36: Entry function name | H36: 登録機能名 | I36: - | J36: E
A37: 20 | D37: upd_usr_id | E37: #MA.FCM_USR_ID | G37: Update user ID | H37: 更新ユーザＩＤ | I37: - | J37: E
A38: 20 | D38: upd_usr_nm | E38: #MA.FCM_USR_NM | G38: Update user name | H38: 更新ユーザ名 | I38: - | J38: E
A39: 20 | D39: upd_func_id | E39: #MA.FUNC_ID | G39: Update function ID | H39: 更新機能ＩＤ | I39: - | J39: E
A40: 20 | D40: upd_func_nm | E40: #MA.FUNC_NM | G40: Update function name | H40: 更新機能名 | I40: - | J40: E
A41: 20 | D41: ins_ts | E41: #MA.SYS_TS | G41: Entry date and time | H41: 登録日時 | I41: - | J41: E
A42: 20 | D42: upd_ts | E42: #MA.SYS_TS | G42: Update date and time | H42: 更新日時 | I42: - | J42: E
A43: 20 | D43: upd_srv_req_no | E43: #MA.SRV_REQ_NO | G43: Update request No. | H43: 更新リクエストＮＯ | I43: - | J43: E
...

Sheet Srch02
A1: * | B1: * | D1: L | E1: 1
A2: * | D2: オペレーション実装仕様書 Operation Specification Implementation Sheet | E2: ModuleID : | F2: =IF(LogicCommon!C2="","",LogicCommon!C2) -> MS | G2: LogicID : | H2: =IF(LogicCommon!E2="","",LogicCommon!E2) -> MSBHL0090 | I2: Ope.ID : | J2: Srch02 | K2: Pj.ID : | L2: MC | M2: Ope.Body : | N2: "mcframe.serverMAUD.MAUDL5010.MAUDL_Searcher"
A3: * | D3: =IF(LogicCommon!A3="","",LogicCommon!A3) | E3: SubModuleID : | F3: =IF(LogicCommon!C3="","",LogicCommon!C3) -> MSBH | G3: LogicClass : | H3: =IF(LogicCommon!E3="","",LogicCommon!E3) -> MSBHL_PayActReg | I3: Ope.Method : | J3: =J2 -> Srch02 | K3: SuperClassPj.ID : | O3: Gene.Type : | P3: ALL
A4: * | E4: Version : | F4: 000000 | G4: LogicName : | H4: =IF(LogicCommon!E4="","",LogicCommon!E4) -> 支払実績登録 | I4: Ope.Name : | J4: 支払予定検索 | K4: SuperLogicID : | L4: =IF(LogicCommon!G4="","",LogicCommon!G4) -> MS.MSUDL5010 | M4: ImplOpe.ID:
A5: * | E5: ACType :
A6: * | D6: 概要 : | E6: 支払予定を検索する。 | M6: ID | O6: ID | Q6: ID
A7: # | I7: U | K7: K | L7: o | M7: MSBHL5030.Srch03 | N7: o | P7: o
A8: # | D8: ブロック名 Block Name | E8: 型 Type | G8: super/share | H8: 対象ブロック名 Target Block Name | K8: CONST | L8: TargetName | M8: OPE.MS.MSBHL5030.PaySchd_Srch03 | N8: TargetName | P8: TargetName | T8: ブロック備考 Block Remarks
A9: # | D9: 項目名 Field Name | E9: 型 Type | F9: 桁 Digits | G9: フルネーム Full Name | H9: 日本語名 Japanese Name | I9: 上り項目 Request Message Field | J9: 下り項目 Response Message Field | R9: 条件および編集方法 Conditions and Editing Methods | T9: 項目備考 Field Remarks
A10: # | L10: 上り項目 Request Message Field | M10: 下り項目 Response Message Field | N10: 上り項目 Request Message Field | O10: 下り項目 Response Message Field | P10: 上り項目 Request Message Field | Q10: 下り項目 Response Message Field
A11: 10 | B11: * | D11: Srch02_Cnd | E11: R
A12: 10 | D12: pay_act_dt | E12: #MA.DT | G12: Actual payment date | H12: 支払実績日 | I12: E | J12: -
A13: 10 | D13: ac_dt | E13: #MA.DT | G13: Recording date | H13: 計上日 | I13: E | J13: -
A14: 10 | D14: pay_act_no | E14: #MA.PAY_ACT_NO | G14: Payment result No. | H14: 支払実績ＮＯ | I14: E | J14: -
A15: 10 | D15: pay_act_seq | E15: #MA.SLIP_SEQ | G15: Payment result sequence No. | H15: 支払実績連番 | I15: E | J15: -
A16: 10 | D16: pay_dpt_cd | E16: #MA.DPT_CD | G16: Payment dept. cd. | H16: 支払部門ＣＤ | I16: E | J16: -
A17: 10 | D17: psppl_cd | E17: #MA.BP_CD | G17: Payee cd. | H17: 支払先ＣＤ | I17: E | J17: -
A18: 10 | D18: trd_cur_cd | E18: #MA.CUR_CD | G18: Currency cd. | H18: 通貨ＣＤ | I18: E | J18: -
A19: 10 | D19: ap_sttl_cd | E19: #MA.STTL_CD | G19: AP settlement method cd. | H19: 債務決済方法ＣＤ | I19: E | J19: -
A20: 10 | D20: ap_sttl_typ | E20: #MA.AP_STTL_TYP | G20: AP settlement type | H20: 債務決済区分 | I20: E | J20: -
A21: 10 | D21: bank_ac_cd | E21: #MA.BANK_AC_CD | G21: Bank account cd. | H21: 口座ＣＤ | I21: E | J21: -
A22: 10 | D22: pay_bank_ac_cd | E22: #MA.BANK_AC_CD | G22: Payee account cd. | H22: 支払先口座ＣＤ | I22: E | J22: -
A23: 10 | D23: ap_setoff_typ | E23: #MA.AP_SETOFF_TYP | G23: AP offset destination type | H23: 債務相殺先区分 | I23: E | J23: -
... A29: 10 | D29: pay_schd_dt | E29: #MA.DT | G29: Scheduled payment date | H29: 支払予定日 | I29: E | J29: -
A31: 20 | B31: * | D31: Srch02_Cnd2 | E31: L
A32: 20 | D32: pay_schd_no | E32: #MA.PAY_SCHD_NO | G32: Payment schedule No. | H32: 支払予定ＮＯ | I32: E | J32: -
A34: 30 | B34: * | D34: Srch02_Hdr | E34: R
A35: 30 | D35: bank_ac_cd | E35: #MA.BANK_AC_CD | G35: Bank account cd. | H35: 口座ＣＤ | I35: - | J35: E
A36: 30 | D36: bank_ac_nm | E36: #MA.BANK_AC_NM | G36: Bank account name | H36: 口座名 | I36: - | J36: E
A37: 30 | D37: pay_bank_ac_cd | E37: #MA.BANK_AC_CD | G37: Payee account cd. | H37: 支払先口座ＣＤ | I37: - | J37: E
A38: 30 | D38: pay_bank_ac_nm | E38: #MA.BANK_AC_NM | G38: Payee account name | H38: 支払先口座名 | I38: - | J38: E
A39: 30 | D39: ap_setoff_typ | E39: #MA.AP_SETOFF_TYP | G39: AP offset destination type | H39: 債務相殺先区分 | I39: - | J39: E | K39: MAC_AP_SETOFF_TYP
A40: 30 | D40: ap_setoff_typ_nm | E40: #MA.AP_SETOFF_TYP_NM | G40: AP offset destination name | H40: 債務相殺先区分名 | I40: - | J40: E
A41: 30 | D41: setoff_cd | E41: #MA.BP_CD | G41: Offset destination cd. | H41: 相殺先ＣＤ | I41: - | J41: E
A42: 30 | D42: setoff_nm | E42: #MA.BP_NM | G42: Offset destination name | H42: 相殺先名 | I42: - | J42: E
A43: 30 | D43: so_dpt_cd | E43: #MA.DPT_CD | G43: Offset dept. cd. | H43: 相殺部門ＣＤ | I43: - | J43: E
A44: 30 | D44: so_dpt_nm | E44: #MA.DPT_NM | G44: Offset dept. name | H44: 相殺部門名 | I44: - | J44: E
A45: 30 | D45: note_no | E45: #MA.NOTE_NO | G45: Note number | H45: 手形番号 | I45: - | J45: E
A46: 30 | D46: note_typ | E46: #MA.NOTE_TYP | G46: Note type | H46: 手形区分 | I46: - | J46: E | K46: MAC_NOTE_TYP
A47: 30 | D47: note_typ_nm | E47: #MA.NOTE_TYP_NM | G47: Note type name | H47: 手形区分名 | I47: - | J47: E
...

Sheet Ins01
A1: * | B1: * | D1: L | E1: 1
A2: * | D2: オペレーション実装仕様書 Operation Specification Implementation Sheet | E2: ModuleID : | F2: MS | G2: LogicID : | H2: =IF(LogicCommon!E2="","",LogicCommon!E2) -> MSBHL0090 | I2: Ope.ID : | J2: Ins01 | K2: Pj.ID : | L2: MC | M2: Ope.Body : | N2: "mcframe.serverMAUD.MAUDL5010.MAUDL_Operation"
A3: * | E3: SubModuleID : | F3: MSBH | G3: LogicClass : | H3: =IF(LogicCommon!E3="","",LogicCommon!E3) -> MSBHL_PayActReg | I3: Ope.Method : | J3: =J2 -> Ins01 | K3: SuperClassPj.ID : | O3: Gene.Type : | P3: ALL
A4: * | E4: Version : | F4: 000000 | G4: LogicName : | H4: =IF(LogicCommon!E4="","",LogicCommon!E4) -> 支払実績登録 | I4: Ope.Name : | J4: 登録 | K4: SuperLogicID : | L4: =IF(LogicCommon!G4="","",LogicCommon!G4) -> MS.MSUDL5010 | M4: ImplOpe.ID:
A5: * | E5: ACType :
A6: * | D6: 概要 : | E6: 支払実績を登録する。 | M6: ID | O6: ID | Q6: ID
A7: # | I7: U | K7: K | L7: o | N7: o | P7: o
A8: # | D8: ブロック名 Block Name | E8: 型 Type | G8: super/share | H8: 対象ブロック名 Target Block Name | L8: TargetName | N8: TargetName | P8: TargetName | T8: ブロック備考 Block Remarks
A9: # | D9: 項目名 Field Name | E9: 型 Type | F9: 桁 Digits | G9: フルネーム Full Name | H9: 日本語名 Japanese Name | I9: 上り項目 Request Message Field | J9: 下り項目 Response Message Field | R9: 条件および編集方法 Conditions and Editing Methods | T9: 項目備考 Field Remarks
A10: # | L10: 上り項目 Request Message Field | M10: 下り項目 Response Message Field | N10: 上り項目 Request Message Field | O10: 下り項目 Response Message Field | P10: 上り項目 Request Message Field | Q10: 下り項目 Response Message Field
A11: 10 | B11: * | D11: Ins01_Hdr | E11: R | G11: $share$ | H11: MS.MSBHL5040.PayAct_Chk01.PayAct_Chk01_Hdr
A12: 10 | D12: pa | E12: R | F12: DBC:MS.MST_PAY_ACT
A13: 10 | D13: pa.pay_act_no# | E13: RI | G13: Payment result No. | H13: 支払実績ＮＯ | I13: - | J13: E
A14: 10 | D14: pa.pay_act_seq# | E14: RI | G14: Payment result sequence No. | H14: 支払実績連番 | I14: - | J14: E
A15: 10 | D15: pa.pay_act_rev# | E15: RI | G15: Payment result revision number | H15: 支払実績改訂番号 | I15: - | J15: E
A16: 10 | D16: pa.pay_act_dt# | E16: RI | G16: Actual payment date | H16: 支払実績日 | I16: E | J16: -
A17: 10 | D17: pa.ac_ym# | E17: RI | G17: Recording month | H17: 計上年月 | I17: - | J17: E
A18: 10 | D18: pa.ac_dt# | E18: RI | G18: Recording date | H18: 計上日 | I18: E | J18: -
A19: 10 | D19: pa.pay_basis_dt# | E19: RI | G19: Payment base date | H19: 支払起算日 | I19: E | J19: -
A20: 10 | D20: can_ac_dt | E20: #MA.DT | G20: Cancellation recording date | H20: 取消計上日 | I20: - | J20: -
A21: 10 | D21: pa.pay_usr_cd# | E21: RI | G21: Payment PIC cd. | H21: 支払担当者ＣＤ | I21: E | J21: -
A22: 10 | D22: pa.pay_dpt_cd# | E22: RI | G22: Payment dept. cd. | H22: 支払部門ＣＤ | I22: E | J22: -
A23: 10 | D23: pa.psppl_cd# | E23: RI | G23: Payee cd. | H23: 支払先ＣＤ | I23: E | J23: -
A24: 10 | D24: pa.trd_cur_cd# | E24: RI | G24: Transaction currency cd. | H24: 取引通貨ＣＤ | I24: E | J24: -
... A51: 10 | D51: pn.sub_char3#note_sub_char3 | E51: RI | G51: Note spare 3 | H51: 手形予備３ | I51: E | J51: -
A53: 20 | B53: * | D53: Ins01_Dtl | E53: L | G53: $share$ | H53: MS.MSBHL5040.PayAct_Chk01.PayAct_Chk01_Dtl
A54: 20 | D54: data_crud_typ | E54: #MA.DATA_CRUD_TYP | G54: Data update type | H54: データ更新区分 | I54: - | J54: -
A55: 20 | D55: pad | E55: R | F55: DBC:MS.MST_PAY_ACT_D
A56: 20 | D56: pad.pay_act_d_no# | E56: RI | G56: Payment result details No. | H56: 支払実績明細ＮＯ | I56: - | J56: E
A57: 20 | D57: pad.pay_act_d_seq# | E57: RI | G57: Payment result details sequence number | H57: 支払実績明細連番 | I57: - | J57: E
A58: 20 | D58: pad.ap_sttl_cd# | E58: RI | G58: AP settlement method cd. | H58: 債務決済方法ＣＤ | I58: E | J58: -
A59: 20 | D59: pad.trd_cur_amt# | E59: RI | G59: Amount (Transaction currency) | H59: 取引通貨金額 | I59: E | J59: -
A60: 20 | D60: pad.trd_cur_com_paid_tax_cd# | E60: RI | G60: Fee tax cd. | H60: 手数料税ＣＤ | I60: E | J60: -
A61: 20 | D61: pad.bank_ac_cd# | E61: RI | G61: Bank account cd. | H61: 口座ＣＤ | I61: E | J61: -
A62: 20 | D62: pad.pay_bank_ac_cd# | E62: RI | G62: Payee account cd. | H62: 支払先口座ＣＤ | I62: E | J62: -
A63: 20 | D63: pad.ap_setoff_typ# | E63: RI | G63: Offset destination type | H63: 相殺先区分 | I63: E | J63: -
A64: 20 | D64: pad.setoff_cd# | E64: RI | G64: Offset destination cd. | H64: 相殺先ＣＤ | I64: E | J64: -
A65: 20 | D65: pad.setoff_nm# | E65: RI | G65: Offset destination name | H65: 相殺先名 | I65: E | J65: -
A66: 20 | D66: pad.so_dpt_cd# | E66: RI | G66: Offset dept. cd. | H66: 相殺部門ＣＤ | I66: E | J66: -
A67: 20 | D67: pad.bsppl_cd# | E67: RI | G67: Scheduled payee cd. | H67: 支払予定管理先ＣＤ | I67: E | J67: -
...

Sheet Upd01
A1: * | B1: * | D1: L | E1: 1
A2: * | D2: オペレーション実装仕様書 Operation Specification Implementation Sheet | E2: ModuleID : | F2: MS | G2: LogicID : | H2: =IF(LogicCommon!E2="","",LogicCommon!E2) -> MSBHL0090 | I2: Ope.ID : | J2: Upd01 | K2: Pj.ID : | L2: MC | M2: Ope.Body : | N2: "mcframe.serverMAUD.MAUDL5010.MAUDL_Operation"
A3: * | E3: SubModuleID : | F3: MSBH | G3: LogicClass : | H3: =IF(LogicCommon!E3="","",LogicCommon!E3) -> MSBHL_PayActReg | I3: Ope.Method : | J3: =J2 -> Upd01 | K3: SuperClassPj.ID : | O3: Gene.Type : | P3: ALL
A4: * | E4: Version : | F4: 000000 | G4: LogicName : | H4: =IF(LogicCommon!E4="","",LogicCommon!E4) -> 支払実績登録 | I4: Ope.Name : | J4: 更新 | K4: SuperLogicID : | L4: =IF(LogicCommon!G4="","",LogicCommon!G4) -> MS.MSUDL5010 | M4: ImplOpe.ID:
A5: * | E5: ACType :
A6: * | D6: 概要 : | E6: 支払実績を更新する。 | M6: ID | O6: ID | Q6: ID
A7: # | I7: U | K7: K | L7: o | N7: o | P7: o
A8: # | D8: ブロック名 Block Name | E8: 型 Type | G8: super/share | H8: 対象ブロック名 Target Block Name | L8: TargetName | N8: TargetName | P8: TargetName | T8: ブロック備考 Block Remarks
A9: # | D9: 項目名 Field Name | E9: 型 Type | F9: 桁 Digits | G9: フルネーム Full Name | H9: 日本語名 Japanese Name | I9: 上り項目 Request Message Field | J9: 下り項目 Response Message Field | R9: 条件および編集方法 Conditions and Editing Methods | T9: 項目備考 Field Remarks
A10: # | L10: 上り項目 Request Message Field | M10: 下り項目 Response Message Field | N10: 上り項目 Request Message Field | O10: 下り項目 Response Message Field | P10: 上り項目 Request Message Field | Q10: 下り項目 Response Message Field
A11: 10 | B11: * | D11: Upd01_Hdr | E11: R | G11: $share$ | H11: MS.MSBHL5040.PayAct_Chk01.PayAct_Chk01_Hdr
A12: 10 | D12: pa | E12: R | F12: DBC:MS.MST_PAY_ACT
A13: 10 | D13: pa.pay_act_no# | E13: RI | G13: Payment result No. | H13: 支払実績ＮＯ | I13: E | J13: E
A14: 10 | D14: pa.pay_act_seq# | E14: RI | G14: Payment result sequence No. | H14: 支払実績連番 | I14: E | J14: E
A15: 10 | D15: pa.pay_act_rev# | E15: RI | G15: Payment result revision number | H15: 支払実績改訂番号 | I15: - | J15: E
A16: 10 | D16: pa.pay_act_dt# | E16: RI | G16: Actual payment date | H16: 支払実績日 | I16: E | J16: -
A17: 10 | D17: pa.ac_ym# | E17: RI | G17: Recording month | H17: 計上年月 | I17: - | J17: E
A18: 10 | D18: pa.ac_dt# | E18: RI | G18: Recording date | H18: 計上日 | I18: E | J18: -
A19: 10 | D19: pa.pay_basis_dt# | E19: RI | G19: Payment base date | H19: 支払起算日 | I19: E | J19: -
A20: 10 | D20: can_ac_dt | E20: #MA.DT | G20: Cancellation recording date | H20: 取消計上日 | I20: E | J20: -
A21: 10 | D21: pa.pay_usr_cd# | E21: RI | G21: Payment PIC cd. | H21: 支払担当者ＣＤ | I21: E | J21: -
A22: 10 | D22: pa.pay_dpt_cd# | E22: RI | G22: Payment dept. cd. | H22: 支払部門ＣＤ | I22: E | J22: -
A23: 10 | D23: pa.psppl_cd# | E23: RI | G23: Payee cd. | H23: 支払先ＣＤ | I23: E | J23: -
A24: 10 | D24: pa.trd_cur_cd# | E24: RI | G24: Transaction currency cd. | H24: 取引通貨ＣＤ | I24: E | J24: -
... A51: 10 | D51: pn.sub_char3#note_sub_char3 | E51: RI | G51: Note spare 3 | H51: 手形予備３ | I51: E | J51: -
A53: 20 | B53: * | D53: Upd01_Dtl | E53: L | G53: $share$ | H53: MS.MSBHL5040.PayAct_Chk01.PayAct_Chk01_Dtl
A54: 20 | D54: data_crud_typ | E54: #MA.DATA_CRUD_TYP | G54: Data update type | H54: データ更新区分 | I54: E | J54: -
A55: 20 | D55: pad | E55: R | F55: DBC:MS.MST_PAY_ACT_D
A56: 20 | D56: pad.pay_act_d_no# | E56: RI | G56: Payment result details No. | H56: 支払実績明細ＮＯ | I56: E | J56: E
A57: 20 | D57: pad.pay_act_d_seq# | E57: RI | G57: Payment result details sequence number | H57: 支払実績明細連番 | I57: E | J57: E
A58: 20 | D58: pad.ap_sttl_cd# | E58: RI | G58: AP settlement method cd. | H58: 債務決済方法ＣＤ | I58: E | J58: -
A59: 20 | D59: pad.trd_cur_amt# | E59: RI | G59: Amount (Transaction currency) | H59: 取引通貨金額 | I59: E | J59: -
A60: 20 | D60: pad.trd_cur_com_paid_tax_cd# | E60: RI | G60: Fee tax cd. | H60: 手数料税ＣＤ | I60: E | J60: -
A61: 20 | D61: pad.bank_ac_cd# | E61: RI | G61: Bank account cd. | H61: 口座ＣＤ | I61: E | J61: -
A62: 20 | D62: pad.pay_bank_ac_cd# | E62: RI | G62: Payee account cd. | H62: 支払先口座ＣＤ | I62: E | J62: -
A63: 20 | D63: pad.ap_setoff_typ# | E63: RI | G63: Offset destination type | H63: 相殺先区分 | I63: E | J63: -
A64: 20 | D64: pad.setoff_cd# | E64: RI | G64: Offset destination cd. | H64: 相殺先ＣＤ | I64: E | J64: -
A65: 20 | D65: pad.setoff_nm# | E65: RI | G65: Offset destination name | H65: 相殺先名 | I65: E | J65: -
A66: 20 | D66: pad.so_dpt_cd# | E66: RI | G66: Offset dept. cd. | H66: 相殺部門ＣＤ | I66: E | J66: -
A67: 20 | D67: pad.bsppl_cd# | E67: RI | G67: Scheduled payee cd. | H67: 支払予定管理先ＣＤ | I67: E | J67: -
...

Sheet Del01
A1: * | B1: * | D1: L | E1: 1
A2: * | D2: オペレーション実装仕様書 Operation Specification Implementation Sheet | E2: ModuleID : | F2: MS | G2: LogicID : | H2: =IF(LogicCommon!E2="","",LogicCommon!E2) -> MSBHL0090 | I2: Ope.ID : | J2: Del01 | K2: Pj.ID : | L2: MC | M2: Ope.Body : | N2: "mcframe.serverMAUD.MAUDL5010.MAUDL_Operation"
A3: * | E3: SubModuleID : | F3: MSBH | G3: LogicClass : | H3: =IF(LogicCommon!E3="","",LogicCommon!E3) -> MSBHL_PayActReg | I3: Ope.Method : | J3: =J2 -> Del01 | K3: SuperClassPj.ID : | O3: Gene.Type : | P3: ALL
A4: * | E4: Version : | F4: 000000 | G4: LogicName : | H4: =IF(LogicCommon!E4="","",LogicCommon!E4) -> 支払実績登録 | I4: Ope.Name : | J4: 取消 | K4: SuperLogicID : | L4: =IF(LogicCommon!G4="","",LogicCommon!G4) -> MS.MSUDL5010 | M4: ImplOpe.ID:
A5: * | E5: ACType :
A6: * | D6: 概要 : | E6: 支払実績を取り消す。 | M6: ID | O6: ID | Q6: ID
A7: # | I7: U | K7: K | L7: o | N7: o | P7: o
A8: # | D8: ブロック名 Block Name | E8: 型 Type | G8: super/share | H8: 対象ブロック名 Target Block Name | L8: TargetName | N8: TargetName | P8: TargetName | T8: ブロック備考 Block Remarks
A9: # | D9: 項目名 Field Name | E9: 型 Type | F9: 桁 Digits | G9: フルネーム Full Name | H9: 日本語名 Japanese Name | I9: 上り項目 Request Message Field | J9: 下り項目 Response Message Field | R9: 条件および編集方法 Conditions and Editing Methods | T9: 項目備考 Field Remarks
A10: # | L10: 上り項目 Request Message Field | M10: 下り項目 Response Message Field | N10: 上り項目 Request Message Field | O10: 下り項目 Response Message Field | P10: 上り項目 Request Message Field | Q10: 下り項目 Response Message Field
A11: 10 | B11: * | D11: Del01_Hdr | E11: R | G11: $share$ | H11: MS.MSBHL5040.PayAct_Chk01.PayAct_Chk01_Hdr
A12: 10 | D12: pa | E12: R | F12: DBC:MS.MST_PAY_ACT
A13: 10 | D13: pa.pay_act_no# | E13: RI | G13: Payment result No. | H13: 支払実績ＮＯ | I13: E | J13: -
A14: 10 | D14: pa.pay_act_seq# | E14: RI | G14: Payment result sequence No. | H14: 支払実績連番 | I14: E | J14: -
A15: 10 | D15: can_ac_dt | E15: #MA.DT | G15: Cancellation recording date | H15: 取消計上日 | I15: E | J15: -
A17: 20 | B17: * | D17: Del01_Dtl | E17: L | G17: $share$ | H17: MS.MSBHL5040.PayAct_Chk01.PayAct_Chk01_Dtl
A18: 20 | D18: pad | E18: R | F18: DBC:MS.MST_PAY_ACT_D
A19: 20 | D19: pad.pay_act_d_no# | E19: RI | G19: Payment result details No. | H19: 支払実績明細ＮＯ | I19: E | J19: -
A20: 20 | D20: pad.pay_act_d_seq# | E20: RI | G20: Payment result details sequence number | H20: 支払実績明細連番 | I20: E | J20: -
A21: 20 | D21: pad.pay_chk_mng_no# | E21: RI | G21: Payment collation management No. | H21: 支払照合管理ＮＯ | I21: E | J21: -
A22: 20 | D22: pay_chk_upd_cntr | E22: #MA.UPD_CNT | G22: Payment collation update counter | H22: 支払照合更新カウンタ | I22: E | J22: -
D23: 詳細 :

Sheet 来歴
A1: 変更来歴
A3: Rev. | H3: 修正番号 | O3: 変更内容 | AQ3: 変更箇所
A4: 1 | O4: 初版
A5: 1.1 | O5: 英語の名称を追記 | AQ5: 全般
