Workbook

Sheet LogicCommon
A2: オペレーション実装仕様書 | B2: ModuleID : | C2: MS | D2: LogicID : | E2: MSBHL5130 | F2: Pj.ID : | G2: MC
B3: SubModuleID : | C3: MSBH | D3: LogicClass : | E3: MSBHL_ApSwBalService | F3: SuperClassPj.ID :
D4: LogicName : | E4: 債務残高振替サービス | F4: SuperLogicID : | G4: MS.MSUDL5010
A5: 概要 : | B5: 債務残高振替を行う
A6: 詳細 :

Sheet ApSwBal_Chk01
A1: * | B1: * | D1: L | E1: 1
A2: * | D2: オペレーション実装仕様書 Operation Specification Implementation Sheet | E2: ModuleID : | F2: =IF(LogicCommon!C2="","",LogicCommon!C2) -> MS | G2: LogicID : | H2: =IF(LogicCommon!E2="","",LogicCommon!E2) -> MSBHL5130 | I2: Ope.ID : | J2: ApSwBal_Chk01 | K2: Pj.ID : | L2: MC | M2: Ope.Body : | N2: MA.MAUDL5010.Checker
A3: * | D3: =IF(LogicCommon!A3="","",LogicCommon!A3) | E3: SubModuleID : | F3: =IF(LogicCommon!C3="","",LogicCommon!C3) -> MSBH | G3: LogicClass : | H3: =IF(LogicCommon!E3="","",LogicCommon!E3) -> MSBHL_ApSwBalService | I3: Ope.Method : | J3: =J2 -> ApSwBal_Chk01 | K3: SuperClassPj.ID : | O3: Gene.Type : | P3: ALL
A4: * | E4: Version : | F4: 000000 | G4: LogicName : | H4: =IF(LogicCommon!E4="","",LogicCommon!E4) -> 債務残高振替サービス | I4: Ope.Name : | J4: 残高振替前チェック | K4: SuperLogicID : | L4: MS.MSUDL5010 | M4: ImplOpe.ID:
A5: * | E5: ACType :
A6: * | D6: 概要 : | E6: 債務残高振替が可能かチェックをする。 | M6: ID | O6: ID | Q6: ID | AD6: ID | AF6: ID | AH6: ID
A7: # | I7: U | K7: K | L7: K | M7: K | N7: K | O7: K | P7: K | Q7: K | R7: K | S7: K | T7: K | U7: K | V7: K | W7: K | X7: K | Y7: K | Z7: K | AA7: K | AB7: K | AC7: o | AE7: o | AG7: o
A8: # | D8: ブロック名 Block Name | E8: 型 Type | G8: super/share | H8: 対象ブロック名 Target Block Name | K8: REQ_UPD_CNT_CHK | L8: REQUIRED | M8: CHK_NUM | N8: SMALL_LARGE | O8: CHK_DT | P8: BEFORE_AFTER | Q8: CHK_PTN | R8: DUPLICATE | S8: TOO_MANY_INPUTS | T8: AT_LEAST_ONE | U8: ONLY_ONE_INPUT | V8: LIST_LOGIC | W8: LIST_OUT | X8: LIST_OUT_BASE | Y8: LIST_IN | Z8: LIST_IN_BASE | AA8: CONST | AB8: NULL_VAL | AC8: TargetName | AE8: TargetName | AG8: TargetName | AK8: ブロック備考 Block Remarks
A9: # | D9: 項目名 Field Name | E9: 型 Type | F9: 桁 Digits | G9: フルネーム Full Name | H9: 日本語名 Japanese Name | I9: 上り項目 Request Message Field | J9: 下り項目 Response Message Field | AI9: 条件および編集方法 Conditions and Editing Methods | AK9: 項目備考 Field Remarks
A10: # | AC10: 上り項目 Request Message Field | AD10: 下り項目 Response Message Field | AE10: 上り項目 Request Message Field | AF10: 下り項目 Response Message Field | AG10: 上り項目 Request Message Field | AH10: 下り項目 Response Message Field
A11: 10 | B11: * | D11: ApSwBal_Chk01_Fr | E11: L
A12: 10 | D12: hdr_peg_no | E12: #MA.INT | G12: Header pegging No. | H12: ヘッダ紐付けＮＯ | I12: E | J12: E
A13: 10 | D13: peg_no | E13: #MA.INT | G13: Pegging No. | H13: 紐付けＮＯ | I13: E | J13: E
A14: 10 | D14: ap_d_no | E14: #MA.AP_D_NO | G14: AP details No. | H14: 買掛明細ＮＯ | I14: E | J14: E
A15: 10 | D15: pay_schd_no | E15: #MA.PAY_SCHD_NO | G15: Payment schedule No. | H15: 支払予定ＮＯ | I15: E | J15: E
A16: 10 | D16: ap_appl_schd_no | E16: #MA.AP_APPL_SCHD_NO | G16: AP reconciliation schedule No. | H16: 買掛消込予定ＮＯ | I16: - | J16: -
A17: 10 | D17: pay_chk_mng_no | E17: #MA.PAY_CHK_MNG_NO | G17: Payment collation management No. | H17: 支払照合管理ＮＯ | I17: - | J17: -
A18: 10 | D18: ap_d_upd_cntr | E18: #MA.UPD_CNT | G18: AP details update counter | H18: 買掛明細更新カウンタ | I18: E | J18: -
A19: 10 | D19: pay_chk_upd_cntr | E19: #MA.UPD_CNT | G19: Payment collation update counter | H19: 支払照合更新カウンタ | I19: E | J19: -
A20: 10 | D20: wrk_ope_typ | E20: #MS.WRK_OPE_TYP | G20: Sales project process type | H20: 案件処理区分 | I20: - | J20: -
A21: 10 | D21: wrk_no | E21: #MA.WRK_NO | G21: Sales project No. | H21: 案件ＮＯ | I21: - | J21: -
A22: 10 | D22: to_ap_d_no | E22: #MA.AP_D_NO | G22: Transfer destination AP details No. | H22: 振替先買掛明細ＮＯ | I22: - | J22: -
A23: 10 | D23: err_flg | E23: #MA.FLG | G23: Error | H23: エラー | I23: - | J23: E
A25: 20 | B25: * | D25: ApSwBal_Chk01_Base | E25: L
A26: 20 | D26: hdr_peg_no | E26: #MA.INT | G26: Header pegging No. | H26: ヘッダ紐付けＮＯ | I26: E | J26: E
A27: 20 | D27: peg_no | E27: #MA.INT | G27: Pegging No. | H27: 紐付けＮＯ | I27: E | J27: E
A28: 20 | D28: sw_dt | E28: #MA.DT | G28: Transfer date | H28: 振替日 | I28: E | J28: E | L28: E | O28: bfToday | P28: sw_dt:BF
A29: 20 | D29: ac_dt | E29: #MA.DT | G29: Recording date | H29: 計上日 | I29: E | J29: E | L29: E | O29: bfToday | P29: ac_dt:BF,sw_dt:AF
A30: 20 | D30: pay_basis_dt | E30: #MA.DT | G30: Payment base date | H30: 支払起算日 | I30: E | J30: E | P30: ac_dt:AF
A31: 20 | D31: pay_crryovr_times | E31: #MA.CRRYOVR_TIMES | G31: Payment carry-over count | H31: 支払繰越回数 | I31: E | J31: E
A32: 20 | D32: pay_schd_dt | E32: #MA.DT | G32: Scheduled payment date | H32: 支払予定日 | I32: E | J32: E
A33: 20 | D33: ap_sttl_cd | E33: #MA.STTL_CD | G33: AP settlement method cd. | H33: 債務決済方法ＣＤ | I33: E | J33: E | L33: E | V33: MA.MAUAL0010.ApSttl | W33: ap_sttl_typ;ac_rsn_cd | X33: ap_sttl_typ;ac_rsn_cd | Y33: ac_dt | Z33: dt
A34: 20 | D34: ap_sttl_typ | E34: #MA.AP_STTL_TYP | G34: AP settlement type | H34: 債務決済区分 | I34: - | J34: E
A35: 20 | D35: ac_rsn_cd | E35: #MA.AC_RSN_CD | G35: Accounting reason cd. | H35: 会計理由ＣＤ | I35: - | J35: E
A36: 20 | D36: pay_usr_cd | E36: #MA.USR_CD | G36: Payment PIC cd. | H36: 支払担当者ＣＤ | I36: E | J36: E | V36: MA.MAUAL0010.Usr
A37: 20 | D37: pay_dpt_cd | E37: #MA.DPT_CD | G37: Payment dept. cd. | H37: 支払部門ＣＤ | I37: E | J37: E | L37: E | V37: MA.MAUAL0010.Dpt | W37: wg_cd | X37: wg_cd | Y37: MAC_DPT_IS_SRCH_TYP.AP;ac_dt;pay_usr_cd | Z37: dpt_is_srch_typ;dt;usr_cd
A38: 20 | D38: wg_cd | E38: #MA.WG_CD | G38: WG cd. | H38: ワーキンググループＣＤ | I38: - | J38: E
A39: 20 | D39: trd_rmrks | E39: #MA.TRD_RMRKS | G39: Transaction remarks | H39: 取引備考 | I39: E | J39: E
A40: 20 | D40: sub_char1 | E40: #MS.PAY_ACT_SUB_CHAR1 | G40: Spare 1 | H40: 予備１ | I40: E | J40: E
A41: 20 | D41: sub_char2 | E41: #MS.PAY_ACT_SUB_CHAR2 | G41: Spare 2 | H41: 予備２ | I41: E | J41: E
...

Sheet ApSwBal_Ins01
A1: * | B1: * | D1: L | E1: 1
A2: * | D2: オペレーション実装仕様書 Operation Specification Implementation Sheet | E2: ModuleID : | F2: =IF(LogicCommon!C2="","",LogicCommon!C2) -> MS | G2: LogicID : | H2: =IF(LogicCommon!E2="","",LogicCommon!E2) -> MSBHL5130 | I2: Ope.ID : | J2: ApSwBal_Ins01 | K2: Pj.ID : | L2: MC | M2: Ope.Body : | N2: "mcframe.serverMAUD.MAUDL5010.MAUDL_Operation"
A3: * | D3: =IF(LogicCommon!A3="","",LogicCommon!A3) | E3: SubModuleID : | F3: =IF(LogicCommon!C3="","",LogicCommon!C3) -> MSBH | G3: LogicClass : | H3: =IF(LogicCommon!E3="","",LogicCommon!E3) -> MSBHL_ApSwBalService | I3: Ope.Method : | J3: =J2 -> ApSwBal_Ins01 | K3: SuperClassPj.ID : | O3: Gene.Type : | P3: ALL
A4: * | E4: Version : | F4: 000000 | G4: LogicName : | H4: =IF(LogicCommon!E4="","",LogicCommon!E4) -> 債務残高振替サービス | I4: Ope.Name : | J4: 残高振替 | K4: SuperLogicID : | L4: MS.MSUDL5010 | M4: ImplOpe.ID:
A5: * | E5: ACType :
A6: * | D6: 概要 : | E6: 債務残高振替を行う。 | M6: ID | O6: ID | Q6: ID
A7: # | I7: U | K7: K | L7: o | N7: o | P7: o
A8: # | D8: ブロック名 Block Name | E8: 型 Type | G8: super/share | H8: 対象ブロック名 Target Block Name | K8: CONST | L8: TargetName | N8: TargetName | P8: TargetName | T8: ブロック備考 Block Remarks
A9: # | D9: 項目名 Field Name | E9: 型 Type | F9: 桁 Digits | G9: フルネーム Full Name | H9: 日本語名 Japanese Name | I9: 上り項目 Request Message Field | J9: 下り項目 Response Message Field | R9: 条件および編集方法 Conditions and Editing Methods | T9: 項目備考 Field Remarks
A10: # | L10: 上り項目 Request Message Field | M10: 下り項目 Response Message Field | N10: 上り項目 Request Message Field | O10: 下り項目 Response Message Field | P10: 上り項目 Request Message Field | Q10: 下り項目 Response Message Field
A11: 10 | B11: * | D11: ApSwBal_Ins01_Fr | E11: L | G11: $share$ | H11: MS.MSBHL5130.ApSwBal_Chk01.ApSwBal_Chk01_Fr
A12: 10 | D12: hdr_peg_no | E12: #MA.INT | G12: Header pegging No. | H12: ヘッダ紐付けＮＯ | I12: E | J12: E
A13: 10 | D13: peg_no | E13: #MA.INT | G13: Pegging No. | H13: 紐付けＮＯ | I13: E | J13: E
A14: 10 | D14: ap_d_no | E14: #MA.AP_D_NO | G14: AP details No. | H14: 買掛明細ＮＯ | I14: E | J14: E
A15: 10 | D15: pay_schd_no | E15: #MA.PAY_SCHD_NO | G15: Payment schedule No. | H15: 支払予定ＮＯ | I15: E | J15: E
A16: 10 | D16: ap_appl_schd_no | E16: #MA.AP_APPL_SCHD_NO | G16: AP reconciliation schedule No. | H16: 買掛消込予定ＮＯ | I16: - | J16: E
A17: 10 | D17: pay_chk_mng_no | E17: #MA.PAY_CHK_MNG_NO | G17: Payment collation management No. | H17: 支払照合管理ＮＯ | I17: - | J17: -
A18: 10 | D18: ap_d_upd_cntr | E18: #MA.UPD_CNT | G18: AP details update counter | H18: 買掛明細更新カウンタ | I18: - | J18: -
A19: 10 | D19: pay_chk_upd_cntr | E19: #MA.UPD_CNT | G19: Payment collation update counter | H19: 支払照合更新カウンタ | I19: - | J19: -
A20: 10 | D20: wrk_ope_typ | E20: #MS.WRK_OPE_TYP | G20: Sales project process type | H20: 案件処理区分 | I20: - | J20: -
A21: 10 | D21: wrk_no | E21: #MA.WRK_NO | G21: Sales project No. | H21: 案件ＮＯ | I21: - | J21: -
A22: 10 | D22: to_ap_d_no | E22: #MA.AP_D_NO | G22: Transfer destination AP details No. | H22: 振替先買掛明細ＮＯ | I22: - | J22: E
A23: 10 | D23: err_flg | E23: #MA.FLG | G23: Error | H23: エラー | I23: - | J23: -
A25: 20 | B25: * | D25: ApSwBal_Ins01_Base | E25: L | G25: $share$ | H25: MS.MSBHL5130.ApSwBal_Chk01.ApSwBal_Chk01_Base
A26: 20 | D26: hdr_peg_no | E26: #MA.INT | G26: Header pegging No. | H26: ヘッダ紐付けＮＯ | I26: E | J26: -
A27: 20 | D27: peg_no | E27: #MA.INT | G27: Pegging No. | H27: 紐付けＮＯ | I27: E | J27: -
A28: 20 | D28: sw_dt | E28: #MA.DT | G28: Transfer date | H28: 振替日 | I28: E | J28: -
A29: 20 | D29: ac_dt | E29: #MA.DT | G29: Recording date | H29: 計上日 | I29: E | J29: -
A30: 20 | D30: pay_basis_dt | E30: #MA.DT | G30: Payment base date | H30: 支払起算日 | I30: E | J30: -
A31: 20 | D31: pay_crryovr_times | E31: #MA.CRRYOVR_TIMES | G31: Payment carry-over count | H31: 支払繰越回数 | I31: E | J31: -
A32: 20 | D32: pay_schd_dt | E32: #MA.DT | G32: Scheduled payment date | H32: 支払予定日 | I32: E | J32: -
A33: 20 | D33: ap_sttl_cd | E33: #MA.STTL_CD | G33: AP settlement method cd. | H33: 債務決済方法ＣＤ | I33: E | J33: -
A34: 20 | D34: ap_sttl_typ | E34: #MA.AP_STTL_TYP | G34: AP settlement type | H34: 債務決済区分 | I34: E | J34: -
A35: 20 | D35: ac_rsn_cd | E35: #MA.AC_RSN_CD | G35: Accounting reason cd. | H35: 会計理由ＣＤ | I35: E | J35: -
A36: 20 | D36: pay_usr_cd | E36: #MA.USR_CD | G36: Payment PIC cd. | H36: 支払担当者ＣＤ | I36: E | J36: -
A37: 20 | D37: pay_dpt_cd | E37: #MA.DPT_CD | G37: Payment dept. cd. | H37: 支払部門ＣＤ | I37: E | J37: -
... A46: 20 | D46: err_flg | E46: #MA.FLG | G46: Error | H46: エラー | I46: - | J46: -
A48: 30 | B48: * | D48: ApSwBal_Ins01_To | E48: L | G48: $share$ | H48: MS.MSBHL5130.ApSwBal_Chk01.ApSwBal_Chk01_To
A49: 30 | D49: hdr_peg_no | E49: #MA.INT | G49: Header pegging No. | H49: ヘッダ紐付けＮＯ | I49: E | J49: -
A50: 30 | D50: peg_no | E50: #MA.INT | G50: Pegging No. | H50: 紐付けＮＯ | I50: E | J50: -
...

Sheet ApSwBal_Prnt01
A1: * | B1: * | D1: L | E1: 1
A2: * | D2: オペレーション実装仕様書 Operation Specification Implementation Sheet | E2: ModuleID : | F2: =IF(LogicCommon!C2="","",LogicCommon!C2) -> MS | G2: LogicID : | H2: =IF(LogicCommon!E2="","",LogicCommon!E2) -> MSBHL5130 | I2: Ope.ID : | J2: ApSwBal_Prnt01 | K2: Pj.ID : | L2: MC | M2: Ope.Body : | N2: "mcframe.serverMAUD.MAUDL5010.MAUDL_Operation"
A3: * | D3: =IF(LogicCommon!A3="","",LogicCommon!A3) | E3: SubModuleID : | F3: =IF(LogicCommon!C3="","",LogicCommon!C3) -> MSBH | G3: LogicClass : | H3: =IF(LogicCommon!E3="","",LogicCommon!E3) -> MSBHL_ApSwBalService | I3: Ope.Method : | J3: =J2 -> ApSwBal_Prnt01 | K3: SuperClassPj.ID : | O3: Gene.Type : | P3: ALL
A4: * | E4: Version : | F4: 000000 | G4: LogicName : | H4: =IF(LogicCommon!E4="","",LogicCommon!E4) -> 債務残高振替サービス | I4: Ope.Name : | J4: 振替伝票発行 | K4: SuperLogicID : | L4: MS.MSUDL5010 | M4: ImplOpe.ID:
A5: * | E5: ACType :
A6: * | D6: 概要 : | E6: 振替伝票を発行する。 | M6: ID | O6: ID | Q6: ID
A7: # | I7: U | K7: K | L7: o | N7: o | P7: o
A8: # | D8: ブロック名 Block Name | E8: 型 Type | G8: super/share | H8: 対象ブロック名 Target Block Name | K8: CONST | L8: TargetName | N8: TargetName | P8: TargetName | T8: ブロック備考 Block Remarks
A9: # | D9: 項目名 Field Name | E9: 型 Type | F9: 桁 Digits | G9: フルネーム Full Name | H9: 日本語名 Japanese Name | I9: 上り項目 Request Message Field | J9: 下り項目 Response Message Field | R9: 条件および編集方法 Conditions and Editing Methods | T9: 項目備考 Field Remarks
A10: # | L10: 上り項目 Request Message Field | M10: 下り項目 Response Message Field | N10: 上り項目 Request Message Field | O10: 下り項目 Response Message Field | P10: 上り項目 Request Message Field | Q10: 下り項目 Response Message Field
A11: 10 | B11: * | D11: ApSwBal_Prnt01_Cnd | E11: L
A12: 10 | D12: pay_act_no | E12: #MA.PAY_ACT_NO | G12: Payment result No. | H12: 支払実績ＮＯ | I12: E | J12: -
A13: 10 | D13: pay_act_seq | E13: #MA.SLIP_SEQ | G13: Payment result sequence No. | H13: 支払実績連番 | I13: E | J13: -
A14: 10 | D14: reprnt_flg | E14: #MA.FLG | G14: Reissue | H14: 再発行 | I14: E | J14: -
L15: 上り項目 Request Message Field | M15: 下り項目 Response Message Field | N15: 上り項目 Request Message Field | O15: 下り項目 Response Message Field | P15: 上り項目 Request Message Field | Q15: 下り項目 Response Message Field
A16: 20 | B16: * | D16: ApSwBal_Prnt01_Hdr | E16: R
A17: 20 | D17: indiv_prnt_flg | E17: #MA.FLG | G17: Individual issue | H17: 個別発行 | I17: E | J17: -
D18: 詳細 :

Sheet 来歴
A1: 変更来歴
A3: Rev. | H3: 修正番号 | O3: 変更内容 | AQ3: 変更箇所
A4: 1 | O4: 初版
A5: 1.1 | O5: 英語の名称を追記 | AQ5: 全般
