Workbook

Sheet LogicCommon
A2: オペレーション実装仕様書 | B2: ModuleID : | C2: MS | D2: LogicID : | E2: MSBHL0070 | F2: Pj.ID : | G2: MC
B3: SubModuleID : | C3: MSBH | D3: LogicClass : | E3: MSBHL_AdvPayReg | F3: SuperClassPj.ID :
D4: LogicName : | E4: 前渡金登録 | F4: SuperLogicID : | G4: MS.MSUDL5010
A5: 概要 :
A6: 詳細 :

Sheet Srch01
A1: * | B1: * | D1: L | E1: 1
A2: * | D2: オペレーション実装仕様書 Operation Specification Implementation Sheet | E2: ModuleID : | F2: =IF(LogicCommon!C2="","",LogicCommon!C2) -> MS | G2: LogicID : | H2: =IF(LogicCommon!E2="","",LogicCommon!E2) -> MSBHL0070 | I2: Ope.ID : | J2: Srch01 | K2: Pj.ID : | L2: MC | M2: Ope.Body : | N2: "mcframe.serverMAUD.MAUDL5010.MAUDL_Searcher"
A3: * | D3: =IF(LogicCommon!A3="","",LogicCommon!A3) | E3: SubModuleID : | F3: =IF(LogicCommon!C3="","",LogicCommon!C3) -> MSBH | G3: LogicClass : | H3: =IF(LogicCommon!E3="","",LogicCommon!E3) -> MSBHL_AdvPayReg | I3: Ope.Method : | J3: =J2 -> Srch01 | K3: SuperClassPj.ID : | O3: Gene.Type : | P3: ALL
A4: * | E4: Version : | F4: 000000 | G4: LogicName : | H4: =IF(LogicCommon!E4="","",LogicCommon!E4) -> 前渡金登録 | I4: Ope.Name : | J4: 前渡金検索 | K4: SuperLogicID : | L4: =IF(LogicCommon!G4="","",LogicCommon!G4) -> MS.MSUDL5010 | M4: ImplOpe.ID:
A5: * | E5: ACType :
A6: * | D6: 概要 : | E6: 前渡金実績、支払手形情報を検索する。 | M6: ID | O6: ID | Q6: ID
A7: # | I7: U | K7: K | L7: o | N7: o | P7: o
A8: # | D8: ブロック名 Block Name | E8: 型 Type | G8: super/share | H8: 対象ブロック名 Target Block Name | K8: CONST | L8: TargetName | N8: TargetName | P8: TargetName | T8: ブロック備考 Block Remarks
A9: # | D9: 項目名 Field Name | E9: 型 Type | F9: 桁 Digits | G9: フルネーム Full Name | H9: 日本語名 Japanese Name | I9: 上り項目 Request Message Field | J9: 下り項目 Response Message Field | R9: 条件および編集方法 Conditions and Editing Methods | T9: 項目備考 Field Remarks
A10: # | L10: 上り項目 Request Message Field | M10: 下り項目 Response Message Field | N10: 上り項目 Request Message Field | O10: 下り項目 Response Message Field | P10: 上り項目 Request Message Field | Q10: 下り項目 Response Message Field
A11: 10 | B11: * | D11: Srch01_Cnd | E11: R
A12: 10 | D12: adv_pay_act_no | E12: #MA.PAY_ACT_NO | G12: Advance payment result No. | H12: 前渡金実績ＮＯ | I12: E | J12: -
A13: 10 | D13: adv_pay_act_rev | E13: #MA.SLIP_REV | G13: Advance payment result revision number | H13: 前渡金実績改訂番号 | I13: E | J13: -
A14: 10 | D14: latest_flg | E14: #MA.FLG | G14: Latest | H14: 最新 | I14: E | J14: -
A16: 20 | B16: * | D16: Srch01_Hdr | E16: R
A17: 20 | D17: adv_pay_act_no | E17: #MA.PAY_ACT_NO | G17: Advance payment result No. | H17: 前渡金実績ＮＯ | I17: - | J17: E
A18: 20 | D18: adv_pay_act_seq | E18: #MA.SLIP_SEQ | G18: Advance payment result sequence number | H18: 前渡金実績連番 | I18: - | J18: E
A19: 20 | D19: adv_pay_act_rev | E19: #MA.SLIP_REV | G19: Advance payment result revision number | H19: 前渡金実績改訂番号 | I19: - | J19: E
A20: 20 | D20: latest_flg | E20: #MA.FLG | G20: Latest | H20: 最新 | I20: - | J20: E
A21: 20 | D21: slip_sts_typ | E21: #MA.SLIP_STS_TYP | G21: Slip status type | H21: 伝票状況区分 | I21: - | J21: -
A22: 20 | D22: bsppl_cd | E22: #MA.BP_CD | G22: Scheduled payee cd. | H22: 支払予定管理先ＣＤ | I22: - | J22: E
A23: 20 | D23: bsppl_nm | E23: #MA.BP_NM | G23: Scheduled payee name | H23: 支払予定管理先名 | I23: - | J23: E
A24: 20 | D24: bsppl_dpt_cd | E24: #MA.DPT_CD | G24: Cd. of dept. in charge of scheduled payee | H24: 支払予定管理先担当部門ＣＤ | I24: - | J24: E
A25: 20 | D25: bsppl_dpt_nm | E25: #MA.DPT_NM | G25: Name of dept. in charge of scheduled payee | H25: 支払予定管理先担当部門名 | I25: - | J25: E
A26: 20 | D26: psppl_cd | E26: #MA.BP_CD | G26: Payee cd. | H26: 支払先ＣＤ | I26: - | J26: E
A27: 20 | D27: psppl_nm | E27: #MA.BP_NM | G27: Payee name | H27: 支払先名 | I27: - | J27: E
A28: 20 | D28: psppl_rmrks | E28: #MA.PSPPL_RMRKS | G28: Payee remarks | H28: 支払先備考 | I28: - | J28: E
... A54: 20 | D54: ap_sttl_nm | E54: #MA.STTL_NM | G54: AP settlement method name | H54: 債務決済方法名 | I54: - | J54: E
A55: 20 | D55: ap_sttl_typ | E55: #MA.AP_STTL_TYP | G55: AP settlement type | H55: 債務決済区分 | I55: - | J55: E | K55: MAC_AP_STTL_TYP
A56: 20 | D56: ap_sttl_typ_nm | E56: #MA.AP_STTL_TYP_NM | G56: AP settlement type name | H56: 債務決済区分名 | I56: - | J56: E
A57: 20 | D57: bank_ac_cd | E57: #MA.BANK_AC_CD | G57: Bank account cd. | H57: 口座ＣＤ | I57: - | J57: E
A58: 20 | D58: bank_ac_nm | E58: #MA.BANK_AC_NM | G58: Bank account name | H58: 口座名 | I58: - | J58: E
A59: 20 | D59: pay_bank_ac_cd | E59: #MA.BANK_AC_CD | G59: Payee account cd. | H59: 支払先口座ＣＤ | I59: - | J59: E
A60: 20 | D60: pay_bank_ac_nm | E60: #MA.BANK_AC_NM | G60: Payee account name | H60: 支払先口座名 | I60: - | J60: E
A61: 20 | D61: pay_spot_flg | E61: #MA.FLG | G61: Payment per transaction flg. | H61: 都度支払ＦＬＧ | I61: - | J61: E
A62: 20 | D62: pay_ntc_adv_pay_flg | E62: #MA.FLG | G62: Display advance payment on payment notice | H62: 支払通知書前渡金表示 | I62: - | J62: E
A63: 20 | D63: trd_rmrks | E63: #MA.TRD_RMRKS | G63: Transaction remarks | H63: 取引備考 | I63: - | J63: E
A64: 20 | D64: intr_rmrks | E64: #MS.ADV_PAY_ACT_INTR_RMRKS | G64: Internal remarks | H64: 内部備考 | I64: - | J64: E
A65: 20 | D65: sub_char1 | E65: #MS.ADV_PAY_ACT_SUB_CHAR1 | G65: Spare 1 | H65: 予備１ | I65: - | J65: E
A66: 20 | D66: sub_char2 | E66: #MS.ADV_PAY_ACT_SUB_CHAR2 | G66: Spare 2 | H66: 予備２ | I66: - | J66: E
...

Sheet Ins01
A1: * | B1: * | D1: L | E1: 1
A2: * | D2: オペレーション実装仕様書 Operation Specification Implementation Sheet | E2: ModuleID : | F2: MS | G2: LogicID : | H2: =IF(LogicCommon!E2="","",LogicCommon!E2) -> MSBHL0070 | I2: Ope.ID : | J2: Ins01 | K2: Pj.ID : | L2: MC | M2: Ope.Body : | N2: "mcframe.serverMAUD.MAUDL5010.MAUDL_Operation"
A3: * | E3: SubModuleID : | F3: MSBH | G3: LogicClass : | H3: =IF(LogicCommon!E3="","",LogicCommon!E3) -> MSBHL_AdvPayReg | I3: Ope.Method : | J3: =J2 -> Ins01 | K3: SuperClassPj.ID : | O3: Gene.Type : | P3: ALL
A4: * | E4: Version : | F4: 000000 | G4: LogicName : | H4: =IF(LogicCommon!E4="","",LogicCommon!E4) -> 前渡金登録 | I4: Ope.Name : | J4: 新規登録 | K4: SuperLogicID : | L4: =IF(LogicCommon!G4="","",LogicCommon!G4) -> MS.MSUDL5010 | M4: ImplOpe.ID:
A5: * | E5: ACType :
A6: * | D6: 概要 : | E6: 前渡金実績、支払手形情報を新規登録する。 | M6: ID | O6: ID | Q6: ID
A7: # | I7: U | K7: K | L7: o | N7: o | P7: o
A8: # | D8: ブロック名 Block Name | E8: 型 Type | G8: super/share | H8: 対象ブロック名 Target Block Name | L8: TargetName | N8: TargetName | P8: TargetName | T8: ブロック備考 Block Remarks
A9: # | D9: 項目名 Field Name | E9: 型 Type | F9: 桁 Digits | G9: フルネーム Full Name | H9: 日本語名 Japanese Name | I9: 上り項目 Request Message Field | J9: 下り項目 Response Message Field | R9: 条件および編集方法 Conditions and Editing Methods | T9: 項目備考 Field Remarks
A10: # | L10: 上り項目 Request Message Field | M10: 下り項目 Response Message Field | N10: 上り項目 Request Message Field | O10: 下り項目 Response Message Field | P10: 上り項目 Request Message Field | Q10: 下り項目 Response Message Field
A11: 10 | B11: * | D11: Ins01_Hdr | E11: R | G11: $share$ | H11: MS.MSBHL5050.AdvPay_Chk01.AdvPay_Chk01_Hdr
A12: 10 | D12: apa | E12: R | F12: DBC:MS.MST_ADV_PAY_ACT
A13: 10 | D13: apa.adv_pay_act_no# | E13: RI | G13: Advance payment result No. | H13: 前渡金実績ＮＯ | I13: - | J13: E
A14: 10 | D14: apa.adv_pay_act_seq# | E14: RI | G14: Advance payment result sequence number | H14: 前渡金実績連番 | I14: - | J14: E
A15: 10 | D15: apa.adv_pay_act_rev# | E15: RI | G15: Advance payment result revision number | H15: 前渡金実績改訂番号 | I15: - | J15: E
A16: 10 | D16: apa.bsppl_cd# | E16: RI | G16: Scheduled payee cd. | H16: 支払予定管理先ＣＤ | I16: E | J16: -
A17: 10 | D17: apa.bsppl_dpt_cd# | E17: RI | G17: Cd. of dept. in charge of scheduled payee | H17: 支払予定管理先担当部門ＣＤ | I17: E | J17: -
A18: 10 | D18: apa.bd_dpt_cd# | E18: RI | G18: Charged dept. cd. | H18: 負担部門ＣＤ | I18: E | J18: -
A19: 10 | D19: apa.pay_dpt_cd# | E19: RI | G19: Payment dept. cd. | H19: 支払部門ＣＤ | I19: E | J19: -
A20: 10 | D20: apa.pay_usr_cd# | E20: RI | G20: Payment PIC cd. | H20: 支払担当者ＣＤ | I20: E | J20: -
A21: 10 | D21: apa.pay_act_dt# | E21: RI | G21: Actual payment date | H21: 支払実績日 | I21: E | J21: -
A22: 10 | D22: apa.ac_dt# | E22: RI | G22: Recording date | H22: 計上日 | I22: E | J22: -
A23: 10 | D23: apa.ac_ym# | E23: RI | G23: Recording month | H23: 計上年月 | I23: - | J23: E
A24: 10 | D24: apa.trd_cur_cd# | E24: RI | G24: Transaction currency cd. | H24: 取引通貨ＣＤ | I24: E | J24: -
... A38: 10 | D38: apa.sub_char3# | E38: RI | G38: Spare 3 | H38: 予備３ | I38: E | J38: -
A39: 10 | D39: pn | E39: R | F39: DBC:MS.MST_PAY_NOTE
A40: 10 | D40: pn.note_no# | E40: RI | G40: Note number | H40: 手形番号 | I40: E | J40: -
A41: 10 | D41: pn.note_typ# | E41: RI | G41: Note type | H41: 手形区分 | I41: E | J41: -
A42: 10 | D42: pn.note_rsn_cd# | E42: RI | G42: Note reason cd. | H42: 手形理由ＣＤ | I42: E | J42: -
A43: 10 | D43: pn.draw_dt# | E43: RI | G43: Drawing date | H43: 振出日 | I43: E | J43: -
A44: 10 | D44: pn.due_dt# | E44: RI | G44: Payment due date | H44: 支払期日 | I44: E | J44: -
A45: 10 | D45: pn.note_days# | E45: RI | G45: Note sight | H45: 手形サイト | I45: E | J45: -
A46: 10 | D46: pn.drawer_nm# | E46: RI | G46: Drawer name | H46: 振出人名 | I46: E | J46: -
A47: 10 | D47: pn.draw_bank_cd# | E47: RI | G47: Drawing bank cd. | H47: 振出銀行ＣＤ | I47: E | J47: -
A48: 10 | D48: pn.draw_branch_cd# | E48: RI | G48: Drawing branch cd. | H48: 振出支店ＣＤ | I48: E | J48: -
A49: 10 | D49: pn.endrsr# | E49: RI | G49: Endorser | H49: 裏書人 | I49: E | J49: -
A50: 10 | D50: pn.accptr# | E50: RI | G50: Accepted by | H50: 引受人 | I50: E | J50: -
A51: 10 | D51: pn.sub_char1#note_sub_char1 | E51: RI | G51: Spare 1 | H51: 予備１ | I51: E | J51: -
... A53: 10 | D53: pn.sub_char3#note_sub_char3 | E53: RI | G53: Spare 3 | H53: 予備３ | I53: E | J53: -
D54: 詳細 :

Sheet Upd01
A1: * | B1: * | D1: L | E1: 1
A2: * | D2: オペレーション実装仕様書 Operation Specification Implementation Sheet | E2: ModuleID : | F2: MS | G2: LogicID : | H2: =IF(LogicCommon!E2="","",LogicCommon!E2) -> MSBHL0070 | I2: Ope.ID : | J2: Upd01 | K2: Pj.ID : | L2: MC | M2: Ope.Body : | N2: "mcframe.serverMAUD.MAUDL5010.MAUDL_Operation"
A3: * | E3: SubModuleID : | F3: MSBH | G3: LogicClass : | H3: =IF(LogicCommon!E3="","",LogicCommon!E3) -> MSBHL_AdvPayReg | I3: Ope.Method : | J3: =J2 -> Upd01 | K3: SuperClassPj.ID : | O3: Gene.Type : | P3: ALL
A4: * | E4: Version : | F4: 000000 | G4: LogicName : | H4: =IF(LogicCommon!E4="","",LogicCommon!E4) -> 前渡金登録 | I4: Ope.Name : | J4: 更新 | K4: SuperLogicID : | L4: =IF(LogicCommon!G4="","",LogicCommon!G4) -> MS.MSUDL5010 | M4: ImplOpe.ID:
A5: * | E5: ACType :
A6: * | D6: 概要 : | E6: 前渡金実績、支払手形情報を更新する。 | M6: ID | O6: ID | Q6: ID
A7: # | I7: U | K7: K | L7: o | N7: o | P7: o
A8: # | D8: ブロック名 Block Name | E8: 型 Type | G8: super/share | H8: 対象ブロック名 Target Block Name | L8: TargetName | N8: TargetName | P8: TargetName | T8: ブロック備考 Block Remarks
A9: # | D9: 項目名 Field Name | E9: 型 Type | F9: 桁 Digits | G9: フルネーム Full Name | H9: 日本語名 Japanese Name | I9: 上り項目 Request Message Field | J9: 下り項目 Response Message Field | R9: 条件および編集方法 Conditions and Editing Methods | T9: 項目備考 Field Remarks
A10: # | L10: 上り項目 Request Message Field | M10: 下り項目 Response Message Field | N10: 上り項目 Request Message Field | O10: 下り項目 Response Message Field | P10: 上り項目 Request Message Field | Q10: 下り項目 Response Message Field
A11: 10 | B11: * | D11: Upd01_Hdr | E11: R | G11: $share$ | H11: MS.MSBHL5050.AdvPay_Chk01.AdvPay_Chk01_Hdr
A12: 10 | D12: apa | E12: R | F12: DBC:MS.MST_ADV_PAY_ACT
A13: 10 | D13: apa.adv_pay_act_no# | E13: RI | G13: Advance payment result No. | H13: 前渡金実績ＮＯ | I13: E | J13: -
A14: 10 | D14: apa.adv_pay_act_seq# | E14: RI | G14: Advance payment result sequence number | H14: 前渡金実績連番 | I14: E | J14: E
A15: 10 | D15: apa.adv_pay_act_rev# | E15: RI | G15: Advance payment result revision number | H15: 前渡金実績改訂番号 | I15: - | J15: E
A16: 10 | D16: apa.bsppl_cd# | E16: RI | G16: Scheduled payee cd. | H16: 支払予定管理先ＣＤ | I16: E | J16: -
A17: 10 | D17: apa.bsppl_dpt_cd# | E17: RI | G17: Cd. of dept. in charge of scheduled payee | H17: 支払予定管理先担当部門ＣＤ | I17: E | J17: -
A18: 10 | D18: apa.bd_dpt_cd# | E18: RI | G18: Charged dept. cd. | H18: 負担部門ＣＤ | I18: E | J18: -
A19: 10 | D19: apa.pay_dpt_cd# | E19: RI | G19: Payment dept. cd. | H19: 支払部門ＣＤ | I19: E | J19: -
A20: 10 | D20: apa.pay_usr_cd# | E20: RI | G20: Payment PIC cd. | H20: 支払担当者ＣＤ | I20: E | J20: -
A21: 10 | D21: apa.pay_act_dt# | E21: RI | G21: Actual payment date | H21: 支払実績日 | I21: E | J21: -
A22: 10 | D22: apa.ac_dt# | E22: RI | G22: Recording date | H22: 計上日 | I22: E | J22: -
A23: 10 | D23: can_ac_dt | E23: #MA.DT | G23: Cancellation recording date | H23: 取消計上日 | I23: E | J23: -
A24: 10 | D24: apa.ac_ym# | E24: RI | G24: Recording month | H24: 計上年月 | I24: - | J24: E
... A39: 10 | D39: apa.sub_char3# | E39: RI | G39: Spare 3 | H39: 予備３ | I39: E | J39: -
A40: 10 | D40: pn | E40: R | F40: DBC:MS.MST_PAY_NOTE
A41: 10 | D41: pn.note_no# | E41: RI | G41: Note number | H41: 手形番号 | I41: E | J41: -
A42: 10 | D42: pn.note_typ# | E42: RI | G42: Note type | H42: 手形区分 | I42: E | J42: -
A43: 10 | D43: pn.note_rsn_cd# | E43: RI | G43: Note reason cd. | H43: 手形理由ＣＤ | I43: E | J43: -
A44: 10 | D44: pn.draw_dt# | E44: RI | G44: Drawing date | H44: 振出日 | I44: E | J44: -
A45: 10 | D45: pn.due_dt# | E45: RI | G45: Payment due date | H45: 支払期日 | I45: E | J45: -
A46: 10 | D46: pn.note_days# | E46: RI | G46: Note sight | H46: 手形サイト | I46: E | J46: -
A47: 10 | D47: pn.drawer_nm# | E47: RI | G47: Drawer name | H47: 振出人名 | I47: E | J47: -
A48: 10 | D48: pn.draw_bank_cd# | E48: RI | G48: Drawing bank cd. | H48: 振出銀行ＣＤ | I48: E | J48: -
A49: 10 | D49: pn.draw_branch_cd# | E49: RI | G49: Drawing branch cd. | H49: 振出支店ＣＤ | I49: E | J49: -
A50: 10 | D50: pn.endrsr# | E50: RI | G50: Endorser | H50: 裏書人 | I50: E | J50: -
A51: 10 | D51: pn.accptr# | E51: RI | G51: Accepted by | H51: 引受人 | I51: E | J51: -
A52: 10 | D52: pn.sub_char1#note_sub_char1 | E52: RI | G52: Spare 1 | H52: 予備１ | I52: E | J52: -
... A55: 10 | D55: adv_pay_upd_cntr | E55: #MA.UPD_CNT | G55: Update counter | H55: 更新カウンタ | I55: E | J55: -
D56: 詳細 :

Sheet Del01
A1: * | B1: * | D1: L | E1: 1
A2: * | D2: オペレーション実装仕様書 Operation Specification Implementation Sheet | E2: ModuleID : | F2: MS | G2: LogicID : | H2: =IF(LogicCommon!E2="","",LogicCommon!E2) -> MSBHL0070 | I2: Ope.ID : | J2: Del01 | K2: Pj.ID : | L2: MC | M2: Ope.Body : | N2: "mcframe.serverMAUD.MAUDL5010.MAUDL_Operation"
A3: * | E3: SubModuleID : | F3: MSBH | G3: LogicClass : | H3: =IF(LogicCommon!E3="","",LogicCommon!E3) -> MSBHL_AdvPayReg | I3: Ope.Method : | J3: =J2 -> Del01 | K3: SuperClassPj.ID : | O3: Gene.Type : | P3: ALL
A4: * | E4: Version : | F4: 000000 | G4: LogicName : | H4: =IF(LogicCommon!E4="","",LogicCommon!E4) -> 前渡金登録 | I4: Ope.Name : | J4: 削除 | K4: SuperLogicID : | L4: =IF(LogicCommon!G4="","",LogicCommon!G4) -> MS.MSUDL5010 | M4: ImplOpe.ID:
A5: * | E5: ACType :
A6: * | D6: 概要 : | E6: 前渡金実績、支払手形情報を取り消す。 | M6: ID | O6: ID | Q6: ID
A7: # | I7: U | K7: K | L7: o | N7: o | P7: o
A8: # | D8: ブロック名 Block Name | E8: 型 Type | G8: super/share | H8: 対象ブロック名 Target Block Name | L8: TargetName | N8: TargetName | P8: TargetName | T8: ブロック備考 Block Remarks
A9: # | D9: 項目名 Field Name | E9: 型 Type | F9: 桁 Digits | G9: フルネーム Full Name | H9: 日本語名 Japanese Name | I9: 上り項目 Request Message Field | J9: 下り項目 Response Message Field | R9: 条件および編集方法 Conditions and Editing Methods | T9: 項目備考 Field Remarks
A10: # | L10: 上り項目 Request Message Field | M10: 下り項目 Response Message Field | N10: 上り項目 Request Message Field | O10: 下り項目 Response Message Field | P10: 上り項目 Request Message Field | Q10: 下り項目 Response Message Field
A11: 10 | B11: * | D11: Del01_Hdr | E11: R | G11: $share$ | H11: MS.MSBHL5050.AdvPay_Chk01.AdvPay_Chk01_Hdr
A12: 10 | D12: apa | E12: R | F12: DBC:MS.MST_ADV_PAY_ACT
A13: 10 | D13: apa.adv_pay_act_no# | E13: RI | G13: Advance payment result No. | H13: 前渡金実績ＮＯ | I13: E | J13: -
A14: 10 | D14: apa.adv_pay_act_seq# | E14: RI | G14: Advance payment result sequence number | H14: 前渡金実績連番 | I14: E | J14: -
A15: 10 | D15: can_ac_dt | E15: #MA.DT | G15: Cancellation recording date | H15: 取消計上日 | I15: E | J15: -
A16: 10 | D16: adv_pay_upd_cntr | E16: #MA.UPD_CNT | G16: Update counter | H16: 更新カウンタ | I16: E | J16: -
D17: 詳細 :

Sheet 来歴
A1: 変更来歴
A3: Rev. | H3: 修正番号 | O3: 変更内容 | AQ3: 変更箇所
A4: 1 | O4: 初版
A5: 1.1 | O5: 英語の名称を追記 | AQ5: 全般
