Workbook

Sheet LogicCommon
A2: ロジック共通定義 | B2: ModuleID : | C2: MA | D2: LogicID : | E2: MABSL0350 | F2: Pj.ID : | G2: MC
B3: SubModuleID : | C3: MABS | D3: LogicClass : | E3: MABSL_ItmSiteReg | F3: SuperClassPj.ID :
D4: LogicName : | E4: 品目マスタ（工場・物流倉庫）登録 | F4: SuperLogicID : | G4: MA.MAUDL5010
A5: 概要 :
A6: 詳細 :

Sheet ItmSite_UpdChk01
A1: * | B1: * | D1: L | E1: 1
A2: * | D2: オペレーション実装仕様書 Operation Specification Implementation Sheet | E2: ModuleID : | F2: =IF(LogicCommon!C2="","",LogicCommon!C2) -> MA | G2: LogicID : | H2: =IF(LogicCommon!E2="","",LogicCommon!E2) -> MABSL0350 | I2: Ope.ID : | J2: ItmSite_UpdChk01 | K2: Pj.ID : | L2: =IF(LogicCommon!G2="","",LogicCommon!G2) -> MC | M2: Ope.Body : | N2: =L4 & ".Checker" -> MA.MAUDL5010.Checker
A3: * | D3: =IF(LogicCommon!A3="","",LogicCommon!A3) | E3: SubModuleID : | F3: =IF(LogicCommon!C3="","",LogicCommon!C3) -> MABS | G3: LogicClass : | H3: =IF(LogicCommon!E3="","",LogicCommon!E3) -> MABSL_ItmSiteReg | I3: Ope.Method : | J3: @ | K3: SuperClassPj.ID : | L3: =IF(LogicCommon!G3="","",LogicCommon!G3) | M3: ReportID : | O3: Gene.Type : | P3: ALL
A4: * | E4: Version : | F4: 000000 | G4: LogicName : | H4: =IF(LogicCommon!E4="","",LogicCommon!E4) -> 品目マスタ（工場・物流倉庫）登録 | I4: Ope.Name : | J4: 登録前チェック | K4: SuperLogicID : | L4: =IF(LogicCommon!G4="","",LogicCommon!G4) -> MA.MAUDL5010
A5: * | E5: ACType :
A6: * | D6: 概要 : | E6: 品目マスタ（工場・物流倉庫）を登録する前のチェックを行う | S6: ID
A7: # | I7: U | K7: K | L7: K | M7: K | N7: K | O7: K | P7: K | Q7: K | R7: o
A8: # | D8: ブロック名 Block Name | E8: 型 Type | G8: super/share | H8: 対象ブロック名 Target Block Name | K8: NULL_VAL | L8: REQUIRED | M8: LIST_LOGIC | N8: LIST_IN | O8: LIST_IN_BASE | P8: LIST_OUT | Q8: LIST_OUT_BASE | R8: TargetName | V8: ブロック備考 Block Remarks
A9: # | D9: 項目名 Field Name | E9: 型 Type | F9: 桁 Digits | G9: フルネーム Full Name | H9: 日本語名 Japanese Name | I9: 上り項目 Request Message Field | J9: 下り項目 Response Message Field | T9: 条件および編集方法 Conditions and Editing Methods | V9: 項目備考 Field Remarks
A10: # | R10: 上り項目 Request Message Field | S10: 下り項目 Response Message Field
A11: 10 | B11: * | D11: ItmSite_UpdChk01_Dtl | E11: L
A12: 10 | D12: itm_cd | E12: #MA.ITM_CD | G12: Item cd. | H12: 品目ＣＤ | I12: E | L12: E
A13: 10 | D13: itm_sub1 | E13: #MA.ITM_SUB1 | G13: Branch No. 1 | H13: 枝番１ | I13: E | K13: E
A14: 10 | D14: itm_sub2 | E14: #MA.ITM_SUB2 | G14: Branch No. 2 | H14: 枝番２ | I14: E | K14: E
A15: 10 | D15: itm_sub3 | E15: #MA.ITM_SUB3 | G15: Branch No. 3 | H15: 枝番３ | I15: E | K15: E | M15: MA.MAUAL0010.ItmSub3 | N15: MAC_ITM_IS_SRCH_TYP.STK1_ASSET1;itm_cd;itm_sub1;itm_sub2;true;true | O15: itm_is_srch_typ;itm_cd;itm_sub1;itm_sub2;release_flg_on;release_flg_off | P15: lot_mng_typ;sublot_mng_typ | Q15: lot_mng_typ;sublot_mng_typ
A16: 10 | D16: lot_mng_typ | E16: #MA.LOT_MNG_TYP | G16: Lot management type | H16: ロット管理区分
A17: 10 | D17: sublot_mng_typ | E17: #MA.SUBLOT_MNG_TYP | G17: Sublot management type | H17: サブロット管理区分
A18: 10 | D18: site_cd | E18: #MA.SITE_CD | G18: Factory/Distribution warehouse cd. | H18: 工場・物流倉庫ＣＤ | I18: E | M18: MA.MAUAL0010.Site
A19: 10 | D19: ntfy_nm | E19: #MA.NTFY_NM | G19: Notification name | H19: 届出名 | I19: E
A20: 10 | D20: plnt_aprv_flg | E20: #MA.FLG | G20: For factory release approval | H20: 工場出荷承認対象 | I20: E
A21: 10 | D21: plnt_aprv_role_cd | E21: #MA.APRV_ROLE_CD | G21: Factory release approval role cd. | H21: 工場出荷承認役割ＣＤ | I21: E | M21: MA.MAUAL0010.AprvRole
A22: 10 | D22: insp_aprv_flg | E22: #MA.FLG | G22: For inspection approval | H22: 検査承認対象 | I22: E
A23: 10 | D23: insp_aprv_role_cd | E23: #MA.APRV_ROLE_CD | G23: Inspection approval role cd. | H23: 検査承認役割ＣＤ | I23: E | M23: MA.MAUAL0010.AprvRole
A24: 10 | D24: mfg_aprv_flg | E24: #MA.FLG | G24: For mfg. approval | H24: 製造承認対象 | I24: E
A25: 10 | D25: mfg_aprv_role_cd | E25: #MA.APRV_ROLE_CD | G25: Mfg. approval role cd. | H25: 製造承認役割ＣＤ | I25: E | M25: MA.MAUAL0010.AprvRole
A26: 10 | D26: xfr_lot_flg | E26: #MA.FLG | G26: Lot No. transfer at transport receipt | H26: 移送入荷時ロットＮＯ振替 | I26: E
A27: 10 | D27: so_prmt_insp_flg | E27: #MA.FLG | G27: Allow inspecting lot shipment | H27: 検査中ロット出荷許可 | I27: E
A28: 10 | D28: in_prmt_insp_flg | E28: #MA.FLG | G28: Allow inspecting lot use | H28: 検査中ロット使用許可 | I28: E
A29: 10 | D29: num_id | E29: #MA.NUM_ID | G29: Numbering ID | H29: 発番ＩＤ | I29: E
A30: 10 | D30: memo1 | E30: #MA.MST_MEMO1 | G30: Memo 1 | H30: メモ１ | I30: E
A31: 10 | D31: memo2 | E31: #MA.MST_MEMO2 | G31: Memo 2 | H31: メモ２ | I31: E
A32: 10 | D32: memo3 | E32: #MA.MST_MEMO3 | G32: Memo 3 | H32: メモ３ | I32: E
A33: 10 | D33: del_flg | E33: #MA.FLG | G33: Logical delete | H33: 論理削除 | I33: E
A34: 10 | D34: upd_cntr | E34: #MA.UPD_CNT | G34: Update counter | H34: 更新カウンタ | I34: E
D35: 詳細 :

Sheet ItmSite_Upd01
A1: * | B1: * | D1: L | E1: 1
A2: * | D2: オペレーション実装仕様書 Operation Specification Implementation Sheet | E2: ModuleID : | F2: =IF(LogicCommon!C2="","",LogicCommon!C2) -> MA | G2: LogicID : | H2: =IF(LogicCommon!E2="","",LogicCommon!E2) -> MABSL0350 | I2: Ope.ID : | J2: ItmSite_Upd01 | K2: Pj.ID : | L2: =IF(LogicCommon!G2="","",LogicCommon!G2) -> MC | M2: Ope.Body : | N2: "mcframe.serverMAUD.MAUDL6010.MAUDL_RLUpdater"
A3: * | D3: =IF(LogicCommon!A3="","",LogicCommon!A3) | E3: SubModuleID : | F3: =IF(LogicCommon!C3="","",LogicCommon!C3) -> MABS | G3: LogicClass : | H3: =IF(LogicCommon!E3="","",LogicCommon!E3) -> MABSL_ItmSiteReg | I3: Ope.Method : | J3: @ | K3: SuperClassPj.ID : | L3: =IF(LogicCommon!G3="","",LogicCommon!G3) | M3: ReportID : | O3: Gene.Type : | P3: ALL
A4: * | E4: Version : | F4: 000000 | G4: LogicName : | H4: =IF(LogicCommon!E4="","",LogicCommon!E4) -> 品目マスタ（工場・物流倉庫）登録 | I4: Ope.Name : | J4: 登録処理 | K4: SuperLogicID : | L4: =IF(LogicCommon!G4="","",LogicCommon!G4) -> MA.MAUDL5010
A5: * | E5: ACType :
A6: * | D6: 概要 : | E6: 品目マスタ（工場・物流倉庫）を登録する | L6: ID | N6: ID | P6: ID | R6: ID
A7: # | I7: U | K7: o | L7: UPDATE.updMaster | M7: o | N7: MAIN.chkMaster | O7: o | Q7: o
A8: # | D8: ブロック名 Block Name | E8: 型 Type | G8: super/share | H8: 対象ブロック名 Target Block Name | K8: TargetName | L8: DBC.MA.MAM_ITM_SITE | M8: TargetName | N8: DBC.MA.MAM_ITM_SITE | O8: TargetName | Q8: TargetName | U8: ブロック備考 Block Remarks
A9: # | D9: 項目名 Field Name | E9: 型 Type | F9: 桁 Digits | G9: フルネーム Full Name | H9: 日本語名 Japanese Name | I9: 上り項目 Request Message Field | J9: 下り項目 Response Message Field | S9: 条件および編集方法 Conditions and Editing Methods | U9: 項目備考 Field Remarks
A10: # | K10: 上り項目 Request Message Field | L10: 下り項目 Response Message Field | M10: 上り項目 Request Message Field | N10: 下り項目 Response Message Field | O10: 上り項目 Request Message Field | P10: 下り項目 Response Message Field | Q10: 上り項目 Request Message Field | R10: 下り項目 Response Message Field
A11: 10 | B11: * | D11: ItmSite_Upd01_Dtl | E11: L | G11: $share$ | H11: MA.MABSL0350.ItmSite_UpdChk01.ItmSite_UpdChk01_Dtl | K11: L | M11: L
A12: 10 | D12: itm_cd | E12: #MA.ITM_CD | G12: Item cd. | H12: 品目ＣＤ | I12: E | K12: E | M12: E
A13: 10 | D13: itm_sub1 | E13: #MA.ITM_SUB1 | G13: Branch No. 1 | H13: 枝番１ | I13: E | K13: E | M13: E
A14: 10 | D14: itm_sub2 | E14: #MA.ITM_SUB2 | G14: Branch No. 2 | H14: 枝番２ | I14: E | K14: E | M14: E
A15: 10 | D15: itm_sub3 | E15: #MA.ITM_SUB3 | G15: Branch No. 3 | H15: 枝番３ | I15: E | K15: E | M15: E
A16: 10 | D16: site_cd | E16: #MA.SITE_CD | G16: Factory/Distribution warehouse cd. | H16: 工場・物流倉庫ＣＤ | I16: E | K16: E | M16: E
A17: 10 | D17: ntfy_nm | E17: #MA.NTFY_NM | G17: Notification name | H17: 届出名 | I17: E | K17: E
A18: 10 | D18: plnt_aprv_flg | E18: #MA.FLG | G18: For factory release approval | H18: 工場出荷承認対象 | I18: E | K18: E
A19: 10 | D19: plnt_aprv_role_cd | E19: #MA.APRV_ROLE_CD | G19: Factory release approval role cd. | H19: 工場出荷承認役割ＣＤ | I19: E | K19: E
A20: 10 | D20: insp_aprv_flg | E20: #MA.FLG | G20: For inspection approval | H20: 検査承認対象 | I20: E | K20: E
A21: 10 | D21: insp_aprv_role_cd | E21: #MA.APRV_ROLE_CD | G21: Inspection approval role cd. | H21: 検査承認役割ＣＤ | I21: E | K21: E
A22: 10 | D22: mfg_aprv_flg | E22: #MA.FLG | G22: For mfg. approval | H22: 製造承認対象 | I22: E | K22: E
A23: 10 | D23: mfg_aprv_role_cd | E23: #MA.APRV_ROLE_CD | G23: Mfg. approval role cd. | H23: 製造承認役割ＣＤ | I23: E | K23: E
A24: 10 | D24: xfr_lot_flg | E24: #MA.FLG | G24: Lot No. transfer at transport receipt | H24: 移送入荷時ロットＮＯ振替 | I24: E | K24: E
A25: 10 | D25: so_prmt_insp_flg | E25: #MA.FLG | G25: Allow inspecting lot shipment | H25: 検査中ロット出荷許可 | I25: E | K25: E
A26: 10 | D26: in_prmt_insp_flg | E26: #MA.FLG | G26: Allow inspecting lot use | H26: 検査中ロット使用許可 | I26: E | K26: E
A27: 10 | D27: num_id | E27: #MA.NUM_ID | G27: Numbering ID | H27: 発番ＩＤ | I27: E | K27: E
A28: 10 | D28: memo1 | E28: #MA.MST_MEMO1 | G28: Memo 1 | H28: メモ１ | I28: E | K28: E
... A32: 10 | D32: upd_cntr | E32: #MA.UPD_CNT | G32: Update counter | H32: 更新カウンタ | I32: E | K32: E
D33: 詳細 :

Sheet ItmSite_DelChk01
A1: * | B1: * | D1: L | E1: 1
A2: * | D2: オペレーション実装仕様書 Operation Specification Implementation Sheet | E2: ModuleID : | F2: =IF(LogicCommon!C2="","",LogicCommon!C2) -> MA | G2: LogicID : | H2: =IF(LogicCommon!E2="","",LogicCommon!E2) -> MABSL0350 | I2: Ope.ID : | J2: ItmSite_DelChk01 | K2: Pj.ID : | L2: =IF(LogicCommon!G2="","",LogicCommon!G2) -> MC | M2: Ope.Body : | N2: =L4 & ".Checker" -> MA.MAUDL5010.Checker
A3: * | D3: =IF(LogicCommon!A3="","",LogicCommon!A3) | E3: SubModuleID : | F3: =IF(LogicCommon!C3="","",LogicCommon!C3) -> MABS | G3: LogicClass : | H3: =IF(LogicCommon!E3="","",LogicCommon!E3) -> MABSL_ItmSiteReg | I3: Ope.Method : | J3: @ | K3: SuperClassPj.ID : | L3: =IF(LogicCommon!G3="","",LogicCommon!G3) | M3: ReportID : | O3: Gene.Type : | P3: ALL
A4: * | E4: Version : | F4: 000000 | G4: LogicName : | H4: =IF(LogicCommon!E4="","",LogicCommon!E4) -> 品目マスタ（工場・物流倉庫）登録 | I4: Ope.Name : | J4: 削除前チェック | K4: SuperLogicID : | L4: =IF(LogicCommon!G4="","",LogicCommon!G4) -> MA.MAUDL5010
A5: * | E5: ACType :
A6: * | D6: 概要 : | E6: 品目マスタ（工場・物流倉庫）を削除する前のチェックを行う | Q6: ID
A7: # | I7: U | K7: K | L7: K | M7: K | N7: K | P7: o
A8: # | D8: ブロック名 Block Name | E8: 型 Type | G8: super/share | H8: 対象ブロック名 Target Block Name | K8: NULL_VAL | L8: REQUIRED | M8: SCALE | N8: CONST | P8: TargetName | T8: ブロック備考 Block Remarks
A9: # | D9: 項目名 Field Name | E9: 型 Type | F9: 桁 Digits | G9: フルネーム Full Name | H9: 日本語名 Japanese Name | I9: 上り項目 Request Message Field | J9: 下り項目 Response Message Field | R9: 条件および編集方法 Conditions and Editing Methods | T9: 項目備考 Field Remarks
A10: # | P10: 上り項目 Request Message Field | Q10: 下り項目 Response Message Field
A11: 10 | B11: * | D11: ItmSite_DelChk01_Dtl | E11: L
A12: 10 | D12: itm_cd | E12: #MA.ITM_CD | G12: Item cd. | H12: 品目ＣＤ | I12: E | L12: E
A13: 10 | D13: itm_sub1 | E13: #MA.ITM_SUB1 | G13: Branch No. 1 | H13: 枝番１ | I13: E | L13: E
A14: 10 | D14: itm_sub2 | E14: #MA.ITM_SUB2 | G14: Branch No. 2 | H14: 枝番２ | I14: E | L14: E
A15: 10 | D15: itm_sub3 | E15: #MA.ITM_SUB3 | G15: Branch No. 3 | H15: 枝番３ | I15: E | L15: E
A16: 10 | D16: site_cd | E16: #MA.SITE_CD | G16: Factory/Distribution warehouse cd. | H16: 工場・物流倉庫ＣＤ | I16: E | L16: E
A17: 10 | D17: upd_cntr | E17: #MA.UPD_CNT | G17: Update counter | H17: 更新カウンタ | I17: E
D18: 詳細 :

Sheet ItmSite_Del01
A1: * | B1: * | D1: L | E1: 1
A2: * | D2: オペレーション実装仕様書 Operation Specification Implementation Sheet | E2: ModuleID : | F2: =IF(LogicCommon!C2="","",LogicCommon!C2) -> MA | G2: LogicID : | H2: =IF(LogicCommon!E2="","",LogicCommon!E2) -> MABSL0350 | I2: Ope.ID : | J2: ItmSite_Del01 | K2: Pj.ID : | L2: =IF(LogicCommon!G2="","",LogicCommon!G2) -> MC | M2: Ope.Body : | N2: "mcframe.serverMAUD.MAUDL6010.MAUDL_RLDeleter"
A3: * | D3: =IF(LogicCommon!A3="","",LogicCommon!A3) | E3: SubModuleID : | F3: =IF(LogicCommon!C3="","",LogicCommon!C3) -> MABS | G3: LogicClass : | H3: =IF(LogicCommon!E3="","",LogicCommon!E3) -> MABSL_ItmSiteReg | I3: Ope.Method : | J3: @ | K3: SuperClassPj.ID : | L3: =IF(LogicCommon!G3="","",LogicCommon!G3) | M3: ReportID : | O3: Gene.Type : | P3: ALL
A4: * | E4: Version : | F4: 000000 | G4: LogicName : | H4: =IF(LogicCommon!E4="","",LogicCommon!E4) -> 品目マスタ（工場・物流倉庫）登録 | I4: Ope.Name : | J4: 削除処理 | K4: SuperLogicID : | L4: =IF(LogicCommon!G4="","",LogicCommon!G4) -> MA.MAUDL5010
A5: * | E5: ACType :
A6: * | D6: 概要 : | E6: 品目マスタ（工場・物流倉庫）を削除する | L6: ID | N6: ID
A7: # | I7: U | K7: o | L7: UPDATE.updMaster1 | M7: o
A8: # | D8: ブロック名 Block Name | E8: 型 Type | G8: super/share | H8: 対象ブロック名 Target Block Name | K8: TargetName | L8: DBC.MA.MAM_ITM_SITE | M8: TargetName | Q8: ブロック備考 Block Remarks
A9: # | D9: 項目名 Field Name | E9: 型 Type | F9: 桁 Digits | G9: フルネーム Full Name | H9: 日本語名 Japanese Name | I9: 上り項目 Request Message Field | J9: 下り項目 Response Message Field | O9: 条件および編集方法 Conditions and Editing Methods | Q9: 項目備考 Field Remarks
A10: # | K10: 上り項目 Request Message Field | L10: 下り項目 Response Message Field | M10: 上り項目 Request Message Field | N10: 下り項目 Response Message Field
A11: 10 | B11: * | D11: ItmSite_Del01_Dtl | E11: L | G11: $share$ | H11: MA.MABSL0350.ItmSite_DelChk01.ItmSite_DelChk01_Dtl | K11: L
A12: 10 | D12: itm_cd | E12: #MA.ITM_CD | G12: Item cd. | H12: 品目ＣＤ | I12: E | K12: E
A13: 10 | D13: itm_sub1 | E13: #MA.ITM_SUB1 | G13: Branch No. 1 | H13: 枝番１ | I13: E | K13: E
A14: 10 | D14: itm_sub2 | E14: #MA.ITM_SUB2 | G14: Branch No. 2 | H14: 枝番２ | I14: E | K14: E
A15: 10 | D15: itm_sub3 | E15: #MA.ITM_SUB3 | G15: Branch No. 3 | H15: 枝番３ | I15: E | K15: E
A16: 10 | D16: site_cd | E16: #MA.SITE_CD | G16: Factory/Distribution warehouse cd. | H16: 工場・物流倉庫ＣＤ | I16: E | K16: E
A17: 10 | D17: upd_cntr | E17: #MA.UPD_CNT | G17: Update counter | H17: 更新カウンタ | I17: E | K17: E
D18: 詳細 :

Sheet Srch01
A1: * | B1: * | D1: L | E1: 1
A2: * | D2: オペレーション実装仕様書 Operation Specification Implementation Sheet | E2: ModuleID : | F2: =IF(LogicCommon!C2="","",LogicCommon!C2) -> MA | G2: LogicID : | H2: =IF(LogicCommon!E2="","",LogicCommon!E2) -> MABSL0350 | I2: Ope.ID : | J2: Srch01 | K2: Pj.ID : | L2: =IF(LogicCommon!G2="","",LogicCommon!G2) -> MC | M2: Ope.Body : | N2: "mcframe.serverMAUD.MAUDL6010.MAUDL_RLSearcher"
A3: * | D3: =IF(LogicCommon!A3="","",LogicCommon!A3) | E3: SubModuleID : | F3: =IF(LogicCommon!C3="","",LogicCommon!C3) -> MABS | G3: LogicClass : | H3: =IF(LogicCommon!E3="","",LogicCommon!E3) -> MABSL_ItmSiteReg | I3: Ope.Method : | J3: @ | K3: SuperClassPj.ID : | L3: =IF(LogicCommon!G3="","",LogicCommon!G3) | M3: ReportID : | O3: Gene.Type : | P3: ALL
A4: * | E4: Version : | F4: 000000 | G4: LogicName : | H4: =IF(LogicCommon!E4="","",LogicCommon!E4) -> 品目マスタ（工場・物流倉庫）登録 | I4: Ope.Name : | J4: 検索 | K4: SuperLogicID : | L4: =IF(LogicCommon!G4="","",LogicCommon!G4) -> MA.MAUDL5010
A5: * | E5: ACType :
A6: * | D6: 概要 : | E6: 検索処理を行う | M6: ID | O6: ID
A7: # | I7: U | K7: K | L7: o | M7: SELECT.c0 | N7: o
A8: # | D8: ブロック名 Block Name | E8: 型 Type | G8: super/share | H8: 対象ブロック名 Target Block Name | K8: CONST | L8: TargetName | M8: DBC.MA.MAM_ITM_SITE | N8: TargetName | R8: ブロック備考 Block Remarks
A9: # | D9: 項目名 Field Name | E9: 型 Type | F9: 桁 Digits | G9: フルネーム Full Name | H9: 日本語名 Japanese Name | I9: 上り項目 Request Message Field | J9: 下り項目 Response Message Field | P9: 条件および編集方法 Conditions and Editing Methods | R9: 項目備考 Field Remarks
A10: # | L10: 上り項目 Request Message Field | M10: 下り項目 Response Message Field | N10: 上り項目 Request Message Field | O10: 下り項目 Response Message Field
A11: 10 | B11: * | D11: Srch01_Cnd | E11: R
A12: 10 | D12: itm_typ | E12: #MA.ITM_TYP | G12: Item type | H12: 品目区分 | I12: E
A13: 10 | D13: itm_typ_d_cd | E13: #MA.ITM_TYP_D_CD | G13: Item type details cd. | H13: 品目区分詳細ＣＤ | I13: E
A14: 10 | D14: itm_typ_d_nm | E14: #MA.ITM_TYP_D_NM | G14: Item type details name | H14: 品目区分詳細名 | I14: E
A15: 10 | D15: itm_cd | E15: #MA.ITM_CD | G15: Item cd. | H15: 品目ＣＤ | I15: E
A16: 10 | D16: itm_sub1 | E16: #MA.ITM_SUB1 | G16: Branch No. 1 | H16: 枝番１ | I16: E
A17: 10 | D17: itm_sub2 | E17: #MA.ITM_SUB2 | G17: Branch No. 2 | H17: 枝番２ | I17: E
A18: 10 | D18: itm_sub3 | E18: #MA.ITM_SUB3 | G18: Branch No. 3 | H18: 枝番３ | I18: E
A19: 10 | D19: itm_nm | E19: #MA.ITM_NM | G19: Item name | H19: 品名 | I19: E
A20: 10 | D20: site_cd | E20: #MA.SITE_CD | G20: Factory/Distribution warehouse cd. | H20: 工場・物流倉庫ＣＤ | I20: E
A21: 10 | D21: site_nm | E21: #MA.SITE_NM | G21: Factory/Distribution warehouse name | H21: 工場・物流倉庫名 | I21: E
A22: 10 | D22: off_del_flg | E22: #MA.FLG | G22: Logical delete. Off | H22: 論理削除.オフ | I22: E
A23: 10 | D23: on_del_flg | E23: #MA.FLG | G23: Logical delete. On | H23: 論理削除.オン | I23: E
... A46: 10 | D46: itm_grp_nm10 | E46: #MA.ITM_GRP_NM | G46: Item classification name 10 | H46: 品目分類名１０ | I46: E
A48: 20 | B48: * | D48: Srch01_Rslt1 | E48: L | M48: L
A49: 20 | D49: del_flg | E49: #MA.FLG | G49: Logical delete | H49: 論理削除 | J49: E | M49: E
A50: 20 | D50: itm_cd | E50: #MA.ITM_CD | G50: Item cd. | H50: 品目ＣＤ | J50: E | M50: E
A51: 20 | D51: itm_sub1 | E51: #MA.ITM_SUB1 | G51: Branch No. 1 | H51: 枝番１ | J51: E | M51: E
A52: 20 | D52: itm_sub2 | E52: #MA.ITM_SUB2 | G52: Branch No. 2 | H52: 枝番２ | J52: E | M52: E
A53: 20 | D53: itm_sub3 | E53: #MA.ITM_SUB3 | G53: Branch No. 3 | H53: 枝番３ | J53: E | M53: E
A54: 20 | D54: itm_nm | E54: #MA.ITM_NM | G54: Item name | H54: 品名 | J54: E | M54: E
A55: 20 | D55: itm_typ | E55: #MA.ITM_TYP | G55: Item type | H55: 品目区分 | J55: E | K55: MAC_ITM_TYP | M55: E
A56: 20 | D56: itm_typ_nm | E56: #MA.ITM_TYP_NM | G56: Item type name | H56: 品目区分名 | J56: E
A57: 20 | D57: itm_typ_d_cd | E57: #MA.ITM_TYP_D_CD | G57: Item type details cd. | H57: 品目区分詳細ＣＤ | J57: E | M57: E
A58: 20 | D58: itm_typ_d_nm | E58: #MA.ITM_TYP_D_NM | G58: Item type details name | H58: 品目区分詳細名 | J58: E | M58: E
A59: 20 | D59: lot_mng_typ | E59: #MA.LOT_MNG_TYP | G59: Lot management type | H59: ロット管理区分 | J59: E | K59: MAC_LOT_MNG_TYP | M59: E
A60: 20 | D60: lot_mng_typ_nm | E60: #MA.LOT_MNG_TYP_NM | G60: Lot management type name | H60: ロット管理区分名 | J60: E
A61: 20 | D61: sublot_mng_typ | E61: #MA.SUBLOT_MNG_TYP | G61: Sublot management type | H61: サブロット管理区分 | J61: E | K61: MAC_SUBLOT_MNG_TYP | M61: E
A62: 20 | D62: sublot_mng_typ_nm | E62: #MA.SUBLOT_MNG_TYP_NM | G62: Sublot management type name | H62: サブロット管理区分名 | J62: E
A63: 20 | D63: site_cd | E63: #MA.SITE_CD | G63: Factory/Distribution warehouse cd. | H63: 工場・物流倉庫ＣＤ | J63: E | M63: E
...

Sheet Upd01
A1: * | B1: * | D1: L | E1: 1
A2: * | D2: オペレーション実装仕様書 Operation Specification Implementation Sheet | E2: ModuleID : | F2: =IF(LogicCommon!C2="","",LogicCommon!C2) -> MA | G2: LogicID : | H2: =IF(LogicCommon!E2="","",LogicCommon!E2) -> MABSL0350 | I2: Ope.ID : | J2: Upd01 | K2: Pj.ID : | L2: =IF(LogicCommon!G2="","",LogicCommon!G2) -> MC | M2: Ope.Body : | N2: "mcframe.serverMAUD.MAUDL6010.MAUDL_RLUpdater"
A3: * | D3: =IF(LogicCommon!A3="","",LogicCommon!A3) | E3: SubModuleID : | F3: =IF(LogicCommon!C3="","",LogicCommon!C3) -> MABS | G3: LogicClass : | H3: =IF(LogicCommon!E3="","",LogicCommon!E3) -> MABSL_ItmSiteReg | I3: Ope.Method : | J3: @ | K3: SuperClassPj.ID : | L3: =IF(LogicCommon!G3="","",LogicCommon!G3) | M3: ReportID : | O3: Gene.Type : | P3: ALL
A4: * | E4: Version : | F4: 000000 | G4: LogicName : | H4: =IF(LogicCommon!E4="","",LogicCommon!E4) -> 品目マスタ（工場・物流倉庫）登録 | I4: Ope.Name : | J4: 登録 | K4: SuperLogicID : | L4: =IF(LogicCommon!G4="","",LogicCommon!G4) -> MA.MAUDL5010
A5: * | E5: ACType :
A6: * | D6: 概要 : | E6: 登録処理を行う | L6: ID | N6: ID | P6: ID | R6: ID
A7: # | I7: U | K7: o | L7: CALL_OPE01.chk01 | M7: o | N7: CALL_OPE01.upd01 | O7: o | Q7: o
A8: # | D8: ブロック名 Block Name | E8: 型 Type | G8: super/share | H8: 対象ブロック名 Target Block Name | K8: TargetName | L8: OPE.MA.MABSL0350.ItmSite_UpdChk01 | M8: TargetName | N8: OPE.MA.MABSL0350.ItmSite_Upd01 | O8: TargetName | Q8: TargetName | U8: ブロック備考 Block Remarks
A9: # | D9: 項目名 Field Name | E9: 型 Type | F9: 桁 Digits | G9: フルネーム Full Name | H9: 日本語名 Japanese Name | I9: 上り項目 Request Message Field | J9: 下り項目 Response Message Field | S9: 条件および編集方法 Conditions and Editing Methods | U9: 項目備考 Field Remarks
A10: # | K10: 上り項目 Request Message Field | L10: 下り項目 Response Message Field | M10: 上り項目 Request Message Field | N10: 下り項目 Response Message Field | O10: 上り項目 Request Message Field | P10: 下り項目 Response Message Field | Q10: 上り項目 Request Message Field | R10: 下り項目 Response Message Field
A11: 10 | B11: * | D11: Upd01_Dtl1 | E11: L | G11: $share$ | H11: MA.MABSL0350.ItmSite_Upd01.ItmSite_Upd01_Dtl | K11: ItmSite_UpdChk01_Dtl | M11: ItmSite_Upd01_Dtl
A12: 10 | D12: itm_cd | E12: #MA.ITM_CD | G12: Item cd. | H12: 品目ＣＤ | I12: E | K12: E | M12: E
A13: 10 | D13: itm_sub1 | E13: #MA.ITM_SUB1 | G13: Branch No. 1 | H13: 枝番１ | I13: E | K13: E | M13: E
A14: 10 | D14: itm_sub2 | E14: #MA.ITM_SUB2 | G14: Branch No. 2 | H14: 枝番２ | I14: E | K14: E | M14: E
A15: 10 | D15: itm_sub3 | E15: #MA.ITM_SUB3 | G15: Branch No. 3 | H15: 枝番３ | I15: E | K15: E | M15: E
A16: 10 | D16: site_cd | E16: #MA.SITE_CD | G16: Factory/Distribution warehouse cd. | H16: 工場・物流倉庫ＣＤ | I16: E | K16: E | M16: E
A17: 10 | D17: ntfy_nm | E17: #MA.NTFY_NM | G17: Notification name | H17: 届出名 | I17: E | K17: E | M17: E
A18: 10 | D18: plnt_aprv_flg | E18: #MA.FLG | G18: For factory release approval | H18: 工場出荷承認対象 | I18: E | K18: E | M18: E
A19: 10 | D19: plnt_aprv_role_cd | E19: #MA.APRV_ROLE_CD | G19: Factory release approval role cd. | H19: 工場出荷承認役割ＣＤ | I19: E | K19: E | M19: E
A20: 10 | D20: insp_aprv_flg | E20: #MA.FLG | G20: For inspection approval | H20: 検査承認対象 | I20: E | K20: E | M20: E
A21: 10 | D21: insp_aprv_role_cd | E21: #MA.APRV_ROLE_CD | G21: Inspection approval role cd. | H21: 検査承認役割ＣＤ | I21: E | K21: E | M21: E
A22: 10 | D22: mfg_aprv_flg | E22: #MA.FLG | G22: For mfg. approval | H22: 製造承認対象 | I22: E | K22: E | M22: E
A23: 10 | D23: mfg_aprv_role_cd | E23: #MA.APRV_ROLE_CD | G23: Mfg. approval role cd. | H23: 製造承認役割ＣＤ | I23: E | K23: E | M23: E
... A32: 10 | D32: upd_cntr | E32: #MA.UPD_CNT | G32: Update counter | H32: 更新カウンタ | I32: E | K32: E | M32: E
D33: 詳細 :

Sheet Del01
A1: * | B1: * | D1: L | E1: 1
A2: * | D2: オペレーション実装仕様書 Operation Specification Implementation Sheet | E2: ModuleID : | F2: =IF(LogicCommon!C2="","",LogicCommon!C2) -> MA | G2: LogicID : | H2: =IF(LogicCommon!E2="","",LogicCommon!E2) -> MABSL0350 | I2: Ope.ID : | J2: Del01 | K2: Pj.ID : | L2: =IF(LogicCommon!G2="","",LogicCommon!G2) -> MC | M2: Ope.Body : | N2: "mcframe.serverMAUD.MAUDL6010.MAUDL_RLDeleter"
A3: * | D3: =IF(LogicCommon!A3="","",LogicCommon!A3) | E3: SubModuleID : | F3: =IF(LogicCommon!C3="","",LogicCommon!C3) -> MABS | G3: LogicClass : | H3: =IF(LogicCommon!E3="","",LogicCommon!E3) -> MABSL_ItmSiteReg | I3: Ope.Method : | J3: @ | K3: SuperClassPj.ID : | L3: =IF(LogicCommon!G3="","",LogicCommon!G3) | M3: ReportID : | O3: Gene.Type : | P3: ALL
A4: * | E4: Version : | F4: 000000 | G4: LogicName : | H4: =IF(LogicCommon!E4="","",LogicCommon!E4) -> 品目マスタ（工場・物流倉庫）登録 | I4: Ope.Name : | J4: 削除 | K4: SuperLogicID : | L4: =IF(LogicCommon!G4="","",LogicCommon!G4) -> MA.MAUDL5010
A5: * | E5: ACType :
A6: * | D6: 概要 : | E6: 削除処理を行う | L6: ID | N6: ID
A7: # | I7: U | K7: o | L7: CALL_OPE01.chk01 | M7: o | N7: CALL_OPE01.del01
A8: # | D8: ブロック名 Block Name | E8: 型 Type | G8: super/share | H8: 対象ブロック名 Target Block Name | K8: TargetName | L8: OPE.MA.MABSL0350.ItmSite_DelChk01 | M8: TargetName | N8: OPE.MA.MABSL0350.ItmSite_Del01 | Q8: ブロック備考 Block Remarks
A9: # | D9: 項目名 Field Name | E9: 型 Type | F9: 桁 Digits | G9: フルネーム Full Name | H9: 日本語名 Japanese Name | I9: 上り項目 Request Message Field | J9: 下り項目 Response Message Field | O9: 条件および編集方法 Conditions and Editing Methods | Q9: 項目備考 Field Remarks
A10: # | K10: 上り項目 Request Message Field | L10: 下り項目 Response Message Field | M10: 上り項目 Request Message Field | N10: 下り項目 Response Message Field
A11: 10 | B11: * | D11: Del01_Dtl1 | E11: L | G11: $share$ | H11: MA.MABSL0350.ItmSite_Del01.ItmSite_Del01_Dtl | K11: ItmSite_DelChk01_Dtl | M11: ItmSite_Del01_Dtl
A12: 10 | D12: itm_cd | E12: #MA.ITM_CD | G12: Item cd. | H12: 品目ＣＤ | I12: E | K12: E | M12: E
A13: 10 | D13: itm_sub1 | E13: #MA.ITM_SUB1 | G13: Branch No. 1 | H13: 枝番１ | I13: E | K13: E | M13: E
A14: 10 | D14: itm_sub2 | E14: #MA.ITM_SUB2 | G14: Branch No. 2 | H14: 枝番２ | I14: E | K14: E | M14: E
A15: 10 | D15: itm_sub3 | E15: #MA.ITM_SUB3 | G15: Branch No. 3 | H15: 枝番３ | I15: E | K15: E | M15: E
A16: 10 | D16: site_cd | E16: #MA.SITE_CD | G16: Factory/Distribution warehouse cd. | H16: 工場・物流倉庫ＣＤ | I16: E | K16: E | M16: E
A17: 10 | D17: upd_cntr | E17: #MA.UPD_CNT | G17: Update counter | H17: 更新カウンタ | I17: E | K17: E | M17: E
D18: 詳細 :

Sheet 来歴
A1: 変更来歴
A3: Rev. | H3: 修正番号 | O3: 変更内容 | AQ3: 変更箇所
A4: 1 | O4: 初版
A5: 1.1 | O5: 英語の名称を追記 | AQ5: 全般
