Workbook

Sheet LogicCommon
A2: ロジック共通定義 | B2: ModuleID : | C2: MA | D2: LogicID : | E2: MABSL0290 | F2: Pj.ID : | G2: MC
B3: SubModuleID : | C3: MABS | D3: LogicClass : | E3: MABSL_ItmCompReg | F3: SuperClassPj.ID :
D4: LogicName : | E4: 品目構成マスタ登録 | F4: SuperLogicID : | G4: MA.MAUDL5010
A5: 概要 :
A6: 詳細 :

Sheet ItmComp_UpdChk01
A1: * | B1: * | D1: L | E1: 1
A2: * | D2: オペレーション実装仕様書 Operation Specification Implementation Sheet | E2: ModuleID : | F2: =IF(LogicCommon!C2="","",LogicCommon!C2) -> MA | G2: LogicID : | H2: =IF(LogicCommon!E2="","",LogicCommon!E2) -> MABSL0290 | I2: Ope.ID : | J2: ItmComp_UpdChk01 | K2: Pj.ID : | L2: =IF(LogicCommon!G2="","",LogicCommon!G2) -> MC | M2: Ope.Body : | N2: =L4 & ".Checker" -> MA.MAUDL5010.Checker
A3: * | D3: =IF(LogicCommon!A3="","",LogicCommon!A3) | E3: SubModuleID : | F3: =IF(LogicCommon!C3="","",LogicCommon!C3) -> MABS | G3: LogicClass : | H3: =IF(LogicCommon!E3="","",LogicCommon!E3) -> MABSL_ItmCompReg | I3: Ope.Method : | J3: @ | K3: SuperClassPj.ID : | L3: =IF(LogicCommon!G3="","",LogicCommon!G3) | M3: ReportID : | O3: Gene.Type : | P3: ALL
A4: * | E4: Version : | F4: 000000 | G4: LogicName : | H4: =IF(LogicCommon!E4="","",LogicCommon!E4) -> 品目構成マスタ登録 | I4: Ope.Name : | J4: チェック | K4: SuperLogicID : | L4: =IF(LogicCommon!G4="","",LogicCommon!G4) -> MA.MAUDL5010
A5: * | E5: ACType :
A6: * | D6: 概要 : | E6: 品目構成マスタの登録前のチェックを行います。 | T6: ID
A7: # | I7: U | K7: K | L7: K | M7: K | N7: K | O7: K | P7: K | Q7: K | R7: K | S7: o
A8: # | D8: ブロック名 Block Name | E8: 型 Type | G8: super/share | H8: 対象ブロック名 Target Block Name | K8: REQUIRED | L8: NULL_VAL | M8: LIST_LOGIC | N8: LIST_OUT | O8: LIST_OUT_BASE | P8: LIST_IN | Q8: LIST_IN_BASE | R8: CHK_NUM | S8: TargetName | W8: ブロック備考 Block Remarks
A9: # | D9: 項目名 Field Name | E9: 型 Type | F9: 桁 Digits | G9: フルネーム Full Name | H9: 日本語名 Japanese Name | I9: 上り項目 Request Message Field | J9: 下り項目 Response Message Field | U9: 条件および編集方法 Conditions and Editing Methods | W9: 項目備考 Field Remarks
A10: # | S10: 上り項目 Request Message Field | T10: 下り項目 Response Message Field
A11: 10 | B11: * | D11: ItmComp_UpdChk01_Dtl | E11: L | G11: $super$ | H11: DBC:MA.MAM_ITM_COMP
A12: 10 | D12: core_itm_cd | E12: #MA.ITM_CD | G12: Main item cd. | H12: 主品目ＣＤ | I12: E | K12: E
A13: 10 | D13: core_itm_sub1 | E13: #MA.ITM_SUB1 | G13: Main branch No. 1 | H13: 主枝番１ | I13: E | L13: E
A14: 10 | D14: core_itm_sub2 | E14: #MA.ITM_SUB2 | G14: Main branch No. 2 | H14: 主枝番２ | I14: E | L14: E
A15: 10 | D15: core_itm_sub3 | E15: #MA.ITM_SUB3 | G15: Main branch No. 3 | H15: 主枝番３ | I15: E | L15: E | M15: MA.MAUAL0010.ItmSub3 | N15: core_itm_unit_cd | O15: ship_unit_cd | P15: MAC_ITM_IS_SRCH_TYP.COMP_CORE_ITM;core_itm_cd;core_itm_sub1;core_itm_sub2;true;true | Q15: itm_is_srch_typ;itm_cd;itm_sub1;itm_sub2;release_flg_on;release_flg_off
A16: 10 | D16: core_itm_unit_cd | E16: #MA.UNIT_CD | G16: Main item unit cd. | H16: 主品目単位ＣＤ | M16: MA.MAUAL0010.ItmUnit | N16: core_itm_dec_place | O16: dec_place | P16: core_itm_cd;core_itm_sub1;core_itm_sub2;core_itm_sub3 | Q16: itm_cd;itm_sub1;itm_sub2;itm_sub3
A17: 10 | D17: core_itm_dec_place | E17: #MA.DEC_PLACE | G17: Main item unit number of decimal places | H17: 主品目単位小数部有効桁数
A18: 10 | D18: core_itm_qty | E18: #MA.QTY | G18: Main item qty. | H18: 主品目数 | I18: E | K18: E | R18: positive
A19: 10 | D19: comp_itm_cd | E19: #MA.ITM_CD | G19: Component item cd. | H19: 構成品目ＣＤ | I19: E | K19: E
A20: 10 | D20: comp_itm_sub1 | E20: #MA.ITM_SUB1 | G20: Configuration branch 1 | H20: 構成枝番１ | I20: E | L20: E
A21: 10 | D21: comp_itm_sub2 | E21: #MA.ITM_SUB2 | G21: Configuration branch 2 | H21: 構成枝番２ | I21: E | L21: E
A22: 10 | D22: comp_itm_sub3 | E22: #MA.ITM_SUB3 | G22: Configuration branch 3 | H22: 構成枝番３ | I22: E | L22: E | M22: MA.MAUAL0010.ItmSub3 | P22: MAC_ITM_IS_SRCH_TYP.NOT_ASSET3;comp_itm_cd;comp_itm_sub1;comp_itm_sub2;true;true | Q22: itm_is_srch_typ;itm_cd;itm_sub1;itm_sub2;release_flg_on;release_flg_off
A23: 10 | D23: comp_itm_unit_cd | E23: #MA.UNIT_CD | G23: Component item unit cd. | H23: 構成品目単位ＣＤ | I23: E | K23: E | M23: MA.MAUAL0010.ItmUnit | N23: comp_itm_dec_place | O23: dec_place | P23: comp_itm_cd;comp_itm_sub1;comp_itm_sub2;comp_itm_sub3 | Q23: itm_cd;itm_sub1;itm_sub2;itm_sub3
A24: 10 | D24: comp_itm_dec_place | E24: #MA.DEC_PLACE | G24: Component item unit number of decimal places | H24: 構成品目単位小数部有効桁数
A25: 10 | D25: comp_itm_qty | E25: #MA.QTY | G25: Component item number | H25: 構成品目数 | I25: E | K25: E | R25: positive
A26: 10 | D26: itm_comp_grp_cd | E26: #MA.ITM_COMP_GRP_CD | G26: Item configuration group cd. | H26: 品目構成グループＣＤ | I26: E | M26: MA.MAUAL0010.ItmCompGrp
A27: 10 | D27: def_flg | E27: #MA.FLG | G27: Normal configuration | H27: 通常構成 | I27: E
A28: 10 | D28: memo1 | E28: #MA.MST_MEMO1 | G28: Memo 1 | H28: メモ１ | I28: E
A29: 10 | D29: memo2 | E29: #MA.MST_MEMO2 | G29: Memo 2 | H29: メモ２ | I29: E
A30: 10 | D30: memo3 | E30: #MA.MST_MEMO3 | G30: Memo 3 | H30: メモ３ | I30: E
A31: 10 | D31: del_flg | E31: #MA.FLG | G31: Logical delete | H31: 論理削除 | I31: E
A32: 10 | D32: upd_cntr | E32: #MA.UPD_CNT | G32: Update counter | H32: 更新カウンタ | I32: E
D33: 詳細 :

Sheet ItmComp_Upd01
A1: * | B1: * | D1: L | E1: 1
A2: * | D2: オペレーション実装仕様書 Operation Specification Implementation Sheet | E2: ModuleID : | F2: =IF(LogicCommon!C2="","",LogicCommon!C2) -> MA | G2: LogicID : | H2: =IF(LogicCommon!E2="","",LogicCommon!E2) -> MABSL0290 | I2: Ope.ID : | J2: ItmComp_Upd01 | K2: Pj.ID : | L2: =IF(LogicCommon!G2="","",LogicCommon!G2) -> MC | M2: Ope.Body : | N2: "mcframe.serverMAUD.MAUDL6010.MAUDL_RLUpdater"
A3: * | D3: =IF(LogicCommon!A3="","",LogicCommon!A3) | E3: SubModuleID : | F3: =IF(LogicCommon!C3="","",LogicCommon!C3) -> MABS | G3: LogicClass : | H3: =IF(LogicCommon!E3="","",LogicCommon!E3) -> MABSL_ItmCompReg | I3: Ope.Method : | J3: @ | K3: SuperClassPj.ID : | L3: =IF(LogicCommon!G3="","",LogicCommon!G3) | M3: ReportID : | O3: Gene.Type : | P3: ALL
A4: * | E4: Version : | F4: 000000 | G4: LogicName : | H4: =IF(LogicCommon!E4="","",LogicCommon!E4) -> 品目構成マスタ登録 | I4: Ope.Name : | J4: 登録 | K4: SuperLogicID : | L4: =IF(LogicCommon!G4="","",LogicCommon!G4) -> MA.MAUDL5010
A5: * | E5: ACType :
A6: * | D6: 概要 : | E6: 品目構成マスタの登録を行います。 | L6: ID | N6: ID | P6: ID | R6: ID
A7: # | I7: U | K7: o | L7: UPDATE.updMaster | M7: o | N7: MAIN.chkMaster | O7: o | Q7: o
A8: # | D8: ブロック名 Block Name | E8: 型 Type | G8: super/share | H8: 対象ブロック名 Target Block Name | K8: TargetName | L8: DBC.MA.MAM_ITM_COMP | M8: TargetName | N8: DBC.MA.MAM_ITM_COMP | O8: TargetName | Q8: TargetName | U8: ブロック備考 Block Remarks
A9: # | D9: 項目名 Field Name | E9: 型 Type | F9: 桁 Digits | G9: フルネーム Full Name | H9: 日本語名 Japanese Name | I9: 上り項目 Request Message Field | J9: 下り項目 Response Message Field | S9: 条件および編集方法 Conditions and Editing Methods | U9: 項目備考 Field Remarks
A10: # | K10: 上り項目 Request Message Field | L10: 下り項目 Response Message Field | M10: 上り項目 Request Message Field | N10: 下り項目 Response Message Field | O10: 上り項目 Request Message Field | P10: 下り項目 Response Message Field | Q10: 上り項目 Request Message Field | R10: 下り項目 Response Message Field
A11: 10 | B11: * | D11: ItmComp_Upd01_Dtl | E11: L | G11: $share$ | H11: MA.MABSL0290.ItmComp_UpdChk01.ItmComp_UpdChk01_Dtl | K11: L | M11: L
A12: 10 | D12: core_itm_cd | E12: #MA.ITM_CD | G12: Main item cd. | H12: 主品目ＣＤ | I12: E | K12: E | M12: E
A13: 10 | D13: core_itm_sub1 | E13: #MA.ITM_SUB1 | G13: Main branch No. 1 | H13: 主枝番１ | I13: E | K13: E | M13: E
A14: 10 | D14: core_itm_sub2 | E14: #MA.ITM_SUB2 | G14: Main branch No. 2 | H14: 主枝番２ | I14: E | K14: E | M14: E
A15: 10 | D15: core_itm_sub3 | E15: #MA.ITM_SUB3 | G15: Main branch No. 3 | H15: 主枝番３ | I15: E | K15: E | M15: E
A16: 10 | D16: core_itm_qty | E16: #MA.QTY | G16: Main item qty. | H16: 主品目数 | I16: E | K16: E
A17: 10 | D17: comp_itm_cd | E17: #MA.ITM_CD | G17: Component item cd. | H17: 構成品目ＣＤ | I17: E | K17: E | M17: E
A18: 10 | D18: comp_itm_sub1 | E18: #MA.ITM_SUB1 | G18: Configuration branch 1 | H18: 構成枝番１ | I18: E | K18: E | M18: E
A19: 10 | D19: comp_itm_sub2 | E19: #MA.ITM_SUB2 | G19: Configuration branch 2 | H19: 構成枝番２ | I19: E | K19: E | M19: E
A20: 10 | D20: comp_itm_sub3 | E20: #MA.ITM_SUB3 | G20: Configuration branch 3 | H20: 構成枝番３ | I20: E | K20: E | M20: E
A21: 10 | D21: comp_itm_unit_cd | E21: #MA.UNIT_CD | G21: Component item unit cd. | H21: 構成品目単位ＣＤ | I21: E | K21: E
A22: 10 | D22: comp_itm_qty | E22: #MA.QTY | G22: Component item number | H22: 構成品目数 | I22: E | K22: E
A23: 10 | D23: itm_comp_grp_cd | E23: #MA.ITM_COMP_GRP_CD | G23: Item configuration group cd. | H23: 品目構成グループＣＤ | I23: E | K23: E
A24: 10 | D24: def_flg | E24: #MA.FLG | G24: Normal configuration | H24: 通常構成 | I24: E | K24: E
A25: 10 | D25: memo1 | E25: #MA.MST_MEMO1 | G25: Memo 1 | H25: メモ１ | I25: E | K25: E
A26: 10 | D26: memo2 | E26: #MA.MST_MEMO2 | G26: Memo 2 | H26: メモ２ | I26: E | K26: E
A27: 10 | D27: memo3 | E27: #MA.MST_MEMO3 | G27: Memo 3 | H27: メモ３ | I27: E | K27: E
A28: 10 | D28: del_flg | E28: #MA.FLG | G28: Logical delete | H28: 論理削除 | I28: E | K28: E
A29: 10 | D29: upd_cntr | E29: #MA.UPD_CNT | G29: Update counter | H29: 更新カウンタ | I29: E | K29: E
D30: 詳細 :

Sheet ItmComp_DelChk01
A1: * | B1: * | D1: L | E1: 1
A2: * | D2: オペレーション実装仕様書 Operation Specification Implementation Sheet | E2: ModuleID : | F2: =IF(LogicCommon!C2="","",LogicCommon!C2) -> MA | G2: LogicID : | H2: =IF(LogicCommon!E2="","",LogicCommon!E2) -> MABSL0290 | I2: Ope.ID : | J2: ItmComp_DelChk01 | K2: Pj.ID : | L2: =IF(LogicCommon!G2="","",LogicCommon!G2) -> MC | M2: Ope.Body : | N2: =L4 & ".Checker" -> MA.MAUDL5010.Checker
A3: * | D3: =IF(LogicCommon!A3="","",LogicCommon!A3) | E3: SubModuleID : | F3: =IF(LogicCommon!C3="","",LogicCommon!C3) -> MABS | G3: LogicClass : | H3: =IF(LogicCommon!E3="","",LogicCommon!E3) -> MABSL_ItmCompReg | I3: Ope.Method : | J3: @ | K3: SuperClassPj.ID : | L3: =IF(LogicCommon!G3="","",LogicCommon!G3) | M3: ReportID : | O3: Gene.Type : | P3: ALL
A4: * | E4: Version : | F4: 000000 | G4: LogicName : | H4: =IF(LogicCommon!E4="","",LogicCommon!E4) -> 品目構成マスタ登録 | I4: Ope.Name : | J4: チェック | K4: SuperLogicID : | L4: =IF(LogicCommon!G4="","",LogicCommon!G4) -> MA.MAUDL5010
A5: * | E5: ACType :
A6: * | D6: 概要 : | E6: 品目構成マスタの削除前のチェックを行います。 | Q6: ID
A7: # | I7: U | K7: K | P7: o
A8: # | D8: ブロック名 Block Name | E8: 型 Type | G8: super/share | H8: 対象ブロック名 Target Block Name | K8: REQUIRED | P8: TargetName | T8: ブロック備考 Block Remarks
A9: # | D9: 項目名 Field Name | E9: 型 Type | F9: 桁 Digits | G9: フルネーム Full Name | H9: 日本語名 Japanese Name | I9: 上り項目 Request Message Field | J9: 下り項目 Response Message Field | R9: 条件および編集方法 Conditions and Editing Methods | T9: 項目備考 Field Remarks
A10: # | P10: 上り項目 Request Message Field | Q10: 下り項目 Response Message Field
A11: 10 | B11: * | D11: ItmComp_DelChk01_Dtl | E11: L | G11: $super$ | H11: DBC:MA.MAM_ITM_COMP
A12: 10 | D12: core_itm_cd | E12: #MA.ITM_CD | G12: Main item cd. | H12: 主品目ＣＤ | I12: E | K12: E
A13: 10 | D13: core_itm_sub1 | E13: #MA.ITM_SUB1 | G13: Main branch No. 1 | H13: 主枝番１ | I13: E | K13: E
A14: 10 | D14: core_itm_sub2 | E14: #MA.ITM_SUB2 | G14: Main branch No. 2 | H14: 主枝番２ | I14: E | K14: E
A15: 10 | D15: core_itm_sub3 | E15: #MA.ITM_SUB3 | G15: Main branch No. 3 | H15: 主枝番３ | I15: E | K15: E
A16: 10 | D16: comp_itm_cd | E16: #MA.ITM_CD | G16: Component item cd. | H16: 構成品目ＣＤ | I16: E | K16: E
A17: 10 | D17: comp_itm_sub1 | E17: #MA.ITM_SUB1 | G17: Configuration branch 1 | H17: 構成枝番１ | I17: E | K17: E
A18: 10 | D18: comp_itm_sub2 | E18: #MA.ITM_SUB2 | G18: Configuration branch 2 | H18: 構成枝番２ | I18: E | K18: E
A19: 10 | D19: comp_itm_sub3 | E19: #MA.ITM_SUB3 | G19: Configuration branch 3 | H19: 構成枝番３ | I19: E | K19: E
A20: 10 | D20: upd_cntr | E20: #MA.UPD_CNT | G20: Update counter | H20: 更新カウンタ | I20: E
D21: 詳細 :

Sheet ItmComp_Del01
A1: * | B1: * | D1: L | E1: 1
A2: * | D2: オペレーション実装仕様書 Operation Specification Implementation Sheet | E2: ModuleID : | F2: =IF(LogicCommon!C2="","",LogicCommon!C2) -> MA | G2: LogicID : | H2: =IF(LogicCommon!E2="","",LogicCommon!E2) -> MABSL0290 | I2: Ope.ID : | J2: ItmComp_Del01 | K2: Pj.ID : | L2: =IF(LogicCommon!G2="","",LogicCommon!G2) -> MC | M2: Ope.Body : | N2: "mcframe.serverMAUD.MAUDL6010.MAUDL_RLDeleter"
A3: * | D3: =IF(LogicCommon!A3="","",LogicCommon!A3) | E3: SubModuleID : | F3: =IF(LogicCommon!C3="","",LogicCommon!C3) -> MABS | G3: LogicClass : | H3: =IF(LogicCommon!E3="","",LogicCommon!E3) -> MABSL_ItmCompReg | I3: Ope.Method : | J3: @ | K3: SuperClassPj.ID : | L3: =IF(LogicCommon!G3="","",LogicCommon!G3) | M3: ReportID : | O3: Gene.Type : | P3: ALL
A4: * | E4: Version : | F4: 000000 | G4: LogicName : | H4: =IF(LogicCommon!E4="","",LogicCommon!E4) -> 品目構成マスタ登録 | I4: Ope.Name : | J4: 削除 | K4: SuperLogicID : | L4: =IF(LogicCommon!G4="","",LogicCommon!G4) -> MA.MAUDL5010
A5: * | E5: ACType :
A6: * | D6: 概要 : | E6: 品目構成マスタの削除を行います。 | L6: ID | N6: ID
A7: # | I7: U | K7: o | L7: UPDATE.updMaster1 | M7: o
A8: # | D8: ブロック名 Block Name | E8: 型 Type | G8: super/share | H8: 対象ブロック名 Target Block Name | K8: TargetName | L8: DBC.MA.MAM_ITM_COMP | M8: TargetName | Q8: ブロック備考 Block Remarks
A9: # | D9: 項目名 Field Name | E9: 型 Type | F9: 桁 Digits | G9: フルネーム Full Name | H9: 日本語名 Japanese Name | I9: 上り項目 Request Message Field | J9: 下り項目 Response Message Field | O9: 条件および編集方法 Conditions and Editing Methods | Q9: 項目備考 Field Remarks
A10: # | K10: 上り項目 Request Message Field | L10: 下り項目 Response Message Field | M10: 上り項目 Request Message Field | N10: 下り項目 Response Message Field
A11: 10 | B11: * | D11: ItmComp_Del01_Dtl | E11: L | G11: $share$ | H11: MA.MABSL0290.ItmComp_DelChk01.ItmComp_DelChk01_Dtl | K11: L
A12: 10 | D12: core_itm_cd | E12: #MA.ITM_CD | G12: Main item cd. | H12: 主品目ＣＤ | I12: E | K12: E
A13: 10 | D13: core_itm_sub1 | E13: #MA.ITM_SUB1 | G13: Main branch No. 1 | H13: 主枝番１ | I13: E | K13: E
A14: 10 | D14: core_itm_sub2 | E14: #MA.ITM_SUB2 | G14: Main branch No. 2 | H14: 主枝番２ | I14: E | K14: E
A15: 10 | D15: core_itm_sub3 | E15: #MA.ITM_SUB3 | G15: Main branch No. 3 | H15: 主枝番３ | I15: E | K15: E
A16: 10 | D16: comp_itm_cd | E16: #MA.ITM_CD | G16: Component item cd. | H16: 構成品目ＣＤ | I16: E | K16: E
A17: 10 | D17: comp_itm_sub1 | E17: #MA.ITM_SUB1 | G17: Configuration branch 1 | H17: 構成枝番１ | I17: E | K17: E
A18: 10 | D18: comp_itm_sub2 | E18: #MA.ITM_SUB2 | G18: Configuration branch 2 | H18: 構成枝番２ | I18: E | K18: E
A19: 10 | D19: comp_itm_sub3 | E19: #MA.ITM_SUB3 | G19: Configuration branch 3 | H19: 構成枝番３ | I19: E | K19: E
A20: 10 | D20: upd_cntr | E20: #MA.UPD_CNT | G20: Update counter | H20: 更新カウンタ | I20: E | K20: E
D21: 詳細 :

Sheet Srch01
A1: * | B1: * | D1: L | E1: 1
A2: * | D2: オペレーション実装仕様書 Operation Specification Implementation Sheet | E2: ModuleID : | F2: =IF(LogicCommon!C2="","",LogicCommon!C2) -> MA | G2: LogicID : | H2: =IF(LogicCommon!E2="","",LogicCommon!E2) -> MABSL0290 | I2: Ope.ID : | J2: Srch01 | K2: Pj.ID : | L2: =IF(LogicCommon!G2="","",LogicCommon!G2) -> MC | M2: Ope.Body : | N2: "mcframe.serverMAUD.MAUDL6010.MAUDL_RLSearcher"
A3: * | D3: =IF(LogicCommon!A3="","",LogicCommon!A3) | E3: SubModuleID : | F3: =IF(LogicCommon!C3="","",LogicCommon!C3) -> MABS | G3: LogicClass : | H3: =IF(LogicCommon!E3="","",LogicCommon!E3) -> MABSL_ItmCompReg | I3: Ope.Method : | J3: @ | K3: SuperClassPj.ID : | L3: =IF(LogicCommon!G3="","",LogicCommon!G3) | M3: ReportID : | O3: Gene.Type : | P3: ALL
A4: * | E4: Version : | F4: 000000 | G4: LogicName : | H4: =IF(LogicCommon!E4="","",LogicCommon!E4) -> 品目構成マスタ登録 | I4: Ope.Name : | J4: 検索 | K4: SuperLogicID : | L4: =IF(LogicCommon!G4="","",LogicCommon!G4) -> MA.MAUDL5010
A5: * | E5: ACType :
A6: * | D6: 概要 : | E6: 品目構成マスタの検索を行います。 | M6: ID | O6: ID
A7: # | I7: U | K7: K | L7: o | M7: SELECT.c0 | N7: o
A8: # | D8: ブロック名 Block Name | E8: 型 Type | G8: super/share | H8: 対象ブロック名 Target Block Name | K8: CONST | L8: TargetName | M8: DBC.MA.MAM_ITM_COMP | N8: TargetName | R8: ブロック備考 Block Remarks
A9: # | D9: 項目名 Field Name | E9: 型 Type | F9: 桁 Digits | G9: フルネーム Full Name | H9: 日本語名 Japanese Name | I9: 上り項目 Request Message Field | J9: 下り項目 Response Message Field | P9: 条件および編集方法 Conditions and Editing Methods | R9: 項目備考 Field Remarks
A10: # | L10: 上り項目 Request Message Field | M10: 下り項目 Response Message Field | N10: 上り項目 Request Message Field | O10: 下り項目 Response Message Field
A11: 10 | B11: * | D11: Srch01_Cnd | E11: R | L11: R
A12: 10 | D12: core_itm_typ | E12: #MA.ITM_TYP | G12: Main item type | H12: 主品目区分 | I12: E | K12: MAC_ITM_TYP
A13: 10 | D13: core_itm_typ_d_cd | E13: #MA.ITM_TYP_D_CD | G13: Main item type details cd. | H13: 主品目区分詳細ＣＤ | I13: E
A14: 10 | D14: core_itm_typ_d_nm | E14: #MA.ITM_TYP_D_NM | G14: Main item type details name | H14: 主品目区分詳細名 | I14: E
A15: 10 | D15: core_itm_cd | E15: #MA.ITM_CD | G15: Main item cd. | H15: 主品目ＣＤ | I15: E | L15: E
A16: 10 | D16: core_itm_sub1 | E16: #MA.ITM_SUB1 | G16: Main branch No. 1 | H16: 主枝番１ | I16: E | L16: E
A17: 10 | D17: core_itm_sub2 | E17: #MA.ITM_SUB2 | G17: Main branch No. 2 | H17: 主枝番２ | I17: E | L17: E
A18: 10 | D18: core_itm_sub3 | E18: #MA.ITM_SUB3 | G18: Main branch No. 3 | H18: 主枝番３ | I18: E | L18: E
A19: 10 | D19: core_itm_nm | E19: #MA.ITM_NM | G19: Main item name | H19: 主品名 | I19: E | L19: E
A20: 10 | D20: comp_itm_typ | E20: #MA.ITM_TYP | G20: Component item type | H20: 構成品目区分 | I20: E | K20: MAC_ITM_TYP
A21: 10 | D21: comp_itm_typ_d_cd | E21: #MA.ITM_TYP_D_CD | G21: Component item type details cd. | H21: 構成品目区分詳細ＣＤ | I21: E
A22: 10 | D22: comp_itm_typ_d_nm | E22: #MA.ITM_TYP_D_NM | G22: Component item type details name | H22: 構成品目区分詳細名 | I22: E
A23: 10 | D23: comp_itm_cd | E23: #MA.ITM_CD | G23: Component item cd. | H23: 構成品目ＣＤ | I23: E | L23: E
A24: 10 | D24: comp_itm_sub1 | E24: #MA.ITM_SUB1 | G24: Configuration branch 1 | H24: 構成枝番１ | I24: E | L24: E
A25: 10 | D25: comp_itm_sub2 | E25: #MA.ITM_SUB2 | G25: Configuration branch 2 | H25: 構成枝番２ | I25: E | L25: E
A26: 10 | D26: comp_itm_sub3 | E26: #MA.ITM_SUB3 | G26: Configuration branch 3 | H26: 構成枝番３ | I26: E | L26: E
A27: 10 | D27: comp_itm_nm | E27: #MA.ITM_NM | G27: Component item name | H27: 構成品目名 | I27: E | L27: E
A28: 10 | D28: off_del_flg | E28: #MA.FLG | G28: Logical delete. Off | H28: 論理削除.オフ | I28: E
A29: 10 | D29: on_del_flg | E29: #MA.FLG | G29: Logical delete. On | H29: 論理削除.オン | I29: E
A30: 10 | D30: memo1 | E30: #MA.MST_MEMO1 | G30: Memo 1 | H30: メモ１ | I30: E | L30: E
A31: 10 | D31: memo2 | E31: #MA.MST_MEMO2 | G31: Memo 2 | H31: メモ２ | I31: E | L31: E
A32: 10 | D32: memo3 | E32: #MA.MST_MEMO3 | G32: Memo 3 | H32: メモ３ | I32: E | L32: E
A33: 10 | D33: core_itm_grp_cd1 | E33: #MA.ITM_GRP_CD | G33: Main item classification cd. 1 | H33: 主品目分類ＣＤ１ | I33: E
A34: 10 | D34: core_itm_grp_nm1 | E34: #MA.ITM_GRP_NM | G34: Main item classification name 1 | H34: 主品目分類名１ | I34: E
A35: 10 | D35: core_itm_grp_cd2 | E35: #MA.ITM_GRP_CD | G35: Main item classification cd. 2 | H35: 主品目分類ＣＤ２ | I35: E
A36: 10 | D36: core_itm_grp_nm2 | E36: #MA.ITM_GRP_NM | G36: Main item classification name 2 | H36: 主品目分類名２ | I36: E
A37: 10 | D37: core_itm_grp_cd3 | E37: #MA.ITM_GRP_CD | G37: Main item classification cd. 3 | H37: 主品目分類ＣＤ３ | I37: E
A38: 10 | D38: core_itm_grp_nm3 | E38: #MA.ITM_GRP_NM | G38: Main item classification name 3 | H38: 主品目分類名３ | I38: E
A39: 10 | D39: core_itm_grp_cd4 | E39: #MA.ITM_GRP_CD | G39: Main item classification cd. 4 | H39: 主品目分類ＣＤ４ | I39: E
A40: 10 | D40: core_itm_grp_nm4 | E40: #MA.ITM_GRP_NM | G40: Main item classification name 4 | H40: 主品目分類名４ | I40: E
...

Sheet Upd01
A1: * | B1: * | D1: L | E1: 1
A2: * | D2: オペレーション実装仕様書 Operation Specification Implementation Sheet | E2: ModuleID : | F2: =IF(LogicCommon!C2="","",LogicCommon!C2) -> MA | G2: LogicID : | H2: =IF(LogicCommon!E2="","",LogicCommon!E2) -> MABSL0290 | I2: Ope.ID : | J2: Upd01 | K2: Pj.ID : | L2: =IF(LogicCommon!G2="","",LogicCommon!G2) -> MC | M2: Ope.Body : | N2: "mcframe.serverMAUD.MAUDL6010.MAUDL_RLUpdater"
A3: * | D3: =IF(LogicCommon!A3="","",LogicCommon!A3) | E3: SubModuleID : | F3: =IF(LogicCommon!C3="","",LogicCommon!C3) -> MABS | G3: LogicClass : | H3: =IF(LogicCommon!E3="","",LogicCommon!E3) -> MABSL_ItmCompReg | I3: Ope.Method : | J3: @ | K3: SuperClassPj.ID : | L3: =IF(LogicCommon!G3="","",LogicCommon!G3) | M3: ReportID : | O3: Gene.Type : | P3: ALL
A4: * | E4: Version : | F4: 000000 | G4: LogicName : | H4: =IF(LogicCommon!E4="","",LogicCommon!E4) -> 品目構成マスタ登録 | I4: Ope.Name : | J4: 登録 | K4: SuperLogicID : | L4: =IF(LogicCommon!G4="","",LogicCommon!G4) -> MA.MAUDL5010
A5: * | E5: ACType :
A6: * | D6: 概要 : | E6: 品目構成マスタの登録を行います。 | L6: ID | N6: ID | P6: ID | R6: ID
A7: # | I7: U | K7: o | L7: CALL_OPE01.chk01 | M7: o | N7: CALL_OPE01.upd01 | O7: o | Q7: o
A8: # | D8: ブロック名 Block Name | E8: 型 Type | G8: super/share | H8: 対象ブロック名 Target Block Name | K8: TargetName | L8: OPE.MA.MABSL0290.ItmComp_UpdChk01 | M8: TargetName | N8: OPE.MA.MABSL0290.ItmComp_Upd01 | O8: TargetName | Q8: TargetName | U8: ブロック備考 Block Remarks
A9: # | D9: 項目名 Field Name | E9: 型 Type | F9: 桁 Digits | G9: フルネーム Full Name | H9: 日本語名 Japanese Name | I9: 上り項目 Request Message Field | J9: 下り項目 Response Message Field | S9: 条件および編集方法 Conditions and Editing Methods | U9: 項目備考 Field Remarks
A10: # | K10: 上り項目 Request Message Field | L10: 下り項目 Response Message Field | M10: 上り項目 Request Message Field | N10: 下り項目 Response Message Field | O10: 上り項目 Request Message Field | P10: 下り項目 Response Message Field | Q10: 上り項目 Request Message Field | R10: 下り項目 Response Message Field
A11: 10 | B11: * | D11: Upd01_Dtl1 | E11: L | G11: $share$ | H11: MA.MABSL0290.ItmComp_Upd01.ItmComp_Upd01_Dtl | K11: ItmComp_UpdChk01_Dtl | M11: ItmComp_Upd01_Dtl
A12: 10 | D12: core_itm_cd | E12: #MA.ITM_CD | G12: Main item cd. | H12: 主品目ＣＤ | I12: E | K12: E | M12: E
A13: 10 | D13: core_itm_sub1 | E13: #MA.ITM_SUB1 | G13: Main branch No. 1 | H13: 主枝番１ | I13: E | K13: E | M13: E
A14: 10 | D14: core_itm_sub2 | E14: #MA.ITM_SUB2 | G14: Main branch No. 2 | H14: 主枝番２ | I14: E | K14: E | M14: E
A15: 10 | D15: core_itm_sub3 | E15: #MA.ITM_SUB3 | G15: Main branch No. 3 | H15: 主枝番３ | I15: E | K15: E | M15: E
A16: 10 | D16: core_itm_qty | E16: #MA.QTY | G16: Main item qty. | H16: 主品目数 | I16: E | K16: E | M16: E
A17: 10 | D17: comp_itm_cd | E17: #MA.ITM_CD | G17: Component item cd. | H17: 構成品目ＣＤ | I17: E | K17: E | M17: E
A18: 10 | D18: comp_itm_sub1 | E18: #MA.ITM_SUB1 | G18: Configuration branch 1 | H18: 構成枝番１ | I18: E | K18: E | M18: E
A19: 10 | D19: comp_itm_sub2 | E19: #MA.ITM_SUB2 | G19: Configuration branch 2 | H19: 構成枝番２ | I19: E | K19: E | M19: E
A20: 10 | D20: comp_itm_sub3 | E20: #MA.ITM_SUB3 | G20: Configuration branch 3 | H20: 構成枝番３ | I20: E | K20: E | M20: E
A21: 10 | D21: comp_itm_unit_cd | E21: #MA.UNIT_CD | G21: Component item unit cd. | H21: 構成品目単位ＣＤ | I21: E | K21: E | M21: E
A22: 10 | D22: comp_itm_qty | E22: #MA.QTY | G22: Component item number | H22: 構成品目数 | I22: E | K22: E | M22: E
A23: 10 | D23: itm_comp_grp_cd | E23: #MA.ITM_COMP_GRP_CD | G23: Item configuration group cd. | H23: 品目構成グループＣＤ | I23: E | K23: E | M23: E
... A29: 10 | D29: upd_cntr | E29: #MA.UPD_CNT | G29: Update counter | H29: 更新カウンタ | I29: E | K29: E | M29: E
D30: 詳細 :

Sheet Del01
A1: * | B1: * | D1: L | E1: 1
A2: * | D2: オペレーション実装仕様書 Operation Specification Implementation Sheet | E2: ModuleID : | F2: =IF(LogicCommon!C2="","",LogicCommon!C2) -> MA | G2: LogicID : | H2: =IF(LogicCommon!E2="","",LogicCommon!E2) -> MABSL0290 | I2: Ope.ID : | J2: Del01 | K2: Pj.ID : | L2: =IF(LogicCommon!G2="","",LogicCommon!G2) -> MC | M2: Ope.Body : | N2: "mcframe.serverMAUD.MAUDL6010.MAUDL_RLDeleter"
A3: * | D3: =IF(LogicCommon!A3="","",LogicCommon!A3) | E3: SubModuleID : | F3: =IF(LogicCommon!C3="","",LogicCommon!C3) -> MABS | G3: LogicClass : | H3: =IF(LogicCommon!E3="","",LogicCommon!E3) -> MABSL_ItmCompReg | I3: Ope.Method : | J3: @ | K3: SuperClassPj.ID : | L3: =IF(LogicCommon!G3="","",LogicCommon!G3) | M3: ReportID : | O3: Gene.Type : | P3: ALL
A4: * | E4: Version : | F4: 000000 | G4: LogicName : | H4: =IF(LogicCommon!E4="","",LogicCommon!E4) -> 品目構成マスタ登録 | I4: Ope.Name : | J4: 削除 | K4: SuperLogicID : | L4: =IF(LogicCommon!G4="","",LogicCommon!G4) -> MA.MAUDL5010
A5: * | E5: ACType :
A6: * | D6: 概要 : | E6: 品目構成マスタの削除を行います。 | L6: ID | N6: ID
A7: # | I7: U | K7: o | L7: CALL_OPE01.chk01 | M7: o | N7: CALL_OPE01.del01
A8: # | D8: ブロック名 Block Name | E8: 型 Type | G8: super/share | H8: 対象ブロック名 Target Block Name | K8: TargetName | L8: OPE.MA.MABSL0290.ItmComp_DelChk01 | M8: TargetName | N8: OPE.MA.MABSL0290.ItmComp_Del01 | Q8: ブロック備考 Block Remarks
A9: # | D9: 項目名 Field Name | E9: 型 Type | F9: 桁 Digits | G9: フルネーム Full Name | H9: 日本語名 Japanese Name | I9: 上り項目 Request Message Field | J9: 下り項目 Response Message Field | O9: 条件および編集方法 Conditions and Editing Methods | Q9: 項目備考 Field Remarks
A10: # | K10: 上り項目 Request Message Field | L10: 下り項目 Response Message Field | M10: 上り項目 Request Message Field | N10: 下り項目 Response Message Field
A11: 10 | B11: * | D11: Del01_Dtl1 | E11: L | G11: $share$ | H11: MA.MABSL0290.ItmComp_Del01.ItmComp_Del01_Dtl | K11: ItmComp_DelChk01_Dtl | M11: ItmComp_Del01_Dtl
A12: 10 | D12: core_itm_cd | E12: #MA.ITM_CD | G12: Main item cd. | H12: 主品目ＣＤ | I12: E | K12: E | M12: E
A13: 10 | D13: core_itm_sub1 | E13: #MA.ITM_SUB1 | G13: Main branch No. 1 | H13: 主枝番１ | I13: E | K13: E | M13: E
A14: 10 | D14: core_itm_sub2 | E14: #MA.ITM_SUB2 | G14: Main branch No. 2 | H14: 主枝番２ | I14: E | K14: E | M14: E
A15: 10 | D15: core_itm_sub3 | E15: #MA.ITM_SUB3 | G15: Main branch No. 3 | H15: 主枝番３ | I15: E | K15: E | M15: E
A16: 10 | D16: comp_itm_cd | E16: #MA.ITM_CD | G16: Component item cd. | H16: 構成品目ＣＤ | I16: E | K16: E | M16: E
A17: 10 | D17: comp_itm_sub1 | E17: #MA.ITM_SUB1 | G17: Configuration branch 1 | H17: 構成枝番１ | I17: E | K17: E | M17: E
A18: 10 | D18: comp_itm_sub2 | E18: #MA.ITM_SUB2 | G18: Configuration branch 2 | H18: 構成枝番２ | I18: E | K18: E | M18: E
A19: 10 | D19: comp_itm_sub3 | E19: #MA.ITM_SUB3 | G19: Configuration branch 3 | H19: 構成枝番３ | I19: E | K19: E | M19: E
A20: 10 | D20: upd_cntr | E20: #MA.UPD_CNT | G20: Update counter | H20: 更新カウンタ | I20: E | K20: E | M20: E
D21: 詳細 :

Sheet 来歴
A1: 変更来歴
A3: Rev. | H3: 修正番号 | O3: 変更内容 | AQ3: 変更箇所
A4: 1 | O4: 初版
A5: 1.1 | O5: 英語の名称を追記 | AQ5: 全般
