Workbook

Sheet LogicCommon
A2: ロジック共通定義 | B2: ModuleID : | C2: MA | D2: LogicID : | E2: MABSL0160 | F2: Pj.ID : | G2: MC
B3: SubModuleID : | C3: MABS | D3: LogicClass : | E3: MABSL_InspPointReg | F3: SuperClassPj.ID :
D4: LogicName : | E4: 検査項目マスタ登録 | F4: SuperLogicID : | G4: MA.MAUDL5010
A5: 概要 :
A6: 詳細 :

Sheet InspPoint_UpdChk01
A1: * | B1: * | D1: L | E1: 1
A2: * | D2: オペレーション実装仕様書 Operation Specification Implementation Sheet | E2: ModuleID : | F2: =IF(LogicCommon!C2="","",LogicCommon!C2) -> MA | G2: LogicID : | H2: =IF(LogicCommon!E2="","",LogicCommon!E2) -> MABSL0160 | I2: Ope.ID : | J2: InspPoint_UpdChk01 | K2: Pj.ID : | L2: =IF(LogicCommon!G2="","",LogicCommon!G2) -> MC | M2: Ope.Body : | N2: =L4 & ".Checker" -> MA.MAUDL5010.Checker
A3: * | D3: =IF(LogicCommon!A3="","",LogicCommon!A3) | E3: SubModuleID : | F3: =IF(LogicCommon!C3="","",LogicCommon!C3) -> MABS | G3: LogicClass : | H3: =IF(LogicCommon!E3="","",LogicCommon!E3) -> MABSL_InspPointReg | I3: Ope.Method : | J3: @ | K3: SuperClassPj.ID : | L3: =IF(LogicCommon!G3="","",LogicCommon!G3) | M3: ReportID : | O3: Gene.Type : | P3: ALL
A4: * | E4: Version : | F4: 000000 | G4: LogicName : | H4: =IF(LogicCommon!E4="","",LogicCommon!E4) -> 検査項目マスタ登録 | I4: Ope.Name : | J4: 登録前チェック | K4: SuperLogicID : | L4: =IF(LogicCommon!G4="","",LogicCommon!G4) -> MA.MAUDL5010
A5: * | E5: ACType :
A6: * | D6: 概要 : | E6: 検査項目マスタを登録する前のチェックを行う | Q6: ID
A7: # | I7: U | K7: K | L7: K | M7: K | P7: o
A8: # | D8: ブロック名 Block Name | E8: 型 Type | G8: super/share | H8: 対象ブロック名 Target Block Name | K8: REQUIRED | L8: CONST | M8: LIST_LOGIC | P8: TargetName | T8: ブロック備考 Block Remarks
A9: # | D9: 項目名 Field Name | E9: 型 Type | F9: 桁 Digits | G9: フルネーム Full Name | H9: 日本語名 Japanese Name | I9: 上り項目 Request Message Field | J9: 下り項目 Response Message Field | R9: 条件および編集方法 Conditions and Editing Methods | T9: 項目備考 Field Remarks
A10: # | P10: 上り項目 Request Message Field | Q10: 下り項目 Response Message Field
A11: 10 | B11: * | D11: InspPoint_UpdChk01_Dtl | E11: L | G11: $super$ | H11: DBC:MA.MAM_INSP_POINT
A12: 10 | D12: insp_point_cd | E12: #MA.INSP_POINT_CD | G12: Inspection checkpoint cd. | H12: 検査項目ＣＤ | I12: E | K12: E
A13: 10 | D13: insp_point_nm | E13: #MA.INSP_POINT_NM | G13: Inspection checkpoint name | H13: 検査項目名 | I13: E | K13: E
A14: 10 | D14: insp_qlqn_typ | E14: #MA.INSP_QLQN_TYP | G14: Qualitative/quantitative type | H14: 定性定量区分 | I14: E | K14: E | L14: MAC_INSP_QLQN_TYP
A15: 10 | D15: unit_cd | E15: #MA.UNIT_CD | G15: Unit cd. | H15: 単位ＣＤ | I15: E | M15: MA.MAUAL0010.Unit
A16: 10 | D16: auto_judg_flg | E16: #MA.FLG | G16: Auto-decide | H16: 自動合否判定 | I16: E
A17: 10 | D17: memo1 | E17: #MA.MST_MEMO1 | G17: Memo 1 | H17: メモ１ | I17: E
A18: 10 | D18: memo2 | E18: #MA.MST_MEMO2 | G18: Memo 2 | H18: メモ２ | I18: E
A19: 10 | D19: memo3 | E19: #MA.MST_MEMO3 | G19: Memo 3 | H19: メモ３ | I19: E
A20: 10 | D20: del_flg | E20: #MA.FLG | G20: Logical delete | H20: 論理削除 | I20: E
A21: 10 | D21: upd_cntr | E21: #MA.UPD_CNT | G21: Update counter | H21: 更新カウンタ | I21: E
D22: 詳細 :

Sheet InspPoint_Upd01
A1: * | B1: * | D1: L | E1: 1
A2: * | D2: オペレーション実装仕様書 Operation Specification Implementation Sheet | E2: ModuleID : | F2: =IF(LogicCommon!C2="","",LogicCommon!C2) -> MA | G2: LogicID : | H2: =IF(LogicCommon!E2="","",LogicCommon!E2) -> MABSL0160 | I2: Ope.ID : | J2: InspPoint_Upd01 | K2: Pj.ID : | L2: =IF(LogicCommon!G2="","",LogicCommon!G2) -> MC | M2: Ope.Body : | N2: "mcframe.serverMAUD.MAUDL6020.MAUDL_LCLRLUpdater"
A3: * | D3: =IF(LogicCommon!A3="","",LogicCommon!A3) | E3: SubModuleID : | F3: =IF(LogicCommon!C3="","",LogicCommon!C3) -> MABS | G3: LogicClass : | H3: =IF(LogicCommon!E3="","",LogicCommon!E3) -> MABSL_InspPointReg | I3: Ope.Method : | J3: @ | K3: SuperClassPj.ID : | L3: =IF(LogicCommon!G3="","",LogicCommon!G3) | M3: ReportID : | O3: Gene.Type : | P3: ALL
A4: * | E4: Version : | F4: 000000 | G4: LogicName : | H4: =IF(LogicCommon!E4="","",LogicCommon!E4) -> 検査項目マスタ登録 | I4: Ope.Name : | J4: 登録処理 | K4: SuperLogicID : | L4: =IF(LogicCommon!G4="","",LogicCommon!G4) -> MA.MAUDL5010
A5: * | E5: ACType :
A6: * | D6: 概要 : | E6: 検査項目マスタを登録する | L6: ID | N6: ID | P6: ID | R6: ID
A7: # | I7: U | K7: o | L7: UPDATE.updMaster | M7: o | N7: MAIN.chkMaster | O7: o | Q7: o
A8: # | D8: ブロック名 Block Name | E8: 型 Type | G8: super/share | H8: 対象ブロック名 Target Block Name | K8: TargetName | L8: DBC.MA.MAM_INSP_POINT | M8: TargetName | N8: DBC.MA.MAM_INSP_POINT | O8: TargetName | Q8: TargetName | U8: ブロック備考 Block Remarks
A9: # | D9: 項目名 Field Name | E9: 型 Type | F9: 桁 Digits | G9: フルネーム Full Name | H9: 日本語名 Japanese Name | I9: 上り項目 Request Message Field | J9: 下り項目 Response Message Field | S9: 条件および編集方法 Conditions and Editing Methods | U9: 項目備考 Field Remarks
A10: # | K10: 上り項目 Request Message Field | L10: 下り項目 Response Message Field | M10: 上り項目 Request Message Field | N10: 下り項目 Response Message Field | O10: 上り項目 Request Message Field | P10: 下り項目 Response Message Field | Q10: 上り項目 Request Message Field | R10: 下り項目 Response Message Field
A11: 10 | B11: * | D11: InspPoint_Upd01_Dtl | E11: L | G11: $share$ | H11: MA.MABSL0160.InspPoint_UpdChk01.InspPoint_UpdChk01_Dtl | K11: L | M11: L
A12: 10 | D12: insp_point_cd | E12: #MA.INSP_POINT_CD | G12: Inspection checkpoint cd. | H12: 検査項目ＣＤ | I12: E | K12: E | M12: E
A13: 10 | D13: insp_point_nm | E13: #MA.INSP_POINT_NM | G13: Inspection checkpoint name | H13: 検査項目名 | I13: E | K13: E
A14: 10 | D14: insp_qlqn_typ | E14: #MA.INSP_QLQN_TYP | G14: Qualitative/quantitative type | H14: 定性定量区分 | I14: E | K14: E
A15: 10 | D15: unit_cd | E15: #MA.UNIT_CD | G15: Unit cd. | H15: 単位ＣＤ | I15: E | K15: E
A16: 10 | D16: auto_judg_flg | E16: #MA.FLG | G16: Auto-decide | H16: 自動合否判定 | I16: E | K16: E
A17: 10 | D17: memo1 | E17: #MA.MST_MEMO1 | G17: Memo 1 | H17: メモ１ | I17: E | K17: E
A18: 10 | D18: memo2 | E18: #MA.MST_MEMO2 | G18: Memo 2 | H18: メモ２ | I18: E | K18: E
A19: 10 | D19: memo3 | E19: #MA.MST_MEMO3 | G19: Memo 3 | H19: メモ３ | I19: E | K19: E
A20: 10 | D20: del_flg | E20: #MA.FLG | G20: Logical delete | H20: 論理削除 | I20: E | K20: E
A21: 10 | D21: upd_cntr | E21: #MA.UPD_CNT | G21: Update counter | H21: 更新カウンタ | I21: E | K21: E
D22: 詳細 :

Sheet InspPointLcl_UpdChk01
A1: * | B1: * | D1: L | E1: 1
A2: * | D2: オペレーション実装仕様書 Operation Specification Implementation Sheet | E2: ModuleID : | F2: =IF(LogicCommon!C2="","",LogicCommon!C2) -> MA | G2: LogicID : | H2: =IF(LogicCommon!E2="","",LogicCommon!E2) -> MABSL0160 | I2: Ope.ID : | J2: InspPointLcl_UpdChk01 | K2: Pj.ID : | L2: =IF(LogicCommon!G2="","",LogicCommon!G2) -> MC | M2: Ope.Body : | N2: =L4 & ".Checker" -> MA.MAUDL5010.Checker
A3: * | D3: =IF(LogicCommon!A3="","",LogicCommon!A3) | E3: SubModuleID : | F3: =IF(LogicCommon!C3="","",LogicCommon!C3) -> MABS | G3: LogicClass : | H3: =IF(LogicCommon!E3="","",LogicCommon!E3) -> MABSL_InspPointReg | I3: Ope.Method : | J3: @ | K3: SuperClassPj.ID : | L3: =IF(LogicCommon!G3="","",LogicCommon!G3) | M3: ReportID : | O3: Gene.Type : | P3: ALL
A4: * | E4: Version : | F4: 000000 | G4: LogicName : | H4: =IF(LogicCommon!E4="","",LogicCommon!E4) -> 検査項目マスタ登録 | I4: Ope.Name : | J4: 登録前チェック(ロケール別情報) | K4: SuperLogicID : | L4: =IF(LogicCommon!G4="","",LogicCommon!G4) -> MA.MAUDL5010
A5: * | E5: ACType :
A6: * | D6: 概要 : | E6: 検査項目マスタ(ロケール別情報)を登録する前のチェックを行う | Q6: ID
A7: # | I7: U | K7: K | P7: o | Q7: EXISTS.chk01
A8: # | D8: ブロック名 Block Name | E8: 型 Type | G8: super/share | H8: 対象ブロック名 Target Block Name | K8: REQUIRED | P8: TargetName | Q8: DBC.MA.MAM_INSP_POINT | T8: ブロック備考 Block Remarks
A9: # | D9: 項目名 Field Name | E9: 型 Type | F9: 桁 Digits | G9: フルネーム Full Name | H9: 日本語名 Japanese Name | I9: 上り項目 Request Message Field | J9: 下り項目 Response Message Field | R9: 条件および編集方法 Conditions and Editing Methods | T9: 項目備考 Field Remarks
A10: # | P10: 上り項目 Request Message Field | Q10: 下り項目 Response Message Field
A11: 10 | B11: * | D11: InspPointLcl_UpdChk01_Dtl | E11: L | G11: $super$ | H11: DBC:MA.MAM_INSP_POINT_LCL | P11: L
A12: 10 | D12: insp_point_cd | E12: #MA.INSP_POINT_CD | G12: Inspection checkpoint cd. | H12: 検査項目ＣＤ | I12: E | K12: E | P12: E
A13: 10 | D13: lcl_cd | E13: #MA.LCL_CD | G13: Locale cd. | H13: ロケールＣＤ | I13: E | K13: E
A14: 10 | D14: insp_point_nm | E14: #MA.INSP_POINT_NM | G14: Inspection checkpoint name | H14: 検査項目名 | I14: E | K14: E
A15: 10 | D15: memo1 | E15: #MA.MST_MEMO1 | G15: Memo 1 | H15: メモ１ | I15: E
A16: 10 | D16: memo2 | E16: #MA.MST_MEMO2 | G16: Memo 2 | H16: メモ２ | I16: E
A17: 10 | D17: memo3 | E17: #MA.MST_MEMO3 | G17: Memo 3 | H17: メモ３ | I17: E
A18: 10 | D18: upd_cntr | E18: #MA.UPD_CNT | G18: Update counter | H18: 更新カウンタ | I18: E
D19: 詳細 :

Sheet InspPointLcl_Upd01
A1: * | B1: * | D1: L | E1: 1
A2: * | D2: オペレーション実装仕様書 Operation Specification Implementation Sheet | E2: ModuleID : | F2: =IF(LogicCommon!C2="","",LogicCommon!C2) -> MA | G2: LogicID : | H2: =IF(LogicCommon!E2="","",LogicCommon!E2) -> MABSL0160 | I2: Ope.ID : | J2: InspPointLcl_Upd01 | K2: Pj.ID : | L2: =IF(LogicCommon!G2="","",LogicCommon!G2) -> MC | M2: Ope.Body : | N2: "mcframe.serverMAUD.MAUDL6020.MAUDL_LCLRLUpdater"
A3: * | D3: =IF(LogicCommon!A3="","",LogicCommon!A3) | E3: SubModuleID : | F3: =IF(LogicCommon!C3="","",LogicCommon!C3) -> MABS | G3: LogicClass : | H3: =IF(LogicCommon!E3="","",LogicCommon!E3) -> MABSL_InspPointReg | I3: Ope.Method : | J3: @ | K3: SuperClassPj.ID : | L3: =IF(LogicCommon!G3="","",LogicCommon!G3) | M3: ReportID : | O3: Gene.Type : | P3: ALL
A4: * | E4: Version : | F4: 000000 | G4: LogicName : | H4: =IF(LogicCommon!E4="","",LogicCommon!E4) -> 検査項目マスタ登録 | I4: Ope.Name : | J4: 登録処理(ロケール別情報) | K4: SuperLogicID : | L4: =IF(LogicCommon!G4="","",LogicCommon!G4) -> MA.MAUDL5010
A5: * | E5: ACType :
A6: * | D6: 概要 : | E6: 検査項目マスタ(ロケール別情報)を登録する | L6: ID | N6: ID | P6: ID | R6: ID
A7: # | I7: U | K7: o | L7: UPDATE.updMaster | M7: o | N7: MAIN.chkMaster | O7: o | Q7: o
A8: # | D8: ブロック名 Block Name | E8: 型 Type | G8: super/share | H8: 対象ブロック名 Target Block Name | K8: TargetName | L8: DBC.MA.MAM_INSP_POINT_LCL | M8: TargetName | N8: DBC.MA.MAM_INSP_POINT_LCL | O8: TargetName | Q8: TargetName | U8: ブロック備考 Block Remarks
A9: # | D9: 項目名 Field Name | E9: 型 Type | F9: 桁 Digits | G9: フルネーム Full Name | H9: 日本語名 Japanese Name | I9: 上り項目 Request Message Field | J9: 下り項目 Response Message Field | S9: 条件および編集方法 Conditions and Editing Methods | U9: 項目備考 Field Remarks
A10: # | K10: 上り項目 Request Message Field | L10: 下り項目 Response Message Field | M10: 上り項目 Request Message Field | N10: 下り項目 Response Message Field | O10: 上り項目 Request Message Field | P10: 下り項目 Response Message Field | Q10: 上り項目 Request Message Field | R10: 下り項目 Response Message Field
A11: 10 | B11: * | D11: InspPointLcl_Upd01_Dtl | E11: L | G11: $share$ | H11: MA.MABSL0160.InspPointLcl_UpdChk01.InspPointLcl_UpdChk01_Dtl | K11: L | M11: L
A12: 10 | D12: insp_point_cd | E12: #MA.INSP_POINT_CD | G12: Inspection checkpoint cd. | H12: 検査項目ＣＤ | I12: E | K12: E | M12: E
A13: 10 | D13: lcl_cd | E13: #MA.LCL_CD | G13: Locale cd. | H13: ロケールＣＤ | I13: E | K13: E | M13: E
A14: 10 | D14: insp_point_nm | E14: #MA.INSP_POINT_NM | G14: Inspection checkpoint name | H14: 検査項目名 | I14: E | K14: E
A15: 10 | D15: memo1 | E15: #MA.MST_MEMO1 | G15: Memo 1 | H15: メモ１ | I15: E | K15: E
A16: 10 | D16: memo2 | E16: #MA.MST_MEMO2 | G16: Memo 2 | H16: メモ２ | I16: E | K16: E
A17: 10 | D17: memo3 | E17: #MA.MST_MEMO3 | G17: Memo 3 | H17: メモ３ | I17: E | K17: E
A18: 10 | D18: upd_cntr | E18: #MA.UPD_CNT | G18: Update counter | H18: 更新カウンタ | I18: E | K18: E
D19: 詳細 :

Sheet InspPoint_DelChk01
A1: * | B1: * | D1: L | E1: 1
A2: * | D2: オペレーション実装仕様書 Operation Specification Implementation Sheet | E2: ModuleID : | F2: =IF(LogicCommon!C2="","",LogicCommon!C2) -> MA | G2: LogicID : | H2: =IF(LogicCommon!E2="","",LogicCommon!E2) -> MABSL0160 | I2: Ope.ID : | J2: InspPoint_DelChk01 | K2: Pj.ID : | L2: =IF(LogicCommon!G2="","",LogicCommon!G2) -> MC | M2: Ope.Body : | N2: =L4 & ".Checker" -> MA.MAUDL5010.Checker
A3: * | D3: =IF(LogicCommon!A3="","",LogicCommon!A3) | E3: SubModuleID : | F3: =IF(LogicCommon!C3="","",LogicCommon!C3) -> MABS | G3: LogicClass : | H3: =IF(LogicCommon!E3="","",LogicCommon!E3) -> MABSL_InspPointReg | I3: Ope.Method : | J3: @ | K3: SuperClassPj.ID : | L3: =IF(LogicCommon!G3="","",LogicCommon!G3) | M3: ReportID : | O3: Gene.Type : | P3: ALL
A4: * | E4: Version : | F4: 000000 | G4: LogicName : | H4: =IF(LogicCommon!E4="","",LogicCommon!E4) -> 検査項目マスタ登録 | I4: Ope.Name : | J4: 削除チェック | K4: SuperLogicID : | L4: =IF(LogicCommon!G4="","",LogicCommon!G4) -> MA.MAUDL5010
A5: * | E5: ACType :
A6: * | D6: 概要 : | E6: 検査項目マスタ、検査項目マスタ(ロケール別情報)を削除する前のチェックを行う | Q6: ID
A7: # | I7: U | K7: K | P7: o
A8: # | D8: ブロック名 Block Name | E8: 型 Type | G8: super/share | H8: 対象ブロック名 Target Block Name | K8: REQUIRED | P8: TargetName | T8: ブロック備考 Block Remarks
A9: # | D9: 項目名 Field Name | E9: 型 Type | F9: 桁 Digits | G9: フルネーム Full Name | H9: 日本語名 Japanese Name | I9: 上り項目 Request Message Field | J9: 下り項目 Response Message Field | R9: 条件および編集方法 Conditions and Editing Methods | T9: 項目備考 Field Remarks
A10: # | P10: 上り項目 Request Message Field | Q10: 下り項目 Response Message Field
A11: 10 | B11: * | D11: InspPoint_DelChk01_Dtl | E11: L
A12: 10 | D12: insp_point_cd | E12: #MA.INSP_POINT_CD | G12: Inspection checkpoint cd. | H12: 検査項目ＣＤ | I12: E | K12: E
A13: 10 | D13: upd_cntr | E13: #MA.UPD_CNT | G13: Update counter | H13: 更新カウンタ | I13: E
D14: 詳細 :

Sheet InspPoint_Del01
A1: * | B1: * | D1: L | E1: 1
A2: * | D2: オペレーション実装仕様書 Operation Specification Implementation Sheet | E2: ModuleID : | F2: =IF(LogicCommon!C2="","",LogicCommon!C2) -> MA | G2: LogicID : | H2: =IF(LogicCommon!E2="","",LogicCommon!E2) -> MABSL0160 | I2: Ope.ID : | J2: InspPoint_Del01 | K2: Pj.ID : | L2: =IF(LogicCommon!G2="","",LogicCommon!G2) -> MC | M2: Ope.Body : | N2: "mcframe.serverMAUD.MAUDL6020.MAUDL_LCLRLDeleter"
A3: * | D3: =IF(LogicCommon!A3="","",LogicCommon!A3) | E3: SubModuleID : | F3: =IF(LogicCommon!C3="","",LogicCommon!C3) -> MABS | G3: LogicClass : | H3: =IF(LogicCommon!E3="","",LogicCommon!E3) -> MABSL_InspPointReg | I3: Ope.Method : | J3: @ | K3: SuperClassPj.ID : | L3: =IF(LogicCommon!G3="","",LogicCommon!G3) | M3: ReportID : | O3: Gene.Type : | P3: ALL
A4: * | E4: Version : | F4: 000000 | G4: LogicName : | H4: =IF(LogicCommon!E4="","",LogicCommon!E4) -> 検査項目マスタ登録 | I4: Ope.Name : | J4: 削除処理 | K4: SuperLogicID : | L4: =IF(LogicCommon!G4="","",LogicCommon!G4) -> MA.MAUDL5010
A5: * | E5: ACType :
A6: * | D6: 概要 : | E6: 検査項目マスタ、検査項目マスタ(ロケール別情報)を削除する | L6: ID | N6: ID
A7: # | I7: U | K7: o | L7: UPDATE.updMaster1 | M7: o | N7: UPDATE.updMaster2
A8: # | D8: ブロック名 Block Name | E8: 型 Type | G8: super/share | H8: 対象ブロック名 Target Block Name | K8: TargetName | L8: DBC.MA.MAM_INSP_POINT | M8: TargetName | N8: DBC.MA.MAM_INSP_POINT_LCL | Q8: ブロック備考 Block Remarks
A9: # | D9: 項目名 Field Name | E9: 型 Type | F9: 桁 Digits | G9: フルネーム Full Name | H9: 日本語名 Japanese Name | I9: 上り項目 Request Message Field | J9: 下り項目 Response Message Field | O9: 条件および編集方法 Conditions and Editing Methods | Q9: 項目備考 Field Remarks
A10: # | K10: 上り項目 Request Message Field | L10: 下り項目 Response Message Field | M10: 上り項目 Request Message Field | N10: 下り項目 Response Message Field
A11: 10 | B11: * | D11: InspPoint_Del01_Dtl | E11: L | G11: $share$ | H11: MA.MABSL0160.InspPoint_DelChk01.InspPoint_DelChk01_Dtl | K11: L | M11: L
A12: 10 | D12: insp_point_cd | E12: #MA.INSP_POINT_CD | G12: Inspection checkpoint cd. | H12: 検査項目ＣＤ | I12: E | K12: E | M12: E
A13: 10 | D13: upd_cntr | E13: #MA.UPD_CNT | G13: Update counter | H13: 更新カウンタ | I13: E | K13: E
D14: 詳細 :

Sheet Srch01
A1: * | B1: * | D1: L | E1: 1
A2: * | D2: オペレーション実装仕様書 Operation Specification Implementation Sheet | E2: ModuleID : | F2: =IF(LogicCommon!C2="","",LogicCommon!C2) -> MA | G2: LogicID : | H2: =IF(LogicCommon!E2="","",LogicCommon!E2) -> MABSL0160 | I2: Ope.ID : | J2: Srch01 | K2: Pj.ID : | L2: =IF(LogicCommon!G2="","",LogicCommon!G2) -> MC | M2: Ope.Body : | N2: "mcframe.serverMAUD.MAUDL6020.MAUDL_LCLRLSearcher"
A3: * | D3: =IF(LogicCommon!A3="","",LogicCommon!A3) | E3: SubModuleID : | F3: =IF(LogicCommon!C3="","",LogicCommon!C3) -> MABS | G3: LogicClass : | H3: =IF(LogicCommon!E3="","",LogicCommon!E3) -> MABSL_InspPointReg | I3: Ope.Method : | J3: @ | K3: SuperClassPj.ID : | L3: =IF(LogicCommon!G3="","",LogicCommon!G3) | M3: ReportID : | O3: Gene.Type : | P3: ALL
A4: * | E4: Version : | F4: 000000 | G4: LogicName : | H4: =IF(LogicCommon!E4="","",LogicCommon!E4) -> 検査項目マスタ登録 | I4: Ope.Name : | J4: 検索 | K4: SuperLogicID : | L4: =IF(LogicCommon!G4="","",LogicCommon!G4) -> MA.MAUDL5010
A5: * | E5: ACType :
A6: * | D6: 概要 : | E6: 検索処理を行う | M6: ID | O6: ID
A7: # | I7: U | K7: K | L7: o | M7: SELECT.c0 | N7: o | O7: SELECT_LCL.c1
A8: # | D8: ブロック名 Block Name | E8: 型 Type | G8: super/share | H8: 対象ブロック名 Target Block Name | K8: CONST | L8: TargetName | M8: DBC.MA.MAM_INSP_POINT | N8: TargetName | O8: DBC.MA.MAM_INSP_POINT_LCL | R8: ブロック備考 Block Remarks
A9: # | D9: 項目名 Field Name | E9: 型 Type | F9: 桁 Digits | G9: フルネーム Full Name | H9: 日本語名 Japanese Name | I9: 上り項目 Request Message Field | J9: 下り項目 Response Message Field | P9: 条件および編集方法 Conditions and Editing Methods | R9: 項目備考 Field Remarks
A10: # | L10: 上り項目 Request Message Field | M10: 下り項目 Response Message Field | N10: 上り項目 Request Message Field | O10: 下り項目 Response Message Field
A11: 10 | B11: * | D11: Srch01_Cnd | E11: R | L11: R
A12: 10 | D12: insp_point_cd | E12: #MA.INSP_POINT_CD | G12: Inspection checkpoint cd. | H12: 検査項目ＣＤ | I12: E
A13: 10 | D13: insp_point_nm_lcl | E13: #MA.INSP_POINT_NM | G13: Inspection checkpoint name | H13: 検査項目名 | I13: E
A14: 10 | D14: insp_qlqn_typ | E14: #MA.INSP_QLQN_TYP | G14: Qualitative/quantitative type | H14: 定性定量区分 | I14: E
A15: 10 | D15: off_del_flg | E15: #MA.FLG | G15: Logical delete. Off | H15: 論理削除.オフ | I15: E
A16: 10 | D16: on_del_flg | E16: #MA.FLG | G16: Logical delete. On | H16: 論理削除.オン | I16: E
A17: 10 | D17: memo1 | E17: #MA.MST_MEMO1 | G17: Memo 1 | H17: メモ１ | I17: E
A18: 10 | D18: memo2 | E18: #MA.MST_MEMO2 | G18: Memo 2 | H18: メモ２ | I18: E
A19: 10 | D19: memo3 | E19: #MA.MST_MEMO3 | G19: Memo 3 | H19: メモ３ | I19: E
A21: 20 | B21: * | D21: Srch01_Rslt1 | E21: L | M21: L
A22: 20 | D22: del_flg | E22: #MA.FLG | G22: Logical delete | H22: 論理削除 | J22: E | M22: E
A23: 20 | D23: insp_point_cd | E23: #MA.INSP_POINT_CD | G23: Inspection checkpoint cd. | H23: 検査項目ＣＤ | J23: E | M23: E
A24: 20 | D24: insp_point_nm_lcl | E24: #MA.INSP_POINT_NM | G24: Inspection checkpoint name | H24: 検査項目名 | J24: E | M24: insp_point_nm
A25: 20 | D25: insp_point_nm | E25: #MA.INSP_POINT_NM | G25: Standard inspection checkpoint name | H25: 標準検査項目名 | J25: E | M25: base_insp_point_nm
A26: 20 | D26: insp_qlqn_typ | E26: #MA.INSP_QLQN_TYP | G26: Qualitative/quantitative type | H26: 定性定量区分 | J26: E | K26: MAC_INSP_QLQN_TYP | M26: E
A27: 20 | D27: insp_qlqn_typ_nm | E27: #MA.INSP_QLQN_TYP_NM | G27: Qualitative/quantitative type name | H27: 定性定量区分名 | J27: E
A28: 20 | D28: unit_cd | E28: #MA.UNIT_CD | G28: Unit cd. | H28: 単位ＣＤ | J28: E | M28: E
A29: 20 | D29: unit_nm | E29: #MA.UNIT_NM | G29: Unit name | H29: 単位名 | J29: E | M29: E
A30: 20 | D30: auto_judg_flg | E30: #MA.FLG | G30: Auto-decide | H30: 自動合否判定 | J30: E | M30: E
A31: 20 | D31: memo1 | E31: #MA.MST_MEMO1 | G31: Memo 1 | H31: メモ１ | J31: E | M31: E
A32: 20 | D32: memo2 | E32: #MA.MST_MEMO2 | G32: Memo 2 | H32: メモ２ | J32: E | M32: E
A33: 20 | D33: memo3 | E33: #MA.MST_MEMO3 | G33: Memo 3 | H33: メモ３ | J33: E | M33: E
A34: 20 | D34: ins_usr_id | E34: #MA.FCM_USR_ID | G34: Entry user ID | H34: 登録ユーザＩＤ | J34: E | M34: E
A35: 20 | D35: ins_usr_nm | E35: #MA.FCM_USR_NM | G35: Entry user name | H35: 登録ユーザ名 | J35: E | M35: E
A36: 20 | D36: ins_ts | E36: #MA.SYS_TS | G36: Entry date and time | H36: 登録日時 | J36: E | M36: E
A37: 20 | D37: ins_func_id | E37: #MA.FUNC_ID | G37: Entry function ID | H37: 登録機能ＩＤ | J37: E | M37: E
A38: 20 | D38: ins_func_nm | E38: #MA.FUNC_NM | G38: Entry function name | H38: 登録機能名 | J38: E
A39: 20 | D39: upd_cntr | E39: #MA.UPD_CNT | G39: Update counter | H39: 更新カウンタ | J39: E | M39: E
A40: 20 | D40: upd_usr_id | E40: #MA.FCM_USR_ID | G40: Update user ID | H40: 更新ユーザＩＤ | J40: E | M40: E
A41: 20 | D41: upd_usr_nm | E41: #MA.FCM_USR_NM | G41: Update user name | H41: 更新ユーザ名 | J41: E | M41: E
...

Sheet Upd01
A1: * | B1: * | D1: L | E1: 1
A2: * | D2: オペレーション実装仕様書 Operation Specification Implementation Sheet | E2: ModuleID : | F2: =IF(LogicCommon!C2="","",LogicCommon!C2) -> MA | G2: LogicID : | H2: =IF(LogicCommon!E2="","",LogicCommon!E2) -> MABSL0160 | I2: Ope.ID : | J2: Upd01 | K2: Pj.ID : | L2: =IF(LogicCommon!G2="","",LogicCommon!G2) -> MC | M2: Ope.Body : | N2: "mcframe.serverMAUD.MAUDL6020.MAUDL_LCLRLUpdater"
A3: * | D3: =IF(LogicCommon!A3="","",LogicCommon!A3) | E3: SubModuleID : | F3: =IF(LogicCommon!C3="","",LogicCommon!C3) -> MABS | G3: LogicClass : | H3: =IF(LogicCommon!E3="","",LogicCommon!E3) -> MABSL_InspPointReg | I3: Ope.Method : | J3: @ | K3: SuperClassPj.ID : | L3: =IF(LogicCommon!G3="","",LogicCommon!G3) | M3: ReportID : | O3: Gene.Type : | P3: ALL
A4: * | E4: Version : | F4: 000000 | G4: LogicName : | H4: =IF(LogicCommon!E4="","",LogicCommon!E4) -> 検査項目マスタ登録 | I4: Ope.Name : | J4: 登録 | K4: SuperLogicID : | L4: =IF(LogicCommon!G4="","",LogicCommon!G4) -> MA.MAUDL5010
A5: * | E5: ACType :
A6: * | D6: 概要 : | E6: 登録処理を行う | L6: ID | N6: ID | P6: ID | R6: ID
A7: # | I7: U | K7: o | L7: CALL_OPE01.chk01 | M7: o | N7: CALL_OPE01.upd01 | O7: o | P7: CALL_OPE02.chk02 | Q7: o | R7: CALL_OPE02.upd02
A8: # | D8: ブロック名 Block Name | E8: 型 Type | G8: super/share | H8: 対象ブロック名 Target Block Name | K8: TargetName | L8: OPE.MA.MABSL0160.InspPoint_UpdChk01 | M8: TargetName | N8: OPE.MA.MABSL0160.InspPoint_Upd01 | O8: TargetName | P8: OPE.MA.MABSL0160.InspPointLcl_UpdChk01 | Q8: TargetName | R8: OPE.MA.MABSL0160.InspPointLcl_Upd01 | U8: ブロック備考 Block Remarks
A9: # | D9: 項目名 Field Name | E9: 型 Type | F9: 桁 Digits | G9: フルネーム Full Name | H9: 日本語名 Japanese Name | I9: 上り項目 Request Message Field | J9: 下り項目 Response Message Field | S9: 条件および編集方法 Conditions and Editing Methods | U9: 項目備考 Field Remarks
A10: # | K10: 上り項目 Request Message Field | L10: 下り項目 Response Message Field | M10: 上り項目 Request Message Field | N10: 下り項目 Response Message Field | O10: 上り項目 Request Message Field | P10: 下り項目 Response Message Field | Q10: 上り項目 Request Message Field | R10: 下り項目 Response Message Field
A11: 10 | B11: * | D11: Upd01_Dtl1 | E11: L | G11: $share$ | H11: MA.MABSL0160.InspPoint_Upd01.InspPoint_Upd01_Dtl | K11: InspPoint_UpdChk01_Dtl | M11: InspPoint_Upd01_Dtl
A12: 10 | D12: insp_point_cd | E12: #MA.INSP_POINT_CD | G12: Inspection checkpoint cd. | H12: 検査項目ＣＤ | I12: E | K12: E | M12: E
A13: 10 | D13: insp_point_nm | E13: #MA.INSP_POINT_NM | G13: Inspection checkpoint name | H13: 検査項目名 | I13: E | K13: E | M13: E
A14: 10 | D14: insp_qlqn_typ | E14: #MA.INSP_QLQN_TYP | G14: Qualitative/quantitative type | H14: 定性定量区分 | I14: E | K14: E | M14: E
A15: 10 | D15: unit_cd | E15: #MA.UNIT_CD | G15: Unit cd. | H15: 単位ＣＤ | I15: E | K15: E | M15: E
A16: 10 | D16: auto_judg_flg | E16: #MA.FLG | G16: Auto-decide | H16: 自動合否判定 | I16: E | K16: E | M16: E
A17: 10 | D17: memo1 | E17: #MA.MST_MEMO1 | G17: Memo 1 | H17: メモ１ | I17: E | K17: E | M17: E
A18: 10 | D18: memo2 | E18: #MA.MST_MEMO2 | G18: Memo 2 | H18: メモ２ | I18: E | K18: E | M18: E
A19: 10 | D19: memo3 | E19: #MA.MST_MEMO3 | G19: Memo 3 | H19: メモ３ | I19: E | K19: E | M19: E
A20: 10 | D20: del_flg | E20: #MA.FLG | G20: Logical delete | H20: 論理削除 | I20: E | K20: E | M20: E
A21: 10 | D21: upd_cntr | E21: #MA.UPD_CNT | G21: Update counter | H21: 更新カウンタ | I21: E | K21: E | M21: E
A23: 20 | B23: * | D23: Upd01_Dtl2 | E23: L | G23: $share$ | H23: MA.MABSL0160.InspPointLcl_Upd01.InspPointLcl_Upd01_Dtl | O23: InspPointLcl_UpdChk01_Dtl | Q23: InspPointLcl_Upd01_Dtl
A24: 20 | D24: insp_point_cd | E24: #MA.INSP_POINT_CD | G24: Inspection checkpoint cd. | H24: 検査項目ＣＤ | I24: E | O24: E | Q24: E
A25: 20 | D25: lcl_cd | E25: #MA.LCL_CD | G25: Locale cd. | H25: ロケールＣＤ | I25: E | O25: E | Q25: E
A26: 20 | D26: insp_point_nm | E26: #MA.INSP_POINT_NM | G26: Inspection checkpoint name | H26: 検査項目名 | I26: E | O26: E | Q26: E
A27: 20 | D27: memo1 | E27: #MA.MST_MEMO1 | G27: Memo 1 | H27: メモ１ | I27: E | O27: E | Q27: E
A28: 20 | D28: memo2 | E28: #MA.MST_MEMO2 | G28: Memo 2 | H28: メモ２ | I28: E | O28: E | Q28: E
A29: 20 | D29: memo3 | E29: #MA.MST_MEMO3 | G29: Memo 3 | H29: メモ３ | I29: E | O29: E | Q29: E
A30: 20 | D30: upd_cntr | E30: #MA.UPD_CNT | G30: Update counter | H30: 更新カウンタ | I30: E | O30: E | Q30: E
D31: 詳細 :

Sheet Del01
A1: * | B1: * | D1: L | E1: 1
A2: * | D2: オペレーション実装仕様書 Operation Specification Implementation Sheet | E2: ModuleID : | F2: =IF(LogicCommon!C2="","",LogicCommon!C2) -> MA | G2: LogicID : | H2: =IF(LogicCommon!E2="","",LogicCommon!E2) -> MABSL0160 | I2: Ope.ID : | J2: Del01 | K2: Pj.ID : | L2: =IF(LogicCommon!G2="","",LogicCommon!G2) -> MC | M2: Ope.Body : | N2: "mcframe.serverMAUD.MAUDL6020.MAUDL_LCLRLDeleter"
A3: * | D3: =IF(LogicCommon!A3="","",LogicCommon!A3) | E3: SubModuleID : | F3: =IF(LogicCommon!C3="","",LogicCommon!C3) -> MABS | G3: LogicClass : | H3: =IF(LogicCommon!E3="","",LogicCommon!E3) -> MABSL_InspPointReg | I3: Ope.Method : | J3: @ | K3: SuperClassPj.ID : | L3: =IF(LogicCommon!G3="","",LogicCommon!G3) | M3: ReportID : | O3: Gene.Type : | P3: ALL
A4: * | E4: Version : | F4: 000000 | G4: LogicName : | H4: =IF(LogicCommon!E4="","",LogicCommon!E4) -> 検査項目マスタ登録 | I4: Ope.Name : | J4: 削除 | K4: SuperLogicID : | L4: =IF(LogicCommon!G4="","",LogicCommon!G4) -> MA.MAUDL5010
A5: * | E5: ACType :
A6: * | D6: 概要 : | E6: 削除処理を行う | L6: ID | N6: ID
A7: # | I7: U | K7: o | L7: CALL_OPE01.chk01 | M7: o | N7: CALL_OPE01.del01
A8: # | D8: ブロック名 Block Name | E8: 型 Type | G8: super/share | H8: 対象ブロック名 Target Block Name | K8: TargetName | L8: OPE.MA.MABSL0160.InspPoint_DelChk01 | M8: TargetName | N8: OPE.MA.MABSL0160.InspPoint_Del01 | Q8: ブロック備考 Block Remarks
A9: # | D9: 項目名 Field Name | E9: 型 Type | F9: 桁 Digits | G9: フルネーム Full Name | H9: 日本語名 Japanese Name | I9: 上り項目 Request Message Field | J9: 下り項目 Response Message Field | O9: 条件および編集方法 Conditions and Editing Methods | Q9: 項目備考 Field Remarks
A10: # | K10: 上り項目 Request Message Field | L10: 下り項目 Response Message Field | M10: 上り項目 Request Message Field | N10: 下り項目 Response Message Field
A11: 10 | B11: * | D11: Del01_Dtl1 | E11: L | G11: $share$ | H11: MA.MABSL0160.InspPoint_Del01.InspPoint_Del01_Dtl | K11: InspPoint_DelChk01_Dtl | M11: InspPoint_Del01_Dtl
A12: 10 | D12: insp_point_cd | E12: #MA.INSP_POINT_CD | G12: Inspection checkpoint cd. | H12: 検査項目ＣＤ | I12: E | K12: E | M12: E
A13: 10 | D13: upd_cntr | E13: #MA.UPD_CNT | G13: Update counter | H13: 更新カウンタ | I13: E | K13: E | M13: E
D14: 詳細 :

Sheet 来歴
A1: 変更来歴
A3: Rev. | H3: 修正番号 | O3: 変更内容 | AQ3: 変更箇所
A4: 1 | O4: 初版
A5: 1.1 | O5: 英語の名称を追記 | AQ5: 全般
