Workbook

Sheet LogicCommon
A2: ロジック共通定義 | B2: ModuleID : | C2: MA | D2: LogicID : | E2: MABSL1030 | F2: Pj.ID : | G2: MC
B3: SubModuleID : | C3: MABS | D3: LogicClass : | E3: MABSL_ComPaidReg | F3: SuperClassPj.ID :
D4: LogicName : | E4: 振込手数料マスタ登録 | F4: SuperLogicID : | G4: MA.MAUDL5010
A5: 概要 :
A6: 詳細 :

Sheet ComPaid_UpdChk01
A1: * | B1: * | D1: L | E1: 1
A2: * | D2: オペレーション実装仕様書 Operation Specification Implementation Sheet | E2: ModuleID : | F2: =IF(LogicCommon!C2="","",LogicCommon!C2) -> MA | G2: LogicID : | H2: =IF(LogicCommon!E2="","",LogicCommon!E2) -> MABSL1030 | I2: Ope.ID : | J2: ComPaid_UpdChk01 | K2: Pj.ID : | L2: =IF(LogicCommon!G2="","",LogicCommon!G2) -> MC | M2: Ope.Body : | N2: =L4 & ".Checker" -> MA.MAUDL5010.Checker
A3: * | D3: =IF(LogicCommon!A3="","",LogicCommon!A3) | E3: SubModuleID : | F3: =IF(LogicCommon!C3="","",LogicCommon!C3) -> MABS | G3: LogicClass : | H3: =IF(LogicCommon!E3="","",LogicCommon!E3) -> MABSL_ComPaidReg | I3: Ope.Method : | J3: @ | K3: SuperClassPj.ID : | L3: =IF(LogicCommon!G3="","",LogicCommon!G3) | M3: ReportID : | O3: Gene.Type : | P3: ALL
A4: * | E4: Version : | F4: 000000 | G4: LogicName : | H4: =IF(LogicCommon!E4="","",LogicCommon!E4) -> 振込手数料マスタ登録 | I4: Ope.Name : | J4: 登録前チェック | K4: SuperLogicID : | L4: =IF(LogicCommon!G4="","",LogicCommon!G4) -> MA.MAUDL5010
A5: * | E5: ACType :
A6: * | D6: 概要 : | E6: 振込手数料マスタを登録する前のチェックをする | T6: ID
A7: # | I7: U | K7: K | L7: K | M7: K | N7: K | O7: K | P7: K | Q7: K | R7: K | S7: o
A8: # | D8: ブロック名 Block Name | E8: 型 Type | G8: super/share | H8: 対象ブロック名 Target Block Name | K8: REQUIRED | L8: CHK_NUM | M8: SMALL_LARGE | N8: LIST_LOGIC | O8: LIST_OUT | P8: LIST_OUT_BASE | Q8: LIST_IN | R8: LIST_IN_BASE | S8: TargetName | W8: ブロック備考 Block Remarks
A9: # | D9: 項目名 Field Name | E9: 型 Type | F9: 桁 Digits | G9: フルネーム Full Name | H9: 日本語名 Japanese Name | I9: 上り項目 Request Message Field | J9: 下り項目 Response Message Field | U9: 条件および編集方法 Conditions and Editing Methods | W9: 項目備考 Field Remarks
A10: # | S10: 上り項目 Request Message Field | T10: 下り項目 Response Message Field
A11: 10 | B11: * | D11: ComPaid_UpdChk01_Dtl | E11: L | G11: $super$ | H11: DBC:MA.MAM_COM_PAID
A12: 10 | D12: cur_cd | E12: #MA.CUR_CD | G12: Currency cd. | H12: 通貨ＣＤ | I12: E | K12: E | N12: MA.MAUAL0010.Cur | O12: amt_dec_place | P12: amt_dec_place
A13: 10 | D13: amt_dec_place | E13: #MA.DEC_PLACE | G13: Amount number of decimal places | H13: 金額小数部有効桁数
A14: 10 | D14: min_amt | E14: #MA.MONEY | G14: Min. amount | H14: 下限金額 | I14: E | M14: E1:S,0:
A15: 10 | D15: max_amt | E15: #MA.MONEY | G15: Max. amount | H15: 上限金額 | I15: E | M15: E1:L,0:
A16: 10 | D16: rcst_cd | E16: #MA.BP_CD | G16: Payer cd. | H16: 入金先ＣＤ | I16: E | N16: MA.MAUAL0010.Bp | Q16: MAC_BP_IS_SRCH_TYP.RCST | R16: bp_is_srch_typ
A17: 10 | D17: com_paid | E17: #MA.MONEY | G17: Transfer fee | H17: 振込手数料 | I17: E | K17: E | L17: positive
A18: 10 | D18: memo1 | E18: #MA.MST_MEMO1 | G18: Memo 1 | H18: メモ１ | I18: E
A19: 10 | D19: memo2 | E19: #MA.MST_MEMO2 | G19: Memo 2 | H19: メモ２ | I19: E
A20: 10 | D20: memo3 | E20: #MA.MST_MEMO3 | G20: Memo 3 | H20: メモ３ | I20: E
A21: 10 | D21: del_flg | E21: #MA.FLG | G21: Logical delete | H21: 論理削除 | I21: E
A22: 10 | D22: upd_cntr | E22: #MA.UPD_CNT | G22: Update counter | H22: 更新カウンタ | I22: E
D23: 詳細 :

Sheet ComPaid_Upd01
A1: * | B1: * | D1: L | E1: 1
A2: * | D2: オペレーション実装仕様書 Operation Specification Implementation Sheet | E2: ModuleID : | F2: =IF(LogicCommon!C2="","",LogicCommon!C2) -> MA | G2: LogicID : | H2: =IF(LogicCommon!E2="","",LogicCommon!E2) -> MABSL1030 | I2: Ope.ID : | J2: ComPaid_Upd01 | K2: Pj.ID : | L2: =IF(LogicCommon!G2="","",LogicCommon!G2) -> MC | M2: Ope.Body : | N2: "mcframe.serverMAUD.MAUDL6010.MAUDL_RLUpdater"
A3: * | D3: =IF(LogicCommon!A3="","",LogicCommon!A3) | E3: SubModuleID : | F3: =IF(LogicCommon!C3="","",LogicCommon!C3) -> MABS | G3: LogicClass : | H3: =IF(LogicCommon!E3="","",LogicCommon!E3) -> MABSL_ComPaidReg | I3: Ope.Method : | J3: @ | K3: SuperClassPj.ID : | L3: =IF(LogicCommon!G3="","",LogicCommon!G3) | M3: ReportID : | O3: Gene.Type : | P3: ALL
A4: * | E4: Version : | F4: 000000 | G4: LogicName : | H4: =IF(LogicCommon!E4="","",LogicCommon!E4) -> 振込手数料マスタ登録 | I4: Ope.Name : | J4: 登録処理 | K4: SuperLogicID : | L4: =IF(LogicCommon!G4="","",LogicCommon!G4) -> MA.MAUDL5010
A5: * | E5: ACType :
A6: * | D6: 概要 : | E6: 振込手数料マスタを登録する | L6: ID | N6: ID | P6: ID | R6: ID
A7: # | I7: U | K7: o | L7: UPDATE.updMaster | M7: o | N7: MAIN.chkMaster | O7: o | Q7: o
A8: # | D8: ブロック名 Block Name | E8: 型 Type | G8: super/share | H8: 対象ブロック名 Target Block Name | K8: TargetName | L8: DBC.MA.MAM_COM_PAID | M8: TargetName | N8: DBC.MA.MAM_COM_PAID | O8: TargetName | Q8: TargetName | U8: ブロック備考 Block Remarks
A9: # | D9: 項目名 Field Name | E9: 型 Type | F9: 桁 Digits | G9: フルネーム Full Name | H9: 日本語名 Japanese Name | I9: 上り項目 Request Message Field | J9: 下り項目 Response Message Field | S9: 条件および編集方法 Conditions and Editing Methods | U9: 項目備考 Field Remarks
A10: # | K10: 上り項目 Request Message Field | L10: 下り項目 Response Message Field | M10: 上り項目 Request Message Field | N10: 下り項目 Response Message Field | O10: 上り項目 Request Message Field | P10: 下り項目 Response Message Field | Q10: 上り項目 Request Message Field | R10: 下り項目 Response Message Field
A11: 10 | B11: * | D11: ComPaid_Upd01_Dtl | E11: L | G11: $share$ | H11: MA.MABSL1030.ComPaid_UpdChk01.ComPaid_UpdChk01_Dtl | K11: L | M11: L
A12: 10 | D12: cur_cd | E12: #MA.CUR_CD | G12: Currency cd. | H12: 通貨ＣＤ | I12: E | K12: E | M12: E
A13: 10 | D13: min_amt | E13: #MA.MONEY | G13: Min. amount | H13: 下限金額 | I13: E | K13: E | M13: E
A14: 10 | D14: max_amt | E14: #MA.MONEY | G14: Max. amount | H14: 上限金額 | I14: E | K14: E | M14: E
A15: 10 | D15: rcst_cd | E15: #MA.BP_CD | G15: Payer cd. | H15: 入金先ＣＤ | I15: E | K15: E | M15: E
A16: 10 | D16: com_paid | E16: #MA.MONEY | G16: Transfer fee | H16: 振込手数料 | I16: E | K16: E | M16: E
A17: 10 | D17: memo1 | E17: #MA.MST_MEMO1 | G17: Memo 1 | H17: メモ１ | I17: E | K17: E
A18: 10 | D18: memo2 | E18: #MA.MST_MEMO2 | G18: Memo 2 | H18: メモ２ | I18: E | K18: E
A19: 10 | D19: memo3 | E19: #MA.MST_MEMO3 | G19: Memo 3 | H19: メモ３ | I19: E | K19: E
A20: 10 | D20: del_flg | E20: #MA.FLG | G20: Logical delete | H20: 論理削除 | I20: E | K20: E
A21: 10 | D21: upd_cntr | E21: #MA.UPD_CNT | G21: Update counter | H21: 更新カウンタ | I21: E | K21: E
D22: 詳細 :

Sheet ComPaid_DelChk01
A1: * | B1: * | D1: L | E1: 1
A2: * | D2: オペレーション実装仕様書 Operation Specification Implementation Sheet | E2: ModuleID : | F2: =IF(LogicCommon!C2="","",LogicCommon!C2) -> MA | G2: LogicID : | H2: =IF(LogicCommon!E2="","",LogicCommon!E2) -> MABSL1030 | I2: Ope.ID : | J2: ComPaid_DelChk01 | K2: Pj.ID : | L2: =IF(LogicCommon!G2="","",LogicCommon!G2) -> MC | M2: Ope.Body : | N2: =L4 & ".Checker" -> MA.MAUDL5010.Checker
A3: * | D3: =IF(LogicCommon!A3="","",LogicCommon!A3) | E3: SubModuleID : | F3: =IF(LogicCommon!C3="","",LogicCommon!C3) -> MABS | G3: LogicClass : | H3: =IF(LogicCommon!E3="","",LogicCommon!E3) -> MABSL_ComPaidReg | I3: Ope.Method : | J3: @ | K3: SuperClassPj.ID : | L3: =IF(LogicCommon!G3="","",LogicCommon!G3) | M3: ReportID : | O3: Gene.Type : | P3: ALL
A4: * | E4: Version : | F4: 000000 | G4: LogicName : | H4: =IF(LogicCommon!E4="","",LogicCommon!E4) -> 振込手数料マスタ登録 | I4: Ope.Name : | J4: 削除前チェック | K4: SuperLogicID : | L4: =IF(LogicCommon!G4="","",LogicCommon!G4) -> MA.MAUDL5010
A5: * | E5: ACType :
A6: * | D6: 概要 : | E6: 振込手数料マスタを削除する前のチェックをする | Q6: ID
A7: # | I7: U | K7: K | P7: o
A8: # | D8: ブロック名 Block Name | E8: 型 Type | G8: super/share | H8: 対象ブロック名 Target Block Name | K8: REQUIRED | P8: TargetName | T8: ブロック備考 Block Remarks
A9: # | D9: 項目名 Field Name | E9: 型 Type | F9: 桁 Digits | G9: フルネーム Full Name | H9: 日本語名 Japanese Name | I9: 上り項目 Request Message Field | J9: 下り項目 Response Message Field | R9: 条件および編集方法 Conditions and Editing Methods | T9: 項目備考 Field Remarks
A10: # | P10: 上り項目 Request Message Field | Q10: 下り項目 Response Message Field
A11: 10 | B11: * | D11: ComPaid_DelChk01_Dtl | E11: L | G11: $super$ | H11: DBC:MA.MAM_COM_PAID
A12: 10 | D12: cur_cd | E12: #MA.CUR_CD | G12: Currency cd. | H12: 通貨ＣＤ | I12: E | K12: E
A13: 10 | D13: min_amt | E13: #MA.MONEY | G13: Min. amount | H13: 下限金額 | I13: E
A14: 10 | D14: max_amt | E14: #MA.MONEY | G14: Max. amount | H14: 上限金額 | I14: E
A15: 10 | D15: rcst_cd | E15: #MA.BP_CD | G15: Payer cd. | H15: 入金先ＣＤ | I15: E
A16: 10 | D16: com_paid | E16: #MA.MONEY | G16: Transfer fee | H16: 振込手数料 | I16: E | K16: E
A17: 10 | D17: upd_cntr | E17: #MA.UPD_CNT | G17: Update counter | H17: 更新カウンタ | I17: E
D18: 詳細 :

Sheet ComPaid_Del01
A1: * | B1: * | D1: L | E1: 1
A2: * | D2: オペレーション実装仕様書 Operation Specification Implementation Sheet | E2: ModuleID : | F2: =IF(LogicCommon!C2="","",LogicCommon!C2) -> MA | G2: LogicID : | H2: =IF(LogicCommon!E2="","",LogicCommon!E2) -> MABSL1030 | I2: Ope.ID : | J2: ComPaid_Del01 | K2: Pj.ID : | L2: =IF(LogicCommon!G2="","",LogicCommon!G2) -> MC | M2: Ope.Body : | N2: "mcframe.serverMAUD.MAUDL6010.MAUDL_RLDeleter"
A3: * | D3: =IF(LogicCommon!A3="","",LogicCommon!A3) | E3: SubModuleID : | F3: =IF(LogicCommon!C3="","",LogicCommon!C3) -> MABS | G3: LogicClass : | H3: =IF(LogicCommon!E3="","",LogicCommon!E3) -> MABSL_ComPaidReg | I3: Ope.Method : | J3: @ | K3: SuperClassPj.ID : | L3: =IF(LogicCommon!G3="","",LogicCommon!G3) | M3: ReportID : | O3: Gene.Type : | P3: ALL
A4: * | E4: Version : | F4: 000000 | G4: LogicName : | H4: =IF(LogicCommon!E4="","",LogicCommon!E4) -> 振込手数料マスタ登録 | I4: Ope.Name : | J4: 削除処理 | K4: SuperLogicID : | L4: =IF(LogicCommon!G4="","",LogicCommon!G4) -> MA.MAUDL5010
A5: * | E5: ACType :
A6: * | D6: 概要 : | E6: 振込手数料マスタを削除する | L6: ID | N6: ID
A7: # | I7: U | K7: o | L7: UPDATE.updMaster1 | M7: o
A8: # | D8: ブロック名 Block Name | E8: 型 Type | G8: super/share | H8: 対象ブロック名 Target Block Name | K8: TargetName | L8: DBC.MA.MAM_COM_PAID | M8: TargetName | Q8: ブロック備考 Block Remarks
A9: # | D9: 項目名 Field Name | E9: 型 Type | F9: 桁 Digits | G9: フルネーム Full Name | H9: 日本語名 Japanese Name | I9: 上り項目 Request Message Field | J9: 下り項目 Response Message Field | O9: 条件および編集方法 Conditions and Editing Methods | Q9: 項目備考 Field Remarks
A10: # | K10: 上り項目 Request Message Field | L10: 下り項目 Response Message Field | M10: 上り項目 Request Message Field | N10: 下り項目 Response Message Field
A11: 10 | B11: * | D11: ComPaid_Del01_Dtl | E11: L | G11: $share$ | H11: MA.MABSL1030.ComPaid_DelChk01.ComPaid_DelChk01_Dtl | K11: L
A12: 10 | D12: cur_cd | E12: #MA.CUR_CD | G12: Currency cd. | H12: 通貨ＣＤ | I12: E | K12: E
A13: 10 | D13: min_amt | E13: #MA.MONEY | G13: Min. amount | H13: 下限金額 | I13: E | K13: E
A14: 10 | D14: max_amt | E14: #MA.MONEY | G14: Max. amount | H14: 上限金額 | I14: E | K14: E
A15: 10 | D15: rcst_cd | E15: #MA.BP_CD | G15: Payer cd. | H15: 入金先ＣＤ | I15: E | K15: E
A16: 10 | D16: com_paid | E16: #MA.MONEY | G16: Transfer fee | H16: 振込手数料 | I16: E | K16: E
A17: 10 | D17: upd_cntr | E17: #MA.UPD_CNT | G17: Update counter | H17: 更新カウンタ | I17: E | K17: E
D18: 詳細 :

Sheet Srch01
A1: * | B1: * | D1: L | E1: 1
A2: * | D2: オペレーション実装仕様書 Operation Specification Implementation Sheet | E2: ModuleID : | F2: =IF(LogicCommon!C2="","",LogicCommon!C2) -> MA | G2: LogicID : | H2: =IF(LogicCommon!E2="","",LogicCommon!E2) -> MABSL1030 | I2: Ope.ID : | J2: Srch01 | K2: Pj.ID : | L2: =IF(LogicCommon!G2="","",LogicCommon!G2) -> MC | M2: Ope.Body : | N2: "mcframe.serverMAUD.MAUDL6010.MAUDL_RLSearcher"
A3: * | D3: =IF(LogicCommon!A3="","",LogicCommon!A3) | E3: SubModuleID : | F3: =IF(LogicCommon!C3="","",LogicCommon!C3) -> MABS | G3: LogicClass : | H3: =IF(LogicCommon!E3="","",LogicCommon!E3) -> MABSL_ComPaidReg | I3: Ope.Method : | J3: @ | K3: SuperClassPj.ID : | L3: =IF(LogicCommon!G3="","",LogicCommon!G3) | M3: ReportID : | O3: Gene.Type : | P3: ALL
A4: * | E4: Version : | F4: 000000 | G4: LogicName : | H4: =IF(LogicCommon!E4="","",LogicCommon!E4) -> 振込手数料マスタ登録 | I4: Ope.Name : | J4: 検索 | K4: SuperLogicID : | L4: =IF(LogicCommon!G4="","",LogicCommon!G4) -> MA.MAUDL5010
A5: * | E5: ACType :
A6: * | D6: 概要 : | E6: 検索処理をする | L6: ID | N6: ID
A7: # | I7: U | K7: o | L7: SELECT.c0 | M7: o
A8: # | D8: ブロック名 Block Name | E8: 型 Type | G8: super/share | H8: 対象ブロック名 Target Block Name | K8: TargetName | L8: DBC.MA.MAM_COM_PAID | M8: TargetName | Q8: ブロック備考 Block Remarks
A9: # | D9: 項目名 Field Name | E9: 型 Type | F9: 桁 Digits | G9: フルネーム Full Name | H9: 日本語名 Japanese Name | I9: 上り項目 Request Message Field | J9: 下り項目 Response Message Field | O9: 条件および編集方法 Conditions and Editing Methods | Q9: 項目備考 Field Remarks
A10: # | K10: 上り項目 Request Message Field | L10: 下り項目 Response Message Field | M10: 上り項目 Request Message Field | N10: 下り項目 Response Message Field
A11: 10 | B11: * | D11: Srch01_Cnd | E11: R | K11: R
A12: 10 | D12: cur_cd | E12: #MA.CUR_CD | G12: Currency cd. | H12: 通貨ＣＤ | I12: E | K12: E
A13: 10 | D13: cur_nm | E13: #MA.CUR_NM | G13: Currency name | H13: 通貨名 | I13: E | K13: E
A14: 10 | D14: rcst_cd | E14: #MA.BP_CD | G14: Payer cd. | H14: 入金先ＣＤ | I14: E | K14: E
A15: 10 | D15: rcst_nm | E15: #MA.BP_NM | G15: Payer name | H15: 入金先名 | I15: E | K15: E
A16: 10 | D16: off_del_flg | E16: #MA.FLG | G16: Logical delete. Off | H16: 論理削除.オフ | I16: E
A17: 10 | D17: on_del_flg | E17: #MA.FLG | G17: Logical delete. On | H17: 論理削除.オン | I17: E
A18: 10 | D18: memo1 | E18: #MA.MST_MEMO1 | G18: Memo 1 | H18: メモ１ | I18: E | K18: E
A19: 10 | D19: memo2 | E19: #MA.MST_MEMO2 | G19: Memo 2 | H19: メモ２ | I19: E | K19: E
A20: 10 | D20: memo3 | E20: #MA.MST_MEMO3 | G20: Memo 3 | H20: メモ３ | I20: E | K20: E
A21: 10 | D21: bp_grp_cd1 | E21: #MA.BP_GRP_CD | G21: BP classification cd. 1 | H21: 取引先分類ＣＤ１ | I21: E
A22: 10 | D22: bp_grp_nm1 | E22: #MA.BP_GRP_NM | G22: BP classification name 1 | H22: 取引先分類名１ | I22: E
A23: 10 | D23: bp_grp_cd2 | E23: #MA.BP_GRP_CD | G23: BP classification cd. 2 | H23: 取引先分類ＣＤ２ | I23: E
A24: 10 | D24: bp_grp_nm2 | E24: #MA.BP_GRP_NM | G24: BP classification name 2 | H24: 取引先分類名２ | I24: E
A25: 10 | D25: bp_grp_cd3 | E25: #MA.BP_GRP_CD | G25: BP classification cd. 3 | H25: 取引先分類ＣＤ３ | I25: E
A26: 10 | D26: bp_grp_nm3 | E26: #MA.BP_GRP_NM | G26: BP classification name 3 | H26: 取引先分類名３ | I26: E
A27: 10 | D27: bp_grp_cd4 | E27: #MA.BP_GRP_CD | G27: BP classification cd. 4 | H27: 取引先分類ＣＤ４ | I27: E
A28: 10 | D28: bp_grp_nm4 | E28: #MA.BP_GRP_NM | G28: BP classification name 4 | H28: 取引先分類名４ | I28: E
A29: 10 | D29: bp_grp_cd5 | E29: #MA.BP_GRP_CD | G29: BP classification cd. 5 | H29: 取引先分類ＣＤ５ | I29: E
A30: 10 | D30: bp_grp_nm5 | E30: #MA.BP_GRP_NM | G30: BP classification name 5 | H30: 取引先分類名５ | I30: E
A31: 10 | D31: bp_grp_cd6 | E31: #MA.BP_GRP_CD | G31: BP classification cd. 6 | H31: 取引先分類ＣＤ６ | I31: E
A32: 10 | D32: bp_grp_nm6 | E32: #MA.BP_GRP_NM | G32: BP classification name 6 | H32: 取引先分類名６ | I32: E
... A40: 10 | D40: bp_grp_nm10 | E40: #MA.BP_GRP_NM | G40: BP classification name 10 | H40: 取引先分類名１０ | I40: E
A42: 20 | B42: * | D42: Srch01_Rslt1 | E42: L | L42: L
A43: 20 | D43: del_flg | E43: #MA.FLG | G43: Logical delete | H43: 論理削除 | J43: E | L43: E
A44: 20 | D44: cur_cd | E44: #MA.CUR_CD | G44: Currency cd. | H44: 通貨ＣＤ | J44: E | L44: E
A45: 20 | D45: cur_nm | E45: #MA.CUR_NM | G45: Currency name | H45: 通貨名 | J45: E | L45: E
A46: 20 | D46: amt_dec_place | E46: #MA.DEC_PLACE | G46: Amount number of decimal places | H46: 金額小数部有効桁数 | J46: E | L46: E
A47: 20 | D47: min_amt | E47: #MA.MONEY | G47: Min. amount | H47: 下限金額 | J47: E | L47: E
A48: 20 | D48: max_amt | E48: #MA.MONEY | G48: Max. amount | H48: 上限金額 | J48: E | L48: E
...

Sheet Upd01
A1: * | B1: * | D1: L | E1: 1
A2: * | D2: オペレーション実装仕様書 Operation Specification Implementation Sheet | E2: ModuleID : | F2: =IF(LogicCommon!C2="","",LogicCommon!C2) -> MA | G2: LogicID : | H2: =IF(LogicCommon!E2="","",LogicCommon!E2) -> MABSL1030 | I2: Ope.ID : | J2: Upd01 | K2: Pj.ID : | L2: =IF(LogicCommon!G2="","",LogicCommon!G2) -> MC | M2: Ope.Body : | N2: "mcframe.serverMAUD.MAUDL6010.MAUDL_RLUpdater"
A3: * | D3: =IF(LogicCommon!A3="","",LogicCommon!A3) | E3: SubModuleID : | F3: =IF(LogicCommon!C3="","",LogicCommon!C3) -> MABS | G3: LogicClass : | H3: =IF(LogicCommon!E3="","",LogicCommon!E3) -> MABSL_ComPaidReg | I3: Ope.Method : | J3: @ | K3: SuperClassPj.ID : | L3: =IF(LogicCommon!G3="","",LogicCommon!G3) | M3: ReportID : | O3: Gene.Type : | P3: ALL
A4: * | E4: Version : | F4: 000000 | G4: LogicName : | H4: =IF(LogicCommon!E4="","",LogicCommon!E4) -> 振込手数料マスタ登録 | I4: Ope.Name : | J4: 登録 | K4: SuperLogicID : | L4: =IF(LogicCommon!G4="","",LogicCommon!G4) -> MA.MAUDL5010
A5: * | E5: ACType :
A6: * | D6: 概要 : | E6: 登録処理をする | L6: ID | N6: ID | P6: ID | R6: ID
A7: # | I7: U | K7: o | L7: CALL_OPE01.chk01 | M7: o | N7: CALL_OPE01.upd01 | O7: o | Q7: o
A8: # | D8: ブロック名 Block Name | E8: 型 Type | G8: super/share | H8: 対象ブロック名 Target Block Name | K8: TargetName | L8: OPE.MA.MABSL1030.ComPaid_UpdChk01 | M8: TargetName | N8: OPE.MA.MABSL1030.ComPaid_Upd01 | O8: TargetName | Q8: TargetName | U8: ブロック備考 Block Remarks
A9: # | D9: 項目名 Field Name | E9: 型 Type | F9: 桁 Digits | G9: フルネーム Full Name | H9: 日本語名 Japanese Name | I9: 上り項目 Request Message Field | J9: 下り項目 Response Message Field | S9: 条件および編集方法 Conditions and Editing Methods | U9: 項目備考 Field Remarks
A10: # | K10: 上り項目 Request Message Field | L10: 下り項目 Response Message Field | M10: 上り項目 Request Message Field | N10: 下り項目 Response Message Field | O10: 上り項目 Request Message Field | P10: 下り項目 Response Message Field | Q10: 上り項目 Request Message Field | R10: 下り項目 Response Message Field
A11: 10 | B11: * | D11: Upd01_Dtl1 | E11: L | G11: $share$ | H11: MA.MABSL1030.ComPaid_Upd01.ComPaid_Upd01_Dtl | K11: ComPaid_UpdChk01_Dtl | M11: ComPaid_Upd01_Dtl
A12: 10 | D12: cur_cd | E12: #MA.CUR_CD | G12: Currency cd. | H12: 通貨ＣＤ | I12: E | K12: E | M12: E
A13: 10 | D13: min_amt | E13: #MA.MONEY | G13: Min. amount | H13: 下限金額 | I13: E | K13: E | M13: E
A14: 10 | D14: max_amt | E14: #MA.MONEY | G14: Max. amount | H14: 上限金額 | I14: E | K14: E | M14: E
A15: 10 | D15: rcst_cd | E15: #MA.BP_CD | G15: Payer cd. | H15: 入金先ＣＤ | I15: E | K15: E | M15: E
A16: 10 | D16: com_paid | E16: #MA.MONEY | G16: Transfer fee | H16: 振込手数料 | I16: E | K16: E | M16: E
A17: 10 | D17: memo1 | E17: #MA.MST_MEMO1 | G17: Memo 1 | H17: メモ１ | I17: E | K17: E | M17: E
A18: 10 | D18: memo2 | E18: #MA.MST_MEMO2 | G18: Memo 2 | H18: メモ２ | I18: E | K18: E | M18: E
A19: 10 | D19: memo3 | E19: #MA.MST_MEMO3 | G19: Memo 3 | H19: メモ３ | I19: E | K19: E | M19: E
A20: 10 | D20: del_flg | E20: #MA.FLG | G20: Logical delete | H20: 論理削除 | I20: E | K20: E | M20: E
A21: 10 | D21: upd_cntr | E21: #MA.UPD_CNT | G21: Update counter | H21: 更新カウンタ | I21: E | K21: E | M21: E
D22: 詳細 :

Sheet Del01
A1: * | B1: * | D1: L | E1: 1
A2: * | D2: オペレーション実装仕様書 Operation Specification Implementation Sheet | E2: ModuleID : | F2: =IF(LogicCommon!C2="","",LogicCommon!C2) -> MA | G2: LogicID : | H2: =IF(LogicCommon!E2="","",LogicCommon!E2) -> MABSL1030 | I2: Ope.ID : | J2: Del01 | K2: Pj.ID : | L2: =IF(LogicCommon!G2="","",LogicCommon!G2) -> MC | M2: Ope.Body : | N2: "mcframe.serverMAUD.MAUDL6010.MAUDL_RLDeleter"
A3: * | D3: =IF(LogicCommon!A3="","",LogicCommon!A3) | E3: SubModuleID : | F3: =IF(LogicCommon!C3="","",LogicCommon!C3) -> MABS | G3: LogicClass : | H3: =IF(LogicCommon!E3="","",LogicCommon!E3) -> MABSL_ComPaidReg | I3: Ope.Method : | J3: @ | K3: SuperClassPj.ID : | L3: =IF(LogicCommon!G3="","",LogicCommon!G3) | M3: ReportID : | O3: Gene.Type : | P3: ALL
A4: * | E4: Version : | F4: 000000 | G4: LogicName : | H4: =IF(LogicCommon!E4="","",LogicCommon!E4) -> 振込手数料マスタ登録 | I4: Ope.Name : | J4: 削除 | K4: SuperLogicID : | L4: =IF(LogicCommon!G4="","",LogicCommon!G4) -> MA.MAUDL5010
A5: * | E5: ACType :
A6: * | D6: 概要 : | E6: 削除処理をする | L6: ID | N6: ID
A7: # | I7: U | K7: o | L7: CALL_OPE01.chk01 | M7: o | N7: CALL_OPE01.del01
A8: # | D8: ブロック名 Block Name | E8: 型 Type | G8: super/share | H8: 対象ブロック名 Target Block Name | K8: TargetName | L8: OPE.MA.MABSL1030.ComPaid_DelChk01 | M8: TargetName | N8: OPE.MA.MABSL1030.ComPaid_Del01 | Q8: ブロック備考 Block Remarks
A9: # | D9: 項目名 Field Name | E9: 型 Type | F9: 桁 Digits | G9: フルネーム Full Name | H9: 日本語名 Japanese Name | I9: 上り項目 Request Message Field | J9: 下り項目 Response Message Field | O9: 条件および編集方法 Conditions and Editing Methods | Q9: 項目備考 Field Remarks
A10: # | K10: 上り項目 Request Message Field | L10: 下り項目 Response Message Field | M10: 上り項目 Request Message Field | N10: 下り項目 Response Message Field
A11: 10 | B11: * | D11: Del01_Dtl1 | E11: L | G11: $share$ | H11: MA.MABSL1030.ComPaid_Del01.ComPaid_Del01_Dtl | K11: ComPaid_DelChk01_Dtl | M11: ComPaid_Del01_Dtl
A12: 10 | D12: cur_cd | E12: #MA.CUR_CD | G12: Currency cd. | H12: 通貨ＣＤ | I12: E | K12: E | M12: E
A13: 10 | D13: min_amt | E13: #MA.MONEY | G13: Min. amount | H13: 下限金額 | I13: E | K13: E | M13: E
A14: 10 | D14: max_amt | E14: #MA.MONEY | G14: Max. amount | H14: 上限金額 | I14: E | K14: E | M14: E
A15: 10 | D15: rcst_cd | E15: #MA.BP_CD | G15: Payer cd. | H15: 入金先ＣＤ | I15: E | K15: E | M15: E
A16: 10 | D16: com_paid | E16: #MA.MONEY | G16: Transfer fee | H16: 振込手数料 | I16: E | K16: E | M16: E
A17: 10 | D17: upd_cntr | E17: #MA.UPD_CNT | G17: Update counter | H17: 更新カウンタ | I17: E | K17: E | M17: E
D18: 詳細 :

Sheet 来歴
A1: 変更来歴
A3: Rev. | H3: 修正番号 | O3: 変更内容 | AQ3: 変更箇所
A4: 1 | O4: 初版
A5: 1.1 | O5: 英語の名称を追記 | AQ5: 全般
