Workbook

Sheet LogicCommon
A2: ロジック共通定義 | B2: ModuleID : | C2: MA | D2: LogicID : | E2: MABSL0850 | F2: Pj.ID : | G2: MC
B3: SubModuleID : | C3: MABS | D3: LogicClass : | E3: MABSL_MpsItmReg | F3: SuperClassPj.ID :
D4: LogicName : | E4: ＭＰＳ品目マスタ登録 | F4: SuperLogicID : | G4: MA.MAUDL5010
A5: 概要 :
A6: 詳細 :

Sheet MpsItm_UpdChk01
A1: * | B1: * | D1: L | E1: 1
A2: * | D2: オペレーション実装仕様書 Operation Specification Implementation Sheet | E2: ModuleID : | F2: =IF(LogicCommon!C2="","",LogicCommon!C2) -> MA | G2: LogicID : | H2: =IF(LogicCommon!E2="","",LogicCommon!E2) -> MABSL0850 | I2: Ope.ID : | J2: MpsItm_UpdChk01 | K2: Pj.ID : | L2: =IF(LogicCommon!G2="","",LogicCommon!G2) -> MC | M2: Ope.Body : | N2: =L4 & ".Checker" -> MA.MAUDL5010.Checker
A3: * | D3: =IF(LogicCommon!A3="","",LogicCommon!A3) | E3: SubModuleID : | F3: =IF(LogicCommon!C3="","",LogicCommon!C3) -> MABS | G3: LogicClass : | H3: =IF(LogicCommon!E3="","",LogicCommon!E3) -> MABSL_MpsItmReg | I3: Ope.Method : | J3: @ | K3: SuperClassPj.ID : | L3: =IF(LogicCommon!G3="","",LogicCommon!G3) | M3: ReportID : | O3: Gene.Type : | P3: ALL
A4: * | E4: Version : | F4: 000000 | G4: LogicName : | H4: =IF(LogicCommon!E4="","",LogicCommon!E4) -> ＭＰＳ品目マスタ登録 | I4: Ope.Name : | J4: 登録前チェック | K4: SuperLogicID : | L4: =IF(LogicCommon!G4="","",LogicCommon!G4) -> MA.MAUDL5010
A5: * | E5: ACType :
A6: * | D6: 概要 : | E6: ＭＰＳ品目マスタを登録する前のチェックを行う | U6: ID | V6: ID
A7: # | I7: U | K7: K | L7: K | M7: K | N7: K | O7: K | P7: K | Q7: K | R7: K | S7: K | T7: K | U7: o
A8: # | D8: ブロック名 Block Name | E8: 型 Type | G8: super/share | H8: 対象ブロック名 Target Block Name | K8: REQUIRED | L8: LIST_LOGIC | M8: NULL_VAL | N8: ONLY_ONE_INPUT | O8: CHK_NUM | P8: LIST_IN | Q8: LIST_IN_BASE | R8: LIST_OUT | S8: LIST_OUT_BASE | T8: TOO_MANY_INPUTS | U8: TargetName | Y8: ブロック備考 Block Remarks
A9: # | D9: 項目名 Field Name | E9: 型 Type | F9: 桁 Digits | G9: フルネーム Full Name | H9: 日本語名 Japanese Name | I9: 上り項目 Request Message Field | J9: 下り項目 Response Message Field | W9: 条件および編集方法 Conditions and Editing Methods | Y9: 項目備考 Field Remarks
A10: # | U10: 上り項目 Request Message Field | V10: 下り項目 Response Message Field
A11: 10 | B11: * | D11: MpsItm_UpdChk01_Dtl | E11: L | G11: $super$ | H11: DBC:MA.MAM_MPS_ITM_
A12: 10 | D12: wg_cd | E12: #MA.WG_CD | G12: WG cd. | H12: ワーキンググループＣＤ | I12: E | L12: MA.MAUAL0010.LgOrMfgWg | M12: E | P12: true | Q12: mode_nullval_flg
A13: 10 | D13: itm_cd | E13: #MA.ITM_CD | G13: Item cd. | H13: 品目ＣＤ | I13: E | K13: E
A14: 10 | D14: itm_sub1 | E14: #MA.ITM_SUB1 | G14: Branch No. 1 | H14: 枝番１ | I14: E | M14: E
A15: 10 | D15: itm_sub2 | E15: #MA.ITM_SUB2 | G15: Branch No. 2 | H15: 枝番２ | I15: E | M15: E
A16: 10 | D16: itm_sub3 | E16: #MA.ITM_SUB3 | G16: Branch No. 3 | H16: 枝番３ | I16: E | L16: MA.MAUAL0010.ItmSub3 | M16: E | P16: MAC_ITM_IS_SRCH_TYP.NOT_ASSET3;itm_cd;itm_sub1;itm_sub2;true;true | Q16: itm_is_srch_typ;itm_cd;itm_sub1;itm_sub2;release_flg_on;release_flg_off
A17: 10 | D17: mps_grp_cd | E17: #MA.MPS_GRP_CD | G17: MPS group cd. | H17: ＭＰＳグループＣＤ | I17: E | K17: E
A18: 10 | D18: strg_loc_cd | E18: #MA.LOC_CD | G18: Storage location cd. | H18: 格納場所ＣＤ | I18: E | K18: E | L18: MA.MAUAL0010.Loc | P18: MAC_LOC_IS_SRCH_TYP.COMM | Q18: loc_is_srch_typ | R18: strg_wg_cd | S18: wg_cd
A19: 10 | D19: strg_wg_cd | E19: #MA.WG_CD | G19: Storage location WG cd. | H19: 格納場所ワーキンググループＣＤ
A20: 10 | D20: mfg_loc_cd | E20: #MA.LOC_CD | G20: Mfg. location cd. | H20: 製造場所ＣＤ | I20: E | L20: MA.MAUAL0010.Loc | M20: E | P20: MAC_LOC_IS_SRCH_TYP.MFG_WG_ALL;strg_wg_cd;true | Q20: loc_is_srch_typ;wg_cd;mode_nullval_flg | T20: E1
A21: 10 | D21: sppl_cd | E21: #MA.BP_CD | G21: Supplier cd. | H21: 発注先ＣＤ | I21: E | L21: MA.MAUAL0010.Bp | M21: E | P21: MAC_BP_IS_SRCH_TYP.SPPL;true | Q21: bp_is_srch_typ;mode_nullval_flg | T21: E1
A22: 10 | D22: maker_cd | E22: #MA.BP_CD | G22: Maker cd. | H22: メーカＣＤ | I22: E | L22: MA.MAUAL0010.Bp | M22: E | P22: MAC_BP_IS_SRCH_TYP.MAKER;true | Q22: bp_is_srch_typ;mode_nullval_flg
A23: 10 | D23: rqst_loc_cd | E23: #MA.LOC_CD | G23: Requested location cd. | H23: 依頼先場所ＣＤ | I23: E | L23: MA.MAUAL0010.Loc | M23: E | P23: MAC_LOC_IS_SRCH_TYP.HOUSE;true | Q23: loc_is_srch_typ;mode_nullval_flg | R23: rqst_wg_cd | S23: wg_cd | T23: E1
A24: 10 | D24: rqst_wg_cd | E24: #MA.WG_CD | G24: Requested location WG cd. | H24: 依頼先場所ワーキンググループＣＤ
A25: 10 | D25: prod_rate | E25: #MA.PROD_RATE | G25: Disaggregation by day proportion ratio | H25: 日ばらし案分比率 | I25: E | K25: E | O25: positive
A26: 10 | D26: prod_begin_day | E26: #MA.PROD_BEGIN_DAY | G26: Disaggregation by day start date | H26: 日ばらし開始日 | I26: E | K26: E
A27: 10 | D27: memo1 | E27: #MA.MST_MEMO1 | G27: Memo 1 | H27: メモ１ | I27: E
A28: 10 | D28: memo2 | E28: #MA.MST_MEMO2 | G28: Memo 2 | H28: メモ２ | I28: E
A29: 10 | D29: memo3 | E29: #MA.MST_MEMO3 | G29: Memo 3 | H29: メモ３ | I29: E
A30: 10 | D30: del_flg | E30: #MA.FLG | G30: Logical delete | H30: 論理削除 | I30: E
A31: 10 | D31: upd_cntr | E31: #MA.UPD_CNT | G31: Update counter | H31: 更新カウンタ | I31: E
D32: 詳細 :

Sheet MpsItm_Upd01
A1: * | B1: * | D1: L | E1: 1
A2: * | D2: オペレーション実装仕様書 Operation Specification Implementation Sheet | E2: ModuleID : | F2: =IF(LogicCommon!C2="","",LogicCommon!C2) -> MA | G2: LogicID : | H2: =IF(LogicCommon!E2="","",LogicCommon!E2) -> MABSL0850 | I2: Ope.ID : | J2: MpsItm_Upd01 | K2: Pj.ID : | L2: =IF(LogicCommon!G2="","",LogicCommon!G2) -> MC | M2: Ope.Body : | N2: "mcframe.serverMAUD.MAUDL6010.MAUDL_RLUpdater"
A3: * | D3: =IF(LogicCommon!A3="","",LogicCommon!A3) | E3: SubModuleID : | F3: =IF(LogicCommon!C3="","",LogicCommon!C3) -> MABS | G3: LogicClass : | H3: =IF(LogicCommon!E3="","",LogicCommon!E3) -> MABSL_MpsItmReg | I3: Ope.Method : | J3: @ | K3: SuperClassPj.ID : | L3: =IF(LogicCommon!G3="","",LogicCommon!G3) | M3: ReportID : | O3: Gene.Type : | P3: ALL
A4: * | E4: Version : | F4: 000000 | G4: LogicName : | H4: =IF(LogicCommon!E4="","",LogicCommon!E4) -> ＭＰＳ品目マスタ登録 | I4: Ope.Name : | J4: 登録処理 | K4: SuperLogicID : | L4: =IF(LogicCommon!G4="","",LogicCommon!G4) -> MA.MAUDL5010
A5: * | E5: ACType :
A6: * | D6: 概要 : | E6: ＭＰＳ品目マスタを登録する | L6: ID | N6: ID
A7: # | I7: U | K7: o | L7: UPDATE.updMaster | M7: o | N7: MAIN.chkMaster
A8: # | D8: ブロック名 Block Name | E8: 型 Type | G8: super/share | H8: 対象ブロック名 Target Block Name | K8: TargetName | L8: DBC.MA.MAM_MPS_ITM_ | M8: TargetName | N8: DBC.MA.MAM_MPS_ITM_ | Q8: ブロック備考 Block Remarks
A9: # | D9: 項目名 Field Name | E9: 型 Type | F9: 桁 Digits | G9: フルネーム Full Name | H9: 日本語名 Japanese Name | I9: 上り項目 Request Message Field | J9: 下り項目 Response Message Field | O9: 条件および編集方法 Conditions and Editing Methods | Q9: 項目備考 Field Remarks
A10: # | K10: 上り項目 Request Message Field | L10: 下り項目 Response Message Field | M10: 上り項目 Request Message Field | N10: 下り項目 Response Message Field
A11: 10 | B11: * | D11: MpsItm_Upd01_Dtl | E11: L | G11: $share$ | H11: MA.MABSL0850.MpsItm_UpdChk01.MpsItm_UpdChk01_Dtl | K11: L | M11: L
A12: 10 | D12: wg_cd | E12: #MA.WG_CD | G12: WG cd. | H12: ワーキンググループＣＤ | I12: E | K12: E | M12: E
A13: 10 | D13: itm_cd | E13: #MA.ITM_CD | G13: Item cd. | H13: 品目ＣＤ | I13: E | K13: E | M13: E
A14: 10 | D14: itm_sub1 | E14: #MA.ITM_SUB1 | G14: Branch No. 1 | H14: 枝番１ | I14: E | K14: E | M14: E
A15: 10 | D15: itm_sub2 | E15: #MA.ITM_SUB2 | G15: Branch No. 2 | H15: 枝番２ | I15: E | K15: E | M15: E
A16: 10 | D16: itm_sub3 | E16: #MA.ITM_SUB3 | G16: Branch No. 3 | H16: 枝番３ | I16: E | K16: E | M16: E
A17: 10 | D17: mps_grp_cd | E17: #MA.MPS_GRP_CD | G17: MPS group cd. | H17: ＭＰＳグループＣＤ | I17: E | K17: E
A18: 10 | D18: strg_loc_cd | E18: #MA.LOC_CD | G18: Storage location cd. | H18: 格納場所ＣＤ | I18: E | K18: E
A19: 10 | D19: mfg_loc_cd | E19: #MA.LOC_CD | G19: Mfg. location cd. | H19: 製造場所ＣＤ | I19: E | K19: E
A20: 10 | D20: sppl_cd | E20: #MA.BP_CD | G20: Supplier cd. | H20: 発注先ＣＤ | I20: E | K20: E
A21: 10 | D21: maker_cd | E21: #MA.BP_CD | G21: Maker cd. | H21: メーカＣＤ | I21: E | K21: E
A22: 10 | D22: rqst_loc_cd | E22: #MA.LOC_CD | G22: Requested location cd. | H22: 依頼先場所ＣＤ | I22: E | K22: E
A23: 10 | D23: prod_rate | E23: #MA.PROD_RATE | G23: Disaggregation by day proportion ratio | H23: 日ばらし案分比率 | I23: E | K23: E
A24: 10 | D24: prod_begin_day | E24: #MA.PROD_BEGIN_DAY | G24: Disaggregation by day start date | H24: 日ばらし開始日 | I24: E | K24: E
A25: 10 | D25: memo1 | E25: #MA.MST_MEMO1 | G25: Memo 1 | H25: メモ１ | I25: E | K25: E
A26: 10 | D26: memo2 | E26: #MA.MST_MEMO2 | G26: Memo 2 | H26: メモ２ | I26: E | K26: E
A27: 10 | D27: memo3 | E27: #MA.MST_MEMO3 | G27: Memo 3 | H27: メモ３ | I27: E | K27: E
A28: 10 | D28: del_flg | E28: #MA.FLG | G28: Logical delete | H28: 論理削除 | I28: E | K28: E
A29: 10 | D29: upd_cntr | E29: #MA.UPD_CNT | G29: Update counter | H29: 更新カウンタ | I29: E | K29: E
D30: 詳細 :

Sheet MpsItm_DelChk01
A1: * | B1: * | D1: L | E1: 1
A2: * | D2: オペレーション実装仕様書 Operation Specification Implementation Sheet | E2: ModuleID : | F2: =IF(LogicCommon!C2="","",LogicCommon!C2) -> MA | G2: LogicID : | H2: =IF(LogicCommon!E2="","",LogicCommon!E2) -> MABSL0850 | I2: Ope.ID : | J2: MpsItm_DelChk01 | K2: Pj.ID : | L2: =IF(LogicCommon!G2="","",LogicCommon!G2) -> MC | M2: Ope.Body : | N2: =L4 & ".Checker" -> MA.MAUDL5010.Checker
A3: * | D3: =IF(LogicCommon!A3="","",LogicCommon!A3) | E3: SubModuleID : | F3: =IF(LogicCommon!C3="","",LogicCommon!C3) -> MABS | G3: LogicClass : | H3: =IF(LogicCommon!E3="","",LogicCommon!E3) -> MABSL_MpsItmReg | I3: Ope.Method : | J3: @ | K3: SuperClassPj.ID : | L3: =IF(LogicCommon!G3="","",LogicCommon!G3) | M3: ReportID : | O3: Gene.Type : | P3: ALL
A4: * | E4: Version : | F4: 000000 | G4: LogicName : | H4: =IF(LogicCommon!E4="","",LogicCommon!E4) -> ＭＰＳ品目マスタ登録 | I4: Ope.Name : | J4: 削除チェック | K4: SuperLogicID : | L4: =IF(LogicCommon!G4="","",LogicCommon!G4) -> MA.MAUDL5010
A5: * | E5: ACType :
A6: * | D6: 概要 : | E6: ＭＰＳ品目マスタを削除する前のチェックを行う | Q6: ID
A7: # | I7: U | K7: K | P7: o
A8: # | D8: ブロック名 Block Name | E8: 型 Type | G8: super/share | H8: 対象ブロック名 Target Block Name | K8: REQUIRED | P8: TargetName | T8: ブロック備考 Block Remarks
A9: # | D9: 項目名 Field Name | E9: 型 Type | F9: 桁 Digits | G9: フルネーム Full Name | H9: 日本語名 Japanese Name | I9: 上り項目 Request Message Field | J9: 下り項目 Response Message Field | R9: 条件および編集方法 Conditions and Editing Methods | T9: 項目備考 Field Remarks
A10: # | P10: 上り項目 Request Message Field | Q10: 下り項目 Response Message Field
A11: 10 | B11: * | D11: MpsItm_DelChk01_Dtl | E11: L
A12: 10 | D12: wg_cd | E12: #MA.WG_CD | G12: WG cd. | H12: ワーキンググループＣＤ | I12: E | K12: E
A13: 10 | D13: itm_cd | E13: #MA.ITM_CD | G13: Item cd. | H13: 品目ＣＤ | I13: E | K13: E
A14: 10 | D14: itm_sub1 | E14: #MA.ITM_SUB1 | G14: Branch No. 1 | H14: 枝番１ | I14: E | K14: E
A15: 10 | D15: itm_sub2 | E15: #MA.ITM_SUB2 | G15: Branch No. 2 | H15: 枝番２ | I15: E | K15: E
A16: 10 | D16: itm_sub3 | E16: #MA.ITM_SUB3 | G16: Branch No. 3 | H16: 枝番３ | I16: E | K16: E
A17: 10 | D17: upd_cntr | E17: #MA.UPD_CNT | G17: Update counter | H17: 更新カウンタ | I17: E
D18: 詳細 :

Sheet MpsItm_Del01
A1: * | B1: * | D1: L | E1: 1
A2: * | D2: オペレーション実装仕様書 Operation Specification Implementation Sheet | E2: ModuleID : | F2: =IF(LogicCommon!C2="","",LogicCommon!C2) -> MA | G2: LogicID : | H2: =IF(LogicCommon!E2="","",LogicCommon!E2) -> MABSL0850 | I2: Ope.ID : | J2: MpsItm_Del01 | K2: Pj.ID : | L2: =IF(LogicCommon!G2="","",LogicCommon!G2) -> MC | M2: Ope.Body : | N2: "mcframe.serverMAUD.MAUDL6010.MAUDL_RLDeleter"
A3: * | D3: =IF(LogicCommon!A3="","",LogicCommon!A3) | E3: SubModuleID : | F3: =IF(LogicCommon!C3="","",LogicCommon!C3) -> MABS | G3: LogicClass : | H3: =IF(LogicCommon!E3="","",LogicCommon!E3) -> MABSL_MpsItmReg | I3: Ope.Method : | J3: @ | K3: SuperClassPj.ID : | L3: =IF(LogicCommon!G3="","",LogicCommon!G3) | M3: ReportID : | O3: Gene.Type : | P3: ALL
A4: * | E4: Version : | F4: 000000 | G4: LogicName : | H4: =IF(LogicCommon!E4="","",LogicCommon!E4) -> ＭＰＳ品目マスタ登録 | I4: Ope.Name : | J4: 削除処理 | K4: SuperLogicID : | L4: =IF(LogicCommon!G4="","",LogicCommon!G4) -> MA.MAUDL5010
A5: * | E5: ACType :
A6: * | D6: 概要 : | E6: ＭＰＳ品目マスタを削除する | L6: ID
A7: # | I7: U | K7: o | L7: UPDATE.updMaster1
A8: # | D8: ブロック名 Block Name | E8: 型 Type | G8: super/share | H8: 対象ブロック名 Target Block Name | K8: TargetName | L8: DBC.MA.MAM_MPS_ITM_ | O8: ブロック備考 Block Remarks
A9: # | D9: 項目名 Field Name | E9: 型 Type | F9: 桁 Digits | G9: フルネーム Full Name | H9: 日本語名 Japanese Name | I9: 上り項目 Request Message Field | J9: 下り項目 Response Message Field | M9: 条件および編集方法 Conditions and Editing Methods | O9: 項目備考 Field Remarks
A10: # | K10: 上り項目 Request Message Field | L10: 下り項目 Response Message Field
A11: 10 | B11: * | D11: MpsItm_Del01_Dtl | E11: L | G11: $share$ | H11: MA.MABSL0850.MpsItm_DelChk01.MpsItm_DelChk01_Dtl | K11: L
A12: 10 | D12: wg_cd | E12: #MA.WG_CD | G12: WG cd. | H12: ワーキンググループＣＤ | I12: E | K12: E
A13: 10 | D13: itm_cd | E13: #MA.ITM_CD | G13: Item cd. | H13: 品目ＣＤ | I13: E | K13: E
A14: 10 | D14: itm_sub1 | E14: #MA.ITM_SUB1 | G14: Branch No. 1 | H14: 枝番１ | I14: E | K14: E
A15: 10 | D15: itm_sub2 | E15: #MA.ITM_SUB2 | G15: Branch No. 2 | H15: 枝番２ | I15: E | K15: E
A16: 10 | D16: itm_sub3 | E16: #MA.ITM_SUB3 | G16: Branch No. 3 | H16: 枝番３ | I16: E | K16: E
A17: 10 | D17: upd_cntr | E17: #MA.UPD_CNT | G17: Update counter | H17: 更新カウンタ | I17: E | K17: E
D18: 詳細 :

Sheet Srch01
A1: * | B1: * | D1: L | E1: 1
A2: * | D2: オペレーション実装仕様書 Operation Specification Implementation Sheet | E2: ModuleID : | F2: =IF(LogicCommon!C2="","",LogicCommon!C2) -> MA | G2: LogicID : | H2: =IF(LogicCommon!E2="","",LogicCommon!E2) -> MABSL0850 | I2: Ope.ID : | J2: Srch01 | K2: Pj.ID : | L2: =IF(LogicCommon!G2="","",LogicCommon!G2) -> MC | M2: Ope.Body : | N2: "mcframe.serverMAUD.MAUDL6010.MAUDL_RLSearcher"
A3: * | D3: =IF(LogicCommon!A3="","",LogicCommon!A3) | E3: SubModuleID : | F3: =IF(LogicCommon!C3="","",LogicCommon!C3) -> MABS | G3: LogicClass : | H3: =IF(LogicCommon!E3="","",LogicCommon!E3) -> MABSL_MpsItmReg | I3: Ope.Method : | J3: @ | K3: SuperClassPj.ID : | L3: =IF(LogicCommon!G3="","",LogicCommon!G3) | M3: ReportID : | O3: Gene.Type : | P3: ALL
A4: * | E4: Version : | F4: 000000 | G4: LogicName : | H4: =IF(LogicCommon!E4="","",LogicCommon!E4) -> ＭＰＳ品目マスタ登録 | I4: Ope.Name : | J4: 検索 | K4: SuperLogicID : | L4: =IF(LogicCommon!G4="","",LogicCommon!G4) -> MA.MAUDL5010
A5: * | E5: ACType :
A6: * | D6: 概要 : | E6: 検索処理を行う | M6: ID
A7: # | I7: U | K7: K | L7: o | M7: SELECT.c0
A8: # | D8: ブロック名 Block Name | E8: 型 Type | G8: super/share | H8: 対象ブロック名 Target Block Name | K8: CONST | L8: TargetName | M8: DBC.MA.MAM_MPS_ITM_ | P8: ブロック備考 Block Remarks
A9: # | D9: 項目名 Field Name | E9: 型 Type | F9: 桁 Digits | G9: フルネーム Full Name | H9: 日本語名 Japanese Name | I9: 上り項目 Request Message Field | J9: 下り項目 Response Message Field | N9: 条件および編集方法 Conditions and Editing Methods | P9: 項目備考 Field Remarks
A10: # | L10: 上り項目 Request Message Field | M10: 下り項目 Response Message Field
A11: 10 | B11: * | D11: Srch01_Cnd | E11: R | L11: R
A12: 10 | D12: cmn_flg | E12: #MA.FLG | G12: Common | H12: 共通 | I12: E
A13: 10 | D13: wg_flg | E13: #MA.FLG | G13: WG | H13: ＷＧ | I13: E
A14: 10 | D14: wg_cd | E14: #MA.WG_CD | G14: WG cd. | H14: ワーキンググループＣＤ | I14: E
A15: 10 | D15: wg_nm | E15: #MA.WG_NM | G15: WG name | H15: ワーキンググループ名 | I15: E
A16: 10 | D16: mps_grp_cd | E16: #MA.MPS_GRP_CD | G16: MPS group cd. | H16: ＭＰＳグループＣＤ | I16: E
A17: 10 | D17: mps_grp_nm | E17: #MA.MPS_GRP_NM | G17: MPS group name | H17: ＭＰＳグループ名 | I17: E
A18: 10 | D18: itm_typ | E18: #MA.ITM_TYP | G18: Item type | H18: 品目区分 | I18: E
A19: 10 | D19: itm_typ_d_cd | E19: #MA.ITM_TYP_D_CD | G19: Item type details cd. | H19: 品目区分詳細ＣＤ | I19: E
A20: 10 | D20: itm_typ_d_nm | E20: #MA.ITM_TYP_D_NM | G20: Item type details name | H20: 品目区分詳細名 | I20: E
A21: 10 | D21: itm_cd | E21: #MA.ITM_CD | G21: Item cd. | H21: 品目ＣＤ | I21: E
A22: 10 | D22: itm_sub1 | E22: #MA.ITM_SUB1 | G22: Branch No. 1 | H22: 枝番１ | I22: E
A23: 10 | D23: itm_sub2 | E23: #MA.ITM_SUB2 | G23: Branch No. 2 | H23: 枝番２ | I23: E
... A50: 10 | D50: itm_grp_nm10 | E50: #MA.ITM_GRP_NM | G50: Item classification name 10 | H50: 品目分類名１０ | I50: E
A52: 20 | B52: * | D52: Srch01_Rslt | E52: L | M52: L
A53: 20 | D53: del_flg | E53: #MA.FLG | G53: Logical delete | H53: 論理削除 | J53: E | M53: E
A54: 20 | D54: wg_cd | E54: #MA.WG_CD | G54: WG cd. | H54: ワーキンググループＣＤ | J54: E | M54: E
A55: 20 | D55: wg_nm | E55: #MA.WG_NM | G55: WG name | H55: ワーキンググループ名 | J55: E | M55: E
A56: 20 | D56: itm_cd | E56: #MA.ITM_CD | G56: Item cd. | H56: 品目ＣＤ | J56: E | M56: E
A57: 20 | D57: itm_sub1 | E57: #MA.ITM_SUB1 | G57: Branch No. 1 | H57: 枝番１ | J57: E | M57: E
A58: 20 | D58: itm_sub2 | E58: #MA.ITM_SUB2 | G58: Branch No. 2 | H58: 枝番２ | J58: E | M58: E
A59: 20 | D59: itm_sub3 | E59: #MA.ITM_SUB3 | G59: Branch No. 3 | H59: 枝番３ | J59: E | M59: E
A60: 20 | D60: itm_nm | E60: #MA.ITM_NM | G60: Item name | H60: 品名 | J60: E | M60: E
A61: 20 | D61: itm_typ | E61: #MA.ITM_TYP | G61: Item type | H61: 品目区分 | J61: E | K61: MAC_ITM_TYP | M61: E
A62: 20 | D62: itm_typ_nm | E62: #MA.ITM_TYP_NM | G62: Item type name | H62: 品目区分名 | J62: E
A63: 20 | D63: itm_typ_d_cd | E63: #MA.ITM_TYP_D_CD | G63: Item type details cd. | H63: 品目区分詳細ＣＤ | J63: E | M63: E
A64: 20 | D64: itm_typ_d_nm | E64: #MA.ITM_TYP_D_NM | G64: Item type details name | H64: 品目区分詳細名 | J64: E | M64: E
A65: 20 | D65: mps_grp_cd | E65: #MA.MPS_GRP_CD | G65: MPS group cd. | H65: ＭＰＳグループＣＤ | J65: E | M65: E
A66: 20 | D66: mps_grp_nm | E66: #MA.MPS_GRP_NM | G66: MPS group name | H66: ＭＰＳグループ名 | J66: E | M66: E
A67: 20 | D67: strg_loc_cd | E67: #MA.LOC_CD | G67: Storage location cd. | H67: 格納場所ＣＤ | J67: E | M67: E
...

Sheet Upd01
A1: * | B1: * | D1: L | E1: 1
A2: * | D2: オペレーション実装仕様書 Operation Specification Implementation Sheet | E2: ModuleID : | F2: =IF(LogicCommon!C2="","",LogicCommon!C2) -> MA | G2: LogicID : | H2: =IF(LogicCommon!E2="","",LogicCommon!E2) -> MABSL0850 | I2: Ope.ID : | J2: Upd01 | K2: Pj.ID : | L2: =IF(LogicCommon!G2="","",LogicCommon!G2) -> MC | M2: Ope.Body : | N2: "mcframe.serverMAUD.MAUDL6010.MAUDL_RLUpdater"
A3: * | D3: =IF(LogicCommon!A3="","",LogicCommon!A3) | E3: SubModuleID : | F3: =IF(LogicCommon!C3="","",LogicCommon!C3) -> MABS | G3: LogicClass : | H3: =IF(LogicCommon!E3="","",LogicCommon!E3) -> MABSL_MpsItmReg | I3: Ope.Method : | J3: @ | K3: SuperClassPj.ID : | L3: =IF(LogicCommon!G3="","",LogicCommon!G3) | M3: ReportID : | O3: Gene.Type : | P3: ALL
A4: * | E4: Version : | F4: 000000 | G4: LogicName : | H4: =IF(LogicCommon!E4="","",LogicCommon!E4) -> ＭＰＳ品目マスタ登録 | I4: Ope.Name : | J4: 登録 | K4: SuperLogicID : | L4: =IF(LogicCommon!G4="","",LogicCommon!G4) -> MA.MAUDL5010
A5: * | E5: ACType :
A6: * | D6: 概要 : | E6: 登録処理を行う | L6: ID | N6: ID
A7: # | I7: U | K7: o | L7: CALL_OPE01.chk01 | M7: o | N7: CALL_OPE01.upd01
A8: # | D8: ブロック名 Block Name | E8: 型 Type | G8: super/share | H8: 対象ブロック名 Target Block Name | K8: TargetName | L8: OPE.MA.MABSL0850.MpsItm_UpdChk01 | M8: TargetName | N8: OPE.MA.MABSL0850.MpsItm_Upd01 | Q8: ブロック備考 Block Remarks
A9: # | D9: 項目名 Field Name | E9: 型 Type | F9: 桁 Digits | G9: フルネーム Full Name | H9: 日本語名 Japanese Name | I9: 上り項目 Request Message Field | J9: 下り項目 Response Message Field | O9: 条件および編集方法 Conditions and Editing Methods | Q9: 項目備考 Field Remarks
A10: # | K10: 上り項目 Request Message Field | L10: 下り項目 Response Message Field | M10: 上り項目 Request Message Field | N10: 下り項目 Response Message Field
A11: 10 | B11: * | D11: Upd01_Dtl | E11: L | G11: $share$ | H11: MA.MABSL0850.MpsItm_Upd01.MpsItm_Upd01_Dtl | K11: MpsItm_UpdChk01_Dtl | M11: MpsItm_Upd01_Dtl
A12: 10 | D12: wg_cd | E12: #MA.WG_CD | G12: WG cd. | H12: ワーキンググループＣＤ | I12: E | K12: E | M12: E
A13: 10 | D13: itm_cd | E13: #MA.ITM_CD | G13: Item cd. | H13: 品目ＣＤ | I13: E | K13: E | M13: E
A14: 10 | D14: itm_sub1 | E14: #MA.ITM_SUB1 | G14: Branch No. 1 | H14: 枝番１ | I14: E | K14: E | M14: E
A15: 10 | D15: itm_sub2 | E15: #MA.ITM_SUB2 | G15: Branch No. 2 | H15: 枝番２ | I15: E | K15: E | M15: E
A16: 10 | D16: itm_sub3 | E16: #MA.ITM_SUB3 | G16: Branch No. 3 | H16: 枝番３ | I16: E | K16: E | M16: E
A17: 10 | D17: mps_grp_cd | E17: #MA.MPS_GRP_CD | G17: MPS group cd. | H17: ＭＰＳグループＣＤ | I17: E | K17: E | M17: E
A18: 10 | D18: strg_loc_cd | E18: #MA.LOC_CD | G18: Storage location cd. | H18: 格納場所ＣＤ | I18: E | K18: E | M18: E
A19: 10 | D19: mfg_loc_cd | E19: #MA.LOC_CD | G19: Mfg. location cd. | H19: 製造場所ＣＤ | I19: E | K19: E | M19: E
A20: 10 | D20: sppl_cd | E20: #MA.BP_CD | G20: Supplier cd. | H20: 発注先ＣＤ | I20: E | K20: E | M20: E
A21: 10 | D21: maker_cd | E21: #MA.BP_CD | G21: Maker cd. | H21: メーカＣＤ | I21: E | K21: E | M21: E
A22: 10 | D22: rqst_loc_cd | E22: #MA.LOC_CD | G22: Requested location cd. | H22: 依頼先場所ＣＤ | I22: E | K22: E | M22: E
A23: 10 | D23: prod_rate | E23: #MA.PROD_RATE | G23: Disaggregation by day proportion ratio | H23: 日ばらし案分比率 | I23: E | K23: E | M23: E
... A29: 10 | D29: upd_cntr | E29: #MA.UPD_CNT | G29: Update counter | H29: 更新カウンタ | I29: E | K29: E | M29: E
D30: 詳細 :

Sheet Del01
A1: * | B1: * | D1: L | E1: 1
A2: * | D2: オペレーション実装仕様書 Operation Specification Implementation Sheet | E2: ModuleID : | F2: =IF(LogicCommon!C2="","",LogicCommon!C2) -> MA | G2: LogicID : | H2: =IF(LogicCommon!E2="","",LogicCommon!E2) -> MABSL0850 | I2: Ope.ID : | J2: Del01 | K2: Pj.ID : | L2: =IF(LogicCommon!G2="","",LogicCommon!G2) -> MC | M2: Ope.Body : | N2: "mcframe.serverMAUD.MAUDL6010.MAUDL_RLDeleter"
A3: * | D3: =IF(LogicCommon!A3="","",LogicCommon!A3) | E3: SubModuleID : | F3: =IF(LogicCommon!C3="","",LogicCommon!C3) -> MABS | G3: LogicClass : | H3: =IF(LogicCommon!E3="","",LogicCommon!E3) -> MABSL_MpsItmReg | I3: Ope.Method : | J3: @ | K3: SuperClassPj.ID : | L3: =IF(LogicCommon!G3="","",LogicCommon!G3) | M3: ReportID : | O3: Gene.Type : | P3: ALL
A4: * | E4: Version : | F4: 000000 | G4: LogicName : | H4: =IF(LogicCommon!E4="","",LogicCommon!E4) -> ＭＰＳ品目マスタ登録 | I4: Ope.Name : | J4: 削除 | K4: SuperLogicID : | L4: =IF(LogicCommon!G4="","",LogicCommon!G4) -> MA.MAUDL5010
A5: * | E5: ACType :
A6: * | D6: 概要 : | E6: 削除処理を行う | L6: ID | N6: ID
A7: # | I7: U | K7: o | L7: CALL_OPE01.chk01 | M7: o | N7: CALL_OPE01.del01
A8: # | D8: ブロック名 Block Name | E8: 型 Type | G8: super/share | H8: 対象ブロック名 Target Block Name | K8: TargetName | L8: OPE.MA.MABSL0850.MpsItm_DelChk01 | M8: TargetName | N8: OPE.MA.MABSL0850.MpsItm_Del01 | Q8: ブロック備考 Block Remarks
A9: # | D9: 項目名 Field Name | E9: 型 Type | F9: 桁 Digits | G9: フルネーム Full Name | H9: 日本語名 Japanese Name | I9: 上り項目 Request Message Field | J9: 下り項目 Response Message Field | O9: 条件および編集方法 Conditions and Editing Methods | Q9: 項目備考 Field Remarks
A10: # | K10: 上り項目 Request Message Field | L10: 下り項目 Response Message Field | M10: 上り項目 Request Message Field | N10: 下り項目 Response Message Field
A11: 10 | B11: * | D11: Del01_Dtl | E11: L | G11: $share$ | H11: MA.MABSL0850.MpsItm_Del01.MpsItm_Del01_Dtl | K11: MpsItm_DelChk01_Dtl | M11: MpsItm_Del01_Dtl
A12: 10 | D12: wg_cd | E12: #MA.WG_CD | G12: WG cd. | H12: ワーキンググループＣＤ | I12: E | K12: E | M12: E
A13: 10 | D13: itm_cd | E13: #MA.ITM_CD | G13: Item cd. | H13: 品目ＣＤ | I13: E | K13: E | M13: E
A14: 10 | D14: itm_sub1 | E14: #MA.ITM_SUB1 | G14: Branch No. 1 | H14: 枝番１ | I14: E | K14: E | M14: E
A15: 10 | D15: itm_sub2 | E15: #MA.ITM_SUB2 | G15: Branch No. 2 | H15: 枝番２ | I15: E | K15: E | M15: E
A16: 10 | D16: itm_sub3 | E16: #MA.ITM_SUB3 | G16: Branch No. 3 | H16: 枝番３ | I16: E | K16: E | M16: E
A17: 10 | D17: upd_cntr | E17: #MA.UPD_CNT | G17: Update counter | H17: 更新カウンタ | I17: E | K17: E | M17: E
D18: 詳細 :

Sheet 来歴
A1: 変更来歴
A3: Rev. | H3: 修正番号 | O3: 変更内容 | AQ3: 変更箇所
A4: 1 | O4: 初版
A5: 1.1 | O5: 英語の名称を追記 | AQ5: 全般
