Workbook

Sheet LogicCommon
A2: オペレーション実装仕様書 | B2: ModuleID : | C2: MS | D2: LogicID : | E2: MSBEL5200 | F2: Pj.ID : | G2: MC
B3: SubModuleID : | C3: MSBE | D3: LogicClass : | E3: MSBEL_XfrSchdService | F3: SuperClassPj.ID :
D4: LogicName : | E4: 移動・移送予定サービス | F4: SuperLogicID : | G4: MS.MSUDL5010
A5: 概要 : | B5: 移動・移送予定を登録するサービス
A6: 詳細 :

Sheet XfrSchd_Chk02
A1: * | B1: * | D1: L | E1: 1
A2: * | D2: オペレーション実装仕様書 Operation Specification Implementation Sheet | E2: ModuleID : | F2: =IF(LogicCommon!C2="","",LogicCommon!C2) -> MS | G2: LogicID : | H2: =IF(LogicCommon!E2="","",LogicCommon!E2) -> MSBEL5200 | I2: Ope.ID : | J2: XfrSchd_Chk02 | K2: Pj.ID : | L2: =IF(LogicCommon!G2="","",LogicCommon!G2) -> MC | M2: Ope.Body : | N2: "mcframe.serverMAUD.MAUDL5010.MAUDL_Operation"
A3: * | D3: =IF(LogicCommon!A3="","",LogicCommon!A3) | E3: SubModuleID : | F3: =IF(LogicCommon!C3="","",LogicCommon!C3) -> MSBE | G3: LogicClass : | H3: =IF(LogicCommon!E3="","",LogicCommon!E3) -> MSBEL_XfrSchdService | I3: Ope.Method : | J3: @ | K3: SuperClassPj.ID : | L3: =IF(LogicCommon!G3="","",LogicCommon!G3) | O3: Gene.Type : | P3: ALL
A4: * | E4: Version : | F4: 000000 | G4: LogicName : | H4: =IF(LogicCommon!E4="","",LogicCommon!E4) -> 移動・移送予定サービス | I4: Ope.Name : | J4: 更新(移動・移送予定) | K4: SuperLogicID : | L4: =IF(LogicCommon!G4="","",LogicCommon!G4) -> MS.MSUDL5010 | M4: ImplOpe.ID:
A5: * | E5: ACType :
A6: * | D6: 概要 : | E6: 更新対象の移動引当状況の進捗をチェックする。 | M6: ID | O6: ID | Q6: ID
A7: # | I7: U | K7: K | L7: o | N7: o | P7: o
A8: # | D8: ブロック名 Block Name | E8: 型 Type | G8: super/share | H8: 対象ブロック名 Target Block Name | L8: TargetName | N8: TargetName | P8: TargetName | T8: ブロック備考 Block Remarks
A9: # | D9: 項目名 Field Name | E9: 型 Type | F9: 桁 Digits | G9: フルネーム Full Name | H9: 日本語名 Japanese Name | I9: 上り項目 Request Message Field | J9: 下り項目 Response Message Field | R9: 条件および編集方法 Conditions and Editing Methods | T9: 項目備考 Field Remarks
A10: # | L10: 上り項目 Request Message Field | M10: 下り項目 Response Message Field | N10: 上り項目 Request Message Field | O10: 下り項目 Response Message Field | P10: 上り項目 Request Message Field | Q10: 下り項目 Response Message Field
A11: 10 | B11: * | D11: XfrSchdChk02_Dtl | E11: L
A12: 10 | D12: peg_no | E12: #MA.INT | G12: Pegging No. | H12: 紐付けＮＯ | I12: E | J12: E
A13: 10 | D13: data_crud_typ | E13: #MA.DATA_CRUD_TYP | G13: Data update type | H13: データ更新区分 | I13: E
A14: 10 | D14: xas | E14: R | F14: DBC:MS.MST_XFR_ALLOC_STS
A15: 10 | D15: xas.xfr_alloc_sts_no# | E15: RI | G15: Movement allocation status No. | H15: 移動引当状況ＮＯ | I15: E
A16: 10 | D16: xas.pr_sts_typ# | E16: RI | G16: Progress status type | H16: 進捗状況区分 | I16: E
A17: 10 | D17: xas.xfr_schd_no# | E17: RI | G17: Movement/transport schedule No. | H17: 移動・移送予定ＮＯ | I17: E
A18: 10 | D18: xas.xfr_inst_d_no# | E18: RI | G18: Movement order details No. | H18: 移動指図明細ＮＯ | I18: E
A19: 10 | D19: xas.trd_cd# | E19: RI | G19: Transaction cd. | H19: 取引ＣＤ | I19: E
A20: 10 | D20: xas.trd_ptn_typ# | E20: RI | G20: Transaction pattern type | H20: 取引パタン区分 | I20: E
A21: 10 | D21: xas.wg_cd# | E21: RI | G21: WG cd. | H21: ワーキンググループＣＤ | I21: E
A22: 10 | D22: xas.lg_grp_cd# | E22: RI | G22: Distribution group cd. | H22: 物流グループＣＤ | I22: E
A23: 10 | D23: xas.gi_loc_cd# | E23: RI | G23: GI location cd. | H23: 出庫場所ＣＤ | I23: E
A24: 10 | D24: xas.gi_str_ln_cd# | E24: RI | G24: GI rack/line cd. | H24: 出庫棚・ラインＣＤ | I24: E
A25: 10 | D25: xas.gi_stk_arrv_bp_cd# | E25: RI | G25: GI inventory arriving point cd. | H25: 出庫在庫着荷先ＣＤ | I25: E
A26: 10 | D26: xas.gr_loc_cd# | E26: RI | G26: GR location cd. | H26: 入庫場所ＣＤ | I26: E
... A78: 10 | D78: inst_rem_abort_flg | E78: #MA.FLG | G78: Cancel remaining order qty. flg. | H78: 指図残数打切ＦＬＧ | I78: E
A79: 10 | D79: gi_def_loc_cd | E79: #MA.LOC_CD | G79: GI default location cd. | H79: 出庫デフォルト場所ＣＤ | I79: - | J79: -
A80: 10 | D80: wk_peg_no | E80: #MA.INT | G80: Pegging No. for temporary work | H80: 一時作業用紐付けＮＯ | I80: - | J80: -
A81: 10 | D81: wk_ret_peg_no | E81: #MA.INT | G81: Pegging No. for temporary work (Returns) | H81: 一時作業用紐付けＮＯ（返品） | I81: - | J81: -
A82: 10 | D82: abort_only_flg | E82: #MA.FLG | G82: Correct cancel remaining only | H82: 打切のみ訂正 | I82: - | J82: -
A83: 10 | D83: err_flg | E83: #MA.FLG | G83: Error flg. | H83: エラーＦＬＧ | I83: - | J83: E
A85: 20 | B85: * | D85: XfrSchdChk02_Ctrl | E85: R
A86: 20 | D86: schd_flg | E86: #MA.FLG | G86: Schedule flg. | H86: 予定ＦＬＧ | I86: E | J86: -
A87: 20 | D87: inst_flg | E87: #MA.FLG | G87: Order flg. | H87: 指図ＦＬＧ | I87: E | J87: -
A88: 20 | D88: act_flg | E88: #MA.FLG | G88: Result flg. | H88: 実績ＦＬＧ | I88: E | J88: -
A89: 20 | D89: re_call_flg | E89: #MA.FLG | G89: Recursive call flg. | H89: 再帰呼出ＦＬＧ | I89: E | J89: -
A90: 20 | D90: alloc_off_flg | E90: #MA.FLG | I90: E | J90: -
A92: 30 | B92: * | D92: XfrSchdChk02_AllocRslt | E92: L
A93: 30 | D93: peg_no | E93: #MA.INT | G93: Pegging No. | H93: 紐付けＮＯ | I93: - | J93: E
...

Sheet XfrSchd_Chk04
A1: * | B1: * | D1: L | E1: 1
A2: * | D2: オペレーション実装仕様書 Operation Specification Implementation Sheet | E2: ModuleID : | F2: =IF(LogicCommon!C2="","",LogicCommon!C2) -> MS | G2: LogicID : | H2: =IF(LogicCommon!E2="","",LogicCommon!E2) -> MSBEL5200 | I2: Ope.ID : | J2: XfrSchd_Chk04 | K2: Pj.ID : | L2: =IF(LogicCommon!G2="","",LogicCommon!G2) -> MC | M2: Ope.Body : | N2: "mcframe.serverMAUD.MAUDL5010.MAUDL_Operation"
A3: * | D3: =IF(LogicCommon!A3="","",LogicCommon!A3) | E3: SubModuleID : | F3: =IF(LogicCommon!C3="","",LogicCommon!C3) -> MSBE | G3: LogicClass : | H3: =IF(LogicCommon!E3="","",LogicCommon!E3) -> MSBEL_XfrSchdService | I3: Ope.Method : | J3: @ | K3: SuperClassPj.ID : | L3: =IF(LogicCommon!G3="","",LogicCommon!G3) | O3: Gene.Type : | P3: ALL
A4: * | E4: Version : | F4: 000000 | G4: LogicName : | H4: =IF(LogicCommon!E4="","",LogicCommon!E4) -> 移動・移送予定サービス | I4: Ope.Name : | J4: 更新(移動・移送予定) | K4: SuperLogicID : | L4: =IF(LogicCommon!G4="","",LogicCommon!G4) -> MS.MSUDL5010 | M4: ImplOpe.ID:
A5: * | E5: ACType :
A6: * | D6: 概要 : | E6: 更新対象の移動・移送予定の進捗をチェックする。配送先が定まるかをチェックする。 | M6: ID | O6: ID | Q6: ID
A7: # | I7: U | K7: K | L7: o | N7: o | P7: o
A8: # | D8: ブロック名 Block Name | E8: 型 Type | G8: super/share | H8: 対象ブロック名 Target Block Name | L8: TargetName | N8: TargetName | P8: TargetName | T8: ブロック備考 Block Remarks
A9: # | D9: 項目名 Field Name | E9: 型 Type | F9: 桁 Digits | G9: フルネーム Full Name | H9: 日本語名 Japanese Name | I9: 上り項目 Request Message Field | J9: 下り項目 Response Message Field | R9: 条件および編集方法 Conditions and Editing Methods | T9: 項目備考 Field Remarks
A10: # | L10: 上り項目 Request Message Field | M10: 下り項目 Response Message Field | N10: 上り項目 Request Message Field | O10: 下り項目 Response Message Field | P10: 上り項目 Request Message Field | Q10: 下り項目 Response Message Field
A11: 10 | B11: * | D11: XfrSchdChk04_Dtl | E11: L
A12: 10 | D12: peg_no | E12: #MA.INT | G12: Pegging No. | H12: 紐付けＮＯ | I12: E | J12: E
A13: 10 | D13: data_crud_typ | E13: #MA.DATA_CRUD_TYP | G13: Data update type | H13: データ更新区分 | I13: E | J13: -
A14: 10 | D14: xs | E14: R | F14: DBC:MS.MST_XFR_SCHD
A15: 10 | D15: xs.xfr_schd_no# | E15: RI | G15: Movement/transport schedule No. | H15: 移動・移送予定ＮＯ | I15: E | J15: -
A16: 10 | D16: xs.xfr_src_typ# | E16: RI | G16: Source movement/transport type | H16: 移動・移送元区分 | I16: E | J16: -
A17: 10 | D17: xs.xfr_src_no# | E17: RI | G17: Source movement/transport No. | H17: 移動・移送元ＮＯ | I17: E | J17: -
A18: 10 | D18: xs.trd_cd# | E18: RI | G18: Transaction cd. | H18: 取引ＣＤ | I18: E | J18: -
A19: 10 | D19: xs.trd_ptn_typ# | E19: RI | G19: Transaction pattern type | H19: 取引パタン区分 | I19: E | J19: -
A20: 10 | D20: xs.gi_lg_grp_cd# | E20: RI | G20: GI distribution group cd. | H20: 出庫物流グループＣＤ | I20: E | J20: -
A21: 10 | D21: xs.gi_loc_cd# | E21: RI | G21: GI location cd. | H21: 出庫場所ＣＤ | I21: E | J21: -
A22: 10 | D22: xs.gi_str_ln_cd# | E22: RI | G22: GI rack/line cd. | H22: 出庫棚ラインＣＤ | I22: E | J22: -
A23: 10 | D23: xs.gi_stk_arrv_bp_cd# | E23: RI | G23: GI inventory arriving point cd. | H23: 出庫在庫着荷先ＣＤ | I23: E | J23: -
A24: 10 | D24: xs.gr_lg_grp_cd# | E24: RI | G24: GR distribution group cd. | H24: 入庫物流グループＣＤ | I24: - | J24: -
A25: 10 | D25: xs.gr_loc_cd# | E25: RI | G25: GR location cd. | H25: 入庫場所ＣＤ | I25: E | J25: -
A26: 10 | D26: xs.gr_str_ln_cd# | E26: RI | G26: GR rack/line cd. | H26: 入庫棚ラインＣＤ | I26: E | J26: -
... A113: 10 | D113: err_flg | E113: #MA.FLG | G113: Error flg. | H113: エラーＦＬＧ | I113: - | J113: E
A115: 20 | B115: * | D115: XfrSchdChk04_Ctrl | E115: R
A116: 20 | D116: screen_flg | E116: #MA.FLG | G116: Screen call flg. | H116: 画面呼出ＦＬＧ | I116: E | J116: -
A117: 20 | D117: alloc_check_exec_flg | E117: #MA.FLG | G117: Allocatable number check execution flg. | H117: 引当可能数チェック実行ＦＬＧ | I117: E | J117: -
A118: 20 | D118: file_imp_flg | E118: #MA.FLG | G118: Import file | H118: ファイル入力 | I118: E | J118: -
A120: 30 | B120: * | D120: XfrSchdChk04_AllocRslt | E120: L | G120: $share$ | H120: MS.MSBEL5200.XfrSchd_Chk04.XfrSchdChk04_Dtl
A121: 30 | D121: peg_no | E121: #MA.INT | G121: Pegging No. | H121: 紐付けＮＯ | I121: - | J121: E
A122: 30 | D122: xs | E122: R | F122: DBC:MS.MST_XFR_SCHD
A123: 30 | D123: xs.lot_no# | E123: RI | G123: Request lot No. | H123: 依頼ロットＮＯ | I123: - | J123: E
A124: 30 | D124: xs.sublot_no# | E124: RI | G124: Request sublot No. | H124: 依頼サブロットＮＯ | I124: - | J124: E
A125: 30 | D125: xs.ver_no# | E125: RI | G125: Request version No. | H125: 依頼版ＮＯ | I125: - | J125: E
A126: 30 | D126: xs.sno1# | E126: RI | G126: Allocation SEIBAN No. 1 | H126: 引当手配ＮＯ１ | I126: - | J126: E
A127: 30 | D127: xs.sno2# | E127: RI | G127: Allocation SEIBAN No. 2 | H127: 引当手配ＮＯ２ | I127: - | J127: E
A128: 30 | D128: xs.sno3# | E128: RI | G128: Allocation SEIBAN No. 3 | H128: 引当手配ＮＯ３ | I128: - | J128: E
...

Sheet XfrSchd_Upd01
A1: * | B1: * | D1: L | E1: 1
A2: * | D2: オペレーション実装仕様書 Operation Specification Implementation Sheet | E2: ModuleID : | F2: =IF(LogicCommon!C2="","",LogicCommon!C2) -> MS | G2: LogicID : | H2: =IF(LogicCommon!E2="","",LogicCommon!E2) -> MSBEL5200 | I2: Ope.ID : | J2: XfrSchd_Upd01 | K2: Pj.ID : | L2: =IF(LogicCommon!G2="","",LogicCommon!G2) -> MC | M2: Ope.Body : | N2: "mcframe.serverMAUD.MAUDL5010.MAUDL_Operation"
A3: * | D3: =IF(LogicCommon!A3="","",LogicCommon!A3) | E3: SubModuleID : | F3: =IF(LogicCommon!C3="","",LogicCommon!C3) -> MSBE | G3: LogicClass : | H3: =IF(LogicCommon!E3="","",LogicCommon!E3) -> MSBEL_XfrSchdService | I3: Ope.Method : | J3: @ | K3: SuperClassPj.ID : | L3: =IF(LogicCommon!G3="","",LogicCommon!G3) | O3: Gene.Type : | P3: ALL
A4: * | E4: Version : | F4: 000000 | G4: LogicName : | H4: =IF(LogicCommon!E4="","",LogicCommon!E4) -> 移動・移送予定サービス | I4: Ope.Name : | J4: 更新(移動・移送予定) | K4: SuperLogicID : | L4: =IF(LogicCommon!G4="","",LogicCommon!G4) -> MS.MSUDL5010 | M4: ImplOpe.ID:
A5: * | E5: ACType :
A6: * | D6: 概要 : | E6: 移動・移送予定にデータを登録する。移動・移送予定のデータを更新・削除する。 | M6: ID | O6: ID | Q6: ID
A7: # | I7: U | K7: K | L7: o | N7: o | P7: o
A8: # | D8: ブロック名 Block Name | E8: 型 Type | G8: super/share | H8: 対象ブロック名 Target Block Name | L8: TargetName | N8: TargetName | P8: TargetName | T8: ブロック備考 Block Remarks
A9: # | D9: 項目名 Field Name | E9: 型 Type | F9: 桁 Digits | G9: フルネーム Full Name | H9: 日本語名 Japanese Name | I9: 上り項目 Request Message Field | J9: 下り項目 Response Message Field | R9: 条件および編集方法 Conditions and Editing Methods | T9: 項目備考 Field Remarks
A10: # | L10: 上り項目 Request Message Field | M10: 下り項目 Response Message Field | N10: 上り項目 Request Message Field | O10: 下り項目 Response Message Field | P10: 上り項目 Request Message Field | Q10: 下り項目 Response Message Field
A11: 10 | B11: * | D11: XfrSchd_Dtl | E11: L
A12: 10 | D12: peg_no | E12: #MA.INT | G12: Pegging No. | H12: 紐付けＮＯ | I12: E | J12: E
A13: 10 | D13: data_crud_typ | E13: #MA.DATA_CRUD_TYP | G13: Data update type | H13: データ更新区分 | I13: E | J13: E
A14: 10 | D14: xs | E14: R | F14: DBC:MS.MST_XFR_SCHD
A15: 10 | D15: xs.xfr_schd_no# | E15: RI | G15: Movement/transport schedule No. | H15: 移動・移送予定ＮＯ | I15: E | J15: E
A16: 10 | D16: xs.xfr_src_typ# | E16: RI | G16: Source movement/transport type | H16: 移動・移送元区分 | I16: E | J16: E
A17: 10 | D17: xs.xfr_src_no# | E17: RI | G17: Source movement/transport No. | H17: 移動・移送元ＮＯ | I17: E | J17: E
A18: 10 | D18: xs.trd_cd# | E18: RI | G18: Transaction cd. | H18: 取引ＣＤ | I18: E
A19: 10 | D19: xs.trd_ptn_typ# | E19: RI | G19: Transaction pattern type | H19: 取引パタン区分 | I19: E
A20: 10 | D20: xs.gi_wg_cd# | E20: RI | G20: GI WG cd. | H20: 出庫ワーキンググループＣＤ | I20: E
A21: 10 | D21: xs.gi_lg_grp_cd# | E21: RI | G21: GI distribution group cd. | H21: 出庫物流グループＣＤ | I21: E
A22: 10 | D22: xs.gi_loc_cd# | E22: RI | G22: GI location cd. | H22: 出庫場所ＣＤ | I22: E
A23: 10 | D23: xs.gi_str_ln_cd# | E23: RI | G23: GI rack/line cd. | H23: 出庫棚・ラインＣＤ | I23: E
A24: 10 | D24: xs.gi_stk_arrv_bp_cd# | E24: RI | G24: GI inventory arriving point cd. | H24: 出庫在庫着荷先ＣＤ | I24: E
A25: 10 | D25: xs.gr_wg_cd# | E25: RI | G25: GR WG cd. | H25: 入庫ワーキンググループＣＤ | I25: E
A26: 10 | D26: xs.gr_lg_grp_cd# | E26: RI | G26: GR distribution group cd. | H26: 入庫物流グループＣＤ | I26: E
A27: 10 | D27: xs.gr_loc_cd# | E27: RI | G27: GR location cd. | H27: 入庫場所ＣＤ | I27: E
A28: 10 | D28: xs.gr_str_ln_cd# | E28: RI | G28: GR rack/line cd. | H28: 入庫棚・ラインＣＤ | I28: E
A29: 10 | D29: xs.gr_stk_arrv_bp_cd# | E29: RI | G29: GR inventory arriving point cd. | H29: 入庫在庫着荷先ＣＤ | I29: E
... A136: 10 | D136: alloc_flg | E136: #MA.FLG | G136: Location allocation flg. | H136: 場所引当ＦＬＧ | I136: E
L137: 上り項目 Request Message Field | M137: 下り項目 Response Message Field | N137: 上り項目 Request Message Field | O137: 下り項目 Response Message Field | P137: 上り項目 Request Message Field | Q137: 下り項目 Response Message Field
A138: 20 | B138: * | D138: XfrSchd_Ctrl | E138: R
A139: 20 | D139: screen_flg | E139: #MA.FLG | G139: Screen call flg. | H139: 画面呼出ＦＬＧ | I139: E
L140: 上り項目 Request Message Field | M140: 下り項目 Response Message Field | N140: 上り項目 Request Message Field | O140: 下り項目 Response Message Field | P140: 上り項目 Request Message Field | Q140: 下り項目 Response Message Field
A141: 30 | B141: * | D141: XfrSchd_AllocRslt | E141: L | G141: $share$ | H141: MS.MSBEL5200.XfrSchd_Chk04.XfrSchdChk04_Dtl
A142: 30 | D142: peg_no | E142: #MA.INT | G142: Pegging No. | H142: 紐付けＮＯ | I142: E
A143: 30 | D143: xs | E143: R | F143: DBC:MS.MST_XFR_SCHD
A144: 30 | D144: xs.lot_no# | E144: RI | G144: Request lot No. | H144: 依頼ロットＮＯ | I144: E
A145: 30 | D145: xs.sublot_no# | E145: RI | G145: Request sublot No. | H145: 依頼サブロットＮＯ | I145: E
A146: 30 | D146: xs.ver_no# | E146: RI | G146: Request version No. | H146: 依頼版ＮＯ | I146: E
...

Sheet XfrSchd_Upd02
A1: * | B1: * | D1: L | E1: 1
A2: * | D2: オペレーション実装仕様書 Operation Specification Implementation Sheet | E2: ModuleID : | F2: =IF(LogicCommon!C2="","",LogicCommon!C2) -> MS | G2: LogicID : | H2: =IF(LogicCommon!E2="","",LogicCommon!E2) -> MSBEL5200 | I2: Ope.ID : | J2: XfrSchd_Upd02 | K2: Pj.ID : | L2: =IF(LogicCommon!G2="","",LogicCommon!G2) -> MC | M2: Ope.Body : | N2: "mcframe.serverMAUD.MAUDL5010.MAUDL_Operation"
A3: * | D3: =IF(LogicCommon!A3="","",LogicCommon!A3) | E3: SubModuleID : | F3: =IF(LogicCommon!C3="","",LogicCommon!C3) -> MSBE | G3: LogicClass : | H3: =IF(LogicCommon!E3="","",LogicCommon!E3) -> MSBEL_XfrSchdService | I3: Ope.Method : | J3: @ | K3: SuperClassPj.ID : | L3: =IF(LogicCommon!G3="","",LogicCommon!G3) | O3: Gene.Type : | P3: ALL
A4: * | E4: Version : | F4: 000000 | G4: LogicName : | H4: =IF(LogicCommon!E4="","",LogicCommon!E4) -> 移動・移送予定サービス | I4: Ope.Name : | J4: 更新(移動・移送進捗) | K4: SuperLogicID : | L4: =IF(LogicCommon!G4="","",LogicCommon!G4) -> MS.MSUDL5010 | M4: ImplOpe.ID:
A5: * | E5: ACType :
A6: * | D6: 概要 : | E6: 移動引当状況にデータを登録する。移動引当状況のデータを更新・削除する。 | M6: ID | O6: ID | Q6: ID
A7: # | I7: U | K7: K | L7: o | N7: o | P7: o
A8: # | D8: ブロック名 Block Name | E8: 型 Type | G8: super/share | H8: 対象ブロック名 Target Block Name | L8: TargetName | N8: TargetName | P8: TargetName | T8: ブロック備考 Block Remarks
A9: # | D9: 項目名 Field Name | E9: 型 Type | F9: 桁 Digits | G9: フルネーム Full Name | H9: 日本語名 Japanese Name | I9: 上り項目 Request Message Field | J9: 下り項目 Response Message Field | R9: 条件および編集方法 Conditions and Editing Methods | T9: 項目備考 Field Remarks
A10: # | L10: 上り項目 Request Message Field | M10: 下り項目 Response Message Field | N10: 上り項目 Request Message Field | O10: 下り項目 Response Message Field | P10: 上り項目 Request Message Field | Q10: 下り項目 Response Message Field
A11: 10 | B11: * | D11: XfrPr_Dtl | E11: L
A12: 10 | D12: peg_no | E12: #MA.INT | G12: Pegging No. | H12: 紐付けＮＯ | I12: E | J12: E
A13: 10 | D13: data_crud_typ | E13: #MA.DATA_CRUD_TYP | G13: Data update type | H13: データ更新区分 | I13: E
A14: 10 | D14: xas | E14: R | F14: DBC:MS.MST_XFR_ALLOC_STS
A15: 10 | D15: xas.xfr_alloc_sts_no# | E15: RI | G15: Movement allocation status No. | H15: 移動引当状況ＮＯ | I15: E | J15: E
A16: 10 | D16: xas.pr_sts_typ# | E16: RI | G16: Progress status type | H16: 進捗状況区分 | I16: E
A17: 10 | D17: xas.xfr_schd_no# | E17: RI | G17: Movement/transport schedule No. | H17: 移動・移送予定ＮＯ | I17: E
A18: 10 | D18: xas.xfr_inst_d_no# | E18: RI | G18: Movement order details No. | H18: 移動指図明細ＮＯ | I18: E
A19: 10 | D19: xas.trd_cd# | E19: RI | G19: Transaction cd. | H19: 取引ＣＤ | I19: E
A20: 10 | D20: xas.trd_ptn_typ# | E20: RI | G20: Transaction pattern type | H20: 取引パタン区分 | I20: E
A21: 10 | D21: xas.wg_cd# | E21: RI | G21: WG cd. | H21: ワーキンググループＣＤ | I21: E
A22: 10 | D22: xas.lg_grp_cd# | E22: RI | G22: Distribution group cd. | H22: 物流グループＣＤ | I22: E
A23: 10 | D23: xas.gi_loc_cd# | E23: RI | G23: GI location cd. | H23: 出庫場所ＣＤ | I23: E
A24: 10 | D24: xas.gi_str_ln_cd# | E24: RI | G24: GI rack/line cd. | H24: 出庫棚・ラインＣＤ | I24: E
A25: 10 | D25: xas.gi_stk_arrv_bp_cd# | E25: RI | G25: GI inventory arriving point cd. | H25: 出庫在庫着荷先ＣＤ | I25: E
A26: 10 | D26: xas.gr_loc_cd# | E26: RI | G26: GR location cd. | H26: 入庫場所ＣＤ | I26: E
A27: 10 | D27: xas.gr_str_ln_cd# | E27: RI | G27: GR rack/line cd. | H27: 入庫棚・ラインＣＤ | I27: E
... A89: 10 | D89: inst_rem_abort_flg | E89: #MA.FLG | G89: Cancel remaining order qty. flg. | H89: 指図残数打切ＦＬＧ | I89: E
A90: 10 | D90: prov_schd_no | E90: #MA.PROV_SCHD_NO | G90: Supply schedule No. | H90: 支給予定ＮＯ | I90: - | J90: E
A91: 10 | D91: ret_prov_schd_no | E91: #MA.PROV_SCHD_NO | G91: Supply schedule No. (Return) | H91: 支給予定ＮＯ（返品） | I91: - | J91: E
A92: 10 | D92: xs | E92: R | F92: DBC:MS.MST_XFR_SCHD
A93: 10 | D93: xs.xrate_inpt_flg# | E93: RI | G93: Set exchange rate | H93: 為替レート指定 | I93: E
A94: 10 | D94: xs.xrate# | E94: RI | G94: Exchange rate | H94: 為替レート | I94: E
A95: 10 | D95: xs.ptax_xrate_inpt_flg# | E95: RI | G95: Set tax exchange rate | H95: 納税為替レート指定 | I95: E
A96: 10 | D96: xs.ptax_xrate# | E96: RI | G96: Taxpaying exchange rate | H96: 納税為替レート | I96: E
A97: 10 | D97: xs.trd_cur_cd# | E97: RI | G97: Transaction currency cd. | H97: 取引通貨ＣＤ | I97: E
A98: 10 | D98: xs.tax_fix_flg# | E98: RI | G98: Set tax | H98: 税指定 | I98: E
A99: 10 | D99: xs.tax_cd# | E99: RI | G99: Tax cd. | H99: 税ＣＤ | I99: E
A100: 10 | D100: xs.trd_cur_upri# | E100: RI | G100: Unit price (Transaction currency) | H100: 取引通貨単価 | I100: E
A101: 10 | D101: xs.trd_cur_amt# | E101: RI | G101: Amount (Transaction currency) | H101: 取引通貨金額 | I101: -
...

Sheet XfrSchd_Upd03
A1: * | B1: * | D1: L | E1: 1
A2: * | D2: オペレーション実装仕様書 Operation Specification Implementation Sheet | E2: ModuleID : | F2: =IF(LogicCommon!C2="","",LogicCommon!C2) -> MS | G2: LogicID : | H2: =IF(LogicCommon!E2="","",LogicCommon!E2) -> MSBEL5200 | I2: Ope.ID : | J2: XfrSchd_Upd03 | K2: Pj.ID : | L2: =IF(LogicCommon!G2="","",LogicCommon!G2) -> MC | M2: Ope.Body : | N2: "mcframe.serverMAUD.MAUDL5010.MAUDL_Operation"
A3: * | D3: =IF(LogicCommon!A3="","",LogicCommon!A3) | E3: SubModuleID : | F3: =IF(LogicCommon!C3="","",LogicCommon!C3) -> MSBE | G3: LogicClass : | H3: =IF(LogicCommon!E3="","",LogicCommon!E3) -> MSBEL_XfrSchdService | I3: Ope.Method : | J3: @ | K3: SuperClassPj.ID : | L3: =IF(LogicCommon!G3="","",LogicCommon!G3) | O3: Gene.Type : | P3: ALL
A4: * | E4: Version : | F4: 000000 | G4: LogicName : | H4: =IF(LogicCommon!E4="","",LogicCommon!E4) -> 移動・移送予定サービス | I4: Ope.Name : | J4: 更新(依頼元訂正) | K4: SuperLogicID : | L4: =IF(LogicCommon!G4="","",LogicCommon!G4) -> MS.MSUDL5010 | M4: ImplOpe.ID:
A5: * | E5: ACType :
A6: * | D6: 概要 : | E6: 移動・移送予定の依頼元訂正ＦＬＧを更新する。 | M6: ID | O6: ID | Q6: ID
A7: # | I7: U | K7: K | L7: o | N7: o | P7: o
A8: # | D8: ブロック名 Block Name | E8: 型 Type | G8: super/share | H8: 対象ブロック名 Target Block Name | L8: TargetName | N8: TargetName | P8: TargetName | T8: ブロック備考 Block Remarks
A9: # | D9: 項目名 Field Name | E9: 型 Type | F9: 桁 Digits | G9: フルネーム Full Name | H9: 日本語名 Japanese Name | I9: 上り項目 Request Message Field | J9: 下り項目 Response Message Field | R9: 条件および編集方法 Conditions and Editing Methods | T9: 項目備考 Field Remarks
A10: # | L10: 上り項目 Request Message Field | M10: 下り項目 Response Message Field | N10: 上り項目 Request Message Field | O10: 下り項目 Response Message Field | P10: 上り項目 Request Message Field | Q10: 下り項目 Response Message Field
A11: 10 | B11: * | D11: XfrSchdMod_Dtl | E11: L
A12: 10 | D12: xfr_src_typ | E12: #MS.XFR_SRC_TYP | G12: Source movement/transport type | H12: 移動・移送元区分 | I12: E
A13: 10 | D13: xfr_src_no | E13: #MA.XFR_SRC_NO | G13: Source movement/transport No. | H13: 移動・移送元ＮＯ | I13: E
A14: 10 | D14: xfr_schd_no | E14: #MA.XFR_SCHD_NO | G14: Movement/transport schedule No. | H14: 移動・移送予定ＮＯ | I14: E
A15: 10 | D15: rqst_mod_flg | E15: #MA.FLG | G15: Edited by request source flg. | H15: 依頼元訂正ＦＬＧ | I15: E
A16: 10 | D16: rqst_can_flg | E16: #MA.FLG | G16: Unpegged flg. | H16: 紐切れＦＬＧ | I16: E
D17: 詳細 :

Sheet XfrSchd_Sprt01
A1: * | B1: * | D1: L | E1: 1
A2: * | D2: オペレーション実装仕様書 Operation Specification Implementation Sheet | E2: ModuleID : | F2: =IF(LogicCommon!C2="","",LogicCommon!C2) -> MS | G2: LogicID : | H2: =IF(LogicCommon!E2="","",LogicCommon!E2) -> MSBEL5200 | I2: Ope.ID : | J2: XfrSchd_Sprt01 | K2: Pj.ID : | L2: =IF(LogicCommon!G2="","",LogicCommon!G2) -> MC | M2: Ope.Body : | N2: "mcframe.serverMAUD.MAUDL5010.MAUDL_Operation"
A3: * | D3: =IF(LogicCommon!A3="","",LogicCommon!A3) | E3: SubModuleID : | F3: =IF(LogicCommon!C3="","",LogicCommon!C3) -> MSBE | G3: LogicClass : | H3: =IF(LogicCommon!E3="","",LogicCommon!E3) -> MSBEL_XfrSchdService | I3: Ope.Method : | J3: @ | K3: SuperClassPj.ID : | L3: =IF(LogicCommon!G3="","",LogicCommon!G3) | O3: Gene.Type : | P3: ALL
A4: * | E4: Version : | F4: 000000 | G4: LogicName : | H4: =IF(LogicCommon!E4="","",LogicCommon!E4) -> 移動・移送予定サービス | I4: Ope.Name : | J4: 輸出判定補助 | K4: SuperLogicID : | L4: =IF(LogicCommon!G4="","",LogicCommon!G4) -> MS.MSUDL5010 | M4: ImplOpe.ID:
A5: * | E5: ACType :
A6: * | D6: 概要 : | E6: 輸出の場合に配送先や輸出完了予定日を計算する。 | M6: ID | O6: ID | Q6: ID
A7: # | I7: U | K7: K | L7: o | N7: o | P7: o
A8: # | D8: ブロック名 Block Name | E8: 型 Type | G8: super/share | H8: 対象ブロック名 Target Block Name | L8: TargetName | N8: TargetName | P8: TargetName | T8: ブロック備考 Block Remarks
A9: # | D9: 項目名 Field Name | E9: 型 Type | F9: 桁 Digits | G9: フルネーム Full Name | H9: 日本語名 Japanese Name | I9: 上り項目 Request Message Field | J9: 下り項目 Response Message Field | R9: 条件および編集方法 Conditions and Editing Methods | T9: 項目備考 Field Remarks
A10: # | L10: 上り項目 Request Message Field | M10: 下り項目 Response Message Field | N10: 上り項目 Request Message Field | O10: 下り項目 Response Message Field | P10: 上り項目 Request Message Field | Q10: 下り項目 Response Message Field
A11: 10 | B11: * | D11: XfrSchdEx_Dtl | E11: L
A12: 10 | D12: peg_no | E12: #MA.INT | G12: Pegging No. | H12: 紐付けＮＯ | I12: E | J12: E
A13: 10 | D13: gi_lg_grp_cd | E13: #MA.LG_GRP_CD | G13: GI distribution group cd. | H13: 出庫物流グループＣＤ | I13: E
A14: 10 | D14: gi_loc_cd | E14: #MA.LOC_CD | G14: GI location cd. | H14: 出庫場所ＣＤ | I14: E
A15: 10 | D15: gr_lg_grp_cd | E15: #MA.LG_GRP_CD | G15: GR distribution group cd. | H15: 入庫物流グループＣＤ | I15: E
A16: 10 | D16: gr_loc_cd | E16: #MA.LOC_CD | G16: GR location cd. | H16: 入庫場所ＣＤ | I16: E
A17: 10 | D17: itm_cd | E17: #MA.ITM_CD | G17: Item cd. | H17: 品目ＣＤ | I17: E
A18: 10 | D18: itm_sub1 | E18: #MA.ITM_SUB1 | G18: Branch No. 1 | H18: 枝番１ | I18: E
A19: 10 | D19: itm_sub2 | E19: #MA.ITM_SUB2 | G19: Branch No. 2 | H19: 枝番２ | I19: E
A20: 10 | D20: itm_sub3 | E20: #MA.ITM_SUB3 | G20: Branch No. 3 | H20: 枝番３ | I20: E
A21: 10 | D21: ship_term_cd | E21: #MA.SHIP_TERM_CD | G21: Shipping conditions cd. | H21: 出荷条件ＣＤ | I21: E | J21: E
A22: 10 | D22: gr_schd_dt | E22: #MA.DT | G22: Scheduled GR date | H22: 入庫予定日 | I22: E
A23: 10 | D23: gi_schd_dt | E23: #MA.DT | G23: Scheduled GI date | H23: 出庫予定日 | I23: E
A24: 10 | D24: gi_stk_arrv_bp_cd | E24: #MA.BP_CD | G24: GI inventory arriving point | H24: 出庫在庫着荷先 | J24: E
A25: 10 | D25: iv_trd_flg | E25: #MA.FLG | G25: For invoice transaction flg. | H25: インボイス取引対象ＦＬＧ | J25: E
A26: 10 | D26: ex_cmpl_schd_dt | E26: #MA.DT | G26: Scheduled export completion date | H26: 輸出完了予定日 | J26: E
A27: 10 | D27: ship_to_id_typ | E27: #MS.SHIP_TO_ID_TYP | G27: Receiving point identification type | H27: 送付先識別区分 | J27: E
A28: 10 | D28: ship_to_id_cd | E28: #MS.SHIP_TO_ID_CD | G28: Receiving point identification cd. | H28: 送付先識別ＣＤ | J28: -
A29: 10 | D29: ship_to_lg_grp_cd | E29: #MA.LG_GRP_CD | G29: Receiving point distribution group cd. | H29: 送付先物流グループＣＤ | J29: -
A30: 10 | D30: tdlv_cd | E30: #MA.BP_CD | G30: Receiving point cd. | H30: 配送先ＣＤ | J30: E
A31: 10 | D31: via_dlv_typ | E31: #MA.VIA_DLV_TYP | G31: Receiving point stopover type | H31: 配送先経由区分 | J31: E
A32: 10 | D32: io_schd_typ | E32: #MS.IO_SCHD_TYP | G32: GR/GI schedule type | H32: 受払予定区分 | J32: E
A33: 10 | D33: trd_ptn_typ | E33: #MA.TRD_PTN_TYP | G33: Transaction pattern type | H33: 取引パタン区分 | J33: E
A34: 10 | D34: err_flg | E34: #MA.FLG | G34: Error flg. | H34: エラーＦＬＧ | J34: E
D35: 詳細 :

Sheet 来歴
A1: 変更来歴
A3: Rev. | H3: 修正番号 | O3: 変更内容 | AQ3: 変更箇所
A4: 1 | O4: 初版
A5: 1.1 | H5: MS7032#023 | O5: XfrSchdChk02_AllocRsltプロックを追加 | AQ5: XfrSchd_Chk02シート
A6: 1.2 | O6: 英語の名称を追記 | AQ6: 全般
