Workbook

Sheet LogicCommon
A2: ロジック共通定義 | B2: ModuleID : | C2: MS | D2: LogicID : | E2: MSBEL1010 | F2: Pj.ID : | G2: MC
B3: SubModuleID : | C3: MSBE | D3: LogicClass : | E3: MSBEL_XfrInstReg | F3: SuperClassPj.ID :
D4: LogicName : | E4: 移動指図登録 | F4: SuperLogicID : | G4: MS.MSUDL5010
A5: 概要 :
A6: 詳細 :

Sheet Srch01
A1: * | B1: * | D1: L | E1: 1
A2: * | D2: オペレーション実装仕様書 Operation Specification Implementation Sheet | E2: ModuleID : | F2: =IF(LogicCommon!C2="","",LogicCommon!C2) -> MS | G2: LogicID : | H2: =IF(LogicCommon!E2="","",LogicCommon!E2) -> MSBEL1010 | I2: Ope.ID : | J2: Srch01 | K2: Pj.ID : | L2: =IF(LogicCommon!G2="","",LogicCommon!G2) -> MC | M2: Ope.Body : | N2: "mcframe.serverMAUD.MAUDL5010.MAUDL_Searcher"
A3: * | E3: SubModuleID : | F3: =IF(LogicCommon!C3="","",LogicCommon!C3) -> MSBE | G3: LogicClass : | H3: =IF(LogicCommon!E3="","",LogicCommon!E3) -> MSBEL_XfrInstReg | I3: Ope.Method : | J3: Srch01 | K3: SuperClassPj.ID : | L3: =IF(LogicCommon!G3="","",LogicCommon!G3) | O3: Gene.Type : | P3: ALL
A4: * | E4: Version : | F4: 000000 | G4: LogicName : | H4: =IF(LogicCommon!E4="","",LogicCommon!E4) -> 移動指図登録 | I4: Ope.Name : | J4: 予定検索 | K4: SuperLogicID : | L4: =IF(LogicCommon!G4="","",LogicCommon!G4) -> MS.MSUDL5010 | M4: ImplOpe.ID:
A5: * | E5: ACType :
A6: * | D6: 概要 : | E6: 移動・移送予定を検索する | M6: ID | O6: ID
A7: # | I7: U | K7: K | L7: o | N7: o
A8: # | D8: ブロック名 Block Name | E8: 型 Type | G8: super/share | H8: 対象ブロック名 Target Block Name | K8: CONST | L8: TargetName | N8: TargetName | R8: ブロック備考 Block Remarks
A9: # | D9: 項目名 Field Name | E9: 型 Type | F9: 桁 Digits | G9: フルネーム Full Name | H9: 日本語名 Japanese Name | I9: 上り項目 Request Message Field | J9: 下り項目 Response Message Field | P9: 条件および編集方法 Conditions and Editing Methods | R9: 項目備考 Field Remarks
A10: # | L10: 上り項目 Request Message Field | M10: 下り項目 Response Message Field | N10: 上り項目 Request Message Field | O10: 下り項目 Response Message Field
A11: 10 | B11: * | D11: Srch01_Cnd | E11: R
A12: 10 | D12: srch_tgt_no | E12: #MS.SRCH_TGT_NO | G12: Search target No. | H12: 検索対象ＮＯ | I12: E | J12: -
L13: 上り項目 Request Message Field | M13: 下り項目 Response Message Field | N13: 上り項目 Request Message Field | O13: 下り項目 Response Message Field
A14: 20 | B14: * | D14: Srch01_Hdr | E14: R
A15: 20 | D15: trd_cd | E15: #MA.TRD_CD | G15: Transaction cd. | H15: 取引ＣＤ | I15: - | J15: E
A16: 20 | D16: trd_nm | E16: #MA.TRD_NM | G16: Transaction name | H16: 取引名 | I16: - | J16: E
A17: 20 | D17: trd_ptn_typ | E17: #MA.TRD_PTN_TYP | G17: Transaction pattern type | H17: 取引パタン区分 | I17: - | J17: E
A18: 20 | D18: xfr_inst_no | E18: #MA.XFR_INST_NO | G18: Movement order No. | H18: 移動指図ＮＯ | I18: - | J18: -
A19: 20 | D19: gr_loc_cd | E19: #MA.LOC_CD | G19: GR location cd. | H19: 入庫場所ＣＤ | I19: - | J19: E
A20: 20 | D20: gr_loc_nm | E20: #MA.LOC_NM | G20: GR location name | H20: 入庫場所名 | I20: - | J20: E
A21: 20 | D21: gr_str_ln_tgt_flg | E21: #MA.FLG | G21: For GR rack/line | H21: 入庫棚・ライン対象 | I21: - | J21: E
A22: 20 | D22: gr_sppl_cd | E22: #MA.BP_CD | G22: GR supplier cd. | H22: 入庫発注先ＣＤ | I22: - | J22: E
A23: 20 | D23: gr_cur_cd | E23: #MA.CUR_CD | G23: GR currency cd. | H23: 入庫通貨ＣＤ | I23: - | J23: E
A24: 20 | D24: gr_onr_prsppl_flg | E24: #MA.FLG | G24: GR chargeable supplier | H24: 入庫有償支給先 | I24: - | J24: E
A25: 20 | D25: gr_prov_basis_typ | E25: #MA.PROV_BASIS_TYP | G25: GR supply recording type | H25: 入庫支給計上区分 | I25: - | J25: E
A26: 20 | D26: wg_cd | E26: #MA.WG_CD | G26: WG cd. | H26: ワーキンググループＣＤ | I26: - | J26: E
... A60: 20 | D60: upd_srv_req_no | E60: #MA.SRV_REQ_NO | G60: Update request No. | H60: 更新リクエストＮＯ | I60: - | J60: E
A62: 30 | B62: * | D62: Srch01_Dtl | E62: L
A63: 30 | D63: pr_sts_typ | E63: #MS.PR_STS_TYP | G63: Progress status type | H63: 進捗状況区分 | I63: - | J63: E | K63: MSC_PR_STS_TYP
A64: 30 | D64: pr_sts_typ_nm | E64: #MS.PR_STS_TYP_NM | G64: Progress status type name | H64: 進捗状況区分名 | I64: - | J64: E
A65: 30 | D65: itm_cd | E65: #MA.ITM_CD | G65: Item cd. | H65: 品目ＣＤ | I65: - | J65: E
A66: 30 | D66: itm_sub1 | E66: #MA.ITM_SUB1 | G66: Branch No. 1 | H66: 枝番１ | I66: - | J66: E
A67: 30 | D67: itm_sub2 | E67: #MA.ITM_SUB2 | G67: Branch No. 2 | H67: 枝番２ | I67: - | J67: E
A68: 30 | D68: itm_sub3 | E68: #MA.ITM_SUB3 | G68: Branch No. 3 | H68: 枝番３ | I68: - | J68: E
A69: 30 | D69: itm_nm | E69: #MA.ITM_NM | G69: Item name | H69: 品名 | I69: - | J69: E
A70: 30 | D70: lot_mng_typ | E70: #MA.LOT_MNG_TYP | G70: Lot management type | H70: ロット管理区分 | I70: - | J70: E
A71: 30 | D71: sublot_mng_typ | E71: #MA.SUBLOT_MNG_TYP | G71: Sublot management type | H71: サブロット管理区分 | I71: - | J71: E
A72: 30 | D72: sno1_mng_typ | E72: #MA.SNO_MNG_TYP | G72: SEIBAN No. 1 management type | H72: 手配ＮＯ１管理区分 | I72: - | J72: E
A73: 30 | D73: sno2_mng_typ | E73: #MA.SNO_MNG_TYP | G73: SEIBAN No. 2 management type | H73: 手配ＮＯ２管理区分 | I73: - | J73: E
A74: 30 | D74: sno3_mng_typ | E74: #MA.SNO_MNG_TYP | G74: SEIBAN No. 3 management type | H74: 手配ＮＯ３管理区分 | I74: - | J74: E
...

Sheet Srch02
A1: * | B1: * | D1: L | E1: 1
A2: * | D2: オペレーション実装仕様書 Operation Specification Implementation Sheet | E2: ModuleID : | F2: =IF(LogicCommon!C2="","",LogicCommon!C2) -> MS | G2: LogicID : | H2: =IF(LogicCommon!E2="","",LogicCommon!E2) -> MSBEL1010 | I2: Ope.ID : | J2: Srch02 | K2: Pj.ID : | L2: =IF(LogicCommon!G2="","",LogicCommon!G2) -> MC | M2: Ope.Body : | N2: "mcframe.serverMAUD.MAUDL5010.MAUDL_Searcher"
A3: * | E3: SubModuleID : | F3: =IF(LogicCommon!C3="","",LogicCommon!C3) -> MSBE | G3: LogicClass : | H3: =IF(LogicCommon!E3="","",LogicCommon!E3) -> MSBEL_XfrInstReg | I3: Ope.Method : | J3: Srch02 | K3: SuperClassPj.ID : | L3: =IF(LogicCommon!G3="","",LogicCommon!G3) | O3: Gene.Type : | P3: ALL
A4: * | E4: Version : | F4: 000000 | G4: LogicName : | H4: =IF(LogicCommon!E4="","",LogicCommon!E4) -> 移動指図登録 | I4: Ope.Name : | J4: 指図検索 | K4: SuperLogicID : | L4: =IF(LogicCommon!G4="","",LogicCommon!G4) -> MS.MSUDL5010 | M4: ImplOpe.ID:
A5: * | E5: ACType :
A6: * | D6: 概要 : | E6: 移動指図を検索する | M6: ID | O6: ID
A7: # | I7: U | K7: K | L7: o | N7: o
A8: # | D8: ブロック名 Block Name | E8: 型 Type | G8: super/share | H8: 対象ブロック名 Target Block Name | K8: CONST | L8: TargetName | N8: TargetName | R8: ブロック備考 Block Remarks
A9: # | D9: 項目名 Field Name | E9: 型 Type | F9: 桁 Digits | G9: フルネーム Full Name | H9: 日本語名 Japanese Name | I9: 上り項目 Request Message Field | J9: 下り項目 Response Message Field | P9: 条件および編集方法 Conditions and Editing Methods | R9: 項目備考 Field Remarks
A10: # | L10: 上り項目 Request Message Field | M10: 下り項目 Response Message Field | N10: 上り項目 Request Message Field | O10: 下り項目 Response Message Field
A11: 10 | B11: * | D11: Srch02_Cnd | E11: R | G11: $share$ | H11: MS.MSBEL1010.Srch01.Srch01_Cnd
A12: 10 | D12: srch_tgt_no | E12: #MS.SRCH_TGT_NO | G12: Search target No. | H12: 検索対象ＮＯ | I12: E | J12: -
L13: 上り項目 Request Message Field | M13: 下り項目 Response Message Field | N13: 上り項目 Request Message Field | O13: 下り項目 Response Message Field
A14: 20 | B14: * | D14: Srch02_Hdr | E14: R | G14: $share$ | H14: MS.MSBEL1010.Srch01.Srch01_Hdr
A15: 20 | D15: trd_cd | E15: #MA.TRD_CD | G15: Transaction cd. | H15: 取引ＣＤ | I15: - | J15: E
A16: 20 | D16: trd_nm | E16: #MA.TRD_NM | G16: Transaction name | H16: 取引名 | I16: - | J16: E
A17: 20 | D17: trd_ptn_typ | E17: #MA.TRD_PTN_TYP | G17: Transaction pattern type | H17: 取引パタン区分 | I17: - | J17: E
A18: 20 | D18: xfr_inst_no | E18: #MA.XFR_INST_NO | G18: Movement order No. | H18: 移動指図ＮＯ | I18: - | J18: E
A19: 20 | D19: gr_loc_cd | E19: #MA.LOC_CD | G19: GR location cd. | H19: 入庫場所ＣＤ | I19: - | J19: E
A20: 20 | D20: gr_loc_nm | E20: #MA.LOC_NM | G20: GR location name | H20: 入庫場所名 | I20: - | J20: E
A21: 20 | D21: gr_str_ln_tgt_flg | E21: #MA.FLG | G21: For GR rack/line | H21: 入庫棚・ライン対象 | I21: - | J21: E
A22: 20 | D22: gr_sppl_cd | E22: #MA.BP_CD | G22: GR supplier cd. | H22: 入庫発注先ＣＤ | I22: - | J22: E
A23: 20 | D23: gr_cur_cd | E23: #MA.CUR_CD | G23: GR currency cd. | H23: 入庫通貨ＣＤ | I23: - | J23: E
A24: 20 | D24: gr_onr_prsppl_flg | E24: #MA.FLG | G24: GR chargeable supplier | H24: 入庫有償支給先 | I24: - | J24: E
A25: 20 | D25: gr_prov_basis_typ | E25: #MA.PROV_BASIS_TYP | G25: GR supply recording type | H25: 入庫支給計上区分 | I25: - | J25: E
A26: 20 | D26: wg_cd | E26: #MA.WG_CD | G26: WG cd. | H26: ワーキンググループＣＤ | I26: - | J26: E
... A60: 20 | D60: upd_srv_req_no | E60: #MA.SRV_REQ_NO | G60: Update request No. | H60: 更新リクエストＮＯ | I60: - | J60: E
A62: 30 | B62: * | D62: Srch02_Dtl | E62: L | G62: $share$ | H62: MS.MSBEL1010.Srch01.Srch01_Dtl
A63: 30 | D63: pr_sts_typ | E63: #MS.PR_STS_TYP | G63: Progress status type | H63: 進捗状況区分 | I63: - | J63: E | K63: MSC_PR_STS_TYP
A64: 30 | D64: pr_sts_typ_nm | E64: #MS.PR_STS_TYP_NM | G64: Progress status type name | H64: 進捗状況区分名 | I64: - | J64: E
A65: 30 | D65: itm_cd | E65: #MA.ITM_CD | G65: Item cd. | H65: 品目ＣＤ | I65: - | J65: E
A66: 30 | D66: itm_sub1 | E66: #MA.ITM_SUB1 | G66: Branch No. 1 | H66: 枝番１ | I66: - | J66: E
A67: 30 | D67: itm_sub2 | E67: #MA.ITM_SUB2 | G67: Branch No. 2 | H67: 枝番２ | I67: - | J67: E
A68: 30 | D68: itm_sub3 | E68: #MA.ITM_SUB3 | G68: Branch No. 3 | H68: 枝番３ | I68: - | J68: E
A69: 30 | D69: itm_nm | E69: #MA.ITM_NM | G69: Item name | H69: 品名 | I69: - | J69: E
A70: 30 | D70: lot_mng_typ | E70: #MA.LOT_MNG_TYP | G70: Lot management type | H70: ロット管理区分 | I70: - | J70: E
A71: 30 | D71: sublot_mng_typ | E71: #MA.SUBLOT_MNG_TYP | G71: Sublot management type | H71: サブロット管理区分 | I71: - | J71: E
A72: 30 | D72: sno1_mng_typ | E72: #MA.SNO_MNG_TYP | G72: SEIBAN No. 1 management type | H72: 手配ＮＯ１管理区分 | I72: - | J72: E
A73: 30 | D73: sno2_mng_typ | E73: #MA.SNO_MNG_TYP | G73: SEIBAN No. 2 management type | H73: 手配ＮＯ２管理区分 | I73: - | J73: E
A74: 30 | D74: sno3_mng_typ | E74: #MA.SNO_MNG_TYP | G74: SEIBAN No. 3 management type | H74: 手配ＮＯ３管理区分 | I74: - | J74: E
...

Sheet Chk01
A1: * | B1: * | D1: L | E1: 1
A2: * | D2: オペレーション実装仕様書 Operation Specification Implementation Sheet | E2: ModuleID : | F2: =IF(LogicCommon!C2="","",LogicCommon!C2) -> MS | G2: LogicID : | H2: =IF(LogicCommon!E2="","",LogicCommon!E2) -> MSBEL1010 | I2: Ope.ID : | J2: Chk01 | K2: Pj.ID : | L2: =IF(LogicCommon!G2="","",LogicCommon!G2) -> MC | M2: Ope.Body : | N2: MA.MAUDL5010.Checker
A3: * | E3: SubModuleID : | F3: =IF(LogicCommon!C3="","",LogicCommon!C3) -> MSBE | G3: LogicClass : | H3: =IF(LogicCommon!E3="","",LogicCommon!E3) -> MSBEL_XfrInstReg | I3: Ope.Method : | J3: Chk01 | K3: SuperClassPj.ID : | L3: =IF(LogicCommon!G3="","",LogicCommon!G3) | O3: Gene.Type : | P3: ALL
A4: * | E4: Version : | F4: 000000 | G4: LogicName : | H4: =IF(LogicCommon!E4="","",LogicCommon!E4) -> 移動指図登録 | I4: Ope.Name : | J4: 登録前チェック | K4: SuperLogicID : | L4: =IF(LogicCommon!G4="","",LogicCommon!G4) -> MS.MSUDL5010 | M4: ImplOpe.ID:
A5: * | E5: ACType :
A6: * | D6: 概要 : | E6: 移動指図が登録可能かチェックする | AD6: ID | AF6: ID
A7: # | I7: U | K7: K | L7: K | M7: K | N7: K | O7: K | P7: K | Q7: K | R7: K | S7: K | T7: K | U7: K | V7: K | W7: K | X7: K | Y7: K | Z7: K | AA7: K | AB7: K | AC7: o | AE7: o
A8: # | D8: ブロック名 Block Name | E8: 型 Type | G8: super/share | H8: 対象ブロック名 Target Block Name | K8: REQ_UPD_CNT_CHK | L8: REQUIRED | M8: CHK_NUM | N8: SMALL_LARGE | O8: CHK_DT | P8: BEFORE_AFTER | Q8: CHK_PTN | R8: DUPLICATE | S8: TOO_MANY_INPUTS | T8: AT_LEAST_ONE | U8: ONLY_ONE_INPUT | V8: LIST_LOGIC | W8: LIST_OUT | X8: LIST_OUT_BASE | Y8: LIST_IN | Z8: LIST_IN_BASE | AA8: CONST | AB8: NULL_VAL | AC8: TargetName | AE8: TargetName | AI8: ブロック備考 Block Remarks
A9: # | D9: 項目名 Field Name | E9: 型 Type | F9: 桁 Digits | G9: フルネーム Full Name | H9: 日本語名 Japanese Name | I9: 上り項目 Request Message Field | J9: 下り項目 Response Message Field | AG9: 条件および編集方法 Conditions and Editing Methods | AI9: 項目備考 Field Remarks
A10: #
A11: 10 | B11: * | D11: Chk01_Hdr | E11: R
A12: 10 | D12: trd_cd | E12: #MA.TRD_CD | G12: Transaction cd. | H12: 取引ＣＤ | I12: E | J12: E | L12: I,U | V12: MA.MAUAL0010.Trd | W12: trd_nm;trd_ptn_typ
A13: 10 | D13: trd_nm | E13: #MA.TRD_NM | G13: Transaction name | H13: 取引名 | I13: - | J13: E
A14: 10 | D14: trd_ptn_typ | E14: #MA.TRD_PTN_TYP | G14: Transaction pattern type | H14: 取引パタン区分 | I14: - | J14: E
A15: 10 | D15: xfr_inst_no | E15: #MA.XFR_INST_NO | G15: Movement order No. | H15: 移動指図ＮＯ | I15: - | J15: -
A16: 10 | D16: gr_loc_cd | E16: #MA.LOC_CD | G16: GR location cd. | H16: 入庫場所ＣＤ | I16: E | J16: E | L16: I,U | V16: MA.MAUAL0010.Loc | W16: gr_loc_nm;wg_cd;wg_nm;gr_str_ln_tgt_flg;lg_grp_cd;lg_grp_nm;gr_sppl_cd | X16: loc_nm;wg_cd;wg_nm;str_ln_tgt_flg;lg_grp_cd;lg_grp_nm;sppl_cd
A17: 10 | D17: gr_loc_nm | E17: #MA.LOC_NM | G17: GR location name | H17: 入庫場所名 | I17: - | J17: E
A18: 10 | D18: gr_str_ln_tgt_flg | E18: #MA.FLG | G18: For GR rack/line | H18: 入庫棚・ライン対象 | I18: - | J18: E
A19: 10 | D19: gr_sppl_cd | E19: #MA.BP_CD | G19: GR supplier cd. | H19: 入庫発注先ＣＤ | I19: - | J19: E | V19: MA.MAUAL0010.Bp | W19: gr_onr_prsppl_flg;gr_prov_basis_typ;gr_cur_cd | X19: onr_prsppl_flg;prov_basis_typ;cur_cd
A20: 10 | D20: gr_cur_cd | E20: #MA.CUR_CD | G20: GR currency cd. | H20: 入庫通貨ＣＤ | I20: - | J20: E
A21: 10 | D21: gr_onr_prsppl_flg | E21: #MA.FLG | G21: GR chargeable supplier | H21: 入庫有償支給先 | I21: - | J21: E
A22: 10 | D22: gr_prov_basis_typ | E22: #MA.PROV_BASIS_TYP | G22: GR supply recording type | H22: 入庫支給計上区分 | I22: - | J22: E
A23: 10 | D23: wg_cd | E23: #MA.WG_CD | G23: WG cd. | H23: ワーキンググループＣＤ | I23: - | J23: E
A24: 10 | D24: wg_nm | E24: #MA.WG_NM | G24: WG name | H24: ワーキンググループ名 | I24: - | J24: E
A25: 10 | D25: lg_grp_cd | E25: #MA.LG_GRP_CD | G25: Distribution group cd. | H25: 物流グループＣＤ | I25: - | J25: E
A26: 10 | D26: lg_grp_nm | E26: #MA.LG_GRP_NM | G26: Distribution group name | H26: 物流グループ名 | I26: - | J26: E
A27: 10 | D27: xfr_schd_dt | E27: #MA.DT | G27: Scheduled movement date | H27: 移動予定日 | I27: E | J27: E | L27: I,U
A28: 10 | D28: xfr_inst_dt | E28: #MA.DT | G28: Movement order date | H28: 移動指図日 | I28: E | J28: E | L28: I,U
A29: 10 | D29: inst_usr_cd | E29: #MA.USR_CD | G29: Order PIC cd. | H29: 指図担当者ＣＤ | I29: E | J29: E | V29: MA.MAUAL0010.Usr | W29: inst_usr_nm | X29: usr_nm
A30: 10 | D30: inst_usr_nm | E30: #MA.USR_NM | G30: Order PIC name | H30: 指図担当者名 | I30: - | J30: E
A31: 10 | D31: inst_dpt_cd | E31: #MA.DPT_CD | G31: Order dept. cd. | H31: 指図部門ＣＤ | I31: E | J31: E | V31: MA.MAUAL0010.Dpt | W31: inst_dpt_nm | X31: dpt_nm | Y31: inst_usr_cd;xfr_inst_dt;MAC_DPT_IS_SRCH_TYP.SCE | Z31: usr_cd;dt;dpt_is_srch_typ
A32: 10 | D32: inst_dpt_nm | E32: #MA.DPT_NM | G32: Order dept. name | H32: 指図部門名 | I32: - | J32: E
A33: 10 | D33: pick_print | E33: #MA.FLG | G33: Picking list immediate issue | H33: ピッキングリスト即時発行 | I33: E | J33: E
A34: 10 | D34: inst_print | E34: #MA.FLG | G34: Order sheet immediate issue | H34: 指図書即時発行 | I34: E | J34: E
A35: 10 | D35: dlv_print | E35: #MA.FLG | G35: Delivery note immediate issue | H35: 納品書即時発行 | I35: E | J35: E
A36: 10 | D36: pick_prnt_flg | E36: #MA.FLG | G36: Picking list issued | H36: ピッキングリスト発行済 | I36: - | J36: E
A37: 10 | D37: inst_prnt_flg | E37: #MA.FLG | G37: Order sheet issued | H37: 指図書発行済 | I37: - | J37: E
A38: 10 | D38: dlv_prnt_flg | E38: #MA.FLG | G38: Delivery note issued | H38: 納品書発行済 | I38: - | J38: E
A39: 10 | D39: registered_act | E39: #MA.FLG | G39: Result entered | H39: 実績登録済 | I39: - | J39: -
A40: 10 | D40: trd_rmrks | E40: #MA.TRD_RMRKS | G40: Transaction remarks | H40: 取引備考 | I40: E | J40: E
...

Sheet Chk02
A1: * | B1: * | D1: L | E1: 1
A2: * | D2: オペレーション実装仕様書 Operation Specification Implementation Sheet | E2: ModuleID : | F2: =IF(LogicCommon!C2="","",LogicCommon!C2) -> MS | G2: LogicID : | H2: =IF(LogicCommon!E2="","",LogicCommon!E2) -> MSBEL1010 | I2: Ope.ID : | J2: Chk02 | K2: Pj.ID : | L2: =IF(LogicCommon!G2="","",LogicCommon!G2) -> MC | M2: Ope.Body : | N2: MA.MAUDL5010.Checker
A3: * | E3: SubModuleID : | F3: =IF(LogicCommon!C3="","",LogicCommon!C3) -> MSBE | G3: LogicClass : | H3: =IF(LogicCommon!E3="","",LogicCommon!E3) -> MSBEL_XfrInstReg | I3: Ope.Method : | J3: Chk02 | K3: SuperClassPj.ID : | L3: =IF(LogicCommon!G3="","",LogicCommon!G3) | O3: Gene.Type : | P3: ALL
A4: * | E4: Version : | F4: 000000 | G4: LogicName : | H4: =IF(LogicCommon!E4="","",LogicCommon!E4) -> 移動指図登録 | I4: Ope.Name : | J4: 更新前チェック | K4: SuperLogicID : | L4: =IF(LogicCommon!G4="","",LogicCommon!G4) -> MS.MSUDL5010 | M4: ImplOpe.ID:
A5: * | E5: ACType :
A6: * | D6: 概要 : | E6: 移動指図が更新可能かチェックする | AD6: ID | AF6: ID
A7: # | I7: U | K7: K | L7: K | M7: K | N7: K | O7: K | P7: K | Q7: K | R7: K | S7: K | T7: K | U7: K | V7: K | W7: K | X7: K | Y7: K | Z7: K | AA7: K | AB7: K | AC7: o | AE7: o
A8: # | D8: ブロック名 Block Name | E8: 型 Type | G8: super/share | H8: 対象ブロック名 Target Block Name | K8: REQ_UPD_CNT_CHK | L8: REQUIRED | M8: CHK_NUM | N8: SMALL_LARGE | O8: CHK_DT | P8: BEFORE_AFTER | Q8: CHK_PTN | R8: DUPLICATE | S8: TOO_MANY_INPUTS | T8: AT_LEAST_ONE | U8: ONLY_ONE_INPUT | V8: LIST_LOGIC | W8: LIST_OUT | X8: LIST_OUT_BASE | Y8: LIST_IN | Z8: LIST_IN_BASE | AA8: CONST | AB8: NULL_VAL | AC8: TargetName | AE8: TargetName | AI8: ブロック備考 Block Remarks
A9: # | D9: 項目名 Field Name | E9: 型 Type | F9: 桁 Digits | G9: フルネーム Full Name | H9: 日本語名 Japanese Name | I9: 上り項目 Request Message Field | J9: 下り項目 Response Message Field | AG9: 条件および編集方法 Conditions and Editing Methods | AI9: 項目備考 Field Remarks
A10: #
A11: 10 | B11: * | D11: Chk02_Hdr | E11: R | G11: $share$ | H11: MS.MSBEL1010.Chk01.Chk01_Hdr
A12: 10 | D12: trd_cd | E12: #MA.TRD_CD | G12: Transaction cd. | H12: 取引ＣＤ | I12: E | J12: E
A13: 10 | D13: trd_nm | E13: #MA.TRD_NM | G13: Transaction name | H13: 取引名 | I13: - | J13: E
A14: 10 | D14: trd_ptn_typ | E14: #MA.TRD_PTN_TYP | G14: Transaction pattern type | H14: 取引パタン区分 | I14: - | J14: E
A15: 10 | D15: xfr_inst_no | E15: #MA.XFR_INST_NO | G15: Movement order No. | H15: 移動指図ＮＯ | I15: E | J15: E
A16: 10 | D16: gr_loc_cd | E16: #MA.LOC_CD | G16: GR location cd. | H16: 入庫場所ＣＤ | I16: E | J16: E
A17: 10 | D17: gr_loc_nm | E17: #MA.LOC_NM | G17: GR location name | H17: 入庫場所名 | I17: - | J17: E
A18: 10 | D18: gr_str_ln_tgt_flg | E18: #MA.FLG | G18: For GR rack/line | H18: 入庫棚・ライン対象 | I18: - | J18: E
A19: 10 | D19: gr_sppl_cd | E19: #MA.BP_CD | G19: GR supplier cd. | H19: 入庫発注先ＣＤ | I19: - | J19: E
A20: 10 | D20: gr_cur_cd | E20: #MA.CUR_CD | G20: GR currency cd. | H20: 入庫通貨ＣＤ | I20: - | J20: E
A21: 10 | D21: gr_onr_prsppl_flg | E21: #MA.FLG | G21: GR chargeable supplier | H21: 入庫有償支給先 | I21: - | J21: E
A22: 10 | D22: gr_prov_basis_typ | E22: #MA.PROV_BASIS_TYP | G22: GR supply recording type | H22: 入庫支給計上区分 | I22: - | J22: E
A23: 10 | D23: wg_cd | E23: #MA.WG_CD | G23: WG cd. | H23: ワーキンググループＣＤ | I23: - | J23: E
... A58: 10 | D58: err_flg | E58: #MA.FLG | G58: Error | H58: エラー | I58: - | J58: -
A60: 20 | B60: * | D60: Chk02_Dtl | E60: L | G60: $share$ | H60: MS.MSBEL1010.Chk01.Chk01_Dtl
A61: 20 | D61: peg_no | E61: #MA.INT | G61: Pegging No. | H61: 紐付けＮＯ | I61: - | J61: E
A62: 20 | D62: data_crud_typ | E62: #MA.DATA_CRUD_TYP | G62: Data update type | H62: データ更新区分 | I62: E | J62: E
A63: 20 | D63: pr_sts_typ | E63: #MS.PR_STS_TYP | G63: Progress status type | H63: 進捗状況区分 | I63: E | J63: E
A64: 20 | D64: pr_sts_typ_nm | E64: #MS.PR_STS_TYP_NM | G64: Progress status type name | H64: 進捗状況区分名 | I64: - | J64: E
A65: 20 | D65: itm_cd | E65: #MA.ITM_CD | G65: Item cd. | H65: 品目ＣＤ | I65: E | J65: E
A66: 20 | D66: itm_sub1 | E66: #MA.ITM_SUB1 | G66: Branch No. 1 | H66: 枝番１ | I66: E | J66: E
A67: 20 | D67: itm_sub2 | E67: #MA.ITM_SUB2 | G67: Branch No. 2 | H67: 枝番２ | I67: E | J67: E
A68: 20 | D68: itm_sub3 | E68: #MA.ITM_SUB3 | G68: Branch No. 3 | H68: 枝番３ | I68: E | J68: E
A69: 20 | D69: itm_nm | E69: #MA.ITM_NM | G69: Item name | H69: 品名 | I69: - | J69: E
A70: 20 | D70: lot_mng_typ | E70: #MA.LOT_MNG_TYP | G70: Lot management type | H70: ロット管理区分 | I70: - | J70: E
A71: 20 | D71: sublot_mng_typ | E71: #MA.SUBLOT_MNG_TYP | G71: Sublot management type | H71: サブロット管理区分 | I71: - | J71: E
A72: 20 | D72: sno1_mng_typ | E72: #MA.SNO_MNG_TYP | G72: SEIBAN No. 1 management type | H72: 手配ＮＯ１管理区分 | I72: - | J72: E
... A208: 20 | D208: err_flg | E208: #MA.FLG | G208: Error | H208: エラー | I208: - | J208: -
D209: 詳細 :

Sheet Chk03
A1: * | B1: * | D1: L | E1: 1
A2: * | D2: オペレーション実装仕様書 Operation Specification Implementation Sheet | E2: ModuleID : | F2: =IF(LogicCommon!C2="","",LogicCommon!C2) -> MS | G2: LogicID : | H2: =IF(LogicCommon!E2="","",LogicCommon!E2) -> MSBEL1010 | I2: Ope.ID : | J2: Chk03 | K2: Pj.ID : | L2: =IF(LogicCommon!G2="","",LogicCommon!G2) -> MC | M2: Ope.Body : | N2: MA.MAUDL5010.Checker
A3: * | E3: SubModuleID : | F3: =IF(LogicCommon!C3="","",LogicCommon!C3) -> MSBE | G3: LogicClass : | H3: =IF(LogicCommon!E3="","",LogicCommon!E3) -> MSBEL_XfrInstReg | I3: Ope.Method : | J3: Chk03 | K3: SuperClassPj.ID : | L3: =IF(LogicCommon!G3="","",LogicCommon!G3) | O3: Gene.Type : | P3: ALL
A4: * | E4: Version : | F4: 000000 | G4: LogicName : | H4: =IF(LogicCommon!E4="","",LogicCommon!E4) -> 移動指図登録 | I4: Ope.Name : | J4: 取消前チェック | K4: SuperLogicID : | L4: =IF(LogicCommon!G4="","",LogicCommon!G4) -> MS.MSUDL5010 | M4: ImplOpe.ID:
A5: * | E5: ACType :
A6: * | D6: 概要 : | E6: 移動指図が取消可能かチェックする | AD6: ID | AF6: ID
A7: # | I7: U | K7: K | L7: K | M7: K | N7: K | O7: K | P7: K | Q7: K | R7: K | S7: K | T7: K | U7: K | V7: K | W7: K | X7: K | Y7: K | Z7: K | AA7: K | AB7: K | AC7: o | AE7: o
A8: # | D8: ブロック名 Block Name | E8: 型 Type | G8: super/share | H8: 対象ブロック名 Target Block Name | K8: REQ_UPD_CNT_CHK | L8: REQUIRED | M8: CHK_NUM | N8: SMALL_LARGE | O8: CHK_DT | P8: BEFORE_AFTER | Q8: CHK_PTN | R8: DUPLICATE | S8: TOO_MANY_INPUTS | T8: AT_LEAST_ONE | U8: ONLY_ONE_INPUT | V8: LIST_LOGIC | W8: LIST_OUT | X8: LIST_OUT_BASE | Y8: LIST_IN | Z8: LIST_IN_BASE | AA8: CONST | AB8: NULL_VAL | AC8: TargetName | AE8: TargetName | AI8: ブロック備考 Block Remarks
A9: # | D9: 項目名 Field Name | E9: 型 Type | F9: 桁 Digits | G9: フルネーム Full Name | H9: 日本語名 Japanese Name | I9: 上り項目 Request Message Field | J9: 下り項目 Response Message Field | AG9: 条件および編集方法 Conditions and Editing Methods | AI9: 項目備考 Field Remarks
A10: #
A11: 10 | B11: * | D11: Chk03_Hdr | E11: R | G11: $share$ | H11: MS.MSBEL1010.Chk01.Chk01_Hdr
A12: 10 | D12: xfr_inst_no | E12: #MA.XFR_INST_NO | G12: Movement order No. | H12: 移動指図ＮＯ | I12: E | J12: E
A13: 10 | D13: dlv_print | E13: #MA.FLG | G13: Delivery note immediate issue | H13: 納品書即時発行 | I13: E | J13: E
A14: 10 | D14: inst_upd_cntr | E14: #MA.UPD_CNT | G14: Update counter (Order) | H14: 更新カウンタ(指図) | I14: E | J14: E
A15: 10 | D15: err_flg | E15: #MA.FLG | G15: Error | H15: エラー | I15: - | J15: E
A17: 20 | B17: * | D17: Chk03_Dtl | E17: L | G17: $share$ | H17: MS.MSBEL1010.Chk01.Chk01_Dtl
A18: 20 | D18: xfr_alloc_sts_no | E18: #MA.XFR_ALLOC_STS_NO | G18: Movement allocation status No. | H18: 移動引当状況ＮＯ | I18: E | J18: -
A19: 20 | D19: xfr_inst_no | E19: #MA.XFR_INST_NO | G19: Movement order No. | H19: 移動指図ＮＯ | I19: - | J19: -
A20: 20 | D20: xfr_inst_d_no | E20: #MA.XFR_INST_D_NO | G20: Movement order details No. | H20: 移動指図明細ＮＯ | I20: E | J20: -
A21: 20 | D21: alloc_sts_upd_cntr | E21: #MA.UPD_CNT | G21: Update counter (Allocation status) | H21: 更新カウンタ(引当状況) | I21: E | J21: -
A22: 20 | D22: wms_flg | E22: #MA.FLG | G22: WMS flg. | H22: ＷＭＳＦＬＧ | I22: E | J22: E
D23: 詳細 :

Sheet Chk04
A1: * | B1: * | D1: L | E1: 1
A2: * | D2: オペレーション実装仕様書 Operation Specification Implementation Sheet | E2: ModuleID : | F2: =IF(LogicCommon!C2="","",LogicCommon!C2) -> MS | G2: LogicID : | H2: =IF(LogicCommon!E2="","",LogicCommon!E2) -> MSBEL1010 | I2: Ope.ID : | J2: Chk04 | K2: Pj.ID : | L2: =IF(LogicCommon!G2="","",LogicCommon!G2) -> MC | M2: Ope.Body : | N2: MA.MAUDL5010.Checker
A3: * | E3: SubModuleID : | F3: =IF(LogicCommon!C3="","",LogicCommon!C3) -> MSBE | G3: LogicClass : | H3: =IF(LogicCommon!E3="","",LogicCommon!E3) -> MSBEL_XfrInstReg | I3: Ope.Method : | J3: Chk04 | K3: SuperClassPj.ID : | L3: =IF(LogicCommon!G3="","",LogicCommon!G3) | O3: Gene.Type : | P3: ALL
A4: * | E4: Version : | F4: 000000 | G4: LogicName : | H4: =IF(LogicCommon!E4="","",LogicCommon!E4) -> 移動指図登録 | I4: Ope.Name : | J4: 帳票発行前チェック | K4: SuperLogicID : | L4: =IF(LogicCommon!G4="","",LogicCommon!G4) -> MS.MSUDL5010 | M4: ImplOpe.ID:
A5: * | E5: ACType :
A6: * | D6: 概要 : | E6: 帳票が発行可能かチェックする | AD6: ID | AF6: ID
A7: # | I7: U | K7: K | L7: K | M7: K | N7: K | O7: K | P7: K | Q7: K | R7: K | S7: K | T7: K | U7: K | V7: K | W7: K | X7: K | Y7: K | Z7: K | AA7: K | AB7: K | AC7: o | AE7: o
A8: # | D8: ブロック名 Block Name | E8: 型 Type | G8: super/share | H8: 対象ブロック名 Target Block Name | K8: REQ_UPD_CNT_CHK | L8: REQUIRED | M8: CHK_NUM | N8: SMALL_LARGE | O8: CHK_DT | P8: BEFORE_AFTER | Q8: CHK_PTN | R8: DUPLICATE | S8: TOO_MANY_INPUTS | T8: AT_LEAST_ONE | U8: ONLY_ONE_INPUT | V8: LIST_LOGIC | W8: LIST_OUT | X8: LIST_OUT_BASE | Y8: LIST_IN | Z8: LIST_IN_BASE | AA8: CONST | AB8: NULL_VAL | AC8: TargetName | AE8: TargetName | AI8: ブロック備考 Block Remarks
A9: # | D9: 項目名 Field Name | E9: 型 Type | F9: 桁 Digits | G9: フルネーム Full Name | H9: 日本語名 Japanese Name | I9: 上り項目 Request Message Field | J9: 下り項目 Response Message Field | AG9: 条件および編集方法 Conditions and Editing Methods | AI9: 項目備考 Field Remarks
A10: #
A11: 10 | B11: * | D11: Chk04_Hdr | E11: R | G11: $share$ | H11: MS.MSBEL1010.Chk01.Chk01_Hdr
A12: 10 | D12: xfr_inst_no | E12: #MA.XFR_INST_NO | G12: Movement order No. | H12: 移動指図ＮＯ | I12: E | J12: E
A13: 10 | D13: inst_upd_cntr | E13: #MA.UPD_CNT | G13: Update counter (Order) | H13: 更新カウンタ(指図) | I13: E | J13: E
A14: 10 | D14: err_flg | E14: #MA.FLG | G14: Error | H14: エラー | I14: - | J14: E
A16: 20 | B16: * | D16: Chk04_Dtl | E16: L
A17: 20 | D17: base_ac_dt | E17: #MA.DT | G17: Supply recording date (Base) | H17: 支給計上日（基） | I17: E | J17: -
D18: 詳細 :

Sheet Ins01
A1: * | B1: * | D1: L | E1: 1
A2: * | D2: オペレーション実装仕様書 Operation Specification Implementation Sheet | E2: ModuleID : | F2: =IF(LogicCommon!C2="","",LogicCommon!C2) -> MS | G2: LogicID : | H2: =IF(LogicCommon!E2="","",LogicCommon!E2) -> MSBEL1010 | I2: Ope.ID : | J2: Ins01 | K2: Pj.ID : | L2: =IF(LogicCommon!G2="","",LogicCommon!G2) -> MC | M2: Ope.Body : | N2: "mcframe.serverMAUD.MAUDL5010.MAUDL_Operation"
A3: * | E3: SubModuleID : | F3: =IF(LogicCommon!C3="","",LogicCommon!C3) -> MSBE | G3: LogicClass : | H3: =IF(LogicCommon!E3="","",LogicCommon!E3) -> MSBEL_XfrInstReg | I3: Ope.Method : | J3: Ins01 | K3: SuperClassPj.ID : | L3: =IF(LogicCommon!G3="","",LogicCommon!G3) | O3: Gene.Type : | P3: ALL
A4: * | E4: Version : | F4: 000000 | G4: LogicName : | H4: =IF(LogicCommon!E4="","",LogicCommon!E4) -> 移動指図登録 | I4: Ope.Name : | J4: 登録 | K4: SuperLogicID : | L4: =IF(LogicCommon!G4="","",LogicCommon!G4) -> MS.MSUDL5010 | M4: ImplOpe.ID:
A5: * | E5: ACType :
A6: * | D6: 概要 : | E6: 移動指図を新規登録する | L6: ID | N6: ID | P6: ID | R6: ID
A7: # | I7: U | K7: o | M7: o | O7: o | Q7: o
A8: # | D8: ブロック名 Block Name | E8: 型 Type | G8: super/share | H8: 対象ブロック名 Target Block Name | K8: TargetName | M8: TargetName | O8: TargetName | Q8: TargetName | U8: ブロック備考 Block Remarks
A9: # | D9: 項目名 Field Name | E9: 型 Type | F9: 桁 Digits | G9: フルネーム Full Name | H9: 日本語名 Japanese Name | I9: 上り項目 Request Message Field | J9: 下り項目 Response Message Field | S9: 条件および編集方法 Conditions and Editing Methods | U9: 項目備考 Field Remarks
A10: # | K10: 上り項目 Request Message Field | L10: 下り項目 Response Message Field | M10: 上り項目 Request Message Field | N10: 下り項目 Response Message Field | O10: 上り項目 Request Message Field | P10: 下り項目 Response Message Field | Q10: 上り項目 Request Message Field | R10: 下り項目 Response Message Field
A11: 10 | B11: * | D11: Ins01_Hdr | E11: R | G11: $share$ | H11: MS.MSBEL1010.Chk01.Chk01_Hdr
A12: 10 | D12: trd_cd | E12: #MA.TRD_CD | G12: Transaction cd. | H12: 取引ＣＤ | I12: E | J12: -
A13: 10 | D13: trd_nm | E13: #MA.TRD_NM | G13: Transaction name | H13: 取引名 | I13: - | J13: -
A14: 10 | D14: trd_ptn_typ | E14: #MA.TRD_PTN_TYP | G14: Transaction pattern type | H14: 取引パタン区分 | I14: - | J14: -
A15: 10 | D15: xfr_inst_no | E15: #MA.XFR_INST_NO | G15: Movement order No. | H15: 移動指図ＮＯ | I15: - | J15: E
A16: 10 | D16: gr_loc_cd | E16: #MA.LOC_CD | G16: GR location cd. | H16: 入庫場所ＣＤ | I16: E | J16: -
A17: 10 | D17: gr_loc_nm | E17: #MA.LOC_NM | G17: GR location name | H17: 入庫場所名 | I17: - | J17: -
A18: 10 | D18: gr_str_ln_tgt_flg | E18: #MA.FLG | G18: For GR rack/line | H18: 入庫棚・ライン対象 | I18: - | J18: -
A19: 10 | D19: gr_sppl_cd | E19: #MA.BP_CD | G19: GR supplier cd. | H19: 入庫発注先ＣＤ | I19: - | J19: -
A20: 10 | D20: gr_cur_cd | E20: #MA.CUR_CD | G20: GR currency cd. | H20: 入庫通貨ＣＤ | I20: - | J20: -
A21: 10 | D21: gr_onr_prsppl_flg | E21: #MA.FLG | G21: GR chargeable supplier | H21: 入庫有償支給先 | I21: - | J21: -
A22: 10 | D22: gr_prov_basis_typ | E22: #MA.PROV_BASIS_TYP | G22: GR supply recording type | H22: 入庫支給計上区分 | I22: - | J22: -
A23: 10 | D23: wg_cd | E23: #MA.WG_CD | G23: WG cd. | H23: ワーキンググループＣＤ | I23: - | J23: -
... A58: 10 | D58: err_flg | E58: #MA.FLG | G58: Error | H58: エラー | I58: - | J58: -
A60: 20 | B60: * | D60: Ins01_Dtl | E60: L | G60: $share$ | H60: MS.MSBEL1010.Chk01.Chk01_Dtl
A61: 20 | D61: peg_no | E61: #MA.INT | G61: Pegging No. | H61: 紐付けＮＯ | I61: - | J61: -
A62: 20 | D62: data_crud_typ | E62: #MA.DATA_CRUD_TYP | G62: Data update type | H62: データ更新区分 | I62: - | J62: -
A63: 20 | D63: pr_sts_typ | E63: #MS.PR_STS_TYP | G63: Progress status type | H63: 進捗状況区分 | I63: E | J63: E
A64: 20 | D64: pr_sts_typ_nm | E64: #MS.PR_STS_TYP_NM | G64: Progress status type name | H64: 進捗状況区分名 | I64: - | J64: E
A65: 20 | D65: itm_cd | E65: #MA.ITM_CD | G65: Item cd. | H65: 品目ＣＤ | I65: E | J65: -
A66: 20 | D66: itm_sub1 | E66: #MA.ITM_SUB1 | G66: Branch No. 1 | H66: 枝番１ | I66: E | J66: -
A67: 20 | D67: itm_sub2 | E67: #MA.ITM_SUB2 | G67: Branch No. 2 | H67: 枝番２ | I67: E | J67: -
A68: 20 | D68: itm_sub3 | E68: #MA.ITM_SUB3 | G68: Branch No. 3 | H68: 枝番３ | I68: E | J68: -
A69: 20 | D69: itm_nm | E69: #MA.ITM_NM | G69: Item name | H69: 品名 | I69: - | J69: -
A70: 20 | D70: lot_mng_typ | E70: #MA.LOT_MNG_TYP | G70: Lot management type | H70: ロット管理区分 | I70: - | J70: -
A71: 20 | D71: sublot_mng_typ | E71: #MA.SUBLOT_MNG_TYP | G71: Sublot management type | H71: サブロット管理区分 | I71: - | J71: -
A72: 20 | D72: sno1_mng_typ | E72: #MA.SNO_MNG_TYP | G72: SEIBAN No. 1 management type | H72: 手配ＮＯ１管理区分 | I72: - | J72: -
... A198: 20 | D198: err_flg | E198: #MA.FLG | G198: Error | H198: エラー | I198: - | J198: -
A200: 30 | B200: * | D200: Ins01_Cnd | E200: R
A201: 30 | D201: indiv_prnt_flg | E201: #MA.FLG | G201: Individual issue | H201: 個別発行 | I201: E | J201: -
...

Sheet Upd01
A1: * | B1: * | D1: L | E1: 1
A2: * | D2: オペレーション実装仕様書 Operation Specification Implementation Sheet | E2: ModuleID : | F2: =IF(LogicCommon!C2="","",LogicCommon!C2) -> MS | G2: LogicID : | H2: =IF(LogicCommon!E2="","",LogicCommon!E2) -> MSBEL1010 | I2: Ope.ID : | J2: Upd01 | K2: Pj.ID : | L2: =IF(LogicCommon!G2="","",LogicCommon!G2) -> MC | M2: Ope.Body : | N2: "mcframe.serverMAUD.MAUDL5010.MAUDL_Operation"
A3: * | E3: SubModuleID : | F3: =IF(LogicCommon!C3="","",LogicCommon!C3) -> MSBE | G3: LogicClass : | H3: =IF(LogicCommon!E3="","",LogicCommon!E3) -> MSBEL_XfrInstReg | I3: Ope.Method : | J3: Upd01 | K3: SuperClassPj.ID : | L3: =IF(LogicCommon!G3="","",LogicCommon!G3) | O3: Gene.Type : | P3: ALL
A4: * | E4: Version : | F4: 000000 | G4: LogicName : | H4: =IF(LogicCommon!E4="","",LogicCommon!E4) -> 移動指図登録 | I4: Ope.Name : | J4: 更新 | K4: SuperLogicID : | L4: =IF(LogicCommon!G4="","",LogicCommon!G4) -> MS.MSUDL5010 | M4: ImplOpe.ID:
A5: * | E5: ACType :
A6: * | D6: 概要 : | E6: 移動指図を訂正する | L6: ID | N6: ID | P6: ID | R6: ID
A7: # | I7: U | K7: o | M7: o | O7: o | Q7: o
A8: # | D8: ブロック名 Block Name | E8: 型 Type | G8: super/share | H8: 対象ブロック名 Target Block Name | K8: TargetName | M8: TargetName | O8: TargetName | Q8: TargetName | U8: ブロック備考 Block Remarks
A9: # | D9: 項目名 Field Name | E9: 型 Type | F9: 桁 Digits | G9: フルネーム Full Name | H9: 日本語名 Japanese Name | I9: 上り項目 Request Message Field | J9: 下り項目 Response Message Field | S9: 条件および編集方法 Conditions and Editing Methods | U9: 項目備考 Field Remarks
A10: # | K10: 上り項目 Request Message Field | L10: 下り項目 Response Message Field | M10: 上り項目 Request Message Field | N10: 下り項目 Response Message Field | O10: 上り項目 Request Message Field | P10: 下り項目 Response Message Field | Q10: 上り項目 Request Message Field | R10: 下り項目 Response Message Field
A11: 10 | B11: * | D11: Upd01_Hdr | E11: R | G11: $share$ | H11: MS.MSBEL1010.Chk01.Chk01_Hdr
A12: 10 | D12: trd_cd | E12: #MA.TRD_CD | G12: Transaction cd. | H12: 取引ＣＤ | I12: E | J12: -
A13: 10 | D13: trd_nm | E13: #MA.TRD_NM | G13: Transaction name | H13: 取引名 | I13: - | J13: -
A14: 10 | D14: trd_ptn_typ | E14: #MA.TRD_PTN_TYP | G14: Transaction pattern type | H14: 取引パタン区分 | I14: - | J14: -
A15: 10 | D15: xfr_inst_no | E15: #MA.XFR_INST_NO | G15: Movement order No. | H15: 移動指図ＮＯ | I15: E | J15: -
A16: 10 | D16: gr_loc_cd | E16: #MA.LOC_CD | G16: GR location cd. | H16: 入庫場所ＣＤ | I16: E | J16: -
A17: 10 | D17: gr_loc_nm | E17: #MA.LOC_NM | G17: GR location name | H17: 入庫場所名 | I17: - | J17: -
A18: 10 | D18: gr_str_ln_tgt_flg | E18: #MA.FLG | G18: For GR rack/line | H18: 入庫棚・ライン対象 | I18: - | J18: -
A19: 10 | D19: gr_sppl_cd | E19: #MA.BP_CD | G19: GR supplier cd. | H19: 入庫発注先ＣＤ | I19: - | J19: -
A20: 10 | D20: gr_cur_cd | E20: #MA.CUR_CD | G20: GR currency cd. | H20: 入庫通貨ＣＤ | I20: - | J20: -
A21: 10 | D21: gr_onr_prsppl_flg | E21: #MA.FLG | G21: GR chargeable supplier | H21: 入庫有償支給先 | I21: - | J21: -
A22: 10 | D22: gr_prov_basis_typ | E22: #MA.PROV_BASIS_TYP | G22: GR supply recording type | H22: 入庫支給計上区分 | I22: - | J22: -
A23: 10 | D23: wg_cd | E23: #MA.WG_CD | G23: WG cd. | H23: ワーキンググループＣＤ | I23: - | J23: -
... A58: 10 | D58: err_flg | E58: #MA.FLG | G58: Error | H58: エラー | I58: - | J58: -
A60: 20 | B60: * | D60: Upd01_Dtl | E60: L | G60: $share$ | H60: MS.MSBEL1010.Chk01.Chk01_Dtl
A61: 20 | D61: peg_no | E61: #MA.INT | G61: Pegging No. | H61: 紐付けＮＯ | I61: - | J61: -
A62: 20 | D62: data_crud_typ | E62: #MA.DATA_CRUD_TYP | G62: Data update type | H62: データ更新区分 | I62: - | J62: -
A63: 20 | D63: pr_sts_typ | E63: #MS.PR_STS_TYP | G63: Progress status type | H63: 進捗状況区分 | I63: E | J63: E
A64: 20 | D64: pr_sts_typ_nm | E64: #MS.PR_STS_TYP_NM | G64: Progress status type name | H64: 進捗状況区分名 | I64: - | J64: E
A65: 20 | D65: itm_cd | E65: #MA.ITM_CD | G65: Item cd. | H65: 品目ＣＤ | I65: E | J65: -
A66: 20 | D66: itm_sub1 | E66: #MA.ITM_SUB1 | G66: Branch No. 1 | H66: 枝番１ | I66: E | J66: -
A67: 20 | D67: itm_sub2 | E67: #MA.ITM_SUB2 | G67: Branch No. 2 | H67: 枝番２ | I67: E | J67: -
A68: 20 | D68: itm_sub3 | E68: #MA.ITM_SUB3 | G68: Branch No. 3 | H68: 枝番３ | I68: E | J68: -
A69: 20 | D69: itm_nm | E69: #MA.ITM_NM | G69: Item name | H69: 品名 | I69: - | J69: -
A70: 20 | D70: lot_mng_typ | E70: #MA.LOT_MNG_TYP | G70: Lot management type | H70: ロット管理区分 | I70: - | J70: -
A71: 20 | D71: sublot_mng_typ | E71: #MA.SUBLOT_MNG_TYP | G71: Sublot management type | H71: サブロット管理区分 | I71: - | J71: -
A72: 20 | D72: sno1_mng_typ | E72: #MA.SNO_MNG_TYP | G72: SEIBAN No. 1 management type | H72: 手配ＮＯ１管理区分 | I72: - | J72: -
... A198: 20 | D198: err_flg | E198: #MA.FLG | G198: Error | H198: エラー | I198: - | J198: -
A200: 30 | B200: * | D200: Upd01_Cnd | E200: R
A201: 30 | D201: indiv_prnt_flg | E201: #MA.FLG | G201: Individual issue | H201: 個別発行 | I201: E | J201: -
...

Sheet Del01
A1: * | B1: * | D1: L | E1: 1
A2: * | D2: オペレーション実装仕様書 Operation Specification Implementation Sheet | E2: ModuleID : | F2: =IF(LogicCommon!C2="","",LogicCommon!C2) -> MS | G2: LogicID : | H2: =IF(LogicCommon!E2="","",LogicCommon!E2) -> MSBEL1010 | I2: Ope.ID : | J2: Del01 | K2: Pj.ID : | L2: =IF(LogicCommon!G2="","",LogicCommon!G2) -> MC | M2: Ope.Body : | N2: "mcframe.serverMAUD.MAUDL5010.MAUDL_Operation"
A3: * | E3: SubModuleID : | F3: =IF(LogicCommon!C3="","",LogicCommon!C3) -> MSBE | G3: LogicClass : | H3: =IF(LogicCommon!E3="","",LogicCommon!E3) -> MSBEL_XfrInstReg | I3: Ope.Method : | J3: Del01 | K3: SuperClassPj.ID : | L3: =IF(LogicCommon!G3="","",LogicCommon!G3) | O3: Gene.Type : | P3: ALL
A4: * | E4: Version : | F4: 000000 | G4: LogicName : | H4: =IF(LogicCommon!E4="","",LogicCommon!E4) -> 移動指図登録 | I4: Ope.Name : | J4: 取消 | K4: SuperLogicID : | L4: =IF(LogicCommon!G4="","",LogicCommon!G4) -> MS.MSUDL5010 | M4: ImplOpe.ID:
A5: * | E5: ACType :
A6: * | D6: 概要 : | E6: 移動指図を取消する | L6: ID | N6: ID | P6: ID | R6: ID
A7: # | I7: U | K7: o | M7: o | O7: o | Q7: o
A8: # | D8: ブロック名 Block Name | E8: 型 Type | G8: super/share | H8: 対象ブロック名 Target Block Name | K8: TargetName | M8: TargetName | O8: TargetName | Q8: TargetName | U8: ブロック備考 Block Remarks
A9: # | D9: 項目名 Field Name | E9: 型 Type | F9: 桁 Digits | G9: フルネーム Full Name | H9: 日本語名 Japanese Name | I9: 上り項目 Request Message Field | J9: 下り項目 Response Message Field | S9: 条件および編集方法 Conditions and Editing Methods | U9: 項目備考 Field Remarks
A10: # | K10: 上り項目 Request Message Field | L10: 下り項目 Response Message Field | M10: 上り項目 Request Message Field | N10: 下り項目 Response Message Field | O10: 上り項目 Request Message Field | P10: 下り項目 Response Message Field | Q10: 上り項目 Request Message Field | R10: 下り項目 Response Message Field
A11: 10 | B11: * | D11: Del01_Hdr | E11: R | G11: $share$ | H11: MS.MSBEL1010.Chk01.Chk01_Hdr
A12: 10 | D12: xfr_inst_no | E12: #MA.XFR_INST_NO | G12: Movement order No. | H12: 移動指図ＮＯ | I12: E | J12: -
A13: 10 | D13: dlv_print | E13: #MA.FLG | G13: Delivery note immediate issue | H13: 納品書即時発行 | I13: E | J13: -
A14: 10 | D14: inst_upd_cntr | E14: #MA.UPD_CNT | G14: Update counter (Order) | H14: 更新カウンタ(指図) | I14: E | J14: -
A15: 10 | D15: err_flg | E15: #MA.FLG | G15: Error | H15: エラー | I15: - | J15: -
A17: 20 | B17: * | D17: Del01_Dtl | E17: L | G17: $share$ | H17: MS.MSBEL1010.Chk01.Chk01_Dtl
A18: 20 | D18: xfr_alloc_sts_no | E18: #MA.XFR_ALLOC_STS_NO | G18: Movement allocation status No. | H18: 移動引当状況ＮＯ | I18: E | J18: -
A19: 20 | D19: xfr_inst_no | E19: #MA.XFR_INST_NO | G19: Movement order No. | H19: 移動指図ＮＯ | I19: - | J19: -
A20: 20 | D20: xfr_inst_d_no | E20: #MA.XFR_INST_D_NO | G20: Movement order details No. | H20: 移動指図明細ＮＯ | I20: E | J20: -
A21: 20 | D21: alloc_sts_upd_cntr | E21: #MA.UPD_CNT | G21: Update counter (Allocation status) | H21: 更新カウンタ(引当状況) | I21: E | J21: -
A22: 20 | D22: wms_flg | E22: #MA.FLG | G22: WMS flg. | H22: ＷＭＳＦＬＧ | I22: E | J22: -
A24: 30 | B24: * | D24: Del01_Cnd | E24: R
A25: 30 | D25: indiv_prnt_flg | E25: #MA.FLG | G25: Individual issue | H25: 個別発行 | I25: E | J25: -
D26: 詳細 :

Sheet Prnt01
A1: * | B1: * | D1: L | E1: 1
A2: * | D2: オペレーション実装仕様書 Operation Specification Implementation Sheet | E2: ModuleID : | F2: =IF(LogicCommon!C2="","",LogicCommon!C2) -> MS | G2: LogicID : | H2: =IF(LogicCommon!E2="","",LogicCommon!E2) -> MSBEL1010 | I2: Ope.ID : | J2: Prnt01 | K2: Pj.ID : | L2: =IF(LogicCommon!G2="","",LogicCommon!G2) -> MC | M2: Ope.Body : | N2: "mcframe.serverMAUD.MAUDL5010.MAUDL_Operation"
A3: * | E3: SubModuleID : | F3: =IF(LogicCommon!C3="","",LogicCommon!C3) -> MSBE | G3: LogicClass : | H3: =IF(LogicCommon!E3="","",LogicCommon!E3) -> MSBEL_XfrInstReg | I3: Ope.Method : | J3: Prnt01 | K3: SuperClassPj.ID : | L3: =IF(LogicCommon!G3="","",LogicCommon!G3) | O3: Gene.Type : | P3: ALL
A4: * | E4: Version : | F4: 000000 | G4: LogicName : | H4: =IF(LogicCommon!E4="","",LogicCommon!E4) -> 移動指図登録 | I4: Ope.Name : | J4: 帳票発行 | K4: SuperLogicID : | L4: =IF(LogicCommon!G4="","",LogicCommon!G4) -> MS.MSUDL5010 | M4: ImplOpe.ID:
A5: * | E5: ACType :
A6: * | D6: 概要 : | E6: 帳票を発行する | L6: ID | N6: ID | P6: ID | R6: ID
A7: # | I7: U | K7: o | M7: o | O7: o | Q7: o
A8: # | D8: ブロック名 Block Name | E8: 型 Type | G8: super/share | H8: 対象ブロック名 Target Block Name | K8: TargetName | M8: TargetName | O8: TargetName | Q8: TargetName | U8: ブロック備考 Block Remarks
A9: # | D9: 項目名 Field Name | E9: 型 Type | F9: 桁 Digits | G9: フルネーム Full Name | H9: 日本語名 Japanese Name | I9: 上り項目 Request Message Field | J9: 下り項目 Response Message Field | S9: 条件および編集方法 Conditions and Editing Methods | U9: 項目備考 Field Remarks
A10: # | K10: 上り項目 Request Message Field | L10: 下り項目 Response Message Field | M10: 上り項目 Request Message Field | N10: 下り項目 Response Message Field | O10: 上り項目 Request Message Field | P10: 下り項目 Response Message Field | Q10: 上り項目 Request Message Field | R10: 下り項目 Response Message Field
A11: 10 | B11: * | D11: Prnt01_Hdr | E11: R | G11: $share$ | H11: MS.MSBEL1010.Chk01.Chk01_Hdr
A12: 10 | D12: xfr_inst_no | E12: #MA.XFR_INST_NO | G12: Movement order No. | H12: 移動指図ＮＯ | I12: E | J12: -
A13: 10 | D13: pick_print | E13: #MA.FLG | G13: Picking list immediate issue | H13: ピッキングリスト即時発行 | I13: E | J13: -
A14: 10 | D14: inst_print | E14: #MA.FLG | G14: Order sheet immediate issue | H14: 指図書即時発行 | I14: E | J14: -
A15: 10 | D15: dlv_print | E15: #MA.FLG | G15: Delivery note immediate issue | H15: 納品書即時発行 | I15: E | J15: -
A16: 10 | D16: pick_prnt_flg | E16: #MA.FLG | G16: Picking list issued | H16: ピッキングリスト発行済 | I16: E | J16: E
A17: 10 | D17: inst_prnt_flg | E17: #MA.FLG | G17: Order sheet issued | H17: 指図書発行済 | I17: E | J17: E
A18: 10 | D18: dlv_prnt_flg | E18: #MA.FLG | G18: Delivery note issued | H18: 納品書発行済 | I18: E | J18: E
A19: 10 | D19: inst_upd_cntr | E19: #MA.UPD_CNT | G19: Update counter (Order) | H19: 更新カウンタ(指図) | I19: E | J19: -
A20: 10 | D20: err_flg | E20: #MA.FLG | G20: Error | H20: エラー | I20: - | J20: -
A22: 20 | B22: * | D22: Prnt01_Cnd | E22: R
A23: 20 | D23: indiv_prnt_flg | E23: #MA.FLG | G23: Individual issue | H23: 個別発行 | I23: E | J23: -
A25: 30 | B25: * | D25: Prnt01_Dtl | E25: L
A26: 30 | D26: base_ac_dt | E26: #MA.DT | G26: Supply recording date (Base) | H26: 支給計上日（基） | I26: E | J26: -
D27: 詳細 :

Sheet Sprt01
A1: * | B1: * | D1: L | E1: 1
A2: * | D2: オペレーション実装仕様書 Operation Specification Implementation Sheet | E2: ModuleID : | F2: =IF(LogicCommon!C2="","",LogicCommon!C2) -> MS | G2: LogicID : | H2: =IF(LogicCommon!E2="","",LogicCommon!E2) -> MSBEL1010 | I2: Ope.ID : | J2: Sprt01 | K2: Pj.ID : | L2: =IF(LogicCommon!G2="","",LogicCommon!G2) -> MC | M2: Ope.Body : | N2: "mcframe.serverMAUD.MAUDL5010.MAUDL_Operation"
A3: * | E3: SubModuleID : | F3: =IF(LogicCommon!C3="","",LogicCommon!C3) -> MSBE | G3: LogicClass : | H3: =IF(LogicCommon!E3="","",LogicCommon!E3) -> MSBEL_XfrInstReg | I3: Ope.Method : | J3: Sprt01 | K3: SuperClassPj.ID : | L3: =IF(LogicCommon!G3="","",LogicCommon!G3) | O3: Gene.Type : | P3: ALL
A4: * | E4: Version : | F4: 000000 | G4: LogicName : | H4: =IF(LogicCommon!E4="","",LogicCommon!E4) -> 移動指図登録 | I4: Ope.Name : | J4: ロット提案 | K4: SuperLogicID : | L4: =IF(LogicCommon!G4="","",LogicCommon!G4) -> MS.MSUDL5010 | M4: ImplOpe.ID:
A5: * | E5: ACType :
A6: * | D6: 概要 : | E6: ロット提案を行う | M6: ID | O6: ID
A7: # | I7: U | K7: K | L7: o | N7: o
A8: # | D8: ブロック名 Block Name | E8: 型 Type | G8: super/share | H8: 対象ブロック名 Target Block Name | K8: CONST | L8: TargetName | N8: TargetName | R8: ブロック備考 Block Remarks
A9: # | D9: 項目名 Field Name | E9: 型 Type | F9: 桁 Digits | G9: フルネーム Full Name | H9: 日本語名 Japanese Name | I9: 上り項目 Request Message Field | J9: 下り項目 Response Message Field | P9: 条件および編集方法 Conditions and Editing Methods | R9: 項目備考 Field Remarks
A10: # | L10: 上り項目 Request Message Field | M10: 下り項目 Response Message Field | N10: 上り項目 Request Message Field | O10: 下り項目 Response Message Field
L11: 上り項目 Request Message Field | M11: 下り項目 Response Message Field | N11: 上り項目 Request Message Field | O11: 下り項目 Response Message Field
A12: 10 | B12: * | D12: Sprt01_Hdr | E12: R
A13: 10 | D13: trd_cd | E13: #MA.TRD_CD | G13: Transaction cd. | H13: 取引ＣＤ | I13: E | J13: -
A14: 10 | D14: gr_loc_cd | E14: #MA.LOC_CD | G14: GR location cd. | H14: 入庫場所ＣＤ | I14: E | J14: -
A15: 10 | D15: xfr_schd_dt | E15: #MA.DT | G15: Scheduled movement date | H15: 移動予定日 | I15: E | J15: -
L16: 上り項目 Request Message Field | M16: 下り項目 Response Message Field | N16: 上り項目 Request Message Field | O16: 下り項目 Response Message Field
A17: 20 | B17: * | D17: Sprt01_Dtl | E17: L
A18: 20 | D18: peg_no | E18: #MA.INT | G18: Pegging No. | H18: 紐付けＮＯ | I18: E | J18: E
A19: 20 | D19: check | E19: #MA.FLG | G19: Select | H19: 選択 | I19: E | J19: -
A20: 20 | D20: trd_ptn_typ | E20: #MA.TRD_PTN_TYP | G20: Transaction pattern type | H20: 取引パタン区分 | I20: - | J20: -
A21: 20 | D21: lg_grp_cd | E21: #MA.LG_GRP_CD | G21: Distribution group cd. | H21: 物流グループＣＤ | I21: - | J21: -
A22: 20 | D22: itm_cd | E22: #MA.ITM_CD | G22: Item cd. | H22: 品目ＣＤ | I22: E | J22: -
A23: 20 | D23: itm_sub1 | E23: #MA.ITM_SUB1 | G23: Branch No. 1 | H23: 枝番１ | I23: E | J23: -
A24: 20 | D24: itm_sub2 | E24: #MA.ITM_SUB2 | G24: Branch No. 2 | H24: 枝番２ | I24: E | J24: -
A25: 20 | D25: itm_sub3 | E25: #MA.ITM_SUB3 | G25: Branch No. 3 | H25: 枝番３ | I25: E | J25: -
A26: 20 | D26: alloc_flg | E26: #MA.FLG | G26: Allocation | H26: 引当 | I26: E | J26: -
A27: 20 | D27: not_lot_mix_flg | E27: #MA.FLG | G27: Prohibit mixed lots | H27: ロット混在不可 | I27: - | J27: -
A28: 20 | D28: not_sublot_mix_flg | E28: #MA.FLG | G28: Prohibit mixed sublots | H28: サブロット混在不可 | I28: - | J28: -
A29: 20 | D29: lot_none_flg | E29: #MA.FLG | G29: Without lot | H29: ロット指定無 | I29: E | J29: -
... A52: 20 | D52: gd_nm | E52: #MA.STK_GD_NM | G52: Grading name | H52: 格付名 | I52: - | J52: E
A53: 20 | D53: quality_typ | E53: #MA.QUALITY_TYP | G53: Conforming type | H53: 良品区分 | I53: E | J53: E | K53: MAC_QUALITY_TYP
A54: 20 | D54: quality_typ_nm | E54: #MA.QUALITY_TYP_NM | G54: Conforming type name | H54: 良品区分名 | I54: - | J54: E
A55: 20 | D55: sno1_null_flg | E55: #MA.FLG | G55: Allow without SEIBAN No. 1 | H55: 手配ＮＯ１無し可 | I55: E | J55: -
A56: 20 | D56: sno1 | E56: #MA.SNO1 | G56: SEIBAN No. 1 | H56: 手配ＮＯ１ | I56: E | J56: -
A57: 20 | D57: sno2_null_flg | E57: #MA.FLG | G57: Allow without SEIBAN No. 2 | H57: 手配ＮＯ２無し可 | I57: E | J57: -
A58: 20 | D58: sno2 | E58: #MA.SNO2 | G58: SEIBAN No. 2 | H58: 手配ＮＯ２ | I58: E | J58: -
A59: 20 | D59: sno3_null_flg | E59: #MA.FLG | G59: Allow without SEIBAN No. 3 | H59: 手配ＮＯ３無し可 | I59: E | J59: -
A60: 20 | D60: sno3 | E60: #MA.SNO3 | G60: SEIBAN No. 3 | H60: 手配ＮＯ３ | I60: E | J60: -
A61: 20 | D61: sno4_null_flg | E61: #MA.FLG | G61: Allow without SEIBAN No. 4 | H61: 手配ＮＯ４無し可 | I61: E | J61: -
A62: 20 | D62: sno4 | E62: #MA.SNO4 | G62: SEIBAN No. 4 | H62: 手配ＮＯ４ | I62: E | J62: -
...

Sheet Sprt02
A1: * | B1: * | D1: L | E1: 1
A2: * | D2: オペレーション実装仕様書 Operation Specification Implementation Sheet | E2: ModuleID : | F2: =IF(LogicCommon!C2="","",LogicCommon!C2) -> MS | G2: LogicID : | H2: =IF(LogicCommon!E2="","",LogicCommon!E2) -> MSBEL1010 | I2: Ope.ID : | J2: Sprt02 | K2: Pj.ID : | L2: =IF(LogicCommon!G2="","",LogicCommon!G2) -> MC | M2: Ope.Body : | N2: "mcframe.serverMAUD.MAUDL5010.MAUDL_Operation"
A3: * | E3: SubModuleID : | F3: =IF(LogicCommon!C3="","",LogicCommon!C3) -> MSBE | G3: LogicClass : | H3: =IF(LogicCommon!E3="","",LogicCommon!E3) -> MSBEL_XfrInstReg | I3: Ope.Method : | J3: Sprt02 | K3: SuperClassPj.ID : | L3: =IF(LogicCommon!G3="","",LogicCommon!G3) | O3: Gene.Type : | P3: ALL
A4: * | E4: Version : | F4: 000000 | G4: LogicName : | H4: =IF(LogicCommon!E4="","",LogicCommon!E4) -> 移動指図登録 | I4: Ope.Name : | J4: 支給日取得 | K4: SuperLogicID : | L4: =IF(LogicCommon!G4="","",LogicCommon!G4) -> MS.MSUDL5010 | M4: ImplOpe.ID:
A5: * | E5: ACType :
A6: * | D6: 概要 : | E6: 返品元の支給計上日の取得を行う。 | M6: ID | O6: ID
A7: # | I7: U | K7: K | L7: o | N7: o
A8: # | D8: ブロック名 Block Name | E8: 型 Type | G8: super/share | H8: 対象ブロック名 Target Block Name | K8: CONST | L8: TargetName | N8: TargetName | R8: ブロック備考 Block Remarks
A9: # | D9: 項目名 Field Name | E9: 型 Type | F9: 桁 Digits | G9: フルネーム Full Name | H9: 日本語名 Japanese Name | I9: 上り項目 Request Message Field | J9: 下り項目 Response Message Field | P9: 条件および編集方法 Conditions and Editing Methods | R9: 項目備考 Field Remarks
A10: # | L10: 上り項目 Request Message Field | M10: 下り項目 Response Message Field | N10: 上り項目 Request Message Field | O10: 下り項目 Response Message Field
L11: 上り項目 Request Message Field | M11: 下り項目 Response Message Field | N11: 上り項目 Request Message Field | O11: 下り項目 Response Message Field
A12: 10 | B12: * | D12: Sprt02_Hdr | E12: R
A13: 10 | D13: trd_cd | E13: #MA.TRD_CD | G13: Transaction cd. | H13: 取引ＣＤ | I13: E | J13: -
A14: 10 | D14: trd_nm | E14: #MA.TRD_NM | G14: Transaction name | H14: 取引名 | I14: E | J14: -
A15: 10 | D15: trd_ptn_typ | E15: #MA.TRD_PTN_TYP | G15: Transaction pattern type | H15: 取引パタン区分 | I15: E | J15: -
L16: 上り項目 Request Message Field | M16: 下り項目 Response Message Field | N16: 上り項目 Request Message Field | O16: 下り項目 Response Message Field
A17: 20 | B17: * | D17: Sprt02_Dtl | E17: L
A18: 20 | D18: peg_no | E18: #MA.INT | G18: Pegging No. | H18: 紐付けＮＯ | I18: E | J18: E
A19: 20 | D19: check | E19: #MA.FLG | G19: Select | H19: 選択 | I19: E | J19: -
A20: 20 | D20: base_dlv_slip_no | E20: #MA.DLV_SLIP_NO | G20: Return-from delivery note No. | H20: 返品元納品書ＮＯ | I20: E | J20: E
A21: 20 | D21: base_prov_act_no | E21: #MA.PROV_ACT_NO | G21: Return-from supply result No. | H21: 返品元支給実績ＮＯ | I21: E | J21: E
A22: 20 | D22: base_ac_dt | E22: #MA.DT | G22: Supply recording date (Base) | H22: 支給計上日（基） | I22: E | J22: E
D23: 詳細 :

Sheet 来歴
A1: 変更来歴
A3: Rev. | H3: 修正番号 | O3: 変更内容 | AQ3: 変更箇所
A4: 1 | O4: 初版
A5: 1.1 | H5: MS7032#218 | O5: Sprt01_Dtlブロックに以下の項目を追加 skip_chk_ship_flg | AQ5: Sprt01
A6: 1.2 | O6: 英語の名称を追記 | AQ6: 全般
