Workbook

Sheet LogicCommon
A2: オペレーション実装仕様書 | B2: ModuleID : | C2: MS | D2: LogicID : | E2: MSBEL5540 | F2: Pj.ID : | G2: MC
B3: SubModuleID : | C3: MSBE | D3: LogicClass : | E3: MSBEL_ShipActService | F3: SuperClassPj.ID :
D4: LogicName : | E4: 出荷実績サービス | F4: SuperLogicID : | G4: MS.MSUDL5010
A5: 概要 :
A6: 詳細 :

Sheet ShipAct_Upd01
A1: * | B1: * | D1: L | E1: 1
A2: * | D2: オペレーション実装仕様書 Operation Specification Implementation Sheet | E2: ModuleID : | F2: =IF(LogicCommon!C2="","",LogicCommon!C2) -> MS | G2: LogicID : | H2: =IF(LogicCommon!E2="","",LogicCommon!E2) -> MSBEL5540 | I2: Ope.ID : | J2: ShipAct_Upd01 | K2: Pj.ID : | L2: =IF(LogicCommon!G2="","",LogicCommon!G2) -> MC | M2: Ope.Body : | N2: "mcframe.serverMAUD.MAUDL5010.MAUDL_Operation"
A3: * | D3: =IF(LogicCommon!A3="","",LogicCommon!A3) | E3: SubModuleID : | F3: =IF(LogicCommon!C3="","",LogicCommon!C3) -> MSBE | G3: LogicClass : | H3: =IF(LogicCommon!E3="","",LogicCommon!E3) -> MSBEL_ShipActService | I3: Ope.Method : | J3: =J2 -> ShipAct_Upd01 | K3: SuperClassPj.ID : | L3: =IF(LogicCommon!G3="","",LogicCommon!G3) | O3: Gene.Type : | P3: ALL
A4: * | E4: Version : | F4: 000000 | G4: LogicName : | H4: =IF(LogicCommon!E4="","",LogicCommon!E4) -> 出荷実績サービス | I4: Ope.Name : | J4: 更新 | K4: SuperLogicID : | L4: =IF(LogicCommon!G4="","",LogicCommon!G4) -> MS.MSUDL5010 | M4: ImplOpe.ID:
A5: * | E5: ACType :
A6: * | D6: 概要 : | E6: 出荷実績を登録・更新・削除する。 | M6: ID | O6: ID | Q6: ID
A7: # | I7: U | K7: K | L7: o | N7: o | P7: o
A8: # | D8: ブロック名 Block Name | E8: 型 Type | G8: super/share | H8: 対象ブロック名 Target Block Name | K8: CONST | L8: TargetName | N8: TargetName | P8: TargetName | T8: ブロック備考 Block Remarks
A9: # | D9: 項目名 Field Name | E9: 型 Type | F9: 桁 Digits | G9: フルネーム Full Name | H9: 日本語名 Japanese Name | I9: 上り項目 Request Message Field | J9: 下り項目 Response Message Field | R9: 条件および編集方法 Conditions and Editing Methods | T9: 項目備考 Field Remarks
A10: # | L10: 上り項目 Request Message Field | M10: 下り項目 Response Message Field | N10: 上り項目 Request Message Field | O10: 下り項目 Response Message Field | P10: 上り項目 Request Message Field | Q10: 下り項目 Response Message Field
A11: 10 | B11: * | D11: ShipAct_Hdr | E11: L
A12: 10 | D12: data_crud_typ | E12: #MA.DATA_CRUD_TYP | G12: Data update type | H12: データ更新区分 | I12: E | J12: -
A13: 10 | D13: sa | E13: R | F13: DBC:MS.MST_SHIP_ACT | G13: Shipping result | H13: 出荷実績
A14: 10 | D14: sa.ship_act_no# | E14: RI | G14: Shipping result No. | H14: 出荷実績ＮＯ | I14: E | J14: E
A15: 10 | D15: sa.ship_act_rev# | E15: RI | G15: Shipping result rev. number | H15: 出荷実績改訂番号 | I15: - | J15: E
A16: 10 | D16: sa.ship_inst_no# | E16: RI | G16: Shipping order No. | H16: 出荷指図ＮＯ | I16: E | J16: -
A17: 10 | D17: sa.ac_dt# | E17: RI | G17: Recording date | H17: 計上日 | I17: E | J17: -
A18: 10 | D18: sa.ship_tm# | E18: RI | G18: Shipping date and time | H18: 出荷日時 | I18: E | J18: -
A19: 10 | D19: sa.dlv_tm# | E19: RI | G19: Delivery date and time | H19: 納品日時 | I19: E | J19: -
A20: 10 | D20: can_ac_dt | E20: #MA.DT | G20: Cancellation recording date | H20: 取消計上日 | I20: E | J20: -
A21: 10 | D21: sa.rqst_dpt_cd# | E21: RI | G21: Requesting dept. cd. | H21: 依頼元部門ＣＤ | I21: E | J21: -
A22: 10 | D22: sa.rqst_usr_cd# | E22: RI | G22: Requesting PIC cd. | H22: 依頼元担当者ＣＤ | I22: E | J22: -
A23: 10 | D23: sa.ship_fr_lg_grp_cd# | E23: RI | G23: Shipping point distribution group cd. | H23: 出荷元物流グループＣＤ | I23: E | J23: -
A24: 10 | D24: sa.wg_cd# | E24: RI | G24: WG cd. | H24: ＷＧ ＣＤ | I24: E | J24: -
A25: 10 | D25: sa.ship_term_cd# | E25: RI | G25: Shipping conditions cd. | H25: 出荷条件ＣＤ | I25: E | J25: -
... A65: 10 | D65: dlv_slip_no | E65: #MA.DLV_SLIP_NO | G65: Delivery note No. | H65: 納品書ＮＯ | I65: E | J65: -
A67: 20 | B67: * | D67: ShipAct_Dtl | E67: L
A68: 20 | D68: data_crud_typ | E68: #MA.DATA_CRUD_TYP | G68: Data update type | H68: データ更新区分 | I68: E | J68: -
A69: 20 | D69: sad | E69: R | F69: DBC:MS.MST_SHIP_ACT_D | G69: Shipping result details | H69: 出荷実績明細
A70: 20 | D70: sad.ship_act_d_no# | E70: RI | G70: Shipping result details No. | H70: 出荷実績明細ＮＯ | I70: E | J70: E
A71: 20 | D71: sad.ship_act_no# | E71: RI | G71: Shipping result No. | H71: 出荷実績ＮＯ | I71: - | J71: E
A72: 20 | D72: sad.disp_seq# | E72: RI | G72: Display order | H72: 表示順 | I72: E | J72: -
A73: 20 | D73: sad.ship_alloc_sts_no# | E73: RI | G73: Shipping allocation status No. | H73: 出荷引当状況ＮＯ | I73: E | J73: -
A74: 20 | D74: sad.trd_cd# | E74: RI | G74: Transaction cd. | H74: 取引ＣＤ | I74: E | J74: -
A75: 20 | D75: sad.trd_ptn_typ# | E75: RI | G75: Transaction pattern type | H75: 取引パタン区分 | I75: E | J75: -
A76: 20 | D76: sad.ship_loc_cd# | E76: RI | G76: Shipping location cd. | H76: 出荷場所ＣＤ | I76: E | J76: -
A77: 20 | D77: sad.ship_str_ln_cd# | E77: RI | G77: Shipping rack/line cd. | H77: 出荷棚・ラインＣＤ | I77: E | J77: -
A78: 20 | D78: sad.dlv_id_typ# | E78: RI | G78: Delivery destination identification type | H78: 納品先識別区分 | I78: E | J78: -
A79: 20 | D79: sad.dlv_id_cd# | E79: RI | G79: Delivery destination identification cd. | H79: 納品先識別ＣＤ | I79: E | J79: -
A80: 20 | D80: sad.dlv_id_nm# | E80: RI | G80: Delivery destination identification name | H80: 納品先識別名 | I80: E | J80: -
...

Sheet ShipAct_Upd02
A1: * | B1: * | D1: L | E1: 1
A2: * | D2: オペレーション実装仕様書 Operation Specification Implementation Sheet | E2: ModuleID : | F2: =IF(LogicCommon!C2="","",LogicCommon!C2) -> MS | G2: LogicID : | H2: =IF(LogicCommon!E2="","",LogicCommon!E2) -> MSBEL5540 | I2: Ope.ID : | J2: ShipAct_Upd02 | K2: Pj.ID : | L2: =IF(LogicCommon!G2="","",LogicCommon!G2) -> MC | M2: Ope.Body : | N2: "mcframe.serverMAUD.MAUDL5010.MAUDL_Operation"
A3: * | D3: =IF(LogicCommon!A3="","",LogicCommon!A3) | E3: SubModuleID : | F3: =IF(LogicCommon!C3="","",LogicCommon!C3) -> MSBE | G3: LogicClass : | H3: =IF(LogicCommon!E3="","",LogicCommon!E3) -> MSBEL_ShipActService | I3: Ope.Method : | J3: =J2 -> ShipAct_Upd02 | K3: SuperClassPj.ID : | L3: =IF(LogicCommon!G3="","",LogicCommon!G3) | O3: Gene.Type : | P3: ALL
A4: * | E4: Version : | F4: 000000 | G4: LogicName : | H4: =IF(LogicCommon!E4="","",LogicCommon!E4) -> 出荷実績サービス | I4: Ope.Name : | J4: 更新（出荷返品・入荷） | K4: SuperLogicID : | L4: =IF(LogicCommon!G4="","",LogicCommon!G4) -> MS.MSUDL5010 | M4: ImplOpe.ID:
A5: * | E5: ACType :
A6: * | D6: 概要 : | E6: 出荷返品および納品数量を更新する。 | M6: ID | O6: ID | Q6: ID
A7: # | I7: U | K7: K | L7: o | N7: o | P7: o
A8: # | D8: ブロック名 Block Name | E8: 型 Type | G8: super/share | H8: 対象ブロック名 Target Block Name | L8: TargetName | N8: TargetName | P8: TargetName | T8: ブロック備考 Block Remarks
A9: # | D9: 項目名 Field Name | E9: 型 Type | F9: 桁 Digits | G9: フルネーム Full Name | H9: 日本語名 Japanese Name | I9: 上り項目 Request Message Field | J9: 下り項目 Response Message Field | R9: 条件および編集方法 Conditions and Editing Methods | T9: 項目備考 Field Remarks
A10: # | L10: 上り項目 Request Message Field | M10: 下り項目 Response Message Field | N10: 上り項目 Request Message Field | O10: 下り項目 Response Message Field | P10: 上り項目 Request Message Field | Q10: 下り項目 Response Message Field
A11: 10 | B11: * | D11: ShipAct_Dtl | E11: L | G11: $share$ | H11: MS.MSBEL5540.ShipAct_Upd01.ShipAct_Dtl
A12: 10 | D12: data_crud_typ | E12: #MA.DATA_CRUD_TYP | G12: Data update type | H12: データ更新区分 | I12: - | J12: -
A13: 10 | D13: sad | E13: R | F13: DBC:MS.MST_SHIP_ACT_D | G13: Shipping result details | H13: 出荷実績明細
A14: 10 | D14: sad.ship_act_d_no# | E14: RI | G14: Shipping result details No. | H14: 出荷実績明細ＮＯ | I14: - | J14: -
A15: 10 | D15: sad.ship_act_no# | E15: RI | G15: Shipping result No. | H15: 出荷実績ＮＯ | I15: - | J15: -
A16: 10 | D16: sad.disp_seq# | E16: RI | G16: Display order | H16: 表示順 | I16: - | J16: -
A17: 10 | D17: sad.ship_alloc_sts_no# | E17: RI | G17: Shipping allocation status No. | H17: 出荷引当状況ＮＯ | I17: - | J17: -
A18: 10 | D18: sad.trd_cd# | E18: RI | G18: Transaction cd. | H18: 取引ＣＤ | I18: - | J18: -
A19: 10 | D19: sad.trd_ptn_typ# | E19: RI | G19: Transaction pattern type | H19: 取引パタン区分 | I19: - | J19: -
A20: 10 | D20: sad.ship_loc_cd# | E20: RI | G20: Shipping location cd. | H20: 出荷場所ＣＤ | I20: - | J20: -
A21: 10 | D21: sad.ship_str_ln_cd# | E21: RI | G21: Shipping rack/line cd. | H21: 出荷棚・ラインＣＤ | I21: - | J21: -
A22: 10 | D22: sad.dlv_id_typ# | E22: RI | G22: Delivery destination identification type | H22: 納品先識別区分 | I22: - | J22: -
A23: 10 | D23: sad.dlv_id_cd# | E23: RI | G23: Delivery destination identification cd. | H23: 納品先識別ＣＤ | I23: - | J23: -
A24: 10 | D24: sad.dlv_id_nm# | E24: RI | G24: Delivery destination identification name | H24: 納品先識別名 | I24: - | J24: -
A25: 10 | D25: sad.dlv_zip_cd# | E25: RI | G25: Zip code (Delivery destination) | H25: 納品先郵便番号 | I25: - | J25: -
... A102: 10 | D102: err_flg | E102: #MA.FLG | G102: Error | H102: エラー | I102: - | J102: -

Sheet ShipAct_Upd03
A1: * | B1: * | D1: L | E1: 1
A2: * | D2: オペレーション実装仕様書 Operation Specification Implementation Sheet | E2: ModuleID : | F2: =IF(LogicCommon!C2="","",LogicCommon!C2) -> MS | G2: LogicID : | H2: =IF(LogicCommon!E2="","",LogicCommon!E2) -> MSBEL5540 | I2: Ope.ID : | J2: ShipAct_Upd03 | K2: Pj.ID : | L2: =IF(LogicCommon!G2="","",LogicCommon!G2) -> MC | M2: Ope.Body : | N2: "mcframe.serverMAUD.MAUDL5010.MAUDL_Operation"
A3: * | D3: =IF(LogicCommon!A3="","",LogicCommon!A3) | E3: SubModuleID : | F3: =IF(LogicCommon!C3="","",LogicCommon!C3) -> MSBE | G3: LogicClass : | H3: =IF(LogicCommon!E3="","",LogicCommon!E3) -> MSBEL_ShipActService | I3: Ope.Method : | J3: =J2 -> ShipAct_Upd03 | K3: SuperClassPj.ID : | L3: =IF(LogicCommon!G3="","",LogicCommon!G3) | O3: Gene.Type : | P3: ALL
A4: * | E4: Version : | F4: 000000 | G4: LogicName : | H4: =IF(LogicCommon!E4="","",LogicCommon!E4) -> 出荷実績サービス | I4: Ope.Name : | J4: 現品票発行済更新 | K4: SuperLogicID : | L4: =IF(LogicCommon!G4="","",LogicCommon!G4) -> MS.MSUDL5010 | M4: ImplOpe.ID:
A5: * | E5: ACType :
A6: * | D6: 概要 : | E6: 現品票発行済フラグをオン(発行済)に更新する。 | M6: ID | O6: ID | Q6: ID
A7: # | I7: U | K7: K | L7: o | N7: o | P7: o
A8: # | D8: ブロック名 Block Name | E8: 型 Type | G8: super/share | H8: 対象ブロック名 Target Block Name | L8: TargetName | N8: TargetName | P8: TargetName | T8: ブロック備考 Block Remarks
A9: # | D9: 項目名 Field Name | E9: 型 Type | F9: 桁 Digits | G9: フルネーム Full Name | H9: 日本語名 Japanese Name | I9: 上り項目 Request Message Field | J9: 下り項目 Response Message Field | R9: 条件および編集方法 Conditions and Editing Methods | T9: 項目備考 Field Remarks
A10: # | L10: 上り項目 Request Message Field | M10: 下り項目 Response Message Field | N10: 上り項目 Request Message Field | O10: 下り項目 Response Message Field | P10: 上り項目 Request Message Field | Q10: 下り項目 Response Message Field
A11: 10 | B11: * | D11: ShipAct_Dtl | E11: L | G11: $share$ | H11: MS.MSBEL5540.ShipAct_Upd01.ShipAct_Dtl
A12: 10 | D12: data_crud_typ | E12: #MA.DATA_CRUD_TYP | G12: Data update type | H12: データ更新区分 | I12: - | J12: -
A13: 10 | D13: sad | E13: R | F13: DBC:MS.MST_SHIP_ACT_D | G13: Shipping result details | H13: 出荷実績明細
A14: 10 | D14: sad.ship_act_d_no# | E14: RI | G14: Shipping result details No. | H14: 出荷実績明細ＮＯ | I14: E | J14: -
A15: 10 | D15: sad.ship_act_no# | E15: RI | G15: Shipping result No. | H15: 出荷実績ＮＯ | I15: - | J15: -
A16: 10 | D16: sad.disp_seq# | E16: RI | G16: Display order | H16: 表示順 | I16: - | J16: -
A17: 10 | D17: sad.ship_alloc_sts_no# | E17: RI | G17: Shipping allocation status No. | H17: 出荷引当状況ＮＯ | I17: - | J17: -
A18: 10 | D18: sad.trd_cd# | E18: RI | G18: Transaction cd. | H18: 取引ＣＤ | I18: - | J18: -
A19: 10 | D19: sad.trd_ptn_typ# | E19: RI | G19: Transaction pattern type | H19: 取引パタン区分 | I19: - | J19: -
A20: 10 | D20: sad.ship_loc_cd# | E20: RI | G20: Shipping location cd. | H20: 出荷場所ＣＤ | I20: - | J20: -
A21: 10 | D21: sad.ship_str_ln_cd# | E21: RI | G21: Shipping rack/line cd. | H21: 出荷棚・ラインＣＤ | I21: - | J21: -
A22: 10 | D22: sad.dlv_id_typ# | E22: RI | G22: Delivery destination identification type | H22: 納品先識別区分 | I22: - | J22: -
A23: 10 | D23: sad.dlv_id_cd# | E23: RI | G23: Delivery destination identification cd. | H23: 納品先識別ＣＤ | I23: - | J23: -
A24: 10 | D24: sad.dlv_id_nm# | E24: RI | G24: Delivery destination identification name | H24: 納品先識別名 | I24: - | J24: -
A25: 10 | D25: sad.dlv_zip_cd# | E25: RI | G25: Zip code (Delivery destination) | H25: 納品先郵便番号 | I25: - | J25: -
... A102: 10 | D102: err_flg | E102: #MA.FLG | G102: Error | H102: エラー | I102: - | J102: -

Sheet ShipAct_Chk01
A1: * | B1: * | D1: L | E1: 1
A2: * | D2: オペレーション実装仕様書 Operation Specification Implementation Sheet | E2: ModuleID : | F2: =IF(LogicCommon!C2="","",LogicCommon!C2) -> MS | G2: LogicID : | H2: =IF(LogicCommon!E2="","",LogicCommon!E2) -> MSBEL5540 | I2: Ope.ID : | J2: ShipAct_Chk01 | K2: Pj.ID : | L2: =IF(LogicCommon!G2="","",LogicCommon!G2) -> MC | M2: Ope.Body : | N2: "mcframe.serverMAUD.MAUDL5010.MAUDL_Operation"
A3: * | D3: =IF(LogicCommon!A3="","",LogicCommon!A3) | E3: SubModuleID : | F3: =IF(LogicCommon!C3="","",LogicCommon!C3) -> MSBE | G3: LogicClass : | H3: =IF(LogicCommon!E3="","",LogicCommon!E3) -> MSBEL_ShipActService | I3: Ope.Method : | J3: =J2 -> ShipAct_Chk01 | K3: SuperClassPj.ID : | L3: =IF(LogicCommon!G3="","",LogicCommon!G3) | O3: Gene.Type : | P3: ALL
A4: * | E4: Version : | F4: 000000 | G4: LogicName : | H4: =IF(LogicCommon!E4="","",LogicCommon!E4) -> 出荷実績サービス | I4: Ope.Name : | J4: 更新前チェック（サービス呼出のみ） | K4: SuperLogicID : | L4: =IF(LogicCommon!G4="","",LogicCommon!G4) -> MS.MSUDL5010 | M4: ImplOpe.ID:
A5: * | E5: ACType :
A6: * | D6: 概要 : | E6: 出荷実績の登録・更新・削除の前に後続のチェックサービスを呼び出し登録・更新・削除が可能かチェックをする。 | M6: ID | O6: ID | Q6: ID
A7: # | I7: U | K7: K | L7: o | N7: o | P7: o
A8: # | D8: ブロック名 Block Name | E8: 型 Type | G8: super/share | H8: 対象ブロック名 Target Block Name | L8: TargetName | N8: TargetName | P8: TargetName | T8: ブロック備考 Block Remarks
A9: # | D9: 項目名 Field Name | E9: 型 Type | F9: 桁 Digits | G9: フルネーム Full Name | H9: 日本語名 Japanese Name | I9: 上り項目 Request Message Field | J9: 下り項目 Response Message Field | R9: 条件および編集方法 Conditions and Editing Methods | T9: 項目備考 Field Remarks
A10: # | L10: 上り項目 Request Message Field | M10: 下り項目 Response Message Field | N10: 上り項目 Request Message Field | O10: 下り項目 Response Message Field | P10: 上り項目 Request Message Field | Q10: 下り項目 Response Message Field
A11: 10 | B11: * | D11: ShipAct_Hdr | E11: L | G11: $share$ | H11: MS.MSBEL5540.ShipAct_Upd01.ShipAct_Hdr
A12: 10 | D12: data_crud_typ | E12: #MA.DATA_CRUD_TYP | G12: Data update type | H12: データ更新区分 | I12: E | J12: -
A13: 10 | D13: sa | E13: R | F13: DBC:MS.MST_SHIP_ACT | G13: Shipping result | H13: 出荷実績
A14: 10 | D14: sa.ship_act_no# | E14: RI | G14: Shipping result No. | H14: 出荷実績ＮＯ | I14: E | J14: -
A15: 10 | D15: sa.ship_act_rev# | E15: RI | G15: Shipping result rev. number | H15: 出荷実績改訂番号 | I15: - | J15: -
A16: 10 | D16: sa.ship_inst_no# | E16: RI | G16: Shipping order No. | H16: 出荷指図ＮＯ | I16: E | J16: -
A17: 10 | D17: sa.ac_dt# | E17: RI | G17: Recording date | H17: 計上日 | I17: E | J17: -
A18: 10 | D18: sa.ship_tm# | E18: RI | G18: Shipping date and time | H18: 出荷日時 | I18: E | J18: -
A19: 10 | D19: sa.dlv_tm# | E19: RI | G19: Delivery date and time | H19: 納品日時 | I19: E | J19: -
A20: 10 | D20: can_ac_dt | E20: #MA.DT | G20: Cancellation recording date | H20: 取消計上日 | I20: E | J20: -
A21: 10 | D21: sa.rqst_dpt_cd# | E21: RI | G21: Requesting dept. cd. | H21: 依頼元部門ＣＤ | I21: - | J21: -
A22: 10 | D22: sa.rqst_usr_cd# | E22: RI | G22: Requesting PIC cd. | H22: 依頼元担当者ＣＤ | I22: - | J22: -
A23: 10 | D23: sa.ship_fr_lg_grp_cd# | E23: RI | G23: Shipping point distribution group cd. | H23: 出荷元物流グループＣＤ | I23: E | J23: -
A24: 10 | D24: sa.wg_cd# | E24: RI | G24: WG cd. | H24: ＷＧ ＣＤ | I24: - | J24: -
A25: 10 | D25: sa.ship_term_cd# | E25: RI | G25: Shipping conditions cd. | H25: 出荷条件ＣＤ | I25: - | J25: -
... A63: 10 | D63: dlv_slip_no | E63: #MA.DLV_SLIP_NO | G63: Delivery note No. | H63: 納品書ＮＯ | I63: - | J63: -
A65: 20 | B65: * | D65: SihpAct_Dtl | E65: L | G65: $share$ | H65: MS.MSBEL5540.ShipAct_Upd01.ShipAct_Dtl
A66: 20 | D66: data_crud_typ | E66: #MA.DATA_CRUD_TYP | G66: Data update type | H66: データ更新区分 | I66: E | J66: -
A67: 20 | D67: sad | E67: R | F67: DBC:MS.MST_SHIP_ACT_D | G67: Shipping result details | H67: 出荷実績明細
A68: 20 | D68: sad.ship_act_d_no# | E68: RI | G68: Shipping result details No. | H68: 出荷実績明細ＮＯ | I68: E | J68: -
A69: 20 | D69: sad.ship_act_no# | E69: RI | G69: Shipping result No. | H69: 出荷実績ＮＯ | I69: - | J69: -
A70: 20 | D70: sad.disp_seq# | E70: RI | G70: Display order | H70: 表示順 | I70: - | J70: -
A71: 20 | D71: sad.ship_alloc_sts_no# | E71: RI | G71: Shipping allocation status No. | H71: 出荷引当状況ＮＯ | I71: E | J71: -
A72: 20 | D72: sad.trd_cd# | E72: RI | G72: Transaction cd. | H72: 取引ＣＤ | I72: E | J72: -
A73: 20 | D73: sad.trd_ptn_typ# | E73: RI | G73: Transaction pattern type | H73: 取引パタン区分 | I73: E | J73: -
A74: 20 | D74: sad.ship_loc_cd# | E74: RI | G74: Shipping location cd. | H74: 出荷場所ＣＤ | I74: E | J74: -
A75: 20 | D75: sad.ship_str_ln_cd# | E75: RI | G75: Shipping rack/line cd. | H75: 出荷棚・ラインＣＤ | I75: E | J75: -
A76: 20 | D76: sad.dlv_id_typ# | E76: RI | G76: Delivery destination identification type | H76: 納品先識別区分 | I76: E | J76: -
A77: 20 | D77: sad.dlv_id_cd# | E77: RI | G77: Delivery destination identification cd. | H77: 納品先識別ＣＤ | I77: E | J77: -
A78: 20 | D78: sad.dlv_id_nm# | E78: RI | G78: Delivery destination identification name | H78: 納品先識別名 | I78: - | J78: -
...

Sheet ShipAct_InptChk01
A1: * | B1: * | D1: L | E1: 1
A2: * | D2: オペレーション実装仕様書 Operation Specification Implementation Sheet | E2: ModuleID : | F2: =IF(LogicCommon!C2="","",LogicCommon!C2) -> MS | G2: LogicID : | H2: =IF(LogicCommon!E2="","",LogicCommon!E2) -> MSBEL5540 | I2: Ope.ID : | J2: ShipAct_InptChk01 | K2: Pj.ID : | L2: =IF(LogicCommon!G2="","",LogicCommon!G2) -> MC | M2: Ope.Body : | N2: MA.MAUDL5010.Checker
A3: * | D3: =IF(LogicCommon!A3="","",LogicCommon!A3) | E3: SubModuleID : | F3: =IF(LogicCommon!C3="","",LogicCommon!C3) -> MSBE | G3: LogicClass : | H3: =IF(LogicCommon!E3="","",LogicCommon!E3) -> MSBEL_ShipActService | I3: Ope.Method : | J3: =J2 -> ShipAct_InptChk01 | K3: SuperClassPj.ID : | L3: =IF(LogicCommon!G3="","",LogicCommon!G3) | O3: Gene.Type : | P3: ALL
A4: * | E4: Version : | F4: 000000 | G4: LogicName : | H4: =IF(LogicCommon!E4="","",LogicCommon!E4) -> 出荷実績サービス | I4: Ope.Name : | J4: 登録・更新前チェック | K4: SuperLogicID : | L4: =IF(LogicCommon!G4="","",LogicCommon!G4) -> MS.MSUDL5010 | M4: ImplOpe.ID:
A5: * | E5: ACType :
A6: * | D6: 概要 : | E6: 出荷実績の登録・更新が可能かチェックをする。 | M6: ID | O6: ID | Q6: ID | AD6: ID | AF6: ID | AH6: ID
A7: # | I7: U | K7: K | L7: K | M7: K | N7: K | O7: K | P7: K | Q7: K | R7: K | S7: K | T7: K | U7: K | V7: K | W7: K | X7: K | Y7: K | Z7: K | AA7: K | AB7: K | AC7: o | AD7: SA.v0 | AE7: o | AG7: o
A8: # | D8: ブロック名 Block Name | E8: 型 Type | G8: super/share | H8: 対象ブロック名 Target Block Name | K8: REQ_UPD_CNT_CHK | L8: REQUIRED | M8: CHK_NUM | N8: SMALL_LARGE | O8: CHK_DT | P8: BEFORE_AFTER | Q8: CHK_PTN | R8: DUPLICATE | S8: TOO_MANY_INPUTS | T8: AT_LEAST_ONE | U8: ONLY_ONE_INPUT | V8: LIST_LOGIC | W8: LIST_OUT | X8: LIST_OUT_BASE | Y8: LIST_IN | Z8: LIST_IN_BASE | AA8: CONST | AB8: NULL_VAL | AC8: TargetName | AD8: OPE.MS.MSBEL5540.ShipAct_Chk01 | AE8: TargetName | AG8: TargetName | AK8: ブロック備考 Block Remarks
A9: # | D9: 項目名 Field Name | E9: 型 Type | F9: 桁 Digits | G9: フルネーム Full Name | H9: 日本語名 Japanese Name | I9: 上り項目 Request Message Field | J9: 下り項目 Response Message Field | AI9: 条件および編集方法 Conditions and Editing Methods | AK9: 項目備考 Field Remarks
A10: # | AC10: 上り項目 Request Message Field | AD10: 下り項目 Response Message Field | AE10: 上り項目 Request Message Field | AF10: 下り項目 Response Message Field | AG10: 上り項目 Request Message Field | AH10: 下り項目 Response Message Field
A11: 10 | B11: * | D11: ShipAct_InptChk01_Hdr | E11: L | AC11: ShipAct_Hdr | AD11: ShipAct_Hdr
A12: 10 | D12: data_crud_typ | E12: #MA.DATA_CRUD_TYP | G12: Data update type | H12: データ更新区分 | I12: E | J12: E | L12: E | AC12: E | AD12: -
A13: 10 | D13: ship_act_no | E13: #MA.SHIP_ACT_NO | G13: Shipping result No. | H13: 出荷実績ＮＯ | I13: E | J13: E | AC13: E | AD13: -
A14: 10 | D14: ship_act_rev | E14: #MA.SLIP_REV | G14: Shipping result rev. number | H14: 出荷実績改訂番号 | I14: - | J14: - | AC14: - | AD14: -
A15: 10 | D15: ship_inst_no | E15: #MA.SHIP_INST_NO | G15: Shipping order No. | H15: 出荷指図ＮＯ | I15: E | J15: E | AC15: E | AD15: -
A16: 10 | D16: ac_dt | E16: #MA.DT | G16: Recording date | H16: 計上日 | I16: E | J16: E | L16: E | O16: bfToday | AC16: E | AD16: -
A17: 10 | D17: can_ac_dt | E17: #MA.DT | G17: Cancellation recording date | H17: 取消計上日 | I17: E | J17: E | O17: bfToday | AC17: E | AD17: -
A18: 10 | D18: ship_tm | E18: #MA.TM | G18: Shipping date and time | H18: 出荷日時 | I18: E | J18: E | L18: E | O18: tmBfToday | P18: ship_tm:BF | AC18: E | AD18: -
A19: 10 | D19: ship_dt | E19: #MA.DT | G19: Shipping date | H19: 出荷日 | I19: - | J19: - | AC19: - | AD19: -
A20: 10 | D20: dlv_tm | E20: #MA.TM | G20: Delivery date and time | H20: 納品日時 | I20: E | J20: E | L20: E | P20: ship_tm:AF | AC20: E | AD20: -
A21: 10 | D21: rqst_usr_cd | E21: #MA.USR_CD | G21: Requesting PIC cd. | H21: 依頼元担当者ＣＤ | I21: E | J21: E | V21: MA.MAUAL0010.Usr | AC21: - | AD21: -
A22: 10 | D22: rqst_dpt_cd | E22: #MA.DPT_CD | G22: Requesting dept. cd. | H22: 依頼元部門ＣＤ | I22: E | J22: E | V22: MA.MAUAL0010.Dpt | Y22: rqst_usr_cd;ac_dt;MAC_DPT_IS_SRCH_TYP.SCE | Z22: usr_cd;dt;dpt_is_srch_typ | AC22: - | AD22: -
A23: 10 | D23: ship_fr_lg_grp_cd | E23: #MA.LG_GRP_CD | G23: Shipping point distribution group cd. | H23: 出荷元物流グループＣＤ | I23: E | J23: E | L23: E | V23: MA.MAUAL0010.LgGrp | W23: wg_cd | Y23: true | Z23: loc_flg | AC23: E | AD23: -
A24: 10 | D24: wg_cd | E24: #MA.WG_CD | G24: WG cd. | H24: ＷＧ ＣＤ | I24: - | J24: E | AC24: - | AD24: -
A25: 10 | D25: ship_term_cd | E25: #MA.SHIP_TERM_CD | G25: Shipping conditions cd. | H25: 出荷条件ＣＤ | I25: - | J25: E | V25: MA.MAUAL0010.ShipTerm | AC25: - | AD25: -
A26: 10 | D26: ship_usr_cd | E26: #MA.USR_CD | G26: Shipping PIC cd. | H26: 出荷担当者ＣＤ | I26: E | J26: E | V26: MA.MAUAL0010.Usr | AC26: - | AD26: -
A27: 10 | D27: ship_dpt_cd | E27: #MA.DPT_CD | G27: Shipping dept. cd. | H27: 出荷部門ＣＤ | I27: E | J27: E | V27: MA.MAUAL0010.Dpt | Y27: ship_usr_cd;ship_dt;true;MAC_DPT_IS_SRCH_TYP.SHIP | Z27: usr_cd;dt;ship_dpt_flg;dpt_is_srch_typ | AC27: - | AD27: -
A28: 10 | D28: cst_cd | E28: #MA.BP_CD | G28: Customer cd. | H28: 得意先ＣＤ | I28: E | J28: E | V28: MA.MAUAL0010.Bp | Y28: MAC_BP_IS_SRCH_TYP.CST_NOT_SUNDRY | Z28: bp_is_srch_typ | AC28: E | AD28: -
A29: 10 | D29: ship_to_id_typ | E29: #MS.SHIP_TO_ID_TYP | G29: Receiving point identification type | H29: 送付先識別区分 | I29: E | J29: E | L29: E | AA29: MSC_SHIP_TO_ID_TYP | AC29: E | AD29: -
A30: 10 | D30: ship_to_id_cd | E30: #MS.SHIP_TO_ID_CD | G30: Receiving point identification cd. | H30: 送付先識別ＣＤ | I30: E | J30: E | L30: E | V30: MS.MSUAL0060.ShipToId | W30: ship_to_sundry_flg;ship_to_id_nm;ship_to_zip_cd;ship_to_addr1;ship_to_addr2;ship_to_addr3;ship_to_addr4;ship_to_cntct_dpt;ship_to_cntct_psn;ship_to_tel;ship_to_fax;ship_to_lg_grp_cd | X30: ship_to_sundry_flg;ship_to_id_nm;zip_cd;addr1;addr2;addr3;addr4;ship_to_cntct_dpt;ship_to_cntct_psn;tel;fax;lg_grp_cd | Y30: ship_to_id_typ;ship_dt | Z30: ship_to_id_typ;base_dt | AC30: E | AD30: -
A31: 10 | D31: ship_to_id_nm | E31: #MS.SHIP_TO_ID_NM | G31: Receiving point Identification name | H31: 送付先識別名 | I31: E | J31: E | AC31: - | AD31: -
A32: 10 | D32: ship_to_zip_cd | E32: #MA.ZIP_CD | G32: Receiving point zip code | H32: 送付先郵便番号 | I32: E | J32: E | AC32: - | AD32: -
A33: 10 | D33: ship_to_addr1 | E33: #MA.ADDR1 | G33: Receiving point address 1 | H33: 送付先住所１ | I33: E | J33: E | AC33: - | AD33: -
A34: 10 | D34: ship_to_addr2 | E34: #MA.ADDR2 | G34: Receiving point address 2 | H34: 送付先住所２ | I34: E | J34: E | AC34: - | AD34: -
A35: 10 | D35: ship_to_addr3 | E35: #MA.ADDR3 | G35: Receiving point address 3 | H35: 送付先住所３ | I35: E | J35: E | AC35: - | AD35: -
A36: 10 | D36: ship_to_addr4 | E36: #MA.ADDR4 | G36: Receiving point address 4 | H36: 送付先住所４ | I36: E | J36: E | AC36: - | AD36: -
A37: 10 | D37: ship_to_cntct_dpt | E37: #MA.BP_CNTCT_DPT | G37: Receiving point dept. | H37: 送付先部署 | I37: E | J37: E | AC37: - | AD37: -
A38: 10 | D38: ship_to_cntct_psn | E38: #MA.BP_CNTCT_PSN | G38: Receiving point PIC | H38: 送付先担当者 | I38: E | J38: E | AC38: - | AD38: -
A39: 10 | D39: ship_to_tel | E39: #MA.TEL | G39: Receiving point TEL | H39: 送付先ＴＥＬ | I39: E | J39: E | AC39: - | AD39: -
A40: 10 | D40: ship_to_fax | E40: #MA.TEL | G40: Receiving point FAX | H40: 送付先ＦＡＸ | I40: E | J40: E | AC40: - | AD40: -
...

Sheet ShipAct_InptChk02
A1: * | B1: * | D1: L | E1: 1
A2: * | D2: オペレーション実装仕様書 Operation Specification Implementation Sheet | E2: ModuleID : | F2: =IF(LogicCommon!C2="","",LogicCommon!C2) -> MS | G2: LogicID : | H2: =IF(LogicCommon!E2="","",LogicCommon!E2) -> MSBEL5540 | I2: Ope.ID : | J2: ShipAct_InptChk02 | K2: Pj.ID : | L2: =IF(LogicCommon!G2="","",LogicCommon!G2) -> MC | M2: Ope.Body : | N2: MA.MAUDL5010.Checker
A3: * | D3: =IF(LogicCommon!A3="","",LogicCommon!A3) | E3: SubModuleID : | F3: =IF(LogicCommon!C3="","",LogicCommon!C3) -> MSBE | G3: LogicClass : | H3: =IF(LogicCommon!E3="","",LogicCommon!E3) -> MSBEL_ShipActService | I3: Ope.Method : | J3: =J2 -> ShipAct_InptChk02 | K3: SuperClassPj.ID : | L3: =IF(LogicCommon!G3="","",LogicCommon!G3) | O3: Gene.Type : | P3: ALL
A4: * | E4: Version : | F4: 000000 | G4: LogicName : | H4: =IF(LogicCommon!E4="","",LogicCommon!E4) -> 出荷実績サービス | I4: Ope.Name : | J4: 削除前チェック | K4: SuperLogicID : | L4: =IF(LogicCommon!G4="","",LogicCommon!G4) -> MS.MSUDL5010 | M4: ImplOpe.ID:
A5: * | E5: ACType :
A6: * | D6: 概要 : | E6: 出荷実績の削除が可能かチェックをする。 | AD6: ID | AF6: ID | AH6: ID
A7: # | I7: U | K7: K | L7: K | M7: K | N7: K | O7: K | P7: K | Q7: K | R7: K | S7: K | T7: K | U7: K | V7: K | W7: K | X7: K | Y7: K | Z7: K | AA7: K | AB7: K | AC7: o | AD7: SA.v0 | AE7: o | AG7: o
A8: # | D8: ブロック名 Block Name | E8: 型 Type | G8: super/share | H8: 対象ブロック名 Target Block Name | K8: REQ_UPD_CNT_CHK | L8: REQUIRED | M8: CHK_NUM | N8: SMALL_LARGE | O8: CHK_DT | P8: BEFORE_AFTER | Q8: CHK_PTN | R8: DUPLICATE | S8: TOO_MANY_INPUTS | T8: ONLY_ONE_INPUT | U8: AT_LEAST_ONE | V8: LIST_LOGIC | W8: LIST_OUT | X8: LIST_OUT_BASE | Y8: LIST_IN | Z8: LIST_IN_BASE | AA8: CONST | AB8: NULL_VAL | AC8: TargetName | AD8: OPE.MS.MSBEL5540.ShipAct_Chk01 | AE8: TargetName | AG8: TargetName | AK8: ブロック備考 Block Remarks
A9: # | D9: 項目名 Field Name | E9: 型 Type | F9: 桁 Digits | G9: フルネーム Full Name | H9: 日本語名 Japanese Name | I9: 上り項目 Request Message Field | J9: 下り項目 Response Message Field | AI9: 条件および編集方法 Conditions and Editing Methods | AK9: 項目備考 Field Remarks
A10: # | AC10: 上り項目 Request Message Field | AD10: 下り項目 Response Message Field | AE10: 上り項目 Request Message Field | AF10: 下り項目 Response Message Field | AG10: 上り項目 Request Message Field | AH10: 下り項目 Response Message Field
A11: 10 | B11: * | D11: ShipAct_InptChk02_Hdr | E11: L | AC11: ShipAct_Hdr | AD11: ShipAct_Hdr
A12: 10 | D12: data_crud_typ | E12: #MA.DATA_CRUD_TYP | G12: Data update type | H12: データ更新区分 | I12: E | J12: E | L12: E | AC12: E | AD12: -
A13: 10 | D13: ship_act_no | E13: #MA.SHIP_ACT_NO | G13: Shipping result No. | H13: 出荷実績ＮＯ | I13: E | J13: E | L13: E | AC13: E | AD13: -
A14: 10 | D14: ship_act_rev | E14: #MA.SLIP_REV | G14: Shipping result rev. number | H14: 出荷実績改訂番号 | I14: - | J14: - | AC14: - | AD14: -
A15: 10 | D15: ship_inst_no | E15: #MA.SHIP_INST_NO | G15: Shipping order No. | H15: 出荷指図ＮＯ | I15: - | J15: - | AC15: - | AD15: -
A16: 10 | D16: ac_dt | E16: #MA.DT | G16: Recording date | H16: 計上日 | I16: - | J16: - | AC16: - | AD16: -
A17: 10 | D17: can_ac_dt | E17: #MA.DT | G17: Cancellation recording date | H17: 取消計上日 | I17: E | J17: E | L17: E | O17: bfToday | AC17: E | AD17: -
A18: 10 | D18: ship_tm | E18: #MA.TM | G18: Shipping date and time | H18: 出荷日時 | I18: - | J18: - | AC18: - | AD18: -
A19: 10 | D19: dlv_tm | E19: #MA.TM | G19: Delivery date and time | H19: 納品日時 | I19: - | J19: - | AC19: - | AD19: -
A20: 10 | D20: rqst_dpt_cd | E20: #MA.DPT_CD | G20: Requesting dept. cd. | H20: 依頼元部門ＣＤ | I20: - | J20: - | AC20: - | AD20: -
A21: 10 | D21: rqst_usr_cd | E21: #MA.USR_CD | G21: Requesting PIC cd. | H21: 依頼元担当者ＣＤ | I21: - | J21: - | AC21: - | AD21: -
A22: 10 | D22: ship_fr_lg_grp_cd | E22: #MA.LG_GRP_CD | G22: Shipping point distribution group cd. | H22: 出荷元物流グループＣＤ | I22: - | J22: - | AC22: - | AD22: -
A23: 10 | D23: wg_cd | E23: #MA.WG_CD | G23: WG cd. | H23: ＷＧ ＣＤ | I23: - | J23: - | AC23: - | AD23: -
A24: 10 | D24: ship_term_cd | E24: #MA.SHIP_TERM_CD | G24: Shipping conditions cd. | H24: 出荷条件ＣＤ | I24: - | J24: - | AC24: - | AD24: -
A25: 10 | D25: ship_dpt_cd | E25: #MA.DPT_CD | G25: Shipping dept. cd. | H25: 出荷部門ＣＤ | I25: - | J25: - | AC25: - | AD25: -
A26: 10 | D26: ship_usr_cd | E26: #MA.USR_CD | G26: Shipping PIC cd. | H26: 出荷担当者ＣＤ | I26: - | J26: - | AC26: - | AD26: -
A27: 10 | D27: ship_to_lg_grp_cd | E27: #MA.LG_GRP_CD | G27: Receiving point distribution group cd. | H27: 出荷先物流グループＣＤ | I27: - | J27: - | AC27: - | AD27: -
A28: 10 | D28: cst_cd | E28: #MA.BP_CD | G28: Customer cd. | H28: 得意先ＣＤ | I28: - | J28: - | AC28: - | AD28: -
A29: 10 | D29: ship_to_id_typ | E29: #MS.SHIP_TO_ID_TYP | G29: Receiving point identification type | H29: 送付先識別区分 | I29: - | J29: - | AC29: - | AD29: -
... A53: 10 | D53: err_flg | E53: #MA.FLG | G53: Error | H53: エラー | I53: - | J53: E | AC53: - | AD53: E
A55: 20 | B55: * | D55: ShipAct_InptChk02_Cntr | E55: L | G55: $share$ | H55: MS.MSBEL5540.ShipAct_InptChk01.ShipAct_InptChk01_Cntr
A56: 20 | D56: ship_alloc_sts_no | E56: #MA.SHIP_ALLOC_STS_NO | G56: Shipping allocation status No. | H56: 出荷引当状況ＮＯ | I56: E | J56: -
A57: 20 | D57: ship_pr_no | E57: #MA.SHIP_PR_NO | G57: Shipping progress No. | H57: 出荷進捗ＮＯ | I57: E | J57: -

Sheet ShipAct_RevUpd01
A1: * | B1: * | D1: L | E1: 1
A2: * | D2: オペレーション実装仕様書 Operation Specification Implementation Sheet | E2: ModuleID : | F2: MS | G2: LogicID : | H2: MSBEL5540 | I2: Ope.ID : | J2: ShipAct_RevUpd01 | K2: Pj.ID : | L2: MC | M2: Ope.Body : | N2: "mcframe.serverMAUD.MAUDL5010.MAUDL_Operation"
A3: * | E3: SubModuleID : | F3: MSBE | G3: LogicClass : | H3: MSBEL_ShipActService | I3: Ope.Method : | J3: ShipAct_RevUpd01 | K3: SuperClassPj.ID : | O3: Gene.Type : | P3: ALL
A4: * | E4: Version : | F4: 000000 | G4: LogicName : | H4: 出荷実績サービス | I4: Ope.Name : | J4: 出荷実績改訂履歴更新 | K4: SuperLogicID : | L4: MS.MSUDL5010 | M4: ImplOpe.ID: | N4: MA.MAUCL5020.RevData_Upd01
A5: * | E5: ACType :
A6: * | D6: 概要 : | E6: 出荷実績改訂履歴テーブルを更新する。改訂履歴データ更新用の共通処理（MAUCL5020）から呼び出される。 | M6: ID | O6: ID | Q6: ID
A7: # | I7: U | K7: K | L7: o | N7: o | P7: o
A8: # | D8: ブロック名 Block Name | E8: 型 Type | G8: super/share | H8: 対象ブロック名 Target Block Name | L8: TargetName | N8: TargetName | P8: TargetName | T8: ブロック備考 Block Remarks
A9: # | D9: 項目名 Field Name | E9: 型 Type | F9: 桁 Digits | G9: フルネーム Full Name | H9: 日本語名 Japanese Name | I9: 上り項目 Request Message Field | J9: 下り項目 Response Message Field | R9: 条件および編集方法 Conditions and Editing Methods | T9: 項目備考 Field Remarks
A10: # | L10: 上り項目 Request Message Field | M10: 下り項目 Response Message Field | N10: 上り項目 Request Message Field | O10: 下り項目 Response Message Field | P10: 上り項目 Request Message Field | Q10: 下り項目 Response Message Field
A11: 10 | B11: * | D11: ShipAct_RevUpd01_Dtl | E11: L | G11: $share$ | H11: MA.MAUCL5020.RevData_Upd01.RevData_Upd01_Dtl
A12: 10 | D12: rev_data_src_no | E12: #MA.SRC_NO | G12: Revision history data source No. | H12: 改訂履歴データ作成元ＮＯ | I12: E | J12: -
A13: 10 | D13: rev_no | E13: #MA.SLIP_REV | G13: Rev. number | H13: 改訂番号 | I13: E | J13: -

Sheet 来歴
A1: 変更来歴
A3: Rev. | H3: 修正番号 | O3: 変更内容 | AQ3: 変更箇所
A4: 1 | O4: 初版
A5: 1.1 | H5: MS7031#404 | O5: ShipAct_InptChk01_Dtlブロックに以下の項目を追加 not_lot_mix_flg、not_sublot_mix_flg | AQ5: ShipAct_InptChk01
A6: 〃 | H6: 〃 | O6: SihpAct_Dtlブロックに以下の項目を追加 not_lot_mix_flg、not_sublot_mix_flg | AQ6: ShipAct_Chk01
A7: 〃 | H7: 〃 | O7: SihpAct_Dtlブロックに以下の項目を追加 not_lot_mix_flg、not_sublot_mix_flg | AQ7: ShipAct_Upd01
A8: 1.2 | O8: 英語の名称を追記 | AQ8: 全般
A9: 1.3 | H9: MS7033#058 | O9: SihpAct_Dtlブロックに以下の項目を追加 org_peg_no | AQ9: ShipAct_Upd01
