Workbook

Sheet LogicCommon
A2: オペレーション実装仕様書 | B2: ModuleID : | C2: MS | D2: LogicID : | E2: MSBEL5090 | F2: Pj.ID : | G2: MC
B3: SubModuleID : | C3: MSBE | D3: LogicClass : | E3: MSBEL_ShipStkRplService | F3: SuperClassPj.ID :
D4: LogicName : | E4: 出荷品在庫補充サービス | F4: SuperLogicID : | G4: MS.MSUDL5010
A5: 概要 :
A6: 詳細 :

Sheet ShipStkRpl_Ins01
A1: * | B1: * | D1: L | E1: 1
A2: * | D2: オペレーション実装仕様書 Operation Specification Implementation Sheet | E2: ModuleID : | F2: =IF(LogicCommon!C2="","",LogicCommon!C2) -> MS | G2: LogicID : | H2: =IF(LogicCommon!E2="","",LogicCommon!E2) -> MSBEL5090 | I2: Ope.ID : | J2: ShipStkRpl_Ins01 | K2: Pj.ID : | L2: =IF(LogicCommon!G2="","",LogicCommon!G2) -> MC | M2: Ope.Body : | N2: "mcframe.serverMAUD.MAUDL5010.MAUDL_Operation"
A3: * | D3: =IF(LogicCommon!A3="","",LogicCommon!A3) | E3: SubModuleID : | F3: =IF(LogicCommon!C3="","",LogicCommon!C3) -> MSBE | G3: LogicClass : | H3: =IF(LogicCommon!E3="","",LogicCommon!E3) -> MSBEL_ShipStkRplService | I3: Ope.Method : | J3: ShipStkRpl_Ins01 | K3: SuperClassPj.ID : | L3: =IF(LogicCommon!G3="","",LogicCommon!G3) | O3: Gene.Type : | P3: ALL
A4: * | E4: Version : | F4: 000000 | G4: LogicName : | H4: =IF(LogicCommon!E4="","",LogicCommon!E4) -> 出荷品在庫補充サービス | I4: Ope.Name : | J4: 不足情報・移動予定作成 | K4: SuperLogicID : | L4: =IF(LogicCommon!G4="","",LogicCommon!G4) -> MS.MSUDL5010 | M4: ImplOpe.ID:
A5: * | E5: ACType :
A6: * | D6: 概要 : | M6: ID | O6: ID | Q6: ID
A7: # | I7: U | K7: K | L7: o | N7: o | P7: o
A8: # | D8: ブロック名 Block Name | E8: 型 Type | G8: super/share | H8: 対象ブロック名 Target Block Name | L8: TargetName | N8: TargetName | P8: TargetName | T8: ブロック備考 Block Remarks
A9: # | D9: 項目名 Field Name | E9: 型 Type | F9: 桁 Digits | G9: フルネーム Full Name | H9: 日本語名 Japanese Name | I9: 上り項目 Request Message Field | J9: 下り項目 Response Message Field | R9: 条件および編集方法 Conditions and Editing Methods | T9: 項目備考 Field Remarks
A10: # | L10: 上り項目 Request Message Field | M10: 下り項目 Response Message Field | N10: 上り項目 Request Message Field | O10: 下り項目 Response Message Field | P10: 上り項目 Request Message Field | Q10: 下り項目 Response Message Field
A11: 10 | B11: * | D11: ShipStkRpl_Cnd | E11: R
A12: 10 | D12: xfr_schd_del_flg | E12: #MA.FLG | G12: Delete movement schedule | H12: 移動予定削除 | I12: E
A13: 10 | D13: xfr_schd_crt_flg | E13: #MA.FLG | G13: Create movement schedule | H13: 移動予定作成 | I13: E
A14: 10 | D14: ship_stk_rpl_lst_del_flg | E14: #MA.FLG | G14: Delete shortage info. | H14: 不足情報削除
A15: 10 | D15: schd_flg | E15: #MA.FLG | G15: Schedule | H15: 予定 | I15: E
A16: 10 | D16: slo_flg | E16: #MA.FLG | G16: Sales order | H16: 受注 | I16: E
A17: 10 | D17: prms_flg | E17: #MA.FLG | G17: Order promising | H17: 納期回答 | I17: E
A18: 10 | D18: dlv_inst_flg | E18: #MA.FLG | G18: Delivery order | H18: 納入指示 | I18: E
A19: 10 | D19: ord_flg | E19: #MA.FLG | G19: Ordered | H19: 指図済 | I19: E
A20: 10 | D20: dt_fr | E20: #MA.DT | G20: Scheduled shipping date FROM | H20: 出荷予定日ＦＲＯＭ
A21: 10 | D21: dt_to | E21: #MA.DT | G21: Scheduled shipping date TO | H21: 出荷予定日ＴＯ
A22: 10 | D22: tm_fr | E22: #MA.TM | G22: Scheduled shipping date and time FROM | H22: 出荷予定日時ＦＲＯＭ | I22: E
A23: 10 | D23: tm_to | E23: #MA.TM | G23: Scheduled shipping date and time TO | H23: 出荷予定日時ＴＯ | I23: E
A24: 10 | D24: not_alloc_flg | E24: #MA.FLG | G24: Unallocated | H24: 未引当 | I24: E
A25: 10 | D25: alloc_flg | E25: #MA.FLG | G25: Allocation | H25: 引当 | I25: E
A26: 10 | D26: ship_term_cd | E26: #MA.SHIP_TERM_CD | G26: Shipping conditions cd. | H26: 出荷条件ＣＤ | I26: E
A27: 10 | D27: ship_wk_cd | E27: #MA.SHIP_WK_CD | G27: Shipping operation cd. | H27: 出荷作業ＣＤ | I27: E
A28: 10 | D28: screen_flg | E28: #MA.FLG | G28: Screen execution | H28: 画面実行
A29: 10 | D29: batch_log_no | E29: #MA.BATCH_LOG_NO | G29: Batch log No. | H29: バッチログＮＯ | I29: E
L30: 上り項目 Request Message Field | M30: 下り項目 Response Message Field | N30: 上り項目 Request Message Field | O30: 下り項目 Response Message Field | P30: 上り項目 Request Message Field | Q30: 下り項目 Response Message Field
A31: 20 | B31: * | D31: ShipStkRpl_Dtl | E31: L
A32: 20 | D32: loc_cd | E32: #MA.LOC_CD | G32: Location cd. | H32: 場所ＣＤ | I32: E
A33: 20 | D33: str_ln_cd | E33: #MA.STR_LN_CD | G33: Rack/Line cd. | H33: 棚・ラインＣＤ | I33: E
A34: 20 | D34: itm_cd | E34: #MA.ITM_CD | G34: Item cd. | H34: 品目ＣＤ
A35: 20 | D35: itm_sub1 | E35: #MA.ITM_SUB1 | G35: Branch No. 1 | H35: 枝番１
A36: 20 | D36: itm_sub2 | E36: #MA.ITM_SUB2 | G36: Branch No. 2 | H36: 枝番２
A37: 20 | D37: itm_sub3 | E37: #MA.ITM_SUB3 | G37: Branch No. 3 | H37: 枝番３
A38: 20 | D38: wg_cd | E38: #MA.WG_CD | G38: WG cd. | H38: ワーキンググループＣＤ
A39: 20 | D39: total_cnt | E39: #MA.INT | G39: Number of processes | H39: 処理件数
L40: 上り項目 Request Message Field | M40: 下り項目 Response Message Field | N40: 上り項目 Request Message Field | O40: 下り項目 Response Message Field | P40: 上り項目 Request Message Field | Q40: 下り項目 Response Message Field
...

Sheet ShipStkRpl_Ins02
A1: * | B1: * | D1: L | E1: 1
A2: * | D2: オペレーション実装仕様書 Operation Specification Implementation Sheet | E2: ModuleID : | F2: =IF(LogicCommon!C2="","",LogicCommon!C2) -> MS | G2: LogicID : | H2: =IF(LogicCommon!E2="","",LogicCommon!E2) -> MSBEL5090 | I2: Ope.ID : | J2: ShipStkRpl_Ins02 | K2: Pj.ID : | L2: =IF(LogicCommon!G2="","",LogicCommon!G2) -> MC | M2: Ope.Body : | N2: "mcframe.serverMAUD.MAUDL5010.MAUDL_Operation"
A3: * | D3: =IF(LogicCommon!A3="","",LogicCommon!A3) | E3: SubModuleID : | F3: =IF(LogicCommon!C3="","",LogicCommon!C3) -> MSBE | G3: LogicClass : | H3: =IF(LogicCommon!E3="","",LogicCommon!E3) -> MSBEL_ShipStkRplService | I3: Ope.Method : | J3: ShipStkRpl_Ins02 | K3: SuperClassPj.ID : | L3: =IF(LogicCommon!G3="","",LogicCommon!G3) | O3: Gene.Type : | P3: ALL
A4: * | E4: Version : | F4: 000000 | G4: LogicName : | H4: =IF(LogicCommon!E4="","",LogicCommon!E4) -> 出荷品在庫補充サービス | I4: Ope.Name : | J4: 不足情報・移動予定作成（スレッド単位） | K4: SuperLogicID : | L4: =IF(LogicCommon!G4="","",LogicCommon!G4) -> MS.MSUDL5010 | M4: ImplOpe.ID:
A5: * | E5: ACType :
A6: * | D6: 概要 : | M6: ID | O6: ID | Q6: ID
A7: # | I7: U | K7: K | L7: o | N7: o | P7: o
A8: # | D8: ブロック名 Block Name | E8: 型 Type | G8: super/share | H8: 対象ブロック名 Target Block Name | L8: TargetName | N8: TargetName | P8: TargetName | T8: ブロック備考 Block Remarks
A9: # | D9: 項目名 Field Name | E9: 型 Type | F9: 桁 Digits | G9: フルネーム Full Name | H9: 日本語名 Japanese Name | I9: 上り項目 Request Message Field | J9: 下り項目 Response Message Field | R9: 条件および編集方法 Conditions and Editing Methods | T9: 項目備考 Field Remarks
A10: # | L10: 上り項目 Request Message Field | M10: 下り項目 Response Message Field | N10: 上り項目 Request Message Field | O10: 下り項目 Response Message Field | P10: 上り項目 Request Message Field | Q10: 下り項目 Response Message Field
A11: 10 | B11: * | D11: ShipStkRpl_Cnd | E11: R | G11: $share$ | H11: MS.MSBEL5090.ShipStkRpl_Ins01.ShipStkRpl_Cnd
A12: 10 | D12: xfr_schd_del_flg | E12: #MA.FLG | G12: Delete movement schedule | H12: 移動予定削除 | I12: E
A13: 10 | D13: xfr_schd_crt_flg | E13: #MA.FLG | G13: Create movement schedule | H13: 移動予定作成 | I13: E
A14: 10 | D14: schd_flg | E14: #MA.FLG | G14: Schedule | H14: 予定 | I14: E
A15: 10 | D15: slo_flg | E15: #MA.FLG | G15: Sales order | H15: 受注 | I15: E
A16: 10 | D16: prms_flg | E16: #MA.FLG | G16: Order promising | H16: 納期回答 | I16: E
A17: 10 | D17: dlv_inst_flg | E17: #MA.FLG | G17: Delivery order | H17: 納入指示 | I17: E
A18: 10 | D18: ord_flg | E18: #MA.FLG | G18: Ordered | H18: 指図済 | I18: E
A19: 10 | D19: tm_fr | E19: #MA.DT | G19: Scheduled shipping date and time FROM | H19: 出荷予定日時ＦＲＯＭ | I19: E
A20: 10 | D20: tm_to | E20: #MA.DT | G20: Scheduled shipping date and time TO | H20: 出荷予定日時ＴＯ | I20: E
A21: 10 | D21: not_alloc_flg | E21: #MA.FLG | G21: Unallocated | H21: 未引当 | I21: E
A22: 10 | D22: alloc_flg | E22: #MA.FLG | G22: Allocation | H22: 引当 | I22: E
A23: 10 | D23: ship_term_cd | E23: #MA.SHIP_TERM_CD | G23: Shipping conditions cd. | H23: 出荷条件ＣＤ | I23: E
... A25: 10 | D25: batch_log_no | E25: #MA.BATCH_LOG_NO | G25: Batch log No. | H25: バッチログＮＯ | I25: E
L26: 上り項目 Request Message Field | M26: 下り項目 Response Message Field | N26: 上り項目 Request Message Field | O26: 下り項目 Response Message Field | P26: 上り項目 Request Message Field | Q26: 下り項目 Response Message Field
A27: 20 | B27: * | D27: ShipStkRpl_Dtl | E27: L | G27: $share$ | H27: MS.MSBEL5090.ShipStkRpl_Ins01.ShipStkRpl_Dtl
A28: 20 | D28: loc_cd | E28: #MA.LOC_CD | G28: Location cd. | H28: 場所ＣＤ | I28: E
A29: 20 | D29: str_ln_cd | E29: #MA.STR_LN_CD | G29: Rack/Line cd. | H29: 棚・ラインＣＤ | I29: E
A30: 20 | D30: itm_cd | E30: #MA.ITM_CD | G30: Item cd. | H30: 品目ＣＤ | I30: E
A31: 20 | D31: itm_sub1 | E31: #MA.ITM_SUB1 | G31: Branch No. 1 | H31: 枝番１ | I31: E
A32: 20 | D32: itm_sub2 | E32: #MA.ITM_SUB2 | G32: Branch No. 2 | H32: 枝番２ | I32: E
A33: 20 | D33: itm_sub3 | E33: #MA.ITM_SUB3 | G33: Branch No. 3 | H33: 枝番３ | I33: E
L34: 上り項目 Request Message Field | M34: 下り項目 Response Message Field | N34: 上り項目 Request Message Field | O34: 下り項目 Response Message Field | P34: 上り項目 Request Message Field | Q34: 下り項目 Response Message Field
A35: 30 | B35: * | D35: ShipStkRpl_Cnt | E35: R | G35: $share$ | H35: MS.MSBEL5090.ShipStkRpl_Ins01.ShipStkRpl_Cnt
A36: 30 | D36: xfr_del_cnt | E36: #MA.INT | G36: Deleted number of movement/transport schedule | H36: 移動移送予定削除件数 | J36: E
A37: 30 | D37: ship_io_schd_cnt | E37: #MA.INT | G37: Number of GR/GI schedule for shipping | H37: 出荷の受払予定件数 | J37: E
A38: 30 | D38: lst_crt_cnt | E38: #MA.INT | G38: Created number of shortage info. | H38: 不足情報の作成件数 | J38: E
A39: 30 | D39: lst_del_of_xfr_crt_cnt | E39: #MA.INT | G39: Number of missing info. deleted due to movement/transport schedule creation | H39: 移動移送予定作成に伴い削除した不足情報の件数 | J39: E
A40: 30 | D40: xfr_crt_success_cnt | E40: #MA.INT | G40: Created number of movement/transport schedule | H40: 移動移送予定作成件数 | J40: E
A41: 30 | D41: xfr_crt_error_cnt | E41: #MA.INT | G41: Error count during movement/transport schedule creating | H41: 移動移送予定作成エラー件数 | J41: E
...

Sheet ShipStkRpl_Ins03
A1: * | B1: * | D1: L | E1: 1
A2: * | D2: オペレーション実装仕様書 Operation Specification Implementation Sheet | E2: ModuleID : | F2: =IF(LogicCommon!C2="","",LogicCommon!C2) -> MS | G2: LogicID : | H2: =IF(LogicCommon!E2="","",LogicCommon!E2) -> MSBEL5090 | I2: Ope.ID : | J2: ShipStkRpl_Ins03 | K2: Pj.ID : | L2: =IF(LogicCommon!G2="","",LogicCommon!G2) -> MC | M2: Ope.Body : | N2: "mcframe.serverMAUD.MAUDL5010.MAUDL_Operation"
A3: * | D3: =IF(LogicCommon!A3="","",LogicCommon!A3) | E3: SubModuleID : | F3: =IF(LogicCommon!C3="","",LogicCommon!C3) -> MSBE | G3: LogicClass : | H3: =IF(LogicCommon!E3="","",LogicCommon!E3) -> MSBEL_ShipStkRplService | I3: Ope.Method : | J3: ShipStkRpl_Ins03 | K3: SuperClassPj.ID : | L3: =IF(LogicCommon!G3="","",LogicCommon!G3) | O3: Gene.Type : | P3: ALL
A4: * | E4: Version : | F4: 000000 | G4: LogicName : | H4: =IF(LogicCommon!E4="","",LogicCommon!E4) -> 出荷品在庫補充サービス | I4: Ope.Name : | J4: 移動予定作成 | K4: SuperLogicID : | L4: =IF(LogicCommon!G4="","",LogicCommon!G4) -> MS.MSUDL5010 | M4: ImplOpe.ID:
A5: * | E5: ACType :
A6: * | D6: 概要 : | M6: ID | O6: ID | Q6: ID
A7: # | I7: U | K7: K | L7: o | N7: o | P7: o
A8: # | D8: ブロック名 Block Name | E8: 型 Type | G8: super/share | H8: 対象ブロック名 Target Block Name | L8: TargetName | N8: TargetName | P8: TargetName | T8: ブロック備考 Block Remarks
A9: # | D9: 項目名 Field Name | E9: 型 Type | F9: 桁 Digits | G9: フルネーム Full Name | H9: 日本語名 Japanese Name | I9: 上り項目 Request Message Field | J9: 下り項目 Response Message Field | R9: 条件および編集方法 Conditions and Editing Methods | T9: 項目備考 Field Remarks
A10: # | L10: 上り項目 Request Message Field | M10: 下り項目 Response Message Field | N10: 上り項目 Request Message Field | O10: 下り項目 Response Message Field | P10: 上り項目 Request Message Field | Q10: 下り項目 Response Message Field
A11: 10 | B11: * | D11: ShipStkRpl_Cnd | E11: R | G11: $share$ | H11: MS.MSBEL5090.ShipStkRpl_Ins01.ShipStkRpl_Cnd
A12: 10 | D12: screen_flg | E12: #MA.FLG | G12: Screen execution | H12: 画面実行 | I12: E
L13: 上り項目 Request Message Field | M13: 下り項目 Response Message Field | N13: 上り項目 Request Message Field | O13: 下り項目 Response Message Field | P13: 上り項目 Request Message Field | Q13: 下り項目 Response Message Field
A14: 20 | B14: * | D14: ShipStkRpl_Lst | E14: L
A15: 20 | D15: rl | E15: R | F15: DBC:MS.MST_SHIP_STK_RPL_LST
A16: 20 | D16: rl.batch_data_no# | E16: RI | G16: Data No. | H16: データＮＯ | I16: E | J16: E
A17: 20 | D17: rl.loc_cd# | E17: RI | G17: Location cd. | H17: 場所ＣＤ
A18: 20 | D18: rl.str_ln_cd# | E18: RI | G18: Rack/Line cd. | H18: 棚・ラインＣＤ
A19: 20 | D19: rl.wg_cd# | E19: RI | G19: WG cd. | H19: ワーキンググループＣＤ
A20: 20 | D20: rl.itm_cd# | E20: RI | G20: Item cd. | H20: 品目ＣＤ
A21: 20 | D21: rl.itm_sub1# | E21: RI | G21: Branch No. 1 | H21: 枝番１
A22: 20 | D22: rl.itm_sub2# | E22: RI | G22: Branch No. 2 | H22: 枝番２
A23: 20 | D23: rl.itm_sub3# | E23: RI | G23: Branch No. 3 | H23: 枝番３
A24: 20 | D24: rl.schd_dt# | E24: RI | G24: Scheduled date | H24: 予定日付
A25: 20 | D25: rl.upd_cntr# | E25: RI | G25: Update counter | H25: 更新カウンタ | I25: E
A26: 20 | D26: rtn_sts_typ | E26: #MA.RTN_STS_TYP | G26: Process result status type | H26: 処理結果状況区分 | J26: E
D27: 詳細 :

Sheet ShipStkRpl_Del01
A1: * | B1: * | D1: L | E1: 1
A2: * | D2: オペレーション実装仕様書 Operation Specification Implementation Sheet | E2: ModuleID : | F2: =IF(LogicCommon!C2="","",LogicCommon!C2) -> MS | G2: LogicID : | H2: =IF(LogicCommon!E2="","",LogicCommon!E2) -> MSBEL5090 | I2: Ope.ID : | J2: ShipStkRpl_Del01 | K2: Pj.ID : | L2: =IF(LogicCommon!G2="","",LogicCommon!G2) -> MC | M2: Ope.Body : | N2: "mcframe.serverMAUD.MAUDL5010.MAUDL_Operation"
A3: * | D3: =IF(LogicCommon!A3="","",LogicCommon!A3) | E3: SubModuleID : | F3: =IF(LogicCommon!C3="","",LogicCommon!C3) -> MSBE | G3: LogicClass : | H3: =IF(LogicCommon!E3="","",LogicCommon!E3) -> MSBEL_ShipStkRplService | I3: Ope.Method : | J3: ShipStkRpl_Del01 | K3: SuperClassPj.ID : | L3: =IF(LogicCommon!G3="","",LogicCommon!G3) | O3: Gene.Type : | P3: ALL
A4: * | E4: Version : | F4: 000000 | G4: LogicName : | H4: =IF(LogicCommon!E4="","",LogicCommon!E4) -> 出荷品在庫補充サービス | I4: Ope.Name : | J4: 不足情報・移動予定削除 | K4: SuperLogicID : | L4: =IF(LogicCommon!G4="","",LogicCommon!G4) -> MS.MSUDL5010 | M4: ImplOpe.ID:
A5: * | E5: ACType :
A6: * | D6: 概要 : | M6: ID | O6: ID | Q6: ID
A7: # | I7: U | K7: K | L7: o | N7: o | P7: o
A8: # | D8: ブロック名 Block Name | E8: 型 Type | G8: super/share | H8: 対象ブロック名 Target Block Name | L8: TargetName | N8: TargetName | P8: TargetName | T8: ブロック備考 Block Remarks
A9: # | D9: 項目名 Field Name | E9: 型 Type | F9: 桁 Digits | G9: フルネーム Full Name | H9: 日本語名 Japanese Name | I9: 上り項目 Request Message Field | J9: 下り項目 Response Message Field | R9: 条件および編集方法 Conditions and Editing Methods | T9: 項目備考 Field Remarks
A10: # | L10: 上り項目 Request Message Field | M10: 下り項目 Response Message Field | N10: 上り項目 Request Message Field | O10: 下り項目 Response Message Field | P10: 上り項目 Request Message Field | Q10: 下り項目 Response Message Field
A11: 10 | B11: * | D11: ShipStkRpl_Cnd | E11: R | G11: $share$ | H11: MS.MSBEL5090.ShipStkRpl_Ins01.ShipStkRpl_Cnd
A12: 10 | D12: ship_stk_rpl_lst_del_flg | E12: #MA.FLG | G12: Delete shortage info. | H12: 不足情報削除 | I12: E
A13: 10 | D13: xfr_schd_del_flg | E13: #MA.FLG | G13: Delete movement schedule | H13: 移動予定削除 | I13: E
A14: 10 | D14: tm_fr | E14: #MA.DT | G14: Scheduled GR date and time FROM | H14: 入庫予定日時ＦＲＯＭ | I14: E
A15: 10 | D15: tm_to | E15: #MA.DT | G15: Scheduled GR date and time TO | H15: 入庫予定日時ＴＯ | I15: E
L16: 上り項目 Request Message Field | M16: 下り項目 Response Message Field | N16: 上り項目 Request Message Field | O16: 下り項目 Response Message Field | P16: 上り項目 Request Message Field | Q16: 下り項目 Response Message Field
A17: 20 | B17: * | D17: ShipStkRpl_Dtl | E17: L | G17: $share$ | H17: MS.MSBEL5090.ShipStkRpl_Ins01.ShipStkRpl_Dtl
A18: 20 | D18: loc_cd | E18: #MA.LOC_CD | G18: Location cd. | H18: 場所ＣＤ | I18: E
A19: 20 | D19: str_ln_cd | E19: #MA.STR_LN_CD | G19: Rack/Line cd. | H19: 棚・ラインＣＤ | I19: E
L20: 上り項目 Request Message Field | M20: 下り項目 Response Message Field | N20: 上り項目 Request Message Field | O20: 下り項目 Response Message Field | P20: 上り項目 Request Message Field | Q20: 下り項目 Response Message Field
A21: 30 | B21: * | D21: ShipStkRpl_Cnt | E21: R | G21: $share$ | H21: MS.MSBEL5090.ShipStkRpl_Ins01.ShipStkRpl_Cnt
A22: 30 | D22: lst_del_cnt | E22: #MA.INT | G22: Deleted number of shortage info. | H22: 不足情報の削除件数 | J22: E
A23: 30 | D23: xfr_del_cnt | E23: #MA.INT | G23: Deleted number of movement/transport schedule | H23: 移動移送予定削除件数 | J23: E
D24: 詳細 :

Sheet ShipStkRpl_LstIns01
A1: * | B1: * | D1: L | E1: 1
A2: * | D2: オペレーション実装仕様書 Operation Specification Implementation Sheet | E2: ModuleID : | F2: =IF(LogicCommon!C2="","",LogicCommon!C2) -> MS | G2: LogicID : | H2: =IF(LogicCommon!E2="","",LogicCommon!E2) -> MSBEL5090 | I2: Ope.ID : | J2: ShipStkRpl_LstIns01 | K2: Pj.ID : | L2: =IF(LogicCommon!G2="","",LogicCommon!G2) -> MC | M2: Ope.Body : | N2: "mcframe.serverMAUD.MAUDL5010.MAUDL_Operation"
A3: * | D3: =IF(LogicCommon!A3="","",LogicCommon!A3) | E3: SubModuleID : | F3: =IF(LogicCommon!C3="","",LogicCommon!C3) -> MSBE | G3: LogicClass : | H3: =IF(LogicCommon!E3="","",LogicCommon!E3) -> MSBEL_ShipStkRplService | I3: Ope.Method : | J3: ShipStkRpl_LstIns01 | K3: SuperClassPj.ID : | L3: =IF(LogicCommon!G3="","",LogicCommon!G3) | O3: Gene.Type : | P3: ALL
A4: * | E4: Version : | F4: 000000 | G4: LogicName : | H4: =IF(LogicCommon!E4="","",LogicCommon!E4) -> 出荷品在庫補充サービス | I4: Ope.Name : | J4: 不足情報作成 | K4: SuperLogicID : | L4: =IF(LogicCommon!G4="","",LogicCommon!G4) -> MS.MSUDL5010 | M4: ImplOpe.ID:
A5: * | E5: ACType :
A6: * | D6: 概要 : | M6: ID | O6: ID | Q6: ID
A7: # | I7: U | K7: K | L7: o | N7: o | P7: o
A8: # | D8: ブロック名 Block Name | E8: 型 Type | G8: super/share | H8: 対象ブロック名 Target Block Name | L8: TargetName | N8: TargetName | P8: TargetName | T8: ブロック備考 Block Remarks
A9: # | D9: 項目名 Field Name | E9: 型 Type | F9: 桁 Digits | G9: フルネーム Full Name | H9: 日本語名 Japanese Name | I9: 上り項目 Request Message Field | J9: 下り項目 Response Message Field | R9: 条件および編集方法 Conditions and Editing Methods | T9: 項目備考 Field Remarks
A10: # | L10: 上り項目 Request Message Field | M10: 下り項目 Response Message Field | N10: 上り項目 Request Message Field | O10: 下り項目 Response Message Field | P10: 上り項目 Request Message Field | Q10: 下り項目 Response Message Field
A11: 10 | B11: * | D11: ShipStkRpl_Cnd | E11: R | G11: $share$ | H11: MS.MSBEL5090.ShipStkRpl_Ins01.ShipStkRpl_Cnd
A12: 10 | D12: schd_flg | E12: #MA.FLG | G12: Schedule | H12: 予定 | I12: E
A13: 10 | D13: slo_flg | E13: #MA.FLG | G13: Sales order | H13: 受注 | I13: E
A14: 10 | D14: prms_flg | E14: #MA.FLG | G14: Order promising | H14: 納期回答 | I14: E
A15: 10 | D15: dlv_inst_flg | E15: #MA.FLG | G15: Delivery order | H15: 納入指示 | I15: E
A16: 10 | D16: ord_flg | E16: #MA.FLG | G16: Ordered | H16: 指図済 | I16: E
A17: 10 | D17: tm_fr | E17: #MA.DT | G17: Scheduled shipping date and time FROM | H17: 出荷予定日時ＦＲＯＭ | I17: E
A18: 10 | D18: tm_to | E18: #MA.DT | G18: Scheduled shipping date and time TO | H18: 出荷予定日時ＴＯ | I18: E
A19: 10 | D19: not_alloc_flg | E19: #MA.FLG | G19: Unallocated | H19: 未引当 | I19: E
A20: 10 | D20: alloc_flg | E20: #MA.FLG | G20: Allocation | H20: 引当 | I20: E
A21: 10 | D21: ship_term_cd | E21: #MA.SHIP_TERM_CD | G21: Shipping conditions cd. | H21: 出荷条件ＣＤ | I21: E
A22: 10 | D22: ship_wk_cd | E22: #MA.SHIP_WK_CD | G22: Shipping operation cd. | H22: 出荷作業ＣＤ | I22: E
A23: 10 | D23: batch_log_no | E23: #MA.BATCH_LOG_NO | G23: Batch log No. | H23: バッチログＮＯ | I23: E
L24: 上り項目 Request Message Field | M24: 下り項目 Response Message Field | N24: 上り項目 Request Message Field | O24: 下り項目 Response Message Field | P24: 上り項目 Request Message Field | Q24: 下り項目 Response Message Field
A25: 20 | B25: * | D25: ShipStkRpl_Dtl | E25: L | G25: $share$ | H25: MS.MSBEL5090.ShipStkRpl_Ins01.ShipStkRpl_Dtl
A26: 20 | D26: loc_cd | E26: #MA.LOC_CD | G26: Location cd. | H26: 場所ＣＤ | I26: E
A27: 20 | D27: str_ln_cd | E27: #MA.STR_LN_CD | G27: Rack/Line cd. | H27: 棚・ラインＣＤ | I27: E
A28: 20 | D28: itm_cd | E28: #MA.ITM_CD | G28: Item cd. | H28: 品目ＣＤ | I28: E
A29: 20 | D29: itm_sub1 | E29: #MA.ITM_SUB1 | G29: Branch No. 1 | H29: 枝番１ | I29: E
A30: 20 | D30: itm_sub2 | E30: #MA.ITM_SUB2 | G30: Branch No. 2 | H30: 枝番２ | I30: E
A31: 20 | D31: itm_sub3 | E31: #MA.ITM_SUB3 | G31: Branch No. 3 | H31: 枝番３ | I31: E
L32: 上り項目 Request Message Field | M32: 下り項目 Response Message Field | N32: 上り項目 Request Message Field | O32: 下り項目 Response Message Field | P32: 上り項目 Request Message Field | Q32: 下り項目 Response Message Field
A33: 30 | B33: * | D33: ShipStkRpl_Lst | E33: L | G33: $share$ | H33: MS.MSBEL5090.ShipStkRpl_Ins03.ShipStkRpl_Lst
A34: 30 | D34: rl | E34: R | F34: DBC:MS.MST_SHIP_STK_RPL_LST
A35: 30 | D35: rl.batch_data_no# | E35: RI | G35: Data No. | H35: データＮＯ | J35: E
A36: 30 | D36: rl.loc_cd# | E36: RI | G36: Location cd. | H36: 場所ＣＤ | J36: E
A37: 30 | D37: rl.str_ln_cd# | E37: RI | G37: Rack/Line cd. | H37: 棚・ラインＣＤ | J37: E
A38: 30 | D38: rl.wg_cd# | E38: RI | G38: WG cd. | H38: ワーキンググループＣＤ | J38: E
A39: 30 | D39: rl.itm_cd# | E39: RI | G39: Item cd. | H39: 品目ＣＤ | J39: E
A40: 30 | D40: rl.itm_sub1# | E40: RI | G40: Branch No. 1 | H40: 枝番１ | J40: E
...

Sheet ShipStkRpl_XfrIns01
A1: * | B1: * | D1: L | E1: 1
A2: * | D2: オペレーション実装仕様書 Operation Specification Implementation Sheet | E2: ModuleID : | F2: =IF(LogicCommon!C2="","",LogicCommon!C2) -> MS | G2: LogicID : | H2: =IF(LogicCommon!E2="","",LogicCommon!E2) -> MSBEL5090 | I2: Ope.ID : | J2: ShipStkRpl_XfrIns01 | K2: Pj.ID : | L2: =IF(LogicCommon!G2="","",LogicCommon!G2) -> MC | M2: Ope.Body : | N2: "mcframe.serverMAUD.MAUDL5010.MAUDL_Operation"
A3: * | D3: =IF(LogicCommon!A3="","",LogicCommon!A3) | E3: SubModuleID : | F3: =IF(LogicCommon!C3="","",LogicCommon!C3) -> MSBE | G3: LogicClass : | H3: =IF(LogicCommon!E3="","",LogicCommon!E3) -> MSBEL_ShipStkRplService | I3: Ope.Method : | J3: ShipStkRpl_XfrIns01 | K3: SuperClassPj.ID : | L3: =IF(LogicCommon!G3="","",LogicCommon!G3) | O3: Gene.Type : | P3: ALL
A4: * | E4: Version : | F4: 000000 | G4: LogicName : | H4: =IF(LogicCommon!E4="","",LogicCommon!E4) -> 出荷品在庫補充サービス | I4: Ope.Name : | J4: 移動予定作成 | K4: SuperLogicID : | L4: =IF(LogicCommon!G4="","",LogicCommon!G4) -> MS.MSUDL5010 | M4: ImplOpe.ID:
A5: * | E5: ACType :
A6: * | D6: 概要 : | M6: ID | O6: ID | Q6: ID
A7: # | I7: U | K7: K | L7: o | N7: o | P7: o
A8: # | D8: ブロック名 Block Name | E8: 型 Type | G8: super/share | H8: 対象ブロック名 Target Block Name | L8: TargetName | N8: TargetName | P8: TargetName | T8: ブロック備考 Block Remarks
A9: # | D9: 項目名 Field Name | E9: 型 Type | F9: 桁 Digits | G9: フルネーム Full Name | H9: 日本語名 Japanese Name | I9: 上り項目 Request Message Field | J9: 下り項目 Response Message Field | R9: 条件および編集方法 Conditions and Editing Methods | T9: 項目備考 Field Remarks
A10: # | L10: 上り項目 Request Message Field | M10: 下り項目 Response Message Field | N10: 上り項目 Request Message Field | O10: 下り項目 Response Message Field | P10: 上り項目 Request Message Field | Q10: 下り項目 Response Message Field
A11: 10 | B11: * | D11: ShipStkRpl_Cnd | E11: R | G11: $share$ | H11: MS.MSBEL5090.ShipStkRpl_Ins01.ShipStkRpl_Cnd
A12: 10 | D12: schd_flg | E12: #MA.FLG | G12: Schedule | H12: 予定 | I12: E
A13: 10 | D13: slo_flg | E13: #MA.FLG | G13: Sales order | H13: 受注 | I13: E
A14: 10 | D14: prms_flg | E14: #MA.FLG | G14: Order promising | H14: 納期回答 | I14: E
A15: 10 | D15: dlv_inst_flg | E15: #MA.FLG | G15: Delivery order | H15: 納入指示 | I15: E
A16: 10 | D16: ord_flg | E16: #MA.FLG | G16: Ordered | H16: 指図済 | I16: E
A17: 10 | D17: tm_fr | E17: #MA.DT | G17: Scheduled shipping date and time FROM | H17: 出荷予定日時ＦＲＯＭ | I17: E
A18: 10 | D18: tm_to | E18: #MA.DT | G18: Scheduled shipping date and time TO | H18: 出荷予定日時ＴＯ | I18: E
A19: 10 | D19: screen_flg | E19: #MA.FLG | G19: Screen execution | H19: 画面実行 | I19: E
L20: 上り項目 Request Message Field | M20: 下り項目 Response Message Field | N20: 上り項目 Request Message Field | O20: 下り項目 Response Message Field | P20: 上り項目 Request Message Field | Q20: 下り項目 Response Message Field
A21: 20 | B21: * | D21: ShipStkRpl_Lst | E21: L | G21: $share$ | H21: MS.MSBEL5090.ShipStkRpl_Ins03.ShipStkRpl_Lst
A22: 20 | D22: rl | E22: R | F22: DBC:MS.MST_SHIP_STK_RPL_LST
A23: 20 | D23: rl.batch_data_no# | E23: RI | G23: Data No. | H23: データＮＯ | I23: E | J23: E
A24: 20 | D24: rl.loc_cd# | E24: RI | G24: Location cd. | H24: 場所ＣＤ | I24: E
A25: 20 | D25: rl.str_ln_cd# | E25: RI | G25: Rack/Line cd. | H25: 棚・ラインＣＤ | I25: E
A26: 20 | D26: rl.wg_cd# | E26: RI | G26: WG cd. | H26: ワーキンググループＣＤ | I26: E
A27: 20 | D27: rl.itm_cd# | E27: RI | G27: Item cd. | H27: 品目ＣＤ | I27: E
A28: 20 | D28: rl.itm_sub1# | E28: RI | G28: Branch No. 1 | H28: 枝番１ | I28: E
A29: 20 | D29: rl.itm_sub2# | E29: RI | G29: Branch No. 2 | H29: 枝番２ | I29: E
A30: 20 | D30: rl.itm_sub3# | E30: RI | G30: Branch No. 3 | H30: 枝番３ | I30: E
A31: 20 | D31: rl.schd_dt# | E31: RI | G31: Scheduled date | H31: 予定日付 | I31: E
A32: 20 | D32: rl.upd_cntr# | E32: RI | G32: Update counter | H32: 更新カウンタ | I32: E
A33: 20 | D33: rtn_sts_typ | E33: #MA.RTN_STS_TYP | G33: Process result status type | H33: 処理結果状況区分 | J33: E
L34: 上り項目 Request Message Field | M34: 下り項目 Response Message Field | N34: 上り項目 Request Message Field | O34: 下り項目 Response Message Field | P34: 上り項目 Request Message Field | Q34: 下り項目 Response Message Field
A35: 30 | B35: * | D35: ShipStkRpl_Cnt | E35: R | G35: $share$ | H35: MS.MSBEL5090.ShipStkRpl_Ins01.ShipStkRpl_Cnt
A36: 30 | D36: lst_del_of_xfr_crt_cnt | E36: #MA.INT | G36: Number of missing info. deleted due to movement/transport schedule creation | H36: 移動移送予定作成に伴い削除した不足情報の件数 | J36: E
A37: 30 | D37: xfr_crt_success_cnt | E37: #MA.INT | G37: Created number of movement/transport schedule | H37: 移動移送予定作成件数 | J37: E
A38: 30 | D38: xfr_crt_error_cnt | E38: #MA.INT | G38: Error count during movement/transport schedule creating | H38: 移動移送予定作成エラー件数 | J38: E
D39: 詳細 :

Sheet ShipStkRpl_LstDel01
A1: * | B1: * | D1: L | E1: 1
A2: * | D2: オペレーション実装仕様書 Operation Specification Implementation Sheet | E2: ModuleID : | F2: =IF(LogicCommon!C2="","",LogicCommon!C2) -> MS | G2: LogicID : | H2: =IF(LogicCommon!E2="","",LogicCommon!E2) -> MSBEL5090 | I2: Ope.ID : | J2: ShipStkRpl_LstDel01 | K2: Pj.ID : | L2: =IF(LogicCommon!G2="","",LogicCommon!G2) -> MC | M2: Ope.Body : | N2: "mcframe.serverMAUD.MAUDL5010.MAUDL_Operation"
A3: * | D3: =IF(LogicCommon!A3="","",LogicCommon!A3) | E3: SubModuleID : | F3: =IF(LogicCommon!C3="","",LogicCommon!C3) -> MSBE | G3: LogicClass : | H3: =IF(LogicCommon!E3="","",LogicCommon!E3) -> MSBEL_ShipStkRplService | I3: Ope.Method : | J3: ShipStkRpl_LstDel01 | K3: SuperClassPj.ID : | L3: =IF(LogicCommon!G3="","",LogicCommon!G3) | O3: Gene.Type : | P3: ALL
A4: * | E4: Version : | F4: 000000 | G4: LogicName : | H4: =IF(LogicCommon!E4="","",LogicCommon!E4) -> 出荷品在庫補充サービス | I4: Ope.Name : | J4: 不足情報削除 | K4: SuperLogicID : | L4: =IF(LogicCommon!G4="","",LogicCommon!G4) -> MS.MSUDL5010 | M4: ImplOpe.ID:
A5: * | E5: ACType :
A6: * | D6: 概要 : | M6: ID | O6: ID | Q6: ID
A7: # | I7: U | K7: K | L7: o | N7: o | P7: o
A8: # | D8: ブロック名 Block Name | E8: 型 Type | G8: super/share | H8: 対象ブロック名 Target Block Name | L8: TargetName | N8: TargetName | P8: TargetName | T8: ブロック備考 Block Remarks
A9: # | D9: 項目名 Field Name | E9: 型 Type | F9: 桁 Digits | G9: フルネーム Full Name | H9: 日本語名 Japanese Name | I9: 上り項目 Request Message Field | J9: 下り項目 Response Message Field | R9: 条件および編集方法 Conditions and Editing Methods | T9: 項目備考 Field Remarks
A10: # | L10: 上り項目 Request Message Field | M10: 下り項目 Response Message Field | N10: 上り項目 Request Message Field | O10: 下り項目 Response Message Field | P10: 上り項目 Request Message Field | Q10: 下り項目 Response Message Field
A11: 10 | B11: * | D11: ShipStkRpl_Dtl | E11: L | G11: $share$ | H11: MS.MSBEL5090.ShipStkRpl_Ins01.ShipStkRpl_Dtl
A12: 10 | D12: loc_cd | E12: #MA.LOC_CD | G12: Location cd. | H12: 場所ＣＤ | I12: E
A13: 10 | D13: str_ln_cd | E13: #MA.STR_LN_CD | G13: Rack/Line cd. | H13: 棚・ラインＣＤ | I13: E
L14: 上り項目 Request Message Field | M14: 下り項目 Response Message Field | N14: 上り項目 Request Message Field | O14: 下り項目 Response Message Field | P14: 上り項目 Request Message Field | Q14: 下り項目 Response Message Field
A15: 20 | B15: * | D15: ShipStkRpl_Cnt | E15: R | G15: $share$ | H15: MS.MSBEL5090.ShipStkRpl_Ins01.ShipStkRpl_Cnt
A16: 20 | D16: lst_del_cnt | E16: #MA.INT | G16: Deleted number of shortage info. | H16: 不足情報の削除件数 | J16: E
D17: 詳細 :

Sheet ShipStkRpl_XfrDel01
A1: * | B1: * | D1: L | E1: 1
A2: * | D2: オペレーション実装仕様書 Operation Specification Implementation Sheet | E2: ModuleID : | F2: =IF(LogicCommon!C2="","",LogicCommon!C2) -> MS | G2: LogicID : | H2: =IF(LogicCommon!E2="","",LogicCommon!E2) -> MSBEL5090 | I2: Ope.ID : | J2: ShipStkRpl_XfrDel01 | K2: Pj.ID : | L2: =IF(LogicCommon!G2="","",LogicCommon!G2) -> MC | M2: Ope.Body : | N2: "mcframe.serverMAUD.MAUDL5010.MAUDL_Operation"
A3: * | D3: =IF(LogicCommon!A3="","",LogicCommon!A3) | E3: SubModuleID : | F3: =IF(LogicCommon!C3="","",LogicCommon!C3) -> MSBE | G3: LogicClass : | H3: =IF(LogicCommon!E3="","",LogicCommon!E3) -> MSBEL_ShipStkRplService | I3: Ope.Method : | J3: ShipStkRpl_XfrDel01 | K3: SuperClassPj.ID : | L3: =IF(LogicCommon!G3="","",LogicCommon!G3) | O3: Gene.Type : | P3: ALL
A4: * | E4: Version : | F4: 000000 | G4: LogicName : | H4: =IF(LogicCommon!E4="","",LogicCommon!E4) -> 出荷品在庫補充サービス | I4: Ope.Name : | J4: 移動予定削除 | K4: SuperLogicID : | L4: =IF(LogicCommon!G4="","",LogicCommon!G4) -> MS.MSUDL5010 | M4: ImplOpe.ID:
A5: * | E5: ACType :
A6: * | D6: 概要 : | M6: ID | O6: ID | Q6: ID
A7: # | I7: U | K7: K | L7: o | N7: o | P7: o
A8: # | D8: ブロック名 Block Name | E8: 型 Type | G8: super/share | H8: 対象ブロック名 Target Block Name | L8: TargetName | N8: TargetName | P8: TargetName | T8: ブロック備考 Block Remarks
A9: # | D9: 項目名 Field Name | E9: 型 Type | F9: 桁 Digits | G9: フルネーム Full Name | H9: 日本語名 Japanese Name | I9: 上り項目 Request Message Field | J9: 下り項目 Response Message Field | R9: 条件および編集方法 Conditions and Editing Methods | T9: 項目備考 Field Remarks
A10: # | L10: 上り項目 Request Message Field | M10: 下り項目 Response Message Field | N10: 上り項目 Request Message Field | O10: 下り項目 Response Message Field | P10: 上り項目 Request Message Field | Q10: 下り項目 Response Message Field
A11: 10 | B11: * | D11: ShipStkRpl_Cnd | E11: R | G11: $share$ | H11: MS.MSBEL5090.ShipStkRpl_Ins01.ShipStkRpl_Cnd
A12: 10 | D12: tm_fr | E12: #MA.DT | G12: Scheduled GR date and time FROM | H12: 入庫予定日時ＦＲＯＭ | I12: E
A13: 10 | D13: tm_to | E13: #MA.DT | G13: Scheduled GR date and time TO | H13: 入庫予定日時ＴＯ | I13: E
L14: 上り項目 Request Message Field | M14: 下り項目 Response Message Field | N14: 上り項目 Request Message Field | O14: 下り項目 Response Message Field | P14: 上り項目 Request Message Field | Q14: 下り項目 Response Message Field
A15: 20 | B15: * | D15: ShipStkRpl_Dtl | E15: L | G15: $share$ | H15: MS.MSBEL5090.ShipStkRpl_Ins01.ShipStkRpl_Dtl
A16: 20 | D16: loc_cd | E16: #MA.LOC_CD | G16: Location cd. | H16: 場所ＣＤ | I16: E
A17: 20 | D17: str_ln_cd | E17: #MA.STR_LN_CD | G17: Rack/Line cd. | H17: 棚・ラインＣＤ | I17: E
A18: 20 | D18: itm_cd | E18: #MA.ITM_CD | G18: Item cd. | H18: 品目ＣＤ | I18: E
A19: 20 | D19: itm_sub1 | E19: #MA.ITM_SUB1 | G19: Branch No. 1 | H19: 枝番１ | I19: E
A20: 20 | D20: itm_sub2 | E20: #MA.ITM_SUB2 | G20: Branch No. 2 | H20: 枝番２ | I20: E
A21: 20 | D21: itm_sub3 | E21: #MA.ITM_SUB3 | G21: Branch No. 3 | H21: 枝番３ | I21: E
L22: 上り項目 Request Message Field | M22: 下り項目 Response Message Field | N22: 上り項目 Request Message Field | O22: 下り項目 Response Message Field | P22: 上り項目 Request Message Field | Q22: 下り項目 Response Message Field
A23: 30 | B23: * | D23: ShipStkRpl_Xfr | E23: L
A24: 30 | D24: peg_no | E24: #MA.INT | G24: Pegging No. | H24: 紐付けＮＯ
A25: 30 | D25: err_flg | E25: #MA.FLG | G25: Error | H25: エラー
A26: 30 | D26: xfr_schd_no | E26: #MA.XFR_SCHD_NO | G26: Movement/transport schedule No. | H26: 移動移送予定ＮＯ
L27: 上り項目 Request Message Field | M27: 下り項目 Response Message Field | N27: 上り項目 Request Message Field | O27: 下り項目 Response Message Field | P27: 上り項目 Request Message Field | Q27: 下り項目 Response Message Field
A28: 40 | B28: * | D28: ShipStkRpl_Cnt | E28: R | G28: $share$ | H28: MS.MSBEL5090.ShipStkRpl_Ins01.ShipStkRpl_Cnt
A29: 40 | D29: xfr_del_cnt | E29: #MA.INT | G29: Deleted number of movement/transport schedule | H29: 移動移送予定削除件数 | J29: E
D30: 詳細 :

Sheet 来歴
A1: 変更来歴
A3: Rev. | H3: 修正番号 | O3: 変更内容 | AQ3: 変更箇所
A4: 1 | O4: 初版
A5: 1.1 | O5: 英語の名称を追記 | AQ5: 全般
