Workbook

Sheet LogicCommon
A2: オペレーション実装仕様書 | B2: ModuleID : | C2: MS | D2: LogicID : | E2: MSBEL5530 | F2: Pj.ID : | G2: MC
B3: SubModuleID : | C3: MSBE | D3: LogicClass : | E3: MSBEL_ShipInstService | F3: SuperClassPj.ID :
D4: LogicName : | E4: 出荷指図サービス | F4: SuperLogicID : | G4: MS.MSUDL5010
A5: 概要 : | B5: 出荷予定に対する指図情報を作成します。
A6: 詳細 :

Sheet ShipInst_Chk01
A1: * | B1: * | D1: L | E1: 1
A2: * | D2: オペレーション実装仕様書 Operation Specification Implementation Sheet | E2: ModuleID : | F2: =IF(LogicCommon!C2="","",LogicCommon!C2) -> MS | G2: LogicID : | H2: =IF(LogicCommon!E2="","",LogicCommon!E2) -> MSBEL5530 | I2: Ope.ID : | J2: ShipInst_Chk01 | K2: Pj.ID : | L2: MC | M2: Ope.Body : | N2: MA.MAUDL5010.Checker
A3: * | D3: =IF(LogicCommon!A3="","",LogicCommon!A3) | E3: SubModuleID : | F3: =IF(LogicCommon!C3="","",LogicCommon!C3) -> MSBE | G3: LogicClass : | H3: =IF(LogicCommon!E3="","",LogicCommon!E3) -> MSBEL_ShipInstService | I3: Ope.Method : | J3: @ | K3: SuperClassPj.ID : | O3: Gene.Type : | P3: ALL
A4: * | E4: Version : | F4: 000000 | G4: LogicName : | H4: =IF(LogicCommon!E4="","",LogicCommon!E4) -> 出荷指図サービス | I4: Ope.Name : | J4: 出荷指図登録前チェック | K4: SuperLogicID : | L4: MS.MSUDL5010 | M4: ImplOpe.ID:
A5: * | E5: ACType :
A6: * | D6: 概要 : | E6: 出荷指図登録オペレーション実施前に事前チェックを行います。 | AD6: ID | AF6: ID | AH6: ID
A7: # | I7: U | K7: K | L7: K | M7: K | N7: K | O7: K | P7: K | Q7: K | R7: K | S7: K | T7: K | U7: K | V7: K | W7: K | X7: K | Y7: K | Z7: K | AA7: K | AB7: K | AC7: o | AE7: o | AG7: o
A8: # | D8: ブロック名 Block Name | E8: 型 Type | G8: super/share | H8: 対象ブロック名 Target Block Name | K8: REQ_UPD_CNT_CHK | L8: REQUIRED | M8: CHK_NUM | N8: SMALL_LARGE | O8: CHK_DT | P8: BEFORE_AFTER | Q8: CHK_PTN | R8: DUPLICATE | S8: TOO_MANY_INPUTS | T8: AT_LEAST_ONE | U8: ONLY_ONE_INPUT | V8: LIST_LOGIC | W8: LIST_OUT | X8: LIST_OUT_BASE | Y8: LIST_IN | Z8: LIST_IN_BASE | AA8: CONST | AB8: NULL_VAL | AE8: TargetName | AG8: TargetName | AK8: ブロック備考 Block Remarks
A9: # | D9: 項目名 Field Name | E9: 型 Type | F9: 桁 Digits | G9: フルネーム Full Name | H9: 日本語名 Japanese Name | I9: 上り項目 Request Message Field | J9: 下り項目 Response Message Field | AI9: 条件および編集方法 Conditions and Editing Methods | AK9: 項目備考 Field Remarks
A10: # | AC10: 上り項目 Request Message Field | AD10: 下り項目 Response Message Field | AE10: 上り項目 Request Message Field | AF10: 下り項目 Response Message Field | AG10: 上り項目 Request Message Field | AH10: 下り項目 Response Message Field
A11: 10 | B11: * | D11: ShipInst_Chk01_Hdr | E11: L
A12: 10 | D12: data_crud_typ | E12: #MA.DATA_CRUD_TYP | G12: Data update type | H12: データ更新区分 | I12: E | J12: E
A13: 10 | D13: ship_inst_no | E13: #MA.SHIP_INST_NO | G13: Shipping order No. | H13: 出荷指図ＮＯ | I13: - | J13: E
A14: 10 | D14: ship_fr_lg_grp_cd | E14: #MA.LG_GRP_CD | G14: Shipping point distribution group cd. | H14: 出荷元物流グループＣＤ | I14: E | J14: E
A15: 10 | D15: wg_cd | E15: #MA.WG_CD | G15: WG cd. | H15: ワーキンググループＣＤ | I15: E | J15: E
A16: 10 | D16: ship_term_cd | E16: #MA.SHIP_TERM_CD | G16: Shipping conditions cd. | H16: 出荷条件ＣＤ | I16: E | J16: E
A17: 10 | D17: ship_wk_cd | E17: #MA.SHIP_WK_CD | G17: Shipping operation cd. | H17: 出荷作業ＣＤ | I17: E | J17: E
A18: 10 | D18: ship_schd_tm | E18: #MA.TM | G18: Scheduled shipping date and time | H18: 出荷予定日時 | I18: E | J18: E
A19: 10 | D19: dlv_schd_tm | E19: #MA.TM | G19: Scheduled delivery date and time | H19: 納品予定日時 | I19: E | J19: E
A20: 10 | D20: inst_dpt_cd | E20: #MA.DPT_CD | G20: Order dept. cd. | H20: 指図部門ＣＤ | I20: E | J20: E
A21: 10 | D21: inst_usr_cd | E21: #MA.USR_CD | G21: Order PIC cd. | H21: 指図担当者ＣＤ | I21: E | J21: E
A22: 10 | D22: ship_inst_tm | E22: #MA.TM | G22: Shipping order date and time | H22: 出荷指図日時 | I22: E | J22: E
A23: 10 | D23: ship_to_lg_grp_cd | E23: #MA.LG_GRP_CD | G23: Receiving point distribution group cd. | H23: 出荷先物流グループＣＤ | I23: E | J23: E
... A26: 10 | D26: ship_to_id_nm | E26: #MS.SHIP_TO_ID_NM | G26: Receiving point Identification name | H26: 送付先識別名 | I26: E | J26: E
A27: 10 | D27: ship_to_zip_cd | E27: #MA.ZIP_CD | G27: Receiving point zip code | H27: 送付先郵便番号 | I27: E | J27: E | Q27: ZIP
A28: 10 | D28: ship_to_addr1 | E28: #MA.ADDR | G28: Receiving point address 1 | H28: 送付先住所１ | I28: E | J28: E
A29: 10 | D29: ship_to_addr2 | E29: #MA.ADDR | G29: Receiving point address 2 | H29: 送付先住所２ | I29: E | J29: E
A30: 10 | D30: ship_to_addr3 | E30: #MA.ADDR | G30: Receiving point address 3 | H30: 送付先住所３ | I30: E | J30: E
A31: 10 | D31: ship_to_addr4 | E31: #MA.ADDR | G31: Receiving point address 4 | H31: 送付先住所４ | I31: E | J31: E
A32: 10 | D32: ship_to_cntct_dpt | E32: #MA.BP_CNTCT_DPT | G32: Receiving point dept. | H32: 送付先部署 | I32: E | J32: E
A33: 10 | D33: ship_to_cntct_psn | E33: #MA.BP_CNTCT_PSN | G33: Receiving point PIC | H33: 送付先担当者 | I33: E | J33: E
A34: 10 | D34: ship_to_tel | E34: #MA.TEL | G34: Receiving point TEL | H34: 送付先ＴＥＬ | I34: E | J34: E | Q34: TEL
A35: 10 | D35: ship_to_fax | E35: #MA.TEL | G35: Receiving point FAX | H35: 送付先ＦＡＸ | I35: E | J35: E | Q35: TEL
A36: 10 | D36: ship_to_sundry_flg | E36: #MA.FLG | G36: Miscellaneous receiving point flg. | H36: 送付先諸口ＦＬＧ | I36: E | J36: E
A37: 10 | D37: via_dlv_typ | E37: #MA.VIA_DLV_TYP | G37: Receiving point stopover type | H37: 配送先経由区分 | I37: E | J37: E
A38: 10 | D38: iv_no | E38: #MA.IV_NO | G38: Invoice No. | H38: インボイスＮＯ | I38: E | J38: E
A39: 10 | D39: intr_rmrks | E39: #MS.SHIP_INST_INTR_RMRKS | G39: Internal remarks | H39: 内部備考 | I39: E | J39: E
A40: 10 | D40: inst_rmrks | E40: #MS.SHIP_INST_RMRKS | G40: Order remarks | H40: 指図備考 | I40: E | J40: E
A41: 10 | D41: sub_char1 | E41: #MS.SHIP_INST_SUB_CHAR1 | G41: Spare 1 | H41: 予備１ | I41: E | J41: E
A42: 10 | D42: sub_char2 | E42: #MS.SHIP_INST_SUB_CHAR2 | G42: Spare 2 | H42: 予備２ | I42: E | J42: E
...

Sheet ShipInst_Chk02
A1: * | B1: * | D1: L | E1: 1
A2: * | D2: オペレーション実装仕様書 Operation Specification Implementation Sheet | E2: ModuleID : | F2: =IF(LogicCommon!C2="","",LogicCommon!C2) -> MS | G2: LogicID : | H2: =IF(LogicCommon!E2="","",LogicCommon!E2) -> MSBEL5530 | I2: Ope.ID : | J2: ShipInst_Chk02 | K2: Pj.ID : | L2: MC | M2: Ope.Body : | N2: MA.MAUDL5010.Checker
A3: * | D3: =IF(LogicCommon!A3="","",LogicCommon!A3) | E3: SubModuleID : | F3: =IF(LogicCommon!C3="","",LogicCommon!C3) -> MSBE | G3: LogicClass : | H3: =IF(LogicCommon!E3="","",LogicCommon!E3) -> MSBEL_ShipInstService | I3: Ope.Method : | J3: @ | K3: SuperClassPj.ID : | O3: Gene.Type : | P3: ALL
A4: * | E4: Version : | F4: 000000 | G4: LogicName : | H4: =IF(LogicCommon!E4="","",LogicCommon!E4) -> 出荷指図サービス | I4: Ope.Name : | J4: 出荷指図更新前チェック | K4: SuperLogicID : | L4: MS.MSUDL5010 | M4: ImplOpe.ID:
A5: * | E5: ACType :
A6: * | D6: 概要 : | E6: 出荷指図更新オペレーション実施前に事前チェックを行います。 | AD6: ID | AF6: ID | AH6: ID
A7: # | I7: U | K7: K | L7: K | M7: K | N7: K | O7: K | P7: K | Q7: K | R7: K | S7: K | T7: K | U7: K | V7: K | W7: K | X7: K | Y7: K | Z7: K | AA7: K | AB7: K | AC7: o | AE7: o | AG7: o
A8: # | D8: ブロック名 Block Name | E8: 型 Type | G8: super/share | H8: 対象ブロック名 Target Block Name | K8: REQ_UPD_CNT_CHK | L8: REQUIRED | M8: CHK_NUM | N8: SMALL_LARGE | O8: CHK_DT | P8: BEFORE_AFTER | Q8: CHK_PTN | R8: DUPLICATE | S8: TOO_MANY_INPUTS | T8: AT_LEAST_ONE | U8: ONLY_ONE_INPUT | V8: LIST_LOGIC | W8: LIST_OUT | X8: LIST_OUT_BASE | Y8: LIST_IN | Z8: LIST_IN_BASE | AA8: CONST | AB8: NULL_VAL | AE8: TargetName | AG8: TargetName | AK8: ブロック備考 Block Remarks
A9: # | D9: 項目名 Field Name | E9: 型 Type | F9: 桁 Digits | G9: フルネーム Full Name | H9: 日本語名 Japanese Name | I9: 上り項目 Request Message Field | J9: 下り項目 Response Message Field | AI9: 条件および編集方法 Conditions and Editing Methods | AK9: 項目備考 Field Remarks
A10: # | AC10: 上り項目 Request Message Field | AD10: 下り項目 Response Message Field | AE10: 上り項目 Request Message Field | AF10: 下り項目 Response Message Field | AG10: 上り項目 Request Message Field | AH10: 下り項目 Response Message Field
A11: 10 | B11: * | D11: ShipInst_Chk02_Hdr | E11: L | G11: $share$ | H11: MS.MSBEL5530.ShipInst_Chk01.ShipInst_Chk01_Hdr
A12: 10 | D12: data_crud_typ | E12: #MA.DATA_CRUD_TYP | G12: Data update type | H12: データ更新区分 | I12: E | J12: E
A13: 10 | D13: ship_inst_no | E13: #MA.SHIP_INST_NO | G13: Shipping order No. | H13: 出荷指図ＮＯ | I13: E | J13: E
A14: 10 | D14: ship_fr_lg_grp_cd | E14: #MA.LG_GRP_CD | G14: Shipping point distribution group cd. | H14: 出荷元物流グループＣＤ | I14: E | J14: E
A15: 10 | D15: wg_cd | E15: #MA.WG_CD | G15: WG cd. | H15: ワーキンググループＣＤ | I15: E | J15: E
A16: 10 | D16: ship_term_cd | E16: #MA.SHIP_TERM_CD | G16: Shipping conditions cd. | H16: 出荷条件ＣＤ | I16: E | J16: E
A17: 10 | D17: ship_wk_cd | E17: #MA.SHIP_WK_CD | G17: Shipping operation cd. | H17: 出荷作業ＣＤ | I17: E | J17: E
A18: 10 | D18: ship_schd_tm | E18: #MA.TM | G18: Scheduled shipping date and time | H18: 出荷予定日時 | I18: E | J18: E
A19: 10 | D19: dlv_schd_tm | E19: #MA.TM | G19: Scheduled delivery date and time | H19: 納品予定日時 | I19: E | J19: E
A20: 10 | D20: inst_dpt_cd | E20: #MA.DPT_CD | G20: Order dept. cd. | H20: 指図部門ＣＤ | I20: E | J20: E
A21: 10 | D21: inst_usr_cd | E21: #MA.USR_CD | G21: Order PIC cd. | H21: 指図担当者ＣＤ | I21: E | J21: E
A22: 10 | D22: ship_inst_tm | E22: #MA.TM | G22: Shipping order date and time | H22: 出荷指図日時 | I22: E | J22: E
A23: 10 | D23: ship_to_lg_grp_cd | E23: #MA.LG_GRP_CD | G23: Receiving point distribution group cd. | H23: 出荷先物流グループＣＤ | I23: E | J23: E
... A26: 10 | D26: ship_to_id_nm | E26: #MS.SHIP_TO_ID_NM | G26: Receiving point Identification name | H26: 送付先識別名 | I26: E | J26: E
A27: 10 | D27: ship_to_zip_cd | E27: #MA.ZIP_CD | G27: Receiving point zip code | H27: 送付先郵便番号 | I27: E | J27: E | Q27: ZIP
A28: 10 | D28: ship_to_addr1 | E28: #MA.ADDR | G28: Receiving point address 1 | H28: 送付先住所１ | I28: E | J28: E
A29: 10 | D29: ship_to_addr2 | E29: #MA.ADDR | G29: Receiving point address 2 | H29: 送付先住所２ | I29: E | J29: E
A30: 10 | D30: ship_to_addr3 | E30: #MA.ADDR | G30: Receiving point address 3 | H30: 送付先住所３ | I30: E | J30: E
A31: 10 | D31: ship_to_addr4 | E31: #MA.ADDR | G31: Receiving point address 4 | H31: 送付先住所４ | I31: E | J31: E
A32: 10 | D32: ship_to_cntct_dpt | E32: #MA.BP_CNTCT_DPT | G32: Receiving point dept. | H32: 送付先部署 | I32: E | J32: E
A33: 10 | D33: ship_to_cntct_psn | E33: #MA.BP_CNTCT_PSN | G33: Receiving point PIC | H33: 送付先担当者 | I33: E | J33: E
A34: 10 | D34: ship_to_tel | E34: #MA.TEL | G34: Receiving point TEL | H34: 送付先ＴＥＬ | I34: E | J34: E | Q34: TEL
A35: 10 | D35: ship_to_fax | E35: #MA.TEL | G35: Receiving point FAX | H35: 送付先ＦＡＸ | I35: E | J35: E | Q35: TEL
A36: 10 | D36: ship_to_sundry_flg | E36: #MA.FLG | G36: Miscellaneous receiving point flg. | H36: 送付先諸口ＦＬＧ | I36: E | J36: E
A37: 10 | D37: via_dlv_typ | E37: #MA.VIA_DLV_TYP | G37: Receiving point stopover type | H37: 配送先経由区分 | I37: E | J37: E
A38: 10 | D38: iv_no | E38: #MA.IV_NO | G38: Invoice No. | H38: インボイスＮＯ | I38: E | J38: E
A39: 10 | D39: intr_rmrks | E39: #MS.SHIP_INST_INTR_RMRKS | G39: Internal remarks | H39: 内部備考 | I39: E | J39: E
A40: 10 | D40: inst_rmrks | E40: #MS.SHIP_INST_RMRKS | G40: Order remarks | H40: 指図備考 | I40: E | J40: E
A41: 10 | D41: sub_char1 | E41: #MS.SHIP_INST_SUB_CHAR1 | G41: Spare 1 | H41: 予備１ | I41: E | J41: E
A42: 10 | D42: sub_char2 | E42: #MS.SHIP_INST_SUB_CHAR2 | G42: Spare 2 | H42: 予備２ | I42: E | J42: E
...

Sheet ShipInst_Chk03
A1: * | B1: * | D1: L | E1: 1
A2: * | D2: オペレーション実装仕様書 Operation Specification Implementation Sheet | E2: ModuleID : | F2: =IF(LogicCommon!C2="","",LogicCommon!C2) -> MS | G2: LogicID : | H2: =IF(LogicCommon!E2="","",LogicCommon!E2) -> MSBEL5530 | I2: Ope.ID : | J2: ShipInst_Chk03 | K2: Pj.ID : | L2: MC | M2: Ope.Body : | N2: MA.MAUDL5010.Checker
A3: * | D3: =IF(LogicCommon!A3="","",LogicCommon!A3) | E3: SubModuleID : | F3: =IF(LogicCommon!C3="","",LogicCommon!C3) -> MSBE | G3: LogicClass : | H3: =IF(LogicCommon!E3="","",LogicCommon!E3) -> MSBEL_ShipInstService | I3: Ope.Method : | J3: @ | K3: SuperClassPj.ID : | O3: Gene.Type : | P3: ALL
A4: * | E4: Version : | F4: 000000 | G4: LogicName : | H4: =IF(LogicCommon!E4="","",LogicCommon!E4) -> 出荷指図サービス | I4: Ope.Name : | J4: 出荷指図削除前チェック | K4: SuperLogicID : | L4: MS.MSUDL5010 | M4: ImplOpe.ID:
A5: * | E5: ACType :
A6: * | D6: 概要 : | E6: 出荷指図削除オペレーション実施前に事前チェックを行います。 | AD6: ID | AF6: ID | AH6: ID
A7: # | I7: U | K7: K | L7: K | M7: K | N7: K | O7: K | P7: K | Q7: K | R7: K | S7: K | T7: K | U7: K | V7: K | W7: K | X7: K | Y7: K | Z7: K | AA7: K | AB7: K | AC7: o | AE7: o | AG7: o
A8: # | D8: ブロック名 Block Name | E8: 型 Type | G8: super/share | H8: 対象ブロック名 Target Block Name | K8: REQ_UPD_CNT_CHK | L8: REQUIRED | M8: CHK_NUM | N8: SMALL_LARGE | O8: CHK_DT | P8: BEFORE_AFTER | Q8: CHK_PTN | R8: DUPLICATE | S8: TOO_MANY_INPUTS | T8: AT_LEAST_ONE | U8: ONLY_ONE_INPUT | V8: LIST_LOGIC | W8: LIST_OUT | X8: LIST_OUT_BASE | Y8: LIST_IN | Z8: LIST_IN_BASE | AA8: CONST | AB8: NULL_VAL | AE8: TargetName | AG8: TargetName | AK8: ブロック備考 Block Remarks
A9: # | D9: 項目名 Field Name | E9: 型 Type | F9: 桁 Digits | G9: フルネーム Full Name | H9: 日本語名 Japanese Name | I9: 上り項目 Request Message Field | J9: 下り項目 Response Message Field | AI9: 条件および編集方法 Conditions and Editing Methods | AK9: 項目備考 Field Remarks
A10: # | AC10: 上り項目 Request Message Field | AD10: 下り項目 Response Message Field | AE10: 上り項目 Request Message Field | AF10: 下り項目 Response Message Field | AG10: 上り項目 Request Message Field | AH10: 下り項目 Response Message Field
A11: 10 | B11: * | D11: ShipInst_Chk03_Hdr | E11: L
A12: 10 | D12: err_flg | E12: #MA.FLG | G12: Error flg. | H12: エラーＦＬＧ | I12: - | J12: E
A13: 10 | D13: data_crud_typ | E13: #MA.DATA_CRUD_TYP | G13: Data update type | H13: データ更新区分 | I13: E | J13: E
A14: 10 | D14: ship_inst_no | E14: #MA.SHIP_INST_NO | G14: Shipping order No. | H14: 出荷指図ＮＯ | I14: E | J14: E
A15: 10 | D15: dlv_prnt_flg | E15: #MA.FLG | G15: Delivery note immediate issue flg. | H15: 納品書即時発行ＦＬＧ | I15: E | J15: E
A16: 10 | D16: is_src_shipinst_list_flg | E16: #MA.FLG | G16: Caller shipping order list | H16: 呼出元出荷指図一覧 | I16: E | J16: E
A18: 20 | B18: * | D18: ShipInst_Chk03_Dtl | E18: L
A19: 20 | D19: ship_inst_no | E19: #MA.SHIP_INST_NO | G19: Shipping order No. | H19: 出荷指図ＮＯ | I19: E | J19: E
A20: 20 | D20: ship_alloc_sts_no | E20: #MA.SHIP_ALLOC_STS_NO | G20: Shipping allocation status No. | H20: 出荷引当状況ＮＯ | I20: E | J20: E
A21: 20 | D21: wms_flg | E21: #MA.FLG | G21: WMS | H21: ＷＭＳ | I21: E | J21: E

Sheet ShipInst_Ins01
A1: * | B1: * | D1: L | E1: 1
A2: * | D2: オペレーション実装仕様書 Operation Specification Implementation Sheet | E2: ModuleID : | F2: =IF(LogicCommon!C2="","",LogicCommon!C2) -> MS | G2: LogicID : | H2: =IF(LogicCommon!E2="","",LogicCommon!E2) -> MSBEL5530 | I2: Ope.ID : | J2: ShipInst_Ins01 | K2: Pj.ID : | L2: =IF(LogicCommon!G2="","",LogicCommon!G2) -> MC | M2: Ope.Body : | N2: "mcframe.serverMAUD.MAUDL5010.MAUDL_Operation"
A3: * | D3: =IF(LogicCommon!A3="","",LogicCommon!A3) | E3: SubModuleID : | F3: =IF(LogicCommon!C3="","",LogicCommon!C3) -> MSBE | G3: LogicClass : | H3: =IF(LogicCommon!E3="","",LogicCommon!E3) -> MSBEL_ShipInstService | I3: Ope.Method : | J3: @ | K3: SuperClassPj.ID : | L3: =IF(LogicCommon!G3="","",LogicCommon!G3) | O3: Gene.Type : | P3: ALL
A4: * | E4: Version : | F4: 000000 | G4: LogicName : | H4: =IF(LogicCommon!E4="","",LogicCommon!E4) -> 出荷指図サービス | I4: Ope.Name : | J4: 出荷指図登録 | K4: SuperLogicID : | L4: =IF(LogicCommon!G4="","",LogicCommon!G4) -> MS.MSUDL5010 | M4: ImplOpe.ID:
A5: * | E5: ACType :
A6: * | D6: 概要 : | E6: 出荷指図を登録します。 | M6: ID | O6: ID | Q6: ID
A7: # | I7: U | K7: K | L7: o | N7: o | P7: o
A8: # | D8: ブロック名 Block Name | E8: 型 Type | G8: super/share | H8: 対象ブロック名 Target Block Name | L8: TargetName | N8: TargetName | P8: TargetName | T8: ブロック備考 Block Remarks
A9: # | D9: 項目名 Field Name | E9: 型 Type | F9: 桁 Digits | G9: フルネーム Full Name | H9: 日本語名 Japanese Name | I9: 上り項目 Request Message Field | J9: 下り項目 Response Message Field | R9: 条件および編集方法 Conditions and Editing Methods | T9: 項目備考 Field Remarks
A10: # | L10: 上り項目 Request Message Field | M10: 下り項目 Response Message Field | N10: 上り項目 Request Message Field | O10: 下り項目 Response Message Field | P10: 上り項目 Request Message Field | Q10: 下り項目 Response Message Field
A11: 10 | B11: * | D11: ShipInst_Ins01_Hdr | E11: L | G11: $share$ | H11: MS.MSBEL5530.ShipInst_Chk01.ShipInst_Chk01_Hdr
A12: 10 | D12: data_crud_typ | E12: #MA.DATA_CRUD_TYP | G12: Data update type | H12: データ更新区分 | I12: E | J12: E
A13: 10 | D13: ship_inst_no | E13: #MA.SHIP_INST_NO | G13: Shipping order No. | H13: 出荷指図ＮＯ | I13: - | J13: E
A14: 10 | D14: ship_fr_lg_grp_cd | E14: #MA.LG_GRP_CD | G14: Shipping point distribution group cd. | H14: 出荷元物流グループＣＤ | I14: E | J14: E
A15: 10 | D15: wg_cd | E15: #MA.WG_CD | G15: WG cd. | H15: ワーキンググループＣＤ | I15: E | J15: E
A16: 10 | D16: ship_term_cd | E16: #MA.SHIP_TERM_CD | G16: Shipping conditions cd. | H16: 出荷条件ＣＤ | I16: E | J16: E
A17: 10 | D17: ship_wk_cd | E17: #MA.SHIP_WK_CD | G17: Shipping operation cd. | H17: 出荷作業ＣＤ | I17: E | J17: E
A18: 10 | D18: ship_schd_tm | E18: #MA.TM | G18: Scheduled shipping date and time | H18: 出荷予定日時 | I18: E | J18: E
A19: 10 | D19: dlv_schd_tm | E19: #MA.TM | G19: Scheduled delivery date and time | H19: 納品予定日時 | I19: E | J19: E
A20: 10 | D20: inst_dpt_cd | E20: #MA.DPT_CD | G20: Order dept. cd. | H20: 指図部門ＣＤ | I20: E | J20: E
A21: 10 | D21: inst_usr_cd | E21: #MA.USR_CD | G21: Order PIC cd. | H21: 指図担当者ＣＤ | I21: E | J21: E
A22: 10 | D22: ship_inst_tm | E22: #MA.TM | G22: Shipping order date and time | H22: 出荷指図日時 | I22: E | J22: E
A23: 10 | D23: ship_to_lg_grp_cd | E23: #MA.LG_GRP_CD | G23: Receiving point distribution group cd. | H23: 出荷先物流グループＣＤ | I23: E | J23: E
... A50: 10 | D50: lot_chk_off_flg | E50: #MA.FLG | G50: Ignore lot check | H50: ロットチェック無視 | I50: E | J50: -
A52: 20 | B52: * | D52: ShipInst_Ins01_Dtl | E52: L | G52: $share$ | H52: MS.MSBEL5530.ShipInst_Chk01.ShipInst_Chk01_Dtl
A53: 20 | D53: peg_no | E53: #MA.INT | G53: Pegging No. | H53: 紐付けＮＯ | I53: E | J53: E
A54: 20 | D54: err_flg | E54: #MA.FLG | G54: Error flg. | H54: エラーＦＬＧ | I54: - | J54: -
A55: 20 | D55: data_crud_typ | E55: #MA.DATA_CRUD_TYP | G55: Data update type | H55: データ更新区分 | I55: E | J55: E
A56: 20 | D56: tmp_inst_d_no | E56: #MA.INT | G56: Temporary order details No. | H56: 仮指図明細ＮＯ | I56: E | J56: E
A57: 20 | D57: ship_inst_d_no | E57: #MA.SHIP_INST_D_NO | G57: Shipping order details No. | H57: 出荷指図明細ＮＯ | I57: - | J57: E
A58: 20 | D58: ship_inst_no | E58: #MA.SHIP_INST_NO | G58: Shipping order No. | H58: 出荷指図ＮＯ | I58: - | J58: E
A59: 20 | D59: disp_seq | E59: #MA.DISP_SEQ | G59: Display order | H59: 表示順 | I59: E | J59: E
A60: 20 | D60: ship_loc_cd | E60: #MA.LOC_CD | G60: Shipping location cd. | H60: 出荷場所ＣＤ | I60: E | J60: E
A61: 20 | D61: ship_str_ln_cd | E61: #MA.STR_LN_CD | G61: Shipping rack/line cd. | H61: 出荷棚・ラインＣＤ | I61: E | J61: E
A62: 20 | D62: ship_lg_grp_cd | E62: #MA.LG_GRP_CD | G62: Shipping distribution group cd. | H62: 出荷物流グループＣＤ | I62: E | J62: E
A63: 20 | D63: alloc_loc_cd | E63: #MA.LOC_CD | G63: Allocation location cd. | H63: 引当場所ＣＤ | I63: E | J63: E
A64: 20 | D64: alloc_str_ln_cd | E64: #MA.STR_LN_CD | G64: Allocation rack/line cd. | H64: 引当棚・ラインＣＤ | I64: E | J64: E
... A135: 20 | D135: ship_schd_tm | E135: #MA.TM | G135: Scheduled shipping date and time | H135: 出荷予定日時 | I135: - | J135: -
A136: 20 | D136: sas | E136: R | F136: DBC:MS.MST_SHIP_ALLOC_STS
A137: 20 | D137: sas.ship_alloc_sts_no# | E137: RI | G137: Shipping allocation status No. | H137: 出荷引当状況ＮＯ | I137: E | J137: E
...

Sheet ShipInst_Upd01
A1: * | B1: * | D1: L | E1: 1
A2: * | D2: オペレーション実装仕様書 Operation Specification Implementation Sheet | E2: ModuleID : | F2: =IF(LogicCommon!C2="","",LogicCommon!C2) -> MS | G2: LogicID : | H2: =IF(LogicCommon!E2="","",LogicCommon!E2) -> MSBEL5530 | I2: Ope.ID : | J2: ShipInst_Upd01 | K2: Pj.ID : | L2: =IF(LogicCommon!G2="","",LogicCommon!G2) -> MC | M2: Ope.Body : | N2: "mcframe.serverMAUD.MAUDL5010.MAUDL_Operation"
A3: * | D3: =IF(LogicCommon!A3="","",LogicCommon!A3) | E3: SubModuleID : | F3: =IF(LogicCommon!C3="","",LogicCommon!C3) -> MSBE | G3: LogicClass : | H3: =IF(LogicCommon!E3="","",LogicCommon!E3) -> MSBEL_ShipInstService | I3: Ope.Method : | J3: @ | K3: SuperClassPj.ID : | L3: =IF(LogicCommon!G3="","",LogicCommon!G3) | O3: Gene.Type : | P3: ALL
A4: * | E4: Version : | F4: 000000 | G4: LogicName : | H4: =IF(LogicCommon!E4="","",LogicCommon!E4) -> 出荷指図サービス | I4: Ope.Name : | J4: 出荷指図更新 | K4: SuperLogicID : | L4: =IF(LogicCommon!G4="","",LogicCommon!G4) -> MS.MSUDL5010 | M4: ImplOpe.ID:
A5: * | E5: ACType :
A6: * | D6: 概要 : | E6: 出荷指図NOの単位で出荷指図を訂正する。 | M6: ID | O6: ID | Q6: ID
A7: # | I7: U | K7: K | L7: o | N7: o | P7: o
A8: # | D8: ブロック名 Block Name | E8: 型 Type | G8: super/share | H8: 対象ブロック名 Target Block Name | L8: TargetName | N8: TargetName | P8: TargetName | T8: ブロック備考 Block Remarks
A9: # | D9: 項目名 Field Name | E9: 型 Type | F9: 桁 Digits | G9: フルネーム Full Name | H9: 日本語名 Japanese Name | I9: 上り項目 Request Message Field | J9: 下り項目 Response Message Field | R9: 条件および編集方法 Conditions and Editing Methods | T9: 項目備考 Field Remarks
A10: # | L10: 上り項目 Request Message Field | M10: 下り項目 Response Message Field | N10: 上り項目 Request Message Field | O10: 下り項目 Response Message Field | P10: 上り項目 Request Message Field | Q10: 下り項目 Response Message Field
A11: 10 | B11: * | D11: ShipInst_Upd01_Hdr | E11: L | G11: $share$ | H11: MS.MSBEL5530.ShipInst_Chk01.ShipInst_Chk01_Hdr
A12: 10 | D12: data_crud_typ | E12: #MA.DATA_CRUD_TYP | G12: Data update type | H12: データ更新区分 | I12: E | J12: E
A13: 10 | D13: ship_inst_no | E13: #MA.SHIP_INST_NO | G13: Shipping order No. | H13: 出荷指図ＮＯ | I13: E | J13: E
A14: 10 | D14: ship_fr_lg_grp_cd | E14: #MA.LG_GRP_CD | G14: Shipping point distribution group cd. | H14: 出荷元物流グループＣＤ | I14: E | J14: E
A15: 10 | D15: wg_cd | E15: #MA.WG_CD | G15: WG cd. | H15: ワーキンググループＣＤ | I15: E | J15: E
A16: 10 | D16: ship_term_cd | E16: #MA.SHIP_TERM_CD | G16: Shipping conditions cd. | H16: 出荷条件ＣＤ | I16: E | J16: E
A17: 10 | D17: ship_wk_cd | E17: #MA.SHIP_WK_CD | G17: Shipping operation cd. | H17: 出荷作業ＣＤ | I17: E | J17: E
A18: 10 | D18: ship_schd_tm | E18: #MA.TM | G18: Scheduled shipping date and time | H18: 出荷予定日時 | I18: E | J18: E
A19: 10 | D19: dlv_schd_tm | E19: #MA.TM | G19: Scheduled delivery date and time | H19: 納品予定日時 | I19: E | J19: E
A20: 10 | D20: inst_dpt_cd | E20: #MA.DPT_CD | G20: Order dept. cd. | H20: 指図部門ＣＤ | I20: E | J20: E
A21: 10 | D21: inst_usr_cd | E21: #MA.USR_CD | G21: Order PIC cd. | H21: 指図担当者ＣＤ | I21: E | J21: E
A22: 10 | D22: ship_inst_tm | E22: #MA.TM | G22: Shipping order date and time | H22: 出荷指図日時 | I22: E | J22: E
A23: 10 | D23: ship_to_lg_grp_cd | E23: #MA.LG_GRP_CD | G23: Receiving point distribution group cd. | H23: 出荷先物流グループＣＤ | I23: E | J23: E
... A50: 10 | D50: lot_chk_off_flg | E50: #MA.FLG | G50: Ignore lot check | H50: ロットチェック無視 | I50: E | J50: -
A52: 20 | B52: * | D52: ShipInst_Upd01_Dtl | E52: L | G52: $share$ | H52: MS.MSBEL5530.ShipInst_Chk01.ShipInst_Chk01_Dtl
A53: 20 | D53: peg_no | E53: #MA.INT | G53: Pegging No. | H53: 紐付けＮＯ | I53: E | J53: E
A54: 20 | D54: err_flg | E54: #MA.FLG | G54: Error flg. | H54: エラーＦＬＧ | I54: - | J54: -
A55: 20 | D55: data_crud_typ | E55: #MA.DATA_CRUD_TYP | G55: Data update type | H55: データ更新区分 | I55: E | J55: E
A56: 20 | D56: tmp_inst_d_no | E56: #MA.INT | G56: Temporary order details No. | H56: 仮指図明細ＮＯ | I56: E | J56: E
A57: 20 | D57: ship_inst_d_no | E57: #MA.SHIP_INST_D_NO | G57: Shipping order details No. | H57: 出荷指図明細ＮＯ | I57: E | J57: E
A58: 20 | D58: ship_inst_no | E58: #MA.SHIP_INST_NO | G58: Shipping order No. | H58: 出荷指図ＮＯ | I58: E | J58: E
A59: 20 | D59: disp_seq | E59: #MA.DISP_SEQ | G59: Display order | H59: 表示順 | I59: E | J59: E
A60: 20 | D60: ship_loc_cd | E60: #MA.LOC_CD | G60: Shipping location cd. | H60: 出荷場所ＣＤ | I60: E | J60: E
A61: 20 | D61: ship_str_ln_cd | E61: #MA.STR_LN_CD | G61: Shipping rack/line cd. | H61: 出荷棚・ラインＣＤ | I61: E | J61: E
A62: 20 | D62: ship_lg_grp_cd | E62: #MA.LG_GRP_CD | G62: Shipping distribution group cd. | H62: 出荷物流グループＣＤ | I62: E | J62: E
A63: 20 | D63: alloc_loc_cd | E63: #MA.LOC_CD | G63: Allocation location cd. | H63: 引当場所ＣＤ | I63: E | J63: E
A64: 20 | D64: alloc_str_ln_cd | E64: #MA.STR_LN_CD | G64: Allocation rack/line cd. | H64: 引当棚・ラインＣＤ | I64: E | J64: E
... A135: 20 | D135: ship_schd_tm | E135: #MA.TM | G135: Scheduled shipping date and time | H135: 出荷予定日時 | I135: - | J135: -
A136: 20 | D136: sas | E136: R | F136: DBC:MS.MST_SHIP_ALLOC_STS
A137: 20 | D137: sas.ship_alloc_sts_no# | E137: RI | G137: Shipping allocation status No. | H137: 出荷引当状況ＮＯ | I137: E | J137: E
...

Sheet ShipInst_Upd02
A1: * | B1: * | D1: L | E1: 1
A2: * | D2: オペレーション実装仕様書 Operation Specification Implementation Sheet | E2: ModuleID : | F2: =IF(LogicCommon!C2="","",LogicCommon!C2) -> MS | G2: LogicID : | H2: =IF(LogicCommon!E2="","",LogicCommon!E2) -> MSBEL5530 | I2: Ope.ID : | J2: ShipInst_Upd02 | K2: Pj.ID : | L2: =IF(LogicCommon!G2="","",LogicCommon!G2) -> MC | M2: Ope.Body : | N2: "mcframe.serverMAUD.MAUDL5010.MAUDL_Operation"
A3: * | D3: =IF(LogicCommon!A3="","",LogicCommon!A3) | E3: SubModuleID : | F3: =IF(LogicCommon!C3="","",LogicCommon!C3) -> MSBE | G3: LogicClass : | H3: =IF(LogicCommon!E3="","",LogicCommon!E3) -> MSBEL_ShipInstService | I3: Ope.Method : | J3: @ | K3: SuperClassPj.ID : | L3: =IF(LogicCommon!G3="","",LogicCommon!G3) | O3: Gene.Type : | P3: ALL
A4: * | E4: Version : | F4: 000000 | G4: LogicName : | H4: =IF(LogicCommon!E4="","",LogicCommon!E4) -> 出荷指図サービス | I4: Ope.Name : | J4: 打切・実績数更新 | K4: SuperLogicID : | L4: =IF(LogicCommon!G4="","",LogicCommon!G4) -> MS.MSUDL5010 | M4: ImplOpe.ID:
A5: * | E5: ACType :
A6: * | D6: 概要 : | E6: 出荷実績明細NO単位で打切および出荷実績数を更新する。 | M6: ID | O6: ID | Q6: ID
A7: # | I7: U | K7: K | L7: o | N7: o | P7: o
A8: # | D8: ブロック名 Block Name | E8: 型 Type | G8: super/share | H8: 対象ブロック名 Target Block Name | L8: TargetName | N8: TargetName | P8: TargetName | T8: ブロック備考 Block Remarks
A9: # | D9: 項目名 Field Name | E9: 型 Type | F9: 桁 Digits | G9: フルネーム Full Name | H9: 日本語名 Japanese Name | I9: 上り項目 Request Message Field | J9: 下り項目 Response Message Field | R9: 条件および編集方法 Conditions and Editing Methods | T9: 項目備考 Field Remarks
A10: # | L10: 上り項目 Request Message Field | M10: 下り項目 Response Message Field | N10: 上り項目 Request Message Field | O10: 下り項目 Response Message Field | P10: 上り項目 Request Message Field | Q10: 下り項目 Response Message Field
A11: 10 | B11: * | D11: ShipInst_Upd02_Dtl | E11: L
A12: 10 | D12: ship_inst_d_no | E12: #MA.SHIP_INST_D_NO | G12: Shipping order details No. | H12: 出荷指図明細ＮＯ | I12: E | J12: E
A13: 10 | D13: abort_flg | E13: #MA.FLG | G13: Cancel remaining flg. | H13: 打切ＦＬＧ | I13: E | J13: E

Sheet ShipInst_Del01
A1: * | B1: * | D1: L | E1: 1
A2: * | D2: オペレーション実装仕様書 Operation Specification Implementation Sheet | E2: ModuleID : | F2: =IF(LogicCommon!C2="","",LogicCommon!C2) -> MS | G2: LogicID : | H2: =IF(LogicCommon!E2="","",LogicCommon!E2) -> MSBEL5530 | I2: Ope.ID : | J2: ShipInst_Del01 | K2: Pj.ID : | L2: =IF(LogicCommon!G2="","",LogicCommon!G2) -> MC | M2: Ope.Body : | N2: "mcframe.serverMAUD.MAUDL5010.MAUDL_Operation"
A3: * | D3: =IF(LogicCommon!A3="","",LogicCommon!A3) | E3: SubModuleID : | F3: =IF(LogicCommon!C3="","",LogicCommon!C3) -> MSBE | G3: LogicClass : | H3: =IF(LogicCommon!E3="","",LogicCommon!E3) -> MSBEL_ShipInstService | I3: Ope.Method : | J3: @ | K3: SuperClassPj.ID : | L3: =IF(LogicCommon!G3="","",LogicCommon!G3) | O3: Gene.Type : | P3: ALL
A4: * | E4: Version : | F4: 000000 | G4: LogicName : | H4: =IF(LogicCommon!E4="","",LogicCommon!E4) -> 出荷指図サービス | I4: Ope.Name : | J4: 出荷指図削除 | K4: SuperLogicID : | L4: =IF(LogicCommon!G4="","",LogicCommon!G4) -> MS.MSUDL5010 | M4: ImplOpe.ID:
A5: * | E5: ACType :
A6: * | D6: 概要 : | E6: 出荷指図NOの単位で出荷指図を取消する。 | M6: ID | O6: ID | Q6: ID
A7: # | I7: U | K7: K | L7: o | N7: o | P7: o
A8: # | D8: ブロック名 Block Name | E8: 型 Type | G8: super/share | H8: 対象ブロック名 Target Block Name | L8: TargetName | N8: TargetName | P8: TargetName | T8: ブロック備考 Block Remarks
A9: # | D9: 項目名 Field Name | E9: 型 Type | F9: 桁 Digits | G9: フルネーム Full Name | H9: 日本語名 Japanese Name | I9: 上り項目 Request Message Field | J9: 下り項目 Response Message Field | R9: 条件および編集方法 Conditions and Editing Methods | T9: 項目備考 Field Remarks
A10: # | L10: 上り項目 Request Message Field | M10: 下り項目 Response Message Field | N10: 上り項目 Request Message Field | O10: 下り項目 Response Message Field | P10: 上り項目 Request Message Field | Q10: 下り項目 Response Message Field
A11: 10 | B11: * | D11: ShipInst_Del01_Hdr | E11: L | G11: $share$ | H11: MS.MSBEL5530.ShipInst_Chk03.ShipInst_Chk03_Hdr
A12: 10 | D12: err_flg | E12: #MA.FLG | G12: Error flg. | H12: エラーＦＬＧ | I12: - | J12: -
A13: 10 | D13: data_crud_typ | E13: #MA.DATA_CRUD_TYP | G13: Data update type | H13: データ更新区分 | I13: E | J13: E
A14: 10 | D14: ship_inst_no | E14: #MA.SHIP_INST_NO | G14: Shipping order No. | H14: 出荷指図ＮＯ | I14: E | J14: E
A15: 10 | D15: dlv_prnt_flg | E15: #MA.FLG | G15: Delivery note immediate issue flg. | H15: 納品書即時発行ＦＬＧ | I15: E | J15: E
A16: 10 | D16: is_src_shipinst_list_flg | E16: #MA.FLG | G16: Caller shipping order list | H16: 呼出元出荷指図一覧 | I16: E | J16: -
A18: 20 | B18: * | D18: ShipInst_Del01_Dtl | E18: L | G18: $share$ | H18: MS.MSBEL5530.ShipInst_Chk03.ShipInst_Chk03_Dtl
A19: 20 | D19: ship_inst_no | E19: #MA.SHIP_INST_NO | G19: Shipping order No. | H19: 出荷指図ＮＯ | I19: E | J19: -
A20: 20 | D20: ship_alloc_sts_no | E20: #MA.SHIP_ALLOC_STS_NO | G20: Shipping allocation status No. | H20: 出荷引当状況ＮＯ | I20: E | J20: -
A21: 20 | D21: wms_flg | E21: #MA.FLG | G21: WMS | H21: ＷＭＳ | I21: E | J21: -
A23: 30 | B23: * | D23: ShipInst_Del01_Cnd | E23: R
A24: 30 | D24: bndl_prnt_flg | E24: #MA.FLG | G24: Multiple issue | H24: まとめ発行 | I24: E | J24: -

Sheet ShipInst_RevUpd01
A1: * | B1: * | D1: L | E1: 1
A2: * | D2: オペレーション実装仕様書 Operation Specification Implementation Sheet | E2: ModuleID : | F2: =IF(LogicCommon!C2="","",LogicCommon!C2) -> MS | G2: LogicID : | H2: =IF(LogicCommon!E2="","",LogicCommon!E2) -> MSBEL5530 | I2: Ope.ID : | J2: ShipInst_RevUpd01 | K2: Pj.ID : | L2: =IF(LogicCommon!G2="","",LogicCommon!G2) -> MC | M2: Ope.Body : | N2: "mcframe.serverMAUD.MAUDL5010.MAUDL_Operation"
A3: * | D3: =IF(LogicCommon!A3="","",LogicCommon!A3) | E3: SubModuleID : | F3: =IF(LogicCommon!C3="","",LogicCommon!C3) -> MSBE | G3: LogicClass : | H3: =IF(LogicCommon!E3="","",LogicCommon!E3) -> MSBEL_ShipInstService | I3: Ope.Method : | J3: @ | K3: SuperClassPj.ID : | L3: =IF(LogicCommon!G3="","",LogicCommon!G3) | O3: Gene.Type : | P3: ALL
A4: * | E4: Version : | F4: 000000 | G4: LogicName : | H4: =IF(LogicCommon!E4="","",LogicCommon!E4) -> 出荷指図サービス | I4: Ope.Name : | J4: 出荷指図改訂履歴更新 | K4: SuperLogicID : | L4: =IF(LogicCommon!G4="","",LogicCommon!G4) -> MS.MSUDL5010 | M4: ImplOpe.ID: | N4: MA.MAUCL5020.RevData_Upd01
A5: * | E5: ACType :
A6: * | D6: 概要 : | E6: 出荷指図改訂履歴テーブルを更新する。改訂履歴データ更新用の共通処理（MAUCL5020）から呼び出される。 | M6: ID | O6: ID | Q6: ID
A7: # | I7: U | K7: K | L7: o | N7: o | P7: o
A8: # | D8: ブロック名 Block Name | E8: 型 Type | G8: super/share | H8: 対象ブロック名 Target Block Name | L8: TargetName | N8: TargetName | P8: TargetName | T8: ブロック備考 Block Remarks
A9: # | D9: 項目名 Field Name | E9: 型 Type | F9: 桁 Digits | G9: フルネーム Full Name | H9: 日本語名 Japanese Name | I9: 上り項目 Request Message Field | J9: 下り項目 Response Message Field | R9: 条件および編集方法 Conditions and Editing Methods | T9: 項目備考 Field Remarks
A10: # | L10: 上り項目 Request Message Field | M10: 下り項目 Response Message Field | N10: 上り項目 Request Message Field | O10: 下り項目 Response Message Field | P10: 上り項目 Request Message Field | Q10: 下り項目 Response Message Field
A11: 10 | B11: * | D11: ShipInst_RevUpd01_Dtl | E11: L | G11: $share$ | H11: MA.MAUCL5020.RevData_Upd01.RevData_Upd01_Dtl
A12: 10 | D12: rev_data_src_no | E12: #MA.SRC_NO | G12: Revision history data source No. | H12: 改訂履歴データ作成元ＮＯ | I12: E | J12: -
A13: 10 | D13: rev_no | E13: #MA.SLIP_REV | G13: Rev. number | H13: 改訂番号 | I13: E | J13: -

Sheet 来歴
A1: 変更来歴
A3: Rev. | H3: 修正番号 | O3: 変更内容 | AQ3: 変更箇所
A4: 1 | O4: 初版
A5: 1.1 | O5: 英語の名称を追記 | AQ5: 全般
