Workbook

Sheet LogicCommon
A2: オペレーション実装仕様書 | B2: ModuleID : | C2: MS | D2: LogicID : | E2: MSBEL1420 | F2: Pj.ID : | G2: MC
B3: SubModuleID : | C3: MSBE | D3: LogicClass : | E3: MSBEL_ShipSchdReg | F3: SuperClassPj.ID :
D4: LogicName : | E4: 出荷予定変更登録 | F4: SuperLogicID : | G4: MS.MSUDL5010
A5: 概要 :
A6: 詳細 :

Sheet Srch01
A1: * | B1: * | D1: L | E1: 1
A2: * | D2: オペレーション実装仕様書 Operation Specification Implementation Sheet | E2: ModuleID : | F2: =IF(LogicCommon!C2="","",LogicCommon!C2) -> MS | G2: LogicID : | H2: =IF(LogicCommon!E2="","",LogicCommon!E2) -> MSBEL1420 | I2: Ope.ID : | J2: Srch01 | K2: Pj.ID : | L2: =IF(LogicCommon!G2="","",LogicCommon!G2) -> MC | M2: Ope.Body : | N2: "mcframe.serverMAUD.MAUDL5010.MAUDL_Searcher"
A3: * | D3: =IF(LogicCommon!A3="","",LogicCommon!A3) | E3: SubModuleID : | F3: =IF(LogicCommon!C3="","",LogicCommon!C3) -> MSBE | G3: LogicClass : | H3: =IF(LogicCommon!E3="","",LogicCommon!E3) -> MSBEL_ShipSchdReg | I3: Ope.Method : | J3: Srch01 | K3: SuperClassPj.ID : | L3: =IF(LogicCommon!G3="","",LogicCommon!G3) | O3: Gene.Type : | P3: ALL
A4: * | E4: Version : | F4: 000000 | G4: LogicName : | H4: =IF(LogicCommon!E4="","",LogicCommon!E4) -> 出荷予定変更登録 | I4: Ope.Name : | J4: 検索 | K4: SuperLogicID : | L4: =IF(LogicCommon!G4="","",LogicCommon!G4) -> MS.MSUDL5010 | M4: ImplOpe.ID:
A5: * | E5: ACType :
A6: * | D6: 概要 : | E6: 出荷予定を検索する。 | M6: ID | O6: ID | Q6: ID
A7: # | I7: U | K7: K | L7: o | N7: o | P7: o
A8: # | D8: ブロック名 Block Name | E8: 型 Type | G8: super/share | H8: 対象ブロック名 Target Block Name | K8: CONST | L8: TargetName | N8: TargetName | P8: TargetName | T8: ブロック備考 Block Remarks
A9: # | D9: 項目名 Field Name | E9: 型 Type | F9: 桁 Digits | G9: フルネーム Full Name | H9: 日本語名 Japanese Name | I9: 上り項目 Request Message Field | J9: 下り項目 Response Message Field | R9: 条件および編集方法 Conditions and Editing Methods | T9: 項目備考 Field Remarks
A10: # | L10: 上り項目 Request Message Field | M10: 下り項目 Response Message Field | N10: 上り項目 Request Message Field | O10: 下り項目 Response Message Field | P10: 上り項目 Request Message Field | Q10: 下り項目 Response Message Field
A11: 10 | B11: * | D11: Srch01_Cnd | E11: R
A12: 10 | D12: ope | E12: C | G12: Operation type | H12: 操作種別 | I12: E | J12: -
A13: 10 | D13: srch_mode | E13: C | G13: Search mode | H13: 検索モード | I13: E | J13: -
A14: 10 | D14: no_lot_chk_flg | E14: #MA.FLG | G14: Ignore lot check | H14: ロットチェック無視 | I14: - | J14: -
A15: 10 | D15: not_inst_flg | E15: #MA.FLG | G15: Unordered (Shipping progress status) | H15: 未指図（出荷進捗状況） | I15: E | J15: -
A16: 10 | D16: inst_flg | E16: #MA.FLG | G16: Ordered (Shipping progress status) | H16: 指図済（出荷進捗状況） | I16: E | J16: -
A17: 10 | D17: not_ship_flg | E17: #MA.FLG | G17: Not shipped (Shipping progress status) | H17: 未出荷（出荷進捗状況） | I17: E | J17: -
A18: 10 | D18: part_ship_flg | E18: #MA.FLG | G18: Partial shipment (Shipping progress status) | H18: 一部出荷（出荷進捗状況） | I18: E | J18: -
A19: 10 | D19: ship_flg | E19: #MA.FLG | G19: Shipped (Shipping progress status) | H19: 出荷済（出荷進捗状況） | I19: E | J19: -
A20: 10 | D20: not_alloc_flg | E20: #MA.FLG | G20: Unallocated (Allocation status) | H20: 未引当（引当状況） | I20: E | J20: -
A21: 10 | D21: part_alloc_flg | E21: #MA.FLG | G21: Partial allocation (Allocation status) | H21: 一部引当（引当状況） | I21: E | J21: -
A22: 10 | D22: all_alloc_flg | E22: #MA.FLG | G22: 100% allocation (Allocation status) | H22: 全数引当（引当状況） | I22: E | J22: -
A23: 10 | D23: alloc_invalid_flg | E23: #MA.FLG | G23: Exclude (Allocation status) | H23: 対象外（引当状況） | I23: E | J23: -
... A187: 10 | D187: itm_grp_nm10 | E187: #MA.ITM_GRP_NM | G187: Item classification name 10 | H187: 品目分類名１０ | I187: E | J187: -
A189: 20 | B189: * | D189: Srch01_Rslt | E189: L
A190: 20 | D190: pr_sts_typ | E190: #MS.PR_STS_TYP | G190: Progress status type | H190: 進捗状況区分 | I190: - | J190: E | K190: MSC_PR_STS_TYP
A191: 20 | D191: pr_sts_typ_nm | E191: #MS.PR_STS_TYP_NM | G191: Progress status type name | H191: 進捗状況区分名 | I191: - | J191: E
A192: 20 | D192: alloc_sts_typ | E192: #MS.ALLOC_STS_TYP | G192: Allocation status type | H192: 引当状況区分 | I192: - | J192: E | K192: MSC_ALLOC_STS_TYP
A193: 20 | D193: alloc_sts_typ_nm | E193: #MS.ALLOC_STS_TYP_NM | G193: Allocation status type name | H193: 引当状況区分名 | I193: - | J193: E
A194: 20 | D194: ship_abl_flg | E194: #MA.FLG | G194: Shipping available | H194: 出荷可能 | I194: - | J194: E
A195: 20 | D195: fix_flg | E195: #MA.FLG | G195: Firm | H195: 確定 | I195: - | J195: E
A196: 20 | D196: org_fix_flg | E196: #MA.FLG | G196: Source firm | H196: 元確定 | I196: - | J196: E
A197: 20 | D197: dlv_rqst_dt | E197: #MA.DT | G197: Desired delivery date | H197: 納入希望日 | I197: - | J197: E
A198: 20 | D198: dlv_rqst_hm | E198: #MA.HM | G198: Desired delivery time | H198: 納入希望時刻 | I198: - | J198: E
A199: 20 | D199: pd_inst_dlv_dt | E199: #MA.DT | G199: Delivery request date | H199: 納品依頼日 | I199: - | J199: E
A200: 20 | D200: pd_inst_dlv_hm | E200: #MA.HM | G200: Delivery request time | H200: 納品依頼時刻 | I200: - | J200: E
A201: 20 | D201: dlv_day_week_typ | E201: #MA.DAY_WEEK_TYP | G201: Arrival day type (Week) | H201: 着曜日区分 | I201: - | J201: E | K201: MAC_DAY_WEEK_TYP
A202: 20 | D202: dlv_day_week_typ_nm | E202: #MA.DAY_WEEK_TYP_NM | G202: Arrival day of week | H202: 着曜日 | I202: - | J202: E
A203: 20 | D203: ship_rqst_dt | E203: #MA.DT | G203: Desired shipping date | H203: 出荷希望日 | I203: - | J203: E
A204: 20 | D204: ship_rqst_hm | E204: #MA.HM | G204: Desired shipping time | H204: 出荷希望時刻 | I204: - | J204: E
...

Sheet Chk01
A1: * | B1: * | D1: L | E1: 1
A2: * | D2: オペレーション実装仕様書 Operation Specification Implementation Sheet | E2: ModuleID : | F2: =IF(LogicCommon!C2="","",LogicCommon!C2) -> MS | G2: LogicID : | H2: =IF(LogicCommon!E2="","",LogicCommon!E2) -> MSBEL1420 | I2: Ope.ID : | J2: Chk01 | K2: Pj.ID : | L2: =IF(LogicCommon!G2="","",LogicCommon!G2) -> MC | M2: Ope.Body : | N2: MA.MAUDL5010.Checker
A3: * | D3: =IF(LogicCommon!A3="","",LogicCommon!A3) | E3: SubModuleID : | F3: =IF(LogicCommon!C3="","",LogicCommon!C3) -> MSBE | G3: LogicClass : | H3: =IF(LogicCommon!E3="","",LogicCommon!E3) -> MSBEL_ShipSchdReg | I3: Ope.Method : | J3: Chk01 | K3: SuperClassPj.ID : | L3: =IF(LogicCommon!G3="","",LogicCommon!G3) | O3: Gene.Type : | P3: ALL
A4: * | E4: Version : | F4: 000000 | G4: LogicName : | H4: =IF(LogicCommon!E4="","",LogicCommon!E4) -> 出荷予定変更登録 | I4: Ope.Name : | J4: 訂正前チェック | K4: SuperLogicID : | L4: =IF(LogicCommon!G4="","",LogicCommon!G4) -> MS.MSUDL5010 | M4: ImplOpe.ID:
A5: * | E5: ACType :
A6: * | D6: 概要 : | E6: 出荷予定を訂正するために、チェックを行う | AD6: ID | AF6: ID | AH6: ID
A7: # | I7: U | K7: K | L7: K | M7: K | N7: K | O7: K | P7: K | Q7: K | R7: K | S7: K | T7: K | U7: K | V7: K | W7: K | X7: K | Y7: K | Z7: K | AA7: K | AB7: K | AC7: o | AE7: o | AG7: o
A8: # | D8: ブロック名 Block Name | E8: 型 Type | G8: super/share | H8: 対象ブロック名 Target Block Name | K8: REQ_UPD_CNT_CHK | L8: REQUIRED | M8: CHK_NUM | N8: SMALL_LARGE | O8: CHK_DT | P8: BEFORE_AFTER | Q8: CHK_PTN | R8: DUPLICATE | S8: TOO_MANY_INPUTS | T8: AT_LEAST_ONE | U8: ONLY_ONE_INPUT | V8: LIST_LOGIC | W8: LIST_OUT | X8: LIST_OUT_BASE | Y8: LIST_IN | Z8: LIST_IN_BASE | AA8: CONST | AB8: NULL_VAL | AE8: TargetName | AG8: TargetName | AK8: ブロック備考 Block Remarks
A9: # | D9: 項目名 Field Name | E9: 型 Type | F9: 桁 Digits | G9: フルネーム Full Name | H9: 日本語名 Japanese Name | I9: 上り項目 Request Message Field | J9: 下り項目 Response Message Field | AI9: 条件および編集方法 Conditions and Editing Methods | AK9: 項目備考 Field Remarks
A10: # | AC10: 上り項目 Request Message Field | AD10: 下り項目 Response Message Field | AE10: 上り項目 Request Message Field | AF10: 下り項目 Response Message Field | AG10: 上り項目 Request Message Field | AH10: 下り項目 Response Message Field
A11: 10 | B11: * | D11: Chk01_Rslt | E11: L
A12: 10 | D12: peg_no | E12: #MA.INT | G12: Pegging No. | H12: 紐付けＮＯ | I12: E | J12: E
A13: 10 | D13: err_flg | E13: #MA.FLG | G13: Error | H13: エラー | I13: - | J13: E
A14: 10 | D14: alloc_sts_typ | E14: #MS.ALLOC_STS_TYP | G14: Allocation status type | H14: 引当状況区分 | I14: - | J14: - | AA14: MSC_ALLOC_STS_TYP
A15: 10 | D15: alloc_sts_typ_nm | E15: #MS.ALLOC_STS_TYP_NM | G15: Allocation status type name | H15: 引当状況区分名 | I15: - | J15: -
A16: 10 | D16: ship_schd_tm | E16: #MA.TM | G16: Scheduled shipping date and time | H16: 出荷予定日時 | I16: E | J16: E | P16: schd_tm:BF
A17: 10 | D17: ship_schd_time | E17: #MA.CHAR_HM | G17: Shipping schedule time | H17: 出荷予定時間 | I17: - | J17: -
A18: 10 | D18: dlv_schd_tm | E18: #MA.TM | G18: Scheduled delivery date and time | H18: 納品予定日時 | I18: E | J18: E | P18: schd_tm:AF
A19: 10 | D19: no_calc_flg | E19: #MA.FLG | G19: Not auto-calculate | H19: 自動計算しない | I19: E | J19: E
A20: 10 | D20: ship_block_flg | E20: #MA.FLG | G20: Pending shipping | H20: 出荷留め | I20: E | J20: E
A21: 10 | D21: cl_time_chk_flg | E21: #MA.FLG | G21: Closing time check | H21: 締時間チェック | I21: E | J21: E
A22: 10 | D22: ship_dt_chk_flg | E22: #MA.FLG | G22: Shipping date check | H22: 出荷日チェック | I22: E | J22: E
A23: 10 | D23: ship_term_cd | E23: #MA.SHIP_TERM_CD | G23: Shipping conditions cd. | H23: 出荷条件ＣＤ | I23: E | J23: E | V23: MA.MAUAL0010.ShipTerm | W23: ship_wk_grp_cd | X23: ship_wk_grp_cd | Y23: ship_fr_lg_grp_cd;ship_to_lg_grp_cd | Z23: fr_lg_grp_cd;to_lg_grp_cd
A24: 10 | D24: ship_wk_grp_cd | E24: #MA.SHIP_WK_GRP_CD | G24: Shipping operation group cd. | H24: 出荷作業グループＣＤ | I24: - | J24: -
A25: 10 | D25: ship_wk_cd | E25: #MA.SHIP_WK_CD | G25: Shipping operation cd. | H25: 出荷作業ＣＤ | I25: E | J25: E | V25: MA.MAUAL0010.ShipWk
A26: 10 | D26: itm_cd | E26: #MA.ITM_CD | G26: Item cd. | H26: 品目ＣＤ | I26: - | J26: -
A27: 10 | D27: itm_sub1 | E27: #MA.ITM_SUB1 | G27: Branch No. 1 | H27: 枝番１ | I27: - | J27: -
A28: 10 | D28: itm_sub2 | E28: #MA.ITM_SUB2 | G28: Branch No. 2 | H28: 枝番２ | I28: - | J28: -
A29: 10 | D29: itm_sub3 | E29: #MA.ITM_SUB3 | G29: Branch No. 3 | H29: 枝番３ | I29: - | J29: -
A30: 10 | D30: alloc_sno1 | E30: #MA.SNO1 | G30: Allocation SEIBAN No. 1 | H30: 引当手配ＮＯ１ | I30: E | J30: E
A31: 10 | D31: alloc_sno2 | E31: #MA.SNO2 | G31: Allocation SEIBAN No. 2 | H31: 引当手配ＮＯ２ | I31: E | J31: E
A32: 10 | D32: alloc_sno3 | E32: #MA.SNO3 | G32: Allocation SEIBAN No. 3 | H32: 引当手配ＮＯ３ | I32: E | J32: E
A33: 10 | D33: alloc_sno4 | E33: #MA.SNO4 | G33: Allocation SEIBAN No. 4 | H33: 引当手配ＮＯ４ | I33: E | J33: E
A34: 10 | D34: abort_flg | E34: #MA.FLG | G34: Cancel remaining | H34: 打切 | I34: E | J34: E
A35: 10 | D35: trd_unit_cd | E35: #MA.UNIT_CD | G35: Transaction unit cd. | H35: 取引単位ＣＤ | I35: - | J35: -
A36: 10 | D36: trd_unit_nm | E36: #MA.UNIT_NM | G36: Transaction unit name | H36: 取引単位名 | I36: - | J36: -
A37: 10 | D37: trd_unit_dec_place | E37: #MA.DEC_PLACE | G37: Number of decimal places | H37: 小数部有効桁数 | I37: - | J37: -
... A39: 10 | D39: trd_unit_conv_qty | E39: #MA.QTY | G39: Transaction unit conversion qty. | H39: 取引単位換算数量 | I39: - | J39: -
A40: 10 | D40: trd_unit_qty | E40: #MA.QTY | G40: Quantity | H40: 数量 | I40: E | J40: E | L40: E | M40: positive
A41: 10 | D41: alloc_ent_unit_cd | E41: #MA.UNIT_CD | G41: Unit cd. (Allocation) | H41: 単位ＣＤ（引当） | I41: E | J41: E | V41: MA.MAUAL0010.ItmUnit | W41: alloc_ent_unit_nm;alloc_ent_unit_conv_base_qty;alloc_ent_unit_conv_qty;alloc_ent_unit_dec_place | X41: unit_nm;conv_base_qty;conv_qty;dec_place | Y41: itm_cd;itm_sub1;itm_sub2;itm_sub3 | Z41: itm_cd;itm_sub1;itm_sub2;itm_sub3
...

Sheet Srch02
A1: * | B1: * | D1: L | E1: 1
A2: * | D2: オペレーション実装仕様書 Operation Specification Implementation Sheet | E2: ModuleID : | F2: =IF(LogicCommon!C2="","",LogicCommon!C2) -> MS | G2: LogicID : | H2: =IF(LogicCommon!E2="","",LogicCommon!E2) -> MSBEL1420 | I2: Ope.ID : | J2: Srch02 | K2: Pj.ID : | L2: =IF(LogicCommon!G2="","",LogicCommon!G2) -> MC | M2: Ope.Body : | N2: "mcframe.serverMAUD.MAUDL5010.MAUDL_Searcher"
A3: * | D3: =IF(LogicCommon!A3="","",LogicCommon!A3) | E3: SubModuleID : | F3: =IF(LogicCommon!C3="","",LogicCommon!C3) -> MSBE | G3: LogicClass : | H3: =IF(LogicCommon!E3="","",LogicCommon!E3) -> MSBEL_ShipSchdReg | I3: Ope.Method : | J3: Srch02 | K3: SuperClassPj.ID : | L3: =IF(LogicCommon!G3="","",LogicCommon!G3) | O3: Gene.Type : | P3: ALL
A4: * | E4: Version : | F4: 000000 | G4: LogicName : | H4: =IF(LogicCommon!E4="","",LogicCommon!E4) -> 出荷予定変更登録 | I4: Ope.Name : | J4: ロット提案 | K4: SuperLogicID : | L4: =IF(LogicCommon!G4="","",LogicCommon!G4) -> MS.MSUDL5010 | M4: ImplOpe.ID:
A5: * | E5: ACType :
A6: * | D6: 概要 : | E6: ロット提案を実行する。 | M6: ID | O6: ID | Q6: ID
A7: # | I7: U | K7: K | L7: o | N7: o | P7: o
A8: # | D8: ブロック名 Block Name | E8: 型 Type | G8: super/share | H8: 対象ブロック名 Target Block Name | K8: CONST | L8: TargetName | N8: TargetName | P8: TargetName | T8: ブロック備考 Block Remarks
A9: # | D9: 項目名 Field Name | E9: 型 Type | F9: 桁 Digits | G9: フルネーム Full Name | H9: 日本語名 Japanese Name | I9: 上り項目 Request Message Field | J9: 下り項目 Response Message Field | R9: 条件および編集方法 Conditions and Editing Methods | T9: 項目備考 Field Remarks
A10: # | L10: 上り項目 Request Message Field | M10: 下り項目 Response Message Field | N10: 上り項目 Request Message Field | O10: 下り項目 Response Message Field | P10: 上り項目 Request Message Field | Q10: 下り項目 Response Message Field
A11: 10 | B11: * | D11: Srch02_Rslt | E11: L | G11: $share$ | H11: MS.MSBEL1420.Chk01.Chk01_Rslt
A12: 10 | D12: peg_no | E12: #MA.INT | G12: Pegging No. | H12: 紐付けＮＯ | I12: E | J12: E
A13: 10 | D13: ship_schd_tm | E13: #MA.TM | G13: Scheduled shipping date and time | H13: 出荷予定日時 | I13: E | J13: -
A14: 10 | D14: dlv_schd_tm | E14: #MA.TM | G14: Scheduled delivery date and time | H14: 納品予定日時 | I14: E | J14: -
A15: 10 | D15: ship_term_cd | E15: #MA.SHIP_TERM_CD | G15: Shipping conditions cd. | H15: 出荷条件ＣＤ | I15: E | J15: -
A16: 10 | D16: itm_cd | E16: #MA.ITM_CD | G16: Item cd. | H16: 品目ＣＤ | I16: E | J16: -
A17: 10 | D17: itm_sub1 | E17: #MA.ITM_SUB1 | G17: Branch No. 1 | H17: 枝番１ | I17: E | J17: -
A18: 10 | D18: itm_sub2 | E18: #MA.ITM_SUB2 | G18: Branch No. 2 | H18: 枝番２ | I18: E | J18: -
A19: 10 | D19: itm_sub3 | E19: #MA.ITM_SUB3 | G19: Branch No. 3 | H19: 枝番３ | I19: E | J19: -
A20: 10 | D20: alloc_sno1 | E20: #MA.SNO1 | G20: Allocation SEIBAN No. 1 | H20: 引当手配ＮＯ１ | I20: E | J20: E
A21: 10 | D21: alloc_sno2 | E21: #MA.SNO2 | G21: Allocation SEIBAN No. 2 | H21: 引当手配ＮＯ２ | I21: E | J21: E
A22: 10 | D22: alloc_sno3 | E22: #MA.SNO3 | G22: Allocation SEIBAN No. 3 | H22: 引当手配ＮＯ３ | I22: E | J22: E
A23: 10 | D23: alloc_sno4 | E23: #MA.SNO4 | G23: Allocation SEIBAN No. 4 | H23: 引当手配ＮＯ４ | I23: E | J23: E
... A45: 10 | D45: ship_alloc_sts_no | E45: #MA.SHIP_ALLOC_STS_NO | G45: Shipping allocation status No. | H45: 出荷引当状況ＮＯ | I45: E | J45: -
A46: 10 | D46: org_ship_alloc_sts_no | E46: #MA.SHIP_ALLOC_STS_NO | I46: E | J46: -
A47: 10 | D47: alloc_scope_typ | E47: #MA.ALLOC_SCOPE_TYP | G47: Allocation range type | H47: 引当範囲区分 | I47: E | J47: -
A48: 10 | D48: loc_cd | E48: #MA.LOC_CD | G48: Location cd. | H48: 場所ＣＤ | I48: E | J48: E
A49: 10 | D49: loc_nm | E49: #MA.LOC_NM | G49: Location name | H49: 場所名 | I49: E | J49: E
A50: 10 | D50: str_ln_tgt_flg | E50: #MA.FLG | G50: For rack/line | H50: 棚・ライン対象 | I50: E | J50: E
A51: 10 | D51: str_ln_cd | E51: #MA.STR_LN_CD | G51: Rack/Line cd. | H51: 棚・ラインＣＤ | I51: E | J51: E
A52: 10 | D52: str_ln_nm | E52: #MA.STR_LN_NM | G52: Rack/Line name | H52: 棚・ライン名 | I52: E | J52: E
A53: 10 | D53: str_ln_cd_none_flg | E53: #MA.FLG | G53: Without rack/line | H53: 棚・ライン無 | I53: E | J53: E
A54: 10 | D54: lot_no | E54: #MA.LOT_NO | G54: Lot No. | H54: ロットＮＯ | I54: E | J54: E
A55: 10 | D55: sublot_no | E55: #MA.SUBLOT_NO | G55: Sublot No. | H55: サブロットＮＯ | I55: E | J55: E
A56: 10 | D56: ver_no | E56: #MA.VER_NO | G56: Version No. | H56: 版ＮＯ | I56: E | J56: E
A57: 10 | D57: not_lot_mix_flg | E57: #MA.FLG | G57: Prohibit mixed lots | H57: ロット混在不可 | I57: E | J57: -
A58: 10 | D58: not_sublot_mix_flg | E58: #MA.FLG | G58: Prohibit mixed sublots | H58: サブロット混在不可 | I58: E | J58: -
... A62: 10 | D62: no_alloc_flg | E62: #MA.FLG | G62: Remaining allocation | H62: 引当残 | I62: - | J62: E
A64: 20 | B64: * | D64: Srch02_Cnd | E64: R | G64: $share$ | H64: MS.MSBEL1420.Srch01.Srch01_Cnd
A65: 20 | D65: no_lot_chk_flg | E65: #MA.FLG | G65: Ignore lot check | H65: ロットチェック無視 | I65: E | J65: -
...

Sheet Upd01
A1: * | B1: * | D1: L | E1: 1
A2: * | D2: オペレーション実装仕様書 Operation Specification Implementation Sheet | E2: ModuleID : | F2: =IF(LogicCommon!C2="","",LogicCommon!C2) -> MS | G2: LogicID : | H2: =IF(LogicCommon!E2="","",LogicCommon!E2) -> MSBEL1420 | I2: Ope.ID : | J2: Upd01 | K2: Pj.ID : | L2: =IF(LogicCommon!G2="","",LogicCommon!G2) -> MC | M2: Ope.Body : | N2: "mcframe.serverMAUD.MAUDL5010.MAUDL_Operation"
A3: * | D3: =IF(LogicCommon!A3="","",LogicCommon!A3) | E3: SubModuleID : | F3: =IF(LogicCommon!C3="","",LogicCommon!C3) -> MSBE | G3: LogicClass : | H3: =IF(LogicCommon!E3="","",LogicCommon!E3) -> MSBEL_ShipSchdReg | I3: Ope.Method : | J3: Upd01 | K3: SuperClassPj.ID : | L3: =IF(LogicCommon!G3="","",LogicCommon!G3) | O3: Gene.Type : | P3: ALL
A4: * | E4: Version : | F4: 000000 | G4: LogicName : | H4: =IF(LogicCommon!E4="","",LogicCommon!E4) -> 出荷予定変更登録 | I4: Ope.Name : | J4: 訂正 | K4: SuperLogicID : | L4: =IF(LogicCommon!G4="","",LogicCommon!G4) -> MS.MSUDL5010 | M4: ImplOpe.ID:
A5: * | E5: ACType :
A6: * | D6: 概要 : | E6: 出荷予定を更新する。 | M6: ID | O6: ID | Q6: ID
A7: # | I7: U | K7: K | L7: o | N7: o | P7: o
A8: # | D8: ブロック名 Block Name | E8: 型 Type | G8: super/share | H8: 対象ブロック名 Target Block Name | L8: TargetName | N8: TargetName | P8: TargetName | T8: ブロック備考 Block Remarks
A9: # | D9: 項目名 Field Name | E9: 型 Type | F9: 桁 Digits | G9: フルネーム Full Name | H9: 日本語名 Japanese Name | I9: 上り項目 Request Message Field | J9: 下り項目 Response Message Field | R9: 条件および編集方法 Conditions and Editing Methods | T9: 項目備考 Field Remarks
A10: # | L10: 上り項目 Request Message Field | M10: 下り項目 Response Message Field | N10: 上り項目 Request Message Field | O10: 下り項目 Response Message Field | P10: 上り項目 Request Message Field | Q10: 下り項目 Response Message Field
A11: 10 | B11: * | D11: Upd01_Rslt | E11: L | G11: $share$ | H11: MS.MSBEL1420.Chk01.Chk01_Rslt
A12: 10 | D12: peg_no | E12: #MA.INT | G12: Pegging No. | H12: 紐付けＮＯ | I12: - | J12: -
A13: 10 | D13: err_flg | E13: #MA.FLG | G13: Error | H13: エラー | I13: - | J13: -
A14: 10 | D14: alloc_sts_typ | E14: #MS.ALLOC_STS_TYP | G14: Allocation status type | H14: 引当状況区分 | I14: - | J14: E
A15: 10 | D15: alloc_sts_typ_nm | E15: #MS.ALLOC_STS_TYP_NM | G15: Allocation status type name | H15: 引当状況区分名 | I15: - | J15: E
A16: 10 | D16: ship_schd_tm | E16: #MA.TM | G16: Scheduled shipping date and time | H16: 出荷予定日時 | I16: E | J16: -
A17: 10 | D17: dlv_schd_tm | E17: #MA.TM | G17: Scheduled delivery date and time | H17: 納品予定日時 | I17: E | J17: -
A18: 10 | D18: no_calc_flg | E18: #MA.FLG | G18: Not auto-calculate | H18: 自動計算しない | I18: E | J18: -
A19: 10 | D19: ship_block_flg | E19: #MA.FLG | G19: Pending shipping | H19: 出荷留め | I19: E | J19: -
A20: 10 | D20: cl_time_chk_flg | E20: #MA.FLG | G20: Closing time check | H20: 締時間チェック | I20: E | J20: -
A21: 10 | D21: ship_dt_chk_flg | E21: #MA.FLG | G21: Shipping date check | H21: 出荷日チェック | I21: E | J21: -
A22: 10 | D22: ship_term_cd | E22: #MA.SHIP_TERM_CD | G22: Shipping conditions cd. | H22: 出荷条件ＣＤ | I22: E | J22: -
A23: 10 | D23: ship_wk_cd | E23: #MA.SHIP_WK_CD | G23: Shipping operation cd. | H23: 出荷作業ＣＤ | I23: E | J23: -
... A52: 10 | D52: ship_alloc_sts_no | E52: #MA.SHIP_ALLOC_STS_NO | G52: Shipping allocation status No. | H52: 出荷引当状況ＮＯ | I52: E | J52: -
A53: 10 | D53: org_ship_alloc_sts_no | E53: #MA.SHIP_ALLOC_STS_NO | I53: E | J53: -
A54: 10 | D54: ship_pr_no | E54: #MA.SHIP_PR_NO | G54: Shipping progress No. | H54: 出荷進捗ＮＯ | I54: E | J54: -
A55: 10 | D55: fix_ship_schd_dt | E55: #MA.DT | G55: Scheduled firm shipping date | H55: 確定出荷予定日 | I55: - | J55: E
A56: 10 | D56: fix_ship_schd_hm | E56: #MA.HM | G56: Firm shipping schedule time | H56: 確定出荷予定時刻 | I56: - | J56: E
A57: 10 | D57: fix_dlv_schd_dt | E57: #MA.DT | G57: Scheduled firm delivery date | H57: 確定納品予定日 | I57: - | J57: E
A58: 10 | D58: fix_dlv_schd_hm | E58: #MA.HM | G58: Firm schedule delivery time | H58: 確定納品予定時刻 | I58: - | J58: E
A59: 10 | D59: upd_cntr | E59: #MA.UPD_CNT | G59: Shipping schedule update counter | H59: 出荷予定更新カウンタ | I59: E | J59: -
A60: 10 | D60: ship_pr_upd_cntr | E60: #MA.UPD_CNT | G60: Shipping progress update counter | H60: 出荷進捗更新カウンタ | I60: E | J60: -
A61: 10 | D61: ship_fr_lg_grp_cd | E61: #MA.LG_GRP_CD | G61: Shipping point distribution group cd. | H61: 出荷元物流グループＣＤ | I61: E | J61: -
A62: 10 | D62: ship_to_lg_grp_cd | E62: #MA.LG_GRP_CD | G62: Receiving point distribution group cd. | H62: 出荷先物流グループＣＤ | I62: E | J62: -
A63: 10 | D63: alloc_grp_cd | E63: #MA.ALLOC_GRP_CD | G63: Gross allocation location group cd. | H63: 総量引当場所グループＣＤ | I63: E | J63: -
A64: 10 | D64: dlv_id_cd | E64: #MS.DLV_ID_CD | G64: Delivery destination cd. | H64: 納品先ＣＤ | I64: E | J64: -
A65: 10 | D65: cst_cd | E65: #MA.BP_CD | G65: Customer cd. | H65: 得意先ＣＤ | I65: E | J65: -
... A71: 10 | D71: fix_flg | E71: #MA.FLG | G71: Firm | H71: 確定 | I71: E | J71: -
A73: 20 | B73: * | D73: Upd01_Cnd | E73: R | G73: $share$ | H73: MS.MSBEL1420.Srch01.Srch01_Cnd
A74: 20 | D74: srch_mode | E74: C | G74: Search mode | H74: 検索モード | I74: E | J74: -
...

Sheet Sprt01
A1: * | B1: * | D1: L | E1: 1
A2: * | D2: オペレーション実装仕様書 Operation Specification Implementation Sheet | E2: ModuleID : | F2: =IF(LogicCommon!C2="","",LogicCommon!C2) -> MS | G2: LogicID : | H2: =IF(LogicCommon!E2="","",LogicCommon!E2) -> MSBEL1420 | I2: Ope.ID : | J2: Sprt01 | K2: Pj.ID : | L2: =IF(LogicCommon!G2="","",LogicCommon!G2) -> MC | M2: Ope.Body : | N2: "mcframe.serverMAUD.MAUDL5010.MAUDL_Operation"
A3: * | D3: =IF(LogicCommon!A3="","",LogicCommon!A3) | E3: SubModuleID : | F3: =IF(LogicCommon!C3="","",LogicCommon!C3) -> MSBE | G3: LogicClass : | H3: =IF(LogicCommon!E3="","",LogicCommon!E3) -> MSBEL_ShipSchdReg | I3: Ope.Method : | J3: Sprt01 | K3: SuperClassPj.ID : | L3: =IF(LogicCommon!G3="","",LogicCommon!G3) | O3: Gene.Type : | P3: ALL
A4: * | E4: Version : | F4: 000000 | G4: LogicName : | H4: =IF(LogicCommon!E4="","",LogicCommon!E4) -> 出荷予定変更登録 | I4: Ope.Name : | J4: 支給日取得 | K4: SuperLogicID : | L4: =IF(LogicCommon!G4="","",LogicCommon!G4) -> MS.MSUDL5010 | M4: ImplOpe.ID:
A5: * | E5: ACType :
A6: * | D6: 概要 : | E6: 支給元の支給計上日を取得する。 | M6: ID | O6: ID | Q6: ID
A7: # | I7: U | K7: K | L7: o | N7: o | P7: o
A8: # | D8: ブロック名 Block Name | E8: 型 Type | G8: super/share | H8: 対象ブロック名 Target Block Name | L8: TargetName | N8: TargetName | P8: TargetName | T8: ブロック備考 Block Remarks
A9: # | D9: 項目名 Field Name | E9: 型 Type | F9: 桁 Digits | G9: フルネーム Full Name | H9: 日本語名 Japanese Name | I9: 上り項目 Request Message Field | J9: 下り項目 Response Message Field | R9: 条件および編集方法 Conditions and Editing Methods | T9: 項目備考 Field Remarks
A10: # | L10: 上り項目 Request Message Field | M10: 下り項目 Response Message Field | N10: 上り項目 Request Message Field | O10: 下り項目 Response Message Field | P10: 上り項目 Request Message Field | Q10: 下り項目 Response Message Field
A11: 10 | B11: * | D11: Sprt01_Rslt | E11: L
A12: 10 | D12: trd_cd | E12: #MA.TRD_CD | G12: Transaction cd. | H12: 取引ＣＤ | I12: E | J12: -
A13: 10 | D13: trd_nm | E13: #MA.TRD_NM | G13: Transaction name | H13: 取引名 | I13: E
A14: 10 | D14: trd_ptn_typ | E14: #MA.TRD_PTN_TYP | G14: Transaction pattern type | H14: 取引パタン区分 | I14: E | J14: -
A15: 10 | D15: base_dlv_slip_no | E15: #MA.DLV_SLIP_NO | G15: Return-from delivery note No. | H15: 返品元納品書ＮＯ | I15: E | J15: E
A16: 10 | D16: base_prov_act_no | E16: #MA.PROV_ACT_NO | G16: Return-from supply result No. | H16: 返品元支給実績ＮＯ | I16: E | J16: E
A17: 10 | D17: base_ac_dt | E17: #MA.DT | G17: Supply recording date (Base) | H17: 支給計上日（基） | I17: E | J17: E
D18: 詳細 :

Sheet 来歴
A1: 変更来歴
A3: Rev. | H3: 修正番号 | O3: 変更内容 | AQ3: 変更箇所
A4: 1 | O4: 初版
A5: 1.1 | H5: MS7031#404 | O5: Chk01_Rsltブロックに以下の項目を追加 not_lot_mix_flg、not_sublot_mix_flg、slo_d_no | AQ5: Chk01
A6: 〃 | H6: 〃 | O6: Srch02_Rsltブロックに以下の項目を追加 not_lot_mix_flg、not_sublot_mix_flg | AQ6: Srch02
A7: 〃 | H7: 〃 | O7: Upd01_Rsltブロックに以下の項目を追加 not_lot_mix_flg、not_sublot_mix_flg | AQ7: Upd01
A8: 1.2 | H8: MS7032#171 | O8: Srch01_Cndブロックに「via_dlv_typ」を追加 Srch01_Rsltブロックの「via_dlv_typ」の「CONST」を変更 Srch01_Rsltブロックに「via_dlv_typ_nm」を追加 | AQ8: Srch01
A9: 1.3 | H9: MS7032#285 | O9: Upd01_Rsltブロックに「dlv_schd_tm」を追加 | AQ9: Upd01
A10: 〃 | H10: 〃 | O10: Chk01_Rsltブロックの「dlv_schd_tm」を上り電文に追加 Chk01_Rsltブロックの「ship_schd_tm」の「BEFORE_AFTER」に「schd_tm:BF」を設定 Chk01_Rsltブロックの「dlv_schd_tm」の「BEFORE_AFTER」に「schd_tm:AF」を設定 | AQ10: Chk01
A11: 1.4 | O11: 英語の名称を追記 | AQ11: 全般
