Workbook

Sheet LogicCommon
A2: ロジック共通定義 | B2: ModuleID : | C2: MS | D2: LogicID : | E2: MSBEL2410 | F2: Pj.ID : | G2: MC
B3: SubModuleID : | C3: MSBE | D3: LogicClass : | E3: MSBEL_AcXfrInstReg | F3: SuperClassPj.ID :
D4: LogicName : | E4: 他勘定振替指図登録 | F4: SuperLogicID : | G4: MS.MSUDL5010
A5: 概要 :
A6: 詳細 :

Sheet Srch01
A1: * | B1: * | D1: L | E1: 1
A2: * | D2: オペレーション実装仕様書 Operation Specification Implementation Sheet | E2: ModuleID : | F2: =IF(LogicCommon!C2="","",LogicCommon!C2) -> MS | G2: LogicID : | H2: =IF(LogicCommon!E2="","",LogicCommon!E2) -> MSBEL2410 | I2: Ope.ID : | J2: Srch01 | K2: Pj.ID : | L2: =IF(LogicCommon!G2="","",LogicCommon!G2) -> MC | M2: Ope.Body : | N2: "mcframe.serverMAUD.MAUDL5010.MAUDL_Searcher"
A3: * | E3: SubModuleID : | F3: =IF(LogicCommon!C3="","",LogicCommon!C3) -> MSBE | G3: LogicClass : | H3: =IF(LogicCommon!E3="","",LogicCommon!E3) -> MSBEL_AcXfrInstReg | I3: Ope.Method : | J3: Srch01 | K3: SuperClassPj.ID : | L3: =IF(LogicCommon!G3="","",LogicCommon!G3) | O3: Gene.Type : | P3: ALL
A4: * | E4: Version : | F4: 000000 | G4: LogicName : | H4: =IF(LogicCommon!E4="","",LogicCommon!E4) -> 他勘定振替指図登録 | I4: Ope.Name : | J4: 検索 | K4: SuperLogicID : | L4: =IF(LogicCommon!G4="","",LogicCommon!G4) -> MS.MSUDL5010 | M4: ImplOpe.ID:
A5: * | E5: ACType :
A6: * | D6: 概要 : | E6: 他勘定振替指図を検索する。 | M6: ID | O6: ID
A7: # | I7: U | K7: K | L7: o | N7: o
A8: # | D8: ブロック名 Block Name | E8: 型 Type | G8: super/share | H8: 対象ブロック名 Target Block Name | K8: CONST | L8: TargetName | N8: TargetName | R8: ブロック備考 Block Remarks
A9: # | D9: 項目名 Field Name | E9: 型 Type | F9: 桁 Digits | G9: フルネーム Full Name | H9: 日本語名 Japanese Name | I9: 上り項目 Request Message Field | J9: 下り項目 Response Message Field | P9: 条件および編集方法 Conditions and Editing Methods | R9: 項目備考 Field Remarks
A10: # | L10: 上り項目 Request Message Field | M10: 下り項目 Response Message Field | N10: 上り項目 Request Message Field | O10: 下り項目 Response Message Field
A11: 10 | B11: * | D11: Srch01_Cnd | E11: R
A12: 10 | D12: screen_ope | E12: C | G12: Operation type | H12: 操作種別 | I12: E | J12: -
A13: 10 | D13: acxfr_inst_no | E13: #MA.ACXFR_INST_NO | G13: Other accounting transfer order No. | H13: 他勘定振替指図ＮＯ | I13: E | J13: -
L14: 上り項目 Request Message Field | M14: 下り項目 Response Message Field | N14: 上り項目 Request Message Field | O14: 下り項目 Response Message Field
A15: 20 | B15: * | D15: Srch01_Hdr | E15: R
A16: 20 | D16: acxfr_inst_no | E16: #MA.ACXFR_INST_NO | G16: Other accounting transfer order No. | H16: 他勘定振替指図ＮＯ | I16: - | J16: E
A17: 20 | D17: trd_cd | E17: #MA.TRD_CD | G17: Transaction cd. | H17: 取引ＣＤ | I17: - | J17: E
A18: 20 | D18: trd_nm | E18: #MA.TRD_NM | G18: Transaction name | H18: 取引名 | I18: - | J18: E
A19: 20 | D19: loc_cd | E19: #MA.LOC_CD | G19: Location cd. | H19: 場所ＣＤ | I19: - | J19: E
A20: 20 | D20: loc_nm | E20: #MA.LOC_NM | G20: Location name | H20: 場所名 | I20: - | J20: E
A21: 20 | D21: sppl_cd | E21: #MA.BP_CD | G21: Supplier cd. | H21: 発注先ＣＤ | I21: - | J21: E
A22: 20 | D22: str_ln_tgt_flg | E22: #MA.FLG | G22: For rack/line | H22: 棚・ライン対象 | I22: - | J22: E
A23: 20 | D23: wg_cd | E23: #MA.WG_CD | G23: WG cd. | H23: ワーキンググループＣＤ | I23: - | J23: E
A24: 20 | D24: wg_nm | E24: #MA.WG_NM | G24: WG name | H24: ワーキンググループ名 | I24: - | J24: E
A25: 20 | D25: acxfr_inst_dt | E25: #MA.DT | G25: Other accounting transfer order date | H25: 他勘定振替指図日 | I25: - | J25: E
A26: 20 | D26: inst_usr_cd | E26: #MA.USR_CD | G26: Implementation PIC cd. | H26: 実施担当者ＣＤ | I26: - | J26: E
A27: 20 | D27: inst_usr_nm | E27: #MA.USR_NM | G27: Implementation PC name | H27: 実施担当者名 | I27: - | J27: E
... A48: 20 | D48: upd_srv_req_no | E48: #MA.SRV_REQ_NO | G48: Update request No. | H48: 更新リクエストＮＯ | I48: - | J48: E
A50: 30 | B50: * | D50: Srch01_Dtl | E50: L
A51: 30 | D51: abort_flg | E51: #MA.FLG | G51: Cancel remaining | H51: 打切 | I51: - | J51: E
A52: 30 | D52: pr_sts_typ | E52: #MS.PR_STS_TYP | G52: Progress status type | H52: 進捗状況区分 | I52: - | J52: E | K52: MSC_PR_STS_TYP
A53: 30 | D53: pr_sts_typ_nm | E53: #MS.PR_STS_TYP_NM | G53: Progress status type name | H53: 進捗状況区分名 | I53: - | J53: E
A54: 30 | D54: itm_cd | E54: #MA.ITM_CD | G54: Item cd. | H54: 品目ＣＤ | I54: - | J54: E
A55: 30 | D55: itm_sub1 | E55: #MA.ITM_SUB1 | G55: Branch No. 1 | H55: 枝番１ | I55: - | J55: E
A56: 30 | D56: itm_sub2 | E56: #MA.ITM_SUB2 | G56: Branch No. 2 | H56: 枝番２ | I56: - | J56: E
A57: 30 | D57: itm_sub3 | E57: #MA.ITM_SUB3 | G57: Branch No. 3 | H57: 枝番３ | I57: - | J57: E
A58: 30 | D58: itm_nm | E58: #MA.ITM_NM | G58: Item name | H58: 品名 | I58: - | J58: E
A59: 30 | D59: sundry_itm_flg | E59: #MA.FLG | G59: Miscellaneous item | H59: 諸口品 | I59: - | J59: E
A60: 30 | D60: lot_mng_typ | E60: #MA.LOT_MNG_TYP | G60: Lot management type | H60: ロット管理区分 | I60: - | J60: E
A61: 30 | D61: sublot_mng_typ | E61: #MA.SUBLOT_MNG_TYP | G61: Sublot management type | H61: サブロット管理区分 | I61: - | J61: E
...

Sheet Chk01
A1: * | B1: * | D1: L | E1: 1
A2: * | D2: オペレーション実装仕様書 Operation Specification Implementation Sheet | E2: ModuleID : | F2: =IF(LogicCommon!C2="","",LogicCommon!C2) -> MS | G2: LogicID : | H2: =IF(LogicCommon!E2="","",LogicCommon!E2) -> MSBEL2410 | I2: Ope.ID : | J2: Chk01 | K2: Pj.ID : | L2: =IF(LogicCommon!G2="","",LogicCommon!G2) -> MC | M2: Ope.Body : | N2: MA.MAUDL5010.Checker
A3: * | E3: SubModuleID : | F3: =IF(LogicCommon!C3="","",LogicCommon!C3) -> MSBE | G3: LogicClass : | H3: =IF(LogicCommon!E3="","",LogicCommon!E3) -> MSBEL_AcXfrInstReg | I3: Ope.Method : | J3: Chk01 | K3: SuperClassPj.ID : | L3: =IF(LogicCommon!G3="","",LogicCommon!G3) | O3: Gene.Type : | P3: ALL
A4: * | E4: Version : | F4: 000000 | G4: LogicName : | H4: =IF(LogicCommon!E4="","",LogicCommon!E4) -> 他勘定振替指図登録 | I4: Ope.Name : | J4: 登録前チェック | K4: SuperLogicID : | L4: =IF(LogicCommon!G4="","",LogicCommon!G4) -> MS.MSUDL5010 | M4: ImplOpe.ID:
A5: * | E5: ACType :
A6: * | D6: 概要 : | E6: 他勘定振替指図を登録する前に、チェックを実行します。 | AD6: ID | AF6: ID
A7: # | I7: U | K7: K | L7: K | M7: K | N7: K | O7: K | P7: K | Q7: K | R7: K | S7: K | T7: K | U7: K | V7: K | W7: K | X7: K | Y7: K | Z7: K | AA7: K | AB7: K | AC7: o | AE7: o
A8: # | D8: ブロック名 Block Name | E8: 型 Type | G8: super/share | H8: 対象ブロック名 Target Block Name | K8: REQ_UPD_CNT_CHK | L8: REQUIRED | M8: CHK_NUM | N8: SMALL_LARGE | O8: CHK_DT | P8: BEFORE_AFTER | Q8: CHK_PTN | R8: DUPLICATE | S8: TOO_MANY_INPUTS | T8: AT_LEAST_ONE | U8: ONLY_ONE_INPUT | V8: LIST_LOGIC | W8: LIST_OUT | X8: LIST_OUT_BASE | Y8: LIST_IN | Z8: LIST_IN_BASE | AA8: CONST | AB8: NULL_VAL | AC8: TargetName | AE8: TargetName | AI8: ブロック備考 Block Remarks
A9: # | D9: 項目名 Field Name | E9: 型 Type | F9: 桁 Digits | G9: フルネーム Full Name | H9: 日本語名 Japanese Name | I9: 上り項目 Request Message Field | J9: 下り項目 Response Message Field | AG9: 条件および編集方法 Conditions and Editing Methods | AI9: 項目備考 Field Remarks
A10: # | AC10: 上り項目 Request Message Field | AD10: 下り項目 Response Message Field | AE10: 上り項目 Request Message Field | AF10: 下り項目 Response Message Field
A11: 10 | B11: * | D11: Chk01_Hdr | E11: R
A12: 10 | D12: acxfr_inst_no | E12: #MA.ACXFR_INST_NO | G12: Other accounting transfer order No. | H12: 他勘定振替指図ＮＯ | I12: - | J12: -
A13: 10 | D13: trd_cd | E13: #MA.TRD_CD | G13: Transaction cd. | H13: 取引ＣＤ | I13: E | J13: E | L13: E | V13: MA.MAUAL0010.Trd | W13: trd_ptn_typ
A14: 10 | D14: trd_ptn_typ | E14: #MA.TRD_PTN_TYP | G14: Transaction pattern type | H14: 取引パタン区分 | I14: - | J14: E
A15: 10 | D15: acxfr_gr_flg | E15: #MA.FLG | G15: Other accounting transfer GR | H15: 他勘定振替入庫 | I15: - | J15: -
A16: 10 | D16: acxfr_gi_flg | E16: #MA.FLG | G16: Other accounting transfer GI | H16: 他勘定振替出庫 | I16: - | J16: -
A17: 10 | D17: disp_flg | E17: #MA.FLG | G17: Disposal | H17: 廃棄 | I17: - | J17: -
A18: 10 | D18: loc_cd | E18: #MA.LOC_CD | G18: Location cd. | H18: 場所ＣＤ | I18: E | J18: E | L18: E | V18: MA.MAUAL0010.Loc | W18: wg_cd;sppl_cd
A19: 10 | D19: wg_cd | E19: #MA.WG_CD | G19: WG cd. | H19: ワーキンググループＣＤ | I19: - | J19: E | V19: MA.MAUAL0010.Wg
A20: 10 | D20: sppl_cd | E20: #MA.BP_CD | G20: Supplier cd. | H20: 発注先ＣＤ | I20: - | J20: -
A21: 10 | D21: acxfr_inst_dt | E21: #MA.DT | G21: Other accounting transfer order date | H21: 他勘定振替指図日 | I21: E | J21: E | L21: E | O21: bfToday
A22: 10 | D22: inst_usr_cd | E22: #MA.USR_CD | G22: Order PIC cd. | H22: 指図担当者ＣＤ | I22: E | J22: E | V22: MA.MAUAL0010.Usr
A23: 10 | D23: inst_dpt_cd | E23: #MA.DPT_CD | G23: Order dept. cd. | H23: 指図部門ＣＤ | I23: E | J23: E | V23: MA.MAUAL0010.Dpt | Y23: inst_usr_cd;acxfr_inst_dt;MAC_DPT_IS_SRCH_TYP.SCE | Z23: usr_cd;dt;dpt_is_srch_typ
A24: 10 | D24: intr_rmrks | E24: #MS.ACXFR_INST_INTR_RMRKS | G24: Internal remarks | H24: 内部備考 | I24: E | J24: E
A25: 10 | D25: trd_rmrks | E25: #MA.TRD_RMRKS | G25: Transaction remarks | H25: 取引備考 | I25: E | J25: E
A26: 10 | D26: inst_rmrks | E26: #MS.ACXFR_INST_RMRKS | G26: Order remarks | H26: 指図備考 | I26: E | J26: E
A27: 10 | D27: sub_char1 | E27: #MS.ACXFR_INST_SUB_CHAR1 | G27: Spare 1 | H27: 予備１ | I27: E | J27: E
A28: 10 | D28: sub_char2 | E28: #MS.ACXFR_INST_SUB_CHAR2 | G28: Spare 2 | H28: 予備２ | I28: E | J28: E
A29: 10 | D29: sub_char3 | E29: #MS.ACXFR_INST_SUB_CHAR3 | G29: Spare 3 | H29: 予備３ | I29: E | J29: E
A30: 10 | D30: inst_upd_cntr | E30: #MA.UPD_CNT | G30: Update counter (Order) | H30: 更新カウンタ(指図) | I30: - | J30: -
A31: 10 | D31: hdr_dtl_peg | E31: #MA.INT | G31: Header details pegged | H31: ヘッダ明細紐付 | I31: - | J31: E
A32: 10 | D32: data_crud_typ | E32: #MA.DATA_CRUD_TYP | G32: Data update type | H32: データ更新区分 | I32: - | J32: E
A33: 10 | D33: err_flg | E33: #MA.FLG | G33: Error | H33: エラー | I33: - | J33: -
A34: 10 | D34: peg_no | E34: #MA.INT | G34: Pegging No. | H34: 紐付けＮＯ | I34: E | J34: E
A36: 20 | B36: * | D36: Chk01_Dtl | E36: L
A37: 20 | D37: peg_no | E37: #MA.INT | G37: Pegging No. | H37: 紐付けＮＯ | I37: E | J37: E
A38: 20 | D38: abort_flg | E38: #MA.FLG | G38: Cancel remaining | H38: 打切 | I38: E | J38: E
A39: 20 | D39: pr_sts_typ | E39: #MS.PR_STS_TYP | G39: Progress status type | H39: 進捗状況区分 | I39: - | J39: E | AA39: MSC_PR_STS_TYP
A40: 20 | D40: itm_cd | E40: #MA.ITM_CD | G40: Item cd. | H40: 品目ＣＤ | I40: E | J40: E | L40: E
A41: 20 | D41: itm_sub1 | E41: #MA.ITM_SUB1 | G41: Branch No. 1 | H41: 枝番１ | I41: E | J41: E | L41: E | AB41: E
...

Sheet Chk02
A1: * | B1: * | D1: L | E1: 1
A2: * | D2: オペレーション実装仕様書 Operation Specification Implementation Sheet | E2: ModuleID : | F2: =IF(LogicCommon!C2="","",LogicCommon!C2) -> MS | G2: LogicID : | H2: =IF(LogicCommon!E2="","",LogicCommon!E2) -> MSBEL2410 | I2: Ope.ID : | J2: Chk02 | K2: Pj.ID : | L2: =IF(LogicCommon!G2="","",LogicCommon!G2) -> MC | M2: Ope.Body : | N2: MA.MAUDL5010.Checker
A3: * | E3: SubModuleID : | F3: =IF(LogicCommon!C3="","",LogicCommon!C3) -> MSBE | G3: LogicClass : | H3: =IF(LogicCommon!E3="","",LogicCommon!E3) -> MSBEL_AcXfrInstReg | I3: Ope.Method : | J3: Chk02 | K3: SuperClassPj.ID : | L3: =IF(LogicCommon!G3="","",LogicCommon!G3) | O3: Gene.Type : | P3: ALL
A4: * | E4: Version : | F4: 000000 | G4: LogicName : | H4: =IF(LogicCommon!E4="","",LogicCommon!E4) -> 他勘定振替指図登録 | I4: Ope.Name : | J4: 更新前チェック | K4: SuperLogicID : | L4: =IF(LogicCommon!G4="","",LogicCommon!G4) -> MS.MSUDL5010 | M4: ImplOpe.ID:
A5: * | E5: ACType :
A6: * | D6: 概要 : | E6: 他勘定振替指図を更新する前に、チェックを実行します。 | L6: ID | N6: ID
A7: # | I7: U | K7: o | M7: o
A8: # | D8: ブロック名 Block Name | E8: 型 Type | G8: super/share | H8: 対象ブロック名 Target Block Name | K8: TargetName | M8: TargetName | Q8: ブロック備考 Block Remarks
A9: # | D9: 項目名 Field Name | E9: 型 Type | F9: 桁 Digits | G9: フルネーム Full Name | H9: 日本語名 Japanese Name | I9: 上り項目 Request Message Field | J9: 下り項目 Response Message Field | O9: 条件および編集方法 Conditions and Editing Methods | Q9: 項目備考 Field Remarks
A10: # | K10: 上り項目 Request Message Field | L10: 下り項目 Response Message Field | M10: 上り項目 Request Message Field | N10: 下り項目 Response Message Field
A11: 10 | B11: * | D11: Chk02_Hdr | E11: R | G11: $share$ | H11: MS.MSBEL2410.Chk01.Chk01_Hdr
A12: 10 | D12: acxfr_inst_no | E12: #MA.ACXFR_INST_NO | G12: Other accounting transfer order No. | H12: 他勘定振替指図ＮＯ | I12: E | J12: E
A13: 10 | D13: trd_cd | E13: #MA.TRD_CD | G13: Transaction cd. | H13: 取引ＣＤ | I13: - | J13: E
A14: 10 | D14: trd_ptn_typ | E14: #MA.TRD_PTN_TYP | G14: Transaction pattern type | H14: 取引パタン区分 | I14: - | J14: E
A15: 10 | D15: acxfr_gr_flg | E15: #MA.FLG | G15: Other accounting transfer GR | H15: 他勘定振替入庫 | I15: - | J15: -
A16: 10 | D16: acxfr_gi_flg | E16: #MA.FLG | G16: Other accounting transfer GI | H16: 他勘定振替出庫 | I16: - | J16: -
A17: 10 | D17: disp_flg | E17: #MA.FLG | G17: Disposal | H17: 廃棄 | I17: - | J17: -
A18: 10 | D18: loc_cd | E18: #MA.LOC_CD | G18: Location cd. | H18: 場所ＣＤ | I18: - | J18: E
A19: 10 | D19: wg_cd | E19: #MA.WG_CD | G19: WG cd. | H19: ワーキンググループＣＤ | I19: - | J19: E
A20: 10 | D20: sppl_cd | E20: #MA.BP_CD | G20: Supplier cd. | H20: 発注先ＣＤ | I20: - | J20: -
A21: 10 | D21: acxfr_inst_dt | E21: #MA.DT | G21: Other accounting transfer order date | H21: 他勘定振替指図日 | I21: E | J21: E
A22: 10 | D22: inst_usr_cd | E22: #MA.USR_CD | G22: Order PIC cd. | H22: 指図担当者ＣＤ | I22: E | J22: E
A23: 10 | D23: inst_dpt_cd | E23: #MA.DPT_CD | G23: Order dept. cd. | H23: 指図部門ＣＤ | I23: E | J23: E
... A34: 10 | D34: peg_no | E34: #MA.INT | G34: Pegging No. | H34: 紐付けＮＯ | I34: E | J34: E
A36: 20 | B36: * | D36: Chk02_Dtl | E36: L | G36: $share$ | H36: MS.MSBEL2410.Chk01.Chk01_Dtl
A37: 20 | D37: peg_no | E37: #MA.INT | G37: Pegging No. | H37: 紐付けＮＯ | I37: E | J37: E
A38: 20 | D38: abort_flg | E38: #MA.FLG | G38: Cancel remaining | H38: 打切 | I38: E | J38: E
A39: 20 | D39: pr_sts_typ | E39: #MS.PR_STS_TYP | G39: Progress status type | H39: 進捗状況区分 | I39: E | J39: E
A40: 20 | D40: itm_cd | E40: #MA.ITM_CD | G40: Item cd. | H40: 品目ＣＤ | I40: E | J40: E
A41: 20 | D41: itm_sub1 | E41: #MA.ITM_SUB1 | G41: Branch No. 1 | H41: 枝番１ | I41: E | J41: E
A42: 20 | D42: itm_sub2 | E42: #MA.ITM_SUB2 | G42: Branch No. 2 | H42: 枝番２ | I42: E | J42: E
A43: 20 | D43: itm_sub3 | E43: #MA.ITM_SUB3 | G43: Branch No. 3 | H43: 枝番３ | I43: E | J43: E
A44: 20 | D44: itm_nm | E44: #MA.ITM_NM | G44: Item name | H44: 品名 | I44: E | J44: E
A45: 20 | D45: sundry_itm_flg | E45: #MA.FLG | G45: Miscellaneous item | H45: 諸口品 | I45: - | J45: -
A46: 20 | D46: lot_mng_typ | E46: #MA.LOT_MNG_TYP | G46: Lot management type | H46: ロット管理区分 | I46: - | J46: -
A47: 20 | D47: sublot_mng_typ | E47: #MA.SUBLOT_MNG_TYP | G47: Sublot management type | H47: サブロット管理区分 | I47: - | J47: -
A48: 20 | D48: sno1_mng_typ | E48: #MA.SNO_MNG_TYP | G48: SEIBAN No. 1 management type | H48: 手配ＮＯ１管理区分 | I48: - | J48: -
... A146: 20 | D146: schd_upd_cntr | E146: #MA.UPD_CNT | G146: Update counter (Schedule) | H146: 更新カウンタ（予定） | I146: E | J146: E
D147: 詳細 :

Sheet Chk03
A1: * | B1: * | D1: L | E1: 1
A2: * | D2: オペレーション実装仕様書 Operation Specification Implementation Sheet | E2: ModuleID : | F2: =IF(LogicCommon!C2="","",LogicCommon!C2) -> MS | G2: LogicID : | H2: =IF(LogicCommon!E2="","",LogicCommon!E2) -> MSBEL2410 | I2: Ope.ID : | J2: Chk03 | K2: Pj.ID : | L2: =IF(LogicCommon!G2="","",LogicCommon!G2) -> MC | M2: Ope.Body : | N2: MA.MAUDL5010.Checker
A3: * | E3: SubModuleID : | F3: =IF(LogicCommon!C3="","",LogicCommon!C3) -> MSBE | G3: LogicClass : | H3: =IF(LogicCommon!E3="","",LogicCommon!E3) -> MSBEL_AcXfrInstReg | I3: Ope.Method : | J3: Chk03 | K3: SuperClassPj.ID : | L3: =IF(LogicCommon!G3="","",LogicCommon!G3) | O3: Gene.Type : | P3: ALL
A4: * | E4: Version : | F4: 000000 | G4: LogicName : | H4: =IF(LogicCommon!E4="","",LogicCommon!E4) -> 他勘定振替指図登録 | I4: Ope.Name : | J4: 取消前チェック | K4: SuperLogicID : | L4: =IF(LogicCommon!G4="","",LogicCommon!G4) -> MS.MSUDL5010 | M4: ImplOpe.ID:
A5: * | E5: ACType :
A6: * | D6: 概要 : | E6: 他勘定振替指図を取消する前に、チェックを実行します。 | AD6: ID | AF6: ID
A7: # | I7: U | K7: K | L7: K | M7: K | N7: K | O7: K | P7: K | Q7: K | R7: K | S7: K | T7: K | U7: K | V7: K | W7: K | X7: K | Y7: K | Z7: K | AA7: K | AB7: K | AC7: o | AE7: o
A8: # | D8: ブロック名 Block Name | E8: 型 Type | G8: super/share | H8: 対象ブロック名 Target Block Name | K8: REQ_UPD_CNT_CHK | L8: REQUIRED | M8: CHK_NUM | N8: SMALL_LARGE | O8: CHK_DT | P8: BEFORE_AFTER | Q8: CHK_PTN | R8: DUPLICATE | S8: TOO_MANY_INPUTS | T8: AT_LEAST_ONE | U8: ONLY_ONE_INPUT | V8: LIST_LOGIC | W8: LIST_OUT | X8: LIST_OUT_BASE | Y8: LIST_IN | Z8: LIST_IN_BASE | AA8: CONST | AB8: NULL_VAL | AC8: TargetName | AE8: TargetName | AI8: ブロック備考 Block Remarks
A9: # | D9: 項目名 Field Name | E9: 型 Type | F9: 桁 Digits | G9: フルネーム Full Name | H9: 日本語名 Japanese Name | I9: 上り項目 Request Message Field | J9: 下り項目 Response Message Field | AG9: 条件および編集方法 Conditions and Editing Methods | AI9: 項目備考 Field Remarks
A10: # | AC10: 上り項目 Request Message Field | AD10: 下り項目 Response Message Field | AE10: 上り項目 Request Message Field | AF10: 下り項目 Response Message Field
A11: 10 | B11: * | D11: Chk03_Hdr | E11: R
A12: 10 | D12: acxfr_inst_no | E12: #MA.ACXFR_INST_NO | G12: Other accounting transfer order No. | H12: 他勘定振替指図ＮＯ | I12: E | J12: E | L12: E
A13: 10 | D13: inst_upd_cntr | E13: #MA.UPD_CNT | G13: Update counter (Order) | H13: 更新カウンタ(指図) | I13: E | J13: E | K13: E
A14: 10 | D14: trd_ptn_typ | E14: #MA.TRD_PTN_TYP | G14: Transaction pattern type | H14: 取引パタン区分 | I14: - | J14: -
A15: 10 | D15: hdr_dtl_peg | E15: #MA.INT | G15: Header details pegged | H15: ヘッダ明細紐付 | I15: - | J15: -
A16: 10 | D16: data_crud_typ | E16: #MA.DATA_CRUD_TYP | G16: Data update type | H16: データ更新区分 | I16: - | J16: -
A17: 10 | D17: loc_cd | E17: #MA.LOC_CD | G17: Location cd. | H17: 場所ＣＤ | I17: E | J17: E
A18: 10 | D18: err_flg | E18: #MA.FLG | G18: Error | H18: エラー | I18: - | J18: -
A19: 10 | D19: peg_no | E19: #MA.INT | G19: Pegging No. | H19: 紐付けＮＯ | I19: - | J19: -
A21: 20 | B21: * | D21: Chk03_Dtl | E21: L
A22: 20 | D22: acxfr_schd_no | E22: #MA.ACXFR_SCHD_NO | G22: Other accounting transfer schedule No. | H22: 他勘定振替予定ＮＯ | I22: - | J22: E
A23: 20 | D23: acxfr_inst_d_no | E23: #MA.ACXFR_INST_D_NO | G23: Other accounting transfer order details No. | H23: 他勘定振替指図明細ＮＯ | I23: - | J23: E
A24: 20 | D24: acxfr_inst_no | E24: #MA.ACXFR_INST_NO | G24: Other accounting transfer order No. | H24: 他勘定振替指図ＮＯ | I24: - | J24: E
A25: 20 | D25: hdr_dtl_peg | E25: #MA.INT | G25: Header details pegged | H25: ヘッダ明細紐付 | I25: - | J25: E
A26: 20 | D26: data_crud_typ | E26: #MA.DATA_CRUD_TYP | G26: Data update type | H26: データ更新区分 | I26: - | J26: E
A27: 20 | D27: err_flg | E27: #MA.FLG | G27: Error | H27: エラー | I27: - | J27: -
A28: 20 | D28: peg_no | E28: #MA.INT | G28: Pegging No. | H28: 紐付けＮＯ | I28: - | J28: -
D29: 詳細 :

Sheet Ins01
A1: * | B1: * | D1: L | E1: 1
A2: * | D2: オペレーション実装仕様書 Operation Specification Implementation Sheet | E2: ModuleID : | F2: =IF(LogicCommon!C2="","",LogicCommon!C2) -> MS | G2: LogicID : | H2: =IF(LogicCommon!E2="","",LogicCommon!E2) -> MSBEL2410 | I2: Ope.ID : | J2: Ins01 | K2: Pj.ID : | L2: =IF(LogicCommon!G2="","",LogicCommon!G2) -> MC | M2: Ope.Body : | N2: "mcframe.serverMAUD.MAUDL5010.MAUDL_Operation"
A3: * | E3: SubModuleID : | F3: =IF(LogicCommon!C3="","",LogicCommon!C3) -> MSBE | G3: LogicClass : | H3: =IF(LogicCommon!E3="","",LogicCommon!E3) -> MSBEL_AcXfrInstReg | I3: Ope.Method : | J3: Ins01 | K3: SuperClassPj.ID : | L3: =IF(LogicCommon!G3="","",LogicCommon!G3) | O3: Gene.Type : | P3: ALL
A4: * | E4: Version : | F4: 000000 | G4: LogicName : | H4: =IF(LogicCommon!E4="","",LogicCommon!E4) -> 他勘定振替指図登録 | I4: Ope.Name : | J4: 新規登録 | K4: SuperLogicID : | L4: =IF(LogicCommon!G4="","",LogicCommon!G4) -> MS.MSUDL5010 | M4: ImplOpe.ID:
A5: * | E5: ACType :
A6: * | D6: 概要 : | E6: 他勘定振替指図を新規登録する。 | M6: ID | O6: ID | Q6: ID
A7: # | I7: U | L7: o | N7: o | P7: o
A8: # | D8: ブロック名 Block Name | E8: 型 Type | G8: super/share | H8: 対象ブロック名 Target Block Name | L8: TargetName | N8: TargetName | P8: TargetName | T8: ブロック備考 Block Remarks
A9: # | D9: 項目名 Field Name | E9: 型 Type | F9: 桁 Digits | G9: フルネーム Full Name | H9: 日本語名 Japanese Name | I9: 上り項目 Request Message Field | J9: 下り項目 Response Message Field | R9: 条件および編集方法 Conditions and Editing Methods | T9: 項目備考 Field Remarks
A10: # | K10: 下り項目 Response Message Field | L10: 上り項目 Request Message Field | M10: 下り項目 Response Message Field | N10: 上り項目 Request Message Field | O10: 下り項目 Response Message Field | P10: 上り項目 Request Message Field | Q10: 下り項目 Response Message Field
A11: 10 | B11: * | D11: Ins01_Hdr | E11: R | G11: $share$ | H11: MS.MSBEL2410.Chk01.Chk01_Hdr
A12: 10 | D12: acxfr_inst_no | E12: #MA.ACXFR_INST_NO | G12: Other accounting transfer order No. | H12: 他勘定振替指図ＮＯ | I12: - | J12: E
A13: 10 | D13: trd_cd | E13: #MA.TRD_CD | G13: Transaction cd. | H13: 取引ＣＤ | I13: E | J13: -
A14: 10 | D14: trd_ptn_typ | E14: #MA.TRD_PTN_TYP | G14: Transaction pattern type | H14: 取引パタン区分 | I14: - | J14: -
A15: 10 | D15: acxfr_gr_flg | E15: #MA.FLG | G15: Other accounting transfer GR | H15: 他勘定振替入庫 | I15: - | J15: -
A16: 10 | D16: acxfr_gi_flg | E16: #MA.FLG | G16: Other accounting transfer GI | H16: 他勘定振替出庫 | I16: - | J16: -
A17: 10 | D17: disp_flg | E17: #MA.FLG | G17: Disposal | H17: 廃棄 | I17: - | J17: -
A18: 10 | D18: loc_cd | E18: #MA.LOC_CD | G18: Location cd. | H18: 場所ＣＤ | I18: E | J18: -
A19: 10 | D19: wg_cd | E19: #MA.WG_CD | G19: WG cd. | H19: ワーキンググループＣＤ | I19: - | J19: -
A20: 10 | D20: sppl_cd | E20: #MA.BP_CD | G20: Supplier cd. | H20: 発注先ＣＤ | I20: - | J20: -
A21: 10 | D21: acxfr_inst_dt | E21: #MA.DT | G21: Other accounting transfer order date | H21: 他勘定振替指図日 | I21: E | J21: -
A22: 10 | D22: inst_usr_cd | E22: #MA.USR_CD | G22: Order PIC cd. | H22: 指図担当者ＣＤ | I22: E | J22: -
A23: 10 | D23: inst_dpt_cd | E23: #MA.DPT_CD | G23: Order dept. cd. | H23: 指図部門ＣＤ | I23: E | J23: -
... A34: 10 | D34: peg_no | E34: #MA.INT | G34: Pegging No. | H34: 紐付けＮＯ | I34: - | J34: -
A36: 20 | B36: * | D36: Ins01_Dtl | E36: L | G36: $share$ | H36: MS.MSBEL2410.Chk01.Chk01_Dtl
A37: 20 | D37: peg_no | E37: #MA.INT | G37: Pegging No. | H37: 紐付けＮＯ | I37: E | J37: -
A38: 20 | D38: abort_flg | E38: #MA.FLG | G38: Cancel remaining | H38: 打切 | I38: E | J38: -
A39: 20 | D39: pr_sts_typ | E39: #MS.PR_STS_TYP | G39: Progress status type | H39: 進捗状況区分 | I39: - | J39: E
A40: 20 | D40: itm_cd | E40: #MA.ITM_CD | G40: Item cd. | H40: 品目ＣＤ | I40: E | J40: -
A41: 20 | D41: itm_sub1 | E41: #MA.ITM_SUB1 | G41: Branch No. 1 | H41: 枝番１ | I41: E | J41: -
A42: 20 | D42: itm_sub2 | E42: #MA.ITM_SUB2 | G42: Branch No. 2 | H42: 枝番２ | I42: E | J42: -
A43: 20 | D43: itm_sub3 | E43: #MA.ITM_SUB3 | G43: Branch No. 3 | H43: 枝番３ | I43: E | J43: -
A44: 20 | D44: itm_nm | E44: #MA.ITM_NM | G44: Item name | H44: 品名 | I44: E | J44: -
A45: 20 | D45: sundry_itm_flg | E45: #MA.FLG | G45: Miscellaneous item | H45: 諸口品 | I45: - | J45: -
A46: 20 | D46: lot_mng_typ | E46: #MA.LOT_MNG_TYP | G46: Lot management type | H46: ロット管理区分 | I46: - | J46: -
A47: 20 | D47: sublot_mng_typ | E47: #MA.SUBLOT_MNG_TYP | G47: Sublot management type | H47: サブロット管理区分 | I47: - | J47: -
A48: 20 | D48: sno1_mng_typ | E48: #MA.SNO_MNG_TYP | G48: SEIBAN No. 1 management type | H48: 手配ＮＯ１管理区分 | I48: - | J48: -
... A141: 20 | D141: schd_upd_cntr | E141: #MA.UPD_CNT | G141: Update counter (Schedule) | H141: 更新カウンタ（予定） | I141: E | J141: -
D142: 詳細 :

Sheet Upd01
A1: * | B1: * | D1: L | E1: 1
A2: * | D2: オペレーション実装仕様書 Operation Specification Implementation Sheet | E2: ModuleID : | F2: =IF(LogicCommon!C2="","",LogicCommon!C2) -> MS | G2: LogicID : | H2: =IF(LogicCommon!E2="","",LogicCommon!E2) -> MSBEL2410 | I2: Ope.ID : | J2: Upd01 | K2: Pj.ID : | L2: =IF(LogicCommon!G2="","",LogicCommon!G2) -> MC | M2: Ope.Body : | N2: "mcframe.serverMAUD.MAUDL5010.MAUDL_Operation"
A3: * | E3: SubModuleID : | F3: =IF(LogicCommon!C3="","",LogicCommon!C3) -> MSBE | G3: LogicClass : | H3: =IF(LogicCommon!E3="","",LogicCommon!E3) -> MSBEL_AcXfrInstReg | I3: Ope.Method : | J3: Upd01 | K3: SuperClassPj.ID : | L3: =IF(LogicCommon!G3="","",LogicCommon!G3) | O3: Gene.Type : | P3: ALL
A4: * | E4: Version : | F4: 000000 | G4: LogicName : | H4: =IF(LogicCommon!E4="","",LogicCommon!E4) -> 他勘定振替指図登録 | I4: Ope.Name : | J4: 更新 | K4: SuperLogicID : | L4: =IF(LogicCommon!G4="","",LogicCommon!G4) -> MS.MSUDL5010 | M4: ImplOpe.ID:
A5: * | E5: ACType :
A6: * | D6: 概要 : | E6: 登録済みの他勘定振替指図を更新する。 | M6: ID | O6: ID | Q6: ID
A7: # | I7: U | L7: o | N7: o | P7: o
A8: # | D8: ブロック名 Block Name | E8: 型 Type | G8: super/share | H8: 対象ブロック名 Target Block Name | L8: TargetName | N8: TargetName | P8: TargetName | T8: ブロック備考 Block Remarks
A9: # | D9: 項目名 Field Name | E9: 型 Type | F9: 桁 Digits | G9: フルネーム Full Name | H9: 日本語名 Japanese Name | I9: 上り項目 Request Message Field | J9: 下り項目 Response Message Field | R9: 条件および編集方法 Conditions and Editing Methods | T9: 項目備考 Field Remarks
A10: # | K10: 下り項目 Response Message Field | L10: 上り項目 Request Message Field | M10: 下り項目 Response Message Field | N10: 上り項目 Request Message Field | O10: 下り項目 Response Message Field | P10: 上り項目 Request Message Field | Q10: 下り項目 Response Message Field
A11: 10 | B11: * | D11: Upd01_Hdr | E11: R | G11: $share$ | H11: MS.MSBEL2410.Chk01.Chk01_Hdr
A12: 10 | D12: acxfr_inst_no | E12: #MA.ACXFR_INST_NO | G12: Other accounting transfer order No. | H12: 他勘定振替指図ＮＯ | I12: E | J12: -
A13: 10 | D13: trd_cd | E13: #MA.TRD_CD | G13: Transaction cd. | H13: 取引ＣＤ | I13: - | J13: -
A14: 10 | D14: trd_ptn_typ | E14: #MA.TRD_PTN_TYP | G14: Transaction pattern type | H14: 取引パタン区分 | I14: - | J14: -
A15: 10 | D15: acxfr_gr_flg | E15: #MA.FLG | G15: Other accounting transfer GR | H15: 他勘定振替入庫 | I15: - | J15: -
A16: 10 | D16: acxfr_gi_flg | E16: #MA.FLG | G16: Other accounting transfer GI | H16: 他勘定振替出庫 | I16: - | J16: -
A17: 10 | D17: disp_flg | E17: #MA.FLG | G17: Disposal | H17: 廃棄 | I17: - | J17: -
A18: 10 | D18: loc_cd | E18: #MA.LOC_CD | G18: Location cd. | H18: 場所ＣＤ | I18: - | J18: -
A19: 10 | D19: wg_cd | E19: #MA.WG_CD | G19: WG cd. | H19: ワーキンググループＣＤ | I19: - | J19: -
A20: 10 | D20: sppl_cd | E20: #MA.BP_CD | G20: Supplier cd. | H20: 発注先ＣＤ | I20: - | J20: -
A21: 10 | D21: acxfr_inst_dt | E21: #MA.DT | G21: Other accounting transfer order date | H21: 他勘定振替指図日 | I21: E | J21: -
A22: 10 | D22: inst_usr_cd | E22: #MA.USR_CD | G22: Order PIC cd. | H22: 指図担当者ＣＤ | I22: E | J22: -
A23: 10 | D23: inst_dpt_cd | E23: #MA.DPT_CD | G23: Order dept. cd. | H23: 指図部門ＣＤ | I23: E | J23: -
... A34: 10 | D34: peg_no | E34: #MA.INT | G34: Pegging No. | H34: 紐付けＮＯ | I34: - | J34: -
A36: 20 | B36: * | D36: Upd01_Dtl | E36: L | G36: $share$ | H36: MS.MSBEL2410.Chk01.Chk01_Dtl
A37: 20 | D37: peg_no | E37: #MA.INT | G37: Pegging No. | H37: 紐付けＮＯ | I37: E | J37: -
A38: 20 | D38: abort_flg | E38: #MA.FLG | G38: Cancel remaining | H38: 打切 | I38: E | J38: -
A39: 20 | D39: pr_sts_typ | E39: #MS.PR_STS_TYP | G39: Progress status type | H39: 進捗状況区分 | I39: E | J39: E
A40: 20 | D40: itm_cd | E40: #MA.ITM_CD | G40: Item cd. | H40: 品目ＣＤ | I40: E | J40: -
A41: 20 | D41: itm_sub1 | E41: #MA.ITM_SUB1 | G41: Branch No. 1 | H41: 枝番１ | I41: E | J41: -
A42: 20 | D42: itm_sub2 | E42: #MA.ITM_SUB2 | G42: Branch No. 2 | H42: 枝番２ | I42: E | J42: -
A43: 20 | D43: itm_sub3 | E43: #MA.ITM_SUB3 | G43: Branch No. 3 | H43: 枝番３ | I43: E | J43: -
A44: 20 | D44: itm_nm | E44: #MA.ITM_NM | G44: Item name | H44: 品名 | I44: E | J44: -
A45: 20 | D45: sundry_itm_flg | E45: #MA.FLG | G45: Miscellaneous item | H45: 諸口品 | I45: - | J45: -
A46: 20 | D46: lot_mng_typ | E46: #MA.LOT_MNG_TYP | G46: Lot management type | H46: ロット管理区分 | I46: - | J46: -
A47: 20 | D47: sublot_mng_typ | E47: #MA.SUBLOT_MNG_TYP | G47: Sublot management type | H47: サブロット管理区分 | I47: - | J47: -
A48: 20 | D48: sno1_mng_typ | E48: #MA.SNO_MNG_TYP | G48: SEIBAN No. 1 management type | H48: 手配ＮＯ１管理区分 | I48: - | J48: -
... A141: 20 | D141: schd_upd_cntr | E141: #MA.UPD_CNT | G141: Update counter (Schedule) | H141: 更新カウンタ（予定） | I141: E | J141: -
D142: 詳細 :

Sheet Del01
A1: * | B1: * | D1: L | E1: 1
A2: * | D2: オペレーション実装仕様書 Operation Specification Implementation Sheet | E2: ModuleID : | F2: =IF(LogicCommon!C2="","",LogicCommon!C2) -> MS | G2: LogicID : | H2: =IF(LogicCommon!E2="","",LogicCommon!E2) -> MSBEL2410 | I2: Ope.ID : | J2: Del01 | K2: Pj.ID : | L2: =IF(LogicCommon!G2="","",LogicCommon!G2) -> MC | M2: Ope.Body : | N2: "mcframe.serverMAUD.MAUDL5010.MAUDL_Operation"
A3: * | E3: SubModuleID : | F3: =IF(LogicCommon!C3="","",LogicCommon!C3) -> MSBE | G3: LogicClass : | H3: =IF(LogicCommon!E3="","",LogicCommon!E3) -> MSBEL_AcXfrInstReg | I3: Ope.Method : | J3: Del01 | K3: SuperClassPj.ID : | L3: =IF(LogicCommon!G3="","",LogicCommon!G3) | O3: Gene.Type : | P3: ALL
A4: * | E4: Version : | F4: 000000 | G4: LogicName : | H4: =IF(LogicCommon!E4="","",LogicCommon!E4) -> 他勘定振替指図登録 | I4: Ope.Name : | J4: 削除 | K4: SuperLogicID : | L4: =IF(LogicCommon!G4="","",LogicCommon!G4) -> MS.MSUDL5010 | M4: ImplOpe.ID:
A5: * | E5: ACType :
A6: * | D6: 概要 : | E6: 登録済みの他勘定振替指図を削除する。 | L6: ID | N6: ID | P6: ID
A7: # | I7: U | K7: o | M7: o | O7: o
A8: # | D8: ブロック名 Block Name | E8: 型 Type | G8: super/share | H8: 対象ブロック名 Target Block Name | K8: TargetName | M8: TargetName | O8: TargetName | S8: ブロック備考 Block Remarks
A9: # | D9: 項目名 Field Name | E9: 型 Type | F9: 桁 Digits | G9: フルネーム Full Name | H9: 日本語名 Japanese Name | I9: 上り項目 Request Message Field | J9: 下り項目 Response Message Field | Q9: 条件および編集方法 Conditions and Editing Methods | S9: 項目備考 Field Remarks
A10: # | K10: 上り項目 Request Message Field | L10: 下り項目 Response Message Field | M10: 上り項目 Request Message Field | N10: 下り項目 Response Message Field | O10: 上り項目 Request Message Field | P10: 下り項目 Response Message Field
A11: 10 | B11: * | D11: Del01_Hdr | E11: R | G11: $share$ | H11: MS.MSBEL2410.Chk03.Chk03_Hdr
A12: 10 | D12: acxfr_inst_no | E12: #MA.ACXFR_INST_NO | G12: Other accounting transfer order No. | H12: 他勘定振替指図ＮＯ | I12: E | J12: -
A13: 10 | D13: inst_upd_cntr | E13: #MA.UPD_CNT | G13: Update counter (Order) | H13: 更新カウンタ(指図) | I13: E | J13: -
A14: 10 | D14: trd_ptn_typ | E14: #MA.TRD_PTN_TYP | G14: Transaction pattern type | H14: 取引パタン区分 | I14: - | J14: -
A15: 10 | D15: hdr_dtl_peg | E15: #MA.INT | G15: Header details pegged | H15: ヘッダ明細紐付 | I15: - | J15: -
A16: 10 | D16: data_crud_typ | E16: #MA.DATA_CRUD_TYP | G16: Data update type | H16: データ更新区分 | I16: - | J16: -
A17: 10 | D17: loc_cd | E17: #MA.LOC_CD | G17: Location cd. | H17: 場所ＣＤ | I17: E | J17: -
A18: 10 | D18: err_flg | E18: #MA.FLG | G18: Error | H18: エラー | I18: - | J18: -
A19: 10 | D19: peg_no | E19: #MA.INT | G19: Pegging No. | H19: 紐付けＮＯ | I19: - | J19: -
A21: 20 | B21: * | D21: Del01_Dtl | E21: L | G21: $share$ | H21: MS.MSBEL2410.Chk03.Chk03_Dtl
A22: 20 | D22: acxfr_schd_no | E22: #MA.ACXFR_SCHD_NO | G22: Other accounting transfer schedule No. | H22: 他勘定振替予定ＮＯ | I22: - | J22: -
A23: 20 | D23: acxfr_inst_d_no | E23: #MA.ACXFR_INST_D_NO | G23: Other accounting transfer order details No. | H23: 他勘定振替指図明細ＮＯ | I23: - | J23: -
A24: 20 | D24: acxfr_inst_no | E24: #MA.ACXFR_INST_NO | G24: Other accounting transfer order No. | H24: 他勘定振替指図ＮＯ | I24: - | J24: -
A25: 20 | D25: hdr_dtl_peg | E25: #MA.INT | G25: Header details pegged | H25: ヘッダ明細紐付 | I25: - | J25: -
A26: 20 | D26: data_crud_typ | E26: #MA.DATA_CRUD_TYP | G26: Data update type | H26: データ更新区分 | I26: - | J26: -
A27: 20 | D27: err_flg | E27: #MA.FLG | G27: Error | H27: エラー | I27: - | J27: -
A28: 20 | D28: peg_no | E28: #MA.INT | G28: Pegging No. | H28: 紐付けＮＯ | I28: - | J28: -
D29: 詳細 :

Sheet Sprt01
A1: * | B1: * | D1: L | E1: 1
A2: * | D2: オペレーション実装仕様書 Operation Specification Implementation Sheet | E2: ModuleID : | F2: =IF(LogicCommon!C2="","",LogicCommon!C2) -> MS | G2: LogicID : | H2: =IF(LogicCommon!E2="","",LogicCommon!E2) -> MSBEL2410 | I2: Ope.ID : | J2: Sprt01 | K2: Pj.ID : | L2: =IF(LogicCommon!G2="","",LogicCommon!G2) -> MC | M2: Ope.Body : | N2: "mcframe.serverMAUD.MAUDL5010.MAUDL_Operation"
A3: * | E3: SubModuleID : | F3: =IF(LogicCommon!C3="","",LogicCommon!C3) -> MSBE | G3: LogicClass : | H3: =IF(LogicCommon!E3="","",LogicCommon!E3) -> MSBEL_AcXfrInstReg | I3: Ope.Method : | J3: Sprt01 | K3: SuperClassPj.ID : | L3: =IF(LogicCommon!G3="","",LogicCommon!G3) | O3: Gene.Type : | P3: ALL
A4: * | E4: Version : | F4: 000000 | G4: LogicName : | H4: =IF(LogicCommon!E4="","",LogicCommon!E4) -> 他勘定振替指図登録 | I4: Ope.Name : | J4: ロット提案 | K4: SuperLogicID : | L4: =IF(LogicCommon!G4="","",LogicCommon!G4) -> MS.MSUDL5010 | M4: ImplOpe.ID:
A5: * | E5: ACType :
A6: * | D6: 概要 : | E6: ロット提案を行う。 | M6: ID | O6: ID | Q6: ID
A7: # | I7: U | K7: K | L7: o | N7: o | P7: o
A8: # | D8: ブロック名 Block Name | E8: 型 Type | G8: super/share | H8: 対象ブロック名 Target Block Name | K8: CONST | L8: TargetName | N8: TargetName | P8: TargetName | T8: ブロック備考 Block Remarks
A9: # | D9: 項目名 Field Name | E9: 型 Type | F9: 桁 Digits | G9: フルネーム Full Name | H9: 日本語名 Japanese Name | I9: 上り項目 Request Message Field | J9: 下り項目 Response Message Field | R9: 条件および編集方法 Conditions and Editing Methods | T9: 項目備考 Field Remarks
A10: # | L10: 上り項目 Request Message Field | M10: 下り項目 Response Message Field | N10: 上り項目 Request Message Field | O10: 下り項目 Response Message Field | P10: 上り項目 Request Message Field | Q10: 下り項目 Response Message Field
A11: 10 | B11: * | D11: Sprt01_Hdr | E11: R
A12: 10 | D12: trd_cd | E12: #MA.TRD_CD | G12: Transaction cd. | H12: 取引ＣＤ | I12: E | J12: -
A13: 10 | D13: loc_cd | E13: #MA.LOC_CD | G13: GI location cd. | H13: 出庫場所ＣＤ | I13: E | J13: -
A15: 20 | B15: * | D15: Sprt01_Dtl | E15: L
A16: 20 | D16: peg_no | E16: #MA.INT | G16: Pegging No. | H16: 紐付けＮＯ | I16: E | J16: E
A17: 20 | D17: check | E17: #MA.FLG | G17: Select | H17: 選択 | I17: E | J17: -
A18: 20 | D18: trd_ptn_typ | E18: #MA.TRD_PTN_TYP | G18: Transaction pattern type | H18: 取引パタン区分 | I18: - | J18: -
A19: 20 | D19: lg_grp_cd | E19: #MA.LG_GRP_CD | G19: Distribution group cd. | H19: 物流グループＣＤ | I19: - | J19: -
A20: 20 | D20: itm_cd | E20: #MA.ITM_CD | G20: Item cd. | H20: 品目ＣＤ | I20: E | J20: -
A21: 20 | D21: itm_sub1 | E21: #MA.ITM_SUB1 | G21: Branch No. 1 | H21: 枝番１ | I21: E | J21: -
A22: 20 | D22: itm_sub2 | E22: #MA.ITM_SUB2 | G22: Branch No. 2 | H22: 枝番２ | I22: E | J22: -
A23: 20 | D23: itm_sub3 | E23: #MA.ITM_SUB3 | G23: Branch No. 3 | H23: 枝番３ | I23: E | J23: -
A24: 20 | D24: alloc_flg | E24: #MA.FLG | G24: Allocation | H24: 引当 | I24: E | J24: -
A25: 20 | D25: not_lot_mix_flg | E25: #MA.FLG | G25: Prohibit mixed lots | H25: ロット混在不可 | I25: - | J25: -
A26: 20 | D26: not_sublot_mix_flg | E26: #MA.FLG | G26: Prohibit mixed sublots | H26: サブロット混在不可 | I26: - | J26: -
A27: 20 | D27: no_lot_fix_flg | E27: #MA.FLG | G27: Without lot | H27: ロット指定無 | I27: E | J27: -
... A46: 20 | D46: gd_nm | E46: #MA.STK_GD_NM | G46: Grading name | H46: 格付名 | I46: - | J46: E
A47: 20 | D47: quality_typ | E47: #MA.QUALITY_TYP | G47: Conforming type | H47: 良品区分 | I47: E | J47: E | K47: MAC_QUALITY_TYP
A48: 20 | D48: quality_typ_nm | E48: #MA.QUALITY_TYP_NM | G48: Conforming type name | H48: 良品区分名 | I48: - | J48: E
A49: 20 | D49: sno1 | E49: #MA.SNO1 | G49: SEIBAN No. 1 | H49: 手配ＮＯ１ | I49: E | J49: -
A50: 20 | D50: sno2 | E50: #MA.SNO2 | G50: SEIBAN No. 2 | H50: 手配ＮＯ２ | I50: E | J50: -
A51: 20 | D51: sno3 | E51: #MA.SNO3 | G51: SEIBAN No. 3 | H51: 手配ＮＯ３ | I51: E | J51: -
A52: 20 | D52: sno4 | E52: #MA.SNO4 | G52: SEIBAN No. 4 | H52: 手配ＮＯ４ | I52: E | J52: -
A53: 20 | D53: stk_id_typ | E53: #MS.STK_ID_TYP | G53: Inventory identification type | H53: 在庫識別区分 | I53: E | J53: E | K53: MSC_STK_ID_TYP
A54: 20 | D54: stk_id_typ_nm | E54: #MS.STK_ID_TYP_NM | G54: Inventory identification type name | H54: 在庫識別区分名 | I54: - | J54: E
A55: 20 | D55: stk_bp_cd | E55: #MA.BP_CD | G55: Inventory BP cd. | H55: 在庫取引先ＣＤ | I55: E | J55: E
A56: 20 | D56: stk_bp_nm | E56: #MA.BP_NM | G56: Inventory BP name | H56: 在庫取引先名 | I56: - | J56: E
A57: 20 | D57: acxfr_schd_dt | E57: #MA.DT | G57: Scheduled other accounting transfer date | H57: 他勘定振替予定日 | I57: E | J57: -
A58: 20 | D58: rsn_cd | E58: #MA.BIZ_RSN_CD | G58: Reason cd. | H58: 理由ＣＤ | I58: E | J58: -
A59: 20 | D59: vld_dt_fr | E59: #MA.DT | G59: Expiration date FR | H59: 有効期限ＦＲ | I59: - | J59: -
...

Sheet 来歴
A1: 変更来歴
A3: Rev. | H3: 修正番号 | O3: 変更内容 | AQ3: 変更箇所
A4: 1 | O4: 初版
A5: 1.1 | H5: MS7031#225 | O5: Sprt01_Dtlブロック ・acxfr_inst_d_noを追加 | AQ5: Sprt01シート
A6: 1.2 | O6: 英語の名称を追記 | AQ6: 全般
